Workbook
Name 明细科目: OFFSET(会计科目!$I$2,MATCH(凭证录入!$F1,总账科目,0),1,,COUNTA(OFFSET(会计科目!$J$2:$IV$2,MATCH(凭证录入!$F1,总账科目,0),)))
Name 总账科目: 会计科目!$I$3:$I$76

Sheet 主界面
A1: 财务记账管理系统

Sheet 基础信息
F1: xwchen | IQ1: xwchen
C2: 基本信息录入
C3: 编制单位： | D3: XIN SHENG
C4: 所属财务期间： | D4: 45992
C5: 填表日期： | D5: 46022
C6: 单位负责人：
C7: 财务负责人：
C8: 复核人：
C9: 制表人：
C11: 注：以上基本信息录入后，各表相关信息将自动生成，无需再录入。 财务期间格式必须如：2020年6月，否则相关表格会显示错误

Sheet 会计科目
A1: 新旧会计科目对照表 | G1: 会计制度使用科目 | J1: 注：以下明细科目可根据需要自行增减或修改，但科目之间不可有空单元格。
A2: 序号 | B2: 编号 | C2: 新会计准则使用科目 | D2: 原会计制度使用科目 | E2: 核算内容 | G2: 序号 | H2: 科目代码 | I2: 总账科目 | J2: 明细科目1 | K2: 明细科目2 | L2: 明细科目3 | M2: 明细科目4 | N2: 明细科目5 | O2: 明细科目6 | P2: 明细科目7 | Q2: 明细科目8 | R2: 明细科目9 | S2: 明细科目10 | T2: 明细科目11 | U2: 明细科目12 | V2: 明细科目13 | W2: 明细科目14 | X2: 明细科目15 | Y2: 明细科目16 | Z2: 明细科目17 | AA2: 明细科目18 | AB2: 明细科目19 | AC2: 明细科目20 | AD2: 明细科目21 | AE2: 明细科目22 | AF2: 明细科目23 | AG2: 明细科目24 | AH2: 明细科目25 | AI2: 明细科目26 | AJ2: 明细科目27 | AK2: 明细科目28 | AL2: 明细科目29 | AM2: 明细科目30 | AN2: 明细科目31 | AO2: 明细科目32 | AP2: 明细科目33 | AQ2: 明细科目34 | AR2: 明细科目35 | AS2: 明细科目36 | AT2: 明细科目37 | AU2: 明细科目38 | AV2: 明细科目39 | AW2: 明细科目40 | AX2: 明细科目41 | AY2: 明细科目42 | AZ2: 明细科目43 | BA2: 明细科目44 | BB2: 明细科目45 | BC2: 明细科目46 | BD2: 明细科目47 | BE2: 明细科目48 | BF2: 明细科目49 | BG2: 明细科目50
C3: 一、资产类 | G3: 一、资产类
A4: 1 | B4: 1001 | C4: 库存现金 | D4: 现金 | E4: 企业的库存现金 | G4: 1 | H4: 1001 | I4: 库存现金 | J4: 苏姆 | K4: 苏姆【工资卡】 | L4: 人民币【李伟忠卡】 | N4: 美元
A5: 2 | B5: 1002 | C5: 银行存款 | D5: 银行存款 | E5: 企业存入银行或其他金融机构的各种款项 | G5: 2 | H5: 1002 | I5: 银行存款 | J5: 国民投资银行（基本户） | L5: 银行卡1029 | N5: 美元账户 | O5: 定期存款
A6: 3 | B6: 1003 | C6: 存放中央银行款项 | D6: ※ | E6: 企业（银行）存放于中国人民银行（以下简称“中央银行”）的各种款项，包括业务资金的调拨、办理同城票据交换和异地跨系统资金汇划、提取或缴存现金等。 | G6: 3 | H6: 1012 | I6: 其他货币资金 | J6: 海关账户
A7: 4 | B7: 1011 | C7: 存放同业 | D7: ※ | E7: 企业（银行）存放于境内、境外银行和非银行金融机构的款项 | G7: 4 | H7: 1101 | I7: 短期投资 | J7: 股票 | K7: 债券 | L7: 基金 | M7: 其他
A8: 5 | B8: 1012 | C8: 其他货币资金 | D8: 其他货币资金 | E8: 企业的银行汇票存款、银行本票存款、信用卡存款、信用证保证金存款、存出投资款、外埠存款等其他货币资金。 | G8: 5 | H8: 1121 | I8: 应收票据
A9: 6 | B9: 1021 | C9: 结算备付金 | D9: ※ | E9: 企业（证券）为证券交易的资金清算与交收而存入指定清算代理机构的款项。企业（证券）向客户收取的结算手续费、向证券交易所支付的结算手续费。 | G9: 6 | H9: 1122 | I9: 应收账款 | J9: 工程款 | K9: 矿石开采服务
A10: 7 | B10: 1031 | C10: 存出保证金 | D10: ※ | E10: 企业（金融）因办理业务需要存出或交纳的各种保证金款项。 | G10: 7 | H10: 1123 | I10: 预付账款
A11: 8 | B11: 1101 | C11: 交易性金融资产 | D11: 短期投资 | E11: 企业为交易目的所持有的债券投资、股票投资、基金投资等交易性金融资产的公允价值 | G11: 8 | H11: 1131 | I11: 应收股利
A12: 9 | B12: 1111 | C12: 买入返售金融资产 | D12: ※ | E12: 企业（金融）按照返售协议约定先买入再按固定价格返售的票据、证券、贷款等金融资产所融出的资金 | G12: 9 | H12: 1132 | I12: 应收利息
A13: 10 | B13: 1121 | C13: 应收票据 | D13: 应收票据 | E13: 企业因销售商品、提供劳务等而收到的商业汇票，包括银行承兑汇票和商业承兑汇票。 | G13: 10 | H13: 1221 | I13: 其他应收款 | J13: 项目备用金 | K13: 社保个人部分 | L13: 其他
A14: 11 | B14: 1122 | C14: 应收账款 | D14: 应收账款 | E14: 企业因销售商品、提供劳务等经营活动应收取的款项 | G14: 11 | H14: 1401 | I14: 材料采购
A15: 12 | B15: 1123 | C15: 预付账款 | D15: 预付账款 | E15: 企业按照合同规定预付的款项。预付款项情况不多的，也可以不设置本科目，将预付的款项直接记入“应付账款”科目 | G15: 12 | H15: 1402 | I15: 在途物资
A16: 13 | B16: 1131 | C16: 应收股利 | D16: 应收股利 | E16: 企业应收取的现金股利和应收取其他单位分配的利润。 | G16: 13 | H16: 1403 | I16: 原材料
A17: 14 | B17: 1132 | C17: 应收利息 | D17: 应收利息 | E17: 企业交易性金融资产、持有至到期投资、可供出售金融资产、发放贷款、存放中央银行款项、拆出资金、买入返售金融资产等应收取的利息。 | G17: 14 | H17: 1404 | I17: 材料成本差异
A18: 15 | B18: 1201 | C18: 应收代位追偿款 | D18: 其他应收款 | E18: 企业（保险）按照原保险合同约定承担赔付保险金责任后确认的代位追偿款 | G18: 15 | H18: 1405 | I18: 库存商品
A19: 16 | B19: 1211 | C19: 应收分保账款 | D19: ※ | E19: 企业（保险）从事再保险业务应收取的款项 | G19: 16 | H19: 1407 | I19: 商品进销差价
A20: 17 | B20: 1212 | C20: 应收分保合同准备金 | D20: ※ | E20: 企业（再保险分出人）从事再保险业务确认的应收分保未到期责任准备金，以及应向再保险接受人摊回的保险责任准备金 | G20: 17 | H20: 1408 | I20: 委托加工物资
A21: 18 | B21: 1221 | C21: 其他应收款 | D21: ※ | E21: 企业除存出保证金、买入返售金融资产、应收票据、应收账款、预付账款、应收股利、应收利息、应收代位追偿款、应收分保账款、应收分保合同准备金、长期应收款等以外的其他各种应收及暂付款项。 | G21: 18 | H21: 1411 | I21: 周转材料
A22: 19 | B22: 1231 | C22: 坏账准备 | D22: 坏账准备 | E22: 企业应收款项的坏账准备 | G22: 19 | H22: 1421 | I22: 消耗性生物资产
A23: 20 | B23: 1301 | C23: 贴现资产 | D23: ※ | E23: 企业（银行）办理商业票据的贴现、转贴现等业务所融出的资金。 | G23: 20 | H23: 1501 | I23: 长期债券投资 | J23: 债券投资 | K23: 其他债权投资
A24: 21 | B24: 1302 | C24: 拆出资金 | D24: ※ | E24: 企业（金融）拆借给境内、境外其他金融机构的款项 | G24: 21 | H24: 1511 | I24: 长期股权投资 | J24: 股票投资 | K24: 其他股权投资
A25: 22 | B25: 1303 | C25: 贷款 | D25: ※ | E25: 企业（银行）按规定发放的各种客户贷款。 | G25: 22 | H25: 1601 | I25: 固定资产
A26: 23 | B26: 1304 | C26: 贷款损失准备 | D26: ※ | E26: 企业（银行）贷款的减值准备。计提贷款损失准备的资产包括贴现资产、拆出资金、客户贷款、银团贷款、贸易融资、协议透支、信用卡透支、转贷款和垫款等. | G26: 23 | H26: 1602 | I26: 累计折旧
A27: 24 | B27: 1311 | C27: 代理兑付证券 | D27: ※ | E27: 企业（证券、银行等）接受委托代理兑付到期的证券。 | G27: 24 | H27: 1604 | I27: 在建工程 | J27: 建筑工程 | K27: 安装工程 | L27: 技术改造工程 | M27: 其他支出
A28: 25 | B28: 1321 | C28: 代理业务资产 | D28: ※ | E28: 企业不承担风险的代理业务形成的资产。 | G28: 25 | H28: 1605 | I28: 工程物资
A29: 26 | B29: 1401 | C29: 材料采购 | D29: 物资采购 | E29: 企业采用计划成本进行材料日常核算而购入材料的采购成本。 | G29: 26 | H29: 1606 | I29: 固定资产清理
A30: 27 | B30: 1402 | C30: 在途物资 | D30: 在途物资 | E30: 企业采用实际成本（或进价）进行材料、商品等物资的日常核算、货款已付尚未验收入库的在途物资的采购成本。 | G30: 27 | H30: 1621 | I30: 生产性生物资产
A31: 28 | B31: 1403 | C31: 原材料 | D31: 原材料 | E31: 企业库存的各种材料。 | G31: 28 | H31: 1622 | I31: 生产性生物资产累计折旧
A32: 29 | B32: 1404 | C32: 材料成本差异 | D32: 材料成本差异 | E32: 企业采用计划成本进行日常核算的材料计划成本与实际成本的差额。 | G32: 29 | H32: 1631 | I32: 临时设施 | J32: 项目部办公区 | K32: 炸药库房 | L32: 管理区 | M32: 工人生活区
A33: 30 | B33: 1405 | C33: 库存商品 | D33: 库存商品 | E33: 企业库存的各种商品的实际成本(或进价)或计划成本（或售价）。 | G33: 30 | H33: 1632 | I33: 临时设施累计折旧
A34: 31 | B34: 1406 | C34: 发出商品 | D34: 分期收款发出商品 | E34: 企业未满足收入确认条件但已发出商品的实际成本（或进价）或计划成本（或售价）。 | G34: 31 | H34: 1701 | I34: 无形资产
A35: 32 | B35: 1407 | C35: 商品进销差价 | D35: 商品进销差价 | E35: 企业采用售价进行日常核算的商品售价与进价之间的差额。 | G35: 32 | H35: 1702 | I35: 累计摊销
A36: 33 | B36: 1408 | C36: 委托加工物资 | D36: 委托加工物资 | E36: 企业委托外单位加工的各种材料、商品等物资的实际成本。 | G36: 33 | H36: 1801 | I36: 长期待摊费用
A37: 34 | B37: 1411 | C37: 周转材料 | D37: 包装物、低值易耗品 | E37: 企业周转材料的计划成本或实际成本。 | G37: 34 | H37: 1901 | I37: 待处理财产损溢
A38: 35 | B38: 1421 | C38: 消耗性生物资产 | D38: ※ | E38: 企业（农业）持有的消耗性生物资产的实际成本。 | G38: 二、负债类
A39: 36 | B39: 1431 | C39: 贵金属 | D39: ※ | E39: 企业（金融）持有的黄金、白银等贵金属存货的成本。 | G39: 35 | H39: 2001 | I39: 短期借款
A40: 37 | B40: 1441 | C40: 抵债资产 | D40: ※ | E40: 企业（金融）依法取得并准备按有关规定进行处置的实物抵债资产的成本。 | G40: 36 | H40: 2201 | I40: 应付票据
...

Sheet 凭证录入
A1: 记 账 凭 证
A2: ="财务期间："&TEXT(基础信息!D4,"yyyy年m月") -> 财务期间：2025年12月 | K2: xwchen
A3: 公司名称： | C3: =基础信息!D3 -> XIN SHENG | G3: 试算平衡： | H3: =IF(AND(SUM(H6:H65536)-SUM(I6:I65536)>=-0.0001,SUM(H6:H65536)-SUM(I6:I65536)<=0.0001),"借贷平衡","借贷不平衡，差异"&SUM(H6:H65536)-SUM(I6:I65536)) -> 借贷平衡
A4: 凭证字 | B4: 凭证号 | C4: 月 | D4: 日 | E4: 摘要 | F4: 会计科目 | H4: 借方金额 | I4: 贷方金额 | J4: 附件张数
F5: 总账科目 | G5: 明细科目
A6: 记 账 凭 证 | B6: 1 | C6: 8 | D6: 1 | E6: 收李伟忠投资款（1500万*43%） | F6: 库存现金 | G6: 人民币 | H6: 6450000
A7: 记 账 凭 证 | B7: 1 | C7: 8 | D7: 1 | E7: 收李伟忠投资款（1500万*43%） | F7: 实收资本 | G7: 李伟忠 | I7: 6450000
A8: 记 账 凭 证 | B8: 2 | C8: 8 | D8: 1 | E8: 收李成远投资款（1500万*18%） | F8: 库存现金 | G8: 人民币 | H8: 2700000
A9: 记 账 凭 证 | B9: 2 | C9: 8 | D9: 1 | E9: 收李成远投资款（1500万*18%） | F9: 实收资本 | G9: 李成远 | I9: 2700000
A10: 记 账 凭 证 | B10: 3 | C10: 8 | D10: 1 | E10: 收崔保健投资款 | F10: 库存现金 | G10: 人民币 | H10: 100000
A11: 记 账 凭 证 | B11: 3 | C11: 8 | D11: 1 | E11: 收崔保健投资款 | F11: 实收资本 | G11: 崔保健 | I11: 100000
A12: 记 账 凭 证 | B12: 4 | C12: 5 | D12: 17 | E12: 支郭冬购买烟酒招待费，转账+现金人民币3000 | F12: 管理费用 | G12: 业务招待费 | H12: 38600
A13: 记 账 凭 证 | B13: 4 | C13: 5 | D13: 17 | E13: 支郭冬购买烟酒招待费，转账+现金人民币3000 | F13: 库存现金 | G13: 人民币 | I13: 38600
A14: 记 账 凭 证 | B14: 5 | C14: 8 | D14: 1 | E14: 收甲方退还人民币现金30000元 | F14: 库存现金 | G14: 人民币 | H14: 30000
A15: 记 账 凭 证 | B15: 5 | C15: 8 | D15: 1 | E15: 收甲方退还人民币现金30000元 | F15: 其他应收款 | I15: 30000
A16: 记 账 凭 证 | B16: 6 | C16: 8 | D16: 1 | E16: 支人民币3万换苏姆，汇率1792 | F16: 库存现金 | G16: 苏姆现金 | H16: 30000
A17: 记 账 凭 证 | B17: 6 | C17: 8 | D17: 1 | E17: 支人民币3万换苏姆，汇率1792 | F17: 库存现金 | G17: 人民币 | I17: 30000
A18: 记 账 凭 证 | B18: 7 | C18: 6 | D18: 9 | E18: 支矿部郭晓岩人民币换苏姆，汇率1800 | F18: 库存现金 | G18: 苏姆 | H18: 11907
A19: 记 账 凭 证 | B19: 7 | C19: 6 | D19: 9 | E19: 支矿部郭晓岩人民币换苏姆，汇率1800 | F19: 库存现金 | G19: 人民币 | I19: 11907
A20: 记 账 凭 证 | B20: 8 | C20: 7 | D20: 22 | E20: 支人民币284738换5亿苏姆，汇率1756 | F20: 库存现金 | G20: 苏姆 | H20: 284738
A21: 记 账 凭 证 | B21: 8 | C21: 7 | D21: 22 | E21: 支人民币284738换5亿苏姆，汇率1756 | F21: 库存现金 | G21: 人民币 | I21: 284738
A22: 记 账 凭 证 | B22: 9 | C22: 8 | D22: 1 | E22: 支人民币108300换1.5万美金，汇率7.22 | F22: 库存现金 | G22: 美元 | H22: 108300
A23: 记 账 凭 证 | B23: 9 | C23: 8 | D23: 1 | E23: 支人民币108300换1.5万美金，汇率7.22 | F23: 库存现金 | G23: 人民币 | I23: 108300
A24: 记 账 凭 证 | B24: 10 | C24: 8 | D24: 1 | E24: 支人民币108300换1.5万美金，汇率7.22 | F24: 库存现金 | G24: 美元 | H24: 108300
A25: 记 账 凭 证 | B25: 10 | C25: 8 | D25: 1 | E25: 支人民币108300换1.5万美金，汇率7.22 | F25: 库存现金 | G25: 人民币 | I25: 108300
A26: 记 账 凭 证 | B26: 11 | C26: 8 | D26: 10 | E26: 支曾工、薛工2人7月14天分摊工资 | F26: 应付职工薪酬 | G26: 职工工资--中籍 | H26: 11148
A27: 记 账 凭 证 | B27: 11 | C27: 8 | D27: 10 | E27: 支曾工、薛工2人7月14天分摊工资 | F27: 库存现金 | G27: 人民币 | I27: 11148
A28: 记 账 凭 证 | B28: 12 | C28: 6 | D28: 5 | E28: 支购项目用翻译机一台 | F28: 管理费用 | G28: 其他 | H28: 5500
A29: 记 账 凭 证 | B29: 12 | C29: 6 | D29: 5 | E29: 支购项目用翻译机一台 | F29: 库存现金 | G29: 人民币 | I29: 5500
A30: 记 账 凭 证 | B30: 13 | C30: 8 | D30: 1 | E30: 支西安机场人民币3120兑换400美金，汇率7.8 | F30: 库存现金 | G30: 美元 | H30: 3120
A31: 记 账 凭 证 | B31: 13 | C31: 8 | D31: 1 | E31: 支西安机场人民币3120兑换400美金，汇率7.8 | F31: 库存现金 | G31: 人民币 | I31: 3120
A32: 记 账 凭 证 | B32: 14 | C32: 7 | D32: 31 | E32: 支张迎春工资、差旅费 | F32: 应付职工薪酬 | G32: 职工工资--中籍 | H32: 41500
A33: 记 账 凭 证 | B33: 14 | C33: 7 | D33: 31 | E33: 支张迎春工资、差旅费 | F33: 库存现金 | G33: 人民币 | I33: 41500
A34: 记 账 凭 证 | B34: 15 | C34: 8 | D34: 15 | E34: 支人民币114285兑换2亿苏姆，汇率1750 | F34: 库存现金 | G34: 苏姆 | H34: 114285
A35: 记 账 凭 证 | B35: 15 | C35: 8 | D35: 15 | E35: 支人民币114285兑换2亿苏姆，汇率1750 | F35: 库存现金 | G35: 人民币 | I35: 114285
A36: 记 账 凭 证 | B36: 16 | C36: 5 | D36: 9 | E36: 支付67号矿井溢价款人民币100万 | F36: 管理费用 | G36: 其他 | H36: 1000000
A37: 记 账 凭 证 | B37: 16 | C37: 5 | D37: 9 | E37: 支付67号矿井溢价款人民币100万 | F37: 库存现金 | G37: 人民币 | I37: 1000000
A38: 记 账 凭 证 | B38: 17 | C38: 5 | D38: 10 | E38: 支付67号矿井溢价款人民币100万 | F38: 管理费用 | G38: 其他 | H38: 1000000
A39: 记 账 凭 证 | B39: 17 | C39: 5 | D39: 10 | E39: 支付67号矿井溢价款人民币100万 | F39: 库存现金 | G39: 人民币 | I39: 1000000
A40: 记 账 凭 证 | B40: 18 | C40: 5 | D40: 11 | E40: 支付67号矿井溢价款人民币100万 | F40: 管理费用 | G40: 其他 | H40: 1000000
...

Sheet 凭证打印
O2: xwchen
C3: 记 账 凭 证 | O3: xwchen
C4: ="财务期间："&TEXT(基础信息!D4,"yyyy年m月") -> 财务期间：2025年12月
C5: ="公司名称："&基础信息!D3 -> 公司名称：XIN SHENG | G5: 凭证号： | H5: 1 | J5: 附件： | K5: =IF(ISERROR(VLOOKUP($H$5,凭证录入!$B$4:$J$65536,9,0)),"",VLOOKUP($H$5,凭证录入!$B$4:$J$65536,9,0)) -> 0 | L5: 张
C6: 摘要 | E6: 会计科目 | G6: 借方金额 | J6: 贷方金额
E7: 总账科目 | F7: 明细科目 | M7: 0
C8: =IF(COUNTIF(凭证录入!$B$6:$B$65536,$H$5)-$M7>0,OFFSET(凭证录入!$E$5,MATCH($H$5,凭证录入!$B$6:$B$65536,0)+$M7,0)&"",0) -> 收李伟忠投资款（1500万*43%） | E8: =IF(COUNTIF(凭证录入!$B$6:$B$65536,$H$5)-$M7>0,OFFSET(凭证录入!$E$5,MATCH($H$5,凭证录入!$B$6:$B$65536,0)+$M7,1)&"",0) -> 库存现金 | F8: =IF(COUNTIF(凭证录入!$B$6:$B$65536,$H$5)-$M7>0,OFFSET(凭证录入!$E$5,MATCH($H$5,凭证录入!$B$6:$B$65536,0)+$M7,2)&"",0) -> 人民币 | G8: =IF(COUNTIF(凭证录入!$B$6:$B$65536,$H$5)-$M7>0,OFFSET(凭证录入!$E$5,MATCH($H$5,凭证录入!$B$6:$B$65536,0)+$M7,3),0) -> 6450000 | J8: =IF(COUNTIF(凭证录入!$B$6:$B$65536,$H$5)-$M7>0,OFFSET(凭证录入!$E$5,MATCH($H$5,凭证录入!$B$6:$B$65536,0)+$M7,4),0) -> 0 | M8: 1
C9: =IF(COUNTIF(凭证录入!$B$6:$B$65536,$H$5)-$M8>0,OFFSET(凭证录入!$E$5,MATCH($H$5,凭证录入!$B$6:$B$65536,0)+$M8,0)&"",0) -> 收李伟忠投资款（1500万*43%） | E9: =IF(COUNTIF(凭证录入!$B$6:$B$65536,$H$5)-$M8>0,OFFSET(凭证录入!$E$5,MATCH($H$5,凭证录入!$B$6:$B$65536,0)+$M8,1)&"",0) -> 实收资本 | F9: =IF(COUNTIF(凭证录入!$B$6:$B$65536,$H$5)-$M8>0,OFFSET(凭证录入!$E$5,MATCH($H$5,凭证录入!$B$6:$B$65536,0)+$M8,2)&"",0) -> 李伟忠 | G9: =IF(COUNTIF(凭证录入!$B$6:$B$65536,$H$5)-$M8>0,OFFSET(凭证录入!$E$5,MATCH($H$5,凭证录入!$B$6:$B$65536,0)+$M8,3),0) -> 0 | J9: =IF(COUNTIF(凭证录入!$B$6:$B$65536,$H$5)-$M8>0,OFFSET(凭证录入!$E$5,MATCH($H$5,凭证录入!$B$6:$B$65536,0)+$M8,4),0) -> 6450000 | M9: 2
C10: =IF(COUNTIF(凭证录入!$B$6:$B$65536,$H$5)-$M9>0,OFFSET(凭证录入!$E$5,MATCH($H$5,凭证录入!$B$6:$B$65536,0)+$M9,0)&"",0) -> 0 | E10: =IF(COUNTIF(凭证录入!$B$6:$B$65536,$H$5)-$M9>0,OFFSET(凭证录入!$E$5,MATCH($H$5,凭证录入!$B$6:$B$65536,0)+$M9,1)&"",0) -> 0 | F10: =IF(COUNTIF(凭证录入!$B$6:$B$65536,$H$5)-$M9>0,OFFSET(凭证录入!$E$5,MATCH($H$5,凭证录入!$B$6:$B$65536,0)+$M9,2)&"",0) -> 0 | G10: =IF(COUNTIF(凭证录入!$B$6:$B$65536,$H$5)-$M9>0,OFFSET(凭证录入!$E$5,MATCH($H$5,凭证录入!$B$6:$B$65536,0)+$M9,3),0) -> 0 | J10: =IF(COUNTIF(凭证录入!$B$6:$B$65536,$H$5)-$M9>0,OFFSET(凭证录入!$E$5,MATCH($H$5,凭证录入!$B$6:$B$65536,0)+$M9,4),0) -> 0 | M10: 3
C11: =IF(COUNTIF(凭证录入!$B$6:$B$65536,$H$5)-$M10>0,OFFSET(凭证录入!$E$5,MATCH($H$5,凭证录入!$B$6:$B$65536,0)+$M10,0)&"",0) -> 0 | E11: =IF(COUNTIF(凭证录入!$B$6:$B$65536,$H$5)-$M10>0,OFFSET(凭证录入!$E$5,MATCH($H$5,凭证录入!$B$6:$B$65536,0)+$M10,1)&"",0) -> 0 | F11: =IF(COUNTIF(凭证录入!$B$6:$B$65536,$H$5)-$M10>0,OFFSET(凭证录入!$E$5,MATCH($H$5,凭证录入!$B$6:$B$65536,0)+$M10,2)&"",0) -> 0 | G11: =IF(COUNTIF(凭证录入!$B$6:$B$65536,$H$5)-$M10>0,OFFSET(凭证录入!$E$5,MATCH($H$5,凭证录入!$B$6:$B$65536,0)+$M10,3),0) -> 0 | J11: =IF(COUNTIF(凭证录入!$B$6:$B$65536,$H$5)-$M10>0,OFFSET(凭证录入!$E$5,MATCH($H$5,凭证录入!$B$6:$B$65536,0)+$M10,4),0) -> 0 | M11: 4
C12: =IF(COUNTIF(凭证录入!$B$6:$B$65536,$H$5)-$M11>0,OFFSET(凭证录入!$E$5,MATCH($H$5,凭证录入!$B$6:$B$65536,0)+$M11,0)&"",0) -> 0 | E12: =IF(COUNTIF(凭证录入!$B$6:$B$65536,$H$5)-$M11>0,OFFSET(凭证录入!$E$5,MATCH($H$5,凭证录入!$B$6:$B$65536,0)+$M11,1)&"",0) -> 0 | F12: =IF(COUNTIF(凭证录入!$B$6:$B$65536,$H$5)-$M11>0,OFFSET(凭证录入!$E$5,MATCH($H$5,凭证录入!$B$6:$B$65536,0)+$M11,2)&"",0) -> 0 | G12: =IF(COUNTIF(凭证录入!$B$6:$B$65536,$H$5)-$M11>0,OFFSET(凭证录入!$E$5,MATCH($H$5,凭证录入!$B$6:$B$65536,0)+$M11,3),0) -> 0 | J12: =IF(COUNTIF(凭证录入!$B$6:$B$65536,$H$5)-$M11>0,OFFSET(凭证录入!$E$5,MATCH($H$5,凭证录入!$B$6:$B$65536,0)+$M11,4),0) -> 0 | M12: 5
C13: =IF(COUNTIF(凭证录入!$B$6:$B$65536,$H$5)-$M12>0,OFFSET(凭证录入!$E$5,MATCH($H$5,凭证录入!$B$6:$B$65536,0)+$M12,0)&"",0) -> 0 | E13: =IF(COUNTIF(凭证录入!$B$6:$B$65536,$H$5)-$M12>0,OFFSET(凭证录入!$E$5,MATCH($H$5,凭证录入!$B$6:$B$65536,0)+$M12,1)&"",0) -> 0 | F13: =IF(COUNTIF(凭证录入!$B$6:$B$65536,$H$5)-$M12>0,OFFSET(凭证录入!$E$5,MATCH($H$5,凭证录入!$B$6:$B$65536,0)+$M12,2)&"",0) -> 0 | G13: =IF(COUNTIF(凭证录入!$B$6:$B$65536,$H$5)-$M12>0,OFFSET(凭证录入!$E$5,MATCH($H$5,凭证录入!$B$6:$B$65536,0)+$M12,3),0) -> 0 | J13: =IF(COUNTIF(凭证录入!$B$6:$B$65536,$H$5)-$M12>0,OFFSET(凭证录入!$E$5,MATCH($H$5,凭证录入!$B$6:$B$65536,0)+$M12,4),0) -> 0 | M13: 6
C14: =IF(COUNTIF(凭证录入!$B$6:$B$65536,$H$5)-$M13>0,OFFSET(凭证录入!$E$5,MATCH($H$5,凭证录入!$B$6:$B$65536,0)+$M13,0)&"",0) -> 0 | E14: =IF(COUNTIF(凭证录入!$B$6:$B$65536,$H$5)-$M13>0,OFFSET(凭证录入!$E$5,MATCH($H$5,凭证录入!$B$6:$B$65536,0)+$M13,1)&"",0) -> 0 | F14: =IF(COUNTIF(凭证录入!$B$6:$B$65536,$H$5)-$M13>0,OFFSET(凭证录入!$E$5,MATCH($H$5,凭证录入!$B$6:$B$65536,0)+$M13,2)&"",0) -> 0 | G14: =IF(COUNTIF(凭证录入!$B$6:$B$65536,$H$5)-$M13>0,OFFSET(凭证录入!$E$5,MATCH($H$5,凭证录入!$B$6:$B$65536,0)+$M13,3),0) -> 0 | J14: =IF(COUNTIF(凭证录入!$B$6:$B$65536,$H$5)-$M13>0,OFFSET(凭证录入!$E$5,MATCH($H$5,凭证录入!$B$6:$B$65536,0)+$M13,4),0) -> 0 | M14: 7
C15: =IF(COUNTIF(凭证录入!$B$6:$B$65536,$H$5)-$M14>0,OFFSET(凭证录入!$E$5,MATCH($H$5,凭证录入!$B$6:$B$65536,0)+$M14,0)&"",0) -> 0 | E15: =IF(COUNTIF(凭证录入!$B$6:$B$65536,$H$5)-$M14>0,OFFSET(凭证录入!$E$5,MATCH($H$5,凭证录入!$B$6:$B$65536,0)+$M14,1)&"",0) -> 0 | F15: =IF(COUNTIF(凭证录入!$B$6:$B$65536,$H$5)-$M14>0,OFFSET(凭证录入!$E$5,MATCH($H$5,凭证录入!$B$6:$B$65536,0)+$M14,2)&"",0) -> 0 | G15: =IF(COUNTIF(凭证录入!$B$6:$B$65536,$H$5)-$M14>0,OFFSET(凭证录入!$E$5,MATCH($H$5,凭证录入!$B$6:$B$65536,0)+$M14,3),0) -> 0 | J15: =IF(COUNTIF(凭证录入!$B$6:$B$65536,$H$5)-$M14>0,OFFSET(凭证录入!$E$5,MATCH($H$5,凭证录入!$B$6:$B$65536,0)+$M14,4),0) -> 0 | M15: 8
C16: =IF(AND(G16-J16>=-0.0001,G16-J16<=0.0001),G16,0) -> 6450000 | D16: ="合计："&IF(C16<0,"负",)&SUBSTITUTE(SUBSTITUTE(TEXT(INT(ABS(C16)),"[dbnum2]")&"元"&SUBSTITUTE(SUBSTITUTE(SUBSTITUTE(TEXT(RIGHT(TEXT(C16,".00"),2),"[dbnum2]0角0分"),"零角","零"),"零分","整"),"零整","整"),"零元零",),"零元",) -> 合计：陆佰肆拾伍万元整 | G16: =IF(ISERROR(SUM(G8:I15)),0,SUM(G8:I15)) -> 6450000 | J16: =IF(ISERROR(SUM(J8:L15)),0,SUM(J8:L15)) -> 6450000
C18: ="会计主管："&基础信息!D7 -> 会计主管： | E18: 过账： | F18: ="复核："&基础信息!D8 -> 复核： | J18: ="制单："&基础信息!D9 -> 制单：
C20: 注：打印凭证纸张规格设置为宽21cm、高14cm

Sheet 科目余额表
A1: 科目余额表
W2: xwchen
A3: 编制单位： | B3: =基础信息!D3 -> XIN SHENG | C3: 财务期间： | D3: =TEXT(基础信息!D4,"yyyy年m月") -> 2025年12月 | G3: 单位：元 | H3: 目录!B1 | I3: 每月报表生成后，请务必将余额表中当月期末余额“数值性粘贴”至下表中相应月份，下月期初余额则自动填入。
A4: 科目代码 | B4: 科目名称 | C4: 期初余额 | D4: 本期发生额 | F4: 方向 | G4: 期末余额 | I4: 上年12月 | J4: 45658 | K4: 本年2月 | L4: 本年3月 | M4: 本年4月 | N4: 本年5月 | O4: 本年6月 | P4: 本年7月 | Q4: 本年8月 | R4: 本年9月 | S4: 本年10月 | T4: 本年11月 | U4: 本年12月
D5: 借方 | E5: 贷方 | I5: 0 | J5: 1 | K5: 2 | L5: 3 | M5: 4 | N5: 5 | O5: 6 | P5: 7 | Q5: 8 | R5: 9 | S5: 10 | T5: 11 | U5: 12
A6: =会计科目!H4 -> 1001 | B6: =会计科目!I4 -> 库存现金 | C6: =HLOOKUP(MONTH(基础信息!$D$4)-1,$I$5:$U$74,ROW(A2)) -> 0 | D6: =SUMIF(凭证录入!$F$6:$F$65536,科目余额表!$B6,凭证录入!$H$6:$H$65536) -> 18166770 | E6: =SUMIF(凭证录入!$F$6:$F$65536,科目余额表!$B6,凭证录入!$I$6:$I$65536) -> 12343800 | F6: 借 | G6: =IF(F6="借",C6+D6-E6,C6+E6-D6) -> 5822970
A7: =会计科目!H5 -> 1002 | B7: =会计科目!I5 -> 银行存款 | C7: =HLOOKUP(MONTH(基础信息!$D$4)-1,$I$5:$U$74,ROW(A3)) -> 0 | D7: =SUMIF(凭证录入!$F$6:$F$65536,科目余额表!$B7,凭证录入!$H$6:$H$65536) -> 0 | E7: =SUMIF(凭证录入!$F$6:$F$65536,科目余额表!$B7,凭证录入!$I$6:$I$65536) -> 0 | F7: 借 | G7: =IF(F7="借",C7+D7-E7,C7+E7-D7) -> 0
A8: =会计科目!H6 -> 1012 | B8: =会计科目!I6 -> 其他货币资金 | C8: =HLOOKUP(MONTH(基础信息!$D$4)-1,$I$5:$U$74,ROW(A4)) -> 0 | D8: =SUMIF(凭证录入!$F$6:$F$65536,科目余额表!$B8,凭证录入!$H$6:$H$65536) -> 0 | E8: =SUMIF(凭证录入!$F$6:$F$65536,科目余额表!$B8,凭证录入!$I$6:$I$65536) -> 0 | F8: 借 | G8: =IF(F8="借",C8+D8-E8,C8+E8-D8) -> 0
A9: =会计科目!H7 -> 1101 | B9: =会计科目!I7 -> 短期投资 | C9: =HLOOKUP(MONTH(基础信息!$D$4)-1,$I$5:$U$74,ROW(A5)) -> 0 | D9: =SUMIF(凭证录入!$F$6:$F$65536,科目余额表!$B9,凭证录入!$H$6:$H$65536) -> 0 | E9: =SUMIF(凭证录入!$F$6:$F$65536,科目余额表!$B9,凭证录入!$I$6:$I$65536) -> 0 | F9: 借 | G9: =IF(F9="借",C9+D9-E9,C9+E9-D9) -> 0
A10: =会计科目!H8 -> 1121 | B10: =会计科目!I8 -> 应收票据 | C10: =HLOOKUP(MONTH(基础信息!$D$4)-1,$I$5:$U$74,ROW(A6)) -> 0 | D10: =SUMIF(凭证录入!$F$6:$F$65536,科目余额表!$B10,凭证录入!$H$6:$H$65536) -> 0 | E10: =SUMIF(凭证录入!$F$6:$F$65536,科目余额表!$B10,凭证录入!$I$6:$I$65536) -> 0 | F10: 借 | G10: =IF(F10="借",C10+D10-E10,C10+E10-D10) -> 0
A11: =会计科目!H9 -> 1122 | B11: =会计科目!I9 -> 应收账款 | C11: =HLOOKUP(MONTH(基础信息!$D$4)-1,$I$5:$U$74,ROW(A7)) -> 0 | D11: =SUMIF(凭证录入!$F$6:$F$65536,科目余额表!$B11,凭证录入!$H$6:$H$65536) -> 0 | E11: =SUMIF(凭证录入!$F$6:$F$65536,科目余额表!$B11,凭证录入!$I$6:$I$65536) -> 0 | F11: 借 | G11: =IF(F11="借",C11+D11-E11,C11+E11-D11) -> 0
A12: =会计科目!H10 -> 1123 | B12: =会计科目!I10 -> 预付账款 | C12: =HLOOKUP(MONTH(基础信息!$D$4)-1,$I$5:$U$74,ROW(A8)) -> 0 | D12: =SUMIF(凭证录入!$F$6:$F$65536,科目余额表!$B12,凭证录入!$H$6:$H$65536) -> 0 | E12: =SUMIF(凭证录入!$F$6:$F$65536,科目余额表!$B12,凭证录入!$I$6:$I$65536) -> 0 | F12: 借 | G12: =IF(F12="借",C12+D12-E12,C12+E12-D12) -> 0
A13: =会计科目!H11 -> 1131 | B13: =会计科目!I11 -> 应收股利 | C13: =HLOOKUP(MONTH(基础信息!$D$4)-1,$I$5:$U$74,ROW(A9)) -> 0 | D13: =SUMIF(凭证录入!$F$6:$F$65536,科目余额表!$B13,凭证录入!$H$6:$H$65536) -> 0 | E13: =SUMIF(凭证录入!$F$6:$F$65536,科目余额表!$B13,凭证录入!$I$6:$I$65536) -> 0 | F13: 借 | G13: =IF(F13="借",C13+D13-E13,C13+E13-D13) -> 0
A14: =会计科目!H12 -> 1132 | B14: =会计科目!I12 -> 应收利息 | C14: =HLOOKUP(MONTH(基础信息!$D$4)-1,$I$5:$U$74,ROW(A10)) -> 0 | D14: =SUMIF(凭证录入!$F$6:$F$65536,科目余额表!$B14,凭证录入!$H$6:$H$65536) -> 0 | E14: =SUMIF(凭证录入!$F$6:$F$65536,科目余额表!$B14,凭证录入!$I$6:$I$65536) -> 0 | F14: 借 | G14: =IF(F14="借",C14+D14-E14,C14+E14-D14) -> 0
A15: =会计科目!H13 -> 1221 | B15: =会计科目!I13 -> 其他应收款 | C15: =HLOOKUP(MONTH(基础信息!$D$4)-1,$I$5:$U$74,ROW(A11)) -> 0 | D15: =SUMIF(凭证录入!$F$6:$F$65536,科目余额表!$B15,凭证录入!$H$6:$H$65536) -> 0 | E15: =SUMIF(凭证录入!$F$6:$F$65536,科目余额表!$B15,凭证录入!$I$6:$I$65536) -> 44440 | F15: 借 | G15: =IF(F15="借",C15+D15-E15,C15+E15-D15) -> -44440
A16: =会计科目!H14 -> 1401 | B16: =会计科目!I14 -> 材料采购 | C16: =HLOOKUP(MONTH(基础信息!$D$4)-1,$I$5:$U$74,ROW(A12)) -> 0 | D16: =SUMIF(凭证录入!$F$6:$F$65536,科目余额表!$B16,凭证录入!$H$6:$H$65536) -> 0 | E16: =SUMIF(凭证录入!$F$6:$F$65536,科目余额表!$B16,凭证录入!$I$6:$I$65536) -> 0 | F16: 借 | G16: =IF(F16="借",C16+D16-E16,C16+E16-D16) -> 0
A17: =会计科目!H15 -> 1402 | B17: =会计科目!I15 -> 在途物资 | C17: =HLOOKUP(MONTH(基础信息!$D$4)-1,$I$5:$U$74,ROW(A13)) -> 0 | D17: =SUMIF(凭证录入!$F$6:$F$65536,科目余额表!$B17,凭证录入!$H$6:$H$65536) -> 0 | E17: =SUMIF(凭证录入!$F$6:$F$65536,科目余额表!$B17,凭证录入!$I$6:$I$65536) -> 0 | F17: 借 | G17: =IF(F17="借",C17+D17-E17,C17+E17-D17) -> 0
... A39: =会计科目!H37 -> 1901 | B39: =会计科目!I37 -> 待处理财产损溢 | C39: =HLOOKUP(MONTH(基础信息!$D$4)-1,$I$5:$U$74,ROW(A35)) -> 0 | D39: =SUMIF(凭证录入!$F$6:$F$65536,科目余额表!$B39,凭证录入!$H$6:$H$65536) -> 0 | E39: =SUMIF(凭证录入!$F$6:$F$65536,科目余额表!$B39,凭证录入!$I$6:$I$65536) -> 0 | F39: 借 | G39: =IF(F39="借",C39+D39-E39,C39+E39-D39) -> 0
A40: =会计科目!H39 -> 2001 | B40: =会计科目!I39 -> 短期借款 | C40: =HLOOKUP(MONTH(基础信息!$D$4)-1,$I$5:$U$74,ROW(A36)) -> 0 | D40: =SUMIF(凭证录入!$F$6:$F$65536,科目余额表!$B40,凭证录入!$H$6:$H$65536) -> 0 | E40: =SUMIF(凭证录入!$F$6:$F$65536,科目余额表!$B40,凭证录入!$I$6:$I$65536) -> 0 | F40: 贷 | G40: =IF(F40="借",C40+D40-E40,C40+E40-D40) -> 0
A41: =会计科目!H40 -> 2201 | B41: =会计科目!I40 -> 应付票据 | C41: =HLOOKUP(MONTH(基础信息!$D$4)-1,$I$5:$U$74,ROW(A37)) -> 0 | D41: =SUMIF(凭证录入!$F$6:$F$65536,科目余额表!$B41,凭证录入!$H$6:$H$65536) -> 0 | E41: =SUMIF(凭证录入!$F$6:$F$65536,科目余额表!$B41,凭证录入!$I$6:$I$65536) -> 0 | F41: 贷 | G41: =IF(F41="借",C41+D41-E41,C41+E41-D41) -> 0
A42: =会计科目!H41 -> 2202 | B42: =会计科目!I41 -> 应付账款 | C42: =HLOOKUP(MONTH(基础信息!$D$4)-1,$I$5:$U$74,ROW(A38)) -> 0 | D42: =SUMIF(凭证录入!$F$6:$F$65536,科目余额表!$B42,凭证录入!$H$6:$H$65536) -> 0 | E42: =SUMIF(凭证录入!$F$6:$F$65536,科目余额表!$B42,凭证录入!$I$6:$I$65536) -> 0 | F42: 贷 | G42: =IF(F42="借",C42+D42-E42,C42+E42-D42) -> 0
A43: =会计科目!H42 -> 2203 | B43: =会计科目!I42 -> 预收账款 | C43: =HLOOKUP(MONTH(基础信息!$D$4)-1,$I$5:$U$74,ROW(A39)) -> 0 | D43: =SUMIF(凭证录入!$F$6:$F$65536,科目余额表!$B43,凭证录入!$H$6:$H$65536) -> 0 | E43: =SUMIF(凭证录入!$F$6:$F$65536,科目余额表!$B43,凭证录入!$I$6:$I$65536) -> 0 | F43: 贷 | G43: =IF(F43="借",C43+D43-E43,C43+E43-D43) -> 0
A44: =会计科目!H43 -> 2211 | B44: =会计科目!I43 -> 应付职工薪酬 | C44: =HLOOKUP(MONTH(基础信息!$D$4)-1,$I$5:$U$74,ROW(A40)) -> 0 | D44: =SUMIF(凭证录入!$F$6:$F$65536,科目余额表!$B44,凭证录入!$H$6:$H$65536) -> 788985 | E44: =SUMIF(凭证录入!$F$6:$F$65536,科目余额表!$B44,凭证录入!$I$6:$I$65536) -> 0 | F44: 贷 | G44: =IF(F44="借",C44+D44-E44,C44+E44-D44) -> -788985
A45: =会计科目!H44 -> 2221 | B45: =会计科目!I44 -> 应交税费 | C45: =HLOOKUP(MONTH(基础信息!$D$4)-1,$I$5:$U$74,ROW(A41)) -> 0 | D45: =SUMIF(凭证录入!$F$6:$F$65536,科目余额表!$B45,凭证录入!$H$6:$H$65536) -> 0 | E45: =SUMIF(凭证录入!$F$6:$F$65536,科目余额表!$B45,凭证录入!$I$6:$I$65536) -> 0 | F45: 贷 | G45: =IF(F45="借",C45+D45-E45,C45+E45-D45) -> 0
A46: =会计科目!H45 -> 2231 | B46: =会计科目!I45 -> 应付利息 | C46: =HLOOKUP(MONTH(基础信息!$D$4)-1,$I$5:$U$74,ROW(A42)) -> 0 | D46: =SUMIF(凭证录入!$F$6:$F$65536,科目余额表!$B46,凭证录入!$H$6:$H$65536) -> 0 | E46: =SUMIF(凭证录入!$F$6:$F$65536,科目余额表!$B46,凭证录入!$I$6:$I$65536) -> 0 | F46: 贷 | G46: =IF(F46="借",C46+D46-E46,C46+E46-D46) -> 0
A47: =会计科目!H46 -> 2232 | B47: =会计科目!I46 -> 应付利润 | C47: =HLOOKUP(MONTH(基础信息!$D$4)-1,$I$5:$U$74,ROW(A43)) -> 0 | D47: =SUMIF(凭证录入!$F$6:$F$65536,科目余额表!$B47,凭证录入!$H$6:$H$65536) -> 0 | E47: =SUMIF(凭证录入!$F$6:$F$65536,科目余额表!$B47,凭证录入!$I$6:$I$65536) -> 0 | F47: 贷 | G47: =IF(F47="借",C47+D47-E47,C47+E47-D47) -> 0
A48: =会计科目!H47 -> 2241 | B48: =会计科目!I47 -> 其他应付款 | C48: =HLOOKUP(MONTH(基础信息!$D$4)-1,$I$5:$U$74,ROW(A44)) -> 0 | D48: =SUMIF(凭证录入!$F$6:$F$65536,科目余额表!$B48,凭证录入!$H$6:$H$65536) -> 100000 | E48: =SUMIF(凭证录入!$F$6:$F$65536,科目余额表!$B48,凭证录入!$I$6:$I$65536) -> 0 | F48: 贷 | G48: =IF(F48="借",C48+D48-E48,C48+E48-D48) -> -100000
A49: =会计科目!H48 -> 2401 | B49: =会计科目!I48 -> 递延收益 | C49: =HLOOKUP(MONTH(基础信息!$D$4)-1,$I$5:$U$74,ROW(A45)) -> 0 | D49: =SUMIF(凭证录入!$F$6:$F$65536,科目余额表!$B49,凭证录入!$H$6:$H$65536) -> 0 | E49: =SUMIF(凭证录入!$F$6:$F$65536,科目余额表!$B49,凭证录入!$I$6:$I$65536) -> 0 | F49: 贷 | G49: =IF(F49="借",C49+D49-E49,C49+E49-D49) -> 0
A50: =会计科目!H49 -> 2501 | B50: =会计科目!I49 -> 长期借款 | C50: =HLOOKUP(MONTH(基础信息!$D$4)-1,$I$5:$U$74,ROW(A46)) -> 0 | D50: =SUMIF(凭证录入!$F$6:$F$65536,科目余额表!$B50,凭证录入!$H$6:$H$65536) -> 0 | E50: =SUMIF(凭证录入!$F$6:$F$65536,科目余额表!$B50,凭证录入!$I$6:$I$65536) -> 0 | F50: 贷 | G50: =IF(F50="借",C50+D50-E50,C50+E50-D50) -> 0
A51: =会计科目!H50 -> 2701 | B51: =会计科目!I50 -> 长期应付款 | C51: =HLOOKUP(MONTH(基础信息!$D$4)-1,$I$5:$U$74,ROW(A47)) -> 0 | D51: =SUMIF(凭证录入!$F$6:$F$65536,科目余额表!$B51,凭证录入!$H$6:$H$65536) -> 0 | E51: =SUMIF(凭证录入!$F$6:$F$65536,科目余额表!$B51,凭证录入!$I$6:$I$65536) -> 0 | F51: 贷 | G51: =IF(F51="借",C51+D51-E51,C51+E51-D51) -> 0
A52: =会计科目!H52 -> 3001 | B52: =会计科目!I52 -> 实收资本 | C52: =HLOOKUP(MONTH(基础信息!$D$4)-1,$I$5:$U$74,ROW(A48)) -> 0 | D52: =SUMIF(凭证录入!$F$6:$F$65536,科目余额表!$B52,凭证录入!$H$6:$H$65536) -> 0 | E52: =SUMIF(凭证录入!$F$6:$F$65536,科目余额表!$B52,凭证录入!$I$6:$I$65536) -> 14600000 | F52: 贷 | G52: =IF(F52="借",C52+D52-E52,C52+E52-D52) -> 14600000
A53: =会计科目!H53 -> 3002 | B53: =会计科目!I53 -> 资本公积 | C53: =HLOOKUP(MONTH(基础信息!$D$4)-1,$I$5:$U$74,ROW(A49)) -> 0 | D53: =SUMIF(凭证录入!$F$6:$F$65536,科目余额表!$B53,凭证录入!$H$6:$H$65536) -> 0 | E53: =SUMIF(凭证录入!$F$6:$F$65536,科目余额表!$B53,凭证录入!$I$6:$I$65536) -> 0 | F53: 贷 | G53: =IF(F53="借",C53+D53-E53,C53+E53-D53) -> 0
A54: =会计科目!H54 -> 3101 | B54: =会计科目!I54 -> 盈余公积 | C54: =HLOOKUP(MONTH(基础信息!$D$4)-1,$I$5:$U$74,ROW(A50)) -> 0 | D54: =SUMIF(凭证录入!$F$6:$F$65536,科目余额表!$B54,凭证录入!$H$6:$H$65536) -> 0 | E54: =SUMIF(凭证录入!$F$6:$F$65536,科目余额表!$B54,凭证录入!$I$6:$I$65536) -> 0 | F54: 贷 | G54: =IF(F54="借",C54+D54-E54,C54+E54-D54) -> 0
A55: =会计科目!H55 -> 3103 | B55: =会计科目!I55 -> 本年利润 | C55: =HLOOKUP(MONTH(基础信息!$D$4)-1,$I$5:$U$74,ROW(A51)) -> 0 | D55: =SUMIF(凭证录入!$F$6:$F$65536,科目余额表!$B55,凭证录入!$H$6:$H$65536) -> 0 | E55: =SUMIF(凭证录入!$F$6:$F$65536,科目余额表!$B55,凭证录入!$I$6:$I$65536) -> 0 | F55: 贷 | G55: =IF(F55="借",C55+D55-E55,C55+E55-D55) -> 0
A56: =会计科目!H56 -> 3104 | B56: =会计科目!I56 -> 利润分配 | C56: =HLOOKUP(MONTH(基础信息!$D$4)-1,$I$5:$U$74,ROW(A52)) -> 0 | D56: =SUMIF(凭证录入!$F$6:$F$65536,科目余额表!$B56,凭证录入!$H$6:$H$65536) -> 0 | E56: =SUMIF(凭证录入!$F$6:$F$65536,科目余额表!$B56,凭证录入!$I$6:$I$65536) -> 0 | F56: 贷 | G56: =IF(F56="借",C56+D56-E56,C56+E56-D56) -> 0
A57: =会计科目!H58 -> 4001 | B57: =会计科目!I58 -> 生产成本 | C57: =HLOOKUP(MONTH(基础信息!$D$4)-1,$I$5:$U$74,ROW(A53)) -> 0 | D57: =SUMIF(凭证录入!$F$6:$F$65536,科目余额表!$B57,凭证录入!$H$6:$H$65536) -> 0 | E57: =SUMIF(凭证录入!$F$6:$F$65536,科目余额表!$B57,凭证录入!$I$6:$I$65536) -> 0 | F57: 借 | G57: =IF(F57="借",C57+D57-E57,C57+E57-D57) -> 0
A58: =会计科目!H59 -> 4101 | B58: =会计科目!I59 -> 制造费用 | C58: =HLOOKUP(MONTH(基础信息!$D$4)-1,$I$5:$U$74,ROW(A54)) -> 0 | D58: =SUMIF(凭证录入!$F$6:$F$65536,科目余额表!$B58,凭证录入!$H$6:$H$65536) -> 0 | E58: =SUMIF(凭证录入!$F$6:$F$65536,科目余额表!$B58,凭证录入!$I$6:$I$65536) -> 0 | F58: 借 | G58: =IF(F58="借",C58+D58-E58,C58+E58-D58) -> 0
A59: =会计科目!H60 -> 4301 | B59: =会计科目!I60 -> 研发支出 | C59: =HLOOKUP(MONTH(基础信息!$D$4)-1,$I$5:$U$74,ROW(A55)) -> 0 | D59: =SUMIF(凭证录入!$F$6:$F$65536,科目余额表!$B59,凭证录入!$H$6:$H$65536) -> 0 | E59: =SUMIF(凭证录入!$F$6:$F$65536,科目余额表!$B59,凭证录入!$I$6:$I$65536) -> 0 | F59: 借 | G59: =IF(F59="借",C59+D59-E59,C59+E59-D59) -> 0
A60: =会计科目!H61 -> 4401 | B60: =会计科目!I61 -> 工程施工 | C60: =HLOOKUP(MONTH(基础信息!$D$4)-1,$I$5:$U$74,ROW(A56)) -> 0 | D60: =SUMIF(凭证录入!$F$6:$F$65536,科目余额表!$B60,凭证录入!$H$6:$H$65536) -> 0 | E60: =SUMIF(凭证录入!$F$6:$F$65536,科目余额表!$B60,凭证录入!$I$6:$I$65536) -> 0 | F60: 借 | G60: =IF(F60="借",C60+D60-E60,C60+E60-D60) -> 0
A61: =会计科目!H62 -> 4403 | B61: =会计科目!I62 -> 机械作业 | C61: =HLOOKUP(MONTH(基础信息!$D$4)-1,$I$5:$U$74,ROW(A57)) -> 0 | D61: =SUMIF(凭证录入!$F$6:$F$65536,科目余额表!$B61,凭证录入!$H$6:$H$65536) -> 0 | E61: =SUMIF(凭证录入!$F$6:$F$65536,科目余额表!$B61,凭证录入!$I$6:$I$65536) -> 0 | F61: 借 | G61: =IF(F61="借",C61+D61-E61,C61+E61-D61) -> 0
...

Sheet 资产负债表
A1: 资 产 负 债 表
L2: xwchen
A4: 编制单位： | B4: =基础信息!D3 -> XIN SHENG | E4: 填表日期： | F4: =基础信息!D5 -> 46022 | G4: =TEXT(基础信息!D4,"yyyy年m月") -> 2025年12月 | J4: 单位：元 | L4: 目录!B1
A5: 资产 | C5: 行次 | D5: 年初数 | E5: 期末数 | F5: 负债和所有者权益 (或股东权益) | H5: 行次 | I5: 年初数 | J5: 期末数
A6: 流动资产： | F6: 流动负债：
A7: 货币资金 | C7: 1 | E7: =科目余额表!G6+科目余额表!G7+科目余额表!G8 -> 5822970 | F7: 短期借款 | H7: 68 | J7: =科目余额表!G40 -> 0
A8: 短期投资 | C8: 2 | E8: =科目余额表!G9 -> 0 | F8: 应付票据 | H8: 69 | J8: =科目余额表!G41 -> 0
A9: 应收票据 | C9: 3 | E9: =科目余额表!G10 -> 0 | F9: 应付账款 | H9: 70 | J9: =科目余额表!G42 -> 0
A10: 应收股利 | C10: 4 | E10: =科目余额表!G13 -> 0 | F10: 预收账款 | H10: 71 | J10: =科目余额表!G43 -> 0
A11: 应收利息 | C11: 5 | E11: =科目余额表!G14 -> 0 | F11: 应付工资 | H11: 72 | J11: =科目余额表!G44 -> -788985
A12: 应收账款 | C12: 6 | E12: =科目余额表!G11 -> 0 | F12: 应付福利费 | H12: 73
A13: 其他应收款 | C13: 7 | E13: =科目余额表!G15 -> -44440 | F13: 应付股利 | H13: 74 | J13: =科目余额表!G47 -> 0
A14: 预付账款 | C14: 8 | E14: =科目余额表!G12 -> 0 | F14: 应交税金 | H14: 75 | J14: =科目余额表!G45 -> 0
A15: 应收补贴款 | C15: 9 | F15: 其他应交款 | H15: 80
A16: 存货 | C16: 10 | E16: =SUM(科目余额表!G16:科目余额表!G24) -> 0 | F16: 其他应付款 | H16: 81 | J16: =科目余额表!G48 -> -100000
A17: 待摊费用 | C17: 11 | F17: 预提费用 | H17: 82
A18: 一年内到期的长期债券投资 | C18: 21 | F18: 预计负债 | H18: 83
A19: 其他流动资产 | C19: 24 | E19: =科目余额表!G39 -> 0 | F19: 一年内到期的长期负债 | H19: 86
A20: 流动资产合计 | C20: 31 | D20: =SUM(D7:D19) -> 0 | E20: =SUM(E7:E19) -> 5778530 | F20: 其他流动负债 | H20: 90 | J20: =科目余额表!G49 -> 0
A21: 长期资产：
A22: 长期股权投资 | C22: 32 | E22: =科目余额表!G26 -> 0 | F22: 流动负债合计 | H22: 100 | I22: =SUM(I7:I21) -> 0 | J22: =SUM(J7:J21) -> -888985
A23: 长期债券投资 | C23: 34 | E23: =科目余额表!G25 -> 0 | F23: 长期负债：
A24: 长期投资合计 | C24: 38 | D24: =SUM(D22:D23) -> 0 | E24: =SUM(E22:E23) -> 0 | F24: 长期借款 | H24: 101 | J24: =科目余额表!G50 -> 0
A25: 固定资产： | F25: 应付债券 | H25: 102
A26: 固定资产原价 | C26: 39 | E26: =科目余额表!G27 -> 3100843 | F26: 长期应付款 | H26: 103 | J26: =科目余额表!G51 -> 0
A27: 减：累计折旧 | C27: 40 | E27: =科目余额表!G28 -> 0 | F27: 专项应付款 | H27: 106
A28: 固定资产净值 | C28: 41 | D28: =D26-D27 -> 0 | E28: =E26-E27 -> 3100843 | F28: 其他长期负债 | H28: 108
A29: 减：固定资产减值准备 | C29: 42 | F29: 长期负债合计 | H29: 110 | I29: =SUM(I24:I28) -> 0 | J29: =SUM(J24:J28) -> 0
A30: 固定资产净额 | C30: 43 | D30: =D28-D29 -> 0 | E30: =E28-E29 -> 3100843 | F30: 递延税项：
A31: 工程物资 | C31: 44 | E31: =科目余额表!G30 -> 0 | F31: 递延税款贷项 | H31: 111
A32: 在建工程 | C32: 45 | E32: =科目余额表!G29 -> 0 | F32: 负债合计 | H32: 114 | I32: =SUM(I22,I29,I31) -> 0 | J32: =SUM(J22,J29,J31) -> -888985
A33: 固定资产清理 | C33: 46 | E33: =科目余额表!G31 -> 0
A34: 固定资产合计 | C34: 50 | D34: =SUM(D30:D33) -> 0 | E34: =SUM(E30:E33)+(科目余额表!G32-科目余额表!G33)+(科目余额表!G34-科目余额表!G35) -> 3100843 | F34: 所有者权益(或股东权益)：
A35: 无形资产及其他资产： | F35: 实收资本(或股本) | H35: 115 | J35: =科目余额表!G52 -> 14600000
A36: 无形资产 | C36: 51 | E36: =科目余额表!G36-科目余额表!G37 -> 0 | F36: 减：已归还投资 | H36: 116
A37: 长期待摊费用 | C37: 52 | E37: =科目余额表!G38 -> 0 | F37: 实收资本(或股本)净额 | H37: 117 | I37: =I35-I36 -> 0 | J37: =J35-J36 -> 14600000
A38: 其他长期资产 | C38: 53 | F38: 资本公积 | H38: 118 | J38: =科目余额表!G53 -> 0
A39: 无形资产及其他资产合计 | C39: 60 | D39: =SUM(D36:D38) -> 0 | E39: =SUM(E36:E38) -> 0 | F39: 盈余公积 | H39: 119 | J39: =科目余额表!G54 -> 0
F40: 其中：法定公益金 | H40: 120
A41: 递延税款： | F41: 未分配利润 | H41: 121 | J41: =科目余额表!G56+损益表!G22 -> -4831642
...

Sheet 损益表
B1: 损 益 表
W2: xwchen
B4: 编制单位： | C4: =资产负债表!B4 -> XIN SHENG | D4: =基础信息!D5 -> 46022 | E4: =资产负债表!G4 -> 2025年12月 | G4: 单位：元 | I4: 每月报表生成后，请务必将损益表中本月数“数值性粘贴”至下表中相应月份，本年累计数则自动计算。
B5: 项目 | E5: 行次 | F5: 本月数 | G5: 本年累计数 | I5: 本年累计数 | J5: 1月 | K5: 2月 | L5: 3月 | M5: 4月 | N5: 5月 | O5: 6月 | P5: 7月 | Q5: 8月 | R5: 9月 | S5: 10月 | T5: 11月 | U5: 12月
B6: 一、主营业务收入 | E6: 1 | F6: =科目余额表!E62 -> 0 | G6: =科目余额表!G62 -> 0 | I6: =SUM(J6:U6) -> 0
B7: 减：主营业务成本 | E7: 4 | F7: =科目余额表!D66 -> 0 | G7: =科目余额表!G66 -> 0 | I7: =SUM(J7:U7) -> 0
B8: 主营业务税金及附加 | E8: 5 | F8: =科目余额表!D68 -> 0 | G8: =科目余额表!G68 -> 0 | I8: =SUM(J8:U8) -> 0
B9: 二、主营业务利润(亏损以“-”号填列) | E9: 10 | F9: =F6-F7-F8 -> 0 | G9: =G6-G7-G8 -> 0 | I9: =SUM(J9:U9) -> 0
B10: 加：其他业务利润(亏损以“-”号填列) | E10: 11 | F10: =科目余额表!E63-科目余额表!D67 -> 0 | G10: =科目余额表!G63-科目余额表!G67 -> 0 | I10: =SUM(J10:U10) -> 0
B11: 减：营业费用 | E11: 14 | F11: =科目余额表!D69 -> 0 | G11: =科目余额表!G69 -> 0 | I11: =SUM(J11:U11) -> 0
B12: 管理费用 | E12: 15 | F12: =科目余额表!D70 -> 4831642 | G12: =科目余额表!G70 -> 4831642 | I12: =SUM(J12:U12) -> 9000 | U12: 9000
B13: 财务费用 | E13: 16 | F13: =科目余额表!D71 -> 0 | G13: =科目余额表!G71 -> 0 | I13: =SUM(J13:U13) -> 0 | U13: 0
B14: 三、营业利润(亏损以“-”号填列) | E14: 18 | F14: =F9+F10-F11-F12-F13 -> -4831642 | G14: =G9+G10-G11-G12-G13 -> -4831642 | I14: =SUM(J14:U14) -> -9000 | U14: -9000
B15: 加：投资收益(亏损以“-”号填列) | E15: 19 | F15: =科目余额表!E64 -> 0 | G15: =科目余额表!G64 -> 0 | I15: =SUM(J15:U15) -> 0 | U15: 0
B16: 补贴收入 | E16: 22 | I16: =SUM(J16:U16) -> 0 | U16: 0
B17: 营业外收入 | E17: 23 | F17: =科目余额表!E65 -> 0 | G17: =科目余额表!G65 -> 0 | I17: =SUM(J17:U17) -> 0 | U17: 0
B18: 减：营业外支出 | E18: 25 | F18: =科目余额表!D72 -> 0 | G18: =科目余额表!G72 -> 0 | I18: =SUM(J18:U18) -> 0 | U18: 0
B19: 加：以前年度损益调整 | E19: 26 | F19: =科目余额表!D74 -> 0 | G19: =科目余额表!G74 -> 0 | I19: =SUM(J19:U19) -> 0 | U19: 0
B20: 四、利润总额(亏损以“-”号填列) | E20: 27 | F20: =F14+F15+F16+F17-F18+F19 -> -4831642 | G20: =G14+G15+G16+G17-G18+G19 -> -4831642 | I20: =SUM(J20:U20) -> -9000 | U20: -9000
B21: 减：所得税 | E21: 28 | F21: =科目余额表!D73 -> 0 | G21: =科目余额表!G73 -> 0 | I21: =SUM(J21:U21) -> 0 | U21: 0
B22: 五、净利润(亏损以“-”号填列) | E22: 30 | F22: =F20-F21 -> -4831642 | G22: =G20-G21 -> -4831642 | I22: =SUM(J22:U22) -> -9000 | U22: -9000
B24: 补充资料
B26: 项目 | F26: 本年累计数 | G26: 上年实际数
B27: １．出售、处置部分或投资单位所得收益
B28: ２．自然灾害发生的损失
B29: ３．会计政策变更增加（或减少）利润总额
B30: ４．会计估计变更增加（或减少）利润总额
B31: ５．债务重组损失
B32: ６．其他
B34: ="单位负责人："&基础信息!D6 -> 单位负责人： | D34: ="财务负责人："&基础信息!D7 -> 财务负责人： | E34: ="复核："&基础信息!D8 -> 复核： | G34: ="制表："&基础信息!D9 -> 制表：
B37: 附：利润分配表
B38: 利润分配表
B40: 编制单位： | C40: =资产负债表!B4 -> XIN SHENG | D40: =YEAR(基础信息!D4)&"年度" -> 2025年度 | G40: 单位：元
B41: 项目 | E41: 行次 | F41: 本年累计数 | G41: 上年实际数
B42: 一、净利润(亏损以“-”号填列) | E42: 1 | F42: =G22 -> -4831642
B43: 加：年初未分配利润 | E43: 2
B44: 其他转入 | E44: 4
B45: 二、可供分配的利润 | E45: 8 | F45: =F42+F43+F44 -> -4831642 | G45: =G42+G43+G44 -> 0
B46: 减：提取法定盈余公积 | E46: 9
B47: 提取法定公益金 | E47: 10
...

Sheet 表外数据录入
A2: 编制现金流量表所需表外数据录入 | F2: 目录!B1
A3: 序号 | B3: 项目 | C3: 金额
A4: 1 | B4: 支付给职工的工资、奖金及各项津贴 | C4: 6000
B5: 养老保险金
B6: 医疗保险金
B7: 失业保险费
B8: 住房公积金
B9: 劳动保护费
B10: 支付给职工的其他福利费
B11: 支付给职工以及为职工支付的现金合计 | C11: =SUM(C4:C10) -> 6000 | D11: 税率
A12: 2 | B12: 主营业务收入（17％增值税部分） | D12: 0.17
B13: 主营业务收入（13％增值税部分） | D13: 0.13
B14: 主营业务收入（6％增值税部分） | D14: 0.06
B15: 主营业务收入（4％增值税部分） | D15: 0.04
B16: 非应税项目主营业务收入(本栏仅供校验勾稽关系不计算销项税额)
B17: 销项税额合计 | C17: =C12*D12+C13*D13+C14*D14+C15*D15 -> 0 | E17: =IF(SUM(C12:C16)=损益表!G6,"","主营业务收入合计与利润表不符！")
B18: 主营业务成本（17％增值税部分） | D18: 0.17
B19: 主营业务成本（13％增值税部分） | D19: 0.13
B20: 小规模纳税人主营业务成本(本栏仅供校验勾稽关系不计算进项税额)
B21: 非增值税行业主营业务成本(本栏仅供校验勾稽关系不计算进项税额) | E21: =IF(SUM(C18:C21)=损益表!G7,"","主营业务成本合计与利润表不符！")
B22: 存货增加额（17％部分） | D22: 0.17
B23: 存货增加额（13％部分） | D23: 0.13
B24: 小规模纳税人进货增加额(本栏仅供校验勾稽关系不计算进项税额) | E24: =IF(SUM(C22:C24)=资产负债表!E16-资产负债表!D16,"","存货增加额与资产负债表不符！")
B25: 进项税额合计 | C25: =C18*D18+C19*D19+C22*D22+C23*D23 -> 0
B26: 应交增值税
B27: 在“主营业务税金及附加”科目列支的各项税金 | C27: =损益表!G8 -> 0
B28: 所得税 | D28: 0.15
B29: 管理费用中列支的税金
B30: 未通过“应交税金”科目核算的其他税金
B31: 支付的各项税费合计
A32: 3 | B32: 收到的税费返还合计 | C32: =SUM(C33:C37) -> 0
B33: 出口退税
B34: 增值税返回
B35: 所得税返回
B36: 财政扶持补贴
B37: 其他税收返回
A38: 4 | B38: 分配股利、利润或偿付利息所支付的现金合计 | C38: =C39+C40+C43 -> 0
B39: 分配股利所支付的现金
B40: 分配利润所支付的现金
B41: 利息支出(根据财务费用科目明细提取，不抵减利息收入)
...

Sheet 现金流量表
B1: 现 金 流 量 表
B4: ="编制单位："&资产负债表!B4 -> 编制单位：XIN SHENG | D4: =TEXT(基础信息!D4,"yyyy年m月") -> 2025年12月 | G4: 单位：元 | H4: 目录!B1
B5: 项目 | C5: 行次 | D5: 金额 | E5: 补充资料 | F5: 行次 | G5: 金额
B6: 一、经营活动产生的现金流量： | E6: 1、将净利润调节为经营活动现金流量：
B7: 销售商品、提供劳务收到的现金： | C7: 1 | D7: =损益表!G6*1.17+(资产负债表!D9-资产负债表!E9)+(资产负债表!D12-资产负债表!E12)+(资产负债表!J10-资产负债表!I10)-表外数据录入!C42 -> 0 | E7: 净利润 | F7: 57 | G7: =损益表!G22 -> -4831642
B8: 收到的税费返还： | C8: 3 | D8: =表外数据录入!C32 -> 0 | E8: 加：计提的资产减值准备 | F8: 58 | G8: =表外数据录入!C44 -> 0
B9: 收到的其他与经营活动有关的现金： | C9: 8 | D9: =G39+D15-D7-D8-D27-D37-D38 -> -5670187 | E9: 固定资产折旧 | F9: 59 | G9: =资产负债表!E27-资产负债表!D27 -> 0
B10: 现金流入小计 | C10: 9 | D10: =SUM(D7:D9) -> -5670187 | E10: 无形资产摊销 | F10: 60 | G10: =表外数据录入!C53 -> 0
B11: 购买商品接受劳务支付的现金 | C11: 10 | D11: =(损益表!G7+资产负债表!E16-资产负债表!D16)*1.17+(资产负债表!I8-资产负债表!J8)+(资产负债表!I9-资产负债表!J9)+(资产负债表!E14-资产负债表!D14) -> 0 | E11: 长期待摊费用摊销 | F11: 61 | G11: =表外数据录入!C54 -> 0
B12: 支付给职工以及为职工支付的现金 | C12: 12 | D12: =表外数据录入!C11 -> 6000 | E12: 待摊费用减少（减：增加） | F12: 64 | G12: =资产负债表!D17-资产负债表!E17 -> 0
B13: 支付的各项税费 | C13: 13 | D13: =表外数据录入!C31 -> 0 | E13: 预提费用增加（减：减少） | F13: 65 | G13: =资产负债表!J17-资产负债表!I17 -> 0
B14: 支付的其他与经营活动有关的现金 | C14: 18 | D14: =IF(((资产负债表!E13-资产负债表!D13)+损益表!G18+损益表!G12+损益表!G11-D12+(D34-损益表!G13)-(资产负债表!E27-资产负债表!D27)-(资产负债表!E12+资产负债表!E13)*0.005/0.995-表外数据录入!C29)<0,ABS(((资产负债表!E13-资产负债表!D13)+损益表!G18+损益表!G12+损益表!G11-D12+(D34-损益表!G13)-(资产负债表!E27-资产负债表!D27)-(资产负债表!E12+资产负债表!E13)*0.005/0.995-表外数据录入!C29)*0.8)," ") | E14: 处置固定资产、无形资产和其他长期资产的损失（减：收益） | F14: 66 | G14: =表外数据录入!C56 -> 0
B15: 现金流出小计 | C15: 20 | D15: =SUM(D11:D14) -> 6000 | E15: 固定资产报废损失 | F15: 67 | G15: =表外数据录入!C55 -> 0
B16: 经营活动产生的现金流量净额 | C16: 21 | D16: =D10-D15 -> -5676187 | E16: 财务费用 | F16: 68 | G16: =表外数据录入!C43 -> 0
B17: 二、投资活动产生的现金流量： | E17: 投资损失（减：收益） | F17: 69 | G17: =-损益表!G15 -> 0
B18: 收回投资所收到的现金 | C18: 22 | D18: =IF((资产负债表!E8+资产负债表!E24-资产负债表!D8-资产负债表!D24)<0,ABS(资产负债表!E8+资产负债表!E24-资产负债表!D8-资产负债表!D24)," ") | E18: 递延税款贷项（减：借项） | F18: 70 | G18: =(资产负债表!J31-资产负债表!I31)-(资产负债表!E42-资产负债表!D42) -> 0
B19: 取得投资收益所收到的现金 | C19: 23 | D19: =表外数据录入!C57 -> 0 | E19: 存货的减少（减：增加） | F19: 71 | G19: =资产负债表!D16-资产负债表!E16 -> 0
B20: 处置固定资产、无形资产和其他长期资产所收回的现金净额 | C20: 25 | D20: =表外数据录入!C60 -> 0 | E20: 经营性应收项目的减少（减：增加） | F20: 72 | G20: =(资产负债表!D9+资产负债表!D10+资产负债表!D11+资产负债表!D12+资产负债表!D13+资产负债表!D14+资产负债表!D15)-(资产负债表!E9+资产负债表!E10+资产负债表!E11+资产负债表!E12+资产负债表!E13+资产负债表!E14+资产负债表!E15) -> 44440
B21: 收到的其他与投资活动有关的现金 | C21: 28 | D21: =表外数据录入!C61 -> 0 | E21: 经营性应付项目的增加（减：减少） | F21: 73 | G21: =资产负债表!J8+资产负债表!J9+资产负债表!J10+资产负债表!J11+资产负债表!J12+资产负债表!J13+资产负债表!J14+资产负债表!J15+资产负债表!J16+资产负债表!J17-资产负债表!I8-资产负债表!I9-资产负债表!I10-资产负债表!I11-资产负债表!I12-资产负债表!I13-资产负债表!I14-资产负债表!I15-资产负债表!I16-资产负债表!I17 -> -888985
B22: 现金流入小计 | C22: 29 | D22: =SUM(D18:D21) -> 0 | E22: 其他 | F22: 74 | G22: =D16-G7-G8-G9-G10-G11-G12-G13-G14-G15-G16-G17-G18-G19-G20-G21 -> 0
B23: 购建固定资产、无形资产和其他长期资产所支付的现金 | C23: 30 | D23: =资产负债表!E26+资产负债表!E31+资产负债表!E32+资产负债表!E39-资产负债表!D26-资产负债表!D31-资产负债表!D32-资产负债表!D39 -> 3100843 | E23: 经营活动产生的现金流量净额 | F23: 75 | G23: =SUM(G7:G22) -> -5676187
B24: 投资所支付的现金 | C24: 31 | D24: =IF((资产负债表!E8+资产负债表!E24-资产负债表!D8-资产负债表!D24)<0," ",资产负债表!E8+资产负债表!E24-资产负债表!D8-资产负债表!D24) -> 0
B25: 支付的其他与投资活动有关的现金 | C25: 35 | D25: =表外数据录入!C62 -> 0
B26: 现金流出小计 | C26: 36 | D26: =SUM(D23:D25) -> 3100843
B27: 投资活动产生的现金流量净额 | C27: 37 | D27: =D22-D26 -> -3100843 | E27: 2、不涉及现金收支的投资和筹资活动：
B28: 三、筹资活动产生的现金流量： | E28: 债务转为资本 | F28: 76
B29: 吸收投资所收到的现金 | C29: 38 | D29: =资产负债表!J35-资产负债表!I35 -> 14600000 | E29: 一年内到期的可转换公司债券 | F29: 77
B30: 取得借款所收到的现金 | C30: 40 | D30: =IF((资产负债表!J7+资产负债表!J29-资产负债表!I7-资产负债表!I29)<0," ",资产负债表!J7+资产负债表!J29-资产负债表!I7-资产负债表!I29) -> 0 | E30: 融资租入固定资产 | F30: 78
B31: 收到的其他与筹资活动有关的现金 | C31: 43 | D31: =表外数据录入!C63 -> 0
B32: 现金流入小计 | C32: 44 | D32: =SUM(D29:D31) -> 14600000
B33: 偿还债务所支付的现金 | C33: 45 | D33: =IF((资产负债表!J7+资产负债表!J29-资产负债表!I7-资产负债表!I29)<0,ABS(资产负债表!J7+资产负债表!J29-资产负债表!I7-资产负债表!I29)," ")
B34: 分配股利、利润和偿付利息所支付的现金 | C34: 46 | D34: =表外数据录入!C38 -> 0 | E34: 3、现金及现金等价物净增加情况
B35: 支付的其他与筹资活动有关的现金 | C35: 52 | D35: =表外数据录入!C64 -> 0 | E35: 现金的期未余额 | F35: 79 | G35: =资产负债表!E7 -> 5822970
B36: 现金流出小计 | C36: 53 | D36: =SUM(D33:D35) -> 0 | E36: 减：现金的期初余额 | F36: 80 | G36: =资产负债表!D7 -> 0
B37: 筹资活动产生的现金流量净额 | C37: 54 | D37: =D32-D36 -> 14600000 | E37: 加：现金等价物的期未余额 | F37: 81
B38: 四、汇率变动对现金的影响 | C38: 55 | E38: 减：现金等价物的期初余额 | F38: 82
B39: 五、现金及现金等价物净增加额 | C39: 56 | D39: =D16+D27+D37+D38 -> 5822970 | E39: 现金及现金等价物净增加额 | F39: 83 | G39: =G35-G36+G37-G38 -> 5822970
B40: 加：期初现金及现金等价物余额
B41: 六、期末现金及现金等价物余额
B43: ="企业负责人："&基础信息!D6 -> 企业负责人： | C43: ="主管会计："&基础信息!D7 -> 主管会计： | E43: ="制表："&基础信息!D9 -> 制表： | F43: ="报送日期："&基础信息!D5 -> 报送日期：46022

Sheet 丁字账
A1: =B2&J2&"财务丁字账" -> XIN SHENG2025年12月财务丁字账 | HM1: 科目余额表 | HU1: 资 产 负 债 表 | IF1: 损 益 表 | IL1: 账结法
A2: 公司名称： | B2: =基础信息!D3 -> XIN SHENG | H2: 财务期间： | J2: =TEXT(基础信息!D4,"yyyy年m月") -> 2025年12月 | R2: 目录!B1 | HM2: 编制单位： | HN2: =B2 -> XIN SHENG | HO2: 财务期间： | HP2: =J2 -> 2025年12月 | HS2: 单位：元 | HU2: 编制单位： | HV2: =B2 -> XIN SHENG | HY2: 填表日期：2010年1月1日 | IA2: ="所属期："&J2 -> 所属期：2025年12月 | ID2: 单位：元 | IF2: 编制单位： | IG2: =HV2 -> XIN SHENG | IH2: =HY2 -> 填表日期：2010年1月1日 | II2: =IA2 -> 所属期：2025年12月 | IK2: 单位：元 | IN2: xwchen
A3: 注：本表为丁字账单独工作表，与其他表格无公式链接关系，另紧接丁字账后面附有相关财务报表，报表数据自动生成。（本表仅供部分还需手工汇总科目的财务人员参考使用）
A4: 科目代码 | B4: 科目名称 | E4: 现金 | H4: 银行存款 | K4: 其他货币资金 | N4: 短期投资 | Q4: 应收票据 | T4: 应收账款 | W4: 预付账款 | Z4: 应收股利 | AC4: 应收利息 | AF4: 其他应收款 | AI4: 坏账准备 | AL4: 物资采购 | AO4: 在途物资 | AR4: 原材料 | AU4: 材料成本差异 | AX4: 库存商品 | BA4: 分期收款发出商品 | BD4: 商品进销差价 | BG4: 委托加工物资 | BJ4: 包装物、低值易耗品 | BM4: 存货跌价准备 | BP4: 长期股权投资 | BS4: 长期投资减值准备 | BV4: 长期应收款 | BY4: 固定资产 | CB4: 累计折旧 | CE4: 固定资产减值准备 | CH4: 在建工程 | CK4: 工程物资 | CN4: 固定资产清理 | CQ4: 无形资产 | CT4: 无形资产减值准备 | CW4: 长期待摊费用 | CZ4: 递延所得税 | DC4: 待处理财产损溢 | DF4: 短期借款 | DI4: 应付票据 | DL4: 应付账款 | DO4: 预收账款 | DR4: 应付工资 | DU4: 应交税金 | DX4: 应付利息 | EA4: 应付股利 | ED4: 其他应付款 | EG4: 长期借款 | EJ4: 应付债券 | EM4: 长期应付款 | EP4: 专项应付款 | ES4: 预计负债 | EV4: 递延长税款 | EY4: 实收资本(股本) | FB4: 资本公积 | FE4: 盈余公积 | FH4: 本年利润 | FK4: 利润分配 | FN4: 生产成本 | FQ4: 制造费用 | FT4: 劳务成本 | FW4: 主营业务收入 | FZ4: 利息收入 | GC4: 其他业务收入 | GF4: 投资收益 | GI4: 营业外收入 | GL4: 主营业务成本 | GO4: 其他业务支出 | GR4: 主营业务税金及附加 | GU4: 营业费用 | GX4: 管理费用 | HA4: 财务费用 | HD4: 营业外支出 | HG4: 所得税 | HJ4: 以前年度损益调整 | HM4: 科目代码 | HN4: 科目名称 | HO4: 期初余额 | HP4: 本期发生额 | HR4: 方向 | HS4: 期末余额 | HU4: 资产 | HW4: 行次 | HX4: 年初数 | HY4: 期末数 | HZ4: 负债和所有者权益 (或股东权益) | IB4: 行次 | IC4: 年初数 | ID4: 期末数 | IF4: 项目 | II4: 行次 | IJ4: 本月数 | IK4: 本年累计数
E5: 借方 | F5: 贷方 | H5: 借方 | I5: 贷方 | K5: 借方 | L5: 贷方 | N5: 借方 | O5: 贷方 | Q5: 借方 | R5: 贷方 | T5: 借方 | U5: 贷方 | W5: 借方 | X5: 贷方 | Z5: 借方 | AA5: 贷方 | AC5: 借方 | AD5: 贷方 | AF5: 借方 | AG5: 贷方 | AI5: 借方 | AJ5: 贷方 | AL5: 借方 | AM5: 贷方 | AO5: 借方 | AP5: 贷方 | AR5: 借方 | AS5: 贷方 | AU5: 借方 | AV5: 贷方 | AX5: 借方 | AY5: 贷方 | BA5: 借方 | BB5: 贷方 | BD5: 借方 | BE5: 贷方 | BG5: 借方 | BH5: 贷方 | BJ5: 借方 | BK5: 贷方 | BM5: 借方 | BN5: 贷方 | BP5: 借方 | BQ5: 贷方 | BS5: 借方 | BT5: 贷方 | BV5: 借方 | BW5: 贷方 | BY5: 借方 | BZ5: 贷方 | CB5: 借方 | CC5: 贷方 | CE5: 借方 | CF5: 贷方 | CH5: 借方 | CI5: 贷方 | CK5: 借方 | CL5: 贷方 | CN5: 借方 | CO5: 贷方 | CQ5: 借方 | CR5: 贷方 | CT5: 借方 | CU5: 贷方 | CW5: 借方 | CX5: 贷方 | CZ5: 借方 | DA5: 贷方 | DC5: 借方 | DD5: 贷方 | DF5: 借方 | DG5: 贷方 | DI5: 借方 | DJ5: 贷方 | DL5: 借方 | DM5: 贷方 | DO5: 借方 | DP5: 贷方 | DR5: 借方 | DS5: 贷方 | DU5: 借方 | DV5: 贷方 | DX5: 借方 | DY5: 贷方 | EA5: 借方 | EB5: 贷方 | ED5: 借方 | EE5: 贷方 | EG5: 借方 | EH5: 贷方 | EJ5: 借方 | EK5: 贷方 | EM5: 借方 | EN5: 贷方 | EP5: 借方 | EQ5: 贷方 | ES5: 借方 | ET5: 贷方 | EV5: 借方 | EW5: 贷方 | EY5: 借方 | EZ5: 贷方 | FB5: 借方 | FC5: 贷方 | FE5: 借方 | FF5: 贷方 | FH5: 借方 | FI5: 贷方 | FK5: 借方 | FL5: 贷方 | FN5: 借方 | FO5: 贷方 | FQ5: 借方 | FR5: 贷方 | FT5: 借方 | FU5: 贷方 | FW5: 借方 | FX5: 贷方 | FZ5: 借方 | GA5: 贷方 | GC5: 借方 | GD5: 贷方 | GF5: 借方 | GG5: 贷方 | GI5: 借方 | GJ5: 贷方 | GL5: 借方 | GM5: 贷方 | GO5: 借方 | GP5: 贷方 | GR5: 借方 | GS5: 贷方 | GU5: 借方 | GV5: 贷方 | GX5: 借方 | GY5: 贷方 | HA5: 借方 | HB5: 贷方 | HD5: 借方 | HE5: 贷方 | HG5: 借方 | HH5: 贷方 | HJ5: 借方 | HK5: 贷方 | HP5: 借方 | HQ5: 贷方
A6: 1001 | B6: 现金 | E6: 1000 | I6: 5000 | U6: 8000 | AR6: 10000 | BY6: 5000 | DG6: 10000 | DL6: 2000 | EG6: 5000 | EZ6: 10000 | HM6: 1001 | HN6: 现金 | HO6: 500 | HP6: =E$101 -> 1000 | HQ6: =F$101 -> 0 | HR6: 借 | HS6: =IF(HR6="借",HO6+HP6-HQ6,HO6+HQ6-HP6) -> 1500 | HU6: 流动资产： | HZ6: 流动负债： | IF6: 一、主营业务收入 | II6: 1 | IJ6: =HQ64 -> 0
A7: 1002 | B7: 银行存款 | H7: 8000 | U7: 6000 | DF7: 8000 | EZ7: 5000 | HM7: 1002 | HN7: 银行存款 | HO7: 10000 | HP7: =H$101 -> 23000 | HQ7: =I$101 -> 15000 | HR7: 借 | HS7: =IF(HR7="借",HO7+HP7-HQ7,HO7+HQ7-HP7) -> 18000 | HU7: 货币资金 | HW7: 1 | HY7: =HS6+HS7+HS8 -> 19500 | HZ7: 短期借款 | IB7: 68 | ID7: =HS41 -> 7000 | IF7: 减：主营业务成本 | II7: 4 | IJ7: =HP69 -> 0
A8: 1012 | B8: 其他货币资金 | H8: 10000 | HM8: 1012 | HN8: 其他货币资金 | HP8: =K$101 -> 0 | HQ8: =L$101 -> 0 | HR8: 借 | HS8: =IF(HR8="借",HO8+HP8-HQ8,HO8+HQ8-HP8) -> 0 | HU8: 短期投资 | HW8: 2 | HY8: =HS9 -> 0 | HZ8: 应付票据 | IB8: 69 | ID8: =HS42 -> 0 | IF8: 主营业务税金及附加 | II8: 5 | IJ8: =HP71 -> 0
A9: 1101 | B9: 短期投资 | H9: 5000 | HM9: 1101 | HN9: 短期投资 | HP9: =N$101 -> 0 | HQ9: =O$101 -> 0 | HR9: 借 | HS9: =IF(HR9="借",HO9+HP9-HQ9,HO9+HQ9-HP9) -> 0 | HU9: 应收票据 | HW9: 3 | HY9: =HS10 -> 0 | HZ9: 应付账款 | IB9: 70 | ID9: =HS43 -> 3000 | IF9: 二、主营业务利润(亏损以“-”号填列) | II9: 10 | IJ9: =IJ6-IJ7-IJ8 -> 0 | IK9: =IK6-IK7-IK8 -> 0
A10: 1121 | B10: 应收票据 | I10: 10000 | HM10: 1121 | HN10: 应收票据 | HP10: =Q$101 -> 0 | HQ10: =R$101 -> 0 | HR10: 借 | HS10: =IF(HR10="借",HO10+HP10-HQ10,HO10+HQ10-HP10) -> 0 | HU10: 应收股利 | HW10: 4 | HY10: =HS13 -> 0 | HZ10: 预收账款 | IB10: 71 | ID10: =HS44 -> 0 | IF10: 加：其他业务利润(亏损以“-”号填列) | II10: 11 | IJ10: =HQ66-HP70 -> 0
A11: 1122 | B11: 应收账款 | HM11: 1122 | HN11: 应收账款 | HO11: 16000 | HP11: =T$101 -> 0 | HQ11: =U$101 -> 14000 | HR11: 借 | HS11: =IF(HR11="借",HO11+HP11-HQ11,HO11+HQ11-HP11) -> 2000 | HU11: 应收利息 | HW11: 5 | HY11: =HS14 -> 0 | HZ11: 应付工资 | IB11: 72 | ID11: =HS45 -> 0 | IF11: 减：营业费用 | II11: 14 | IJ11: =HP72 -> 0
A12: 1123 | B12: 预付账款 | HM12: 1123 | HN12: 预付账款 | HP12: =W$101 -> 0 | HQ12: =X$101 -> 0 | HR12: 借 | HS12: =IF(HR12="借",HO12+HP12-HQ12,HO12+HQ12-HP12) -> 0 | HU12: 应收账款 | HW12: 6 | HY12: =HS11-HS16 -> 2000 | HZ12: 应付福利费 | IB12: 73 | IF12: 管理费用 | II12: 15 | IJ12: =HP73 -> 0
A13: 1131 | B13: 应收股利 | HM13: 1131 | HN13: 应收股利 | HP13: =Z$101 -> 0 | HQ13: =AA$101 -> 0 | HR13: 借 | HS13: =IF(HR13="借",HO13+HP13-HQ13,HO13+HQ13-HP13) -> 0 | HU13: 其他应收款 | HW13: 7 | HY13: =HS15 -> 0 | HZ13: 应付股利 | IB13: 74 | ID13: =HS48 -> 0 | IF13: 财务费用 | II13: 16 | IJ13: =HP74 -> 0
A14: 1132 | B14: 应收利息 | HM14: 1132 | HN14: 应收利息 | HP14: =AC$101 -> 0 | HQ14: =AD$101 -> 0 | HR14: 借 | HS14: =IF(HR14="借",HO14+HP14-HQ14,HO14+HQ14-HP14) -> 0 | HU14: 预付账款 | HW14: 8 | HY14: =HS12 -> 0 | HZ14: 应交税金 | IB14: 75 | ID14: =HS46 -> 0 | IF14: 三、营业利润(亏损以“-”号填列) | II14: 18 | IJ14: =IJ9+IJ10-IJ11-IJ12-IJ13 -> 0 | IK14: =IK9+IK10-IK11-IK12-IK13 -> 0
A15: 1201 | B15: 其他应收款 | HM15: 1201 | HN15: 其他应收款 | HP15: =AF$101 -> 0 | HQ15: =AG$101 -> 0 | HR15: 借 | HS15: =IF(HR15="借",HO15+HP15-HQ15,HO15+HQ15-HP15) -> 0 | HU15: 应收补贴款 | HW15: 9 | HZ15: 其他应交款 | IB15: 80 | IF15: 加：投资收益(亏损以“-”号填列) | II15: 19 | IJ15: =HQ67 -> 0
A16: 1231 | B16: 坏账准备 | HM16: 1231 | HN16: 坏账准备 | HP16: =AI$101 -> 0 | HQ16: =AJ$101 -> 0 | HR16: 贷 | HS16: =IF(HR16="借",HO16+HP16-HQ16,HO16+HQ16-HP16) -> 0 | HU16: 存货 | HW16: 10 | HY16: =SUM(HS17:HS25)-HS26 -> 22000 | HZ16: 其他应付款 | IB16: 81 | ID16: =HS49 -> 0 | IF16: 补贴收入 | II16: 22
A17: 1401 | B17: 物资采购 | HM17: 1401 | HN17: 物资采购 | HP17: =AL$101 -> 0 | HQ17: =AM$101 -> 0 | HR17: 借 | HS17: =IF(HR17="借",HO17+HP17-HQ17,HO17+HQ17-HP17) -> 0 | HU17: 待摊费用 | HW17: 11 | HZ17: 预提费用 | IB17: 82 | IF17: 营业外收入 | II17: 23 | IJ17: =HQ68 -> 0
A18: 1402 | B18: 在途物资 | HM18: 1402 | HN18: 在途物资 | HP18: =AO$101 -> 0 | HQ18: =AP$101 -> 0 | HR18: 借 | HS18: =IF(HR18="借",HO18+HP18-HQ18,HO18+HQ18-HP18) -> 0 | HU18: 一年内到期的长期债券投资 | HW18: 21 | HZ18: 预计负债 | IB18: 83 | ID18: =HS54 -> 0 | IF18: 减：营业外支出 | II18: 25 | IJ18: =HP75 -> 0
A19: 1403 | B19: 原材料 | HM19: 1403 | HN19: 原材料 | HO19: 12000 | HP19: =AR$101 -> 10000 | HQ19: =AS$101 -> 0 | HR19: 借 | HS19: =IF(HR19="借",HO19+HP19-HQ19,HO19+HQ19-HP19) -> 22000 | HU19: 其他流动资产 | HW19: 24 | HZ19: 一年内到期的长期负债 | IB19: 86 | IF19: 加：以前年度损益调整 | II19: 26 | IJ19: =HP77 -> 0
A20: 1404 | B20: 材料成本差异 | HM20: 1404 | HN20: 材料成本差异 | HP20: =AU$101 -> 0 | HQ20: =AV$101 -> 0 | HR20: 借 | HS20: =IF(HR20="借",HO20+HP20-HQ20,HO20+HQ20-HP20) -> 0 | HU20: 流动资产合计 | HW20: 31 | HX20: =SUM(HX7:HX19) -> 0 | HY20: =SUM(HY7:HY19) -> 43500 | HZ20: 其他流动负债 | IB20: 90 | IF20: 四、利润总额(亏损以“-”号填列) | II20: 27 | IJ20: =IJ14+IJ15+IJ16+IJ17-IJ18 -> 0 | IK20: =IK14+IK15+IK16+IK17-IK18 -> 0
A21: 1405 | B21: 库存商品 | HM21: 1405 | HN21: 库存商品 | HP21: =AX$101 -> 0 | HQ21: =AY$101 -> 0 | HR21: 借 | HS21: =IF(HR21="借",HO21+HP21-HQ21,HO21+HQ21-HP21) -> 0 | HU21: 长期资产： | IF21: 减：所得税 | II21: 28 | IJ21: =HP76 -> 0
A22: 1406 | B22: 分期收款发出商品 | HM22: 1406 | HN22: 分期收款发出商品 | HP22: =BA$101 -> 0 | HQ22: =BB$101 -> 0 | HR22: 借 | HS22: =IF(HR22="借",HO22+HP22-HQ22,HO22+HQ22-HP22) -> 0 | HU22: 长期股权投资 | HW22: 32 | HY22: =HS27 -> 0 | HZ22: 流动负债合计 | IB22: 100 | IC22: =SUM(IC7:IC21) -> 0 | ID22: =SUM(ID7:ID21) -> 10000 | IF22: 五、净利润(亏损以“-”号填列) | II22: 30 | IJ22: =IJ20-IJ21 -> 0 | IK22: =IK20-IK21 -> 0
A23: 1407 | B23: 商品进销差价 | HM23: 1407 | HN23: 商品进销差价 | HP23: =BD$101 -> 0 | HQ23: =BE$101 -> 0 | HR23: 借 | HS23: =IF(HR23="借",HO23+HP23-HQ23,HO23+HQ23-HP23) -> 0 | HU23: 长期债券投资 | HW23: 34 | HZ23: 长期负债：
A24: 1408 | B24: 委托加工物资 | HM24: 1408 | HN24: 委托加工物资 | HP24: =BG$101 -> 0 | HQ24: =BH$101 -> 0 | HR24: 借 | HS24: =IF(HR24="借",HO24+HP24-HQ24,HO24+HQ24-HP24) -> 0 | HU24: 长期投资合计 | HW24: 38 | HX24: =SUM(HX22:HX23) -> 0 | HY24: =SUM(HY22:HY23) -> 0 | HZ24: 长期借款 | IB24: 101 | ID24: =HS50 -> 5000 | IF24: 补充资料
A25: 1411 | B25: 包装物、低值易耗品 | HM25: 1411 | HN25: 包装物、低值易耗品 | HP25: =BJ$101 -> 0 | HQ25: =BK$101 -> 0 | HR25: 借 | HS25: =IF(HR25="借",HO25+HP25-HQ25,HO25+HQ25-HP25) -> 0 | HU25: 固定资产： | HZ25: 应付债券 | IB25: 102 | ID25: =HS51 -> 0
A26: 1471 | B26: 存货跌价准备 | HM26: 1471 | HN26: 存货跌价准备 | HP26: =BM$101 -> 0 | HQ26: =BN$101 -> 0 | HR26: 贷 | HS26: =IF(HR26="借",HO26+HP26-HQ26,HO26+HQ26-HP26) -> 0 | HU26: 固定资产原价 | HW26: 39 | HY26: =HS30 -> 36500 | HZ26: 长期应付款 | IB26: 103 | ID26: =HS52 -> 0 | IF26: 项目 | IJ26: 本年累计数 | IK26: 上年实际数
A27: 1511 | B27: 长期股权投资 | HM27: 1511 | HN27: 长期股权投资 | HP27: =BP$101 -> 0 | HQ27: =BQ$101 -> 0 | HR27: 借 | HS27: =IF(HR27="借",HO27+HP27-HQ27,HO27+HQ27-HP27) -> 0 | HU27: 减：累计折旧 | HW27: 40 | HY27: =HS31 -> 0 | HZ27: 专项应付款 | IB27: 106 | ID27: =HS53 -> 0 | IF27: １．出售、处置部分或投资单位所得收益
A28: 1512 | B28: 长期投资减值准备 | HM28: 1512 | HN28: 长期投资减值准备 | HP28: =BS$101 -> 0 | HQ28: =BT$101 -> 0 | HR28: 贷 | HS28: =IF(HR28="借",HO28+HP28-HQ28,HO28+HQ28-HP28) -> 0 | HU28: 固定资产净值 | HW28: 41 | HX28: =HX26-HX27 -> 0 | HY28: =HY26-HY27 -> 36500 | HZ28: 其他长期负债 | IB28: 108 | IF28: ２．自然灾害发生的损失
A29: 1531 | B29: 长期应收款 | HM29: 1531 | HN29: 长期应收款 | HP29: =BV$101 -> 0 | HQ29: =BW$101 -> 0 | HR29: 借 | HS29: =IF(HR29="借",HO29+HP29-HQ29,HO29+HQ29-HP29) -> 0 | HU29: 减：固定资产减值准备 | HW29: 42 | HY29: =HS32 -> 0 | HZ29: 长期负债合计 | IB29: 110 | IC29: =SUM(IC24:IC28) -> 0 | ID29: =SUM(ID24:ID28) -> 5000 | IF29: ３．会计政策变更增加（或减少）利润总额
A30: 1601 | B30: 固定资产 | HM30: 1601 | HN30: 固定资产 | HO30: 31500 | HP30: =BY$101 -> 5000 | HQ30: =BZ$101 -> 0 | HR30: 借 | HS30: =IF(HR30="借",HO30+HP30-HQ30,HO30+HQ30-HP30) -> 36500 | HU30: 固定资产净额 | HW30: 43 | HX30: =HX28-HX29 -> 0 | HY30: =HY28-HY29 -> 36500 | HZ30: 递延税项： | IF30: ４．会计估计变更增加（或减少）利润总额
A31: 1602 | B31: 累计折旧 | HM31: 1602 | HN31: 累计折旧 | HP31: =CB$101 -> 0 | HQ31: =CC$101 -> 0 | HR31: 贷 | HS31: =IF(HR31="借",HO31+HP31-HQ31,HO31+HQ31-HP31) -> 0 | HU31: 工程物资 | HW31: 44 | HY31: =HS34 -> 0 | HZ31: 递延税款贷项 | IB31: 111 | IF31: ５．债务重组损失
A32: 1603 | B32: 固定资产减值准备 | HM32: 1603 | HN32: 固定资产减值准备 | HP32: =CE$101 -> 0 | HQ32: =CF$101 -> 0 | HR32: 贷 | HS32: =IF(HR32="借",HO32+HP32-HQ32,HO32+HQ32-HP32) -> 0 | HU32: 在建工程 | HW32: 45 | HY32: =HS33 -> 0 | HZ32: 负债合计 | IB32: 114 | IC32: =SUM(IC22,IC29,IC31) -> 0 | ID32: =SUM(ID22,ID29,ID31) -> 15000 | IF32: ６．其他
A33: 1604 | B33: 在建工程 | HM33: 1604 | HN33: 在建工程 | HP33: =CH$101 -> 0 | HQ33: =CI$101 -> 0 | HR33: 借 | HS33: =IF(HR33="借",HO33+HP33-HQ33,HO33+HQ33-HP33) -> 0 | HU33: 固定资产清理 | HW33: 46 | HY33: =HS35 -> 0
A34: 1605 | B34: 工程物资 | HM34: 1605 | HN34: 工程物资 | HP34: =CK$101 -> 0 | HQ34: =CL$101 -> 0 | HR34: 借 | HS34: =IF(HR34="借",HO34+HP34-HQ34,HO34+HQ34-HP34) -> 0 | HU34: 固定资产合计 | HW34: 50 | HX34: =SUM(HX30:HX33) -> 0 | HY34: =SUM(HY30:HY33) -> 36500 | HZ34: 所有者权益(或股东权益)： | IF34: 单位负责人： | IH34: 财务负责人： | II34: 复核： | IK34: 制表：
A35: 1606 | B35: 固定资产清理 | HM35: 1606 | HN35: 固定资产清理 | HP35: =CN$101 -> 0 | HQ35: =CO$101 -> 0 | HR35: 借 | HS35: =IF(HR35="借",HO35+HP35-HQ35,HO35+HQ35-HP35) -> 0 | HU35: 无形资产及其他资产： | HZ35: 实收资本(或股本) | IB35: 115 | ID35: =HS56 -> 65000
A36: 1701 | B36: 无形资产 | HM36: 1701 | HN36: 无形资产 | HP36: =CQ$101 -> 0 | HQ36: =CR$101 -> 0 | HR36: 借 | HS36: =IF(HR36="借",HO36+HP36-HQ36,HO36+HQ36-HP36) -> 0 | HU36: 无形资产 | HW36: 51 | HY36: =HS36 -> 0 | HZ36: 减：已归还投资 | IB36: 116
A37: 1703 | B37: 无形资产减值准备 | HM37: 1703 | HN37: 无形资产减值准备 | HP37: =CT$101 -> 0 | HQ37: =CU$101 -> 0 | HR37: 贷 | HS37: =IF(HR37="借",HO37+HP37-HQ37,HO37+HQ37-HP37) -> 0 | HU37: 长期待摊费用 | HW37: 52 | HY37: =HS38 -> 0 | HZ37: 实收资本(或股本)净额 | IB37: 117 | IC37: =IC35-IC36 -> 0 | ID37: =ID35-ID36 -> 65000 | IF37: 附：利润分配表
A38: 1801 | B38: 长期待摊费用 | HM38: 1801 | HN38: 长期待摊费用 | HP38: =CW$101 -> 0 | HQ38: =CX$101 -> 0 | HR38: 借 | HS38: =IF(HR38="借",HO38+HP38-HQ38,HO38+HQ38-HP38) -> 0 | HU38: 其他长期资产 | HW38: 53 | HZ38: 资本公积 | IB38: 118 | ID38: =HS57 -> 0 | IF38: 利润分配表
A39: 1811 | B39: 递延所得税 | HM39: 1811 | HN39: 递延所得税 | HP39: =CZ$101 -> 0 | HQ39: =DA$101 -> 0 | HR39: 借 | HS39: =IF(HR39="借",HO39+HP39-HQ39,HO39+HQ39-HP39) -> 0 | HU39: 无形资产及其他资产合计 | HW39: 60 | HX39: =SUM(HX36:HX38) -> 0 | HY39: =SUM(HY36:HY38) -> 0 | HZ39: 盈余公积 | IB39: 119 | ID39: =HS58 -> 0 | IF39: 编制单位： | IG39: =HV2 -> XIN SHENG | IH39: =YEAR(J2)&"年度" -> 2025年度 | IK39: 单位：元
A40: 1901 | B40: 待处理财产损溢 | HM40: 1901 | HN40: 待处理财产损溢 | HP40: =DC$101 -> 0 | HQ40: =DD$101 -> 0 | HR40: 借 | HS40: =IF(HR40="借",HO40+HP40-HQ40,HO40+HQ40-HP40) -> 0 | HZ40: 其中：法定公益金 | IB40: 120
...

Sheet 使用说明
A1: 使用说明
A2: 1、使用方法：请先录入基础信息、会计科目设置，如需生成现金流量表，需要填上表外数据。然后只需在“凭证录入”表中逐笔录入会计分录，其他表格数据即自动生成（科目余额表期初数、损益表本年累计数请参照表中说明录入，资产负债表年初数需手工输入）。
A3: 2、录入凭证时，请在每行会计分录前输入“凭证号”，会计科目可在下拉菜单中选择或手动输入两种方式，先录总账科目再录明细科目，明细科目会自动根据已录总账科目而调出与之对应的预设明细科目。
A4: 3、所有表中基本上只需填写绿色单元格，填写后自动变色，其余均为公式部分。各表均启用了公式保护，未设密码，如需更改公式，请自行撤销保护，未设密码。
A5: 4、本表设有凭证打印模板，只需输入需要打印的凭证号即自动调出该凭证号的内容，因每张凭证只设了8行分录，所以在录入凭证时请尽量保持每号凭证分录在8行以内，以便打印。若实在要超出8行，如结转类凭证，则打印该凭证时需在凭证模板最后一行分录后插入若干行，再将公式下拉即可，操作前需撤销工作保护。
A6: 5、本表会计科目设置采用旧“企业会计制度”使用科目，所有总账科目均已列入“会计科目”表中，如非必要，请勿修改总账科目，如需修改，则相应报表关联公式也要作相应修改。
A7: 6、明细科目可在总账科目之后自行增减或修改，科目之间不可有空单元格。
A8: 7、资产负债表和损益表的取数公式适用于账结法，录入凭证时需严格按照“科目余额表”中科目借贷方性质录入，否则报表数据将会出错。如：管理费用，科目性质为借方，冲减时不可做在贷方，而应该做借方红字；主营业务收入，科目性质为贷方，冲减时不可做在借方，而应该做贷方红字。
A9: 8、最后附张“丁字账”表，此表与其他表格无公式链接关系，紧接丁字账后面附有相关财务报表，报表数据自动生成。（本丁字账表仅供部分还需手工汇总科目的财务人员参考使用，如无需要，整张“丁字账”工作表隐藏或删除亦可。）
