Workbook

Sheet 首页
A1: 财税代理 · 多公司收支管理 ② 汇总报表（只看，不用录入）
A2: 💡 这本的数都取自【A065-1_流水发票导入.xlsx】（两本放同一个文件夹）。打开时 Excel/WPS 问「是否更新链接 / 启用内容」选「更新」，或者先打开 ① 那本再打开这本，数就是最新的。每张报表顶上的黄格子选公司（或全部）、年份、日期。这本里隐藏的「资金台帐 / 发票导入 / 基础资料 / 往来单位」是取数用的，别改。
A4: 数据到 | B4: =_辅助!$B$2 -> 46279 | C4: 资金台帐 | D4: =_辅助!$B$3&" 笔" -> 27 笔 | E4: 待处理（✗） | F4: =COUNTIF(资金台帐!$X$6:$X$6005,"✗*")&" 笔" -> 7 笔 | G4: 录入表校验 ✗ | H4: =_辅助!$B$1&" 项" -> 2 项
A6: 公司 | B6: 全部 | D6: 年份 | E6: 2026
A8: 本年收入 | B8: 变动利润 | C8: 利润 | D8: 本年新增客户 | E8: 资金余额（现在） | F8: 客户欠款＊ | G8: 欠供应商＊ | H8: 内部往来对不上
A9: =ROUND(SUMIFS(资金台帐!$AB$6:$AB$6005,资金台帐!$U$6:$U$6005,"收入",资金台帐!$O$6:$O$6005,IF($B$6="全部","?*",$B$6),资金台帐!$N$6:$N$6005,">="&DATE($E$6,1,1),资金台帐!$N$6:$N$6005,"<"&DATE($E$6+1,1,1))-SUMIFS(资金台帐!$AC$6:$AC$6005,资金台帐!$U$6:$U$6005,"收入",资金台帐!$O$6:$O$6005,IF($B$6="全部","?*",$B$6),资金台帐!$N$6:$N$6005,">="&DATE($E$6,1,1),资金台帐!$N$6:$N$6005,"<"&DATE($E$6+1,1,1)),2) -> 171000 | B9: =ROUND(SUMIFS(资金台帐!$AB$6:$AB$6005,资金台帐!$U$6:$U$6005,"收入",资金台帐!$O$6:$O$6005,IF($B$6="全部","?*",$B$6),资金台帐!$N$6:$N$6005,">="&DATE($E$6,1,1),资金台帐!$N$6:$N$6005,"<"&DATE($E$6+1,1,1))-SUMIFS(资金台帐!$AC$6:$AC$6005,资金台帐!$U$6:$U$6005,"收入",资金台帐!$O$6:$O$6005,IF($B$6="全部","?*",$B$6),资金台帐!$N$6:$N$6005,">="&DATE($E$6,1,1),资金台帐!$N$6:$N$6005,"<"&DATE($E$6+1,1,1))-(SUMIFS(资金台帐!$AC$6:$AC$6005,资金台帐!$U$6:$U$6005,"变动成本",资金台帐!$O$6:$O$6005,IF($B$6="全部","?*",$B$6),资金台帐!$N$6:$N$6005,">="&DATE($E$6,1,1),资金台帐!$N$6:$N$6005,"<"&DATE($E$6+1,1,1))-SUMIFS(资金台帐!$AB$6:$AB$6005,资金台帐!$U$6:$U$6005,"变动成本",资金台帐!$O$6:$O$6005,IF($B$6="全部","?*",$B$6),资金台帐!$N$6:$N$6005,">="&DATE($E$6,1,1),资金台帐!$N$6:$N$6005,"<"&DATE($E$6+1,1,1))),2) -> 148621.34 | C9: =ROUND(SUMIFS(资金台帐!$AB$6:$AB$6005,资金台帐!$U$6:$U$6005,"收入",资金台帐!$O$6:$O$6005,IF($B$6="全部","?*",$B$6),资金台帐!$N$6:$N$6005,">="&DATE($E$6,1,1),资金台帐!$N$6:$N$6005,"<"&DATE($E$6+1,1,1))-SUMIFS(资金台帐!$AC$6:$AC$6005,资金台帐!$U$6:$U$6005,"收入",资金台帐!$O$6:$O$6005,IF($B$6="全部","?*",$B$6),资金台帐!$N$6:$N$6005,">="&DATE($E$6,1,1),资金台帐!$N$6:$N$6005,"<"&DATE($E$6+1,1,1))-(SUMIFS(资金台帐!$AC$6:$AC$6005,资金台帐!$U$6:$U$6005,"变动成本",资金台帐!$O$6:$O$6005,IF($B$6="全部","?*",$B$6),资金台帐!$N$6:$N$6005,">="&DATE($E$6,1,1),资金台帐!$N$6:$N$6005,"<"&DATE($E$6+1,1,1))-SUMIFS(资金台帐!$AB$6:$AB$6005,资金台帐!$U$6:$U$6005,"变动成本",资金台帐!$O$6:$O$6005,IF($B$6="全部","?*",$B$6),资金台帐!$N$6:$N$6005,">="&DATE($E$6,1,1),资金台帐!$N$6:$N$6005,"<"&DATE($E$6+1,1,1)))-(SUMIFS(资金台帐!$AC$6:$AC$6005,资金台帐!$U$6:$U$6005,"固定成本",资金台帐!$O$6:$O$6005,IF($B$6="全部","?*",$B$6),资金台帐!$N$6:$N$6005,">="&DATE($E$6,1,1),资金台帐!$N$6:$N$6005,"<"&DATE($E$6+1,1,1))-SUMIFS(资金台帐!$AB$6:$AB$6005,资金台帐!$U$6:$U$6005,"固定成本",资金台帐!$O$6:$O$6005,IF($B$6="全部","?*",$B$6),资金台帐!$N$6:$N$6005,">="&DATE($E$6,1,1),资金台帐!$N$6:$N$6005,"<"&DATE($E$6+1,1,1))),2) -> 148621.34 | D9: =COUNTIFS(资金台帐!$T$6:$T$6005,"新增",资金台帐!$AB$6:$AB$6005,">0",资金台帐!$O$6:$O$6005,IF($B$6="全部","?*",$B$6),资金台帐!$N$6:$N$6005,">="&DATE($E$6,1,1),资金台帐!$N$6:$N$6005,"<"&DATE($E$6+1,1,1)) -> 13 | E9: =ROUND(SUMIFS(基础资料!$N$5:$N$24,基础资料!$J$5:$J$24,IF($B$6="全部","?*",$B$6))+SUMIFS(资金台帐!$AD$6:$AD$6005,资金台帐!$O$6:$O$6005,IF($B$6="全部","?*",$B$6)),2) -> 286034.11 | F9: =ROUND(SUMIF(应收应付汇总!$G$6:$G$606,">0"),2) -> 81300 | G9: =ROUND(SUMIF(应收应付汇总!$K$6:$K$606,">0"),2) -> 183.71 | H9: =COUNTIF(内部往来!$B$18:$I$25,"差*")/2+COUNTIF(内部往来!$C$39:$C$46,"✗*") -> 0
A10: 收入、利润、新增客户按上面选的公司和年份；资金余额是所选公司所有账户到现在；＊客户欠款、欠供应商按【应收应付汇总】里选的公司、年份（年底余额，只加正数）；内部往来对不上的看【内部往来】②和最下面。
A12: 表格导航（点表名直接跳过去）
A13: 表名 | B13: 干什么的 | F13: 你要做什么
A14: 收支汇总表 | B14: 「收支类型」× 1～12 月：收入、变动成本、变动利润、固定成本、利润 | F14: 选公司、年份看
A15: 简易现金流量表 | B15: 业务口径的简易现金流量表（经营 / 投资 / 筹资往来），跟账户余额核对 | F15: 选公司、年份看
A16: 资金余额表 | B16: 每个账户期初、收、支、期末，跟银行余额核对 | F16: 选公司、起止日期看
A17: 费用统计 | B17: 收入、各项费用按公司对比 | F17: 选年份、月份范围看
A18: 客户收入统计 | B18: 每月新增客户、新增/续费收入；每个客户首次来款、续费、应收 | F18: 选公司、年份看
A19: 应收应付汇总 | B19: 每个往来单位的应收、应付、其他往来（借款押金） | F19: 选公司、年份看
A20: 往来对账单 | B20: 给某个客户/供应商的对账单：发票、收付款逐笔带余额 | F20: 选公司、单位、起止日期
A21: 内部往来 | B21: 几家公司之间划转的钱谁欠谁、两边对不对得上；自家之间开的票 | F21: 选截止日看
A22: 发票汇总 | B22: 每月销项、进项发票金额，对照同月收付款 | F22: 选公司、年份看

Sheet 收支汇总表
A1: 收 支 汇 总 表（收支类型 × 1～12 月 · 按资金台帐实收实付）
A2: 💡 选公司、年份。行就是「收支类型」：收入 → 变动成本 → 变动利润 → 固定成本 → 利润，下面是其他支出、实收资本、投资、往来。收入类＝收进来减退出去；成本费用类＝付出去减退回来。账户互转、内部公司之间划转不算收入支出（最下面单列）。
B3: 公司 | C3: 全部 | E3: 年份 | F3: 2026
A4: 收支类型 | B4: 项目 | C4: 1月 | D4: 2月 | E4: 3月 | F4: 4月 | G4: 5月 | H4: 6月 | I4: 7月 | J4: 8月 | K4: 9月 | L4: 10月 | M4: 11月 | N4: 12月 | O4: 全年合计 | P4: 占收入 | Q4: 项目名
A5: 收入 | B5: =IF(基础资料!$W$5="",基础资料!$U$5&"",基础资料!$W$5&"") -> 项目 | C5: =ROUND(SUMIFS(资金台帐!$AB$6:$AB$6005,资金台帐!$T$6:$T$6005,$Q5,资金台帐!$U$6:$U$6005,"收入",资金台帐!$O$6:$O$6005,IF($C$3="全部","?*",$C$3),资金台帐!$N$6:$N$6005,">="&DATE($F$3,1,1),资金台帐!$N$6:$N$6005,"<"&DATE($F$3,1+1,1))-SUMIFS(资金台帐!$AC$6:$AC$6005,资金台帐!$T$6:$T$6005,$Q5,资金台帐!$U$6:$U$6005,"收入",资金台帐!$O$6:$O$6005,IF($C$3="全部","?*",$C$3),资金台帐!$N$6:$N$6005,">="&DATE($F$3,1,1),资金台帐!$N$6:$N$6005,"<"&DATE($F$3,1+1,1)),2) -> 0 | D5: =ROUND(SUMIFS(资金台帐!$AB$6:$AB$6005,资金台帐!$T$6:$T$6005,$Q5,资金台帐!$U$6:$U$6005,"收入",资金台帐!$O$6:$O$6005,IF($C$3="全部","?*",$C$3),资金台帐!$N$6:$N$6005,">="&DATE($F$3,2,1),资金台帐!$N$6:$N$6005,"<"&DATE($F$3,2+1,1))-SUMIFS(资金台帐!$AC$6:$AC$6005,资金台帐!$T$6:$T$6005,$Q5,资金台帐!$U$6:$U$6005,"收入",资金台帐!$O$6:$O$6005,IF($C$3="全部","?*",$C$3),资金台帐!$N$6:$N$6005,">="&DATE($F$3,2,1),资金台帐!$N$6:$N$6005,"<"&DATE($F$3,2+1,1)),2) -> 0 | E5: =ROUND(SUMIFS(资金台帐!$AB$6:$AB$6005,资金台帐!$T$6:$T$6005,$Q5,资金台帐!$U$6:$U$6005,"收入",资金台帐!$O$6:$O$6005,IF($C$3="全部","?*",$C$3),资金台帐!$N$6:$N$6005,">="&DATE($F$3,3,1),资金台帐!$N$6:$N$6005,"<"&DATE($F$3,3+1,1))-SUMIFS(资金台帐!$AC$6:$AC$6005,资金台帐!$T$6:$T$6005,$Q5,资金台帐!$U$6:$U$6005,"收入",资金台帐!$O$6:$O$6005,IF($C$3="全部","?*",$C$3),资金台帐!$N$6:$N$6005,">="&DATE($F$3,3,1),资金台帐!$N$6:$N$6005,"<"&DATE($F$3,3+1,1)),2) -> 0 | F5: =ROUND(SUMIFS(资金台帐!$AB$6:$AB$6005,资金台帐!$T$6:$T$6005,$Q5,资金台帐!$U$6:$U$6005,"收入",资金台帐!$O$6:$O$6005,IF($C$3="全部","?*",$C$3),资金台帐!$N$6:$N$6005,">="&DATE($F$3,4,1),资金台帐!$N$6:$N$6005,"<"&DATE($F$3,4+1,1))-SUMIFS(资金台帐!$AC$6:$AC$6005,资金台帐!$T$6:$T$6005,$Q5,资金台帐!$U$6:$U$6005,"收入",资金台帐!$O$6:$O$6005,IF($C$3="全部","?*",$C$3),资金台帐!$N$6:$N$6005,">="&DATE($F$3,4,1),资金台帐!$N$6:$N$6005,"<"&DATE($F$3,4+1,1)),2) -> 0 | G5: =ROUND(SUMIFS(资金台帐!$AB$6:$AB$6005,资金台帐!$T$6:$T$6005,$Q5,资金台帐!$U$6:$U$6005,"收入",资金台帐!$O$6:$O$6005,IF($C$3="全部","?*",$C$3),资金台帐!$N$6:$N$6005,">="&DATE($F$3,5,1),资金台帐!$N$6:$N$6005,"<"&DATE($F$3,5+1,1))-SUMIFS(资金台帐!$AC$6:$AC$6005,资金台帐!$T$6:$T$6005,$Q5,资金台帐!$U$6:$U$6005,"收入",资金台帐!$O$6:$O$6005,IF($C$3="全部","?*",$C$3),资金台帐!$N$6:$N$6005,">="&DATE($F$3,5,1),资金台帐!$N$6:$N$6005,"<"&DATE($F$3,5+1,1)),2) -> 0 | H5: =ROUND(SUMIFS(资金台帐!$AB$6:$AB$6005,资金台帐!$T$6:$T$6005,$Q5,资金台帐!$U$6:$U$6005,"收入",资金台帐!$O$6:$O$6005,IF($C$3="全部","?*",$C$3),资金台帐!$N$6:$N$6005,">="&DATE($F$3,6,1),资金台帐!$N$6:$N$6005,"<"&DATE($F$3,6+1,1))-SUMIFS(资金台帐!$AC$6:$AC$6005,资金台帐!$T$6:$T$6005,$Q5,资金台帐!$U$6:$U$6005,"收入",资金台帐!$O$6:$O$6005,IF($C$3="全部","?*",$C$3),资金台帐!$N$6:$N$6005,">="&DATE($F$3,6,1),资金台帐!$N$6:$N$6005,"<"&DATE($F$3,6+1,1)),2) -> 0 | I5: =ROUND(SUMIFS(资金台帐!$AB$6:$AB$6005,资金台帐!$T$6:$T$6005,$Q5,资金台帐!$U$6:$U$6005,"收入",资金台帐!$O$6:$O$6005,IF($C$3="全部","?*",$C$3),资金台帐!$N$6:$N$6005,">="&DATE($F$3,7,1),资金台帐!$N$6:$N$6005,"<"&DATE($F$3,7+1,1))-SUMIFS(资金台帐!$AC$6:$AC$6005,资金台帐!$T$6:$T$6005,$Q5,资金台帐!$U$6:$U$6005,"收入",资金台帐!$O$6:$O$6005,IF($C$3="全部","?*",$C$3),资金台帐!$N$6:$N$6005,">="&DATE($F$3,7,1),资金台帐!$N$6:$N$6005,"<"&DATE($F$3,7+1,1)),2) -> 0 | J5: =ROUND(SUMIFS(资金台帐!$AB$6:$AB$6005,资金台帐!$T$6:$T$6005,$Q5,资金台帐!$U$6:$U$6005,"收入",资金台帐!$O$6:$O$6005,IF($C$3="全部","?*",$C$3),资金台帐!$N$6:$N$6005,">="&DATE($F$3,8,1),资金台帐!$N$6:$N$6005,"<"&DATE($F$3,8+1,1))-SUMIFS(资金台帐!$AC$6:$AC$6005,资金台帐!$T$6:$T$6005,$Q5,资金台帐!$U$6:$U$6005,"收入",资金台帐!$O$6:$O$6005,IF($C$3="全部","?*",$C$3),资金台帐!$N$6:$N$6005,">="&DATE($F$3,8,1),资金台帐!$N$6:$N$6005,"<"&DATE($F$3,8+1,1)),2) -> 0 | K5: =ROUND(SUMIFS(资金台帐!$AB$6:$AB$6005,资金台帐!$T$6:$T$6005,$Q5,资金台帐!$U$6:$U$6005,"收入",资金台帐!$O$6:$O$6005,IF($C$3="全部","?*",$C$3),资金台帐!$N$6:$N$6005,">="&DATE($F$3,9,1),资金台帐!$N$6:$N$6005,"<"&DATE($F$3,9+1,1))-SUMIFS(资金台帐!$AC$6:$AC$6005,资金台帐!$T$6:$T$6005,$Q5,资金台帐!$U$6:$U$6005,"收入",资金台帐!$O$6:$O$6005,IF($C$3="全部","?*",$C$3),资金台帐!$N$6:$N$6005,">="&DATE($F$3,9,1),资金台帐!$N$6:$N$6005,"<"&DATE($F$3,9+1,1)),2) -> 0 | L5: =ROUND(SUMIFS(资金台帐!$AB$6:$AB$6005,资金台帐!$T$6:$T$6005,$Q5,资金台帐!$U$6:$U$6005,"收入",资金台帐!$O$6:$O$6005,IF($C$3="全部","?*",$C$3),资金台帐!$N$6:$N$6005,">="&DATE($F$3,10,1),资金台帐!$N$6:$N$6005,"<"&DATE($F$3,10+1,1))-SUMIFS(资金台帐!$AC$6:$AC$6005,资金台帐!$T$6:$T$6005,$Q5,资金台帐!$U$6:$U$6005,"收入",资金台帐!$O$6:$O$6005,IF($C$3="全部","?*",$C$3),资金台帐!$N$6:$N$6005,">="&DATE($F$3,10,1),资金台帐!$N$6:$N$6005,"<"&DATE($F$3,10+1,1)),2) -> 0 | M5: =ROUND(SUMIFS(资金台帐!$AB$6:$AB$6005,资金台帐!$T$6:$T$6005,$Q5,资金台帐!$U$6:$U$6005,"收入",资金台帐!$O$6:$O$6005,IF($C$3="全部","?*",$C$3),资金台帐!$N$6:$N$6005,">="&DATE($F$3,11,1),资金台帐!$N$6:$N$6005,"<"&DATE($F$3,11+1,1))-SUMIFS(资金台帐!$AC$6:$AC$6005,资金台帐!$T$6:$T$6005,$Q5,资金台帐!$U$6:$U$6005,"收入",资金台帐!$O$6:$O$6005,IF($C$3="全部","?*",$C$3),资金台帐!$N$6:$N$6005,">="&DATE($F$3,11,1),资金台帐!$N$6:$N$6005,"<"&DATE($F$3,11+1,1)),2) -> 0 | N5: =ROUND(SUMIFS(资金台帐!$AB$6:$AB$6005,资金台帐!$T$6:$T$6005,$Q5,资金台帐!$U$6:$U$6005,"收入",资金台帐!$O$6:$O$6005,IF($C$3="全部","?*",$C$3),资金台帐!$N$6:$N$6005,">="&DATE($F$3,12,1),资金台帐!$N$6:$N$6005,"<"&DATE($F$3,12+1,1))-SUMIFS(资金台帐!$AC$6:$AC$6005,资金台帐!$T$6:$T$6005,$Q5,资金台帐!$U$6:$U$6005,"收入",资金台帐!$O$6:$O$6005,IF($C$3="全部","?*",$C$3),资金台帐!$N$6:$N$6005,">="&DATE($F$3,12,1),资金台帐!$N$6:$N$6005,"<"&DATE($F$3,12+1,1)),2) -> 0 | O5: =ROUND(SUM(C5:N5),2) -> 0 | P5: =IF(N($O$16)=0,"",O5/$O$16) -> 0 | Q5: =基础资料!$U$5&"" -> 项目
B6: =IF(基础资料!$W$6="",基础资料!$U$6&"",基础资料!$W$6&"") -> 续费 | C6: =ROUND(SUMIFS(资金台帐!$AB$6:$AB$6005,资金台帐!$T$6:$T$6005,$Q6,资金台帐!$U$6:$U$6005,"收入",资金台帐!$O$6:$O$6005,IF($C$3="全部","?*",$C$3),资金台帐!$N$6:$N$6005,">="&DATE($F$3,1,1),资金台帐!$N$6:$N$6005,"<"&DATE($F$3,1+1,1))-SUMIFS(资金台帐!$AC$6:$AC$6005,资金台帐!$T$6:$T$6005,$Q6,资金台帐!$U$6:$U$6005,"收入",资金台帐!$O$6:$O$6005,IF($C$3="全部","?*",$C$3),资金台帐!$N$6:$N$6005,">="&DATE($F$3,1,1),资金台帐!$N$6:$N$6005,"<"&DATE($F$3,1+1,1)),2) -> 0 | D6: =ROUND(SUMIFS(资金台帐!$AB$6:$AB$6005,资金台帐!$T$6:$T$6005,$Q6,资金台帐!$U$6:$U$6005,"收入",资金台帐!$O$6:$O$6005,IF($C$3="全部","?*",$C$3),资金台帐!$N$6:$N$6005,">="&DATE($F$3,2,1),资金台帐!$N$6:$N$6005,"<"&DATE($F$3,2+1,1))-SUMIFS(资金台帐!$AC$6:$AC$6005,资金台帐!$T$6:$T$6005,$Q6,资金台帐!$U$6:$U$6005,"收入",资金台帐!$O$6:$O$6005,IF($C$3="全部","?*",$C$3),资金台帐!$N$6:$N$6005,">="&DATE($F$3,2,1),资金台帐!$N$6:$N$6005,"<"&DATE($F$3,2+1,1)),2) -> 0 | E6: =ROUND(SUMIFS(资金台帐!$AB$6:$AB$6005,资金台帐!$T$6:$T$6005,$Q6,资金台帐!$U$6:$U$6005,"收入",资金台帐!$O$6:$O$6005,IF($C$3="全部","?*",$C$3),资金台帐!$N$6:$N$6005,">="&DATE($F$3,3,1),资金台帐!$N$6:$N$6005,"<"&DATE($F$3,3+1,1))-SUMIFS(资金台帐!$AC$6:$AC$6005,资金台帐!$T$6:$T$6005,$Q6,资金台帐!$U$6:$U$6005,"收入",资金台帐!$O$6:$O$6005,IF($C$3="全部","?*",$C$3),资金台帐!$N$6:$N$6005,">="&DATE($F$3,3,1),资金台帐!$N$6:$N$6005,"<"&DATE($F$3,3+1,1)),2) -> 0 | F6: =ROUND(SUMIFS(资金台帐!$AB$6:$AB$6005,资金台帐!$T$6:$T$6005,$Q6,资金台帐!$U$6:$U$6005,"收入",资金台帐!$O$6:$O$6005,IF($C$3="全部","?*",$C$3),资金台帐!$N$6:$N$6005,">="&DATE($F$3,4,1),资金台帐!$N$6:$N$6005,"<"&DATE($F$3,4+1,1))-SUMIFS(资金台帐!$AC$6:$AC$6005,资金台帐!$T$6:$T$6005,$Q6,资金台帐!$U$6:$U$6005,"收入",资金台帐!$O$6:$O$6005,IF($C$3="全部","?*",$C$3),资金台帐!$N$6:$N$6005,">="&DATE($F$3,4,1),资金台帐!$N$6:$N$6005,"<"&DATE($F$3,4+1,1)),2) -> 0 | G6: =ROUND(SUMIFS(资金台帐!$AB$6:$AB$6005,资金台帐!$T$6:$T$6005,$Q6,资金台帐!$U$6:$U$6005,"收入",资金台帐!$O$6:$O$6005,IF($C$3="全部","?*",$C$3),资金台帐!$N$6:$N$6005,">="&DATE($F$3,5,1),资金台帐!$N$6:$N$6005,"<"&DATE($F$3,5+1,1))-SUMIFS(资金台帐!$AC$6:$AC$6005,资金台帐!$T$6:$T$6005,$Q6,资金台帐!$U$6:$U$6005,"收入",资金台帐!$O$6:$O$6005,IF($C$3="全部","?*",$C$3),资金台帐!$N$6:$N$6005,">="&DATE($F$3,5,1),资金台帐!$N$6:$N$6005,"<"&DATE($F$3,5+1,1)),2) -> 0 | H6: =ROUND(SUMIFS(资金台帐!$AB$6:$AB$6005,资金台帐!$T$6:$T$6005,$Q6,资金台帐!$U$6:$U$6005,"收入",资金台帐!$O$6:$O$6005,IF($C$3="全部","?*",$C$3),资金台帐!$N$6:$N$6005,">="&DATE($F$3,6,1),资金台帐!$N$6:$N$6005,"<"&DATE($F$3,6+1,1))-SUMIFS(资金台帐!$AC$6:$AC$6005,资金台帐!$T$6:$T$6005,$Q6,资金台帐!$U$6:$U$6005,"收入",资金台帐!$O$6:$O$6005,IF($C$3="全部","?*",$C$3),资金台帐!$N$6:$N$6005,">="&DATE($F$3,6,1),资金台帐!$N$6:$N$6005,"<"&DATE($F$3,6+1,1)),2) -> 0 | I6: =ROUND(SUMIFS(资金台帐!$AB$6:$AB$6005,资金台帐!$T$6:$T$6005,$Q6,资金台帐!$U$6:$U$6005,"收入",资金台帐!$O$6:$O$6005,IF($C$3="全部","?*",$C$3),资金台帐!$N$6:$N$6005,">="&DATE($F$3,7,1),资金台帐!$N$6:$N$6005,"<"&DATE($F$3,7+1,1))-SUMIFS(资金台帐!$AC$6:$AC$6005,资金台帐!$T$6:$T$6005,$Q6,资金台帐!$U$6:$U$6005,"收入",资金台帐!$O$6:$O$6005,IF($C$3="全部","?*",$C$3),资金台帐!$N$6:$N$6005,">="&DATE($F$3,7,1),资金台帐!$N$6:$N$6005,"<"&DATE($F$3,7+1,1)),2) -> 0 | J6: =ROUND(SUMIFS(资金台帐!$AB$6:$AB$6005,资金台帐!$T$6:$T$6005,$Q6,资金台帐!$U$6:$U$6005,"收入",资金台帐!$O$6:$O$6005,IF($C$3="全部","?*",$C$3),资金台帐!$N$6:$N$6005,">="&DATE($F$3,8,1),资金台帐!$N$6:$N$6005,"<"&DATE($F$3,8+1,1))-SUMIFS(资金台帐!$AC$6:$AC$6005,资金台帐!$T$6:$T$6005,$Q6,资金台帐!$U$6:$U$6005,"收入",资金台帐!$O$6:$O$6005,IF($C$3="全部","?*",$C$3),资金台帐!$N$6:$N$6005,">="&DATE($F$3,8,1),资金台帐!$N$6:$N$6005,"<"&DATE($F$3,8+1,1)),2) -> 0 | K6: =ROUND(SUMIFS(资金台帐!$AB$6:$AB$6005,资金台帐!$T$6:$T$6005,$Q6,资金台帐!$U$6:$U$6005,"收入",资金台帐!$O$6:$O$6005,IF($C$3="全部","?*",$C$3),资金台帐!$N$6:$N$6005,">="&DATE($F$3,9,1),资金台帐!$N$6:$N$6005,"<"&DATE($F$3,9+1,1))-SUMIFS(资金台帐!$AC$6:$AC$6005,资金台帐!$T$6:$T$6005,$Q6,资金台帐!$U$6:$U$6005,"收入",资金台帐!$O$6:$O$6005,IF($C$3="全部","?*",$C$3),资金台帐!$N$6:$N$6005,">="&DATE($F$3,9,1),资金台帐!$N$6:$N$6005,"<"&DATE($F$3,9+1,1)),2) -> 0 | L6: =ROUND(SUMIFS(资金台帐!$AB$6:$AB$6005,资金台帐!$T$6:$T$6005,$Q6,资金台帐!$U$6:$U$6005,"收入",资金台帐!$O$6:$O$6005,IF($C$3="全部","?*",$C$3),资金台帐!$N$6:$N$6005,">="&DATE($F$3,10,1),资金台帐!$N$6:$N$6005,"<"&DATE($F$3,10+1,1))-SUMIFS(资金台帐!$AC$6:$AC$6005,资金台帐!$T$6:$T$6005,$Q6,资金台帐!$U$6:$U$6005,"收入",资金台帐!$O$6:$O$6005,IF($C$3="全部","?*",$C$3),资金台帐!$N$6:$N$6005,">="&DATE($F$3,10,1),资金台帐!$N$6:$N$6005,"<"&DATE($F$3,10+1,1)),2) -> 0 | M6: =ROUND(SUMIFS(资金台帐!$AB$6:$AB$6005,资金台帐!$T$6:$T$6005,$Q6,资金台帐!$U$6:$U$6005,"收入",资金台帐!$O$6:$O$6005,IF($C$3="全部","?*",$C$3),资金台帐!$N$6:$N$6005,">="&DATE($F$3,11,1),资金台帐!$N$6:$N$6005,"<"&DATE($F$3,11+1,1))-SUMIFS(资金台帐!$AC$6:$AC$6005,资金台帐!$T$6:$T$6005,$Q6,资金台帐!$U$6:$U$6005,"收入",资金台帐!$O$6:$O$6005,IF($C$3="全部","?*",$C$3),资金台帐!$N$6:$N$6005,">="&DATE($F$3,11,1),资金台帐!$N$6:$N$6005,"<"&DATE($F$3,11+1,1)),2) -> 0 | N6: =ROUND(SUMIFS(资金台帐!$AB$6:$AB$6005,资金台帐!$T$6:$T$6005,$Q6,资金台帐!$U$6:$U$6005,"收入",资金台帐!$O$6:$O$6005,IF($C$3="全部","?*",$C$3),资金台帐!$N$6:$N$6005,">="&DATE($F$3,12,1),资金台帐!$N$6:$N$6005,"<"&DATE($F$3,12+1,1))-SUMIFS(资金台帐!$AC$6:$AC$6005,资金台帐!$T$6:$T$6005,$Q6,资金台帐!$U$6:$U$6005,"收入",资金台帐!$O$6:$O$6005,IF($C$3="全部","?*",$C$3),资金台帐!$N$6:$N$6005,">="&DATE($F$3,12,1),资金台帐!$N$6:$N$6005,"<"&DATE($F$3,12+1,1)),2) -> 0 | O6: =ROUND(SUM(C6:N6),2) -> 0 | P6: =IF(N($O$16)=0,"",O6/$O$16) -> 0 | Q6: =基础资料!$U$6&"" -> 续费
B7: =IF(基础资料!$W$7="",基础资料!$U$7&"",基础资料!$W$7&"") -> 新增 | C7: =ROUND(SUMIFS(资金台帐!$AB$6:$AB$6005,资金台帐!$T$6:$T$6005,$Q7,资金台帐!$U$6:$U$6005,"收入",资金台帐!$O$6:$O$6005,IF($C$3="全部","?*",$C$3),资金台帐!$N$6:$N$6005,">="&DATE($F$3,1,1),资金台帐!$N$6:$N$6005,"<"&DATE($F$3,1+1,1))-SUMIFS(资金台帐!$AC$6:$AC$6005,资金台帐!$T$6:$T$6005,$Q7,资金台帐!$U$6:$U$6005,"收入",资金台帐!$O$6:$O$6005,IF($C$3="全部","?*",$C$3),资金台帐!$N$6:$N$6005,">="&DATE($F$3,1,1),资金台帐!$N$6:$N$6005,"<"&DATE($F$3,1+1,1)),2) -> 0 | D7: =ROUND(SUMIFS(资金台帐!$AB$6:$AB$6005,资金台帐!$T$6:$T$6005,$Q7,资金台帐!$U$6:$U$6005,"收入",资金台帐!$O$6:$O$6005,IF($C$3="全部","?*",$C$3),资金台帐!$N$6:$N$6005,">="&DATE($F$3,2,1),资金台帐!$N$6:$N$6005,"<"&DATE($F$3,2+1,1))-SUMIFS(资金台帐!$AC$6:$AC$6005,资金台帐!$T$6:$T$6005,$Q7,资金台帐!$U$6:$U$6005,"收入",资金台帐!$O$6:$O$6005,IF($C$3="全部","?*",$C$3),资金台帐!$N$6:$N$6005,">="&DATE($F$3,2,1),资金台帐!$N$6:$N$6005,"<"&DATE($F$3,2+1,1)),2) -> 0 | E7: =ROUND(SUMIFS(资金台帐!$AB$6:$AB$6005,资金台帐!$T$6:$T$6005,$Q7,资金台帐!$U$6:$U$6005,"收入",资金台帐!$O$6:$O$6005,IF($C$3="全部","?*",$C$3),资金台帐!$N$6:$N$6005,">="&DATE($F$3,3,1),资金台帐!$N$6:$N$6005,"<"&DATE($F$3,3+1,1))-SUMIFS(资金台帐!$AC$6:$AC$6005,资金台帐!$T$6:$T$6005,$Q7,资金台帐!$U$6:$U$6005,"收入",资金台帐!$O$6:$O$6005,IF($C$3="全部","?*",$C$3),资金台帐!$N$6:$N$6005,">="&DATE($F$3,3,1),资金台帐!$N$6:$N$6005,"<"&DATE($F$3,3+1,1)),2) -> 0 | F7: =ROUND(SUMIFS(资金台帐!$AB$6:$AB$6005,资金台帐!$T$6:$T$6005,$Q7,资金台帐!$U$6:$U$6005,"收入",资金台帐!$O$6:$O$6005,IF($C$3="全部","?*",$C$3),资金台帐!$N$6:$N$6005,">="&DATE($F$3,4,1),资金台帐!$N$6:$N$6005,"<"&DATE($F$3,4+1,1))-SUMIFS(资金台帐!$AC$6:$AC$6005,资金台帐!$T$6:$T$6005,$Q7,资金台帐!$U$6:$U$6005,"收入",资金台帐!$O$6:$O$6005,IF($C$3="全部","?*",$C$3),资金台帐!$N$6:$N$6005,">="&DATE($F$3,4,1),资金台帐!$N$6:$N$6005,"<"&DATE($F$3,4+1,1)),2) -> 0 | G7: =ROUND(SUMIFS(资金台帐!$AB$6:$AB$6005,资金台帐!$T$6:$T$6005,$Q7,资金台帐!$U$6:$U$6005,"收入",资金台帐!$O$6:$O$6005,IF($C$3="全部","?*",$C$3),资金台帐!$N$6:$N$6005,">="&DATE($F$3,5,1),资金台帐!$N$6:$N$6005,"<"&DATE($F$3,5+1,1))-SUMIFS(资金台帐!$AC$6:$AC$6005,资金台帐!$T$6:$T$6005,$Q7,资金台帐!$U$6:$U$6005,"收入",资金台帐!$O$6:$O$6005,IF($C$3="全部","?*",$C$3),资金台帐!$N$6:$N$6005,">="&DATE($F$3,5,1),资金台帐!$N$6:$N$6005,"<"&DATE($F$3,5+1,1)),2) -> 0 | H7: =ROUND(SUMIFS(资金台帐!$AB$6:$AB$6005,资金台帐!$T$6:$T$6005,$Q7,资金台帐!$U$6:$U$6005,"收入",资金台帐!$O$6:$O$6005,IF($C$3="全部","?*",$C$3),资金台帐!$N$6:$N$6005,">="&DATE($F$3,6,1),资金台帐!$N$6:$N$6005,"<"&DATE($F$3,6+1,1))-SUMIFS(资金台帐!$AC$6:$AC$6005,资金台帐!$T$6:$T$6005,$Q7,资金台帐!$U$6:$U$6005,"收入",资金台帐!$O$6:$O$6005,IF($C$3="全部","?*",$C$3),资金台帐!$N$6:$N$6005,">="&DATE($F$3,6,1),资金台帐!$N$6:$N$6005,"<"&DATE($F$3,6+1,1)),2) -> 0 | I7: =ROUND(SUMIFS(资金台帐!$AB$6:$AB$6005,资金台帐!$T$6:$T$6005,$Q7,资金台帐!$U$6:$U$6005,"收入",资金台帐!$O$6:$O$6005,IF($C$3="全部","?*",$C$3),资金台帐!$N$6:$N$6005,">="&DATE($F$3,7,1),资金台帐!$N$6:$N$6005,"<"&DATE($F$3,7+1,1))-SUMIFS(资金台帐!$AC$6:$AC$6005,资金台帐!$T$6:$T$6005,$Q7,资金台帐!$U$6:$U$6005,"收入",资金台帐!$O$6:$O$6005,IF($C$3="全部","?*",$C$3),资金台帐!$N$6:$N$6005,">="&DATE($F$3,7,1),资金台帐!$N$6:$N$6005,"<"&DATE($F$3,7+1,1)),2) -> 0 | J7: =ROUND(SUMIFS(资金台帐!$AB$6:$AB$6005,资金台帐!$T$6:$T$6005,$Q7,资金台帐!$U$6:$U$6005,"收入",资金台帐!$O$6:$O$6005,IF($C$3="全部","?*",$C$3),资金台帐!$N$6:$N$6005,">="&DATE($F$3,8,1),资金台帐!$N$6:$N$6005,"<"&DATE($F$3,8+1,1))-SUMIFS(资金台帐!$AC$6:$AC$6005,资金台帐!$T$6:$T$6005,$Q7,资金台帐!$U$6:$U$6005,"收入",资金台帐!$O$6:$O$6005,IF($C$3="全部","?*",$C$3),资金台帐!$N$6:$N$6005,">="&DATE($F$3,8,1),资金台帐!$N$6:$N$6005,"<"&DATE($F$3,8+1,1)),2) -> 0 | K7: =ROUND(SUMIFS(资金台帐!$AB$6:$AB$6005,资金台帐!$T$6:$T$6005,$Q7,资金台帐!$U$6:$U$6005,"收入",资金台帐!$O$6:$O$6005,IF($C$3="全部","?*",$C$3),资金台帐!$N$6:$N$6005,">="&DATE($F$3,9,1),资金台帐!$N$6:$N$6005,"<"&DATE($F$3,9+1,1))-SUMIFS(资金台帐!$AC$6:$AC$6005,资金台帐!$T$6:$T$6005,$Q7,资金台帐!$U$6:$U$6005,"收入",资金台帐!$O$6:$O$6005,IF($C$3="全部","?*",$C$3),资金台帐!$N$6:$N$6005,">="&DATE($F$3,9,1),资金台帐!$N$6:$N$6005,"<"&DATE($F$3,9+1,1)),2) -> 171000 | L7: =ROUND(SUMIFS(资金台帐!$AB$6:$AB$6005,资金台帐!$T$6:$T$6005,$Q7,资金台帐!$U$6:$U$6005,"收入",资金台帐!$O$6:$O$6005,IF($C$3="全部","?*",$C$3),资金台帐!$N$6:$N$6005,">="&DATE($F$3,10,1),资金台帐!$N$6:$N$6005,"<"&DATE($F$3,10+1,1))-SUMIFS(资金台帐!$AC$6:$AC$6005,资金台帐!$T$6:$T$6005,$Q7,资金台帐!$U$6:$U$6005,"收入",资金台帐!$O$6:$O$6005,IF($C$3="全部","?*",$C$3),资金台帐!$N$6:$N$6005,">="&DATE($F$3,10,1),资金台帐!$N$6:$N$6005,"<"&DATE($F$3,10+1,1)),2) -> 0 | M7: =ROUND(SUMIFS(资金台帐!$AB$6:$AB$6005,资金台帐!$T$6:$T$6005,$Q7,资金台帐!$U$6:$U$6005,"收入",资金台帐!$O$6:$O$6005,IF($C$3="全部","?*",$C$3),资金台帐!$N$6:$N$6005,">="&DATE($F$3,11,1),资金台帐!$N$6:$N$6005,"<"&DATE($F$3,11+1,1))-SUMIFS(资金台帐!$AC$6:$AC$6005,资金台帐!$T$6:$T$6005,$Q7,资金台帐!$U$6:$U$6005,"收入",资金台帐!$O$6:$O$6005,IF($C$3="全部","?*",$C$3),资金台帐!$N$6:$N$6005,">="&DATE($F$3,11,1),资金台帐!$N$6:$N$6005,"<"&DATE($F$3,11+1,1)),2) -> 0 | N7: =ROUND(SUMIFS(资金台帐!$AB$6:$AB$6005,资金台帐!$T$6:$T$6005,$Q7,资金台帐!$U$6:$U$6005,"收入",资金台帐!$O$6:$O$6005,IF($C$3="全部","?*",$C$3),资金台帐!$N$6:$N$6005,">="&DATE($F$3,12,1),资金台帐!$N$6:$N$6005,"<"&DATE($F$3,12+1,1))-SUMIFS(资金台帐!$AC$6:$AC$6005,资金台帐!$T$6:$T$6005,$Q7,资金台帐!$U$6:$U$6005,"收入",资金台帐!$O$6:$O$6005,IF($C$3="全部","?*",$C$3),资金台帐!$N$6:$N$6005,">="&DATE($F$3,12,1),资金台帐!$N$6:$N$6005,"<"&DATE($F$3,12+1,1)),2) -> 0 | O7: =ROUND(SUM(C7:N7),2) -> 171000 | P7: =IF(N($O$16)=0,"",O7/$O$16) -> 1 | Q7: =基础资料!$U$7&"" -> 新增
B8: =IF(基础资料!$W$8="",基础资料!$U$8&"",基础资料!$W$8&"") -> 代办 | C8: =ROUND(SUMIFS(资金台帐!$AB$6:$AB$6005,资金台帐!$T$6:$T$6005,$Q8,资金台帐!$U$6:$U$6005,"收入",资金台帐!$O$6:$O$6005,IF($C$3="全部","?*",$C$3),资金台帐!$N$6:$N$6005,">="&DATE($F$3,1,1),资金台帐!$N$6:$N$6005,"<"&DATE($F$3,1+1,1))-SUMIFS(资金台帐!$AC$6:$AC$6005,资金台帐!$T$6:$T$6005,$Q8,资金台帐!$U$6:$U$6005,"收入",资金台帐!$O$6:$O$6005,IF($C$3="全部","?*",$C$3),资金台帐!$N$6:$N$6005,">="&DATE($F$3,1,1),资金台帐!$N$6:$N$6005,"<"&DATE($F$3,1+1,1)),2) -> 0 | D8: =ROUND(SUMIFS(资金台帐!$AB$6:$AB$6005,资金台帐!$T$6:$T$6005,$Q8,资金台帐!$U$6:$U$6005,"收入",资金台帐!$O$6:$O$6005,IF($C$3="全部","?*",$C$3),资金台帐!$N$6:$N$6005,">="&DATE($F$3,2,1),资金台帐!$N$6:$N$6005,"<"&DATE($F$3,2+1,1))-SUMIFS(资金台帐!$AC$6:$AC$6005,资金台帐!$T$6:$T$6005,$Q8,资金台帐!$U$6:$U$6005,"收入",资金台帐!$O$6:$O$6005,IF($C$3="全部","?*",$C$3),资金台帐!$N$6:$N$6005,">="&DATE($F$3,2,1),资金台帐!$N$6:$N$6005,"<"&DATE($F$3,2+1,1)),2) -> 0 | E8: =ROUND(SUMIFS(资金台帐!$AB$6:$AB$6005,资金台帐!$T$6:$T$6005,$Q8,资金台帐!$U$6:$U$6005,"收入",资金台帐!$O$6:$O$6005,IF($C$3="全部","?*",$C$3),资金台帐!$N$6:$N$6005,">="&DATE($F$3,3,1),资金台帐!$N$6:$N$6005,"<"&DATE($F$3,3+1,1))-SUMIFS(资金台帐!$AC$6:$AC$6005,资金台帐!$T$6:$T$6005,$Q8,资金台帐!$U$6:$U$6005,"收入",资金台帐!$O$6:$O$6005,IF($C$3="全部","?*",$C$3),资金台帐!$N$6:$N$6005,">="&DATE($F$3,3,1),资金台帐!$N$6:$N$6005,"<"&DATE($F$3,3+1,1)),2) -> 0 | F8: =ROUND(SUMIFS(资金台帐!$AB$6:$AB$6005,资金台帐!$T$6:$T$6005,$Q8,资金台帐!$U$6:$U$6005,"收入",资金台帐!$O$6:$O$6005,IF($C$3="全部","?*",$C$3),资金台帐!$N$6:$N$6005,">="&DATE($F$3,4,1),资金台帐!$N$6:$N$6005,"<"&DATE($F$3,4+1,1))-SUMIFS(资金台帐!$AC$6:$AC$6005,资金台帐!$T$6:$T$6005,$Q8,资金台帐!$U$6:$U$6005,"收入",资金台帐!$O$6:$O$6005,IF($C$3="全部","?*",$C$3),资金台帐!$N$6:$N$6005,">="&DATE($F$3,4,1),资金台帐!$N$6:$N$6005,"<"&DATE($F$3,4+1,1)),2) -> 0 | G8: =ROUND(SUMIFS(资金台帐!$AB$6:$AB$6005,资金台帐!$T$6:$T$6005,$Q8,资金台帐!$U$6:$U$6005,"收入",资金台帐!$O$6:$O$6005,IF($C$3="全部","?*",$C$3),资金台帐!$N$6:$N$6005,">="&DATE($F$3,5,1),资金台帐!$N$6:$N$6005,"<"&DATE($F$3,5+1,1))-SUMIFS(资金台帐!$AC$6:$AC$6005,资金台帐!$T$6:$T$6005,$Q8,资金台帐!$U$6:$U$6005,"收入",资金台帐!$O$6:$O$6005,IF($C$3="全部","?*",$C$3),资金台帐!$N$6:$N$6005,">="&DATE($F$3,5,1),资金台帐!$N$6:$N$6005,"<"&DATE($F$3,5+1,1)),2) -> 0 | H8: =ROUND(SUMIFS(资金台帐!$AB$6:$AB$6005,资金台帐!$T$6:$T$6005,$Q8,资金台帐!$U$6:$U$6005,"收入",资金台帐!$O$6:$O$6005,IF($C$3="全部","?*",$C$3),资金台帐!$N$6:$N$6005,">="&DATE($F$3,6,1),资金台帐!$N$6:$N$6005,"<"&DATE($F$3,6+1,1))-SUMIFS(资金台帐!$AC$6:$AC$6005,资金台帐!$T$6:$T$6005,$Q8,资金台帐!$U$6:$U$6005,"收入",资金台帐!$O$6:$O$6005,IF($C$3="全部","?*",$C$3),资金台帐!$N$6:$N$6005,">="&DATE($F$3,6,1),资金台帐!$N$6:$N$6005,"<"&DATE($F$3,6+1,1)),2) -> 0 | I8: =ROUND(SUMIFS(资金台帐!$AB$6:$AB$6005,资金台帐!$T$6:$T$6005,$Q8,资金台帐!$U$6:$U$6005,"收入",资金台帐!$O$6:$O$6005,IF($C$3="全部","?*",$C$3),资金台帐!$N$6:$N$6005,">="&DATE($F$3,7,1),资金台帐!$N$6:$N$6005,"<"&DATE($F$3,7+1,1))-SUMIFS(资金台帐!$AC$6:$AC$6005,资金台帐!$T$6:$T$6005,$Q8,资金台帐!$U$6:$U$6005,"收入",资金台帐!$O$6:$O$6005,IF($C$3="全部","?*",$C$3),资金台帐!$N$6:$N$6005,">="&DATE($F$3,7,1),资金台帐!$N$6:$N$6005,"<"&DATE($F$3,7+1,1)),2) -> 0 | J8: =ROUND(SUMIFS(资金台帐!$AB$6:$AB$6005,资金台帐!$T$6:$T$6005,$Q8,资金台帐!$U$6:$U$6005,"收入",资金台帐!$O$6:$O$6005,IF($C$3="全部","?*",$C$3),资金台帐!$N$6:$N$6005,">="&DATE($F$3,8,1),资金台帐!$N$6:$N$6005,"<"&DATE($F$3,8+1,1))-SUMIFS(资金台帐!$AC$6:$AC$6005,资金台帐!$T$6:$T$6005,$Q8,资金台帐!$U$6:$U$6005,"收入",资金台帐!$O$6:$O$6005,IF($C$3="全部","?*",$C$3),资金台帐!$N$6:$N$6005,">="&DATE($F$3,8,1),资金台帐!$N$6:$N$6005,"<"&DATE($F$3,8+1,1)),2) -> 0 | K8: =ROUND(SUMIFS(资金台帐!$AB$6:$AB$6005,资金台帐!$T$6:$T$6005,$Q8,资金台帐!$U$6:$U$6005,"收入",资金台帐!$O$6:$O$6005,IF($C$3="全部","?*",$C$3),资金台帐!$N$6:$N$6005,">="&DATE($F$3,9,1),资金台帐!$N$6:$N$6005,"<"&DATE($F$3,9+1,1))-SUMIFS(资金台帐!$AC$6:$AC$6005,资金台帐!$T$6:$T$6005,$Q8,资金台帐!$U$6:$U$6005,"收入",资金台帐!$O$6:$O$6005,IF($C$3="全部","?*",$C$3),资金台帐!$N$6:$N$6005,">="&DATE($F$3,9,1),资金台帐!$N$6:$N$6005,"<"&DATE($F$3,9+1,1)),2) -> 0 | L8: =ROUND(SUMIFS(资金台帐!$AB$6:$AB$6005,资金台帐!$T$6:$T$6005,$Q8,资金台帐!$U$6:$U$6005,"收入",资金台帐!$O$6:$O$6005,IF($C$3="全部","?*",$C$3),资金台帐!$N$6:$N$6005,">="&DATE($F$3,10,1),资金台帐!$N$6:$N$6005,"<"&DATE($F$3,10+1,1))-SUMIFS(资金台帐!$AC$6:$AC$6005,资金台帐!$T$6:$T$6005,$Q8,资金台帐!$U$6:$U$6005,"收入",资金台帐!$O$6:$O$6005,IF($C$3="全部","?*",$C$3),资金台帐!$N$6:$N$6005,">="&DATE($F$3,10,1),资金台帐!$N$6:$N$6005,"<"&DATE($F$3,10+1,1)),2) -> 0 | M8: =ROUND(SUMIFS(资金台帐!$AB$6:$AB$6005,资金台帐!$T$6:$T$6005,$Q8,资金台帐!$U$6:$U$6005,"收入",资金台帐!$O$6:$O$6005,IF($C$3="全部","?*",$C$3),资金台帐!$N$6:$N$6005,">="&DATE($F$3,11,1),资金台帐!$N$6:$N$6005,"<"&DATE($F$3,11+1,1))-SUMIFS(资金台帐!$AC$6:$AC$6005,资金台帐!$T$6:$T$6005,$Q8,资金台帐!$U$6:$U$6005,"收入",资金台帐!$O$6:$O$6005,IF($C$3="全部","?*",$C$3),资金台帐!$N$6:$N$6005,">="&DATE($F$3,11,1),资金台帐!$N$6:$N$6005,"<"&DATE($F$3,11+1,1)),2) -> 0 | N8: =ROUND(SUMIFS(资金台帐!$AB$6:$AB$6005,资金台帐!$T$6:$T$6005,$Q8,资金台帐!$U$6:$U$6005,"收入",资金台帐!$O$6:$O$6005,IF($C$3="全部","?*",$C$3),资金台帐!$N$6:$N$6005,">="&DATE($F$3,12,1),资金台帐!$N$6:$N$6005,"<"&DATE($F$3,12+1,1))-SUMIFS(资金台帐!$AC$6:$AC$6005,资金台帐!$T$6:$T$6005,$Q8,资金台帐!$U$6:$U$6005,"收入",资金台帐!$O$6:$O$6005,IF($C$3="全部","?*",$C$3),资金台帐!$N$6:$N$6005,">="&DATE($F$3,12,1),资金台帐!$N$6:$N$6005,"<"&DATE($F$3,12+1,1)),2) -> 0 | O8: =ROUND(SUM(C8:N8),2) -> 0 | P8: =IF(N($O$16)=0,"",O8/$O$16) -> 0 | Q8: =基础资料!$U$8&"" -> 代办
B9: =IF(基础资料!$W$9="",基础资料!$U$9&"",基础资料!$W$9&"") -> 刻章 | C9: =ROUND(SUMIFS(资金台帐!$AB$6:$AB$6005,资金台帐!$T$6:$T$6005,$Q9,资金台帐!$U$6:$U$6005,"收入",资金台帐!$O$6:$O$6005,IF($C$3="全部","?*",$C$3),资金台帐!$N$6:$N$6005,">="&DATE($F$3,1,1),资金台帐!$N$6:$N$6005,"<"&DATE($F$3,1+1,1))-SUMIFS(资金台帐!$AC$6:$AC$6005,资金台帐!$T$6:$T$6005,$Q9,资金台帐!$U$6:$U$6005,"收入",资金台帐!$O$6:$O$6005,IF($C$3="全部","?*",$C$3),资金台帐!$N$6:$N$6005,">="&DATE($F$3,1,1),资金台帐!$N$6:$N$6005,"<"&DATE($F$3,1+1,1)),2) -> 0 | D9: =ROUND(SUMIFS(资金台帐!$AB$6:$AB$6005,资金台帐!$T$6:$T$6005,$Q9,资金台帐!$U$6:$U$6005,"收入",资金台帐!$O$6:$O$6005,IF($C$3="全部","?*",$C$3),资金台帐!$N$6:$N$6005,">="&DATE($F$3,2,1),资金台帐!$N$6:$N$6005,"<"&DATE($F$3,2+1,1))-SUMIFS(资金台帐!$AC$6:$AC$6005,资金台帐!$T$6:$T$6005,$Q9,资金台帐!$U$6:$U$6005,"收入",资金台帐!$O$6:$O$6005,IF($C$3="全部","?*",$C$3),资金台帐!$N$6:$N$6005,">="&DATE($F$3,2,1),资金台帐!$N$6:$N$6005,"<"&DATE($F$3,2+1,1)),2) -> 0 | E9: =ROUND(SUMIFS(资金台帐!$AB$6:$AB$6005,资金台帐!$T$6:$T$6005,$Q9,资金台帐!$U$6:$U$6005,"收入",资金台帐!$O$6:$O$6005,IF($C$3="全部","?*",$C$3),资金台帐!$N$6:$N$6005,">="&DATE($F$3,3,1),资金台帐!$N$6:$N$6005,"<"&DATE($F$3,3+1,1))-SUMIFS(资金台帐!$AC$6:$AC$6005,资金台帐!$T$6:$T$6005,$Q9,资金台帐!$U$6:$U$6005,"收入",资金台帐!$O$6:$O$6005,IF($C$3="全部","?*",$C$3),资金台帐!$N$6:$N$6005,">="&DATE($F$3,3,1),资金台帐!$N$6:$N$6005,"<"&DATE($F$3,3+1,1)),2) -> 0 | F9: =ROUND(SUMIFS(资金台帐!$AB$6:$AB$6005,资金台帐!$T$6:$T$6005,$Q9,资金台帐!$U$6:$U$6005,"收入",资金台帐!$O$6:$O$6005,IF($C$3="全部","?*",$C$3),资金台帐!$N$6:$N$6005,">="&DATE($F$3,4,1),资金台帐!$N$6:$N$6005,"<"&DATE($F$3,4+1,1))-SUMIFS(资金台帐!$AC$6:$AC$6005,资金台帐!$T$6:$T$6005,$Q9,资金台帐!$U$6:$U$6005,"收入",资金台帐!$O$6:$O$6005,IF($C$3="全部","?*",$C$3),资金台帐!$N$6:$N$6005,">="&DATE($F$3,4,1),资金台帐!$N$6:$N$6005,"<"&DATE($F$3,4+1,1)),2) -> 0 | G9: =ROUND(SUMIFS(资金台帐!$AB$6:$AB$6005,资金台帐!$T$6:$T$6005,$Q9,资金台帐!$U$6:$U$6005,"收入",资金台帐!$O$6:$O$6005,IF($C$3="全部","?*",$C$3),资金台帐!$N$6:$N$6005,">="&DATE($F$3,5,1),资金台帐!$N$6:$N$6005,"<"&DATE($F$3,5+1,1))-SUMIFS(资金台帐!$AC$6:$AC$6005,资金台帐!$T$6:$T$6005,$Q9,资金台帐!$U$6:$U$6005,"收入",资金台帐!$O$6:$O$6005,IF($C$3="全部","?*",$C$3),资金台帐!$N$6:$N$6005,">="&DATE($F$3,5,1),资金台帐!$N$6:$N$6005,"<"&DATE($F$3,5+1,1)),2) -> 0 | H9: =ROUND(SUMIFS(资金台帐!$AB$6:$AB$6005,资金台帐!$T$6:$T$6005,$Q9,资金台帐!$U$6:$U$6005,"收入",资金台帐!$O$6:$O$6005,IF($C$3="全部","?*",$C$3),资金台帐!$N$6:$N$6005,">="&DATE($F$3,6,1),资金台帐!$N$6:$N$6005,"<"&DATE($F$3,6+1,1))-SUMIFS(资金台帐!$AC$6:$AC$6005,资金台帐!$T$6:$T$6005,$Q9,资金台帐!$U$6:$U$6005,"收入",资金台帐!$O$6:$O$6005,IF($C$3="全部","?*",$C$3),资金台帐!$N$6:$N$6005,">="&DATE($F$3,6,1),资金台帐!$N$6:$N$6005,"<"&DATE($F$3,6+1,1)),2) -> 0 | I9: =ROUND(SUMIFS(资金台帐!$AB$6:$AB$6005,资金台帐!$T$6:$T$6005,$Q9,资金台帐!$U$6:$U$6005,"收入",资金台帐!$O$6:$O$6005,IF($C$3="全部","?*",$C$3),资金台帐!$N$6:$N$6005,">="&DATE($F$3,7,1),资金台帐!$N$6:$N$6005,"<"&DATE($F$3,7+1,1))-SUMIFS(资金台帐!$AC$6:$AC$6005,资金台帐!$T$6:$T$6005,$Q9,资金台帐!$U$6:$U$6005,"收入",资金台帐!$O$6:$O$6005,IF($C$3="全部","?*",$C$3),资金台帐!$N$6:$N$6005,">="&DATE($F$3,7,1),资金台帐!$N$6:$N$6005,"<"&DATE($F$3,7+1,1)),2) -> 0 | J9: =ROUND(SUMIFS(资金台帐!$AB$6:$AB$6005,资金台帐!$T$6:$T$6005,$Q9,资金台帐!$U$6:$U$6005,"收入",资金台帐!$O$6:$O$6005,IF($C$3="全部","?*",$C$3),资金台帐!$N$6:$N$6005,">="&DATE($F$3,8,1),资金台帐!$N$6:$N$6005,"<"&DATE($F$3,8+1,1))-SUMIFS(资金台帐!$AC$6:$AC$6005,资金台帐!$T$6:$T$6005,$Q9,资金台帐!$U$6:$U$6005,"收入",资金台帐!$O$6:$O$6005,IF($C$3="全部","?*",$C$3),资金台帐!$N$6:$N$6005,">="&DATE($F$3,8,1),资金台帐!$N$6:$N$6005,"<"&DATE($F$3,8+1,1)),2) -> 0 | K9: =ROUND(SUMIFS(资金台帐!$AB$6:$AB$6005,资金台帐!$T$6:$T$6005,$Q9,资金台帐!$U$6:$U$6005,"收入",资金台帐!$O$6:$O$6005,IF($C$3="全部","?*",$C$3),资金台帐!$N$6:$N$6005,">="&DATE($F$3,9,1),资金台帐!$N$6:$N$6005,"<"&DATE($F$3,9+1,1))-SUMIFS(资金台帐!$AC$6:$AC$6005,资金台帐!$T$6:$T$6005,$Q9,资金台帐!$U$6:$U$6005,"收入",资金台帐!$O$6:$O$6005,IF($C$3="全部","?*",$C$3),资金台帐!$N$6:$N$6005,">="&DATE($F$3,9,1),资金台帐!$N$6:$N$6005,"<"&DATE($F$3,9+1,1)),2) -> 0 | L9: =ROUND(SUMIFS(资金台帐!$AB$6:$AB$6005,资金台帐!$T$6:$T$6005,$Q9,资金台帐!$U$6:$U$6005,"收入",资金台帐!$O$6:$O$6005,IF($C$3="全部","?*",$C$3),资金台帐!$N$6:$N$6005,">="&DATE($F$3,10,1),资金台帐!$N$6:$N$6005,"<"&DATE($F$3,10+1,1))-SUMIFS(资金台帐!$AC$6:$AC$6005,资金台帐!$T$6:$T$6005,$Q9,资金台帐!$U$6:$U$6005,"收入",资金台帐!$O$6:$O$6005,IF($C$3="全部","?*",$C$3),资金台帐!$N$6:$N$6005,">="&DATE($F$3,10,1),资金台帐!$N$6:$N$6005,"<"&DATE($F$3,10+1,1)),2) -> 0 | M9: =ROUND(SUMIFS(资金台帐!$AB$6:$AB$6005,资金台帐!$T$6:$T$6005,$Q9,资金台帐!$U$6:$U$6005,"收入",资金台帐!$O$6:$O$6005,IF($C$3="全部","?*",$C$3),资金台帐!$N$6:$N$6005,">="&DATE($F$3,11,1),资金台帐!$N$6:$N$6005,"<"&DATE($F$3,11+1,1))-SUMIFS(资金台帐!$AC$6:$AC$6005,资金台帐!$T$6:$T$6005,$Q9,资金台帐!$U$6:$U$6005,"收入",资金台帐!$O$6:$O$6005,IF($C$3="全部","?*",$C$3),资金台帐!$N$6:$N$6005,">="&DATE($F$3,11,1),资金台帐!$N$6:$N$6005,"<"&DATE($F$3,11+1,1)),2) -> 0 | N9: =ROUND(SUMIFS(资金台帐!$AB$6:$AB$6005,资金台帐!$T$6:$T$6005,$Q9,资金台帐!$U$6:$U$6005,"收入",资金台帐!$O$6:$O$6005,IF($C$3="全部","?*",$C$3),资金台帐!$N$6:$N$6005,">="&DATE($F$3,12,1),资金台帐!$N$6:$N$6005,"<"&DATE($F$3,12+1,1))-SUMIFS(资金台帐!$AC$6:$AC$6005,资金台帐!$T$6:$T$6005,$Q9,资金台帐!$U$6:$U$6005,"收入",资金台帐!$O$6:$O$6005,IF($C$3="全部","?*",$C$3),资金台帐!$N$6:$N$6005,">="&DATE($F$3,12,1),资金台帐!$N$6:$N$6005,"<"&DATE($F$3,12+1,1)),2) -> 0 | O9: =ROUND(SUM(C9:N9),2) -> 0 | P9: =IF(N($O$16)=0,"",O9/$O$16) -> 0 | Q9: =基础资料!$U$9&"" -> 刻章
B10: =IF(基础资料!$W$10="",基础资料!$U$10&"",基础资料!$W$10&"") -> 场地 | C10: =ROUND(SUMIFS(资金台帐!$AB$6:$AB$6005,资金台帐!$T$6:$T$6005,$Q10,资金台帐!$U$6:$U$6005,"收入",资金台帐!$O$6:$O$6005,IF($C$3="全部","?*",$C$3),资金台帐!$N$6:$N$6005,">="&DATE($F$3,1,1),资金台帐!$N$6:$N$6005,"<"&DATE($F$3,1+1,1))-SUMIFS(资金台帐!$AC$6:$AC$6005,资金台帐!$T$6:$T$6005,$Q10,资金台帐!$U$6:$U$6005,"收入",资金台帐!$O$6:$O$6005,IF($C$3="全部","?*",$C$3),资金台帐!$N$6:$N$6005,">="&DATE($F$3,1,1),资金台帐!$N$6:$N$6005,"<"&DATE($F$3,1+1,1)),2) -> 0 | D10: =ROUND(SUMIFS(资金台帐!$AB$6:$AB$6005,资金台帐!$T$6:$T$6005,$Q10,资金台帐!$U$6:$U$6005,"收入",资金台帐!$O$6:$O$6005,IF($C$3="全部","?*",$C$3),资金台帐!$N$6:$N$6005,">="&DATE($F$3,2,1),资金台帐!$N$6:$N$6005,"<"&DATE($F$3,2+1,1))-SUMIFS(资金台帐!$AC$6:$AC$6005,资金台帐!$T$6:$T$6005,$Q10,资金台帐!$U$6:$U$6005,"收入",资金台帐!$O$6:$O$6005,IF($C$3="全部","?*",$C$3),资金台帐!$N$6:$N$6005,">="&DATE($F$3,2,1),资金台帐!$N$6:$N$6005,"<"&DATE($F$3,2+1,1)),2) -> 0 | E10: =ROUND(SUMIFS(资金台帐!$AB$6:$AB$6005,资金台帐!$T$6:$T$6005,$Q10,资金台帐!$U$6:$U$6005,"收入",资金台帐!$O$6:$O$6005,IF($C$3="全部","?*",$C$3),资金台帐!$N$6:$N$6005,">="&DATE($F$3,3,1),资金台帐!$N$6:$N$6005,"<"&DATE($F$3,3+1,1))-SUMIFS(资金台帐!$AC$6:$AC$6005,资金台帐!$T$6:$T$6005,$Q10,资金台帐!$U$6:$U$6005,"收入",资金台帐!$O$6:$O$6005,IF($C$3="全部","?*",$C$3),资金台帐!$N$6:$N$6005,">="&DATE($F$3,3,1),资金台帐!$N$6:$N$6005,"<"&DATE($F$3,3+1,1)),2) -> 0 | F10: =ROUND(SUMIFS(资金台帐!$AB$6:$AB$6005,资金台帐!$T$6:$T$6005,$Q10,资金台帐!$U$6:$U$6005,"收入",资金台帐!$O$6:$O$6005,IF($C$3="全部","?*",$C$3),资金台帐!$N$6:$N$6005,">="&DATE($F$3,4,1),资金台帐!$N$6:$N$6005,"<"&DATE($F$3,4+1,1))-SUMIFS(资金台帐!$AC$6:$AC$6005,资金台帐!$T$6:$T$6005,$Q10,资金台帐!$U$6:$U$6005,"收入",资金台帐!$O$6:$O$6005,IF($C$3="全部","?*",$C$3),资金台帐!$N$6:$N$6005,">="&DATE($F$3,4,1),资金台帐!$N$6:$N$6005,"<"&DATE($F$3,4+1,1)),2) -> 0 | G10: =ROUND(SUMIFS(资金台帐!$AB$6:$AB$6005,资金台帐!$T$6:$T$6005,$Q10,资金台帐!$U$6:$U$6005,"收入",资金台帐!$O$6:$O$6005,IF($C$3="全部","?*",$C$3),资金台帐!$N$6:$N$6005,">="&DATE($F$3,5,1),资金台帐!$N$6:$N$6005,"<"&DATE($F$3,5+1,1))-SUMIFS(资金台帐!$AC$6:$AC$6005,资金台帐!$T$6:$T$6005,$Q10,资金台帐!$U$6:$U$6005,"收入",资金台帐!$O$6:$O$6005,IF($C$3="全部","?*",$C$3),资金台帐!$N$6:$N$6005,">="&DATE($F$3,5,1),资金台帐!$N$6:$N$6005,"<"&DATE($F$3,5+1,1)),2) -> 0 | H10: =ROUND(SUMIFS(资金台帐!$AB$6:$AB$6005,资金台帐!$T$6:$T$6005,$Q10,资金台帐!$U$6:$U$6005,"收入",资金台帐!$O$6:$O$6005,IF($C$3="全部","?*",$C$3),资金台帐!$N$6:$N$6005,">="&DATE($F$3,6,1),资金台帐!$N$6:$N$6005,"<"&DATE($F$3,6+1,1))-SUMIFS(资金台帐!$AC$6:$AC$6005,资金台帐!$T$6:$T$6005,$Q10,资金台帐!$U$6:$U$6005,"收入",资金台帐!$O$6:$O$6005,IF($C$3="全部","?*",$C$3),资金台帐!$N$6:$N$6005,">="&DATE($F$3,6,1),资金台帐!$N$6:$N$6005,"<"&DATE($F$3,6+1,1)),2) -> 0 | I10: =ROUND(SUMIFS(资金台帐!$AB$6:$AB$6005,资金台帐!$T$6:$T$6005,$Q10,资金台帐!$U$6:$U$6005,"收入",资金台帐!$O$6:$O$6005,IF($C$3="全部","?*",$C$3),资金台帐!$N$6:$N$6005,">="&DATE($F$3,7,1),资金台帐!$N$6:$N$6005,"<"&DATE($F$3,7+1,1))-SUMIFS(资金台帐!$AC$6:$AC$6005,资金台帐!$T$6:$T$6005,$Q10,资金台帐!$U$6:$U$6005,"收入",资金台帐!$O$6:$O$6005,IF($C$3="全部","?*",$C$3),资金台帐!$N$6:$N$6005,">="&DATE($F$3,7,1),资金台帐!$N$6:$N$6005,"<"&DATE($F$3,7+1,1)),2) -> 0 | J10: =ROUND(SUMIFS(资金台帐!$AB$6:$AB$6005,资金台帐!$T$6:$T$6005,$Q10,资金台帐!$U$6:$U$6005,"收入",资金台帐!$O$6:$O$6005,IF($C$3="全部","?*",$C$3),资金台帐!$N$6:$N$6005,">="&DATE($F$3,8,1),资金台帐!$N$6:$N$6005,"<"&DATE($F$3,8+1,1))-SUMIFS(资金台帐!$AC$6:$AC$6005,资金台帐!$T$6:$T$6005,$Q10,资金台帐!$U$6:$U$6005,"收入",资金台帐!$O$6:$O$6005,IF($C$3="全部","?*",$C$3),资金台帐!$N$6:$N$6005,">="&DATE($F$3,8,1),资金台帐!$N$6:$N$6005,"<"&DATE($F$3,8+1,1)),2) -> 0 | K10: =ROUND(SUMIFS(资金台帐!$AB$6:$AB$6005,资金台帐!$T$6:$T$6005,$Q10,资金台帐!$U$6:$U$6005,"收入",资金台帐!$O$6:$O$6005,IF($C$3="全部","?*",$C$3),资金台帐!$N$6:$N$6005,">="&DATE($F$3,9,1),资金台帐!$N$6:$N$6005,"<"&DATE($F$3,9+1,1))-SUMIFS(资金台帐!$AC$6:$AC$6005,资金台帐!$T$6:$T$6005,$Q10,资金台帐!$U$6:$U$6005,"收入",资金台帐!$O$6:$O$6005,IF($C$3="全部","?*",$C$3),资金台帐!$N$6:$N$6005,">="&DATE($F$3,9,1),资金台帐!$N$6:$N$6005,"<"&DATE($F$3,9+1,1)),2) -> 0 | L10: =ROUND(SUMIFS(资金台帐!$AB$6:$AB$6005,资金台帐!$T$6:$T$6005,$Q10,资金台帐!$U$6:$U$6005,"收入",资金台帐!$O$6:$O$6005,IF($C$3="全部","?*",$C$3),资金台帐!$N$6:$N$6005,">="&DATE($F$3,10,1),资金台帐!$N$6:$N$6005,"<"&DATE($F$3,10+1,1))-SUMIFS(资金台帐!$AC$6:$AC$6005,资金台帐!$T$6:$T$6005,$Q10,资金台帐!$U$6:$U$6005,"收入",资金台帐!$O$6:$O$6005,IF($C$3="全部","?*",$C$3),资金台帐!$N$6:$N$6005,">="&DATE($F$3,10,1),资金台帐!$N$6:$N$6005,"<"&DATE($F$3,10+1,1)),2) -> 0 | M10: =ROUND(SUMIFS(资金台帐!$AB$6:$AB$6005,资金台帐!$T$6:$T$6005,$Q10,资金台帐!$U$6:$U$6005,"收入",资金台帐!$O$6:$O$6005,IF($C$3="全部","?*",$C$3),资金台帐!$N$6:$N$6005,">="&DATE($F$3,11,1),资金台帐!$N$6:$N$6005,"<"&DATE($F$3,11+1,1))-SUMIFS(资金台帐!$AC$6:$AC$6005,资金台帐!$T$6:$T$6005,$Q10,资金台帐!$U$6:$U$6005,"收入",资金台帐!$O$6:$O$6005,IF($C$3="全部","?*",$C$3),资金台帐!$N$6:$N$6005,">="&DATE($F$3,11,1),资金台帐!$N$6:$N$6005,"<"&DATE($F$3,11+1,1)),2) -> 0 | N10: =ROUND(SUMIFS(资金台帐!$AB$6:$AB$6005,资金台帐!$T$6:$T$6005,$Q10,资金台帐!$U$6:$U$6005,"收入",资金台帐!$O$6:$O$6005,IF($C$3="全部","?*",$C$3),资金台帐!$N$6:$N$6005,">="&DATE($F$3,12,1),资金台帐!$N$6:$N$6005,"<"&DATE($F$3,12+1,1))-SUMIFS(资金台帐!$AC$6:$AC$6005,资金台帐!$T$6:$T$6005,$Q10,资金台帐!$U$6:$U$6005,"收入",资金台帐!$O$6:$O$6005,IF($C$3="全部","?*",$C$3),资金台帐!$N$6:$N$6005,">="&DATE($F$3,12,1),资金台帐!$N$6:$N$6005,"<"&DATE($F$3,12+1,1)),2) -> 0 | O10: =ROUND(SUM(C10:N10),2) -> 0 | P10: =IF(N($O$16)=0,"",O10/$O$16) -> 0 | Q10: =基础资料!$U$10&"" -> 场地
B11: =IF(基础资料!$W$11="",基础资料!$U$11&"",基础资料!$W$11&"") -> 办证 | C11: =ROUND(SUMIFS(资金台帐!$AB$6:$AB$6005,资金台帐!$T$6:$T$6005,$Q11,资金台帐!$U$6:$U$6005,"收入",资金台帐!$O$6:$O$6005,IF($C$3="全部","?*",$C$3),资金台帐!$N$6:$N$6005,">="&DATE($F$3,1,1),资金台帐!$N$6:$N$6005,"<"&DATE($F$3,1+1,1))-SUMIFS(资金台帐!$AC$6:$AC$6005,资金台帐!$T$6:$T$6005,$Q11,资金台帐!$U$6:$U$6005,"收入",资金台帐!$O$6:$O$6005,IF($C$3="全部","?*",$C$3),资金台帐!$N$6:$N$6005,">="&DATE($F$3,1,1),资金台帐!$N$6:$N$6005,"<"&DATE($F$3,1+1,1)),2) -> 0 | D11: =ROUND(SUMIFS(资金台帐!$AB$6:$AB$6005,资金台帐!$T$6:$T$6005,$Q11,资金台帐!$U$6:$U$6005,"收入",资金台帐!$O$6:$O$6005,IF($C$3="全部","?*",$C$3),资金台帐!$N$6:$N$6005,">="&DATE($F$3,2,1),资金台帐!$N$6:$N$6005,"<"&DATE($F$3,2+1,1))-SUMIFS(资金台帐!$AC$6:$AC$6005,资金台帐!$T$6:$T$6005,$Q11,资金台帐!$U$6:$U$6005,"收入",资金台帐!$O$6:$O$6005,IF($C$3="全部","?*",$C$3),资金台帐!$N$6:$N$6005,">="&DATE($F$3,2,1),资金台帐!$N$6:$N$6005,"<"&DATE($F$3,2+1,1)),2) -> 0 | E11: =ROUND(SUMIFS(资金台帐!$AB$6:$AB$6005,资金台帐!$T$6:$T$6005,$Q11,资金台帐!$U$6:$U$6005,"收入",资金台帐!$O$6:$O$6005,IF($C$3="全部","?*",$C$3),资金台帐!$N$6:$N$6005,">="&DATE($F$3,3,1),资金台帐!$N$6:$N$6005,"<"&DATE($F$3,3+1,1))-SUMIFS(资金台帐!$AC$6:$AC$6005,资金台帐!$T$6:$T$6005,$Q11,资金台帐!$U$6:$U$6005,"收入",资金台帐!$O$6:$O$6005,IF($C$3="全部","?*",$C$3),资金台帐!$N$6:$N$6005,">="&DATE($F$3,3,1),资金台帐!$N$6:$N$6005,"<"&DATE($F$3,3+1,1)),2) -> 0 | F11: =ROUND(SUMIFS(资金台帐!$AB$6:$AB$6005,资金台帐!$T$6:$T$6005,$Q11,资金台帐!$U$6:$U$6005,"收入",资金台帐!$O$6:$O$6005,IF($C$3="全部","?*",$C$3),资金台帐!$N$6:$N$6005,">="&DATE($F$3,4,1),资金台帐!$N$6:$N$6005,"<"&DATE($F$3,4+1,1))-SUMIFS(资金台帐!$AC$6:$AC$6005,资金台帐!$T$6:$T$6005,$Q11,资金台帐!$U$6:$U$6005,"收入",资金台帐!$O$6:$O$6005,IF($C$3="全部","?*",$C$3),资金台帐!$N$6:$N$6005,">="&DATE($F$3,4,1),资金台帐!$N$6:$N$6005,"<"&DATE($F$3,4+1,1)),2) -> 0 | G11: =ROUND(SUMIFS(资金台帐!$AB$6:$AB$6005,资金台帐!$T$6:$T$6005,$Q11,资金台帐!$U$6:$U$6005,"收入",资金台帐!$O$6:$O$6005,IF($C$3="全部","?*",$C$3),资金台帐!$N$6:$N$6005,">="&DATE($F$3,5,1),资金台帐!$N$6:$N$6005,"<"&DATE($F$3,5+1,1))-SUMIFS(资金台帐!$AC$6:$AC$6005,资金台帐!$T$6:$T$6005,$Q11,资金台帐!$U$6:$U$6005,"收入",资金台帐!$O$6:$O$6005,IF($C$3="全部","?*",$C$3),资金台帐!$N$6:$N$6005,">="&DATE($F$3,5,1),资金台帐!$N$6:$N$6005,"<"&DATE($F$3,5+1,1)),2) -> 0 | H11: =ROUND(SUMIFS(资金台帐!$AB$6:$AB$6005,资金台帐!$T$6:$T$6005,$Q11,资金台帐!$U$6:$U$6005,"收入",资金台帐!$O$6:$O$6005,IF($C$3="全部","?*",$C$3),资金台帐!$N$6:$N$6005,">="&DATE($F$3,6,1),资金台帐!$N$6:$N$6005,"<"&DATE($F$3,6+1,1))-SUMIFS(资金台帐!$AC$6:$AC$6005,资金台帐!$T$6:$T$6005,$Q11,资金台帐!$U$6:$U$6005,"收入",资金台帐!$O$6:$O$6005,IF($C$3="全部","?*",$C$3),资金台帐!$N$6:$N$6005,">="&DATE($F$3,6,1),资金台帐!$N$6:$N$6005,"<"&DATE($F$3,6+1,1)),2) -> 0 | I11: =ROUND(SUMIFS(资金台帐!$AB$6:$AB$6005,资金台帐!$T$6:$T$6005,$Q11,资金台帐!$U$6:$U$6005,"收入",资金台帐!$O$6:$O$6005,IF($C$3="全部","?*",$C$3),资金台帐!$N$6:$N$6005,">="&DATE($F$3,7,1),资金台帐!$N$6:$N$6005,"<"&DATE($F$3,7+1,1))-SUMIFS(资金台帐!$AC$6:$AC$6005,资金台帐!$T$6:$T$6005,$Q11,资金台帐!$U$6:$U$6005,"收入",资金台帐!$O$6:$O$6005,IF($C$3="全部","?*",$C$3),资金台帐!$N$6:$N$6005,">="&DATE($F$3,7,1),资金台帐!$N$6:$N$6005,"<"&DATE($F$3,7+1,1)),2) -> 0 | J11: =ROUND(SUMIFS(资金台帐!$AB$6:$AB$6005,资金台帐!$T$6:$T$6005,$Q11,资金台帐!$U$6:$U$6005,"收入",资金台帐!$O$6:$O$6005,IF($C$3="全部","?*",$C$3),资金台帐!$N$6:$N$6005,">="&DATE($F$3,8,1),资金台帐!$N$6:$N$6005,"<"&DATE($F$3,8+1,1))-SUMIFS(资金台帐!$AC$6:$AC$6005,资金台帐!$T$6:$T$6005,$Q11,资金台帐!$U$6:$U$6005,"收入",资金台帐!$O$6:$O$6005,IF($C$3="全部","?*",$C$3),资金台帐!$N$6:$N$6005,">="&DATE($F$3,8,1),资金台帐!$N$6:$N$6005,"<"&DATE($F$3,8+1,1)),2) -> 0 | K11: =ROUND(SUMIFS(资金台帐!$AB$6:$AB$6005,资金台帐!$T$6:$T$6005,$Q11,资金台帐!$U$6:$U$6005,"收入",资金台帐!$O$6:$O$6005,IF($C$3="全部","?*",$C$3),资金台帐!$N$6:$N$6005,">="&DATE($F$3,9,1),资金台帐!$N$6:$N$6005,"<"&DATE($F$3,9+1,1))-SUMIFS(资金台帐!$AC$6:$AC$6005,资金台帐!$T$6:$T$6005,$Q11,资金台帐!$U$6:$U$6005,"收入",资金台帐!$O$6:$O$6005,IF($C$3="全部","?*",$C$3),资金台帐!$N$6:$N$6005,">="&DATE($F$3,9,1),资金台帐!$N$6:$N$6005,"<"&DATE($F$3,9+1,1)),2) -> 0 | L11: =ROUND(SUMIFS(资金台帐!$AB$6:$AB$6005,资金台帐!$T$6:$T$6005,$Q11,资金台帐!$U$6:$U$6005,"收入",资金台帐!$O$6:$O$6005,IF($C$3="全部","?*",$C$3),资金台帐!$N$6:$N$6005,">="&DATE($F$3,10,1),资金台帐!$N$6:$N$6005,"<"&DATE($F$3,10+1,1))-SUMIFS(资金台帐!$AC$6:$AC$6005,资金台帐!$T$6:$T$6005,$Q11,资金台帐!$U$6:$U$6005,"收入",资金台帐!$O$6:$O$6005,IF($C$3="全部","?*",$C$3),资金台帐!$N$6:$N$6005,">="&DATE($F$3,10,1),资金台帐!$N$6:$N$6005,"<"&DATE($F$3,10+1,1)),2) -> 0 | M11: =ROUND(SUMIFS(资金台帐!$AB$6:$AB$6005,资金台帐!$T$6:$T$6005,$Q11,资金台帐!$U$6:$U$6005,"收入",资金台帐!$O$6:$O$6005,IF($C$3="全部","?*",$C$3),资金台帐!$N$6:$N$6005,">="&DATE($F$3,11,1),资金台帐!$N$6:$N$6005,"<"&DATE($F$3,11+1,1))-SUMIFS(资金台帐!$AC$6:$AC$6005,资金台帐!$T$6:$T$6005,$Q11,资金台帐!$U$6:$U$6005,"收入",资金台帐!$O$6:$O$6005,IF($C$3="全部","?*",$C$3),资金台帐!$N$6:$N$6005,">="&DATE($F$3,11,1),资金台帐!$N$6:$N$6005,"<"&DATE($F$3,11+1,1)),2) -> 0 | N11: =ROUND(SUMIFS(资金台帐!$AB$6:$AB$6005,资金台帐!$T$6:$T$6005,$Q11,资金台帐!$U$6:$U$6005,"收入",资金台帐!$O$6:$O$6005,IF($C$3="全部","?*",$C$3),资金台帐!$N$6:$N$6005,">="&DATE($F$3,12,1),资金台帐!$N$6:$N$6005,"<"&DATE($F$3,12+1,1))-SUMIFS(资金台帐!$AC$6:$AC$6005,资金台帐!$T$6:$T$6005,$Q11,资金台帐!$U$6:$U$6005,"收入",资金台帐!$O$6:$O$6005,IF($C$3="全部","?*",$C$3),资金台帐!$N$6:$N$6005,">="&DATE($F$3,12,1),资金台帐!$N$6:$N$6005,"<"&DATE($F$3,12+1,1)),2) -> 0 | O11: =ROUND(SUM(C11:N11),2) -> 0 | P11: =IF(N($O$16)=0,"",O11/$O$16) -> 0 | Q11: =基础资料!$U$11&"" -> 办证
B12: =IF(基础资料!$W$12="",基础资料!$U$12&"",基础资料!$W$12&"") -> 转介绍 | C12: =ROUND(SUMIFS(资金台帐!$AB$6:$AB$6005,资金台帐!$T$6:$T$6005,$Q12,资金台帐!$U$6:$U$6005,"收入",资金台帐!$O$6:$O$6005,IF($C$3="全部","?*",$C$3),资金台帐!$N$6:$N$6005,">="&DATE($F$3,1,1),资金台帐!$N$6:$N$6005,"<"&DATE($F$3,1+1,1))-SUMIFS(资金台帐!$AC$6:$AC$6005,资金台帐!$T$6:$T$6005,$Q12,资金台帐!$U$6:$U$6005,"收入",资金台帐!$O$6:$O$6005,IF($C$3="全部","?*",$C$3),资金台帐!$N$6:$N$6005,">="&DATE($F$3,1,1),资金台帐!$N$6:$N$6005,"<"&DATE($F$3,1+1,1)),2) -> 0 | D12: =ROUND(SUMIFS(资金台帐!$AB$6:$AB$6005,资金台帐!$T$6:$T$6005,$Q12,资金台帐!$U$6:$U$6005,"收入",资金台帐!$O$6:$O$6005,IF($C$3="全部","?*",$C$3),资金台帐!$N$6:$N$6005,">="&DATE($F$3,2,1),资金台帐!$N$6:$N$6005,"<"&DATE($F$3,2+1,1))-SUMIFS(资金台帐!$AC$6:$AC$6005,资金台帐!$T$6:$T$6005,$Q12,资金台帐!$U$6:$U$6005,"收入",资金台帐!$O$6:$O$6005,IF($C$3="全部","?*",$C$3),资金台帐!$N$6:$N$6005,">="&DATE($F$3,2,1),资金台帐!$N$6:$N$6005,"<"&DATE($F$3,2+1,1)),2) -> 0 | E12: =ROUND(SUMIFS(资金台帐!$AB$6:$AB$6005,资金台帐!$T$6:$T$6005,$Q12,资金台帐!$U$6:$U$6005,"收入",资金台帐!$O$6:$O$6005,IF($C$3="全部","?*",$C$3),资金台帐!$N$6:$N$6005,">="&DATE($F$3,3,1),资金台帐!$N$6:$N$6005,"<"&DATE($F$3,3+1,1))-SUMIFS(资金台帐!$AC$6:$AC$6005,资金台帐!$T$6:$T$6005,$Q12,资金台帐!$U$6:$U$6005,"收入",资金台帐!$O$6:$O$6005,IF($C$3="全部","?*",$C$3),资金台帐!$N$6:$N$6005,">="&DATE($F$3,3,1),资金台帐!$N$6:$N$6005,"<"&DATE($F$3,3+1,1)),2) -> 0 | F12: =ROUND(SUMIFS(资金台帐!$AB$6:$AB$6005,资金台帐!$T$6:$T$6005,$Q12,资金台帐!$U$6:$U$6005,"收入",资金台帐!$O$6:$O$6005,IF($C$3="全部","?*",$C$3),资金台帐!$N$6:$N$6005,">="&DATE($F$3,4,1),资金台帐!$N$6:$N$6005,"<"&DATE($F$3,4+1,1))-SUMIFS(资金台帐!$AC$6:$AC$6005,资金台帐!$T$6:$T$6005,$Q12,资金台帐!$U$6:$U$6005,"收入",资金台帐!$O$6:$O$6005,IF($C$3="全部","?*",$C$3),资金台帐!$N$6:$N$6005,">="&DATE($F$3,4,1),资金台帐!$N$6:$N$6005,"<"&DATE($F$3,4+1,1)),2) -> 0 | G12: =ROUND(SUMIFS(资金台帐!$AB$6:$AB$6005,资金台帐!$T$6:$T$6005,$Q12,资金台帐!$U$6:$U$6005,"收入",资金台帐!$O$6:$O$6005,IF($C$3="全部","?*",$C$3),资金台帐!$N$6:$N$6005,">="&DATE($F$3,5,1),资金台帐!$N$6:$N$6005,"<"&DATE($F$3,5+1,1))-SUMIFS(资金台帐!$AC$6:$AC$6005,资金台帐!$T$6:$T$6005,$Q12,资金台帐!$U$6:$U$6005,"收入",资金台帐!$O$6:$O$6005,IF($C$3="全部","?*",$C$3),资金台帐!$N$6:$N$6005,">="&DATE($F$3,5,1),资金台帐!$N$6:$N$6005,"<"&DATE($F$3,5+1,1)),2) -> 0 | H12: =ROUND(SUMIFS(资金台帐!$AB$6:$AB$6005,资金台帐!$T$6:$T$6005,$Q12,资金台帐!$U$6:$U$6005,"收入",资金台帐!$O$6:$O$6005,IF($C$3="全部","?*",$C$3),资金台帐!$N$6:$N$6005,">="&DATE($F$3,6,1),资金台帐!$N$6:$N$6005,"<"&DATE($F$3,6+1,1))-SUMIFS(资金台帐!$AC$6:$AC$6005,资金台帐!$T$6:$T$6005,$Q12,资金台帐!$U$6:$U$6005,"收入",资金台帐!$O$6:$O$6005,IF($C$3="全部","?*",$C$3),资金台帐!$N$6:$N$6005,">="&DATE($F$3,6,1),资金台帐!$N$6:$N$6005,"<"&DATE($F$3,6+1,1)),2) -> 0 | I12: =ROUND(SUMIFS(资金台帐!$AB$6:$AB$6005,资金台帐!$T$6:$T$6005,$Q12,资金台帐!$U$6:$U$6005,"收入",资金台帐!$O$6:$O$6005,IF($C$3="全部","?*",$C$3),资金台帐!$N$6:$N$6005,">="&DATE($F$3,7,1),资金台帐!$N$6:$N$6005,"<"&DATE($F$3,7+1,1))-SUMIFS(资金台帐!$AC$6:$AC$6005,资金台帐!$T$6:$T$6005,$Q12,资金台帐!$U$6:$U$6005,"收入",资金台帐!$O$6:$O$6005,IF($C$3="全部","?*",$C$3),资金台帐!$N$6:$N$6005,">="&DATE($F$3,7,1),资金台帐!$N$6:$N$6005,"<"&DATE($F$3,7+1,1)),2) -> 0 | J12: =ROUND(SUMIFS(资金台帐!$AB$6:$AB$6005,资金台帐!$T$6:$T$6005,$Q12,资金台帐!$U$6:$U$6005,"收入",资金台帐!$O$6:$O$6005,IF($C$3="全部","?*",$C$3),资金台帐!$N$6:$N$6005,">="&DATE($F$3,8,1),资金台帐!$N$6:$N$6005,"<"&DATE($F$3,8+1,1))-SUMIFS(资金台帐!$AC$6:$AC$6005,资金台帐!$T$6:$T$6005,$Q12,资金台帐!$U$6:$U$6005,"收入",资金台帐!$O$6:$O$6005,IF($C$3="全部","?*",$C$3),资金台帐!$N$6:$N$6005,">="&DATE($F$3,8,1),资金台帐!$N$6:$N$6005,"<"&DATE($F$3,8+1,1)),2) -> 0 | K12: =ROUND(SUMIFS(资金台帐!$AB$6:$AB$6005,资金台帐!$T$6:$T$6005,$Q12,资金台帐!$U$6:$U$6005,"收入",资金台帐!$O$6:$O$6005,IF($C$3="全部","?*",$C$3),资金台帐!$N$6:$N$6005,">="&DATE($F$3,9,1),资金台帐!$N$6:$N$6005,"<"&DATE($F$3,9+1,1))-SUMIFS(资金台帐!$AC$6:$AC$6005,资金台帐!$T$6:$T$6005,$Q12,资金台帐!$U$6:$U$6005,"收入",资金台帐!$O$6:$O$6005,IF($C$3="全部","?*",$C$3),资金台帐!$N$6:$N$6005,">="&DATE($F$3,9,1),资金台帐!$N$6:$N$6005,"<"&DATE($F$3,9+1,1)),2) -> 0 | L12: =ROUND(SUMIFS(资金台帐!$AB$6:$AB$6005,资金台帐!$T$6:$T$6005,$Q12,资金台帐!$U$6:$U$6005,"收入",资金台帐!$O$6:$O$6005,IF($C$3="全部","?*",$C$3),资金台帐!$N$6:$N$6005,">="&DATE($F$3,10,1),资金台帐!$N$6:$N$6005,"<"&DATE($F$3,10+1,1))-SUMIFS(资金台帐!$AC$6:$AC$6005,资金台帐!$T$6:$T$6005,$Q12,资金台帐!$U$6:$U$6005,"收入",资金台帐!$O$6:$O$6005,IF($C$3="全部","?*",$C$3),资金台帐!$N$6:$N$6005,">="&DATE($F$3,10,1),资金台帐!$N$6:$N$6005,"<"&DATE($F$3,10+1,1)),2) -> 0 | M12: =ROUND(SUMIFS(资金台帐!$AB$6:$AB$6005,资金台帐!$T$6:$T$6005,$Q12,资金台帐!$U$6:$U$6005,"收入",资金台帐!$O$6:$O$6005,IF($C$3="全部","?*",$C$3),资金台帐!$N$6:$N$6005,">="&DATE($F$3,11,1),资金台帐!$N$6:$N$6005,"<"&DATE($F$3,11+1,1))-SUMIFS(资金台帐!$AC$6:$AC$6005,资金台帐!$T$6:$T$6005,$Q12,资金台帐!$U$6:$U$6005,"收入",资金台帐!$O$6:$O$6005,IF($C$3="全部","?*",$C$3),资金台帐!$N$6:$N$6005,">="&DATE($F$3,11,1),资金台帐!$N$6:$N$6005,"<"&DATE($F$3,11+1,1)),2) -> 0 | N12: =ROUND(SUMIFS(资金台帐!$AB$6:$AB$6005,资金台帐!$T$6:$T$6005,$Q12,资金台帐!$U$6:$U$6005,"收入",资金台帐!$O$6:$O$6005,IF($C$3="全部","?*",$C$3),资金台帐!$N$6:$N$6005,">="&DATE($F$3,12,1),资金台帐!$N$6:$N$6005,"<"&DATE($F$3,12+1,1))-SUMIFS(资金台帐!$AC$6:$AC$6005,资金台帐!$T$6:$T$6005,$Q12,资金台帐!$U$6:$U$6005,"收入",资金台帐!$O$6:$O$6005,IF($C$3="全部","?*",$C$3),资金台帐!$N$6:$N$6005,">="&DATE($F$3,12,1),资金台帐!$N$6:$N$6005,"<"&DATE($F$3,12+1,1)),2) -> 0 | O12: =ROUND(SUM(C12:N12),2) -> 0 | P12: =IF(N($O$16)=0,"",O12/$O$16) -> 0 | Q12: =基础资料!$U$12&"" -> 转介绍
B13: =IF(基础资料!$W$13="",基础资料!$U$13&"",基础资料!$W$13&"") -> 园区返税 | C13: =ROUND(SUMIFS(资金台帐!$AB$6:$AB$6005,资金台帐!$T$6:$T$6005,$Q13,资金台帐!$U$6:$U$6005,"收入",资金台帐!$O$6:$O$6005,IF($C$3="全部","?*",$C$3),资金台帐!$N$6:$N$6005,">="&DATE($F$3,1,1),资金台帐!$N$6:$N$6005,"<"&DATE($F$3,1+1,1))-SUMIFS(资金台帐!$AC$6:$AC$6005,资金台帐!$T$6:$T$6005,$Q13,资金台帐!$U$6:$U$6005,"收入",资金台帐!$O$6:$O$6005,IF($C$3="全部","?*",$C$3),资金台帐!$N$6:$N$6005,">="&DATE($F$3,1,1),资金台帐!$N$6:$N$6005,"<"&DATE($F$3,1+1,1)),2) -> 0 | D13: =ROUND(SUMIFS(资金台帐!$AB$6:$AB$6005,资金台帐!$T$6:$T$6005,$Q13,资金台帐!$U$6:$U$6005,"收入",资金台帐!$O$6:$O$6005,IF($C$3="全部","?*",$C$3),资金台帐!$N$6:$N$6005,">="&DATE($F$3,2,1),资金台帐!$N$6:$N$6005,"<"&DATE($F$3,2+1,1))-SUMIFS(资金台帐!$AC$6:$AC$6005,资金台帐!$T$6:$T$6005,$Q13,资金台帐!$U$6:$U$6005,"收入",资金台帐!$O$6:$O$6005,IF($C$3="全部","?*",$C$3),资金台帐!$N$6:$N$6005,">="&DATE($F$3,2,1),资金台帐!$N$6:$N$6005,"<"&DATE($F$3,2+1,1)),2) -> 0 | E13: =ROUND(SUMIFS(资金台帐!$AB$6:$AB$6005,资金台帐!$T$6:$T$6005,$Q13,资金台帐!$U$6:$U$6005,"收入",资金台帐!$O$6:$O$6005,IF($C$3="全部","?*",$C$3),资金台帐!$N$6:$N$6005,">="&DATE($F$3,3,1),资金台帐!$N$6:$N$6005,"<"&DATE($F$3,3+1,1))-SUMIFS(资金台帐!$AC$6:$AC$6005,资金台帐!$T$6:$T$6005,$Q13,资金台帐!$U$6:$U$6005,"收入",资金台帐!$O$6:$O$6005,IF($C$3="全部","?*",$C$3),资金台帐!$N$6:$N$6005,">="&DATE($F$3,3,1),资金台帐!$N$6:$N$6005,"<"&DATE($F$3,3+1,1)),2) -> 0 | F13: =ROUND(SUMIFS(资金台帐!$AB$6:$AB$6005,资金台帐!$T$6:$T$6005,$Q13,资金台帐!$U$6:$U$6005,"收入",资金台帐!$O$6:$O$6005,IF($C$3="全部","?*",$C$3),资金台帐!$N$6:$N$6005,">="&DATE($F$3,4,1),资金台帐!$N$6:$N$6005,"<"&DATE($F$3,4+1,1))-SUMIFS(资金台帐!$AC$6:$AC$6005,资金台帐!$T$6:$T$6005,$Q13,资金台帐!$U$6:$U$6005,"收入",资金台帐!$O$6:$O$6005,IF($C$3="全部","?*",$C$3),资金台帐!$N$6:$N$6005,">="&DATE($F$3,4,1),资金台帐!$N$6:$N$6005,"<"&DATE($F$3,4+1,1)),2) -> 0 | G13: =ROUND(SUMIFS(资金台帐!$AB$6:$AB$6005,资金台帐!$T$6:$T$6005,$Q13,资金台帐!$U$6:$U$6005,"收入",资金台帐!$O$6:$O$6005,IF($C$3="全部","?*",$C$3),资金台帐!$N$6:$N$6005,">="&DATE($F$3,5,1),资金台帐!$N$6:$N$6005,"<"&DATE($F$3,5+1,1))-SUMIFS(资金台帐!$AC$6:$AC$6005,资金台帐!$T$6:$T$6005,$Q13,资金台帐!$U$6:$U$6005,"收入",资金台帐!$O$6:$O$6005,IF($C$3="全部","?*",$C$3),资金台帐!$N$6:$N$6005,">="&DATE($F$3,5,1),资金台帐!$N$6:$N$6005,"<"&DATE($F$3,5+1,1)),2) -> 0 | H13: =ROUND(SUMIFS(资金台帐!$AB$6:$AB$6005,资金台帐!$T$6:$T$6005,$Q13,资金台帐!$U$6:$U$6005,"收入",资金台帐!$O$6:$O$6005,IF($C$3="全部","?*",$C$3),资金台帐!$N$6:$N$6005,">="&DATE($F$3,6,1),资金台帐!$N$6:$N$6005,"<"&DATE($F$3,6+1,1))-SUMIFS(资金台帐!$AC$6:$AC$6005,资金台帐!$T$6:$T$6005,$Q13,资金台帐!$U$6:$U$6005,"收入",资金台帐!$O$6:$O$6005,IF($C$3="全部","?*",$C$3),资金台帐!$N$6:$N$6005,">="&DATE($F$3,6,1),资金台帐!$N$6:$N$6005,"<"&DATE($F$3,6+1,1)),2) -> 0 | I13: =ROUND(SUMIFS(资金台帐!$AB$6:$AB$6005,资金台帐!$T$6:$T$6005,$Q13,资金台帐!$U$6:$U$6005,"收入",资金台帐!$O$6:$O$6005,IF($C$3="全部","?*",$C$3),资金台帐!$N$6:$N$6005,">="&DATE($F$3,7,1),资金台帐!$N$6:$N$6005,"<"&DATE($F$3,7+1,1))-SUMIFS(资金台帐!$AC$6:$AC$6005,资金台帐!$T$6:$T$6005,$Q13,资金台帐!$U$6:$U$6005,"收入",资金台帐!$O$6:$O$6005,IF($C$3="全部","?*",$C$3),资金台帐!$N$6:$N$6005,">="&DATE($F$3,7,1),资金台帐!$N$6:$N$6005,"<"&DATE($F$3,7+1,1)),2) -> 0 | J13: =ROUND(SUMIFS(资金台帐!$AB$6:$AB$6005,资金台帐!$T$6:$T$6005,$Q13,资金台帐!$U$6:$U$6005,"收入",资金台帐!$O$6:$O$6005,IF($C$3="全部","?*",$C$3),资金台帐!$N$6:$N$6005,">="&DATE($F$3,8,1),资金台帐!$N$6:$N$6005,"<"&DATE($F$3,8+1,1))-SUMIFS(资金台帐!$AC$6:$AC$6005,资金台帐!$T$6:$T$6005,$Q13,资金台帐!$U$6:$U$6005,"收入",资金台帐!$O$6:$O$6005,IF($C$3="全部","?*",$C$3),资金台帐!$N$6:$N$6005,">="&DATE($F$3,8,1),资金台帐!$N$6:$N$6005,"<"&DATE($F$3,8+1,1)),2) -> 0 | K13: =ROUND(SUMIFS(资金台帐!$AB$6:$AB$6005,资金台帐!$T$6:$T$6005,$Q13,资金台帐!$U$6:$U$6005,"收入",资金台帐!$O$6:$O$6005,IF($C$3="全部","?*",$C$3),资金台帐!$N$6:$N$6005,">="&DATE($F$3,9,1),资金台帐!$N$6:$N$6005,"<"&DATE($F$3,9+1,1))-SUMIFS(资金台帐!$AC$6:$AC$6005,资金台帐!$T$6:$T$6005,$Q13,资金台帐!$U$6:$U$6005,"收入",资金台帐!$O$6:$O$6005,IF($C$3="全部","?*",$C$3),资金台帐!$N$6:$N$6005,">="&DATE($F$3,9,1),资金台帐!$N$6:$N$6005,"<"&DATE($F$3,9+1,1)),2) -> 0 | L13: =ROUND(SUMIFS(资金台帐!$AB$6:$AB$6005,资金台帐!$T$6:$T$6005,$Q13,资金台帐!$U$6:$U$6005,"收入",资金台帐!$O$6:$O$6005,IF($C$3="全部","?*",$C$3),资金台帐!$N$6:$N$6005,">="&DATE($F$3,10,1),资金台帐!$N$6:$N$6005,"<"&DATE($F$3,10+1,1))-SUMIFS(资金台帐!$AC$6:$AC$6005,资金台帐!$T$6:$T$6005,$Q13,资金台帐!$U$6:$U$6005,"收入",资金台帐!$O$6:$O$6005,IF($C$3="全部","?*",$C$3),资金台帐!$N$6:$N$6005,">="&DATE($F$3,10,1),资金台帐!$N$6:$N$6005,"<"&DATE($F$3,10+1,1)),2) -> 0 | M13: =ROUND(SUMIFS(资金台帐!$AB$6:$AB$6005,资金台帐!$T$6:$T$6005,$Q13,资金台帐!$U$6:$U$6005,"收入",资金台帐!$O$6:$O$6005,IF($C$3="全部","?*",$C$3),资金台帐!$N$6:$N$6005,">="&DATE($F$3,11,1),资金台帐!$N$6:$N$6005,"<"&DATE($F$3,11+1,1))-SUMIFS(资金台帐!$AC$6:$AC$6005,资金台帐!$T$6:$T$6005,$Q13,资金台帐!$U$6:$U$6005,"收入",资金台帐!$O$6:$O$6005,IF($C$3="全部","?*",$C$3),资金台帐!$N$6:$N$6005,">="&DATE($F$3,11,1),资金台帐!$N$6:$N$6005,"<"&DATE($F$3,11+1,1)),2) -> 0 | N13: =ROUND(SUMIFS(资金台帐!$AB$6:$AB$6005,资金台帐!$T$6:$T$6005,$Q13,资金台帐!$U$6:$U$6005,"收入",资金台帐!$O$6:$O$6005,IF($C$3="全部","?*",$C$3),资金台帐!$N$6:$N$6005,">="&DATE($F$3,12,1),资金台帐!$N$6:$N$6005,"<"&DATE($F$3,12+1,1))-SUMIFS(资金台帐!$AC$6:$AC$6005,资金台帐!$T$6:$T$6005,$Q13,资金台帐!$U$6:$U$6005,"收入",资金台帐!$O$6:$O$6005,IF($C$3="全部","?*",$C$3),资金台帐!$N$6:$N$6005,">="&DATE($F$3,12,1),资金台帐!$N$6:$N$6005,"<"&DATE($F$3,12+1,1)),2) -> 0 | O13: =ROUND(SUM(C13:N13),2) -> 0 | P13: =IF(N($O$16)=0,"",O13/$O$16) -> 0 | Q13: =基础资料!$U$13&"" -> 园区返税
B14: =IF(基础资料!$W$14="",基础资料!$U$14&"",基础资料!$W$14&"") -> 咨询服务 | C14: =ROUND(SUMIFS(资金台帐!$AB$6:$AB$6005,资金台帐!$T$6:$T$6005,$Q14,资金台帐!$U$6:$U$6005,"收入",资金台帐!$O$6:$O$6005,IF($C$3="全部","?*",$C$3),资金台帐!$N$6:$N$6005,">="&DATE($F$3,1,1),资金台帐!$N$6:$N$6005,"<"&DATE($F$3,1+1,1))-SUMIFS(资金台帐!$AC$6:$AC$6005,资金台帐!$T$6:$T$6005,$Q14,资金台帐!$U$6:$U$6005,"收入",资金台帐!$O$6:$O$6005,IF($C$3="全部","?*",$C$3),资金台帐!$N$6:$N$6005,">="&DATE($F$3,1,1),资金台帐!$N$6:$N$6005,"<"&DATE($F$3,1+1,1)),2) -> 0 | D14: =ROUND(SUMIFS(资金台帐!$AB$6:$AB$6005,资金台帐!$T$6:$T$6005,$Q14,资金台帐!$U$6:$U$6005,"收入",资金台帐!$O$6:$O$6005,IF($C$3="全部","?*",$C$3),资金台帐!$N$6:$N$6005,">="&DATE($F$3,2,1),资金台帐!$N$6:$N$6005,"<"&DATE($F$3,2+1,1))-SUMIFS(资金台帐!$AC$6:$AC$6005,资金台帐!$T$6:$T$6005,$Q14,资金台帐!$U$6:$U$6005,"收入",资金台帐!$O$6:$O$6005,IF($C$3="全部","?*",$C$3),资金台帐!$N$6:$N$6005,">="&DATE($F$3,2,1),资金台帐!$N$6:$N$6005,"<"&DATE($F$3,2+1,1)),2) -> 0 | E14: =ROUND(SUMIFS(资金台帐!$AB$6:$AB$6005,资金台帐!$T$6:$T$6005,$Q14,资金台帐!$U$6:$U$6005,"收入",资金台帐!$O$6:$O$6005,IF($C$3="全部","?*",$C$3),资金台帐!$N$6:$N$6005,">="&DATE($F$3,3,1),资金台帐!$N$6:$N$6005,"<"&DATE($F$3,3+1,1))-SUMIFS(资金台帐!$AC$6:$AC$6005,资金台帐!$T$6:$T$6005,$Q14,资金台帐!$U$6:$U$6005,"收入",资金台帐!$O$6:$O$6005,IF($C$3="全部","?*",$C$3),资金台帐!$N$6:$N$6005,">="&DATE($F$3,3,1),资金台帐!$N$6:$N$6005,"<"&DATE($F$3,3+1,1)),2) -> 0 | F14: =ROUND(SUMIFS(资金台帐!$AB$6:$AB$6005,资金台帐!$T$6:$T$6005,$Q14,资金台帐!$U$6:$U$6005,"收入",资金台帐!$O$6:$O$6005,IF($C$3="全部","?*",$C$3),资金台帐!$N$6:$N$6005,">="&DATE($F$3,4,1),资金台帐!$N$6:$N$6005,"<"&DATE($F$3,4+1,1))-SUMIFS(资金台帐!$AC$6:$AC$6005,资金台帐!$T$6:$T$6005,$Q14,资金台帐!$U$6:$U$6005,"收入",资金台帐!$O$6:$O$6005,IF($C$3="全部","?*",$C$3),资金台帐!$N$6:$N$6005,">="&DATE($F$3,4,1),资金台帐!$N$6:$N$6005,"<"&DATE($F$3,4+1,1)),2) -> 0 | G14: =ROUND(SUMIFS(资金台帐!$AB$6:$AB$6005,资金台帐!$T$6:$T$6005,$Q14,资金台帐!$U$6:$U$6005,"收入",资金台帐!$O$6:$O$6005,IF($C$3="全部","?*",$C$3),资金台帐!$N$6:$N$6005,">="&DATE($F$3,5,1),资金台帐!$N$6:$N$6005,"<"&DATE($F$3,5+1,1))-SUMIFS(资金台帐!$AC$6:$AC$6005,资金台帐!$T$6:$T$6005,$Q14,资金台帐!$U$6:$U$6005,"收入",资金台帐!$O$6:$O$6005,IF($C$3="全部","?*",$C$3),资金台帐!$N$6:$N$6005,">="&DATE($F$3,5,1),资金台帐!$N$6:$N$6005,"<"&DATE($F$3,5+1,1)),2) -> 0 | H14: =ROUND(SUMIFS(资金台帐!$AB$6:$AB$6005,资金台帐!$T$6:$T$6005,$Q14,资金台帐!$U$6:$U$6005,"收入",资金台帐!$O$6:$O$6005,IF($C$3="全部","?*",$C$3),资金台帐!$N$6:$N$6005,">="&DATE($F$3,6,1),资金台帐!$N$6:$N$6005,"<"&DATE($F$3,6+1,1))-SUMIFS(资金台帐!$AC$6:$AC$6005,资金台帐!$T$6:$T$6005,$Q14,资金台帐!$U$6:$U$6005,"收入",资金台帐!$O$6:$O$6005,IF($C$3="全部","?*",$C$3),资金台帐!$N$6:$N$6005,">="&DATE($F$3,6,1),资金台帐!$N$6:$N$6005,"<"&DATE($F$3,6+1,1)),2) -> 0 | I14: =ROUND(SUMIFS(资金台帐!$AB$6:$AB$6005,资金台帐!$T$6:$T$6005,$Q14,资金台帐!$U$6:$U$6005,"收入",资金台帐!$O$6:$O$6005,IF($C$3="全部","?*",$C$3),资金台帐!$N$6:$N$6005,">="&DATE($F$3,7,1),资金台帐!$N$6:$N$6005,"<"&DATE($F$3,7+1,1))-SUMIFS(资金台帐!$AC$6:$AC$6005,资金台帐!$T$6:$T$6005,$Q14,资金台帐!$U$6:$U$6005,"收入",资金台帐!$O$6:$O$6005,IF($C$3="全部","?*",$C$3),资金台帐!$N$6:$N$6005,">="&DATE($F$3,7,1),资金台帐!$N$6:$N$6005,"<"&DATE($F$3,7+1,1)),2) -> 0 | J14: =ROUND(SUMIFS(资金台帐!$AB$6:$AB$6005,资金台帐!$T$6:$T$6005,$Q14,资金台帐!$U$6:$U$6005,"收入",资金台帐!$O$6:$O$6005,IF($C$3="全部","?*",$C$3),资金台帐!$N$6:$N$6005,">="&DATE($F$3,8,1),资金台帐!$N$6:$N$6005,"<"&DATE($F$3,8+1,1))-SUMIFS(资金台帐!$AC$6:$AC$6005,资金台帐!$T$6:$T$6005,$Q14,资金台帐!$U$6:$U$6005,"收入",资金台帐!$O$6:$O$6005,IF($C$3="全部","?*",$C$3),资金台帐!$N$6:$N$6005,">="&DATE($F$3,8,1),资金台帐!$N$6:$N$6005,"<"&DATE($F$3,8+1,1)),2) -> 0 | K14: =ROUND(SUMIFS(资金台帐!$AB$6:$AB$6005,资金台帐!$T$6:$T$6005,$Q14,资金台帐!$U$6:$U$6005,"收入",资金台帐!$O$6:$O$6005,IF($C$3="全部","?*",$C$3),资金台帐!$N$6:$N$6005,">="&DATE($F$3,9,1),资金台帐!$N$6:$N$6005,"<"&DATE($F$3,9+1,1))-SUMIFS(资金台帐!$AC$6:$AC$6005,资金台帐!$T$6:$T$6005,$Q14,资金台帐!$U$6:$U$6005,"收入",资金台帐!$O$6:$O$6005,IF($C$3="全部","?*",$C$3),资金台帐!$N$6:$N$6005,">="&DATE($F$3,9,1),资金台帐!$N$6:$N$6005,"<"&DATE($F$3,9+1,1)),2) -> 0 | L14: =ROUND(SUMIFS(资金台帐!$AB$6:$AB$6005,资金台帐!$T$6:$T$6005,$Q14,资金台帐!$U$6:$U$6005,"收入",资金台帐!$O$6:$O$6005,IF($C$3="全部","?*",$C$3),资金台帐!$N$6:$N$6005,">="&DATE($F$3,10,1),资金台帐!$N$6:$N$6005,"<"&DATE($F$3,10+1,1))-SUMIFS(资金台帐!$AC$6:$AC$6005,资金台帐!$T$6:$T$6005,$Q14,资金台帐!$U$6:$U$6005,"收入",资金台帐!$O$6:$O$6005,IF($C$3="全部","?*",$C$3),资金台帐!$N$6:$N$6005,">="&DATE($F$3,10,1),资金台帐!$N$6:$N$6005,"<"&DATE($F$3,10+1,1)),2) -> 0 | M14: =ROUND(SUMIFS(资金台帐!$AB$6:$AB$6005,资金台帐!$T$6:$T$6005,$Q14,资金台帐!$U$6:$U$6005,"收入",资金台帐!$O$6:$O$6005,IF($C$3="全部","?*",$C$3),资金台帐!$N$6:$N$6005,">="&DATE($F$3,11,1),资金台帐!$N$6:$N$6005,"<"&DATE($F$3,11+1,1))-SUMIFS(资金台帐!$AC$6:$AC$6005,资金台帐!$T$6:$T$6005,$Q14,资金台帐!$U$6:$U$6005,"收入",资金台帐!$O$6:$O$6005,IF($C$3="全部","?*",$C$3),资金台帐!$N$6:$N$6005,">="&DATE($F$3,11,1),资金台帐!$N$6:$N$6005,"<"&DATE($F$3,11+1,1)),2) -> 0 | N14: =ROUND(SUMIFS(资金台帐!$AB$6:$AB$6005,资金台帐!$T$6:$T$6005,$Q14,资金台帐!$U$6:$U$6005,"收入",资金台帐!$O$6:$O$6005,IF($C$3="全部","?*",$C$3),资金台帐!$N$6:$N$6005,">="&DATE($F$3,12,1),资金台帐!$N$6:$N$6005,"<"&DATE($F$3,12+1,1))-SUMIFS(资金台帐!$AC$6:$AC$6005,资金台帐!$T$6:$T$6005,$Q14,资金台帐!$U$6:$U$6005,"收入",资金台帐!$O$6:$O$6005,IF($C$3="全部","?*",$C$3),资金台帐!$N$6:$N$6005,">="&DATE($F$3,12,1),资金台帐!$N$6:$N$6005,"<"&DATE($F$3,12+1,1)),2) -> 0 | O14: =ROUND(SUM(C14:N14),2) -> 0 | P14: =IF(N($O$16)=0,"",O14/$O$16) -> 0 | Q14: =基础资料!$U$14&"" -> 咨询服务
B15: =IF(COUNTIFS(基础资料!$V$5:$V$64,"收入",基础资料!$U$5:$U$64,"?*")>11,"其他（含新加项目）","其他") -> 其他 | C15: =ROUND(SUMIFS(资金台帐!$AB$6:$AB$6005,资金台帐!$U$6:$U$6005,"收入",资金台帐!$O$6:$O$6005,IF($C$3="全部","?*",$C$3),资金台帐!$N$6:$N$6005,">="&DATE($F$3,1,1),资金台帐!$N$6:$N$6005,"<"&DATE($F$3,1+1,1))-SUMIFS(资金台帐!$AC$6:$AC$6005,资金台帐!$U$6:$U$6005,"收入",资金台帐!$O$6:$O$6005,IF($C$3="全部","?*",$C$3),资金台帐!$N$6:$N$6005,">="&DATE($F$3,1,1),资金台帐!$N$6:$N$6005,"<"&DATE($F$3,1+1,1))-SUM(C5:C14),2) -> 0 | D15: =ROUND(SUMIFS(资金台帐!$AB$6:$AB$6005,资金台帐!$U$6:$U$6005,"收入",资金台帐!$O$6:$O$6005,IF($C$3="全部","?*",$C$3),资金台帐!$N$6:$N$6005,">="&DATE($F$3,2,1),资金台帐!$N$6:$N$6005,"<"&DATE($F$3,2+1,1))-SUMIFS(资金台帐!$AC$6:$AC$6005,资金台帐!$U$6:$U$6005,"收入",资金台帐!$O$6:$O$6005,IF($C$3="全部","?*",$C$3),资金台帐!$N$6:$N$6005,">="&DATE($F$3,2,1),资金台帐!$N$6:$N$6005,"<"&DATE($F$3,2+1,1))-SUM(D5:D14),2) -> 0 | E15: =ROUND(SUMIFS(资金台帐!$AB$6:$AB$6005,资金台帐!$U$6:$U$6005,"收入",资金台帐!$O$6:$O$6005,IF($C$3="全部","?*",$C$3),资金台帐!$N$6:$N$6005,">="&DATE($F$3,3,1),资金台帐!$N$6:$N$6005,"<"&DATE($F$3,3+1,1))-SUMIFS(资金台帐!$AC$6:$AC$6005,资金台帐!$U$6:$U$6005,"收入",资金台帐!$O$6:$O$6005,IF($C$3="全部","?*",$C$3),资金台帐!$N$6:$N$6005,">="&DATE($F$3,3,1),资金台帐!$N$6:$N$6005,"<"&DATE($F$3,3+1,1))-SUM(E5:E14),2) -> 0 | F15: =ROUND(SUMIFS(资金台帐!$AB$6:$AB$6005,资金台帐!$U$6:$U$6005,"收入",资金台帐!$O$6:$O$6005,IF($C$3="全部","?*",$C$3),资金台帐!$N$6:$N$6005,">="&DATE($F$3,4,1),资金台帐!$N$6:$N$6005,"<"&DATE($F$3,4+1,1))-SUMIFS(资金台帐!$AC$6:$AC$6005,资金台帐!$U$6:$U$6005,"收入",资金台帐!$O$6:$O$6005,IF($C$3="全部","?*",$C$3),资金台帐!$N$6:$N$6005,">="&DATE($F$3,4,1),资金台帐!$N$6:$N$6005,"<"&DATE($F$3,4+1,1))-SUM(F5:F14),2) -> 0 | G15: =ROUND(SUMIFS(资金台帐!$AB$6:$AB$6005,资金台帐!$U$6:$U$6005,"收入",资金台帐!$O$6:$O$6005,IF($C$3="全部","?*",$C$3),资金台帐!$N$6:$N$6005,">="&DATE($F$3,5,1),资金台帐!$N$6:$N$6005,"<"&DATE($F$3,5+1,1))-SUMIFS(资金台帐!$AC$6:$AC$6005,资金台帐!$U$6:$U$6005,"收入",资金台帐!$O$6:$O$6005,IF($C$3="全部","?*",$C$3),资金台帐!$N$6:$N$6005,">="&DATE($F$3,5,1),资金台帐!$N$6:$N$6005,"<"&DATE($F$3,5+1,1))-SUM(G5:G14),2) -> 0 | H15: =ROUND(SUMIFS(资金台帐!$AB$6:$AB$6005,资金台帐!$U$6:$U$6005,"收入",资金台帐!$O$6:$O$6005,IF($C$3="全部","?*",$C$3),资金台帐!$N$6:$N$6005,">="&DATE($F$3,6,1),资金台帐!$N$6:$N$6005,"<"&DATE($F$3,6+1,1))-SUMIFS(资金台帐!$AC$6:$AC$6005,资金台帐!$U$6:$U$6005,"收入",资金台帐!$O$6:$O$6005,IF($C$3="全部","?*",$C$3),资金台帐!$N$6:$N$6005,">="&DATE($F$3,6,1),资金台帐!$N$6:$N$6005,"<"&DATE($F$3,6+1,1))-SUM(H5:H14),2) -> 0 | I15: =ROUND(SUMIFS(资金台帐!$AB$6:$AB$6005,资金台帐!$U$6:$U$6005,"收入",资金台帐!$O$6:$O$6005,IF($C$3="全部","?*",$C$3),资金台帐!$N$6:$N$6005,">="&DATE($F$3,7,1),资金台帐!$N$6:$N$6005,"<"&DATE($F$3,7+1,1))-SUMIFS(资金台帐!$AC$6:$AC$6005,资金台帐!$U$6:$U$6005,"收入",资金台帐!$O$6:$O$6005,IF($C$3="全部","?*",$C$3),资金台帐!$N$6:$N$6005,">="&DATE($F$3,7,1),资金台帐!$N$6:$N$6005,"<"&DATE($F$3,7+1,1))-SUM(I5:I14),2) -> 0 | J15: =ROUND(SUMIFS(资金台帐!$AB$6:$AB$6005,资金台帐!$U$6:$U$6005,"收入",资金台帐!$O$6:$O$6005,IF($C$3="全部","?*",$C$3),资金台帐!$N$6:$N$6005,">="&DATE($F$3,8,1),资金台帐!$N$6:$N$6005,"<"&DATE($F$3,8+1,1))-SUMIFS(资金台帐!$AC$6:$AC$6005,资金台帐!$U$6:$U$6005,"收入",资金台帐!$O$6:$O$6005,IF($C$3="全部","?*",$C$3),资金台帐!$N$6:$N$6005,">="&DATE($F$3,8,1),资金台帐!$N$6:$N$6005,"<"&DATE($F$3,8+1,1))-SUM(J5:J14),2) -> 0 | K15: =ROUND(SUMIFS(资金台帐!$AB$6:$AB$6005,资金台帐!$U$6:$U$6005,"收入",资金台帐!$O$6:$O$6005,IF($C$3="全部","?*",$C$3),资金台帐!$N$6:$N$6005,">="&DATE($F$3,9,1),资金台帐!$N$6:$N$6005,"<"&DATE($F$3,9+1,1))-SUMIFS(资金台帐!$AC$6:$AC$6005,资金台帐!$U$6:$U$6005,"收入",资金台帐!$O$6:$O$6005,IF($C$3="全部","?*",$C$3),资金台帐!$N$6:$N$6005,">="&DATE($F$3,9,1),资金台帐!$N$6:$N$6005,"<"&DATE($F$3,9+1,1))-SUM(K5:K14),2) -> 0 | L15: =ROUND(SUMIFS(资金台帐!$AB$6:$AB$6005,资金台帐!$U$6:$U$6005,"收入",资金台帐!$O$6:$O$6005,IF($C$3="全部","?*",$C$3),资金台帐!$N$6:$N$6005,">="&DATE($F$3,10,1),资金台帐!$N$6:$N$6005,"<"&DATE($F$3,10+1,1))-SUMIFS(资金台帐!$AC$6:$AC$6005,资金台帐!$U$6:$U$6005,"收入",资金台帐!$O$6:$O$6005,IF($C$3="全部","?*",$C$3),资金台帐!$N$6:$N$6005,">="&DATE($F$3,10,1),资金台帐!$N$6:$N$6005,"<"&DATE($F$3,10+1,1))-SUM(L5:L14),2) -> 0 | M15: =ROUND(SUMIFS(资金台帐!$AB$6:$AB$6005,资金台帐!$U$6:$U$6005,"收入",资金台帐!$O$6:$O$6005,IF($C$3="全部","?*",$C$3),资金台帐!$N$6:$N$6005,">="&DATE($F$3,11,1),资金台帐!$N$6:$N$6005,"<"&DATE($F$3,11+1,1))-SUMIFS(资金台帐!$AC$6:$AC$6005,资金台帐!$U$6:$U$6005,"收入",资金台帐!$O$6:$O$6005,IF($C$3="全部","?*",$C$3),资金台帐!$N$6:$N$6005,">="&DATE($F$3,11,1),资金台帐!$N$6:$N$6005,"<"&DATE($F$3,11+1,1))-SUM(M5:M14),2) -> 0 | N15: =ROUND(SUMIFS(资金台帐!$AB$6:$AB$6005,资金台帐!$U$6:$U$6005,"收入",资金台帐!$O$6:$O$6005,IF($C$3="全部","?*",$C$3),资金台帐!$N$6:$N$6005,">="&DATE($F$3,12,1),资金台帐!$N$6:$N$6005,"<"&DATE($F$3,12+1,1))-SUMIFS(资金台帐!$AC$6:$AC$6005,资金台帐!$U$6:$U$6005,"收入",资金台帐!$O$6:$O$6005,IF($C$3="全部","?*",$C$3),资金台帐!$N$6:$N$6005,">="&DATE($F$3,12,1),资金台帐!$N$6:$N$6005,"<"&DATE($F$3,12+1,1))-SUM(N5:N14),2) -> 0 | O15: =ROUND(SUM(C15:N15),2) -> 0 | P15: =IF(N($O$16)=0,"",O15/$O$16) -> 0 | Q15: =基础资料!$U$15&"" -> 其他收入
B16: 小计 | C16: =ROUND(SUM(C5:C15),2) -> 0 | D16: =ROUND(SUM(D5:D15),2) -> 0 | E16: =ROUND(SUM(E5:E15),2) -> 0 | F16: =ROUND(SUM(F5:F15),2) -> 0 | G16: =ROUND(SUM(G5:G15),2) -> 0 | H16: =ROUND(SUM(H5:H15),2) -> 0 | I16: =ROUND(SUM(I5:I15),2) -> 0 | J16: =ROUND(SUM(J5:J15),2) -> 0 | ... O16: =ROUND(SUM(O5:O15),2) -> 171000 | P16: =IF(N($O$16)=0,"",O16/$O$16) -> 1
