Workbook

Sheet Sheet1
A1: 多帐户收支登记表
F2: 收入总额 | G2: 支出总额 | H2: 账户余额
F3: 68868685 | G3: 67149704 | H3: 4429622.6
A4: 序号 | B4: 日期 | C4: 公司账户 | D4: 业务类别 | E4: 摘要内容 | F4: 收入 | G4: 支出 | H4: 账户余额 | I4: 公司 | J4: 电商平台 | K4: 会计科目 | L4: 收支所属月份 | M4: 返利名称 | N4: 月份 | O4: 员工
A5: 1 | B5: 46023 | C5: 邮政公户 | E5: 期初余额 | H5: 1674705.1 | N5: 202601
A6: 2 | B6: 46023 | C6: 农发行公户 | E6: 期初余额 | H6: 230615.22 | N6: 202601
A7: 3 | B7: 46023 | C7: 邢台银行公户 | E7: 期初余额 | H7: 61632.53 | N7: 202601
A8: 4 | B8: 46023 | C8: 农业银行公户 | E8: 期初余额 | H8: 81.65 | N8: 202601
A9: 5 | B9: 46023 | C9: 信用社公户 | E9: 期初余额 | H9: 57038.92
A10: 6 | B10: 46023 | C10: 建行公户 | E10: 期初余额 | H10: 81941.47 | N10: 202601
A11: 7 | B11: 46023 | C11: 沧州个人 | E11: 期初余额 | H11: 15.62 | N11: 202601
A12: 8 | B12: 46023 | C12: 信用社个人 | E12: 期初余额 | H12: 258118.28 | N12: 202601
A13: 9 | B13: 46023 | C13: 邮政个人 | E13: 期初余额 | H13: 292251.86 | N13: 202601
A14: 10 | B14: 46023 | C14: 建行个人 | E14: 期初余额 | H14: 51712.92 | N14: 202601
A15: 11 | B15: 46023 | C15: 现金 | E15: 期初余额 | H15: 2528.16 | N15: 202601
A16: 12 | B16: 46023 | C16: 五优68店邮政 | E16: 期初余额 | N16: 202601
A17: 13 | B17: 46023 | C17: 五优3店邮政 | E17: 期初余额 | N17: 202601
A18: 14 | B18: 46023 | C18: 五优43店邮政 | E18: 期初余额 | N18: 202601
A19: 15 | B19: 46023 | C19: 邮政个人 | D19: 营业款 | E19: 60店郭静钰 | F19: 350.68 | H19: 292602.54 | I19: 博景分店（60分店） | L19: 202512 | N19: 202601
A20: 16 | B20: 46023 | C20: 邮政个人 | D20: 营业款 | E20: 67店姜慧娟 | F20: 619.65 | H20: 293222.19 | I20: 博亮分店（67分店） | L20: 202512 | N20: 202601
A21: 17 | B21: 46023 | C21: 邮政个人 | D21: 营业款 | E21: 68店李国霞 | F21: 1837.2 | H21: 295059.39 | I21: 博山分店（68分店） | L21: 202512 | N21: 202601
A22: 18 | B22: 46023 | C22: 邮政个人 | D22: 营业款 | E22: 62店张彦 | F22: 1655.68 | H22: 296715.07 | I22: 西范村分店（62分店） | L22: 202512 | N22: 202601
A23: 19 | B23: 46023 | C23: 邮政个人 | D23: 营业款 | E23: 2店王玉彩 | F23: 31812.4 | H23: 328527.47 | I23: 新隆分店（2分店） | L23: 202512 | N23: 202601
A24: 20 | B24: 46023 | C24: 邮政个人 | D24: 营业款 | E24: 55店杨芳 | F24: 2336.46 | H24: 330863.93 | I24: 博魏分店（55分店） | L24: 202512 | N24: 202601
A25: 21 | B25: 46023 | C25: 邮政个人 | E25: 转入国燕岭工商银行 | G25: 300000 | H25: 30863.93 | I25: 股东借款 | L25: 202601 | N25: 202601
A26: 22 | B26: 46023 | C26: 邮政个人 | D26: 内部转账 | E26: 邮政公户转入邮政个人 | F26: 500000 | H26: 530863.93 | I26: 内部转款 | L26: 202601 | N26: 202601
A27: 23 | B27: 46024 | C27: 邮政个人 | E27: 转入国燕岭工商银行 | G27: 500000 | H27: 30863.93 | I27: 股东借款 | L27: 202601 | N27: 202601
A28: 24 | B28: 46024 | C28: 邮政个人 | D28: 营业款 | E28: 5店李永娜 | F28: 7465.09 | H28: 38329.02 | I28: 象城街分店（5店） | L28: 202512 | N28: 202601
A29: 25 | B29: 46024 | C29: 邮政个人 | D29: 营业款 | E29: 63店曹雪雪 | F29: 2972.05 | H29: 41301.07 | I29: 博医分店（63分店） | L29: 202512 | N29: 202601
A30: 26 | B30: 46024 | C30: 邮政个人 | D30: 营业款 | E30: 4店张彩红 | F30: 8103.01 | H30: 49404.08 | I30: 东关分店（4分店） | L30: 202512 | N30: 202601
A31: 27 | B31: 46024 | C31: 邮政个人 | D31: 营业款 | E31: 24店曹玉丽 | F31: 16033.13 | H31: 65437.21 | I31: 高村分店（24分店） | L31: 202512 | N31: 202601
A32: 28 | B32: 46024 | C32: 邮政个人 | D32: 营业款 | E32: 66店冯丽 | F32: 4593.28 | H32: 70030.49 | I32: 博实分店（66分店） | L32: 202512 | N32: 202601
A33: 29 | B33: 46024 | C33: 邮政个人 | D33: 营业款 | E33: 57店刘国华 | F33: 13343.62 | H33: 83374.11 | I33: 临城县博城分店（57分店） | L33: 202512 | N33: 202601
A34: 30 | B34: 46024 | C34: 邮政个人 | D34: 营业款 | E34: 23店田少芳 | F34: 3392.35 | H34: 86766.46 | I34: 尹村分店(23分店） | L34: 202512 | N34: 202601
A35: 31 | B35: 46025 | C35: 邮政个人 | D35: 营业款 | E35: 3店王惠娟 | F35: 5578.88 | H35: 92345.34 | I35: 康庄东路分店（3店） | L35: 202512 | N35: 202601
A36: 32 | B36: 46026 | C36: 邮政个人 | D36: 营业款 | E36: 2店王玉彩 | F36: 28189.83 | H36: 120535.17 | I36: 新隆分店（2分店） | L36: 202601 | N36: 202601
A37: 33 | B37: 46027 | C37: 邮政个人 | D37: 营业款 | E37: 5店李永娜 | F37: 6361.83 | H37: 126897 | I37: 象城街分店（5店） | L37: 202601 | N37: 202601
A38: 34 | B38: 46027 | C38: 邮政个人 | D38: 营业款 | E38: 5店李永娜 | F38: 2 | H38: 126899 | I38: 象城街分店（5店） | L38: 202512 | N38: 202601
A39: 35 | B39: 46028 | C39: 邮政个人 | D39: 营业款 | E39: 3店王惠娟 | F39: 5.8 | H39: 126904.8 | I39: 康庄东路分店（3店） | L39: 202512 | N39: 202601
... A41: 37 | B41: 46028 | C41: 邮政个人 | D41: 营业款 | E41: 3店王惠娟 | F41: 6566.62 | H41: 133513.12 | I41: 康庄东路分店（3店） | L41: 202601 | N41: 202601
...

Sheet 月度汇总
A1: 月度门店收支汇总（按“收支所属月份”统计）
A2: 月份 | B2: 门店 | C2: 收入 / 收款分类 | AB2: 支出分类 | AL2: 净额
A3: 月份 | B3: 门店 | C3: 营业款 | D3: 医保即时拨付 | E3: 医保 | F3: 聚合 | G3: 24小时微信 | H3: 美团 | I3: 饿了么 | J3: 健E卡 | K3: 抖音 | L3: 医卡通 | M3: 企健网 | N3: 银联 | O3: 京东 | P3: 药机微信 | Q3: 亲情卡 | R3: 优惠券 | S3: 代金券 | T3: 其他收款 | U3: 调拨收入 | V3: 储值 | W3: 效期 | X3: 内部转入 | Y3: 其他收入 | Z3: 收入合计 | AA3: 工资 | AB3: 水费 | AC3: 电费 | AD3: 宽带费 | AE3: 办公费 | AF3: 话费 | AG3: 房租 | AH3: 调拨支出 | AI3: 内部转出 | AJ3: 其他支出 | AK3: 支出合计 | AL3: 净收支
A4: 202512 | B4: 东关分店（4分店） | C4: =SUMIFS(Sheet1!$F$5:$F$28252,Sheet1!$I$5:$I$28252,$B4,Sheet1!$L$5:$L$28252,$A4,Sheet1!$D$5:$D$28252,"营业款",Sheet1!$E$5:$E$28252,"<>*调拨*",Sheet1!$E$5:$E$28252,"<>*回款*",Sheet1!$E$5:$E$28252,"<>*收款*",Sheet1!$E$5:$E$28252,"<>*医保*",Sheet1!$E$5:$E$28252,"<>*聚合*",Sheet1!$E$5:$E$28252,"<>*24小时微信*",Sheet1!$E$5:$E$28252,"<>*美团*",Sheet1!$E$5:$E$28252,"<>*饿了么*",Sheet1!$E$5:$E$28252,"<>*健E卡*",Sheet1!$E$5:$E$28252,"<>*抖音*",Sheet1!$E$5:$E$28252,"<>*医卡通*",Sheet1!$E$5:$E$28252,"<>*企健网*",Sheet1!$E$5:$E$28252,"<>*银联*",Sheet1!$E$5:$E$28252,"<>*京东*",Sheet1!$E$5:$E$28252,"<>*药机微信*",Sheet1!$E$5:$E$28252,"<>*亲情卡*",Sheet1!$E$5:$E$28252,"<>*优惠券*",Sheet1!$E$5:$E$28252,"<>*代金券*",Sheet1!$E$5:$E$28252,"<>*储值*",Sheet1!$E$5:$E$28252,"<>*效期*") -> 8103.01 | D4: =SUMIFS(Sheet1!$F$5:$F$28252,Sheet1!$I$5:$I$28252,$B4,Sheet1!$L$5:$L$28252,$A4,Sheet1!$D$5:$D$28252,"医保即时拨付",Sheet1!$E$5:$E$28252,"<>*调拨*")+SUMIFS(Sheet1!$F$5:$F$28252,Sheet1!$I$5:$I$28252,$B4,Sheet1!$L$5:$L$28252,$A4,Sheet1!$E$5:$E$28252,"*医保即时拨付*",Sheet1!$D$5:$D$28252,"<>医保即时拨付",Sheet1!$D$5:$D$28252,"<>内部转款",Sheet1!$D$5:$D$28252,"<>内部转账",Sheet1!$E$5:$E$28252,"<>*调拨*") -> 0 | E4: =SUMIFS(Sheet1!$F$5:$F$28252,Sheet1!$I$5:$I$28252,$B4,Sheet1!$L$5:$L$28252,$A4,Sheet1!$D$5:$D$28252,"医保",Sheet1!$E$5:$E$28252,"<>*调拨*",Sheet1!$E$5:$E$28252,"<>*医保即时拨付*")+SUMIFS(Sheet1!$F$5:$F$28252,Sheet1!$I$5:$I$28252,$B4,Sheet1!$L$5:$L$28252,$A4,Sheet1!$E$5:$E$28252,"*医保*",Sheet1!$D$5:$D$28252,"<>医保",Sheet1!$D$5:$D$28252,"<>医保即时拨付",Sheet1!$D$5:$D$28252,"<>内部转款",Sheet1!$D$5:$D$28252,"<>内部转账",Sheet1!$E$5:$E$28252,"<>*医保即时拨付*",Sheet1!$E$5:$E$28252,"<>*调拨*") -> 0 | F4: =SUMIFS(Sheet1!$F$5:$F$28252,Sheet1!$I$5:$I$28252,$B4,Sheet1!$L$5:$L$28252,$A4,Sheet1!$D$5:$D$28252,"聚合",Sheet1!$E$5:$E$28252,"<>*调拨*")+SUMIFS(Sheet1!$F$5:$F$28252,Sheet1!$I$5:$I$28252,$B4,Sheet1!$L$5:$L$28252,$A4,Sheet1!$E$5:$E$28252,"*聚合*",Sheet1!$D$5:$D$28252,"<>聚合",Sheet1!$D$5:$D$28252,"<>内部转款",Sheet1!$D$5:$D$28252,"<>内部转账",Sheet1!$E$5:$E$28252,"<>*调拨*") -> 0 | G4: =SUMIFS(Sheet1!$F$5:$F$28252,Sheet1!$I$5:$I$28252,$B4,Sheet1!$L$5:$L$28252,$A4,Sheet1!$D$5:$D$28252,"24小时微信",Sheet1!$E$5:$E$28252,"<>*调拨*")+SUMIFS(Sheet1!$F$5:$F$28252,Sheet1!$I$5:$I$28252,$B4,Sheet1!$L$5:$L$28252,$A4,Sheet1!$E$5:$E$28252,"*24小时微信*",Sheet1!$D$5:$D$28252,"<>24小时微信",Sheet1!$D$5:$D$28252,"<>内部转款",Sheet1!$D$5:$D$28252,"<>内部转账",Sheet1!$E$5:$E$28252,"<>*调拨*") -> 0 | H4: =SUMIFS(Sheet1!$F$5:$F$28252,Sheet1!$I$5:$I$28252,$B4,Sheet1!$L$5:$L$28252,$A4,Sheet1!$D$5:$D$28252,"美团",Sheet1!$E$5:$E$28252,"<>*调拨*")+SUMIFS(Sheet1!$F$5:$F$28252,Sheet1!$I$5:$I$28252,$B4,Sheet1!$L$5:$L$28252,$A4,Sheet1!$E$5:$E$28252,"*美团*",Sheet1!$D$5:$D$28252,"<>美团",Sheet1!$D$5:$D$28252,"<>内部转款",Sheet1!$D$5:$D$28252,"<>内部转账",Sheet1!$E$5:$E$28252,"<>*调拨*") -> 0 | I4: =SUMIFS(Sheet1!$F$5:$F$28252,Sheet1!$I$5:$I$28252,$B4,Sheet1!$L$5:$L$28252,$A4,Sheet1!$D$5:$D$28252,"饿了么",Sheet1!$E$5:$E$28252,"<>*调拨*")+SUMIFS(Sheet1!$F$5:$F$28252,Sheet1!$I$5:$I$28252,$B4,Sheet1!$L$5:$L$28252,$A4,Sheet1!$E$5:$E$28252,"*饿了么*",Sheet1!$D$5:$D$28252,"<>饿了么",Sheet1!$D$5:$D$28252,"<>内部转款",Sheet1!$D$5:$D$28252,"<>内部转账",Sheet1!$E$5:$E$28252,"<>*调拨*") -> 0 | J4: =SUMIFS(Sheet1!$F$5:$F$28252,Sheet1!$I$5:$I$28252,$B4,Sheet1!$L$5:$L$28252,$A4,Sheet1!$D$5:$D$28252,"健E卡",Sheet1!$E$5:$E$28252,"<>*调拨*")+SUMIFS(Sheet1!$F$5:$F$28252,Sheet1!$I$5:$I$28252,$B4,Sheet1!$L$5:$L$28252,$A4,Sheet1!$E$5:$E$28252,"*健E卡*",Sheet1!$D$5:$D$28252,"<>健E卡",Sheet1!$D$5:$D$28252,"<>内部转款",Sheet1!$D$5:$D$28252,"<>内部转账",Sheet1!$E$5:$E$28252,"<>*调拨*") -> 0 | K4: =SUMIFS(Sheet1!$F$5:$F$28252,Sheet1!$I$5:$I$28252,$B4,Sheet1!$L$5:$L$28252,$A4,Sheet1!$D$5:$D$28252,"抖音",Sheet1!$E$5:$E$28252,"<>*调拨*")+SUMIFS(Sheet1!$F$5:$F$28252,Sheet1!$I$5:$I$28252,$B4,Sheet1!$L$5:$L$28252,$A4,Sheet1!$E$5:$E$28252,"*抖音*",Sheet1!$D$5:$D$28252,"<>抖音",Sheet1!$D$5:$D$28252,"<>内部转款",Sheet1!$D$5:$D$28252,"<>内部转账",Sheet1!$E$5:$E$28252,"<>*调拨*") -> 0 | L4: =SUMIFS(Sheet1!$F$5:$F$28252,Sheet1!$I$5:$I$28252,$B4,Sheet1!$L$5:$L$28252,$A4,Sheet1!$D$5:$D$28252,"医卡通",Sheet1!$E$5:$E$28252,"<>*调拨*")+SUMIFS(Sheet1!$F$5:$F$28252,Sheet1!$I$5:$I$28252,$B4,Sheet1!$L$5:$L$28252,$A4,Sheet1!$E$5:$E$28252,"*医卡通*",Sheet1!$D$5:$D$28252,"<>医卡通",Sheet1!$D$5:$D$28252,"<>内部转款",Sheet1!$D$5:$D$28252,"<>内部转账",Sheet1!$E$5:$E$28252,"<>*调拨*") -> 0 | M4: =SUMIFS(Sheet1!$F$5:$F$28252,Sheet1!$I$5:$I$28252,$B4,Sheet1!$L$5:$L$28252,$A4,Sheet1!$D$5:$D$28252,"企健网",Sheet1!$E$5:$E$28252,"<>*调拨*")+SUMIFS(Sheet1!$F$5:$F$28252,Sheet1!$I$5:$I$28252,$B4,Sheet1!$L$5:$L$28252,$A4,Sheet1!$E$5:$E$28252,"*企健网*",Sheet1!$D$5:$D$28252,"<>企健网",Sheet1!$D$5:$D$28252,"<>内部转款",Sheet1!$D$5:$D$28252,"<>内部转账",Sheet1!$E$5:$E$28252,"<>*调拨*") -> 0 | N4: =SUMIFS(Sheet1!$F$5:$F$28252,Sheet1!$I$5:$I$28252,$B4,Sheet1!$L$5:$L$28252,$A4,Sheet1!$D$5:$D$28252,"银联",Sheet1!$E$5:$E$28252,"<>*调拨*")+SUMIFS(Sheet1!$F$5:$F$28252,Sheet1!$I$5:$I$28252,$B4,Sheet1!$L$5:$L$28252,$A4,Sheet1!$E$5:$E$28252,"*银联*",Sheet1!$D$5:$D$28252,"<>银联",Sheet1!$D$5:$D$28252,"<>内部转款",Sheet1!$D$5:$D$28252,"<>内部转账",Sheet1!$E$5:$E$28252,"<>*调拨*") -> 0 | O4: =SUMIFS(Sheet1!$F$5:$F$28252,Sheet1!$I$5:$I$28252,$B4,Sheet1!$L$5:$L$28252,$A4,Sheet1!$D$5:$D$28252,"京东",Sheet1!$E$5:$E$28252,"<>*调拨*")+SUMIFS(Sheet1!$F$5:$F$28252,Sheet1!$I$5:$I$28252,$B4,Sheet1!$L$5:$L$28252,$A4,Sheet1!$E$5:$E$28252,"*京东*",Sheet1!$D$5:$D$28252,"<>京东",Sheet1!$D$5:$D$28252,"<>内部转款",Sheet1!$D$5:$D$28252,"<>内部转账",Sheet1!$E$5:$E$28252,"<>*调拨*") -> 0 | P4: =SUMIFS(Sheet1!$F$5:$F$28252,Sheet1!$I$5:$I$28252,$B4,Sheet1!$L$5:$L$28252,$A4,Sheet1!$D$5:$D$28252,"药机微信",Sheet1!$E$5:$E$28252,"<>*调拨*")+SUMIFS(Sheet1!$F$5:$F$28252,Sheet1!$I$5:$I$28252,$B4,Sheet1!$L$5:$L$28252,$A4,Sheet1!$E$5:$E$28252,"*药机微信*",Sheet1!$D$5:$D$28252,"<>药机微信",Sheet1!$D$5:$D$28252,"<>内部转款",Sheet1!$D$5:$D$28252,"<>内部转账",Sheet1!$E$5:$E$28252,"<>*调拨*") -> 0 | Q4: =SUMIFS(Sheet1!$F$5:$F$28252,Sheet1!$I$5:$I$28252,$B4,Sheet1!$L$5:$L$28252,$A4,Sheet1!$D$5:$D$28252,"亲情卡",Sheet1!$E$5:$E$28252,"<>*调拨*")+SUMIFS(Sheet1!$F$5:$F$28252,Sheet1!$I$5:$I$28252,$B4,Sheet1!$L$5:$L$28252,$A4,Sheet1!$E$5:$E$28252,"*亲情卡*",Sheet1!$D$5:$D$28252,"<>亲情卡",Sheet1!$D$5:$D$28252,"<>内部转款",Sheet1!$D$5:$D$28252,"<>内部转账",Sheet1!$E$5:$E$28252,"<>*调拨*") -> 0 | R4: =SUMIFS(Sheet1!$F$5:$F$28252,Sheet1!$I$5:$I$28252,$B4,Sheet1!$L$5:$L$28252,$A4,Sheet1!$D$5:$D$28252,"优惠券",Sheet1!$E$5:$E$28252,"<>*调拨*")+SUMIFS(Sheet1!$F$5:$F$28252,Sheet1!$I$5:$I$28252,$B4,Sheet1!$L$5:$L$28252,$A4,Sheet1!$E$5:$E$28252,"*优惠券*",Sheet1!$D$5:$D$28252,"<>优惠券",Sheet1!$D$5:$D$28252,"<>内部转款",Sheet1!$D$5:$D$28252,"<>内部转账",Sheet1!$E$5:$E$28252,"<>*调拨*") -> 0 | S4: =SUMIFS(Sheet1!$F$5:$F$28252,Sheet1!$I$5:$I$28252,$B4,Sheet1!$L$5:$L$28252,$A4,Sheet1!$D$5:$D$28252,"代金券",Sheet1!$E$5:$E$28252,"<>*调拨*")+SUMIFS(Sheet1!$F$5:$F$28252,Sheet1!$I$5:$I$28252,$B4,Sheet1!$L$5:$L$28252,$A4,Sheet1!$E$5:$E$28252,"*代金券*",Sheet1!$D$5:$D$28252,"<>代金券",Sheet1!$D$5:$D$28252,"<>内部转款",Sheet1!$D$5:$D$28252,"<>内部转账",Sheet1!$E$5:$E$28252,"<>*调拨*") -> 0 | T4: =SUMIFS(Sheet1!$F$5:$F$28252,Sheet1!$I$5:$I$28252,$B4,Sheet1!$L$5:$L$28252,$A4,Sheet1!$D$5:$D$28252,"回款",Sheet1!$E$5:$E$28252,"<>*调拨*",Sheet1!$E$5:$E$28252,"<>*医保*",Sheet1!$E$5:$E$28252,"<>*聚合*",Sheet1!$E$5:$E$28252,"<>*24小时微信*",Sheet1!$E$5:$E$28252,"<>*美团*",Sheet1!$E$5:$E$28252,"<>*饿了么*",Sheet1!$E$5:$E$28252,"<>*健E卡*",Sheet1!$E$5:$E$28252,"<>*抖音*",Sheet1!$E$5:$E$28252,"<>*医卡通*",Sheet1!$E$5:$E$28252,"<>*企健网*",Sheet1!$E$5:$E$28252,"<>*银联*",Sheet1!$E$5:$E$28252,"<>*京东*",Sheet1!$E$5:$E$28252,"<>*药机微信*",Sheet1!$E$5:$E$28252,"<>*亲情卡*",Sheet1!$E$5:$E$28252,"<>*优惠券*",Sheet1!$E$5:$E$28252,"<>*代金券*",Sheet1!$E$5:$E$28252,"<>*储值*",Sheet1!$E$5:$E$28252,"<>*效期*")+SUMIFS(Sheet1!$F$5:$F$28252,Sheet1!$I$5:$I$28252,$B4,Sheet1!$L$5:$L$28252,$A4,Sheet1!$D$5:$D$28252,"收款",Sheet1!$E$5:$E$28252,"<>*调拨*",Sheet1!$E$5:$E$28252,"<>*医保*",Sheet1!$E$5:$E$28252,"<>*聚合*",Sheet1!$E$5:$E$28252,"<>*24小时微信*",Sheet1!$E$5:$E$28252,"<>*美团*",Sheet1!$E$5:$E$28252,"<>*饿了么*",Sheet1!$E$5:$E$28252,"<>*健E卡*",Sheet1!$E$5:$E$28252,"<>*抖音*",Sheet1!$E$5:$E$28252,"<>*医卡通*",Sheet1!$E$5:$E$28252,"<>*企健网*",Sheet1!$E$5:$E$28252,"<>*银联*",Sheet1!$E$5:$E$28252,"<>*京东*",Sheet1!$E$5:$E$28252,"<>*药机微信*",Sheet1!$E$5:$E$28252,"<>*亲情卡*",Sheet1!$E$5:$E$28252,"<>*优惠券*",Sheet1!$E$5:$E$28252,"<>*代金券*",Sheet1!$E$5:$E$28252,"<>*储值*",Sheet1!$E$5:$E$28252,"<>*效期*")+SUMIFS(Sheet1!$F$5:$F$28252,Sheet1!$I$5:$I$28252,$B4,Sheet1!$L$5:$L$28252,$A4,Sheet1!$E$5:$E$28252,"*回款*",Sheet1!$D$5:$D$28252,"<>回款",Sheet1!$D$5:$D$28252,"<>收款",Sheet1!$D$5:$D$28252,"<>内部转款",Sheet1!$D$5:$D$28252,"<>内部转账",Sheet1!$E$5:$E$28252,"<>*调拨*",Sheet1!$E$5:$E$28252,"<>*医保*",Sheet1!$E$5:$E$28252,"<>*聚合*",Sheet1!$E$5:$E$28252,"<>*24小时微信*",Sheet1!$E$5:$E$28252,"<>*美团*",Sheet1!$E$5:$E$28252,"<>*饿了么*",Sheet1!$E$5:$E$28252,"<>*健E卡*",Sheet1!$E$5:$E$28252,"<>*抖音*",Sheet1!$E$5:$E$28252,"<>*医卡通*",Sheet1!$E$5:$E$28252,"<>*企健网*",Sheet1!$E$5:$E$28252,"<>*银联*",Sheet1!$E$5:$E$28252,"<>*京东*",Sheet1!$E$5:$E$28252,"<>*药机微信*",Sheet1!$E$5:$E$28252,"<>*亲情卡*",Sheet1!$E$5:$E$28252,"<>*优惠券*",Sheet1!$E$5:$E$28252,"<>*代金券*",Sheet1!$E$5:$E$28252,"<>*储值*",Sheet1!$E$5:$E$28252,"<>*效期*")+SUMIFS(Sheet1!$F$5:$F$28252,Sheet1!$I$5:$I$28252,$B4,Sheet1!$L$5:$L$28252,$A4,Sheet1!$E$5:$E$28252,"*收款*",Sheet1!$E$5:$E$28252,"<>*回款*",Sheet1!$D$5:$D$28252,"<>回款",Sheet1!$D$5:$D$28252,"<>收款",Sheet1!$D$5:$D$28252,"<>内部转款",Sheet1!$D$5:$D$28252,"<>内部转账",Sheet1!$E$5:$E$28252,"<>*调拨*",Sheet1!$E$5:$E$28252,"<>*医保*",Sheet1!$E$5:$E$28252,"<>*聚合*",Sheet1!$E$5:$E$28252,"<>*24小时微信*",Sheet1!$E$5:$E$28252,"<>*美团*",Sheet1!$E$5:$E$28252,"<>*饿了么*",Sheet1!$E$5:$E$28252,"<>*健E卡*",Sheet1!$E$5:$E$28252,"<>*抖音*",Sheet1!$E$5:$E$28252,"<>*医卡通*",Sheet1!$E$5:$E$28252,"<>*企健网*",Sheet1!$E$5:$E$28252,"<>*银联*",Sheet1!$E$5:$E$28252,"<>*京东*",Sheet1!$E$5:$E$28252,"<>*药机微信*",Sheet1!$E$5:$E$28252,"<>*亲情卡*",Sheet1!$E$5:$E$28252,"<>*优惠券*",Sheet1!$E$5:$E$28252,"<>*代金券*",Sheet1!$E$5:$E$28252,"<>*储值*",Sheet1!$E$5:$E$28252,"<>*效期*") -> 0 | U4: =SUMIFS(Sheet1!$F$5:$F$28252,Sheet1!$I$5:$I$28252,$B4,Sheet1!$L$5:$L$28252,$A4,Sheet1!$E$5:$E$28252,"*调拨*") -> 0 | V4: =SUMIFS(Sheet1!$F$5:$F$28252,Sheet1!$I$5:$I$28252,$B4,Sheet1!$L$5:$L$28252,$A4,Sheet1!$D$5:$D$28252,"储值",Sheet1!$E$5:$E$28252,"<>*调拨*")+SUMIFS(Sheet1!$F$5:$F$28252,Sheet1!$I$5:$I$28252,$B4,Sheet1!$L$5:$L$28252,$A4,Sheet1!$E$5:$E$28252,"*储值*",Sheet1!$D$5:$D$28252,"<>储值",Sheet1!$D$5:$D$28252,"<>内部转款",Sheet1!$D$5:$D$28252,"<>内部转账",Sheet1!$E$5:$E$28252,"<>*调拨*") -> 0 | W4: =SUMIFS(Sheet1!$F$5:$F$28252,Sheet1!$I$5:$I$28252,$B4,Sheet1!$L$5:$L$28252,$A4,Sheet1!$D$5:$D$28252,"效期",Sheet1!$E$5:$E$28252,"<>*调拨*")+SUMIFS(Sheet1!$F$5:$F$28252,Sheet1!$I$5:$I$28252,$B4,Sheet1!$L$5:$L$28252,$A4,Sheet1!$E$5:$E$28252,"*效期*",Sheet1!$D$5:$D$28252,"<>效期",Sheet1!$D$5:$D$28252,"<>内部转款",Sheet1!$D$5:$D$28252,"<>内部转账",Sheet1!$E$5:$E$28252,"<>*调拨*") -> 0 | X4: =SUMIFS(Sheet1!$F$5:$F$28252,Sheet1!$I$5:$I$28252,$B4,Sheet1!$L$5:$L$28252,$A4,Sheet1!$D$5:$D$28252,"内部转款",Sheet1!$E$5:$E$28252,"<>*调拨*")+SUMIFS(Sheet1!$F$5:$F$28252,Sheet1!$I$5:$I$28252,$B4,Sheet1!$L$5:$L$28252,$A4,Sheet1!$D$5:$D$28252,"内部转账",Sheet1!$E$5:$E$28252,"<>*调拨*") -> 0 | Y4: =Z4-SUM(C4:X4) -> 0 | Z4: =SUMIFS(Sheet1!$F$5:$F$28252,Sheet1!$I$5:$I$28252,$B4,Sheet1!$L$5:$L$28252,$A4) -> 8103.01 | AA4: =SUMIFS(Sheet1!$G$5:$G$28252,Sheet1!$I$5:$I$28252,$B4,Sheet1!$L$5:$L$28252,$A4,Sheet1!$D$5:$D$28252,"工资",Sheet1!$E$5:$E$28252,"<>*调拨*")+SUMIFS(Sheet1!$G$5:$G$28252,Sheet1!$I$5:$I$28252,$B4,Sheet1!$L$5:$L$28252,$A4,Sheet1!$E$5:$E$28252,"*工资*",Sheet1!$E$5:$E$28252,"<>*调拨*",Sheet1!$D$5:$D$28252,"<>内部转款",Sheet1!$D$5:$D$28252,"<>内部转账",Sheet1!$D$5:$D$28252,"<>工资",Sheet1!$D$5:$D$28252,"<>水费",Sheet1!$D$5:$D$28252,"<>电费",Sheet1!$D$5:$D$28252,"<>宽带费",Sheet1!$D$5:$D$28252,"<>办公费",Sheet1!$D$5:$D$28252,"<>话费",Sheet1!$D$5:$D$28252,"<>房租") -> 0 | AB4: =SUMIFS(Sheet1!$G$5:$G$28252,Sheet1!$I$5:$I$28252,$B4,Sheet1!$L$5:$L$28252,$A4,Sheet1!$D$5:$D$28252,"水费",Sheet1!$E$5:$E$28252,"<>*调拨*")+SUMIFS(Sheet1!$G$5:$G$28252,Sheet1!$I$5:$I$28252,$B4,Sheet1!$L$5:$L$28252,$A4,Sheet1!$E$5:$E$28252,"*水费*",Sheet1!$E$5:$E$28252,"<>*调拨*",Sheet1!$D$5:$D$28252,"<>内部转款",Sheet1!$D$5:$D$28252,"<>内部转账",Sheet1!$D$5:$D$28252,"<>工资",Sheet1!$D$5:$D$28252,"<>水费",Sheet1!$D$5:$D$28252,"<>电费",Sheet1!$D$5:$D$28252,"<>宽带费",Sheet1!$D$5:$D$28252,"<>办公费",Sheet1!$D$5:$D$28252,"<>话费",Sheet1!$D$5:$D$28252,"<>房租",Sheet1!$E$5:$E$28252,"<>*工资*") -> 0 | AC4: =SUMIFS(Sheet1!$G$5:$G$28252,Sheet1!$I$5:$I$28252,$B4,Sheet1!$L$5:$L$28252,$A4,Sheet1!$D$5:$D$28252,"电费",Sheet1!$E$5:$E$28252,"<>*调拨*")+SUMIFS(Sheet1!$G$5:$G$28252,Sheet1!$I$5:$I$28252,$B4,Sheet1!$L$5:$L$28252,$A4,Sheet1!$E$5:$E$28252,"*电费*",Sheet1!$E$5:$E$28252,"<>*调拨*",Sheet1!$D$5:$D$28252,"<>内部转款",Sheet1!$D$5:$D$28252,"<>内部转账",Sheet1!$D$5:$D$28252,"<>工资",Sheet1!$D$5:$D$28252,"<>水费",Sheet1!$D$5:$D$28252,"<>电费",Sheet1!$D$5:$D$28252,"<>宽带费",Sheet1!$D$5:$D$28252,"<>办公费",Sheet1!$D$5:$D$28252,"<>话费",Sheet1!$D$5:$D$28252,"<>房租",Sheet1!$E$5:$E$28252,"<>*工资*",Sheet1!$E$5:$E$28252,"<>*水费*") -> 0 | AD4: =SUMIFS(Sheet1!$G$5:$G$28252,Sheet1!$I$5:$I$28252,$B4,Sheet1!$L$5:$L$28252,$A4,Sheet1!$D$5:$D$28252,"宽带费",Sheet1!$E$5:$E$28252,"<>*调拨*")+SUMIFS(Sheet1!$G$5:$G$28252,Sheet1!$I$5:$I$28252,$B4,Sheet1!$L$5:$L$28252,$A4,Sheet1!$E$5:$E$28252,"*宽带*",Sheet1!$E$5:$E$28252,"<>*调拨*",Sheet1!$D$5:$D$28252,"<>内部转款",Sheet1!$D$5:$D$28252,"<>内部转账",Sheet1!$D$5:$D$28252,"<>工资",Sheet1!$D$5:$D$28252,"<>水费",Sheet1!$D$5:$D$28252,"<>电费",Sheet1!$D$5:$D$28252,"<>宽带费",Sheet1!$D$5:$D$28252,"<>办公费",Sheet1!$D$5:$D$28252,"<>话费",Sheet1!$D$5:$D$28252,"<>房租",Sheet1!$E$5:$E$28252,"<>*工资*",Sheet1!$E$5:$E$28252,"<>*水费*",Sheet1!$E$5:$E$28252,"<>*电费*") -> 0 | AE4: =SUMIFS(Sheet1!$G$5:$G$28252,Sheet1!$I$5:$I$28252,$B4,Sheet1!$L$5:$L$28252,$A4,Sheet1!$D$5:$D$28252,"办公费",Sheet1!$E$5:$E$28252,"<>*调拨*")+SUMIFS(Sheet1!$G$5:$G$28252,Sheet1!$I$5:$I$28252,$B4,Sheet1!$L$5:$L$28252,$A4,Sheet1!$E$5:$E$28252,"*办公*",Sheet1!$E$5:$E$28252,"<>*调拨*",Sheet1!$D$5:$D$28252,"<>内部转款",Sheet1!$D$5:$D$28252,"<>内部转账",Sheet1!$D$5:$D$28252,"<>工资",Sheet1!$D$5:$D$28252,"<>水费",Sheet1!$D$5:$D$28252,"<>电费",Sheet1!$D$5:$D$28252,"<>宽带费",Sheet1!$D$5:$D$28252,"<>办公费",Sheet1!$D$5:$D$28252,"<>话费",Sheet1!$D$5:$D$28252,"<>房租",Sheet1!$E$5:$E$28252,"<>*工资*",Sheet1!$E$5:$E$28252,"<>*水费*",Sheet1!$E$5:$E$28252,"<>*电费*",Sheet1!$E$5:$E$28252,"<>*宽带*") -> 0 | AF4: =SUMIFS(Sheet1!$G$5:$G$28252,Sheet1!$I$5:$I$28252,$B4,Sheet1!$L$5:$L$28252,$A4,Sheet1!$D$5:$D$28252,"话费",Sheet1!$E$5:$E$28252,"<>*调拨*")+SUMIFS(Sheet1!$G$5:$G$28252,Sheet1!$I$5:$I$28252,$B4,Sheet1!$L$5:$L$28252,$A4,Sheet1!$E$5:$E$28252,"*话费*",Sheet1!$E$5:$E$28252,"<>*调拨*",Sheet1!$D$5:$D$28252,"<>内部转款",Sheet1!$D$5:$D$28252,"<>内部转账",Sheet1!$D$5:$D$28252,"<>工资",Sheet1!$D$5:$D$28252,"<>水费",Sheet1!$D$5:$D$28252,"<>电费",Sheet1!$D$5:$D$28252,"<>宽带费",Sheet1!$D$5:$D$28252,"<>办公费",Sheet1!$D$5:$D$28252,"<>话费",Sheet1!$D$5:$D$28252,"<>房租",Sheet1!$E$5:$E$28252,"<>*工资*",Sheet1!$E$5:$E$28252,"<>*水费*",Sheet1!$E$5:$E$28252,"<>*电费*",Sheet1!$E$5:$E$28252,"<>*宽带*",Sheet1!$E$5:$E$28252,"<>*办公*") -> 0 | AG4: =SUMIFS(Sheet1!$G$5:$G$28252,Sheet1!$I$5:$I$28252,$B4,Sheet1!$L$5:$L$28252,$A4,Sheet1!$D$5:$D$28252,"房租",Sheet1!$E$5:$E$28252,"<>*调拨*")+SUMIFS(Sheet1!$G$5:$G$28252,Sheet1!$I$5:$I$28252,$B4,Sheet1!$L$5:$L$28252,$A4,Sheet1!$E$5:$E$28252,"*房租*",Sheet1!$E$5:$E$28252,"<>*调拨*",Sheet1!$D$5:$D$28252,"<>内部转款",Sheet1!$D$5:$D$28252,"<>内部转账",Sheet1!$D$5:$D$28252,"<>工资",Sheet1!$D$5:$D$28252,"<>水费",Sheet1!$D$5:$D$28252,"<>电费",Sheet1!$D$5:$D$28252,"<>宽带费",Sheet1!$D$5:$D$28252,"<>办公费",Sheet1!$D$5:$D$28252,"<>话费",Sheet1!$D$5:$D$28252,"<>房租",Sheet1!$E$5:$E$28252,"<>*工资*",Sheet1!$E$5:$E$28252,"<>*水费*",Sheet1!$E$5:$E$28252,"<>*电费*",Sheet1!$E$5:$E$28252,"<>*宽带*",Sheet1!$E$5:$E$28252,"<>*办公*",Sheet1!$E$5:$E$28252,"<>*话费*") -> 0 | AH4: =SUMIFS(Sheet1!$G$5:$G$28252,Sheet1!$I$5:$I$28252,$B4,Sheet1!$L$5:$L$28252,$A4,Sheet1!$E$5:$E$28252,"*调拨*") -> 0 | AI4: =SUMIFS(Sheet1!$G$5:$G$28252,Sheet1!$I$5:$I$28252,$B4,Sheet1!$L$5:$L$28252,$A4,Sheet1!$D$5:$D$28252,"内部转款",Sheet1!$E$5:$E$28252,"<>*调拨*")+SUMIFS(Sheet1!$G$5:$G$28252,Sheet1!$I$5:$I$28252,$B4,Sheet1!$L$5:$L$28252,$A4,Sheet1!$D$5:$D$28252,"内部转账",Sheet1!$E$5:$E$28252,"<>*调拨*") -> 0 | AJ4: =AK4-SUM(AA4:AI4) -> 0 | AK4: =SUMIFS(Sheet1!$G$5:$G$28252,Sheet1!$I$5:$I$28252,$B4,Sheet1!$L$5:$L$28252,$A4) -> 0 | AL4: =Z4-AK4 -> 8103.01
A5: 202512 | B5: 临城县博城分店（57分店） | C5: =SUMIFS(Sheet1!$F$5:$F$28252,Sheet1!$I$5:$I$28252,$B5,Sheet1!$L$5:$L$28252,$A5,Sheet1!$D$5:$D$28252,"营业款",Sheet1!$E$5:$E$28252,"<>*调拨*",Sheet1!$E$5:$E$28252,"<>*回款*",Sheet1!$E$5:$E$28252,"<>*收款*",Sheet1!$E$5:$E$28252,"<>*医保*",Sheet1!$E$5:$E$28252,"<>*聚合*",Sheet1!$E$5:$E$28252,"<>*24小时微信*",Sheet1!$E$5:$E$28252,"<>*美团*",Sheet1!$E$5:$E$28252,"<>*饿了么*",Sheet1!$E$5:$E$28252,"<>*健E卡*",Sheet1!$E$5:$E$28252,"<>*抖音*",Sheet1!$E$5:$E$28252,"<>*医卡通*",Sheet1!$E$5:$E$28252,"<>*企健网*",Sheet1!$E$5:$E$28252,"<>*银联*",Sheet1!$E$5:$E$28252,"<>*京东*",Sheet1!$E$5:$E$28252,"<>*药机微信*",Sheet1!$E$5:$E$28252,"<>*亲情卡*",Sheet1!$E$5:$E$28252,"<>*优惠券*",Sheet1!$E$5:$E$28252,"<>*代金券*",Sheet1!$E$5:$E$28252,"<>*储值*",Sheet1!$E$5:$E$28252,"<>*效期*") -> 13343.62 | D5: =SUMIFS(Sheet1!$F$5:$F$28252,Sheet1!$I$5:$I$28252,$B5,Sheet1!$L$5:$L$28252,$A5,Sheet1!$D$5:$D$28252,"医保即时拨付",Sheet1!$E$5:$E$28252,"<>*调拨*")+SUMIFS(Sheet1!$F$5:$F$28252,Sheet1!$I$5:$I$28252,$B5,Sheet1!$L$5:$L$28252,$A5,Sheet1!$E$5:$E$28252,"*医保即时拨付*",Sheet1!$D$5:$D$28252,"<>医保即时拨付",Sheet1!$D$5:$D$28252,"<>内部转款",Sheet1!$D$5:$D$28252,"<>内部转账",Sheet1!$E$5:$E$28252,"<>*调拨*") -> 0 | E5: =SUMIFS(Sheet1!$F$5:$F$28252,Sheet1!$I$5:$I$28252,$B5,Sheet1!$L$5:$L$28252,$A5,Sheet1!$D$5:$D$28252,"医保",Sheet1!$E$5:$E$28252,"<>*调拨*",Sheet1!$E$5:$E$28252,"<>*医保即时拨付*")+SUMIFS(Sheet1!$F$5:$F$28252,Sheet1!$I$5:$I$28252,$B5,Sheet1!$L$5:$L$28252,$A5,Sheet1!$E$5:$E$28252,"*医保*",Sheet1!$D$5:$D$28252,"<>医保",Sheet1!$D$5:$D$28252,"<>医保即时拨付",Sheet1!$D$5:$D$28252,"<>内部转款",Sheet1!$D$5:$D$28252,"<>内部转账",Sheet1!$E$5:$E$28252,"<>*医保即时拨付*",Sheet1!$E$5:$E$28252,"<>*调拨*") -> 0 | F5: =SUMIFS(Sheet1!$F$5:$F$28252,Sheet1!$I$5:$I$28252,$B5,Sheet1!$L$5:$L$28252,$A5,Sheet1!$D$5:$D$28252,"聚合",Sheet1!$E$5:$E$28252,"<>*调拨*")+SUMIFS(Sheet1!$F$5:$F$28252,Sheet1!$I$5:$I$28252,$B5,Sheet1!$L$5:$L$28252,$A5,Sheet1!$E$5:$E$28252,"*聚合*",Sheet1!$D$5:$D$28252,"<>聚合",Sheet1!$D$5:$D$28252,"<>内部转款",Sheet1!$D$5:$D$28252,"<>内部转账",Sheet1!$E$5:$E$28252,"<>*调拨*") -> 0 | G5: =SUMIFS(Sheet1!$F$5:$F$28252,Sheet1!$I$5:$I$28252,$B5,Sheet1!$L$5:$L$28252,$A5,Sheet1!$D$5:$D$28252,"24小时微信",Sheet1!$E$5:$E$28252,"<>*调拨*")+SUMIFS(Sheet1!$F$5:$F$28252,Sheet1!$I$5:$I$28252,$B5,Sheet1!$L$5:$L$28252,$A5,Sheet1!$E$5:$E$28252,"*24小时微信*",Sheet1!$D$5:$D$28252,"<>24小时微信",Sheet1!$D$5:$D$28252,"<>内部转款",Sheet1!$D$5:$D$28252,"<>内部转账",Sheet1!$E$5:$E$28252,"<>*调拨*") -> 0 | H5: =SUMIFS(Sheet1!$F$5:$F$28252,Sheet1!$I$5:$I$28252,$B5,Sheet1!$L$5:$L$28252,$A5,Sheet1!$D$5:$D$28252,"美团",Sheet1!$E$5:$E$28252,"<>*调拨*")+SUMIFS(Sheet1!$F$5:$F$28252,Sheet1!$I$5:$I$28252,$B5,Sheet1!$L$5:$L$28252,$A5,Sheet1!$E$5:$E$28252,"*美团*",Sheet1!$D$5:$D$28252,"<>美团",Sheet1!$D$5:$D$28252,"<>内部转款",Sheet1!$D$5:$D$28252,"<>内部转账",Sheet1!$E$5:$E$28252,"<>*调拨*") -> 0 | I5: =SUMIFS(Sheet1!$F$5:$F$28252,Sheet1!$I$5:$I$28252,$B5,Sheet1!$L$5:$L$28252,$A5,Sheet1!$D$5:$D$28252,"饿了么",Sheet1!$E$5:$E$28252,"<>*调拨*")+SUMIFS(Sheet1!$F$5:$F$28252,Sheet1!$I$5:$I$28252,$B5,Sheet1!$L$5:$L$28252,$A5,Sheet1!$E$5:$E$28252,"*饿了么*",Sheet1!$D$5:$D$28252,"<>饿了么",Sheet1!$D$5:$D$28252,"<>内部转款",Sheet1!$D$5:$D$28252,"<>内部转账",Sheet1!$E$5:$E$28252,"<>*调拨*") -> 0 | J5: =SUMIFS(Sheet1!$F$5:$F$28252,Sheet1!$I$5:$I$28252,$B5,Sheet1!$L$5:$L$28252,$A5,Sheet1!$D$5:$D$28252,"健E卡",Sheet1!$E$5:$E$28252,"<>*调拨*")+SUMIFS(Sheet1!$F$5:$F$28252,Sheet1!$I$5:$I$28252,$B5,Sheet1!$L$5:$L$28252,$A5,Sheet1!$E$5:$E$28252,"*健E卡*",Sheet1!$D$5:$D$28252,"<>健E卡",Sheet1!$D$5:$D$28252,"<>内部转款",Sheet1!$D$5:$D$28252,"<>内部转账",Sheet1!$E$5:$E$28252,"<>*调拨*") -> 0 | K5: =SUMIFS(Sheet1!$F$5:$F$28252,Sheet1!$I$5:$I$28252,$B5,Sheet1!$L$5:$L$28252,$A5,Sheet1!$D$5:$D$28252,"抖音",Sheet1!$E$5:$E$28252,"<>*调拨*")+SUMIFS(Sheet1!$F$5:$F$28252,Sheet1!$I$5:$I$28252,$B5,Sheet1!$L$5:$L$28252,$A5,Sheet1!$E$5:$E$28252,"*抖音*",Sheet1!$D$5:$D$28252,"<>抖音",Sheet1!$D$5:$D$28252,"<>内部转款",Sheet1!$D$5:$D$28252,"<>内部转账",Sheet1!$E$5:$E$28252,"<>*调拨*") -> 0 | L5: =SUMIFS(Sheet1!$F$5:$F$28252,Sheet1!$I$5:$I$28252,$B5,Sheet1!$L$5:$L$28252,$A5,Sheet1!$D$5:$D$28252,"医卡通",Sheet1!$E$5:$E$28252,"<>*调拨*")+SUMIFS(Sheet1!$F$5:$F$28252,Sheet1!$I$5:$I$28252,$B5,Sheet1!$L$5:$L$28252,$A5,Sheet1!$E$5:$E$28252,"*医卡通*",Sheet1!$D$5:$D$28252,"<>医卡通",Sheet1!$D$5:$D$28252,"<>内部转款",Sheet1!$D$5:$D$28252,"<>内部转账",Sheet1!$E$5:$E$28252,"<>*调拨*") -> 0 | M5: =SUMIFS(Sheet1!$F$5:$F$28252,Sheet1!$I$5:$I$28252,$B5,Sheet1!$L$5:$L$28252,$A5,Sheet1!$D$5:$D$28252,"企健网",Sheet1!$E$5:$E$28252,"<>*调拨*")+SUMIFS(Sheet1!$F$5:$F$28252,Sheet1!$I$5:$I$28252,$B5,Sheet1!$L$5:$L$28252,$A5,Sheet1!$E$5:$E$28252,"*企健网*",Sheet1!$D$5:$D$28252,"<>企健网",Sheet1!$D$5:$D$28252,"<>内部转款",Sheet1!$D$5:$D$28252,"<>内部转账",Sheet1!$E$5:$E$28252,"<>*调拨*") -> 0 | N5: =SUMIFS(Sheet1!$F$5:$F$28252,Sheet1!$I$5:$I$28252,$B5,Sheet1!$L$5:$L$28252,$A5,Sheet1!$D$5:$D$28252,"银联",Sheet1!$E$5:$E$28252,"<>*调拨*")+SUMIFS(Sheet1!$F$5:$F$28252,Sheet1!$I$5:$I$28252,$B5,Sheet1!$L$5:$L$28252,$A5,Sheet1!$E$5:$E$28252,"*银联*",Sheet1!$D$5:$D$28252,"<>银联",Sheet1!$D$5:$D$28252,"<>内部转款",Sheet1!$D$5:$D$28252,"<>内部转账",Sheet1!$E$5:$E$28252,"<>*调拨*") -> 0 | O5: =SUMIFS(Sheet1!$F$5:$F$28252,Sheet1!$I$5:$I$28252,$B5,Sheet1!$L$5:$L$28252,$A5,Sheet1!$D$5:$D$28252,"京东",Sheet1!$E$5:$E$28252,"<>*调拨*")+SUMIFS(Sheet1!$F$5:$F$28252,Sheet1!$I$5:$I$28252,$B5,Sheet1!$L$5:$L$28252,$A5,Sheet1!$E$5:$E$28252,"*京东*",Sheet1!$D$5:$D$28252,"<>京东",Sheet1!$D$5:$D$28252,"<>内部转款",Sheet1!$D$5:$D$28252,"<>内部转账",Sheet1!$E$5:$E$28252,"<>*调拨*") -> 0 | P5: =SUMIFS(Sheet1!$F$5:$F$28252,Sheet1!$I$5:$I$28252,$B5,Sheet1!$L$5:$L$28252,$A5,Sheet1!$D$5:$D$28252,"药机微信",Sheet1!$E$5:$E$28252,"<>*调拨*")+SUMIFS(Sheet1!$F$5:$F$28252,Sheet1!$I$5:$I$28252,$B5,Sheet1!$L$5:$L$28252,$A5,Sheet1!$E$5:$E$28252,"*药机微信*",Sheet1!$D$5:$D$28252,"<>药机微信",Sheet1!$D$5:$D$28252,"<>内部转款",Sheet1!$D$5:$D$28252,"<>内部转账",Sheet1!$E$5:$E$28252,"<>*调拨*") -> 0 | Q5: =SUMIFS(Sheet1!$F$5:$F$28252,Sheet1!$I$5:$I$28252,$B5,Sheet1!$L$5:$L$28252,$A5,Sheet1!$D$5:$D$28252,"亲情卡",Sheet1!$E$5:$E$28252,"<>*调拨*")+SUMIFS(Sheet1!$F$5:$F$28252,Sheet1!$I$5:$I$28252,$B5,Sheet1!$L$5:$L$28252,$A5,Sheet1!$E$5:$E$28252,"*亲情卡*",Sheet1!$D$5:$D$28252,"<>亲情卡",Sheet1!$D$5:$D$28252,"<>内部转款",Sheet1!$D$5:$D$28252,"<>内部转账",Sheet1!$E$5:$E$28252,"<>*调拨*") -> 0 | R5: =SUMIFS(Sheet1!$F$5:$F$28252,Sheet1!$I$5:$I$28252,$B5,Sheet1!$L$5:$L$28252,$A5,Sheet1!$D$5:$D$28252,"优惠券",Sheet1!$E$5:$E$28252,"<>*调拨*")+SUMIFS(Sheet1!$F$5:$F$28252,Sheet1!$I$5:$I$28252,$B5,Sheet1!$L$5:$L$28252,$A5,Sheet1!$E$5:$E$28252,"*优惠券*",Sheet1!$D$5:$D$28252,"<>优惠券",Sheet1!$D$5:$D$28252,"<>内部转款",Sheet1!$D$5:$D$28252,"<>内部转账",Sheet1!$E$5:$E$28252,"<>*调拨*") -> 0 | S5: =SUMIFS(Sheet1!$F$5:$F$28252,Sheet1!$I$5:$I$28252,$B5,Sheet1!$L$5:$L$28252,$A5,Sheet1!$D$5:$D$28252,"代金券",Sheet1!$E$5:$E$28252,"<>*调拨*")+SUMIFS(Sheet1!$F$5:$F$28252,Sheet1!$I$5:$I$28252,$B5,Sheet1!$L$5:$L$28252,$A5,Sheet1!$E$5:$E$28252,"*代金券*",Sheet1!$D$5:$D$28252,"<>代金券",Sheet1!$D$5:$D$28252,"<>内部转款",Sheet1!$D$5:$D$28252,"<>内部转账",Sheet1!$E$5:$E$28252,"<>*调拨*") -> 0 | T5: =SUMIFS(Sheet1!$F$5:$F$28252,Sheet1!$I$5:$I$28252,$B5,Sheet1!$L$5:$L$28252,$A5,Sheet1!$D$5:$D$28252,"回款",Sheet1!$E$5:$E$28252,"<>*调拨*",Sheet1!$E$5:$E$28252,"<>*医保*",Sheet1!$E$5:$E$28252,"<>*聚合*",Sheet1!$E$5:$E$28252,"<>*24小时微信*",Sheet1!$E$5:$E$28252,"<>*美团*",Sheet1!$E$5:$E$28252,"<>*饿了么*",Sheet1!$E$5:$E$28252,"<>*健E卡*",Sheet1!$E$5:$E$28252,"<>*抖音*",Sheet1!$E$5:$E$28252,"<>*医卡通*",Sheet1!$E$5:$E$28252,"<>*企健网*",Sheet1!$E$5:$E$28252,"<>*银联*",Sheet1!$E$5:$E$28252,"<>*京东*",Sheet1!$E$5:$E$28252,"<>*药机微信*",Sheet1!$E$5:$E$28252,"<>*亲情卡*",Sheet1!$E$5:$E$28252,"<>*优惠券*",Sheet1!$E$5:$E$28252,"<>*代金券*",Sheet1!$E$5:$E$28252,"<>*储值*",Sheet1!$E$5:$E$28252,"<>*效期*")+SUMIFS(Sheet1!$F$5:$F$28252,Sheet1!$I$5:$I$28252,$B5,Sheet1!$L$5:$L$28252,$A5,Sheet1!$D$5:$D$28252,"收款",Sheet1!$E$5:$E$28252,"<>*调拨*",Sheet1!$E$5:$E$28252,"<>*医保*",Sheet1!$E$5:$E$28252,"<>*聚合*",Sheet1!$E$5:$E$28252,"<>*24小时微信*",Sheet1!$E$5:$E$28252,"<>*美团*",Sheet1!$E$5:$E$28252,"<>*饿了么*",Sheet1!$E$5:$E$28252,"<>*健E卡*",Sheet1!$E$5:$E$28252,"<>*抖音*",Sheet1!$E$5:$E$28252,"<>*医卡通*",Sheet1!$E$5:$E$28252,"<>*企健网*",Sheet1!$E$5:$E$28252,"<>*银联*",Sheet1!$E$5:$E$28252,"<>*京东*",Sheet1!$E$5:$E$28252,"<>*药机微信*",Sheet1!$E$5:$E$28252,"<>*亲情卡*",Sheet1!$E$5:$E$28252,"<>*优惠券*",Sheet1!$E$5:$E$28252,"<>*代金券*",Sheet1!$E$5:$E$28252,"<>*储值*",Sheet1!$E$5:$E$28252,"<>*效期*")+SUMIFS(Sheet1!$F$5:$F$28252,Sheet1!$I$5:$I$28252,$B5,Sheet1!$L$5:$L$28252,$A5,Sheet1!$E$5:$E$28252,"*回款*",Sheet1!$D$5:$D$28252,"<>回款",Sheet1!$D$5:$D$28252,"<>收款",Sheet1!$D$5:$D$28252,"<>内部转款",Sheet1!$D$5:$D$28252,"<>内部转账",Sheet1!$E$5:$E$28252,"<>*调拨*",Sheet1!$E$5:$E$28252,"<>*医保*",Sheet1!$E$5:$E$28252,"<>*聚合*",Sheet1!$E$5:$E$28252,"<>*24小时微信*",Sheet1!$E$5:$E$28252,"<>*美团*",Sheet1!$E$5:$E$28252,"<>*饿了么*",Sheet1!$E$5:$E$28252,"<>*健E卡*",Sheet1!$E$5:$E$28252,"<>*抖音*",Sheet1!$E$5:$E$28252,"<>*医卡通*",Sheet1!$E$5:$E$28252,"<>*企健网*",Sheet1!$E$5:$E$28252,"<>*银联*",Sheet1!$E$5:$E$28252,"<>*京东*",Sheet1!$E$5:$E$28252,"<>*药机微信*",Sheet1!$E$5:$E$28252,"<>*亲情卡*",Sheet1!$E$5:$E$28252,"<>*优惠券*",Sheet1!$E$5:$E$28252,"<>*代金券*",Sheet1!$E$5:$E$28252,"<>*储值*",Sheet1!$E$5:$E$28252,"<>*效期*")+SUMIFS(Sheet1!$F$5:$F$28252,Sheet1!$I$5:$I$28252,$B5,Sheet1!$L$5:$L$28252,$A5,Sheet1!$E$5:$E$28252,"*收款*",Sheet1!$E$5:$E$28252,"<>*回款*",Sheet1!$D$5:$D$28252,"<>回款",Sheet1!$D$5:$D$28252,"<>收款",Sheet1!$D$5:$D$28252,"<>内部转款",Sheet1!$D$5:$D$28252,"<>内部转账",Sheet1!$E$5:$E$28252,"<>*调拨*",Sheet1!$E$5:$E$28252,"<>*医保*",Sheet1!$E$5:$E$28252,"<>*聚合*",Sheet1!$E$5:$E$28252,"<>*24小时微信*",Sheet1!$E$5:$E$28252,"<>*美团*",Sheet1!$E$5:$E$28252,"<>*饿了么*",Sheet1!$E$5:$E$28252,"<>*健E卡*",Sheet1!$E$5:$E$28252,"<>*抖音*",Sheet1!$E$5:$E$28252,"<>*医卡通*",Sheet1!$E$5:$E$28252,"<>*企健网*",Sheet1!$E$5:$E$28252,"<>*银联*",Sheet1!$E$5:$E$28252,"<>*京东*",Sheet1!$E$5:$E$28252,"<>*药机微信*",Sheet1!$E$5:$E$28252,"<>*亲情卡*",Sheet1!$E$5:$E$28252,"<>*优惠券*",Sheet1!$E$5:$E$28252,"<>*代金券*",Sheet1!$E$5:$E$28252,"<>*储值*",Sheet1!$E$5:$E$28252,"<>*效期*") -> 0 | U5: =SUMIFS(Sheet1!$F$5:$F$28252,Sheet1!$I$5:$I$28252,$B5,Sheet1!$L$5:$L$28252,$A5,Sheet1!$E$5:$E$28252,"*调拨*") -> 0 | V5: =SUMIFS(Sheet1!$F$5:$F$28252,Sheet1!$I$5:$I$28252,$B5,Sheet1!$L$5:$L$28252,$A5,Sheet1!$D$5:$D$28252,"储值",Sheet1!$E$5:$E$28252,"<>*调拨*")+SUMIFS(Sheet1!$F$5:$F$28252,Sheet1!$I$5:$I$28252,$B5,Sheet1!$L$5:$L$28252,$A5,Sheet1!$E$5:$E$28252,"*储值*",Sheet1!$D$5:$D$28252,"<>储值",Sheet1!$D$5:$D$28252,"<>内部转款",Sheet1!$D$5:$D$28252,"<>内部转账",Sheet1!$E$5:$E$28252,"<>*调拨*") -> 0 | W5: =SUMIFS(Sheet1!$F$5:$F$28252,Sheet1!$I$5:$I$28252,$B5,Sheet1!$L$5:$L$28252,$A5,Sheet1!$D$5:$D$28252,"效期",Sheet1!$E$5:$E$28252,"<>*调拨*")+SUMIFS(Sheet1!$F$5:$F$28252,Sheet1!$I$5:$I$28252,$B5,Sheet1!$L$5:$L$28252,$A5,Sheet1!$E$5:$E$28252,"*效期*",Sheet1!$D$5:$D$28252,"<>效期",Sheet1!$D$5:$D$28252,"<>内部转款",Sheet1!$D$5:$D$28252,"<>内部转账",Sheet1!$E$5:$E$28252,"<>*调拨*") -> 0 | X5: =SUMIFS(Sheet1!$F$5:$F$28252,Sheet1!$I$5:$I$28252,$B5,Sheet1!$L$5:$L$28252,$A5,Sheet1!$D$5:$D$28252,"内部转款",Sheet1!$E$5:$E$28252,"<>*调拨*")+SUMIFS(Sheet1!$F$5:$F$28252,Sheet1!$I$5:$I$28252,$B5,Sheet1!$L$5:$L$28252,$A5,Sheet1!$D$5:$D$28252,"内部转账",Sheet1!$E$5:$E$28252,"<>*调拨*") -> 0 | Y5: =Z5-SUM(C5:X5) -> 0 | Z5: =SUMIFS(Sheet1!$F$5:$F$28252,Sheet1!$I$5:$I$28252,$B5,Sheet1!$L$5:$L$28252,$A5) -> 13343.62 | AA5: =SUMIFS(Sheet1!$G$5:$G$28252,Sheet1!$I$5:$I$28252,$B5,Sheet1!$L$5:$L$28252,$A5,Sheet1!$D$5:$D$28252,"工资",Sheet1!$E$5:$E$28252,"<>*调拨*")+SUMIFS(Sheet1!$G$5:$G$28252,Sheet1!$I$5:$I$28252,$B5,Sheet1!$L$5:$L$28252,$A5,Sheet1!$E$5:$E$28252,"*工资*",Sheet1!$E$5:$E$28252,"<>*调拨*",Sheet1!$D$5:$D$28252,"<>内部转款",Sheet1!$D$5:$D$28252,"<>内部转账",Sheet1!$D$5:$D$28252,"<>工资",Sheet1!$D$5:$D$28252,"<>水费",Sheet1!$D$5:$D$28252,"<>电费",Sheet1!$D$5:$D$28252,"<>宽带费",Sheet1!$D$5:$D$28252,"<>办公费",Sheet1!$D$5:$D$28252,"<>话费",Sheet1!$D$5:$D$28252,"<>房租") -> 0 | AB5: =SUMIFS(Sheet1!$G$5:$G$28252,Sheet1!$I$5:$I$28252,$B5,Sheet1!$L$5:$L$28252,$A5,Sheet1!$D$5:$D$28252,"水费",Sheet1!$E$5:$E$28252,"<>*调拨*")+SUMIFS(Sheet1!$G$5:$G$28252,Sheet1!$I$5:$I$28252,$B5,Sheet1!$L$5:$L$28252,$A5,Sheet1!$E$5:$E$28252,"*水费*",Sheet1!$E$5:$E$28252,"<>*调拨*",Sheet1!$D$5:$D$28252,"<>内部转款",Sheet1!$D$5:$D$28252,"<>内部转账",Sheet1!$D$5:$D$28252,"<>工资",Sheet1!$D$5:$D$28252,"<>水费",Sheet1!$D$5:$D$28252,"<>电费",Sheet1!$D$5:$D$28252,"<>宽带费",Sheet1!$D$5:$D$28252,"<>办公费",Sheet1!$D$5:$D$28252,"<>话费",Sheet1!$D$5:$D$28252,"<>房租",Sheet1!$E$5:$E$28252,"<>*工资*") -> 0 | AC5: =SUMIFS(Sheet1!$G$5:$G$28252,Sheet1!$I$5:$I$28252,$B5,Sheet1!$L$5:$L$28252,$A5,Sheet1!$D$5:$D$28252,"电费",Sheet1!$E$5:$E$28252,"<>*调拨*")+SUMIFS(Sheet1!$G$5:$G$28252,Sheet1!$I$5:$I$28252,$B5,Sheet1!$L$5:$L$28252,$A5,Sheet1!$E$5:$E$28252,"*电费*",Sheet1!$E$5:$E$28252,"<>*调拨*",Sheet1!$D$5:$D$28252,"<>内部转款",Sheet1!$D$5:$D$28252,"<>内部转账",Sheet1!$D$5:$D$28252,"<>工资",Sheet1!$D$5:$D$28252,"<>水费",Sheet1!$D$5:$D$28252,"<>电费",Sheet1!$D$5:$D$28252,"<>宽带费",Sheet1!$D$5:$D$28252,"<>办公费",Sheet1!$D$5:$D$28252,"<>话费",Sheet1!$D$5:$D$28252,"<>房租",Sheet1!$E$5:$E$28252,"<>*工资*",Sheet1!$E$5:$E$28252,"<>*水费*") -> 0 | AD5: =SUMIFS(Sheet1!$G$5:$G$28252,Sheet1!$I$5:$I$28252,$B5,Sheet1!$L$5:$L$28252,$A5,Sheet1!$D$5:$D$28252,"宽带费",Sheet1!$E$5:$E$28252,"<>*调拨*")+SUMIFS(Sheet1!$G$5:$G$28252,Sheet1!$I$5:$I$28252,$B5,Sheet1!$L$5:$L$28252,$A5,Sheet1!$E$5:$E$28252,"*宽带*",Sheet1!$E$5:$E$28252,"<>*调拨*",Sheet1!$D$5:$D$28252,"<>内部转款",Sheet1!$D$5:$D$28252,"<>内部转账",Sheet1!$D$5:$D$28252,"<>工资",Sheet1!$D$5:$D$28252,"<>水费",Sheet1!$D$5:$D$28252,"<>电费",Sheet1!$D$5:$D$28252,"<>宽带费",Sheet1!$D$5:$D$28252,"<>办公费",Sheet1!$D$5:$D$28252,"<>话费",Sheet1!$D$5:$D$28252,"<>房租",Sheet1!$E$5:$E$28252,"<>*工资*",Sheet1!$E$5:$E$28252,"<>*水费*",Sheet1!$E$5:$E$28252,"<>*电费*") -> 0 | AE5: =SUMIFS(Sheet1!$G$5:$G$28252,Sheet1!$I$5:$I$28252,$B5,Sheet1!$L$5:$L$28252,$A5,Sheet1!$D$5:$D$28252,"办公费",Sheet1!$E$5:$E$28252,"<>*调拨*")+SUMIFS(Sheet1!$G$5:$G$28252,Sheet1!$I$5:$I$28252,$B5,Sheet1!$L$5:$L$28252,$A5,Sheet1!$E$5:$E$28252,"*办公*",Sheet1!$E$5:$E$28252,"<>*调拨*",Sheet1!$D$5:$D$28252,"<>内部转款",Sheet1!$D$5:$D$28252,"<>内部转账",Sheet1!$D$5:$D$28252,"<>工资",Sheet1!$D$5:$D$28252,"<>水费",Sheet1!$D$5:$D$28252,"<>电费",Sheet1!$D$5:$D$28252,"<>宽带费",Sheet1!$D$5:$D$28252,"<>办公费",Sheet1!$D$5:$D$28252,"<>话费",Sheet1!$D$5:$D$28252,"<>房租",Sheet1!$E$5:$E$28252,"<>*工资*",Sheet1!$E$5:$E$28252,"<>*水费*",Sheet1!$E$5:$E$28252,"<>*电费*",Sheet1!$E$5:$E$28252,"<>*宽带*") -> 0 | AF5: =SUMIFS(Sheet1!$G$5:$G$28252,Sheet1!$I$5:$I$28252,$B5,Sheet1!$L$5:$L$28252,$A5,Sheet1!$D$5:$D$28252,"话费",Sheet1!$E$5:$E$28252,"<>*调拨*")+SUMIFS(Sheet1!$G$5:$G$28252,Sheet1!$I$5:$I$28252,$B5,Sheet1!$L$5:$L$28252,$A5,Sheet1!$E$5:$E$28252,"*话费*",Sheet1!$E$5:$E$28252,"<>*调拨*",Sheet1!$D$5:$D$28252,"<>内部转款",Sheet1!$D$5:$D$28252,"<>内部转账",Sheet1!$D$5:$D$28252,"<>工资",Sheet1!$D$5:$D$28252,"<>水费",Sheet1!$D$5:$D$28252,"<>电费",Sheet1!$D$5:$D$28252,"<>宽带费",Sheet1!$D$5:$D$28252,"<>办公费",Sheet1!$D$5:$D$28252,"<>话费",Sheet1!$D$5:$D$28252,"<>房租",Sheet1!$E$5:$E$28252,"<>*工资*",Sheet1!$E$5:$E$28252,"<>*水费*",Sheet1!$E$5:$E$28252,"<>*电费*",Sheet1!$E$5:$E$28252,"<>*宽带*",Sheet1!$E$5:$E$28252,"<>*办公*") -> 0 | AG5: =SUMIFS(Sheet1!$G$5:$G$28252,Sheet1!$I$5:$I$28252,$B5,Sheet1!$L$5:$L$28252,$A5,Sheet1!$D$5:$D$28252,"房租",Sheet1!$E$5:$E$28252,"<>*调拨*")+SUMIFS(Sheet1!$G$5:$G$28252,Sheet1!$I$5:$I$28252,$B5,Sheet1!$L$5:$L$28252,$A5,Sheet1!$E$5:$E$28252,"*房租*",Sheet1!$E$5:$E$28252,"<>*调拨*",Sheet1!$D$5:$D$28252,"<>内部转款",Sheet1!$D$5:$D$28252,"<>内部转账",Sheet1!$D$5:$D$28252,"<>工资",Sheet1!$D$5:$D$28252,"<>水费",Sheet1!$D$5:$D$28252,"<>电费",Sheet1!$D$5:$D$28252,"<>宽带费",Sheet1!$D$5:$D$28252,"<>办公费",Sheet1!$D$5:$D$28252,"<>话费",Sheet1!$D$5:$D$28252,"<>房租",Sheet1!$E$5:$E$28252,"<>*工资*",Sheet1!$E$5:$E$28252,"<>*水费*",Sheet1!$E$5:$E$28252,"<>*电费*",Sheet1!$E$5:$E$28252,"<>*宽带*",Sheet1!$E$5:$E$28252,"<>*办公*",Sheet1!$E$5:$E$28252,"<>*话费*") -> 0 | AH5: =SUMIFS(Sheet1!$G$5:$G$28252,Sheet1!$I$5:$I$28252,$B5,Sheet1!$L$5:$L$28252,$A5,Sheet1!$E$5:$E$28252,"*调拨*") -> 0 | AI5: =SUMIFS(Sheet1!$G$5:$G$28252,Sheet1!$I$5:$I$28252,$B5,Sheet1!$L$5:$L$28252,$A5,Sheet1!$D$5:$D$28252,"内部转款",Sheet1!$E$5:$E$28252,"<>*调拨*")+SUMIFS(Sheet1!$G$5:$G$28252,Sheet1!$I$5:$I$28252,$B5,Sheet1!$L$5:$L$28252,$A5,Sheet1!$D$5:$D$28252,"内部转账",Sheet1!$E$5:$E$28252,"<>*调拨*") -> 0 | AJ5: =AK5-SUM(AA5:AI5) -> 0 | AK5: =SUMIFS(Sheet1!$G$5:$G$28252,Sheet1!$I$5:$I$28252,$B5,Sheet1!$L$5:$L$28252,$A5) -> 0 | AL5: =Z5-AK5 -> 13343.62
A6: 202512 | B6: 临城县博康分店（46分店） | C6: =SUMIFS(Sheet1!$F$5:$F$28252,Sheet1!$I$5:$I$28252,$B6,Sheet1!$L$5:$L$28252,$A6,Sheet1!$D$5:$D$28252,"营业款",Sheet1!$E$5:$E$28252,"<>*调拨*",Sheet1!$E$5:$E$28252,"<>*回款*",Sheet1!$E$5:$E$28252,"<>*收款*",Sheet1!$E$5:$E$28252,"<>*医保*",Sheet1!$E$5:$E$28252,"<>*聚合*",Sheet1!$E$5:$E$28252,"<>*24小时微信*",Sheet1!$E$5:$E$28252,"<>*美团*",Sheet1!$E$5:$E$28252,"<>*饿了么*",Sheet1!$E$5:$E$28252,"<>*健E卡*",Sheet1!$E$5:$E$28252,"<>*抖音*",Sheet1!$E$5:$E$28252,"<>*医卡通*",Sheet1!$E$5:$E$28252,"<>*企健网*",Sheet1!$E$5:$E$28252,"<>*银联*",Sheet1!$E$5:$E$28252,"<>*京东*",Sheet1!$E$5:$E$28252,"<>*药机微信*",Sheet1!$E$5:$E$28252,"<>*亲情卡*",Sheet1!$E$5:$E$28252,"<>*优惠券*",Sheet1!$E$5:$E$28252,"<>*代金券*",Sheet1!$E$5:$E$28252,"<>*储值*",Sheet1!$E$5:$E$28252,"<>*效期*") -> 0 | D6: =SUMIFS(Sheet1!$F$5:$F$28252,Sheet1!$I$5:$I$28252,$B6,Sheet1!$L$5:$L$28252,$A6,Sheet1!$D$5:$D$28252,"医保即时拨付",Sheet1!$E$5:$E$28252,"<>*调拨*")+SUMIFS(Sheet1!$F$5:$F$28252,Sheet1!$I$5:$I$28252,$B6,Sheet1!$L$5:$L$28252,$A6,Sheet1!$E$5:$E$28252,"*医保即时拨付*",Sheet1!$D$5:$D$28252,"<>医保即时拨付",Sheet1!$D$5:$D$28252,"<>内部转款",Sheet1!$D$5:$D$28252,"<>内部转账",Sheet1!$E$5:$E$28252,"<>*调拨*") -> 0 | E6: =SUMIFS(Sheet1!$F$5:$F$28252,Sheet1!$I$5:$I$28252,$B6,Sheet1!$L$5:$L$28252,$A6,Sheet1!$D$5:$D$28252,"医保",Sheet1!$E$5:$E$28252,"<>*调拨*",Sheet1!$E$5:$E$28252,"<>*医保即时拨付*")+SUMIFS(Sheet1!$F$5:$F$28252,Sheet1!$I$5:$I$28252,$B6,Sheet1!$L$5:$L$28252,$A6,Sheet1!$E$5:$E$28252,"*医保*",Sheet1!$D$5:$D$28252,"<>医保",Sheet1!$D$5:$D$28252,"<>医保即时拨付",Sheet1!$D$5:$D$28252,"<>内部转款",Sheet1!$D$5:$D$28252,"<>内部转账",Sheet1!$E$5:$E$28252,"<>*医保即时拨付*",Sheet1!$E$5:$E$28252,"<>*调拨*") -> 0 | F6: =SUMIFS(Sheet1!$F$5:$F$28252,Sheet1!$I$5:$I$28252,$B6,Sheet1!$L$5:$L$28252,$A6,Sheet1!$D$5:$D$28252,"聚合",Sheet1!$E$5:$E$28252,"<>*调拨*")+SUMIFS(Sheet1!$F$5:$F$28252,Sheet1!$I$5:$I$28252,$B6,Sheet1!$L$5:$L$28252,$A6,Sheet1!$E$5:$E$28252,"*聚合*",Sheet1!$D$5:$D$28252,"<>聚合",Sheet1!$D$5:$D$28252,"<>内部转款",Sheet1!$D$5:$D$28252,"<>内部转账",Sheet1!$E$5:$E$28252,"<>*调拨*") -> 0 | G6: =SUMIFS(Sheet1!$F$5:$F$28252,Sheet1!$I$5:$I$28252,$B6,Sheet1!$L$5:$L$28252,$A6,Sheet1!$D$5:$D$28252,"24小时微信",Sheet1!$E$5:$E$28252,"<>*调拨*")+SUMIFS(Sheet1!$F$5:$F$28252,Sheet1!$I$5:$I$28252,$B6,Sheet1!$L$5:$L$28252,$A6,Sheet1!$E$5:$E$28252,"*24小时微信*",Sheet1!$D$5:$D$28252,"<>24小时微信",Sheet1!$D$5:$D$28252,"<>内部转款",Sheet1!$D$5:$D$28252,"<>内部转账",Sheet1!$E$5:$E$28252,"<>*调拨*") -> 0 | H6: =SUMIFS(Sheet1!$F$5:$F$28252,Sheet1!$I$5:$I$28252,$B6,Sheet1!$L$5:$L$28252,$A6,Sheet1!$D$5:$D$28252,"美团",Sheet1!$E$5:$E$28252,"<>*调拨*")+SUMIFS(Sheet1!$F$5:$F$28252,Sheet1!$I$5:$I$28252,$B6,Sheet1!$L$5:$L$28252,$A6,Sheet1!$E$5:$E$28252,"*美团*",Sheet1!$D$5:$D$28252,"<>美团",Sheet1!$D$5:$D$28252,"<>内部转款",Sheet1!$D$5:$D$28252,"<>内部转账",Sheet1!$E$5:$E$28252,"<>*调拨*") -> 0 | I6: =SUMIFS(Sheet1!$F$5:$F$28252,Sheet1!$I$5:$I$28252,$B6,Sheet1!$L$5:$L$28252,$A6,Sheet1!$D$5:$D$28252,"饿了么",Sheet1!$E$5:$E$28252,"<>*调拨*")+SUMIFS(Sheet1!$F$5:$F$28252,Sheet1!$I$5:$I$28252,$B6,Sheet1!$L$5:$L$28252,$A6,Sheet1!$E$5:$E$28252,"*饿了么*",Sheet1!$D$5:$D$28252,"<>饿了么",Sheet1!$D$5:$D$28252,"<>内部转款",Sheet1!$D$5:$D$28252,"<>内部转账",Sheet1!$E$5:$E$28252,"<>*调拨*") -> 0 | J6: =SUMIFS(Sheet1!$F$5:$F$28252,Sheet1!$I$5:$I$28252,$B6,Sheet1!$L$5:$L$28252,$A6,Sheet1!$D$5:$D$28252,"健E卡",Sheet1!$E$5:$E$28252,"<>*调拨*")+SUMIFS(Sheet1!$F$5:$F$28252,Sheet1!$I$5:$I$28252,$B6,Sheet1!$L$5:$L$28252,$A6,Sheet1!$E$5:$E$28252,"*健E卡*",Sheet1!$D$5:$D$28252,"<>健E卡",Sheet1!$D$5:$D$28252,"<>内部转款",Sheet1!$D$5:$D$28252,"<>内部转账",Sheet1!$E$5:$E$28252,"<>*调拨*") -> 0 | K6: =SUMIFS(Sheet1!$F$5:$F$28252,Sheet1!$I$5:$I$28252,$B6,Sheet1!$L$5:$L$28252,$A6,Sheet1!$D$5:$D$28252,"抖音",Sheet1!$E$5:$E$28252,"<>*调拨*")+SUMIFS(Sheet1!$F$5:$F$28252,Sheet1!$I$5:$I$28252,$B6,Sheet1!$L$5:$L$28252,$A6,Sheet1!$E$5:$E$28252,"*抖音*",Sheet1!$D$5:$D$28252,"<>抖音",Sheet1!$D$5:$D$28252,"<>内部转款",Sheet1!$D$5:$D$28252,"<>内部转账",Sheet1!$E$5:$E$28252,"<>*调拨*") -> 0 | L6: =SUMIFS(Sheet1!$F$5:$F$28252,Sheet1!$I$5:$I$28252,$B6,Sheet1!$L$5:$L$28252,$A6,Sheet1!$D$5:$D$28252,"医卡通",Sheet1!$E$5:$E$28252,"<>*调拨*")+SUMIFS(Sheet1!$F$5:$F$28252,Sheet1!$I$5:$I$28252,$B6,Sheet1!$L$5:$L$28252,$A6,Sheet1!$E$5:$E$28252,"*医卡通*",Sheet1!$D$5:$D$28252,"<>医卡通",Sheet1!$D$5:$D$28252,"<>内部转款",Sheet1!$D$5:$D$28252,"<>内部转账",Sheet1!$E$5:$E$28252,"<>*调拨*") -> 0 | M6: =SUMIFS(Sheet1!$F$5:$F$28252,Sheet1!$I$5:$I$28252,$B6,Sheet1!$L$5:$L$28252,$A6,Sheet1!$D$5:$D$28252,"企健网",Sheet1!$E$5:$E$28252,"<>*调拨*")+SUMIFS(Sheet1!$F$5:$F$28252,Sheet1!$I$5:$I$28252,$B6,Sheet1!$L$5:$L$28252,$A6,Sheet1!$E$5:$E$28252,"*企健网*",Sheet1!$D$5:$D$28252,"<>企健网",Sheet1!$D$5:$D$28252,"<>内部转款",Sheet1!$D$5:$D$28252,"<>内部转账",Sheet1!$E$5:$E$28252,"<>*调拨*") -> 0 | N6: =SUMIFS(Sheet1!$F$5:$F$28252,Sheet1!$I$5:$I$28252,$B6,Sheet1!$L$5:$L$28252,$A6,Sheet1!$D$5:$D$28252,"银联",Sheet1!$E$5:$E$28252,"<>*调拨*")+SUMIFS(Sheet1!$F$5:$F$28252,Sheet1!$I$5:$I$28252,$B6,Sheet1!$L$5:$L$28252,$A6,Sheet1!$E$5:$E$28252,"*银联*",Sheet1!$D$5:$D$28252,"<>银联",Sheet1!$D$5:$D$28252,"<>内部转款",Sheet1!$D$5:$D$28252,"<>内部转账",Sheet1!$E$5:$E$28252,"<>*调拨*") -> 0 | O6: =SUMIFS(Sheet1!$F$5:$F$28252,Sheet1!$I$5:$I$28252,$B6,Sheet1!$L$5:$L$28252,$A6,Sheet1!$D$5:$D$28252,"京东",Sheet1!$E$5:$E$28252,"<>*调拨*")+SUMIFS(Sheet1!$F$5:$F$28252,Sheet1!$I$5:$I$28252,$B6,Sheet1!$L$5:$L$28252,$A6,Sheet1!$E$5:$E$28252,"*京东*",Sheet1!$D$5:$D$28252,"<>京东",Sheet1!$D$5:$D$28252,"<>内部转款",Sheet1!$D$5:$D$28252,"<>内部转账",Sheet1!$E$5:$E$28252,"<>*调拨*") -> 0 | P6: =SUMIFS(Sheet1!$F$5:$F$28252,Sheet1!$I$5:$I$28252,$B6,Sheet1!$L$5:$L$28252,$A6,Sheet1!$D$5:$D$28252,"药机微信",Sheet1!$E$5:$E$28252,"<>*调拨*")+SUMIFS(Sheet1!$F$5:$F$28252,Sheet1!$I$5:$I$28252,$B6,Sheet1!$L$5:$L$28252,$A6,Sheet1!$E$5:$E$28252,"*药机微信*",Sheet1!$D$5:$D$28252,"<>药机微信",Sheet1!$D$5:$D$28252,"<>内部转款",Sheet1!$D$5:$D$28252,"<>内部转账",Sheet1!$E$5:$E$28252,"<>*调拨*") -> 0 | Q6: =SUMIFS(Sheet1!$F$5:$F$28252,Sheet1!$I$5:$I$28252,$B6,Sheet1!$L$5:$L$28252,$A6,Sheet1!$D$5:$D$28252,"亲情卡",Sheet1!$E$5:$E$28252,"<>*调拨*")+SUMIFS(Sheet1!$F$5:$F$28252,Sheet1!$I$5:$I$28252,$B6,Sheet1!$L$5:$L$28252,$A6,Sheet1!$E$5:$E$28252,"*亲情卡*",Sheet1!$D$5:$D$28252,"<>亲情卡",Sheet1!$D$5:$D$28252,"<>内部转款",Sheet1!$D$5:$D$28252,"<>内部转账",Sheet1!$E$5:$E$28252,"<>*调拨*") -> 0 | R6: =SUMIFS(Sheet1!$F$5:$F$28252,Sheet1!$I$5:$I$28252,$B6,Sheet1!$L$5:$L$28252,$A6,Sheet1!$D$5:$D$28252,"优惠券",Sheet1!$E$5:$E$28252,"<>*调拨*")+SUMIFS(Sheet1!$F$5:$F$28252,Sheet1!$I$5:$I$28252,$B6,Sheet1!$L$5:$L$28252,$A6,Sheet1!$E$5:$E$28252,"*优惠券*",Sheet1!$D$5:$D$28252,"<>优惠券",Sheet1!$D$5:$D$28252,"<>内部转款",Sheet1!$D$5:$D$28252,"<>内部转账",Sheet1!$E$5:$E$28252,"<>*调拨*") -> 0 | S6: =SUMIFS(Sheet1!$F$5:$F$28252,Sheet1!$I$5:$I$28252,$B6,Sheet1!$L$5:$L$28252,$A6,Sheet1!$D$5:$D$28252,"代金券",Sheet1!$E$5:$E$28252,"<>*调拨*")+SUMIFS(Sheet1!$F$5:$F$28252,Sheet1!$I$5:$I$28252,$B6,Sheet1!$L$5:$L$28252,$A6,Sheet1!$E$5:$E$28252,"*代金券*",Sheet1!$D$5:$D$28252,"<>代金券",Sheet1!$D$5:$D$28252,"<>内部转款",Sheet1!$D$5:$D$28252,"<>内部转账",Sheet1!$E$5:$E$28252,"<>*调拨*") -> 0 | T6: =SUMIFS(Sheet1!$F$5:$F$28252,Sheet1!$I$5:$I$28252,$B6,Sheet1!$L$5:$L$28252,$A6,Sheet1!$D$5:$D$28252,"回款",Sheet1!$E$5:$E$28252,"<>*调拨*",Sheet1!$E$5:$E$28252,"<>*医保*",Sheet1!$E$5:$E$28252,"<>*聚合*",Sheet1!$E$5:$E$28252,"<>*24小时微信*",Sheet1!$E$5:$E$28252,"<>*美团*",Sheet1!$E$5:$E$28252,"<>*饿了么*",Sheet1!$E$5:$E$28252,"<>*健E卡*",Sheet1!$E$5:$E$28252,"<>*抖音*",Sheet1!$E$5:$E$28252,"<>*医卡通*",Sheet1!$E$5:$E$28252,"<>*企健网*",Sheet1!$E$5:$E$28252,"<>*银联*",Sheet1!$E$5:$E$28252,"<>*京东*",Sheet1!$E$5:$E$28252,"<>*药机微信*",Sheet1!$E$5:$E$28252,"<>*亲情卡*",Sheet1!$E$5:$E$28252,"<>*优惠券*",Sheet1!$E$5:$E$28252,"<>*代金券*",Sheet1!$E$5:$E$28252,"<>*储值*",Sheet1!$E$5:$E$28252,"<>*效期*")+SUMIFS(Sheet1!$F$5:$F$28252,Sheet1!$I$5:$I$28252,$B6,Sheet1!$L$5:$L$28252,$A6,Sheet1!$D$5:$D$28252,"收款",Sheet1!$E$5:$E$28252,"<>*调拨*",Sheet1!$E$5:$E$28252,"<>*医保*",Sheet1!$E$5:$E$28252,"<>*聚合*",Sheet1!$E$5:$E$28252,"<>*24小时微信*",Sheet1!$E$5:$E$28252,"<>*美团*",Sheet1!$E$5:$E$28252,"<>*饿了么*",Sheet1!$E$5:$E$28252,"<>*健E卡*",Sheet1!$E$5:$E$28252,"<>*抖音*",Sheet1!$E$5:$E$28252,"<>*医卡通*",Sheet1!$E$5:$E$28252,"<>*企健网*",Sheet1!$E$5:$E$28252,"<>*银联*",Sheet1!$E$5:$E$28252,"<>*京东*",Sheet1!$E$5:$E$28252,"<>*药机微信*",Sheet1!$E$5:$E$28252,"<>*亲情卡*",Sheet1!$E$5:$E$28252,"<>*优惠券*",Sheet1!$E$5:$E$28252,"<>*代金券*",Sheet1!$E$5:$E$28252,"<>*储值*",Sheet1!$E$5:$E$28252,"<>*效期*")+SUMIFS(Sheet1!$F$5:$F$28252,Sheet1!$I$5:$I$28252,$B6,Sheet1!$L$5:$L$28252,$A6,Sheet1!$E$5:$E$28252,"*回款*",Sheet1!$D$5:$D$28252,"<>回款",Sheet1!$D$5:$D$28252,"<>收款",Sheet1!$D$5:$D$28252,"<>内部转款",Sheet1!$D$5:$D$28252,"<>内部转账",Sheet1!$E$5:$E$28252,"<>*调拨*",Sheet1!$E$5:$E$28252,"<>*医保*",Sheet1!$E$5:$E$28252,"<>*聚合*",Sheet1!$E$5:$E$28252,"<>*24小时微信*",Sheet1!$E$5:$E$28252,"<>*美团*",Sheet1!$E$5:$E$28252,"<>*饿了么*",Sheet1!$E$5:$E$28252,"<>*健E卡*",Sheet1!$E$5:$E$28252,"<>*抖音*",Sheet1!$E$5:$E$28252,"<>*医卡通*",Sheet1!$E$5:$E$28252,"<>*企健网*",Sheet1!$E$5:$E$28252,"<>*银联*",Sheet1!$E$5:$E$28252,"<>*京东*",Sheet1!$E$5:$E$28252,"<>*药机微信*",Sheet1!$E$5:$E$28252,"<>*亲情卡*",Sheet1!$E$5:$E$28252,"<>*优惠券*",Sheet1!$E$5:$E$28252,"<>*代金券*",Sheet1!$E$5:$E$28252,"<>*储值*",Sheet1!$E$5:$E$28252,"<>*效期*")+SUMIFS(Sheet1!$F$5:$F$28252,Sheet1!$I$5:$I$28252,$B6,Sheet1!$L$5:$L$28252,$A6,Sheet1!$E$5:$E$28252,"*收款*",Sheet1!$E$5:$E$28252,"<>*回款*",Sheet1!$D$5:$D$28252,"<>回款",Sheet1!$D$5:$D$28252,"<>收款",Sheet1!$D$5:$D$28252,"<>内部转款",Sheet1!$D$5:$D$28252,"<>内部转账",Sheet1!$E$5:$E$28252,"<>*调拨*",Sheet1!$E$5:$E$28252,"<>*医保*",Sheet1!$E$5:$E$28252,"<>*聚合*",Sheet1!$E$5:$E$28252,"<>*24小时微信*",Sheet1!$E$5:$E$28252,"<>*美团*",Sheet1!$E$5:$E$28252,"<>*饿了么*",Sheet1!$E$5:$E$28252,"<>*健E卡*",Sheet1!$E$5:$E$28252,"<>*抖音*",Sheet1!$E$5:$E$28252,"<>*医卡通*",Sheet1!$E$5:$E$28252,"<>*企健网*",Sheet1!$E$5:$E$28252,"<>*银联*",Sheet1!$E$5:$E$28252,"<>*京东*",Sheet1!$E$5:$E$28252,"<>*药机微信*",Sheet1!$E$5:$E$28252,"<>*亲情卡*",Sheet1!$E$5:$E$28252,"<>*优惠券*",Sheet1!$E$5:$E$28252,"<>*代金券*",Sheet1!$E$5:$E$28252,"<>*储值*",Sheet1!$E$5:$E$28252,"<>*效期*") -> 0 | U6: =SUMIFS(Sheet1!$F$5:$F$28252,Sheet1!$I$5:$I$28252,$B6,Sheet1!$L$5:$L$28252,$A6,Sheet1!$E$5:$E$28252,"*调拨*") -> 0 | V6: =SUMIFS(Sheet1!$F$5:$F$28252,Sheet1!$I$5:$I$28252,$B6,Sheet1!$L$5:$L$28252,$A6,Sheet1!$D$5:$D$28252,"储值",Sheet1!$E$5:$E$28252,"<>*调拨*")+SUMIFS(Sheet1!$F$5:$F$28252,Sheet1!$I$5:$I$28252,$B6,Sheet1!$L$5:$L$28252,$A6,Sheet1!$E$5:$E$28252,"*储值*",Sheet1!$D$5:$D$28252,"<>储值",Sheet1!$D$5:$D$28252,"<>内部转款",Sheet1!$D$5:$D$28252,"<>内部转账",Sheet1!$E$5:$E$28252,"<>*调拨*") -> 0 | W6: =SUMIFS(Sheet1!$F$5:$F$28252,Sheet1!$I$5:$I$28252,$B6,Sheet1!$L$5:$L$28252,$A6,Sheet1!$D$5:$D$28252,"效期",Sheet1!$E$5:$E$28252,"<>*调拨*")+SUMIFS(Sheet1!$F$5:$F$28252,Sheet1!$I$5:$I$28252,$B6,Sheet1!$L$5:$L$28252,$A6,Sheet1!$E$5:$E$28252,"*效期*",Sheet1!$D$5:$D$28252,"<>效期",Sheet1!$D$5:$D$28252,"<>内部转款",Sheet1!$D$5:$D$28252,"<>内部转账",Sheet1!$E$5:$E$28252,"<>*调拨*") -> 0 | X6: =SUMIFS(Sheet1!$F$5:$F$28252,Sheet1!$I$5:$I$28252,$B6,Sheet1!$L$5:$L$28252,$A6,Sheet1!$D$5:$D$28252,"内部转款",Sheet1!$E$5:$E$28252,"<>*调拨*")+SUMIFS(Sheet1!$F$5:$F$28252,Sheet1!$I$5:$I$28252,$B6,Sheet1!$L$5:$L$28252,$A6,Sheet1!$D$5:$D$28252,"内部转账",Sheet1!$E$5:$E$28252,"<>*调拨*") -> 0 | Y6: =Z6-SUM(C6:X6) -> 0 | Z6: =SUMIFS(Sheet1!$F$5:$F$28252,Sheet1!$I$5:$I$28252,$B6,Sheet1!$L$5:$L$28252,$A6) -> 0 | AA6: =SUMIFS(Sheet1!$G$5:$G$28252,Sheet1!$I$5:$I$28252,$B6,Sheet1!$L$5:$L$28252,$A6,Sheet1!$D$5:$D$28252,"工资",Sheet1!$E$5:$E$28252,"<>*调拨*")+SUMIFS(Sheet1!$G$5:$G$28252,Sheet1!$I$5:$I$28252,$B6,Sheet1!$L$5:$L$28252,$A6,Sheet1!$E$5:$E$28252,"*工资*",Sheet1!$E$5:$E$28252,"<>*调拨*",Sheet1!$D$5:$D$28252,"<>内部转款",Sheet1!$D$5:$D$28252,"<>内部转账",Sheet1!$D$5:$D$28252,"<>工资",Sheet1!$D$5:$D$28252,"<>水费",Sheet1!$D$5:$D$28252,"<>电费",Sheet1!$D$5:$D$28252,"<>宽带费",Sheet1!$D$5:$D$28252,"<>办公费",Sheet1!$D$5:$D$28252,"<>话费",Sheet1!$D$5:$D$28252,"<>房租") -> 0 | AB6: =SUMIFS(Sheet1!$G$5:$G$28252,Sheet1!$I$5:$I$28252,$B6,Sheet1!$L$5:$L$28252,$A6,Sheet1!$D$5:$D$28252,"水费",Sheet1!$E$5:$E$28252,"<>*调拨*")+SUMIFS(Sheet1!$G$5:$G$28252,Sheet1!$I$5:$I$28252,$B6,Sheet1!$L$5:$L$28252,$A6,Sheet1!$E$5:$E$28252,"*水费*",Sheet1!$E$5:$E$28252,"<>*调拨*",Sheet1!$D$5:$D$28252,"<>内部转款",Sheet1!$D$5:$D$28252,"<>内部转账",Sheet1!$D$5:$D$28252,"<>工资",Sheet1!$D$5:$D$28252,"<>水费",Sheet1!$D$5:$D$28252,"<>电费",Sheet1!$D$5:$D$28252,"<>宽带费",Sheet1!$D$5:$D$28252,"<>办公费",Sheet1!$D$5:$D$28252,"<>话费",Sheet1!$D$5:$D$28252,"<>房租",Sheet1!$E$5:$E$28252,"<>*工资*") -> 0 | AC6: =SUMIFS(Sheet1!$G$5:$G$28252,Sheet1!$I$5:$I$28252,$B6,Sheet1!$L$5:$L$28252,$A6,Sheet1!$D$5:$D$28252,"电费",Sheet1!$E$5:$E$28252,"<>*调拨*")+SUMIFS(Sheet1!$G$5:$G$28252,Sheet1!$I$5:$I$28252,$B6,Sheet1!$L$5:$L$28252,$A6,Sheet1!$E$5:$E$28252,"*电费*",Sheet1!$E$5:$E$28252,"<>*调拨*",Sheet1!$D$5:$D$28252,"<>内部转款",Sheet1!$D$5:$D$28252,"<>内部转账",Sheet1!$D$5:$D$28252,"<>工资",Sheet1!$D$5:$D$28252,"<>水费",Sheet1!$D$5:$D$28252,"<>电费",Sheet1!$D$5:$D$28252,"<>宽带费",Sheet1!$D$5:$D$28252,"<>办公费",Sheet1!$D$5:$D$28252,"<>话费",Sheet1!$D$5:$D$28252,"<>房租",Sheet1!$E$5:$E$28252,"<>*工资*",Sheet1!$E$5:$E$28252,"<>*水费*") -> 0 | AD6: =SUMIFS(Sheet1!$G$5:$G$28252,Sheet1!$I$5:$I$28252,$B6,Sheet1!$L$5:$L$28252,$A6,Sheet1!$D$5:$D$28252,"宽带费",Sheet1!$E$5:$E$28252,"<>*调拨*")+SUMIFS(Sheet1!$G$5:$G$28252,Sheet1!$I$5:$I$28252,$B6,Sheet1!$L$5:$L$28252,$A6,Sheet1!$E$5:$E$28252,"*宽带*",Sheet1!$E$5:$E$28252,"<>*调拨*",Sheet1!$D$5:$D$28252,"<>内部转款",Sheet1!$D$5:$D$28252,"<>内部转账",Sheet1!$D$5:$D$28252,"<>工资",Sheet1!$D$5:$D$28252,"<>水费",Sheet1!$D$5:$D$28252,"<>电费",Sheet1!$D$5:$D$28252,"<>宽带费",Sheet1!$D$5:$D$28252,"<>办公费",Sheet1!$D$5:$D$28252,"<>话费",Sheet1!$D$5:$D$28252,"<>房租",Sheet1!$E$5:$E$28252,"<>*工资*",Sheet1!$E$5:$E$28252,"<>*水费*",Sheet1!$E$5:$E$28252,"<>*电费*") -> 0 | AE6: =SUMIFS(Sheet1!$G$5:$G$28252,Sheet1!$I$5:$I$28252,$B6,Sheet1!$L$5:$L$28252,$A6,Sheet1!$D$5:$D$28252,"办公费",Sheet1!$E$5:$E$28252,"<>*调拨*")+SUMIFS(Sheet1!$G$5:$G$28252,Sheet1!$I$5:$I$28252,$B6,Sheet1!$L$5:$L$28252,$A6,Sheet1!$E$5:$E$28252,"*办公*",Sheet1!$E$5:$E$28252,"<>*调拨*",Sheet1!$D$5:$D$28252,"<>内部转款",Sheet1!$D$5:$D$28252,"<>内部转账",Sheet1!$D$5:$D$28252,"<>工资",Sheet1!$D$5:$D$28252,"<>水费",Sheet1!$D$5:$D$28252,"<>电费",Sheet1!$D$5:$D$28252,"<>宽带费",Sheet1!$D$5:$D$28252,"<>办公费",Sheet1!$D$5:$D$28252,"<>话费",Sheet1!$D$5:$D$28252,"<>房租",Sheet1!$E$5:$E$28252,"<>*工资*",Sheet1!$E$5:$E$28252,"<>*水费*",Sheet1!$E$5:$E$28252,"<>*电费*",Sheet1!$E$5:$E$28252,"<>*宽带*") -> 0 | AF6: =SUMIFS(Sheet1!$G$5:$G$28252,Sheet1!$I$5:$I$28252,$B6,Sheet1!$L$5:$L$28252,$A6,Sheet1!$D$5:$D$28252,"话费",Sheet1!$E$5:$E$28252,"<>*调拨*")+SUMIFS(Sheet1!$G$5:$G$28252,Sheet1!$I$5:$I$28252,$B6,Sheet1!$L$5:$L$28252,$A6,Sheet1!$E$5:$E$28252,"*话费*",Sheet1!$E$5:$E$28252,"<>*调拨*",Sheet1!$D$5:$D$28252,"<>内部转款",Sheet1!$D$5:$D$28252,"<>内部转账",Sheet1!$D$5:$D$28252,"<>工资",Sheet1!$D$5:$D$28252,"<>水费",Sheet1!$D$5:$D$28252,"<>电费",Sheet1!$D$5:$D$28252,"<>宽带费",Sheet1!$D$5:$D$28252,"<>办公费",Sheet1!$D$5:$D$28252,"<>话费",Sheet1!$D$5:$D$28252,"<>房租",Sheet1!$E$5:$E$28252,"<>*工资*",Sheet1!$E$5:$E$28252,"<>*水费*",Sheet1!$E$5:$E$28252,"<>*电费*",Sheet1!$E$5:$E$28252,"<>*宽带*",Sheet1!$E$5:$E$28252,"<>*办公*") -> 0 | AG6: =SUMIFS(Sheet1!$G$5:$G$28252,Sheet1!$I$5:$I$28252,$B6,Sheet1!$L$5:$L$28252,$A6,Sheet1!$D$5:$D$28252,"房租",Sheet1!$E$5:$E$28252,"<>*调拨*")+SUMIFS(Sheet1!$G$5:$G$28252,Sheet1!$I$5:$I$28252,$B6,Sheet1!$L$5:$L$28252,$A6,Sheet1!$E$5:$E$28252,"*房租*",Sheet1!$E$5:$E$28252,"<>*调拨*",Sheet1!$D$5:$D$28252,"<>内部转款",Sheet1!$D$5:$D$28252,"<>内部转账",Sheet1!$D$5:$D$28252,"<>工资",Sheet1!$D$5:$D$28252,"<>水费",Sheet1!$D$5:$D$28252,"<>电费",Sheet1!$D$5:$D$28252,"<>宽带费",Sheet1!$D$5:$D$28252,"<>办公费",Sheet1!$D$5:$D$28252,"<>话费",Sheet1!$D$5:$D$28252,"<>房租",Sheet1!$E$5:$E$28252,"<>*工资*",Sheet1!$E$5:$E$28252,"<>*水费*",Sheet1!$E$5:$E$28252,"<>*电费*",Sheet1!$E$5:$E$28252,"<>*宽带*",Sheet1!$E$5:$E$28252,"<>*办公*",Sheet1!$E$5:$E$28252,"<>*话费*") -> 0 | AH6: =SUMIFS(Sheet1!$G$5:$G$28252,Sheet1!$I$5:$I$28252,$B6,Sheet1!$L$5:$L$28252,$A6,Sheet1!$E$5:$E$28252,"*调拨*") -> 0 | AI6: =SUMIFS(Sheet1!$G$5:$G$28252,Sheet1!$I$5:$I$28252,$B6,Sheet1!$L$5:$L$28252,$A6,Sheet1!$D$5:$D$28252,"内部转款",Sheet1!$E$5:$E$28252,"<>*调拨*")+SUMIFS(Sheet1!$G$5:$G$28252,Sheet1!$I$5:$I$28252,$B6,Sheet1!$L$5:$L$28252,$A6,Sheet1!$D$5:$D$28252,"内部转账",Sheet1!$E$5:$E$28252,"<>*调拨*") -> 0 | AJ6: =AK6-SUM(AA6:AI6) -> 0 | AK6: =SUMIFS(Sheet1!$G$5:$G$28252,Sheet1!$I$5:$I$28252,$B6,Sheet1!$L$5:$L$28252,$A6) -> 0 | AL6: =Z6-AK6 -> 0
