Workbook
Name 差旅费: [1]名称!$B$21
Name 费用类别: #REF!
Name 明细科目编码: [2]会计科目表!$A$3:$A$70
Name 明细科目名称: [2]会计科目表!$B$3:$B$70
Name 日期: #REF!
Name 收费项: [3]名称!$B$2:$B$40
Name 收入现金: #REF!
Name 薪资福利: [3]名称!$B$2:$B$45
Name 月份: #REF!
Name 支出现金: #REF!
Name 总账科目名称: [2]总账科目!$B$3:$B$40

Sheet 目录
B1: 目录 | C1: 跳转链接
B2: {=_wpsfn.SHEETSNAME(,1,1)} -> 汇总 | C2: =HYPERLINK("#"&B2&"!a1","跳转链接") -> 跳转链接
B3: 付费项 | C3: =HYPERLINK("#"&B3&"!a1","跳转链接") -> 跳转链接
B4: 力喆实业中国银行 | C4: =HYPERLINK("#"&B4&"!a1","跳转链接") -> 跳转链接
B5: 力喆产业农商银行 | C5: =HYPERLINK("#"&B5&"!a1","跳转链接") -> 跳转链接
B6: 元生万物建设银行 | C6: =HYPERLINK("#"&B6&"!a1","跳转链接") -> 跳转链接
B7: 言吾言中国银行 | C7: =HYPERLINK("#"&B7&"!a1","跳转链接") -> 跳转链接
B8: 力喆传媒海峡银行 | C8: =HYPERLINK("#"&B8&"!a1","跳转链接") -> 跳转链接
B9: 徐洁招商银行 | C9: =HYPERLINK("#"&B9&"!a1","跳转链接") -> 跳转链接 | M9: SHEETSNAME(,1,1)
B10: 力喆贸易建设银行 | C10: =HYPERLINK("#"&B10&"!a1","跳转链接") -> 跳转链接 | M10: HYPERLINK("#"&B2&"!a1","跳转链接")
B11: 古玩城农商银行 | C11: =HYPERLINK("#"&B11&"!a1","跳转链接") -> 跳转链接 | M11: HYPERLINK("#目录!a1","返回目录")
B12: 古玩城现金 | C12: =HYPERLINK("#"&B12&"!a1","跳转链接") -> 跳转链接
B13: 艾泊烨海峡银行 | C13: =HYPERLINK("#"&B13&"!a1","跳转链接") -> 跳转链接
B14: 艾泊烨招商银行 | C14: =HYPERLINK("#"&B14&"!a1","跳转链接") -> 跳转链接
B15: 艾泊烨农商银行 | C15: =HYPERLINK("#"&B15&"!a1","跳转链接") -> 跳转链接
B16: 艾泊烨私户银行 | C16: =HYPERLINK("#"&B16&"!a1","跳转链接") -> 跳转链接
B17: 博烨体育农商银行 | C17: =HYPERLINK("#"&B17&"!a1","跳转链接") -> 跳转链接
B18: 博烨私户 | C18: =HYPERLINK("#"&B18&"!a1","跳转链接") -> 跳转链接
B19: 博烨篮球馆 | C19: =HYPERLINK("#"&B19&"!a1","跳转链接") -> 跳转链接
B20: 博烨羽毛球 | C20: =HYPERLINK("#"&B20&"!a1","跳转链接") -> 跳转链接
B21: 博烨健身房 | C21: =HYPERLINK("#"&B21&"!a1","跳转链接") -> 跳转链接
B22: 博烨匹克球 | C22: =HYPERLINK("#"&B22&"!a1","跳转链接") -> 跳转链接
B23: Sheet1 | C23: =HYPERLINK("#"&B23&"!a1","跳转链接") -> 跳转链接
... B29: 易佰兴农商银行外 | C29: =HYPERLINK("#"&B29&"!a1","跳转链接") -> 跳转链接
C30: =HYPERLINK("#"&B30&"!a1","跳转链接") -> 跳转链接
C31: =HYPERLINK("#"&B31&"!a1","跳转链接") -> 跳转链接
C32: =HYPERLINK("#"&B32&"!a1","跳转链接") -> 跳转链接
C33: =HYPERLINK("#"&B33&"!a1","跳转链接") -> 跳转链接
C34: =HYPERLINK("#"&B34&"!a1","跳转链接") -> 跳转链接

Sheet 中策管理海峡银行
A1: =HYPERLINK("#目录!a1","返回目录") -> 返回目录 | B1: 银行日记账--海峡银行
B3: 月 | C3: 日 | D3: 收费项 | E3: 收付人 | F3: 摘要 | G3: 收入 | H3: 支出 | I3: 余额 | J3: 备注
F4: 期初余额 | I4: 176530.77
B5: 1 | C5: 5 | D5: 银行手续费 | E5: 福建海峡银行股份有限公司福州金城支行 | F5: 支付短信通服务费 | H5: 10 | I5: =I4+G5-H5 -> 176520.77
B6: 1 | C6: 11 | E6: 福建海峡银行股份有限公司福州金城支行 | F6: 自助回单打印机服务费 | H6: 60 | I6: =I5+G6-H6 -> 176460.77
B7: 1 | C7: 15 | E7: 徐洁 | F7: 收徐洁服务费 | G7: 4000 | I7: =I6+G7-H7 -> 180460.77
F8: 本月合计 | G8: =SUM(G5:G7) -> 4000 | H8: =SUM(H5:H7) -> 70 | I8: =I4+G8-H8 -> 180460.77
B9: 2 | C9: 2 | E9: 福建悟空游国际旅行社有限公司 | F9: 旅游费用 | H9: 21320 | I9: =I8+G9-H9 -> 159140.77
B10: 2 | C10: 5 | D10: 银行手续费 | E10: 福建海峡银行股份有限公司福州金城支行 | F10: 支付短信通服务费 | H10: 10 | I10: =I9+G10-H10 -> 159130.77
B11: 2 | C11: 13 | E11: 徐洁 | F11: 收徐洁服务费 | G11: 4000 | I11: =I10+G11-H11 -> 163130.77
B12: 2 | C12: 26 | E12: 福州晋安中策管理咨询有限公司 | F12: 提取备用金 | H12: 48000 | I12: =I11+G12-H12 -> 115130.77
B13: 2 | C13: 28 | E13: 福建悟空游国际旅行社有限公司 | F13: 退回旅游费用 | G13: 800 | I13: =I12+G13-H13 -> 115930.77
F14: 本月合计 | G14: =SUM(G9:G13) -> 4800 | H14: =SUM(H9:H13) -> 69330 | I14: =I8+G14-H14 -> 115930.77
B15: 3 | C15: 5 | D15: 银行手续费 | E15: 福建海峡银行股份有限公司福州金城支行 | F15: 支付短信通服务费 | H15: 10 | I15: =I14+G15-H15 -> 115920.77
B16: 3 | C16: 16 | E16: 徐洁 | F16: 收徐洁服务费 | G16: 4000 | I16: =I15+G16-H16 -> 119920.77
B17: 3 | C17: 21 | E17: 银行 | F17: 利息收入 | G17: 19.75 | I17: =I16+G17-H17 -> 119940.52
F18: 本月合计 | G18: =SUM(G15:G17) -> 4019.75 | H18: =SUM(H15:H17) -> 10 | I18: =I14+G18-H18 -> 119940.52
I19: =I18+G19-H19 -> 119940.52
I20: =I19+G20-H20 -> 119940.52
I21: =I20+G21-H21 -> 119940.52
I22: =I21+G22-H22 -> 119940.52
I23: =I22+G23-H23 -> 119940.52
I24: =I23+G24-H24 -> 119940.52
I25: =I24+G25-H25 -> 119940.52
I26: =I25+G26-H26 -> 119940.52
I27: =I26+G27-H27 -> 119940.52
I28: =I27+G28-H28 -> 119940.52
I29: =I28+G29-H29 -> 119940.52
I30: =I29+G30-H30 -> 119940.52
... I65: =I64+G65-H65 -> 119940.52

Sheet 四季快安兴业银行
A1: =HYPERLINK("#目录!a1","返回目录") -> 返回目录 | B1: 银行日记账--兴业银行
B3: 月 | C3: 日 | D3: 收费项 | E3: 收付人 | F3: 摘要 | G3: 收入 | H3: 支出 | I3: 余额 | J3: 备注
F4: 期初余额 | I4: 125.51
B5: 1 | C5: 15 | E5: 福建省健坤德行资产管理有限责任公司 | F5: 收到福建省健坤德行资产管理有限责任公司借款 | G5: 35000 | I5: =I4+G5-H5 -> 35125.51
B6: 1 | C6: 15 | E6: 福建丰华智能停车场管理有限公司 | F6: 支付福建丰华智能停车场管理有限公司借款 | H6: 35000 | I6: =I5+G6-H6 -> 125.51
B7: 1 | C7: 15 | F7: 支付银行手续费 | H7: 0.5 | I7: =I6+G7-H7 -> 125.01
F8: 本月合计 | G8: =SUM(G5:G7) -> 35000 | H8: =SUM(H5:H7) -> 35000.5 | I8: =I4+G8-H8 -> 125.01
B9: 2 | C9: 12 | E9: 福建省健坤德行资产管理有限责任公司 | F9: 收到福建省健坤德行资产管理有限责任公司借款 | G9: 85000 | I9: =I8+G9-H9 -> 85125.01
B10: 2 | C10: 12 | E10: 福建丰华智能停车场管理有限公司 | F10: 支付福建丰华智能停车场管理有限公司借款 | H10: 85000 | I10: =I9+G10-H10 -> 125.01
B11: 2 | C11: 12 | F11: 支付银行手续费 | H11: 0.5 | I11: =I10+G11-H11 -> 124.51
F12: 本月合计 | G12: =SUM(G9:G11) -> 85000 | H12: =SUM(H9:H11) -> 85000.5 | I12: =I8+G12-H12 -> 124.51
B13: 3 | C13: 16 | E13: 福建省健坤德行资产管理有限责任公司 | F13: 收到福建省健坤德行资产管理有限责任公司借款 | G13: 30000 | I13: =I12+G13-H13 -> 30124.51
B14: 3 | C14: 16 | E14: 福建丰华智能停车场管理有限公司 | F14: 支付福建丰华智能停车场管理有限公司借款 | H14: 30000 | I14: =I13+G14-H14 -> 124.51
B15: 3 | C15: 16 | F15: 支付银行手续费 | H15: 0.5 | I15: =I14+G15-H15 -> 124.01
B16: 3 | C16: 21 | E16: 银行 | F16: 利息收入 | G16: 0.02 | I16: =I15+G16-H16 -> 124.03
F17: 本月合计 | G17: =SUM(G13:G16) -> 30000.02 | H17: =SUM(H13:H16) -> 30000.5 | I17: =I12+G17-H17 -> 124.03
B18: 4 | C18: 14 | F18: 支付银行手续费 | H18: 0.5 | I18: =I17+G18-H18 -> 123.53
B19: 4 | C19: 14 | E19: 福建省健坤德行资产管理有限责任公司 | F19: 收到福建省健坤德行资产管理有限责任公司借款 | G19: 55000 | I19: =I18+G19-H19 -> 55123.53
B20: 4 | C20: 14 | E20: 福建丰华智能停车场管理有限公司 | F20: 支付福建丰华智能停车场管理有限公司借款 | H20: 55000 | I20: =I19+G20-H20 -> 123.53
B21: 4 | C21: 14 | F21: 支付银行手续费 | H21: 0.5 | I21: =I20+G21-H21 -> 123.03
B22: 4 | C22: 16 | E22: 福建省健坤德行资产管理有限责任公司 | F22: 收到福建省健坤德行资产管理有限责任公司借款 | G22: 120000 | I22: =I21+G22-H22 -> 120123.03
B23: 4 | C23: 16 | E23: 福建丰华智能停车场管理有限公司 | F23: 支付福建丰华智能停车场管理有限公司借款 | H23: 120000 | I23: =I22+G23-H23 -> 123.03
B24: 4 | C24: 16 | F24: 支付银行手续费 | H24: 0.5 | I24: =I23+G24-H24 -> 122.53
I25: =I24+G25-H25 -> 122.53
I26: =I25+G26-H26 -> 122.53
I27: =I26+G27-H27 -> 122.53
I28: =I27+G28-H28 -> 122.53
I29: =I28+G29-H29 -> 122.53
I30: =I29+G30-H30 -> 122.53
I31: =I30+G31-H31 -> 122.53
I32: =I31+G32-H32 -> 122.53
I33: =I32+G33-H33 -> 122.53
I34: =I33+G34-H34 -> 122.53
I35: =I34+G35-H35 -> 122.53
I36: =I35+G36-H36 -> 122.53
... I65: =I64+G65-H65 -> 122.53

Sheet 汇总
B1: 2026 | C1: 年各公司收支明细表
A2: =HYPERLINK("#目录!a1","返回目录") -> 返回目录 | B2: 年份 | C2: 2026 | D2: 月份 | E2: 5
E3: 力喆中国银行 | F3: 力喆农商银行 | G3: 力喆私户 | H3: 力喆贸易建行 | I3: 元生万物建行 | J3: 言吾言中行 | K3: 传媒海峡银行 | L3: 古玩城农商银行 | M3: 古玩城现金 | N3: 艾泊烨海峡银行 | O3: 艾泊烨招商银行 | P3: 艾泊烨农商银行 | Q3: 艾泊烨私户 | R3: 易佰兴建行 | S3: 易佰兴私户 | T3: 易佰兴现金 | U3: 易佰兴基本户
A4: 收入明细表 | B4: 月份 | C4: 收入明细 | D4: 青翼创 | E4: 力喆实业 | F4: 力喆实业 | G4: 力喆实业 | H4: 力喆贸易 | I4: 元生万物 | J4: 言吾言 | K4: 力喆传媒 | L4: 古玩城 | M4: 古玩城 | N4: 艾泊烨 | O4: 艾泊烨 | P4: 艾泊烨 | Q4: 艾泊烨 | R4: 易佰兴 | S4: 易佰兴 | T4: 易佰兴 | U4: 易佰兴
C5: 银行期初余额 | D5: =SUMIFS(Sheet1!$L:$L,Sheet1!$A:$A,"="&$E$2) -> 17724.83 | E5: =SUMIFS(Sheet1!$M:$M,Sheet1!$A:$A,"="&$E$2) -> 0 | F5: =SUMIFS(Sheet1!$N:$N,Sheet1!$A:$A,"="&$E$2) -> 6814.57 | G5: =SUMIFS(Sheet1!$R:$R,Sheet1!$A:$A,"="&$E$2) -> 12055.05 | H5: =SUMIFS(Sheet1!$S:$S,Sheet1!$A:$A,"="&$E$2) -> 11156.41 | I5: =SUMIFS(Sheet1!$O:$O,Sheet1!$A:$A,"="&$E$2) -> 35003.97 | J5: =SUMIFS(Sheet1!$P:$P,Sheet1!$A:$A,"="&$E$2) -> 4419.25 | K5: =SUMIFS(Sheet1!$Q:$Q,Sheet1!$A:$A,"="&$E$2) -> 0 | L5: =SUMIFS(Sheet1!$B:$B,Sheet1!$A:$A,"="&$E$2) -> 155258.06 | M5: =SUMIFS(Sheet1!$C:$C,Sheet1!$A:$A,"="&$E$2) -> 0 | N5: =SUMIFS(Sheet1!$D:$D,Sheet1!$A:$A,"="&$E$2) -> 118439.59 | O5: =SUMIFS(Sheet1!$E:$E,Sheet1!$A:$A,"="&$E$2) -> 30536.78 | P5: =SUMIFS(Sheet1!$F:$F,Sheet1!$A:$A,"="&$E$2) -> 3279.77 | Q5: =SUMIFS(Sheet1!$G:$G,Sheet1!$A:$A,"="&$E$2) -> 28831.41 | R5: =SUMIFS(Sheet1!$H:$H,Sheet1!$A:$A,"="&$E$2) -> 8822.26 | S5: =SUMIFS(Sheet1!$I:$I,Sheet1!$A:$A,"="&$E$2) -> 127662.01 | T5: =SUMIFS(Sheet1!$J:$J,Sheet1!$A:$A,"="&$E$2) -> 0 | U5: =SUMIFS(Sheet1!$K:$K,Sheet1!$A:$A,"="&$E$2) -> 1352.1
B6: =E2 -> 5 | C6: 押金 | D6: =SUMIFS(#REF!,#REF!,"="&$E$2,#REF!,"="&$C6) -> #REF! | E6: =SUMIFS(力喆实业中国银行!$G:$G,力喆实业中国银行!$B:$B,"="&$E$2,力喆实业中国银行!$D:$D,"="&$C6) -> 0 | F6: =SUMIFS(力喆产业农商银行!$G:$G,力喆产业农商银行!$B:$B,"="&$E$2,力喆产业农商银行!$D:$D,"="&$C6) -> 0 | G6: =SUMIFS(徐洁招商银行!$G:$G,徐洁招商银行!$B:$B,"="&$E$2,徐洁招商银行!$D:$D,"="&$C6) -> 0 | H6: =SUMIFS(力喆贸易建设银行!$G:$G,力喆贸易建设银行!$B:$B,"="&$E$2,力喆贸易建设银行!$D:$D,"="&$C6) -> 0 | I6: =SUMIFS(元生万物建设银行!$G:$G,元生万物建设银行!$B:$B,"="&$E$2,元生万物建设银行!$D:$D,"="&$C6) -> 0 | J6: =SUMIFS(言吾言中国银行!$G:$G,言吾言中国银行!$B:$B,"="&$E$2,言吾言中国银行!$D:$D,"="&$C6) -> 0 | K6: =SUMIFS(力喆传媒海峡银行!$G:$G,力喆传媒海峡银行!$B:$B,"="&$E$2,力喆传媒海峡银行!$D:$D,"="&$C6) -> 0 | L6: =SUMIFS(古玩城农商银行!$J:$J,古玩城农商银行!$B:$B,"="&$E$2) -> 22200 | M6: =SUMIFS(古玩城现金!$J:$J,古玩城现金!$B:$B,"="&$E$2) -> 0 | N6: =SUMIFS(艾泊烨海峡银行!$G:$G,艾泊烨海峡银行!$B:$B,"="&$E$2,艾泊烨海峡银行!$D:$D,"="&$C6) -> 0 | O6: 0 | P6: =SUMIFS(艾泊烨农商银行!$I:$I,艾泊烨农商银行!$B:$B,"="&$E$2,艾泊烨农商银行!$D:$D,"="&$C6) -> 0 | Q6: =SUMIFS(艾泊烨私户银行!$G:$G,艾泊烨私户银行!$B:$B,"="&$E$2,艾泊烨私户银行!$D:$D,"="&$C6) -> 27380 | R6: =SUMIFS(易佰兴建行!$J:$J,易佰兴建行!$B:$B,"="&$E$2) -> 41422 | S6: =SUMIFS(易佰兴私户!$J:$J,易佰兴私户!$B:$B,"="&$E$2) -> 0 | T6: =SUMIFS(易佰兴现金!$J:$J,易佰兴现金!$B:$B,"="&$E$2) -> 0 | U6: =SUMIFS(易佰兴基本户!$J:$J,易佰兴基本户!$B:$B,"="&$E$2) -> 0
B7: =B6 -> 5 | C7: 往来款 | D7: =SUMIFS(#REF!,#REF!,"="&$E$2,#REF!,"="&$C7) -> #REF! | E7: =SUMIFS(力喆实业中国银行!$G:$G,力喆实业中国银行!$B:$B,"="&$E$2,力喆实业中国银行!$D:$D,"="&$C7) -> 0 | F7: =SUMIFS(力喆产业农商银行!$G:$G,力喆产业农商银行!$B:$B,"="&$E$2,力喆产业农商银行!$D:$D,"="&$C7) -> 47832.11 | G7: =SUMIFS(徐洁招商银行!$G:$G,徐洁招商银行!$B:$B,"="&$E$2,徐洁招商银行!$D:$D,"="&$C7) -> 25000 | H7: =SUMIFS(力喆贸易建设银行!$G:$G,力喆贸易建设银行!$B:$B,"="&$E$2,力喆贸易建设银行!$D:$D,"="&$C7) -> 0 | I7: =SUMIFS(元生万物建设银行!$G:$G,元生万物建设银行!$B:$B,"="&$E$2,元生万物建设银行!$D:$D,"="&$C7) -> 30098.25 | J7: =SUMIFS(言吾言中国银行!$G:$G,言吾言中国银行!$B:$B,"="&$E$2,言吾言中国银行!$D:$D,"="&$C7) -> 0 | K7: =SUMIFS(力喆传媒海峡银行!$G:$G,力喆传媒海峡银行!$B:$B,"="&$E$2,力喆传媒海峡银行!$D:$D,"="&$C7) -> 0 | M7: =SUMIFS(古玩城现金!$D:$D,古玩城现金!$B:$B,"="&$E$2) -> 0 | N7: =SUMIFS(艾泊烨海峡银行!$G:$G,艾泊烨海峡银行!$B:$B,"="&$E$2,艾泊烨海峡银行!$D:$D,"="&$C7) -> 0 | O7: 0 | P7: =SUMIFS(艾泊烨农商银行!$I:$I,艾泊烨农商银行!$B:$B,"="&$E$2,艾泊烨农商银行!$D:$D,"="&$C7) -> 16000 | Q7: =SUMIFS(艾泊烨私户银行!$G:$G,艾泊烨私户银行!$B:$B,"="&$E$2,艾泊烨私户银行!$D:$D,"="&$C7) -> 0 | R7: =SUMIFS(易佰兴建行!$O:$O,易佰兴建行!$B:$B,"="&$E$2,易佰兴建行!D:D,"="&$C7) -> 0 | S7: 0 | T7: =SUMIFS(易佰兴现金!$J:$J,易佰兴现金!$B:$B,"="&$E$2) -> 0 | U7: =SUMIFS(易佰兴基本户!$O:$O,易佰兴基本户!$B:$B,"="&$E$2,易佰兴基本户!$D:$D,"="&$C7) -> 24300
B8: =B24 -> 5 | C8: 场地租金收入 | E8: =SUMIFS(力喆实业中国银行!$G:$G,力喆实业中国银行!$B:$B,"="&$E$2,力喆实业中国银行!$D:$D,"="&$C8) -> 0 | F8: =SUMIFS(力喆产业农商银行!$G:$G,力喆产业农商银行!$B:$B,"="&$E$2,力喆产业农商银行!$D:$D,"="&$C8) -> 0 | G8: =SUMIFS(徐洁招商银行!$G:$G,徐洁招商银行!$B:$B,"="&$E$2,徐洁招商银行!$D:$D,"="&$C8) -> 0 | H8: =SUMIFS(力喆贸易建设银行!$G:$G,力喆贸易建设银行!$B:$B,"="&$E$2,力喆贸易建设银行!$D:$D,"="&$C8) -> 0 | J8: =SUMIFS(言吾言中国银行!$G:$G,言吾言中国银行!$B:$B,"="&$E$2,言吾言中国银行!$D:$D,"="&$C8) -> 0 | M8: =SUMIFS(古玩城现金!$J:$J,古玩城现金!$B:$B,"="&$E$2) -> 0 | N8: =SUMIFS(艾泊烨海峡银行!$G:$G,艾泊烨海峡银行!$B:$B,"="&$E$2,艾泊烨海峡银行!$D:$D,"="&$C8) -> 14000 | O8: 0 | P8: =SUMIFS(艾泊烨农商银行!$I:$I,艾泊烨农商银行!$B:$B,"="&$E$2,艾泊烨农商银行!$D:$D,"="&$C8) -> 0 | Q8: =SUMIFS(艾泊烨私户银行!$G:$G,艾泊烨私户银行!$B:$B,"="&$E$2,艾泊烨私户银行!$D:$D,"="&$C8) -> 9600 | R8: 0 | S8: 0 | T8: =SUMIFS(易佰兴现金!$J:$J,易佰兴现金!$B:$B,"="&$E$2) -> 0 | U8: 0
B9: =B24 -> 5 | C9: 月卡收入 | E9: =SUMIFS(力喆实业中国银行!$G:$G,力喆实业中国银行!$B:$B,"="&$E$2,力喆实业中国银行!$D:$D,"="&$C9) -> 0 | F9: =SUMIFS(力喆产业农商银行!$G:$G,力喆产业农商银行!$B:$B,"="&$E$2,力喆产业农商银行!$D:$D,"="&$C9) -> 0 | G9: =SUMIFS(徐洁招商银行!$G:$G,徐洁招商银行!$B:$B,"="&$E$2,徐洁招商银行!$D:$D,"="&$C9) -> 0 | H9: =SUMIFS(力喆贸易建设银行!$G:$G,力喆贸易建设银行!$B:$B,"="&$E$2,力喆贸易建设银行!$D:$D,"="&$C9) -> 0 | J9: =SUMIFS(言吾言中国银行!$G:$G,言吾言中国银行!$B:$B,"="&$E$2,言吾言中国银行!$D:$D,"="&$C9) -> 0 | L9: 0 | M9: =SUMIFS(古玩城现金!$J:$J,古玩城现金!$B:$B,"="&$E$2) -> 0 | N9: =SUMIFS(艾泊烨海峡银行!$G:$G,艾泊烨海峡银行!$B:$B,"="&$E$2,艾泊烨海峡银行!$D:$D,"="&$C9) -> 350 | O9: 0 | P9: =SUMIFS(艾泊烨农商银行!$I:$I,艾泊烨农商银行!$B:$B,"="&$E$2,艾泊烨农商银行!$D:$D,"="&$C9) -> 0 | Q9: =SUMIFS(艾泊烨私户银行!$G:$G,艾泊烨私户银行!$B:$B,"="&$E$2,艾泊烨私户银行!$D:$D,"="&$C9) -> 27222.77 | R9: 0 | S9: 0 | T9: =SUMIFS(易佰兴现金!$J:$J,易佰兴现金!$B:$B,"="&$E$2) -> 0 | U9: 0
B10: =B15 -> 5 | C10: 营业分成收入 | E10: =SUMIFS(力喆实业中国银行!$G:$G,力喆实业中国银行!$B:$B,"="&$E$2,力喆实业中国银行!$D:$D,"="&$C10) -> 0 | F10: =SUMIFS(力喆产业农商银行!$G:$G,力喆产业农商银行!$B:$B,"="&$E$2,力喆产业农商银行!$D:$D,"="&$C10) -> 0 | G10: =SUMIFS(徐洁招商银行!$G:$G,徐洁招商银行!$B:$B,"="&$E$2,徐洁招商银行!$D:$D,"="&$C10) -> 0 | H10: =SUMIFS(力喆贸易建设银行!$G:$G,力喆贸易建设银行!$B:$B,"="&$E$2,力喆贸易建设银行!$D:$D,"="&$C10) -> 0 | J10: =SUMIFS(言吾言中国银行!$G:$G,言吾言中国银行!$B:$B,"="&$E$2,言吾言中国银行!$D:$D,"="&$C10) -> 0 | L10: 0 | M10: =SUMIFS(古玩城现金!$J:$J,古玩城现金!$B:$B,"="&$E$2) -> 0 | N10: =SUMIFS(艾泊烨海峡银行!$G:$G,艾泊烨海峡银行!$B:$B,"="&$E$2,艾泊烨海峡银行!$D:$D,"="&$C10) -> 2000 | O10: 0 | P10: =SUMIFS(艾泊烨农商银行!$I:$I,艾泊烨农商银行!$B:$B,"="&$E$2,艾泊烨农商银行!$D:$D,"="&$C10) -> 0 | Q10: =SUMIFS(艾泊烨私户银行!$G:$G,艾泊烨私户银行!$B:$B,"="&$E$2,艾泊烨私户银行!$D:$D,"="&$C10) -> 0 | R10: 0 | S10: 0 | T10: =SUMIFS(易佰兴现金!$J:$J,易佰兴现金!$B:$B,"="&$E$2) -> 0 | U10: 0
B11: =B8 -> 5 | C11: 超出部分80%收入 | E11: =SUMIFS(力喆实业中国银行!$G:$G,力喆实业中国银行!$B:$B,"="&$E$2,力喆实业中国银行!$D:$D,"="&$C11) -> 0 | F11: =SUMIFS(力喆产业农商银行!$G:$G,力喆产业农商银行!$B:$B,"="&$E$2,力喆产业农商银行!$D:$D,"="&$C11) -> 0 | G11: =SUMIFS(徐洁招商银行!$G:$G,徐洁招商银行!$B:$B,"="&$E$2,徐洁招商银行!$D:$D,"="&$C11) -> 0 | H11: =SUMIFS(力喆贸易建设银行!$G:$G,力喆贸易建设银行!$B:$B,"="&$E$2,力喆贸易建设银行!$D:$D,"="&$C11) -> 0 | J11: =SUMIFS(言吾言中国银行!$G:$G,言吾言中国银行!$B:$B,"="&$E$2,言吾言中国银行!$D:$D,"="&$C11) -> 0 | M11: =SUMIFS(古玩城现金!$J:$J,古玩城现金!$B:$B,"="&$E$2) -> 0 | N11: =SUMIFS(艾泊烨海峡银行!$G:$G,艾泊烨海峡银行!$B:$B,"="&$E$2,艾泊烨海峡银行!$D:$D,"="&$C11) -> 118449.07 | O11: 0 | P11: =SUMIFS(艾泊烨农商银行!$I:$I,艾泊烨农商银行!$B:$B,"="&$E$2,艾泊烨农商银行!$D:$D,"="&$C11) -> 0 | Q11: =SUMIFS(艾泊烨私户银行!$G:$G,艾泊烨私户银行!$B:$B,"="&$E$2,艾泊烨私户银行!$D:$D,"="&$C11) -> 0 | R11: 0 | S11: 0 | T11: =SUMIFS(易佰兴现金!$J:$J,易佰兴现金!$B:$B,"="&$E$2) -> 0 | U11: 0
B12: =B10 -> 5 | C12: 道闸服务费收入 | E12: =SUMIFS(力喆实业中国银行!$G:$G,力喆实业中国银行!$B:$B,"="&$E$2,力喆实业中国银行!$D:$D,"="&$C12) -> 0 | F12: =SUMIFS(力喆产业农商银行!$G:$G,力喆产业农商银行!$B:$B,"="&$E$2,力喆产业农商银行!$D:$D,"="&$C12) -> 0 | G12: =SUMIFS(徐洁招商银行!$G:$G,徐洁招商银行!$B:$B,"="&$E$2,徐洁招商银行!$D:$D,"="&$C12) -> 0 | H12: =SUMIFS(力喆贸易建设银行!$G:$G,力喆贸易建设银行!$B:$B,"="&$E$2,力喆贸易建设银行!$D:$D,"="&$C12) -> 0 | J12: =SUMIFS(言吾言中国银行!$G:$G,言吾言中国银行!$B:$B,"="&$E$2,言吾言中国银行!$D:$D,"="&$C12) -> 0 | L12: 0 | M12: =SUMIFS(古玩城现金!$J:$J,古玩城现金!$B:$B,"="&$E$2) -> 0 | N12: =SUMIFS(艾泊烨海峡银行!$G:$G,艾泊烨海峡银行!$B:$B,"="&$E$2,艾泊烨海峡银行!$D:$D,"="&$C12) -> 16800 | O12: 0 | P12: =SUMIFS(艾泊烨农商银行!$I:$I,艾泊烨农商银行!$B:$B,"="&$E$2,艾泊烨农商银行!$D:$D,"="&$C12) -> 0 | Q12: =SUMIFS(艾泊烨私户银行!$G:$G,艾泊烨私户银行!$B:$B,"="&$E$2,艾泊烨私户银行!$D:$D,"="&$C12) -> 0 | R12: 0 | S12: 0 | T12: =SUMIFS(易佰兴现金!$J:$J,易佰兴现金!$B:$B,"="&$E$2) -> 0 | U12: 0
B13: =B12 -> 5 | C13: 充电桩收入 | E13: =SUMIFS(力喆实业中国银行!$G:$G,力喆实业中国银行!$B:$B,"="&$E$2,力喆实业中国银行!$D:$D,"="&$C13) -> 0 | F13: =SUMIFS(力喆产业农商银行!$G:$G,力喆产业农商银行!$B:$B,"="&$E$2,力喆产业农商银行!$D:$D,"="&$C13) -> 0 | G13: =SUMIFS(徐洁招商银行!$G:$G,徐洁招商银行!$B:$B,"="&$E$2,徐洁招商银行!$D:$D,"="&$C13) -> 0 | H13: =SUMIFS(力喆贸易建设银行!$G:$G,力喆贸易建设银行!$B:$B,"="&$E$2,力喆贸易建设银行!$D:$D,"="&$C13) -> 0 | J13: =SUMIFS(言吾言中国银行!$G:$G,言吾言中国银行!$B:$B,"="&$E$2,言吾言中国银行!$D:$D,"="&$C13) -> 0 | M13: =SUMIFS(古玩城现金!$J:$J,古玩城现金!$B:$B,"="&$E$2) -> 0 | N13: =SUMIFS(艾泊烨海峡银行!$G:$G,艾泊烨海峡银行!$B:$B,"="&$E$2,艾泊烨海峡银行!$D:$D,"="&$C13) -> 0 | O13: 0 | P13: =SUMIFS(艾泊烨农商银行!$I:$I,艾泊烨农商银行!$B:$B,"="&$E$2,艾泊烨农商银行!$D:$D,"="&$C13) -> 0 | Q13: =SUMIFS(艾泊烨私户银行!$G:$G,艾泊烨私户银行!$B:$B,"="&$E$2,艾泊烨私户银行!$D:$D,"="&$C13) -> 0 | R13: 0 | S13: 0 | T13: =SUMIFS(易佰兴现金!$J:$J,易佰兴现金!$B:$B,"="&$E$2) -> 0 | U13: 0
B14: =B13 -> 5 | C14: 利达大厦租金收入 | E14: =SUMIFS(力喆实业中国银行!$G:$G,力喆实业中国银行!$B:$B,"="&$E$2,力喆实业中国银行!$D:$D,"="&$C14) -> 0 | F14: =SUMIFS(力喆产业农商银行!$G:$G,力喆产业农商银行!$B:$B,"="&$E$2,力喆产业农商银行!$D:$D,"="&$C14) -> 0 | G14: =SUMIFS(徐洁招商银行!$G:$G,徐洁招商银行!$B:$B,"="&$E$2,徐洁招商银行!$D:$D,"="&$C14) -> 73824.8 | H14: =SUMIFS(力喆贸易建设银行!$G:$G,力喆贸易建设银行!$B:$B,"="&$E$2,力喆贸易建设银行!$D:$D,"="&$C14) -> 0 | T14: =SUMIFS(易佰兴现金!$J:$J,易佰兴现金!$B:$B,"="&$E$2) -> 0
B15: =B7 -> 5 | C15: 房租收入 | D15: =SUMIFS(#REF!,#REF!,"="&$E$2,#REF!,"="&$C15) -> #REF! | E15: =SUMIFS(力喆实业中国银行!$G:$G,力喆实业中国银行!$B:$B,"="&$E$2,力喆实业中国银行!$D:$D,"="&$C15) -> 0 | F15: =SUMIFS(力喆产业农商银行!$G:$G,力喆产业农商银行!$B:$B,"="&$E$2,力喆产业农商银行!$D:$D,"="&$C15) -> 0 | G15: =SUMIFS(徐洁招商银行!$G:$G,徐洁招商银行!$B:$B,"="&$E$2,徐洁招商银行!$D:$D,"="&$C15) -> 57832.11 | H15: =SUMIFS(力喆贸易建设银行!$G:$G,力喆贸易建设银行!$B:$B,"="&$E$2,力喆贸易建设银行!$D:$D,"="&$C15) -> 73229.1 | I15: =SUMIFS(元生万物建设银行!$G:$G,元生万物建设银行!$B:$B,"="&$E$2,元生万物建设银行!$D:$D,"="&$C15) -> 0 | J15: =SUMIFS(言吾言中国银行!$G:$G,言吾言中国银行!$B:$B,"="&$E$2,言吾言中国银行!$D:$D,"="&$C15) -> 0 | K15: =SUMIFS(力喆传媒海峡银行!$G:$G,力喆传媒海峡银行!$B:$B,"="&$E$2,力喆传媒海峡银行!$D:$D,"="&$C15) -> 0 | L15: =SUMIFS(古玩城农商银行!$G:$G,古玩城农商银行!$B:$B,"="&$E$2) -> 290765 | M15: =SUMIFS(古玩城现金!$G:$G,古玩城现金!$B:$B,"="&$E$2) -> 10864 | N15: =SUMIFS(艾泊烨海峡银行!$G:$G,艾泊烨海峡银行!$B:$B,"="&$E$2,艾泊烨海峡银行!$D:$D,"="&$C15) -> 0 | O15: 0 | P15: =SUMIFS(艾泊烨农商银行!$I:$I,艾泊烨农商银行!$B:$B,"="&$E$2,艾泊烨农商银行!$D:$D,"="&$C15) -> 0 | Q15: =SUMIFS(艾泊烨私户银行!$G:$G,艾泊烨私户银行!$B:$B,"="&$E$2,艾泊烨私户银行!$D:$D,"="&$C15) -> 0 | R15: =SUMIFS(易佰兴建行!$G:$G,易佰兴建行!$B:$B,"="&$E$2) -> 278302.83 | S15: =SUMIFS(易佰兴私户!$G:$G,易佰兴私户!$B:$B,"="&$E$2) -> 79195 | T15: =SUMIFS(易佰兴现金!$G:$G,易佰兴现金!$B:$B,"="&$E$2) -> 0 | U15: =SUMIFS(易佰兴基本户!$G:$G,易佰兴基本户!$B:$B,"="&$E$2) -> 0
B16: =B15 -> 5 | C16: 物业收入 | D16: =SUMIFS(#REF!,#REF!,"="&$E$2,#REF!,"="&$C16) -> #REF! | E16: =SUMIFS(力喆实业中国银行!$G:$G,力喆实业中国银行!$B:$B,"="&$E$2,力喆实业中国银行!$D:$D,"="&$C16) -> 0 | F16: =SUMIFS(力喆产业农商银行!$G:$G,力喆产业农商银行!$B:$B,"="&$E$2,力喆产业农商银行!$D:$D,"="&$C16) -> 0 | G16: =SUMIFS(徐洁招商银行!$G:$G,徐洁招商银行!$B:$B,"="&$E$2,徐洁招商银行!$D:$D,"="&$C16) -> 0 | H16: =SUMIFS(力喆贸易建设银行!$G:$G,力喆贸易建设银行!$B:$B,"="&$E$2,力喆贸易建设银行!$D:$D,"="&$C16) -> 0 | I16: =SUMIFS(元生万物建设银行!$G:$G,元生万物建设银行!$B:$B,"="&$E$2,元生万物建设银行!$D:$D,"="&$C16) -> 0 | J16: =SUMIFS(言吾言中国银行!$G:$G,言吾言中国银行!$B:$B,"="&$E$2,言吾言中国银行!$D:$D,"="&$C16) -> 0 | K16: =SUMIFS(力喆传媒海峡银行!$G:$G,力喆传媒海峡银行!$B:$B,"="&$E$2,力喆传媒海峡银行!$D:$D,"="&$C16) -> 0 | L16: =SUMIFS(古玩城农商银行!H:H,古玩城农商银行!B:B,"="&$E$2) -> 12400 | M16: =SUMIFS(古玩城现金!$H:$H,古玩城现金!$B:$B,"="&$E$2) -> 600 | N16: =SUMIFS(艾泊烨海峡银行!$G:$G,艾泊烨海峡银行!$B:$B,"="&$E$2,艾泊烨海峡银行!$D:$D,"="&$C16) -> 0 | O16: 0 | P16: =SUMIFS(艾泊烨农商银行!$I:$I,艾泊烨农商银行!$B:$B,"="&$E$2,艾泊烨农商银行!$D:$D,"="&$C16) -> 0 | Q16: =SUMIFS(艾泊烨私户银行!$G:$G,艾泊烨私户银行!$B:$B,"="&$E$2,艾泊烨私户银行!$D:$D,"="&$C16) -> 0 | R16: =SUMIFS(易佰兴建行!$H:$H,易佰兴建行!$B:$B,"="&$E$2) -> 25142.7 | S16: =SUMIFS(易佰兴私户!$H:$H,易佰兴私户!B:B,"="&$E$2) -> 7862.4 | T16: =SUMIFS(易佰兴现金!$H:$H,易佰兴现金!$B:$B,"="&$E$2) -> 0 | U16: =SUMIFS(易佰兴基本户!$H:$H,易佰兴基本户!$B:$B,"="&$E$2) -> 0
B17: =B16 -> 5 | C17: 水电收入 | D17: =SUMIFS(#REF!,#REF!,"="&$E$2,#REF!,"="&$C17) -> #REF! | E17: =SUMIFS(力喆实业中国银行!$G:$G,力喆实业中国银行!$B:$B,"="&$E$2,力喆实业中国银行!$D:$D,"="&$C17) -> 0 | F17: =SUMIFS(力喆产业农商银行!$G:$G,力喆产业农商银行!$B:$B,"="&$E$2,力喆产业农商银行!$D:$D,"="&$C17) -> 0 | G17: =SUMIFS(徐洁招商银行!$G:$G,徐洁招商银行!$B:$B,"="&$E$2,徐洁招商银行!$D:$D,"="&$C17) -> 0 | H17: =SUMIFS(力喆贸易建设银行!$G:$G,力喆贸易建设银行!$B:$B,"="&$E$2,力喆贸易建设银行!$D:$D,"="&$C17) -> 0 | I17: =SUMIFS(元生万物建设银行!$G:$G,元生万物建设银行!$B:$B,"="&$E$2,元生万物建设银行!$D:$D,"="&$C17) -> 0 | J17: =SUMIFS(言吾言中国银行!$G:$G,言吾言中国银行!$B:$B,"="&$E$2,言吾言中国银行!$D:$D,"="&$C17) -> 0 | K17: =SUMIFS(力喆传媒海峡银行!$G:$G,力喆传媒海峡银行!$B:$B,"="&$E$2,力喆传媒海峡银行!$D:$D,"="&$C17) -> 0 | L17: =SUMIFS(古玩城农商银行!$I:$I,古玩城农商银行!$B:$B,"="&$E$2) -> 20631.2 | M17: =SUMIFS(古玩城现金!$I:$I,古玩城现金!$B:$B,"="&$E$2) -> 656 | N17: =SUMIFS(艾泊烨海峡银行!$G:$G,艾泊烨海峡银行!$B:$B,"="&$E$2,艾泊烨海峡银行!$D:$D,"="&$C17) -> 2756.25 | O17: 0 | P17: =SUMIFS(艾泊烨农商银行!$I:$I,艾泊烨农商银行!$B:$B,"="&$E$2,艾泊烨农商银行!$D:$D,"="&$C17) -> 0 | Q17: =SUMIFS(艾泊烨私户银行!$G:$G,艾泊烨私户银行!$B:$B,"="&$E$2,艾泊烨私户银行!$D:$D,"="&$C17) -> 4250.05 | R17: =SUMIFS(易佰兴建行!$I:$I,易佰兴建行!$B:$B,"="&$E$2) -> 188 | S17: =SUMIFS(易佰兴私户!$I:$I,易佰兴私户!B:B,"="&$E$2) -> 25305.83 | T17: =SUMIFS(易佰兴现金!$I:$I,易佰兴现金!$B:$B,"="&$E$2) -> 0 | U17: =SUMIFS(易佰兴基本户!$I:$I,易佰兴基本户!$B:$B,"="&$E$2) -> 0
B18: =B17 -> 5 | C18: 摊位收入 | D18: =SUMIFS(#REF!,#REF!,"="&$E$2,#REF!,"="&$C18) -> #REF! | E18: =SUMIFS(力喆实业中国银行!$G:$G,力喆实业中国银行!$B:$B,"="&$E$2,力喆实业中国银行!$D:$D,"="&$C18) -> 0 | F18: =SUMIFS(力喆产业农商银行!$G:$G,力喆产业农商银行!$B:$B,"="&$E$2,力喆产业农商银行!$D:$D,"="&$C18) -> 0 | G18: =SUMIFS(徐洁招商银行!$G:$G,徐洁招商银行!$B:$B,"="&$E$2,徐洁招商银行!$D:$D,"="&$C18) -> 0 | H18: =SUMIFS(力喆贸易建设银行!$G:$G,力喆贸易建设银行!$B:$B,"="&$E$2,力喆贸易建设银行!$D:$D,"="&$C18) -> 0 | I18: =SUMIFS(元生万物建设银行!$G:$G,元生万物建设银行!$B:$B,"="&$E$2,元生万物建设银行!$D:$D,"="&$C18) -> 0 | J18: =SUMIFS(言吾言中国银行!$G:$G,言吾言中国银行!$B:$B,"="&$E$2,言吾言中国银行!$D:$D,"="&$C18) -> 0 | K18: =SUMIFS(力喆传媒海峡银行!$G:$G,力喆传媒海峡银行!$B:$B,"="&$E$2,力喆传媒海峡银行!$D:$D,"="&$C18) -> 0 | L18: =SUMIFS(古玩城农商银行!$K:$K,古玩城农商银行!$B:$B,"="&$E$2) -> 25185 | M18: =SUMIFS(古玩城现金!$K:$K,古玩城现金!$B:$B,"="&$E$2) -> 4080 | N18: =SUMIFS(艾泊烨海峡银行!$G:$G,艾泊烨海峡银行!$B:$B,"="&$E$2,艾泊烨海峡银行!$D:$D,"="&$C18) -> 0 | O18: 0 | P18: =SUMIFS(艾泊烨农商银行!$I:$I,艾泊烨农商银行!$B:$B,"="&$E$2,艾泊烨农商银行!$D:$D,"="&$C18) -> 0 | Q18: =SUMIFS(艾泊烨私户银行!$G:$G,艾泊烨私户银行!$B:$B,"="&$E$2,艾泊烨私户银行!$D:$D,"="&$C18) -> 0 | R18: 0 | S18: 0 | T18: =SUMIFS(易佰兴现金!$J:$J,易佰兴现金!$B:$B,"="&$E$2) -> 0 | U18: 0
B19: =B18 -> 5 | C19: 停车费收入 | E19: =SUMIFS(力喆实业中国银行!$G:$G,力喆实业中国银行!$B:$B,"="&$E$2,力喆实业中国银行!$D:$D,"="&$C19) -> 0 | F19: =SUMIFS(力喆产业农商银行!$G:$G,力喆产业农商银行!$B:$B,"="&$E$2,力喆产业农商银行!$D:$D,"="&$C19) -> 0 | G19: =SUMIFS(徐洁招商银行!$G:$G,徐洁招商银行!$B:$B,"="&$E$2,徐洁招商银行!$D:$D,"="&$C19) -> 0 | H19: =SUMIFS(力喆贸易建设银行!$G:$G,力喆贸易建设银行!$B:$B,"="&$E$2,力喆贸易建设银行!$D:$D,"="&$C19) -> 0 | J19: =SUMIFS(言吾言中国银行!$G:$G,言吾言中国银行!$B:$B,"="&$E$2,言吾言中国银行!$D:$D,"="&$C19) -> 0 | R19: =SUMIFS(易佰兴建行!$K:$K,易佰兴建行!$B:$B,"="&$E$2) -> 300 | S19: =SUMIFS(易佰兴私户!$K:$K,易佰兴私户!$B:$B,"="&$E$2) -> 6580 | T19: =SUMIFS(易佰兴现金!$K:$K,易佰兴现金!$B:$B,"="&$E$2) -> 240 | U19: =SUMIFS(易佰兴基本户!$K:$K,易佰兴基本户!$B:$B,"="&$E$2) -> 0
B20: =B19 -> 5 | C20: 广告费收入 | E20: =SUMIFS(力喆实业中国银行!$G:$G,力喆实业中国银行!$B:$B,"="&$E$2,力喆实业中国银行!$D:$D,"="&$C20) -> 0 | F20: =SUMIFS(力喆产业农商银行!$G:$G,力喆产业农商银行!$B:$B,"="&$E$2,力喆产业农商银行!$D:$D,"="&$C20) -> 0 | G20: =SUMIFS(徐洁招商银行!$G:$G,徐洁招商银行!$B:$B,"="&$E$2,徐洁招商银行!$D:$D,"="&$C20) -> 0 | H20: =SUMIFS(力喆贸易建设银行!$G:$G,力喆贸易建设银行!$B:$B,"="&$E$2,力喆贸易建设银行!$D:$D,"="&$C20) -> 0 | J20: =SUMIFS(言吾言中国银行!$G:$G,言吾言中国银行!$B:$B,"="&$E$2,言吾言中国银行!$D:$D,"="&$C20) -> 0 | R20: =SUMIFS(易佰兴建行!$L:$L,易佰兴建行!$B:$B,"="&$E$2) -> 500 | S20: 0 | T20: =SUMIFS(易佰兴现金!$J:$J,易佰兴现金!$B:$B,"="&$E$2) -> 0 | U20: =SUMIFS(易佰兴基本户!$L:$L,易佰兴基本户!$B:$B,"="&$E$2) -> 0
B21: =B18 -> 5 | C21: 股东分红 | D21: =SUMIFS(#REF!,#REF!,"="&$E$2,#REF!,"="&$C21) -> #REF! | E21: =SUMIFS(力喆实业中国银行!$G:$G,力喆实业中国银行!$B:$B,"="&$E$2,力喆实业中国银行!$D:$D,"="&$C21) -> 0 | F21: =SUMIFS(力喆产业农商银行!$G:$G,力喆产业农商银行!$B:$B,"="&$E$2,力喆产业农商银行!$D:$D,"="&$C21) -> 0 | G21: =SUMIFS(徐洁招商银行!$G:$G,徐洁招商银行!$B:$B,"="&$E$2,徐洁招商银行!$D:$D,"="&$C21) -> 0 | H21: =SUMIFS(力喆贸易建设银行!$G:$G,力喆贸易建设银行!$B:$B,"="&$E$2,力喆贸易建设银行!$D:$D,"="&$C21) -> 0 | I21: =SUMIFS(元生万物建设银行!$G:$G,元生万物建设银行!$B:$B,"="&$E$2,元生万物建设银行!$D:$D,"="&$C21) -> 0 | J21: =SUMIFS(言吾言中国银行!$G:$G,言吾言中国银行!$B:$B,"="&$E$2,言吾言中国银行!$D:$D,"="&$C21) -> 0 | K21: =SUMIFS(力喆传媒海峡银行!$G:$G,力喆传媒海峡银行!$B:$B,"="&$E$2,力喆传媒海峡银行!$D:$D,"="&$C21) -> 0 | L21: =SUMIFS(古玩城农商银行!$G:$G,古玩城农商银行!$B:$B,"="&$E$2,古玩城农商银行!$D:$D,"="&$C21) -> 0 | M21: =SUMIFS(古玩城现金!$J:$J,古玩城现金!$B:$B,"="&$E$2) -> 0 | N21: =SUMIFS(艾泊烨海峡银行!$G:$G,艾泊烨海峡银行!$B:$B,"="&$E$2,艾泊烨海峡银行!$D:$D,"="&$C21) -> 0 | O21: 0 | P21: =SUMIFS(艾泊烨农商银行!$I:$I,艾泊烨农商银行!$B:$B,"="&$E$2,艾泊烨农商银行!$D:$D,"="&$C21) -> 0 | Q21: =SUMIFS(艾泊烨私户银行!$G:$G,艾泊烨私户银行!$B:$B,"="&$E$2,艾泊烨私户银行!$D:$D,"="&$C21) -> 0 | R21: 0 | S21: 0 | T21: =SUMIFS(易佰兴现金!$J:$J,易佰兴现金!$B:$B,"="&$E$2) -> 0 | U21: 0
B22: =B21 -> 5 | C22: 其他收入 | D22: =SUMIFS(#REF!,#REF!,"="&$E$2,#REF!,"="&$C22) -> #REF! | E22: =SUMIFS(力喆实业中国银行!$G:$G,力喆实业中国银行!$B:$B,"="&$E$2,力喆实业中国银行!$D:$D,"="&$C22) -> 0 | F22: =SUMIFS(力喆产业农商银行!$G:$G,力喆产业农商银行!$B:$B,"="&$E$2,力喆产业农商银行!$D:$D,"="&$C22) -> 0 | G22: =SUMIFS(徐洁招商银行!$G:$G,徐洁招商银行!$B:$B,"="&$E$2,徐洁招商银行!$D:$D,"="&$C22) -> 0 | H22: =SUMIFS(力喆贸易建设银行!$G:$G,力喆贸易建设银行!$B:$B,"="&$E$2,力喆贸易建设银行!$D:$D,"="&$C22) -> 0 | I22: =SUMIFS(元生万物建设银行!$G:$G,元生万物建设银行!$B:$B,"="&$E$2,元生万物建设银行!$D:$D,"="&$C22) -> 0 | J22: =SUMIFS(言吾言中国银行!$G:$G,言吾言中国银行!$B:$B,"="&$E$2,言吾言中国银行!$D:$D,"="&$C22) -> 0 | K22: =SUMIFS(力喆传媒海峡银行!$G:$G,力喆传媒海峡银行!$B:$B,"="&$E$2,力喆传媒海峡银行!$D:$D,"="&$C22) -> 0 | L22: =SUMIFS(古玩城农商银行!$G:$G,古玩城农商银行!$B:$B,"="&$E$2,古玩城农商银行!$D:$D,"="&$C22) -> 0 | M22: =SUMIFS(古玩城现金!$J:$J,古玩城现金!$B:$B,"="&$E$2) -> 0 | N22: =SUMIFS(艾泊烨海峡银行!$G:$G,艾泊烨海峡银行!$B:$B,"="&$E$2,艾泊烨海峡银行!$D:$D,"="&$C22) -> 0 | O22: 0 | P22: =SUMIFS(艾泊烨农商银行!$I:$I,艾泊烨农商银行!$B:$B,"="&$E$2,艾泊烨农商银行!$D:$D,"="&$C22) -> 0 | Q22: =SUMIFS(艾泊烨私户银行!$G:$G,艾泊烨私户银行!$B:$B,"="&$E$2,艾泊烨私户银行!$D:$D,"="&$C22) -> 0 | R22: 0 | S22: 0 | T22: =SUMIFS(易佰兴现金!$J:$J,易佰兴现金!$B:$B,"="&$E$2) -> 0 | U22: 0
B23: =B22 -> 5 | C23: 利息收入 | D23: =SUMIFS(#REF!,#REF!,"="&$E$2,#REF!,"="&$C23) -> #REF! | E23: =SUMIFS(力喆实业中国银行!$G:$G,力喆实业中国银行!$B:$B,"="&$E$2,力喆实业中国银行!$D:$D,"="&$C23) -> 0 | F23: =SUMIFS(力喆产业农商银行!$G:$G,力喆产业农商银行!$B:$B,"="&$E$2,力喆产业农商银行!$D:$D,"="&$C23) -> 0 | G23: =SUMIFS(徐洁招商银行!$G:$G,徐洁招商银行!$B:$B,"="&$E$2,徐洁招商银行!$D:$D,"="&$C23) -> 0 | H23: =SUMIFS(力喆贸易建设银行!$G:$G,力喆贸易建设银行!$B:$B,"="&$E$2,力喆贸易建设银行!$D:$D,"="&$C23) -> 0 | I23: =SUMIFS(元生万物建设银行!$G:$G,元生万物建设银行!$B:$B,"="&$E$2,元生万物建设银行!$D:$D,"="&$C23) -> 0 | J23: =SUMIFS(言吾言中国银行!$G:$G,言吾言中国银行!$B:$B,"="&$E$2,言吾言中国银行!$D:$D,"="&$C23) -> 0 | K23: =SUMIFS(力喆传媒海峡银行!$G:$G,力喆传媒海峡银行!$B:$B,"="&$E$2,力喆传媒海峡银行!$D:$D,"="&$C23) -> 0 | L23: =SUMIFS(古玩城农商银行!$L:$L,古玩城农商银行!$B:$B,"="&$E$2) -> 0 | M23: =SUMIFS(古玩城现金!$J:$J,古玩城现金!$B:$B,"="&$E$2) -> 0 | N23: =SUMIFS(艾泊烨海峡银行!$G:$G,艾泊烨海峡银行!$B:$B,"="&$E$2,艾泊烨海峡银行!$D:$D,"="&$C23) -> 0 | O23: =SUMIFS(艾泊烨招商银行!$G:$G,艾泊烨招商银行!$B:$B,"="&$E$2,艾泊烨招商银行!$D:$D,"="&$C23) -> 0 | P23: =SUMIFS(艾泊烨农商银行!$I:$I,艾泊烨农商银行!$B:$B,"="&$E$2,艾泊烨农商银行!$D:$D,"="&$C23) -> 0 | Q23: =SUMIFS(艾泊烨私户银行!$G:$G,艾泊烨私户银行!$B:$B,"="&$E$2,艾泊烨私户银行!$D:$D,"="&$C23) -> 0 | R23: =SUMIFS(易佰兴建行!$M:$M,易佰兴建行!$B:$B,"="&$E$2) -> 0 | S23: =SUMIFS(易佰兴私户!$M:$M,易佰兴私户!B:B,"="&$E$2) -> 0 | T23: =SUMIFS(易佰兴现金!$J:$J,易佰兴现金!$B:$B,"="&$E$2) -> 0 | U23: =SUMIFS(易佰兴基本户!$M:$M,易佰兴基本户!$B:$B,"="&$E$2) -> 0
B24: =B23 -> 5 | C24: 贷款转入 | E24: =SUMIFS(力喆实业中国银行!$G:$G,力喆实业中国银行!$B:$B,"="&$E$2,力喆实业中国银行!$D:$D,"="&$C24) -> 0 | F24: =SUMIFS(力喆产业农商银行!$G:$G,力喆产业农商银行!$B:$B,"="&$E$2,力喆产业农商银行!$D:$D,"="&$C24) -> 0 | G24: =SUMIFS(徐洁招商银行!$G:$G,徐洁招商银行!$B:$B,"="&$E$2,徐洁招商银行!$D:$D,"="&$C24) -> 0 | H24: =SUMIFS(力喆贸易建设银行!$G:$G,力喆贸易建设银行!$B:$B,"="&$E$2,力喆贸易建设银行!$D:$D,"="&$C24) -> 0 | J24: =SUMIFS(言吾言中国银行!$G:$G,言吾言中国银行!$B:$B,"="&$E$2,言吾言中国银行!$D:$D,"="&$C24) -> 0 | L24: 0 | M24: =SUMIFS(古玩城现金!$J:$J,古玩城现金!$B:$B,"="&$E$2) -> 0 | N24: =SUMIFS(艾泊烨海峡银行!$G:$G,艾泊烨海峡银行!$B:$B,"="&$E$2,艾泊烨海峡银行!$D:$D,"="&$C24) -> 650000 | O24: 0 | P24: =SUMIFS(艾泊烨农商银行!$I:$I,艾泊烨农商银行!$B:$B,"="&$E$2,艾泊烨农商银行!$D:$D,"="&$C24) -> 0 | Q24: =SUMIFS(艾泊烨私户银行!$G:$G,艾泊烨私户银行!$B:$B,"="&$E$2,艾泊烨私户银行!$D:$D,"="&$C24) -> 0 | R24: 0 | S24: 0 | T24: =SUMIFS(易佰兴现金!$J:$J,易佰兴现金!$B:$B,"="&$E$2) -> 0 | U24: 0
B25: =B9 -> 5 | C25: 借款转入 | E25: =SUMIFS(力喆实业中国银行!$G:$G,力喆实业中国银行!$B:$B,"="&$E$2,力喆实业中国银行!$D:$D,"="&$C25) -> 0 | F25: =SUMIFS(力喆产业农商银行!$G:$G,力喆产业农商银行!$B:$B,"="&$E$2,力喆产业农商银行!$D:$D,"="&$C25) -> 0 | G25: =SUMIFS(徐洁招商银行!$G:$G,徐洁招商银行!$B:$B,"="&$E$2,徐洁招商银行!$D:$D,"="&$C25) -> 0 | H25: =SUMIFS(力喆贸易建设银行!$G:$G,力喆贸易建设银行!$B:$B,"="&$E$2,力喆贸易建设银行!$D:$D,"="&$C25) -> 0 | J25: =SUMIFS(言吾言中国银行!$G:$G,言吾言中国银行!$B:$B,"="&$E$2,言吾言中国银行!$D:$D,"="&$C25) -> 0 | L25: =SUMIFS(古玩城农商银行!$N:$N,古玩城农商银行!$B:$B,"="&$E$2,古玩城农商银行!$D:$D,"="&$C25) -> 0 | M25: =SUMIFS(古玩城现金!$J:$J,古玩城现金!$B:$B,"="&$E$2) -> 0 | N25: =SUMIFS(艾泊烨海峡银行!$G:$G,艾泊烨海峡银行!$B:$B,"="&$E$2,艾泊烨海峡银行!$D:$D,"="&$C25) -> 95000 | O25: 0 | P25: =SUMIFS(艾泊烨农商银行!$I:$I,艾泊烨农商银行!$B:$B,"="&$E$2,艾泊烨农商银行!$D:$D,"="&$C25) -> 0 | Q25: =SUMIFS(艾泊烨私户银行!$G:$G,艾泊烨私户银行!$B:$B,"="&$E$2,艾泊烨私户银行!$D:$D,"="&$C25) -> 0 | R25: 0 | S25: 0 | T25: =SUMIFS(易佰兴现金!$J:$J,易佰兴现金!$B:$B,"="&$E$2) -> 0 | U25: 0
B26: =B25 -> 5 | C26: 收回借款 | E26: =SUMIFS(力喆实业中国银行!$G:$G,力喆实业中国银行!$B:$B,"="&$E$2,力喆实业中国银行!$D:$D,"="&$C26) -> 0 | F26: =SUMIFS(力喆产业农商银行!$G:$G,力喆产业农商银行!$B:$B,"="&$E$2,力喆产业农商银行!$D:$D,"="&$C26) -> 0 | G26: =SUMIFS(徐洁招商银行!$G:$G,徐洁招商银行!$B:$B,"="&$E$2,徐洁招商银行!$D:$D,"="&$C26) -> 0 | H26: =SUMIFS(力喆贸易建设银行!$G:$G,力喆贸易建设银行!$B:$B,"="&$E$2,力喆贸易建设银行!$D:$D,"="&$C26) -> 0 | J26: =SUMIFS(言吾言中国银行!$G:$G,言吾言中国银行!$B:$B,"="&$E$2,言吾言中国银行!$D:$D,"="&$C26) -> 0 | L26: =SUMIFS(古玩城农商银行!$N:$N,古玩城农商银行!$B:$B,"="&$E$2,古玩城农商银行!$D:$D,"="&$C26) -> 0 | M26: =SUMIFS(古玩城现金!$J:$J,古玩城现金!$B:$B,"="&$E$2) -> 0 | N26: =SUMIFS(艾泊烨海峡银行!$G:$G,艾泊烨海峡银行!$B:$B,"="&$E$2,艾泊烨海峡银行!$D:$D,"="&$C26) -> 0 | O26: 0 | P26: =SUMIFS(艾泊烨农商银行!$I:$I,艾泊烨农商银行!$B:$B,"="&$E$2,艾泊烨农商银行!$D:$D,"="&$C26) -> 0 | Q26: =SUMIFS(艾泊烨私户银行!$G:$G,艾泊烨私户银行!$B:$B,"="&$E$2,艾泊烨私户银行!$D:$D,"="&$C26) -> 0 | R26: 0 | S26: 0 | T26: =SUMIFS(易佰兴现金!$J:$J,易佰兴现金!$B:$B,"="&$E$2) -> 0 | U26: 0
B27: =B26 -> 5 | C27: 薪资、社医保 | E27: =SUMIFS(力喆实业中国银行!$G:$G,力喆实业中国银行!$B:$B,"="&$E$2,力喆实业中国银行!$D:$D,"="&$C27) -> 0 | F27: =SUMIFS(力喆产业农商银行!$G:$G,力喆产业农商银行!$B:$B,"="&$E$2,力喆产业农商银行!$D:$D,"="&$C27) -> 0 | G27: =SUMIFS(徐洁招商银行!$G:$G,徐洁招商银行!$B:$B,"="&$E$2,徐洁招商银行!$D:$D,"="&$C27) -> 0 | H27: =SUMIFS(力喆贸易建设银行!$G:$G,力喆贸易建设银行!$B:$B,"="&$E$2,力喆贸易建设银行!$D:$D,"="&$C27) -> 0 | J27: =SUMIFS(言吾言中国银行!$G:$G,言吾言中国银行!$B:$B,"="&$E$2,言吾言中国银行!$D:$D,"="&$C27) -> 0 | L27: 0 | M27: =SUMIFS(古玩城现金!$J:$J,古玩城现金!$B:$B,"="&$E$2) -> 0 | N27: =SUMIFS(艾泊烨海峡银行!$G:$G,艾泊烨海峡银行!$B:$B,"="&$E$2,艾泊烨海峡银行!$D:$D,"="&$C27) -> 19844.24 | O27: 0 | P27: =SUMIFS(艾泊烨农商银行!$I:$I,艾泊烨农商银行!$B:$B,"="&$E$2,艾泊烨农商银行!$D:$D,"="&$C27) -> 0 | Q27: =SUMIFS(艾泊烨私户银行!$G:$G,艾泊烨私户银行!$B:$B,"="&$E$2,艾泊烨私户银行!$D:$D,"="&$C27) -> 19745.39 | R27: 0 | S27: 0 | T27: =SUMIFS(易佰兴现金!$J:$J,易佰兴现金!$B:$B,"="&$E$2) -> 0 | U27: 0
B28: 合计 | D28: =SUBTOTAL(109,D6:D27) -> #REF! | E28: =SUBTOTAL(109,E6:E27) -> 0 | F28: =SUBTOTAL(109,F6:F27) -> 47832.11 | G28: =SUBTOTAL(109,G6:G27) -> 156656.91 | H28: =SUBTOTAL(109,H6:H27) -> 73229.1 | I28: =SUBTOTAL(109,I6:I27) -> 30098.25 | J28: =SUBTOTAL(109,J6:J27) -> 0 | K28: =SUBTOTAL(109,K6:K27) -> 0 | ... U28: =SUBTOTAL(109,U6:U27) -> 24300
D29: =D28-SUMIFS(#REF!,#REF!,汇总!$B$17) -> #REF! | E29: =E28-SUMIFS(力喆实业中国银行!$G:$G,力喆实业中国银行!$B:$B,"="&$E$2)-SUMIFS(力喆产业农商银行!$G:$G,力喆产业农商银行!$B:$B,"="&$E$2) -> -47832.11 | F29: =F28-SUMIFS(力喆实业中国银行!$G:$G,力喆实业中国银行!$B:$B,"="&$E$2)-SUMIFS(力喆产业农商银行!$G:$G,力喆产业农商银行!$B:$B,"="&$E$2) -> 0 | G29: =G28-SUMIFS(徐洁招商银行!$G:$G,徐洁招商银行!$B:$B,"="&$E$2) -> 0 | H29: =H28-SUMIFS(力喆贸易建设银行!$G:$G,力喆贸易建设银行!$B:$B,"="&$E$2) -> 0 | I29: =I28-SUMIFS(元生万物建设银行!$G:$G,元生万物建设银行!$B:$B,"="&$E$2) -> 0 | J29: =J28-SUMIFS(言吾言中国银行!$G:$G,言吾言中国银行!$B:$B,"="&$E$2) -> 0 | K29: =K28-SUMIFS(力喆传媒海峡银行!$G:$G,力喆传媒海峡银行!$B:$B,"="&$E$2) -> 0 | L29: =L28-SUMIFS(古玩城农商银行!$N:$N,古玩城农商银行!$B:$B,"="&$E$2) -> -24819.23 | M29: =M28-SUMIFS(古玩城农商银行!$N:$N,古玩城农商银行!$B:$B,"="&$E$2) -> -379800.43 | N29: =N28-SUMIFS(古玩城农商银行!$N:$N,古玩城农商银行!$B:$B,"="&$E$2) -> 523199.13 | O29: =O28-SUMIFS(古玩城农商银行!$N:$N,古玩城农商银行!$B:$B,"="&$E$2) -> -396000.43 | P29: =P28-SUMIFS(古玩城农商银行!$N:$N,古玩城农商银行!$B:$B,"="&$E$2) -> -380000.43 | Q29: =Q28-SUMIFS(古玩城农商银行!$N:$N,古玩城农商银行!$B:$B,"="&$E$2) -> -307802.22 | R29: =R28-SUMIFS(古玩城农商银行!$N:$N,古玩城农商银行!$B:$B,"="&$E$2) -> -50144.9 | S29: =S28-SUMIFS(古玩城农商银行!$N:$N,古玩城农商银行!$B:$B,"="&$E$2) -> -277057.2 | ... U29: =U28-SUMIFS(古玩城农商银行!$N:$N,古玩城农商银行!$B:$B,"="&$E$2) -> -371700.43
A31: 支出明细汇总表 | B31: 月份 | C31: 支出明细 | D31: =D4 -> 青翼创 | E31: =E4 -> 力喆实业 | F31: =F4 -> 力喆实业 | G31: =G4 -> 力喆实业 | H31: =H4 -> 力喆贸易 | I31: =I4 -> 元生万物 | J31: =J4 -> 言吾言 | K31: =K4 -> 力喆传媒 | L31: 古玩城 | M31: 古玩城 | N31: 艾泊烨 | O31: 艾泊烨 | P31: 艾泊烨 | Q31: 艾泊烨 | R31: 易佰兴 | S31: 易佰兴 | T31: 易佰兴 | U31: 易佰兴
B32: =B21 -> 5 | C32: 薪资 | D32: =SUMIFS(#REF!,#REF!,"="&$E$2,#REF!,"="&$C32) -> #REF! | E32: =SUMIFS(力喆实业中国银行!$H:$H,力喆实业中国银行!$B:$B,"="&$E$2,力喆实业中国银行!$D:$D,"="&$C32) -> 0 | F32: =SUMIFS(力喆产业农商银行!$H:$H,力喆产业农商银行!$B:$B,"="&$E$2,力喆产业农商银行!$D:$D,"="&$C32) -> 0 | G32: =SUMIFS(徐洁招商银行!$H:$H,徐洁招商银行!$B:$B,"="&$E$2,徐洁招商银行!$D:$D,"="&$C32) -> 26000 | H32: =SUMIFS(力喆贸易建设银行!$H:$H,力喆贸易建设银行!$B:$B,"="&$E$2,力喆贸易建设银行!$D:$D,"="&$C32) -> 25121.34 | I32: =SUMIFS(元生万物建设银行!$H:$H,元生万物建设银行!$B:$B,"="&$E$2,元生万物建设银行!$D:$D,"="&$C32) -> 0 | J32: =SUMIFS(言吾言中国银行!$H:$H,言吾言中国银行!$B:$B,"="&$E$2,言吾言中国银行!$D:$D,"="&$C32) -> 0 | K32: =SUMIFS(力喆传媒海峡银行!$H:$H,力喆传媒海峡银行!$B:$B,"="&$E$2,力喆传媒海峡银行!$D:$D,"="&$C32) -> 0 | L32: =SUMIFS(古玩城农商银行!$O:$O,古玩城农商银行!$B:$B,"="&$E$2,古玩城农商银行!$D:$D,"="&$C32) -> 34100 | M32: 0 | N32: =SUMIFS(艾泊烨海峡银行!$H:$H,艾泊烨海峡银行!$B:$B,"="&$E$2,艾泊烨海峡银行!$D:$D,"="&$C32) -> 59293.95 | O32: 0 | P32: =SUMIFS(艾泊烨农商银行!$J:$J,艾泊烨农商银行!$B:$B,"="&$E$2,艾泊烨农商银行!D:D,"="&$C32) -> 0 | Q32: =SUMIFS(艾泊烨私户银行!$H:$H,艾泊烨私户银行!$B:$B,"="&$E$2,艾泊烨私户银行!$D:$D,"="&$C32) -> 0 | R32: =SUMIFS(易佰兴建行!$P:$P,易佰兴建行!$B:$B,"="&$E$2,易佰兴建行!$D:$D,"="&$C32) -> 0 | S32: =SUMIFS(易佰兴私户!$P:$P,易佰兴私户!$B:$B,"="&$E$2,易佰兴私户!$D:$D,"="&$C32)+SUMIFS(易佰兴趋势民生银行!$H:$H,易佰兴趋势民生银行!$B:$B,"="&$E$2,易佰兴趋势民生银行!D:D,"="&$C32) -> 19001.01 | T32: =SUMIFS(易佰兴现金!$O:$O,易佰兴现金!$B:$B,"="&$E$2,易佰兴现金!D:D,"="&$C32) -> 0 | U32: =SUMIFS(易佰兴基本户!$P:$P,易佰兴基本户!$B:$B,"="&$E$2,易佰兴基本户!D:D,"="&$C32) -> 26370.73
B33: =B32 -> 5 | C33: 五险一金 | D33: =SUMIFS(#REF!,#REF!,"="&$E$2,#REF!,"="&$C33) -> #REF! | E33: =SUMIFS(力喆实业中国银行!$H:$H,力喆实业中国银行!$B:$B,"="&$E$2,力喆实业中国银行!$D:$D,"="&$C33) -> 0 | F33: =SUMIFS(力喆产业农商银行!$H:$H,力喆产业农商银行!$B:$B,"="&$E$2,力喆产业农商银行!$D:$D,"="&$C33) -> 2987.84 | G33: =SUMIFS(徐洁招商银行!$H:$H,徐洁招商银行!$B:$B,"="&$E$2,徐洁招商银行!$D:$D,"="&$C33) -> 0 | H33: =SUMIFS(力喆贸易建设银行!$H:$H,力喆贸易建设银行!$B:$B,"="&$E$2,力喆贸易建设银行!$D:$D,"="&$C33) -> 6853.33 | I33: =SUMIFS(元生万物建设银行!$H:$H,元生万物建设银行!$B:$B,"="&$E$2,元生万物建设银行!$D:$D,"="&$C33) -> 0 | J33: =SUMIFS(言吾言中国银行!$H:$H,言吾言中国银行!$B:$B,"="&$E$2,言吾言中国银行!$D:$D,"="&$C33) -> 0 | K33: =SUMIFS(力喆传媒海峡银行!$H:$H,力喆传媒海峡银行!$B:$B,"="&$E$2,力喆传媒海峡银行!$D:$D,"="&$C33) -> 0 | L33: =SUMIFS(古玩城农商银行!$O:$O,古玩城农商银行!$B:$B,"="&$E$2,古玩城农商银行!$D:$D,"="&$C33) -> 0 | M33: 0 | N33: =SUMIFS(艾泊烨海峡银行!$H:$H,艾泊烨海峡银行!$B:$B,"="&$E$2,艾泊烨海峡银行!$D:$D,"="&$C33) -> 20682.24 | O33: 0 | P33: =SUMIFS(艾泊烨农商银行!$J:$J,艾泊烨农商银行!$B:$B,"="&$E$2,艾泊烨农商银行!D:D,"="&$C33) -> 0 | Q33: =SUMIFS(艾泊烨私户银行!$H:$H,艾泊烨私户银行!$B:$B,"="&$E$2,艾泊烨私户银行!$D:$D,"="&$C33) -> 0 | R33: =SUMIFS(易佰兴建行!$P:$P,易佰兴建行!$B:$B,"="&$E$2,易佰兴建行!$D:$D,"="&$C33) -> 0 | S33: =SUMIFS(易佰兴私户!$P:$P,易佰兴私户!$B:$B,"="&$E$2,易佰兴私户!$D:$D,"="&$C33) -> 3244.38 | T33: =SUMIFS(易佰兴现金!$O:$O,易佰兴现金!$B:$B,"="&$E$2,易佰兴现金!D:D,"="&$C33) -> 0 | U33: =SUMIFS(易佰兴基本户!$P:$P,易佰兴基本户!$B:$B,"="&$E$2,易佰兴基本户!D:D,"="&$C33) -> 0
B34: =B33 -> 5 | C34: 吴华云账户 | E34: =SUMIFS(力喆实业中国银行!$H:$H,力喆实业中国银行!$B:$B,"="&$E$2,力喆实业中国银行!$D:$D,"="&$C34) -> 0 | F34: =SUMIFS(力喆产业农商银行!$H:$H,力喆产业农商银行!$B:$B,"="&$E$2,力喆产业农商银行!$D:$D,"="&$C34) -> 0 | G34: =SUMIFS(徐洁招商银行!$H:$H,徐洁招商银行!$B:$B,"="&$E$2,徐洁招商银行!$D:$D,"="&$C34) -> 0 | H34: =SUMIFS(力喆贸易建设银行!$H:$H,力喆贸易建设银行!$B:$B,"="&$E$2,力喆贸易建设银行!$D:$D,"="&$C34) -> 0 | T34: =SUMIFS(易佰兴现金!$O:$O,易佰兴现金!$B:$B,"="&$E$2,易佰兴现金!D:D,"="&$C34) -> 0
B35: =B33 -> 5 | C35: 员工保险 | D35: =SUMIFS(#REF!,#REF!,"="&$E$2,#REF!,"="&$C35) -> #REF! | E35: =SUMIFS(力喆实业中国银行!$H:$H,力喆实业中国银行!$B:$B,"="&$E$2,力喆实业中国银行!$D:$D,"="&$C35) -> 0 | F35: =SUMIFS(力喆产业农商银行!$H:$H,力喆产业农商银行!$B:$B,"="&$E$2,力喆产业农商银行!$D:$D,"="&$C35) -> 0 | G35: =SUMIFS(徐洁招商银行!$H:$H,徐洁招商银行!$B:$B,"="&$E$2,徐洁招商银行!$D:$D,"="&$C35) -> 0 | H35: =SUMIFS(力喆贸易建设银行!$H:$H,力喆贸易建设银行!$B:$B,"="&$E$2,力喆贸易建设银行!$D:$D,"="&$C35) -> 0 | I35: =SUMIFS(元生万物建设银行!$H:$H,元生万物建设银行!$B:$B,"="&$E$2,元生万物建设银行!$D:$D,"="&$C35) -> 0 | J35: =SUMIFS(言吾言中国银行!$H:$H,言吾言中国银行!$B:$B,"="&$E$2,言吾言中国银行!$D:$D,"="&$C35) -> 0 | K35: =SUMIFS(力喆传媒海峡银行!$H:$H,力喆传媒海峡银行!$B:$B,"="&$E$2,力喆传媒海峡银行!$D:$D,"="&$C35) -> 0 | L35: =SUMIFS(古玩城农商银行!$O:$O,古玩城农商银行!$B:$B,"="&$E$2,古玩城农商银行!$D:$D,"="&$C35) -> 0 | M35: 0 | N35: =SUMIFS(艾泊烨海峡银行!$H:$H,艾泊烨海峡银行!$B:$B,"="&$E$2,艾泊烨海峡银行!$D:$D,"="&$C35) -> 0 | O35: 0 | P35: =SUMIFS(艾泊烨农商银行!$J:$J,艾泊烨农商银行!$B:$B,"="&$E$2,艾泊烨农商银行!D:D,"="&$C35) -> 0 | Q35: =SUMIFS(艾泊烨私户银行!$H:$H,艾泊烨私户银行!$B:$B,"="&$E$2,艾泊烨私户银行!$D:$D,"="&$C35) -> 0 | R35: =SUMIFS(易佰兴建行!$P:$P,易佰兴建行!$B:$B,"="&$E$2,易佰兴建行!$D:$D,"="&$C35) -> 0 | S35: =SUMIFS(易佰兴私户!$P:$P,易佰兴私户!$B:$B,"="&$E$2,易佰兴私户!$D:$D,"="&$C35) -> 0 | T35: =SUMIFS(易佰兴现金!$O:$O,易佰兴现金!$B:$B,"="&$E$2,易佰兴现金!D:D,"="&$C35) -> 0 | U35: =SUMIFS(易佰兴基本户!$P:$P,易佰兴基本户!$B:$B,"="&$E$2,易佰兴基本户!D:D,"="&$C35) -> 0
B36: =B35 -> 5 | C36: 福利费 | D36: =SUMIFS(#REF!,#REF!,"="&$E$2,#REF!,"="&$C36) -> #REF! | E36: =SUMIFS(力喆实业中国银行!$H:$H,力喆实业中国银行!$B:$B,"="&$E$2,力喆实业中国银行!$D:$D,"="&$C36) -> 0 | F36: =SUMIFS(力喆产业农商银行!$H:$H,力喆产业农商银行!$B:$B,"="&$E$2,力喆产业农商银行!$D:$D,"="&$C36) -> 0 | G36: =SUMIFS(徐洁招商银行!$H:$H,徐洁招商银行!$B:$B,"="&$E$2,徐洁招商银行!$D:$D,"="&$C36) -> 0 | H36: =SUMIFS(力喆贸易建设银行!$H:$H,力喆贸易建设银行!$B:$B,"="&$E$2,力喆贸易建设银行!$D:$D,"="&$C36) -> 0 | I36: =SUMIFS(元生万物建设银行!$H:$H,元生万物建设银行!$B:$B,"="&$E$2,元生万物建设银行!$D:$D,"="&$C36) -> 0 | J36: =SUMIFS(言吾言中国银行!$H:$H,言吾言中国银行!$B:$B,"="&$E$2,言吾言中国银行!$D:$D,"="&$C36) -> 0 | K36: =SUMIFS(力喆传媒海峡银行!$H:$H,力喆传媒海峡银行!$B:$B,"="&$E$2,力喆传媒海峡银行!$D:$D,"="&$C36) -> 0 | L36: =SUMIFS(古玩城农商银行!$O:$O,古玩城农商银行!$B:$B,"="&$E$2,古玩城农商银行!$D:$D,"="&$C36) -> 0 | M36: 0 | N36: =SUMIFS(艾泊烨海峡银行!$H:$H,艾泊烨海峡银行!$B:$B,"="&$E$2,艾泊烨海峡银行!$D:$D,"="&$C36) -> 0 | O36: 0 | P36: =SUMIFS(艾泊烨农商银行!$J:$J,艾泊烨农商银行!$B:$B,"="&$E$2,艾泊烨农商银行!D:D,"="&$C36) -> 0 | Q36: =SUMIFS(艾泊烨私户银行!$H:$H,艾泊烨私户银行!$B:$B,"="&$E$2,艾泊烨私户银行!$D:$D,"="&$C36) -> 0 | R36: =SUMIFS(易佰兴建行!$P:$P,易佰兴建行!$B:$B,"="&$E$2,易佰兴建行!$D:$D,"="&$C36) -> 0 | S36: =SUMIFS(易佰兴私户!$P:$P,易佰兴私户!$B:$B,"="&$E$2,易佰兴私户!$D:$D,"="&$C36) -> 0 | T36: =SUMIFS(易佰兴现金!$O:$O,易佰兴现金!$B:$B,"="&$E$2,易佰兴现金!D:D,"="&$C36) -> 0 | U36: =SUMIFS(易佰兴基本户!$P:$P,易佰兴基本户!$B:$B,"="&$E$2,易佰兴基本户!D:D,"="&$C36) -> 0
B37: =B36 -> 5 | C37: 招待费 | D37: =SUMIFS(#REF!,#REF!,"="&$E$2,#REF!,"="&$C37) -> #REF! | E37: =SUMIFS(力喆实业中国银行!$H:$H,力喆实业中国银行!$B:$B,"="&$E$2,力喆实业中国银行!$D:$D,"="&$C37) -> 0 | F37: =SUMIFS(力喆产业农商银行!$H:$H,力喆产业农商银行!$B:$B,"="&$E$2,力喆产业农商银行!$D:$D,"="&$C37) -> 0 | G37: =SUMIFS(徐洁招商银行!$H:$H,徐洁招商银行!$B:$B,"="&$E$2,徐洁招商银行!$D:$D,"="&$C37) -> 0 | H37: =SUMIFS(力喆贸易建设银行!$H:$H,力喆贸易建设银行!$B:$B,"="&$E$2,力喆贸易建设银行!$D:$D,"="&$C37) -> 0 | I37: =SUMIFS(元生万物建设银行!$H:$H,元生万物建设银行!$B:$B,"="&$E$2,元生万物建设银行!$D:$D,"="&$C37) -> 0 | J37: =SUMIFS(言吾言中国银行!$H:$H,言吾言中国银行!$B:$B,"="&$E$2,言吾言中国银行!$D:$D,"="&$C37) -> 0 | K37: =SUMIFS(力喆传媒海峡银行!$H:$H,力喆传媒海峡银行!$B:$B,"="&$E$2,力喆传媒海峡银行!$D:$D,"="&$C37) -> 0 | L37: =SUMIFS(古玩城农商银行!$O:$O,古玩城农商银行!$B:$B,"="&$E$2,古玩城农商银行!$D:$D,"="&$C37) -> 0 | M37: 0 | N37: =SUMIFS(艾泊烨海峡银行!$H:$H,艾泊烨海峡银行!$B:$B,"="&$E$2,艾泊烨海峡银行!$D:$D,"="&$C37) -> 0 | O37: 0 | P37: =SUMIFS(艾泊烨农商银行!$J:$J,艾泊烨农商银行!$B:$B,"="&$E$2,艾泊烨农商银行!D:D,"="&$C37) -> 0 | Q37: =SUMIFS(艾泊烨私户银行!$H:$H,艾泊烨私户银行!$B:$B,"="&$E$2,艾泊烨私户银行!$D:$D,"="&$C37) -> 0 | R37: =SUMIFS(易佰兴建行!$P:$P,易佰兴建行!$B:$B,"="&$E$2,易佰兴建行!$D:$D,"="&$C37) -> 0 | S37: =SUMIFS(易佰兴私户!$P:$P,易佰兴私户!$B:$B,"="&$E$2,易佰兴私户!$D:$D,"="&$C37) -> 0 | T37: =SUMIFS(易佰兴现金!$O:$O,易佰兴现金!$B:$B,"="&$E$2,易佰兴现金!D:D,"="&$C37) -> 0 | U37: =SUMIFS(易佰兴基本户!$P:$P,易佰兴基本户!$B:$B,"="&$E$2,易佰兴基本户!D:D,"="&$C37) -> 0
B38: =B37 -> 5 | C38: 酒水费 | D38: =SUMIFS(#REF!,#REF!,"="&$E$2,#REF!,"="&$C38) -> #REF! | E38: =SUMIFS(力喆实业中国银行!$H:$H,力喆实业中国银行!$B:$B,"="&$E$2,力喆实业中国银行!$D:$D,"="&$C38) -> 0 | F38: =SUMIFS(力喆产业农商银行!$H:$H,力喆产业农商银行!$B:$B,"="&$E$2,力喆产业农商银行!$D:$D,"="&$C38) -> 0 | G38: =SUMIFS(徐洁招商银行!$H:$H,徐洁招商银行!$B:$B,"="&$E$2,徐洁招商银行!$D:$D,"="&$C38) -> 0 | H38: =SUMIFS(力喆贸易建设银行!$H:$H,力喆贸易建设银行!$B:$B,"="&$E$2,力喆贸易建设银行!$D:$D,"="&$C38) -> 0 | I38: =SUMIFS(元生万物建设银行!$H:$H,元生万物建设银行!$B:$B,"="&$E$2,元生万物建设银行!$D:$D,"="&$C38) -> 0 | J38: =SUMIFS(言吾言中国银行!$H:$H,言吾言中国银行!$B:$B,"="&$E$2,言吾言中国银行!$D:$D,"="&$C38) -> 0 | K38: =SUMIFS(力喆传媒海峡银行!$H:$H,力喆传媒海峡银行!$B:$B,"="&$E$2,力喆传媒海峡银行!$D:$D,"="&$C38) -> 0 | L38: =SUMIFS(古玩城农商银行!$O:$O,古玩城农商银行!$B:$B,"="&$E$2,古玩城农商银行!$D:$D,"="&$C38) -> 0 | M38: 0 | N38: =SUMIFS(艾泊烨海峡银行!$H:$H,艾泊烨海峡银行!$B:$B,"="&$E$2,艾泊烨海峡银行!$D:$D,"="&$C38) -> 0 | O38: 0 | P38: =SUMIFS(艾泊烨农商银行!$J:$J,艾泊烨农商银行!$B:$B,"="&$E$2,艾泊烨农商银行!D:D,"="&$C38) -> 0 | Q38: =SUMIFS(艾泊烨私户银行!$H:$H,艾泊烨私户银行!$B:$B,"="&$E$2,艾泊烨私户银行!$D:$D,"="&$C38) -> 0 | R38: =SUMIFS(易佰兴建行!$P:$P,易佰兴建行!$B:$B,"="&$E$2,易佰兴建行!$D:$D,"="&$C38) -> 0 | S38: =SUMIFS(易佰兴私户!$P:$P,易佰兴私户!$B:$B,"="&$E$2,易佰兴私户!$D:$D,"="&$C38) -> 0 | T38: =SUMIFS(易佰兴现金!$O:$O,易佰兴现金!$B:$B,"="&$E$2,易佰兴现金!D:D,"="&$C38) -> 0 | U38: =SUMIFS(易佰兴基本户!$P:$P,易佰兴基本户!$B:$B,"="&$E$2,易佰兴基本户!D:D,"="&$C38) -> 0
B39: =B38 -> 5 | C39: 公共关系费用 | D39: =SUMIFS(#REF!,#REF!,"="&$E$2,#REF!,"="&$C39) -> #REF! | E39: =SUMIFS(力喆实业中国银行!$H:$H,力喆实业中国银行!$B:$B,"="&$E$2,力喆实业中国银行!$D:$D,"="&$C39) -> 0 | F39: =SUMIFS(力喆产业农商银行!$H:$H,力喆产业农商银行!$B:$B,"="&$E$2,力喆产业农商银行!$D:$D,"="&$C39) -> 0 | G39: =SUMIFS(徐洁招商银行!$H:$H,徐洁招商银行!$B:$B,"="&$E$2,徐洁招商银行!$D:$D,"="&$C39) -> 0 | H39: =SUMIFS(力喆贸易建设银行!$H:$H,力喆贸易建设银行!$B:$B,"="&$E$2,力喆贸易建设银行!$D:$D,"="&$C39) -> 0 | I39: =SUMIFS(元生万物建设银行!$H:$H,元生万物建设银行!$B:$B,"="&$E$2,元生万物建设银行!$D:$D,"="&$C39) -> 0 | J39: =SUMIFS(言吾言中国银行!$H:$H,言吾言中国银行!$B:$B,"="&$E$2,言吾言中国银行!$D:$D,"="&$C39) -> 0 | K39: =SUMIFS(力喆传媒海峡银行!$H:$H,力喆传媒海峡银行!$B:$B,"="&$E$2,力喆传媒海峡银行!$D:$D,"="&$C39) -> 0 | L39: =SUMIFS(古玩城农商银行!$O:$O,古玩城农商银行!$B:$B,"="&$E$2,古玩城农商银行!$D:$D,"="&$C39) -> 0 | M39: 0 | N39: =SUMIFS(艾泊烨海峡银行!$H:$H,艾泊烨海峡银行!$B:$B,"="&$E$2,艾泊烨海峡银行!$D:$D,"="&$C39) -> 0 | O39: 0 | P39: =SUMIFS(艾泊烨农商银行!$J:$J,艾泊烨农商银行!$B:$B,"="&$E$2,艾泊烨农商银行!D:D,"="&$C39) -> 0 | Q39: =SUMIFS(艾泊烨私户银行!$H:$H,艾泊烨私户银行!$B:$B,"="&$E$2,艾泊烨私户银行!$D:$D,"="&$C39) -> 0 | R39: =SUMIFS(易佰兴建行!$P:$P,易佰兴建行!$B:$B,"="&$E$2,易佰兴建行!$D:$D,"="&$C39) -> 0 | S39: =SUMIFS(易佰兴私户!$P:$P,易佰兴私户!$B:$B,"="&$E$2,易佰兴私户!$D:$D,"="&$C39) -> 0 | T39: =SUMIFS(易佰兴现金!$O:$O,易佰兴现金!$B:$B,"="&$E$2,易佰兴现金!D:D,"="&$C39) -> 0 | U39: =SUMIFS(易佰兴基本户!$P:$P,易佰兴基本户!$B:$B,"="&$E$2,易佰兴基本户!D:D,"="&$C39) -> 0
B40: =B39 -> 5 | C40: 办公费 | D40: =SUMIFS(#REF!,#REF!,"="&$E$2,#REF!,"="&$C40) -> #REF! | E40: =SUMIFS(力喆实业中国银行!$H:$H,力喆实业中国银行!$B:$B,"="&$E$2,力喆实业中国银行!$D:$D,"="&$C40) -> 0 | F40: =SUMIFS(力喆产业农商银行!$H:$H,力喆产业农商银行!$B:$B,"="&$E$2,力喆产业农商银行!$D:$D,"="&$C40) -> 0 | G40: =SUMIFS(徐洁招商银行!$H:$H,徐洁招商银行!$B:$B,"="&$E$2,徐洁招商银行!$D:$D,"="&$C40) -> 0 | H40: =SUMIFS(力喆贸易建设银行!$H:$H,力喆贸易建设银行!$B:$B,"="&$E$2,力喆贸易建设银行!$D:$D,"="&$C40) -> 0 | I40: =SUMIFS(元生万物建设银行!$H:$H,元生万物建设银行!$B:$B,"="&$E$2,元生万物建设银行!$D:$D,"="&$C40) -> 0 | J40: =SUMIFS(言吾言中国银行!$H:$H,言吾言中国银行!$B:$B,"="&$E$2,言吾言中国银行!$D:$D,"="&$C40) -> 0 | K40: =SUMIFS(力喆传媒海峡银行!$H:$H,力喆传媒海峡银行!$B:$B,"="&$E$2,力喆传媒海峡银行!$D:$D,"="&$C40) -> 0 | L40: =SUMIFS(古玩城农商银行!$O:$O,古玩城农商银行!$B:$B,"="&$E$2,古玩城农商银行!$D:$D,"="&$C40) -> 731.8 | M40: 0 | N40: =SUMIFS(艾泊烨海峡银行!$H:$H,艾泊烨海峡银行!$B:$B,"="&$E$2,艾泊烨海峡银行!$D:$D,"="&$C40) -> 0 | O40: 0 | P40: =SUMIFS(艾泊烨农商银行!$J:$J,艾泊烨农商银行!$B:$B,"="&$E$2,艾泊烨农商银行!D:D,"="&$C40) -> 0 | Q40: =SUMIFS(艾泊烨私户银行!$H:$H,艾泊烨私户银行!$B:$B,"="&$E$2,艾泊烨私户银行!$D:$D,"="&$C40) -> 0 | R40: =SUMIFS(易佰兴建行!$P:$P,易佰兴建行!$B:$B,"="&$E$2,易佰兴建行!$D:$D,"="&$C40) -> 449 | S40: =SUMIFS(易佰兴私户!$P:$P,易佰兴私户!$B:$B,"="&$E$2,易佰兴私户!$D:$D,"="&$C40) -> 350 | T40: =SUMIFS(易佰兴现金!$O:$O,易佰兴现金!$B:$B,"="&$E$2,易佰兴现金!D:D,"="&$C40) -> 0 | U40: =SUMIFS(易佰兴基本户!$P:$P,易佰兴基本户!$B:$B,"="&$E$2,易佰兴基本户!D:D,"="&$C40) -> 0
B41: =B40 -> 5 | C41: 低值易耗品 | D41: =SUMIFS(#REF!,#REF!,"="&$E$2,#REF!,"="&$C41) -> #REF! | E41: =SUMIFS(力喆实业中国银行!$H:$H,力喆实业中国银行!$B:$B,"="&$E$2,力喆实业中国银行!$D:$D,"="&$C41) -> 0 | F41: =SUMIFS(力喆产业农商银行!$H:$H,力喆产业农商银行!$B:$B,"="&$E$2,力喆产业农商银行!$D:$D,"="&$C41) -> 0 | G41: =SUMIFS(徐洁招商银行!$H:$H,徐洁招商银行!$B:$B,"="&$E$2,徐洁招商银行!$D:$D,"="&$C41) -> 0 | H41: =SUMIFS(力喆贸易建设银行!$H:$H,力喆贸易建设银行!$B:$B,"="&$E$2,力喆贸易建设银行!$D:$D,"="&$C41) -> 0 | I41: =SUMIFS(元生万物建设银行!$H:$H,元生万物建设银行!$B:$B,"="&$E$2,元生万物建设银行!$D:$D,"="&$C41) -> 0 | J41: =SUMIFS(言吾言中国银行!$H:$H,言吾言中国银行!$B:$B,"="&$E$2,言吾言中国银行!$D:$D,"="&$C41) -> 0 | K41: =SUMIFS(力喆传媒海峡银行!$H:$H,力喆传媒海峡银行!$B:$B,"="&$E$2,力喆传媒海峡银行!$D:$D,"="&$C41) -> 0 | L41: =SUMIFS(古玩城农商银行!$O:$O,古玩城农商银行!$B:$B,"="&$E$2,古玩城农商银行!$D:$D,"="&$C41) -> 0 | M41: 0 | N41: =SUMIFS(艾泊烨海峡银行!$H:$H,艾泊烨海峡银行!$B:$B,"="&$E$2,艾泊烨海峡银行!$D:$D,"="&$C41) -> 0 | O41: 0 | P41: =SUMIFS(艾泊烨农商银行!$J:$J,艾泊烨农商银行!$B:$B,"="&$E$2,艾泊烨农商银行!D:D,"="&$C41) -> 0 | Q41: =SUMIFS(艾泊烨私户银行!$H:$H,艾泊烨私户银行!$B:$B,"="&$E$2,艾泊烨私户银行!$D:$D,"="&$C41) -> 0 | R41: =SUMIFS(易佰兴建行!$P:$P,易佰兴建行!$B:$B,"="&$E$2,易佰兴建行!$D:$D,"="&$C41) -> 0 | S41: =SUMIFS(易佰兴私户!$P:$P,易佰兴私户!$B:$B,"="&$E$2,易佰兴私户!$D:$D,"="&$C41) -> 139 | T41: =SUMIFS(易佰兴现金!$O:$O,易佰兴现金!$B:$B,"="&$E$2,易佰兴现金!D:D,"="&$C41) -> 0 | U41: =SUMIFS(易佰兴基本户!$P:$P,易佰兴基本户!$B:$B,"="&$E$2,易佰兴基本户!D:D,"="&$C41) -> 0
...

Sheet 付费项
B1: 收费项 | C1: 收入类型
B2: 薪资 | C2: 往来款 | D2: =VLOOKUP(收费名称[[#This Row],[收费项]],汇总!C:C,1,0) -> 薪资
B3: 五险一金 | C3: 房租 | D3: =VLOOKUP(收费名称[[#This Row],[收费项]],汇总!C:C,1,0) -> 五险一金
B4: 员工保险 | C4: 物业费 | D4: =VLOOKUP(收费名称[[#This Row],[收费项]],汇总!C:C,1,0) -> 员工保险
B5: 福利费 | D5: =VLOOKUP(收费名称[[#This Row],[收费项]],汇总!C:C,1,0) -> 福利费
B6: 招待费 | D6: =VLOOKUP(收费名称[[#This Row],[收费项]],汇总!C:C,1,0) -> 招待费
B7: 酒水费 | D7: =VLOOKUP(收费名称[[#This Row],[收费项]],汇总!C:C,1,0) -> 酒水费
B8: 公共关系费用 | D8: =VLOOKUP(收费名称[[#This Row],[收费项]],汇总!C:C,1,0) -> 公共关系费用
B9: 办公费 | D9: =VLOOKUP(收费名称[[#This Row],[收费项]],汇总!C:C,1,0) -> 办公费
B10: 低值易耗品 | D10: =VLOOKUP(收费名称[[#This Row],[收费项]],汇总!C:C,1,0) -> 低值易耗品
B11: 快递邮电费 | D11: =VLOOKUP(收费名称[[#This Row],[收费项]],汇总!C:C,1,0) -> 快递邮电费
B12: 通讯、宽带费 | D12: =VLOOKUP(收费名称[[#This Row],[收费项]],汇总!C:C,1,0) -> 通讯、宽带费
B13: 差旅费 | D13: =VLOOKUP(收费名称[[#This Row],[收费项]],汇总!C:C,1,0) -> 差旅费
B14: 退押金 | D14: =VLOOKUP(收费名称[[#This Row],[收费项]],汇总!C:C,1,0) -> 退押金
B15: 营销费用 | D15: =VLOOKUP(收费名称[[#This Row],[收费项]],汇总!C:C,1,0) -> 营销费用
B16: 油费 | D16: =VLOOKUP(收费名称[[#This Row],[收费项]],汇总!C:C,1,0) -> 油费
... B40: 车辆使用费 | D40: =VLOOKUP(收费名称[[#This Row],[收费项]],汇总!C:C,1,0) -> 车辆使用费
B41: 拆除费用
B42: 丝绸厂遮阳篷安装费
B43: 丝绸厂土建工程款
B44: 道闸服务费
B45: 场地租金
B46: 还贷款本金
B47: 光伏电费
B48: 垃圾清运费
B49: 中介介绍费
B50: 房租
B51: 佣金
B52: 借款支出
... B57: 丝绸厂电力工程
A58: 收入 | B58: 押金
A59: 收入 | B59: 往来款
B60: 借款转入
A61: 收入 | B61: 房租收入
A62: 收入 | B62: 物业收入
A63: 收入 | B63: 水电收入
A64: 收入 | B64: 摊位收入
A65: 收入 | B65: 其他收入
B66: 利息收入
B67: 贷款转入
...

Sheet 力喆实业中国银行
A1: =HYPERLINK("#目录!a1","返回目录") -> 返回目录 | B1: 力喆产业银行日记账--中国银行
B3: 月 | C3: 日 | D3: 收费项 | E3: 收付人 | F3: 摘要 | G3: 收入 | H3: 支出 | I3: 余额 | J3: 备注
F4: 期初余额 | I4: 20187.05
B5: 3 | C5: 6 | D5: 银行手续费 | E5: 银行 | F5: 回单箱服务年费 | H5: 400 | I5: =I4+G5-H5 -> 19787.05
B6: 3 | C6: 20 | D6: 利息收入 | E6: 银行 | F6: 利息收入 | G6: 2.52 | I6: =I5+G6-H6 -> 19789.57
F7: 本月合计 | G7: =SUM(G5:G6) -> 2.52 | H7: =SUM(H5:H6) -> 400 | I7: =I4+G7-H7 -> 19789.57
B8: 6 | C8: 20 | D8: 利息收入 | E8: 银行 | F8: 利息收入 | G8: 2.53 | I8: =I7+G8-H8 -> 19792.1
F9: 本月合计 | G9: =SUM(G8) -> 2.53 | H9: =SUM(H8) -> 0 | I9: =I6+G9-H9 -> 19792.1
I10: =I9+G10-H10 -> 19792.1
I11: =I10+G11-H11 -> 19792.1
I12: =I11+G12-H12 -> 19792.1
I13: =I12+G13-H13 -> 19792.1
I14: =I13+G14-H14 -> 19792.1
I15: =I14+G15-H15 -> 19792.1
I16: =I15+G16-H16 -> 19792.1
I17: =I16+G17-H17 -> 19792.1
I18: =I17+G18-H18 -> 19792.1
I19: =I18+G19-H19 -> 19792.1
I20: =I19+G20-H20 -> 19792.1
I21: =I20+G21-H21 -> 19792.1
... I65: =I64+G65-H65 -> 19792.1

Sheet 力喆产业农商银行
A1: =HYPERLINK("#目录!a1","返回目录") -> 返回目录 | B1: 力喆产业银行日记账--农商银行
B3: 月 | C3: 日 | D3: 收费项 | E3: 收付人 | F3: 摘要 | G3: 收入 | H3: 支出 | I3: 余额 | J3: 备注
F4: 期初余额 | I4: 20301.19
B5: 1 | C5: 8 | D5: 银行手续费 | F5: 支付短信服务费 | H5: 10 | I5: =I4+G5-H5 -> 20291.19
B6: 1 | C6: 13 | D6: 税费 | E6: 国家税务总局福州市晋安区税务局 | F6: 工会经费（20251001-20251231） | H6: 24 | I6: =I5+G6-H6 -> 20267.19
B7: 1 | C7: 13 | D7: 税费 | E7: 国家税务总局福州市晋安区税务局 | F7: 支付印花税（20251001-20251231） | H7: 6.68 | I7: =I6+G7-H7 -> 20260.51
B8: 1 | C8: 16 | D8: 往来款 | E8: 徐洁 | F8: 收雅道巷63-1租金（2025.12.22-2026.3.21） | G8: 12832.11 | I8: =I7+G8-H8 -> 33092.62
B9: 1 | C9: 16 | D9: 房租 | E9: 福州名城保护开发有限公司 | F9: 支付雅道巷63-1租金（2025.12.22-2026.3.21） | H9: 12832.11 | I9: =I8+G9-H9 -> 20260.51
B10: 1 | C10: 16 | D10: 往来款 | E10: 福建力喆贸易有限公司 | F10: 收回力喆贸易借款 | G10: 50000 | I10: =I9+G10-H10 -> 70260.51
B11: 1 | C11: 21 | D11: 贷款利息 | E11: 农商银行 | F11: 支付900万贷款利息 | H11: 24189.3 | I11: =I10+G11-H11 -> 46071.21
B12: 1 | C12: 21 | D12: 贷款利息 | E12: 农商银行 | F12: 支付900万贷款利息 | H12: 12115.58 | I12: =I11+G12-H12 -> 33955.63
B13: 1 | C13: 21 | D13: 五险一金 | E13: 国家税务总局福州市晋安区税务局 | F13: 企业职工基本养老保险费 20260101-20260131 1940.64 失业保险费 20260101-20260131 80.88 工伤保险费 20260101-20260131 35.32 基本医疗保险费 20260101-20260131 886.6 生育保险 20260101-20260131 62.06 | H13: 3005.5 | I13: =I12+G13-H13 -> 30950.13
B14: 1 | C14: 25 | D14: 通讯、宽带费 | E14: 中国电信股份有限公司福州分公司 | F14: 12月电信宽带费 | H14: 249 | I14: =I13+G14-H14 -> 30701.13
B15: 1 | C15: 27 | D15: 房租收入 | E15: 福州心上造物网络科技有限公司 | F15: 收汤房巷3号26年1月租金4100元、1月物业及12月水费500元、电费119.91元、税费47.2元 | G15: 4767.11 | I15: =I14+G15-H15 -> 35468.24
B16: 1 | C16: 27 | D16: 房租收入 | E16: 福州心上造物网络科技有限公司 | F16: 收汤房巷1号26年1月租金4663.8元、1月物业886.4元、12月水费200元、电费120.75元、税费58.71元 | G16: 5929.66 | I16: =I15+G16-H16 -> 41397.9
F17: 本月合计 | G17: =SUM(G5:G16) -> 73528.88 | H17: =SUM(H5:H16) -> 52432.17 | I17: =I4+G17-H17 -> 41397.9
B18: 2 | C18: 8 | D18: 银行手续费 | E18: 银行 | F18: 支付短信服务费 | H18: 10 | I18: =I17+G18-H18 -> 41387.9
B19: 2 | C19: 10 | D19: ETC（闽AD10200） | E19: 福建省高速公路集团有限公司电子收费管理中心 | F19: 高速ETC记账卡批量扣款 | H19: 6.18 | I19: =I18+G19-H19 -> 41381.72
B20: 2 | C20: 13 | D20: 往来款 | E20: 福建力喆贸易有限公司 | F20: 收回力喆贸易借款 | G20: 20000 | I20: =I19+G20-H20 -> 61381.72
B21: 2 | C21: 13 | D21: 往来款 | E21: 徐洁 | F21: 一般户转入徐洁招行账户 | H21: 16000 | I21: =I20+G21-H21 -> 45381.72
B22: 2 | C22: 17 | D22: 通讯、宽带费 | E22: 中国电信股份有限公司福州分公司 | F22: 1月电信宽带费 | H22: 249 | I22: =I21+G22-H22 -> 45132.72
B23: 2 | C23: 21 | D23: 贷款利息 | E23: 农商银行 | F23: 支付900万贷款利息 | H23: 24189.3 | I23: =I22+G23-H23 -> 20943.42
B24: 2 | C24: 21 | D24: 贷款利息 | E24: 农商银行 | F24: 支付900万贷款利息 | H24: 12115.58 | I24: =I23+G24-H24 -> 8827.84
B25: 2 | C25: 24 | D25: 五险一金 | E25: 国家税务总局福州市晋安区税务局 | F25: 企业职工基本养老保险费 20260201-20260228 1940.64 失业保险费 20260201-20260228 80.88 工伤保险费 20260201-20260228 35.32 基本医疗保险费 20260201-20260228 886.6 生育保险 20260201-20260228 62.06 | H25: 3005.5 | I25: =I24+G25-H25 -> 5822.34
F26: 本月合计 | G26: =SUM(G18:G25) -> 20000 | H26: =SUM(H18:H25) -> 55575.56 | I26: =I17+G26-H26 -> 5822.34
B27: 3 | C27: 8 | D27: 银行手续费 | E27: 银行 | F27: 支付短信服务费 | H27: 10 | I27: =I26+G27-H27 -> 5812.34
B28: 3 | C28: 16 | D28: 通讯、宽带费 | E28: 中国电信股份有限公司福州分公司 | F28: 2月电信宽带费 | H28: 249.2 | I28: =I27+G28-H28 -> 5563.14
B29: 3 | C29: 16 | D29: 往来款 | E29: 福建力喆贸易有限公司 | F29: 收回力喆贸易借款 | G29: 32000 | I29: =I28+G29-H29 -> 37563.14
B30: 3 | C30: 21 | D30: 利息收入 | E30: 银行 | F30: 利息收入 | G30: 3.42 | I30: =I29+G30-H30 -> 37566.56
B31: 3 | C31: 21 | D31: 贷款利息 | E31: 农商银行 | F31: 支付900万贷款利息 | H31: 21848.4 | I31: =I30+G31-H31 -> 15718.16
B32: 3 | C32: 21 | D32: 贷款利息 | E32: 农商银行 | F32: 支付900万贷款利息 | H32: 10943.1 | I32: =I31+G32-H32 -> 4775.06
B33: 3 | C33: 23 | D33: 五险一金 | E33: 国家税务总局福州市晋安区税务局 | F33: 企业职工基本养老保险费 20260301-20260331 1940.64 失业保险费 20260301-20260331 80.88 工伤保险费 20260301-20260331 17.66 基本医疗保险费 20260301-20260331 886.6 生育保险 20260301-20260331 62.06 | H33: 2987.84 | I33: =I32+G33-H33 -> 1787.22
F34: 本月合计 | G34: =SUM(G27:G33) -> 32003.42 | H34: =SUM(H27:H33) -> 36038.54 | I34: =I26+G34-H34 -> 1787.22
B35: 4 | C35: 8 | D35: 银行手续费 | E35: 银行 | F35: 支付短信服务费 | H35: 10 | I35: =I34+G35-H35 -> 1777.22
B36: 4 | C36: 14 | D36: 通讯、宽带费 | E36: 中国电信股份有限公司福州分公司 | F36: 3月电信宽带费，宽带迁移服务费 | H36: 357 | I36: =I35+G36-H36 -> 1420.22
B37: 4 | C37: 15 | D37: 往来款 | E37: 徐洁 | F37: 徐洁转入一般户 | G37: 50000 | I37: =I36+G37-H37 -> 51420.22
B38: 4 | C38: 15 | D38: 往来款 | E38: 福建力喆贸易有限公司 | F38: 收回力喆贸易借款 | G38: 35000 | I38: =I37+G38-H38 -> 86420.22
B39: 4 | C39: 15 | D39: 快递邮电费 | E39: 刘桢颖 | F39: 顺丰快递费 | H39: 16.8 | I39: =I38+G39-H39 -> 86403.42
B40: 4 | C40: 16 | D40: 税费 | E40: 国家税务总局福州市晋安区税务局 | F40: 支付印花税（20260101-20260331） | H40: 11.65 | I40: =I39+G40-H40 -> 86391.77
B41: 4 | C41: 16 | D41: 税费 | E41: 国家税务总局福州市晋安区税务局 | F41: 工会经费（20260101-20260331） | H41: 24 | I41: =I40+G41-H41 -> 86367.77
...

Sheet 元生万物建设银行
A1: =HYPERLINK("#目录!a1","返回目录") -> 返回目录 | B1: 元生万物银行日记账--建设银行
B3: 月 | C3: 日 | D3: 收费项 | E3: 收付人 | F3: 摘要 | G3: 收入 | H3: 支出 | I3: 余额 | J3: 备注
F4: 期初余额 | I4: 36305.74
B5: 1 | C5: 8 | D5: 银行手续费 | E5: 建行广达支行 | F5: 支付手续费 | H5: 1 | I5: =I4+G5-H5 -> 36304.74
B6: 1 | C6: 10 | D6: 银行手续费 | E6: 建行广达支行 | F6: 自助设备使用费 | H6: 30 | I6: =I5+G6-H6 -> 36274.74
B7: 1 | C7: 13 | D7: 税费 | E7: 待报解预算收入（财库联网集中户） | F7: 20251001-20251231印花税 | H7: 42.57 | I7: =I6+G7-H7 -> 36232.17
F8: 本月合计 | H8: =SUM(H5:H7) -> 73.57 | I8: =I4+G8-H8 -> 36232.17
B9: 2 | C9: 10 | D9: 银行手续费 | E9: 建行广达支行 | F9: 自助设备使用费 | H9: 30 | I9: =I8+G9-H9 -> 36202.17
F10: 本月合计 | H10: =SUM(H9:H9) -> 30 | I10: =I8+G10-H10 -> 36202.17
B11: 3 | C11: 4 | D11: 往来款 | E11: 徐洁 | F11: 收衣锦坊52号及衣锦坊54号一进部分租金2026.2.16-2026.3.15 | G11: 30098.25 | I11: =I10+G11-H11 -> 66300.42
B12: 3 | C12: 10 | D12: 银行手续费 | E12: 建行广达支行 | F12: 自助设备使用费 | H12: 30 | I12: =I11+G12-H12 -> 66270.42
B13: 3 | C13: 21 | D13: 利息收入 | E13: 银行 | F13: 利息收入 | G13: 6.03 | I13: =I12+G13-H13 -> 66276.45
B14: 3 | C14: 23 | D14: 往来款 | E14: 徐洁 | F14: 收衣锦坊52号及衣锦坊54号一进部分租金2026.3.16-2026.4.15 | G14: 30098.25 | I14: =I13+G14-H14 -> 96374.7
B15: 3 | C15: 24 | D15: 衣锦坊52号一进房租 | E15: 福州名城保护开发有限公司 | F15: 衣锦坊52号及衣锦坊54号一进部分租金2026.2.16-2026.5.15 | H15: 89536.65 | I15: =I14+G15-H15 -> 6838.05
F16: 本月合计 | G16: =SUM(G11:G15) -> 60202.53 | H16: =SUM(H11:H15) -> 89566.65 | I16: =I10+G16-H16 -> 6838.05
B17: 4 | C17: 2 | D17: 往来款 | E17: 徐洁 | F17: 收衣锦坊52号及衣锦坊54号一进部分租金2026.4.16-2026.5.15 | G17: 30098.25 | I17: =I16+G17-H17 -> 36936.3
B18: 4 | C18: 7 | D18: 银行手续费 | E18: 建行广达支行 | F18: 企业网银服务费 | H18: 600 | I18: =I17+G18-H18 -> 36336.3
B19: 4 | C19: 8 | D19: 银行手续费 | E19: 建行广达支行 | F19: 支付手续费 | H19: 1 | I19: =I18+G19-H19 -> 36335.3
B20: 4 | C20: 10 | D20: 银行手续费 | E20: 建行广达支行 | F20: 自助设备使用费 | H20: 30 | I20: =I19+G20-H20 -> 36305.3
B21: 4 | C21: 17 | D21: 福利费 | E21: 刘桢颖 | F21: 2025年会费用（餐费） | H21: 1301.33 | I21: =I20+G21-H21 -> 35003.97
F22: 本月合计 | G22: =SUM(G17:G21) -> 30098.25 | H22: =SUM(H17:H21) -> 1932.33 | I22: =I16+G22-H22 -> 35003.97
B23: 5 | C23: 6 | D23: 往来款 | E23: 徐洁 | F23: 收衣锦坊52号及衣锦坊54号一进部分租金2026.5.16-2026.6.15 | G23: 30098.25 | I23: =I21+G23-H23 -> 65102.22
B24: 5 | C24: 10 | D24: 银行手续费 | E24: 建行广达支行 | F24: 自助设备使用费 | H24: 30 | I24: =I23+G24-H24 -> 65072.22
F25: 本月合计 | G25: =SUM(G23:G24) -> 30098.25 | H25: =SUM(H23:H24) -> 30 | I25: =I22+G25-H25 -> 65072.22
B26: 6 | C26: 3 | D26: 往来款 | E26: 徐洁 | F26: 收衣锦坊52号及衣锦坊54号一进部分租金2026.6.16-2026.7.15 | G26: 30098.25 | I26: =I24+G26-H26 -> 95170.47
B27: 6 | C27: 10 | D27: 银行手续费 | E27: 建行广达支行 | F27: 自助设备使用费 | H27: 30 | I27: =I26+G27-H27 -> 95140.47
B28: 6 | C28: 21 | D28: 利息收入 | E28: 银行 | F28: 利息收入 | G28: 7 | I28: =I27+G28-H28 -> 95147.47
B29: 6 | C29: 29 | D29: 税费 | E29: 周月平 | F29: 吴海萍徐莺股权转让印花税扣款 | H29: 1881.58 | I29: =I28+G29-H29 -> 93265.89
F30: 本月合计 | G30: =SUM(G26:G29) -> 30105.25 | H30: =SUM(H26:H29) -> 1911.58 | I30: =I25+G30-H30 -> 93265.89
B31: 7 | C31: 10 | D31: 银行手续费 | E31: 建行广达支行 | F31: 自助设备使用费 | H31: 30 | I31: =I29+G31-H31 -> 93235.89
B32: 7 | C32: 13 | D32: 税费 | E32: 待报解预算收入（财库联网集中户） | F32: 20260401-20260630印花税 | H32: 44.7 | I32: =I31+G32-H32 -> 93191.19
B33: 7 | C33: 26 | D33: 银行手续费 | E33: 建行广达支行 | F33: 企业网银服务费 | H33: 600 | I33: =I32+G33-H33 -> 92591.19
B34: 7 | C34: 28 | D34: 衣锦坊52号一进房租 | E34: 福州名城保护开发有限公司 | F34: 衣锦坊52号及衣锦坊54号一进部分租金2026.5.16-2026.8.15 | H34: 89536.65 | I34: =I33+G34-H34 -> 3054.54
B35: 7 | C35: 31 | D35: 往来款 | E35: 徐洁 | F35: 收衣锦坊52号及衣锦坊54号一进部分租金2026.6.16-2026.7.15 | G35: 30098.25 | I35: =I34+G35-H35 -> 33152.79
F36: 本月合计 | G36: =SUM(G31:G35) -> 30098.25 | H36: =SUM(H31:H35) -> 90211.35 | I36: =I30+G36-H36 -> 33152.79
B37: 8 | C37: 3 | D37: 往来款 | E37: 徐洁 | F37: 收衣锦坊52号及衣锦坊54号一进部分租金2026.7.16-2026.8.15 | G37: 30098.25 | I37: =I35+G37-H37 -> 63251.04
B38: 8 | C38: 8 | D38: 银行手续费 | E38: 建行广达支行 | F38: 支付手续费 | H38: 1 | I38: =I37+G38-H38 -> 63250.04
B39: 8 | C39: 10 | D39: 银行手续费 | E39: 建行广达支行 | F39: 自助设备使用费 | H39: 30 | I39: =I38+G39-H39 -> 63220.04
F40: 本月合计 | G40: =SUM(G37:G39) -> 30098.25 | H40: =SUM(H37:H39) -> 31 | I40: =I36+G40-H40 -> 63220.04
B41: 9 | C41: 10 | D41: 银行手续费 | E41: 建行广达支行 | F41: 自助设备使用费 | H41: 30 | I41: =I40+G41-H41 -> 63190.04
...

Sheet 言吾言中国银行
A1: =HYPERLINK("#目录!a1","返回目录") -> 返回目录 | B1: 言吾言银行日记账--中国银行
B3: 月 | C3: 日 | D3: 收费项 | E3: 收付人 | F3: 摘要 | G3: 收入 | H3: 支出 | I3: 余额 | J3: 备注
F4: 期初余额 | I4: 3045.39
B5: 1 | C5: 1 | D5: ETC（闽A6896D） | E5: 福建省高速公路集团有限公司 | F5: 支付ETC费用 | H5: 77.7 | I5: =I4+G5-H5 -> 2967.69
B6: 1 | C6: 2 | D6: ETC（闽A6896D） | E6: 福建省高速公路集团有限公司 | F6: 支付ETC费用 | H6: 24.7 | I6: =I5+G6-H6 -> 2942.99
B7: 1 | C7: 7 | D7: 银行手续费 | E7: 中国银行福州中亭街支行 | F7: 支付短信服务费 | H7: 20 | I7: =I6+G7-H7 -> 2922.99
B8: 1 | C8: 10 | D8: ETC（闽A6896D） | E8: 福建省高速公路集团有限公司 | F8: 支付ETC费用 | H8: 55.1 | I8: =I7+G8-H8 -> 2867.89
B9: 1 | C9: 27 | D9: 油费 | E9: 中石化森美（福建）石油有限公司 | F9: 充值油卡 | H9: 2000 | I9: =I8+G9-H9 -> 867.89
B10: 1 | C10: 27 | D10: 银行手续费 | E10: 中国银行福州中亭街支行 | F10: 转账手续费 | H10: 4.5 | I10: =I9+G10-H10 -> 863.39
B11: 1 | C11: 31 | D11: 银行手续费 | E11: 中国银行福州中亭街支行 | F11: 网银服务费 | H11: 500 | I11: =I10+G11-H11 -> 363.39
F12: 本月合计 | G12: =SUM(G5:G11) -> 0 | H12: =SUM(H5:H11) -> 2682 | I12: =I4+G12-H12 -> 363.39
B13: 2 | C13: 2 | D13: ETC（闽A6896D） | E13: 福建省高速公路集团有限公司 | F13: 支付ETC费用 | H13: 27.43 | I13: =I12+G13-H13 -> 335.96
B14: 2 | C14: 3 | D14: ETC（闽A6896D） | E14: 福建省高速公路集团有限公司 | F14: 支付ETC费用 | H14: 236.92 | I14: =I13+G14-H14 -> 99.04
B15: 2 | C15: 7 | D15: 银行手续费 | E15: 中国银行福州中亭街支行 | F15: 支付短信服务费 | H15: 20 | I15: =I14+G15-H15 -> 79.04
B16: 2 | C16: 9 | D16: 往来款 | E16: 吴海萍 | F16: 转入投资款 | G16: 1000 | I16: =I15+G16-H16 -> 1079.04
B17: 2 | C17: 28 | D17: 往来款 | E17: 吴海萍 | F17: 转入投资款 | G17: 5000 | I17: =I16+G17-H17 -> 6079.04
B18: 2 | C18: 28 | D18: 油费 | E18: 中石化森美（福建）石油有限公司 | F18: 充值油卡 | H18: 2000 | I18: =I17+G18-H18 -> 4079.04
B19: 2 | C19: 28 | D19: ETC（闽A6896D） | E19: 福建省高速公路集团有限公司 | F19: 转账手续费 | H19: 4.5 | I19: =I18+G19-H19 -> 4074.54
B20: 2 | C20: 28 | D20: 往来款 | E20: 福建言吾言物业管理有限公司 | F20: 转入投资款 | G20: 5000 | I20: =I19+G20-H20 -> 9074.54
F21: 本月合计 | G21: =SUM(G13:G20) -> 11000 | H21: =SUM(H13:H20) -> 2288.85 | I21: =I12+G21-H21 -> 9074.54
B22: 3 | C22: 2 | D22: ETC（闽A6896D） | E22: 福建省高速公路集团有限公司 | F22: 支付ETC费用 | H22: 48.94 | I22: =I21+G22-H22 -> 9025.6
B23: 3 | C23: 6 | D23: 银行手续费 | E23: 中国银行福州中亭街支行 | F23: 回单箱网银服务费 | H23: 400 | I23: =I22+G23-H23 -> 8625.6
B24: 3 | C24: 7 | D24: 银行手续费 | E24: 中国银行福州中亭街支行 | F24: 支付短信服务费 | H24: 20 | I24: =I23+G24-H24 -> 8605.6
B25: 3 | C25: 20 | D25: 利息收入 | E25: 中国银行福州中亭街支行 | F25: 利息收入 | G25: 0.45 | I25: =I24+G25-H25 -> 8606.05
B26: 3 | C26: 22 | D26: ETC（闽A6896D） | E26: 福建省高速公路集团有限公司 | F26: 支付ETC费用 | H26: 100.3 | I26: =I25+G26-H26 -> 8505.75
B27: 3 | C27: 24 | D27: 油费 | E27: 中石化森美（福建）石油有限公司 | F27: 充值油卡 | H27: 2000 | I27: =I26+G27-H27 -> 6505.75
B28: 3 | C28: 24 | D28: 银行手续费 | E28: 中国银行福州中亭街支行 | F28: 转账手续费 | H28: 4.5 | I28: =I27+G28-H28 -> 6501.25
F29: 本月合计 | G29: =SUM(G22:G28) -> 0.45 | H29: =SUM(H22:H28) -> 2573.74 | I29: =I20+G29-H29 -> 6501.25
B30: 4 | C30: 7 | D30: 银行手续费 | E30: 中国银行福州中亭街支行 | F30: 支付短信服务费 | H30: 20 | I30: =I28+G30-H30 -> 6481.25
B31: 4 | C31: 21 | D31: ETC（闽A6896D） | E31: 福建省高速公路集团有限公司 | F31: 支付ETC费用 | H31: 28.5 | I31: =I30+G31-H31 -> 6452.75
B32: 4 | C32: 26 | D32: ETC（闽A6896D） | E32: 福建省高速公路集团有限公司 | F32: 支付ETC费用 | H32: 28.5 | I32: =I31+G32-H32 -> 6424.25
B33: 4 | C33: 30 | D33: 油费 | E33: 中石化森美（福建）石油有限公司 | F33: 充值油卡 | H33: 2000 | I33: =I32+G33-H33 -> 4424.25
B34: 4 | C34: 30 | D34: 银行手续费 | E34: 中国银行福州中亭街支行 | F34: 转账手续费 | H34: 4.5 | I34: =I33+G34-H34 -> 4419.75
F35: 本月合计 | G35: =SUM(G30:G34) -> 0 | H35: =SUM(H30:H34) -> 2081.5 | I35: =I29+G35-H35 -> 4419.75
B36: 5 | C36: 7 | D36: 银行手续费 | E36: 中国银行福州中亭街支行 | F36: 支付短信服务费 | H36: 20 | I36: =I34+G36-H36 -> 4399.75
B37: 5 | C37: 9 | D37: ETC（闽A6896D） | E37: 福建省高速公路集团有限公司 | F37: 支付ETC费用 | H37: 28.5 | I37: =I36+G37-H37 -> 4371.25
B38: 5 | C38: 14 | D38: ETC（闽A6896D） | E38: 福建省高速公路集团有限公司 | F38: 支付ETC费用 | H38: 57 | I38: =I37+G38-H38 -> 4314.25
B39: 5 | C39: 30 | D39: ETC（闽A6896D） | E39: 福建省高速公路集团有限公司 | F39: 支付ETC费用 | H39: 28.5 | I39: =I38+G39-H39 -> 4285.75
F40: 本月合计 | G40: =SUM(G36:G39) -> 0 | H40: =SUM(H36:H39) -> 134 | I40: =I34+G40-H40 -> 4285.75
B41: 6 | C41: 2 | D41: 油费 | E41: 中石化森美（福建）石油有限公司 | F41: 充值油卡 | H41: 2000 | I41: =I39+G41-H41 -> 2285.75
...

Sheet 力喆传媒海峡银行
A1: =HYPERLINK("#目录!a1","返回目录") -> 返回目录 | B1: 力喆传媒银行日记账--海峡银行
B3: 月 | C3: 日 | D3: 收费项 | E3: 收付人 | F3: 摘要 | G3: 收入 | H3: 支出 | I3: 余额 | J3: 备注
F4: 期初余额 | I4: 10337.35
B5: 1 | C5: 11 | D5: 银行手续费 | E5: 银行 | F5: 回单打印费 | H5: 60 | I5: =I4+G5-H5 -> 10277.35
F6: 本月合计 | G6: =SUM(G5:G5) -> 0 | H6: =SUM(H5:H5) -> 60 | I6: =I4+G6-H6 -> 10277.35
B7: 2 | C7: 27 | D7: 往来款 | E7: 往来款 | F7: 转入吴海萍 | H7: 5000 | I7: =I6+G7-H7 -> 5277.35
B8: 2 | C8: 27 | D8: 银行手续费 | E8: 银行 | F8: 转账手续费 | H8: 4 | I8: =I7+G8-H8 -> 5273.35
B9: 2 | C9: 28 | D9: 往来款 | E9: 往来款 | F9: 转入吴海萍 | H9: 5000 | I9: =I8+G9-H9 -> 273.35
B10: 2 | C10: 28 | D10: 银行手续费 | E10: 银行 | F10: 转账手续费 | H10: 4 | I10: =I9+G10-H10 -> 269.35
F11: 本月合计 | G11: =SUM(G7:G10) -> 0 | H11: =SUM(H7:H10) -> 10008 | I11: =I6+G11-H11 -> 269.35
B12: 3 | C12: 21 | D12: 利息收入 | E12: 银行 | F12: 利息收入 | G12: 0.99 | I12: =I11+G12-H12 -> 270.34
F13: 本月合计 | G13: =SUM(G12) -> 0.99 | H13: =SUM(H12) -> 0 | I13: =I11+G13-H13 -> 270.34
B14: 6 | C14: 21 | D14: 利息收入 | E14: 银行 | F14: 利息收入 | G14: 0.03 | I14: 270.37
F15: 本月合计 | G15: =SUM(G14) -> 0.03 | H15: 0 | I15: 270.37
B16: 9 | C16: 21 | D16: 利息收入 | E16: 银行 | F16: 利息收入 | G16: 0.03 | I16: =I15+G16-H16 -> 270.4
