Workbook
Name 采购合同号: OFFSET([1]采购合同!$E$6,,,COUNTA([1]采购合同!$E$6:$E$2000))
Name 发票: OFFSET([1]基础信息!$W$6,,,COUNTA([1]基础信息!$W$4:$W$50))
Name 工程项目: OFFSET([1]基础信息!$Q$6,,,COUNTA([1]基础信息!$Q$6:$Q$1000))
Name 供应商: OFFSET([1]基础信息!$U$6,,,COUNTA([1]基础信息!$U$4:$U$2000))
Name 客户: OFFSET([1]基础信息!$T$6,,,COUNTA([1]基础信息!$T$4:$T$2000))
Name 日期: OFFSET(收支登记表!$D$8,,,COUNTA(收支登记表!$D:$D))
Name 收入: [1]基础信息!$G$6:$G$100
Name 税率: [1]基础信息!$Y$6:$Y$20
Name 销售合同号: OFFSET([1]销售合同!$E$6,,,COUNTA([1]销售合同!$E$6:$E$2000))
Name 员工: OFFSET([1]基础信息!$N$6,,,COUNTA([1]基础信息!$N$4:$N$2000))
Name 账户: OFFSET([1]基础信息!$B$6,,,COUNTA([1]基础信息!$B$4:$B$100))
Name 支出: [1]基础信息!$I$6:$I$100

Sheet 收支登记表
D5: 收支登记 | J5: 收入总金额 | K5: 支出总金额 | L5: 收支盈亏 | N5: 客户查询 | O5: 王先生 | P5: 收款金额 | Q5: =SUMIF($O$8:$O$5161,O5,$J$8:$J$5161) -> 0
J6: =SUBTOTAL(9,J8:J5161) -> 8908368.2 | K6: =SUBTOTAL(9,K8:K5161) -> 8744363.7 | L6: =J6-K6 -> 164004.51 | N6: 供应商查询 | O6: 宁波凯瑞 | P6: 付款金额 | Q6: =SUMIF($P$8:$P$5161,$O$6,$K$8:$K$5161) -> 0
D7: 日期 | E7: 凭证号 | F7: 类别 | G7: 账户 | H7: 收支项目 | I7: 业务摘要 | J7: 收入金额 | K7: 支出金额 | L7: 账户结余 | M7: 项目名称 | N7: 负责人 | O7: 客户名称 | P7: 供应商名称 | Q7: 销售合同 | R7: 采购合同 | S7: 备注
D8: 45271 | F8: 支出 | G8: 九江银行 | H8: 个人借款-聂辉 | I8: 聂辉个人借款 | K8: -1668 | L8: =IFERROR(IF(G8="","",VLOOKUP($G8,[1]基础信息!$B:$C,2,FALSE)+SUMIF(G$8:G8,G8,J$8:J8)-SUMIF(G$8:G8,G8,K$8:K8)+SUMIFS([1]内部转账!$G:$G,[1]内部转账!$C:$C,"<="&$D8,[1]内部转账!$E:$E,$G8)-SUMIFS([1]内部转账!$G:$G,[1]内部转账!$C:$C,"<="&$D8,[1]内部转账!$F:$F,$G8)),"") -> 1668 | M8: 个人借款 | N8: 聂辉 | P8: 聂辉
D9: 45271 | F9: 支出 | G9: 九江银行 | K9: 240 | L9: =IFERROR(IF(G9="","",VLOOKUP($G9,[1]基础信息!$B:$C,2,FALSE)+SUMIF(G$8:G9,G9,J$8:J9)-SUMIF(G$8:G9,G9,K$8:K9)+SUMIFS([1]内部转账!$G:$G,[1]内部转账!$C:$C,"<="&$D9,[1]内部转账!$E:$E,$G9)-SUMIFS([1]内部转账!$G:$G,[1]内部转账!$C:$C,"<="&$D9,[1]内部转账!$F:$F,$G9)),"") -> 1428 | P9: 江西省城市建设高级技术学校
D10: 45281 | F10: 支出 | G10: 九江银行 | H10: 办公室-办公费 | I10: 入息 | K10: -0.08 | L10: =IFERROR(IF(G10="","",VLOOKUP($G10,[1]基础信息!$B:$C,2,FALSE)+SUMIF(G$8:G10,G10,J$8:J10)-SUMIF(G$8:G10,G10,K$8:K10)+SUMIFS([1]内部转账!$G:$G,[1]内部转账!$C:$C,"<="&$D10,[1]内部转账!$E:$E,$G10)-SUMIFS([1]内部转账!$G:$G,[1]内部转账!$C:$C,"<="&$D10,[1]内部转账!$F:$F,$G10)),"") -> 1428.08 | M10: 办公室
D11: 45308 | F11: 支出 | G11: 九江银行 | H11: 个人借款-聂辉 | I11: 聂辉交项目保证金 | K11: -500000 | L11: =IFERROR(IF(G11="","",VLOOKUP($G11,[1]基础信息!$B:$C,2,FALSE)+SUMIF(G$8:G11,G11,J$8:J11)-SUMIF(G$8:G11,G11,K$8:K11)+SUMIFS([1]内部转账!$G:$G,[1]内部转账!$C:$C,"<="&$D11,[1]内部转账!$E:$E,$G11)-SUMIFS([1]内部转账!$G:$G,[1]内部转账!$C:$C,"<="&$D11,[1]内部转账!$F:$F,$G11)),"") -> 501428.08 | M11: 个人借款 | N11: 聂辉 | P11: 聂辉
D12: 45308 | F12: 支出 | G12: 九江银行 | H12: 项目-保证金 | I12: 保证金 | K12: 500000 | L12: =IFERROR(IF(G12="","",VLOOKUP($G12,[1]基础信息!$B:$C,2,FALSE)+SUMIF(G$8:G12,G12,J$8:J12)-SUMIF(G$8:G12,G12,K$8:K12)+SUMIFS([1]内部转账!$G:$G,[1]内部转账!$C:$C,"<="&$D12,[1]内部转账!$E:$E,$G12)-SUMIFS([1]内部转账!$G:$G,[1]内部转账!$C:$C,"<="&$D12,[1]内部转账!$F:$F,$G12)),"") -> 1428.08 | M12: 九江欣埠置业有限公司
D13: 45308 | F13: 支出 | G13: 九江银行 | H13: 办公室-办公费 | I13: 对公跨行汇款费 | K13: 15 | L13: =IFERROR(IF(G13="","",VLOOKUP($G13,[1]基础信息!$B:$C,2,FALSE)+SUMIF(G$8:G13,G13,J$8:J13)-SUMIF(G$8:G13,G13,K$8:K13)+SUMIFS([1]内部转账!$G:$G,[1]内部转账!$C:$C,"<="&$D13,[1]内部转账!$E:$E,$G13)-SUMIFS([1]内部转账!$G:$G,[1]内部转账!$C:$C,"<="&$D13,[1]内部转账!$F:$F,$G13)),"") -> 1413.08 | M13: 隆世光伏/共青办公楼/德祥工地
D14: 45310 | F14: 支出 | G14: 九江银行 | H14: 个人借款-聂辉 | I14: 聂辉交项目保证金 | K14: -500000 | L14: =IFERROR(IF(G14="","",VLOOKUP($G14,[1]基础信息!$B:$C,2,FALSE)+SUMIF(G$8:G14,G14,J$8:J14)-SUMIF(G$8:G14,G14,K$8:K14)+SUMIFS([1]内部转账!$G:$G,[1]内部转账!$C:$C,"<="&$D14,[1]内部转账!$E:$E,$G14)-SUMIFS([1]内部转账!$G:$G,[1]内部转账!$C:$C,"<="&$D14,[1]内部转账!$F:$F,$G14)),"") -> 501413.08 | M14: 个人借款 | N14: 聂辉 | P14: 聂辉
D15: 45310 | F15: 支出 | G15: 九江银行 | H15: 项目-保证金 | I15: 保证金 | K15: 500000 | L15: =IFERROR(IF(G15="","",VLOOKUP($G15,[1]基础信息!$B:$C,2,FALSE)+SUMIF(G$8:G15,G15,J$8:J15)-SUMIF(G$8:G15,G15,K$8:K15)+SUMIFS([1]内部转账!$G:$G,[1]内部转账!$C:$C,"<="&$D15,[1]内部转账!$E:$E,$G15)-SUMIFS([1]内部转账!$G:$G,[1]内部转账!$C:$C,"<="&$D15,[1]内部转账!$F:$F,$G15)),"") -> 1413.08 | M15: 九江欣埠置业有限公司
D16: 45324 | F16: 收入 | G16: 九江银行 | H16: 工程款 | I16: 收到劳务费 | J16: 71000 | L16: =IFERROR(IF(G16="","",VLOOKUP($G16,[1]基础信息!$B:$C,2,FALSE)+SUMIF(G$8:G16,G16,J$8:J16)-SUMIF(G$8:G16,G16,K$8:K16)+SUMIFS([1]内部转账!$G:$G,[1]内部转账!$C:$C,"<="&$D16,[1]内部转账!$E:$E,$G16)-SUMIFS([1]内部转账!$G:$G,[1]内部转账!$C:$C,"<="&$D16,[1]内部转账!$F:$F,$G16)),"") -> 72413.08 | M16: 温州盛为装饰工程有限公司 | O16: 温州盛为装饰工程有限公司
D17: 45329 | F17: 支出 | G17: 九江银行 | H17: 项目-劳务费 | I17: 张小朋 | K17: 5000 | L17: =IFERROR(IF(G17="","",VLOOKUP($G17,[1]基础信息!$B:$C,2,FALSE)+SUMIF(G$8:G17,G17,J$8:J17)-SUMIF(G$8:G17,G17,K$8:K17)+SUMIFS([1]内部转账!$G:$G,[1]内部转账!$C:$C,"<="&$D17,[1]内部转账!$E:$E,$G17)-SUMIFS([1]内部转账!$G:$G,[1]内部转账!$C:$C,"<="&$D17,[1]内部转账!$F:$F,$G17)),"") -> 67413.08 | M17: 温州盛为装饰工程有限公司 | P17: 张小朋
D18: 45329 | F18: 支出 | G18: 九江银行 | H18: 项目-劳务费 | I18: 张亮亮 | K18: 10000 | L18: =IFERROR(IF(G18="","",VLOOKUP($G18,[1]基础信息!$B:$C,2,FALSE)+SUMIF(G$8:G18,G18,J$8:J18)-SUMIF(G$8:G18,G18,K$8:K18)+SUMIFS([1]内部转账!$G:$G,[1]内部转账!$C:$C,"<="&$D18,[1]内部转账!$E:$E,$G18)-SUMIFS([1]内部转账!$G:$G,[1]内部转账!$C:$C,"<="&$D18,[1]内部转账!$F:$F,$G18)),"") -> 57413.08 | M18: 温州盛为装饰工程有限公司
D19: 45329 | F19: 支出 | G19: 九江银行 | H19: 项目-劳务费 | I19: 刘洪文 | K19: 7000 | L19: =IFERROR(IF(G19="","",VLOOKUP($G19,[1]基础信息!$B:$C,2,FALSE)+SUMIF(G$8:G19,G19,J$8:J19)-SUMIF(G$8:G19,G19,K$8:K19)+SUMIFS([1]内部转账!$G:$G,[1]内部转账!$C:$C,"<="&$D19,[1]内部转账!$E:$E,$G19)-SUMIFS([1]内部转账!$G:$G,[1]内部转账!$C:$C,"<="&$D19,[1]内部转账!$F:$F,$G19)),"") -> 50413.08 | M19: 温州盛为装饰工程有限公司
D20: 45329 | F20: 支出 | G20: 九江银行 | H20: 项目-劳务费 | I20: 张国平 | K20: 10000 | L20: =IFERROR(IF(G20="","",VLOOKUP($G20,[1]基础信息!$B:$C,2,FALSE)+SUMIF(G$8:G20,G20,J$8:J20)-SUMIF(G$8:G20,G20,K$8:K20)+SUMIFS([1]内部转账!$G:$G,[1]内部转账!$C:$C,"<="&$D20,[1]内部转账!$E:$E,$G20)-SUMIFS([1]内部转账!$G:$G,[1]内部转账!$C:$C,"<="&$D20,[1]内部转账!$F:$F,$G20)),"") -> 40413.08 | M20: 温州盛为装饰工程有限公司
D21: 45329 | F21: 支出 | G21: 九江银行 | H21: 项目-劳务费 | I21: 彭雪亮 | K21: 5000 | L21: =IFERROR(IF(G21="","",VLOOKUP($G21,[1]基础信息!$B:$C,2,FALSE)+SUMIF(G$8:G21,G21,J$8:J21)-SUMIF(G$8:G21,G21,K$8:K21)+SUMIFS([1]内部转账!$G:$G,[1]内部转账!$C:$C,"<="&$D21,[1]内部转账!$E:$E,$G21)-SUMIFS([1]内部转账!$G:$G,[1]内部转账!$C:$C,"<="&$D21,[1]内部转账!$F:$F,$G21)),"") -> 35413.08 | M21: 温州盛为装饰工程有限公司
D22: 45329 | F22: 支出 | G22: 九江银行 | H22: 项目-劳务费 | I22: 张启红 | K22: 7000 | L22: =IFERROR(IF(G22="","",VLOOKUP($G22,[1]基础信息!$B:$C,2,FALSE)+SUMIF(G$8:G22,G22,J$8:J22)-SUMIF(G$8:G22,G22,K$8:K22)+SUMIFS([1]内部转账!$G:$G,[1]内部转账!$C:$C,"<="&$D22,[1]内部转账!$E:$E,$G22)-SUMIFS([1]内部转账!$G:$G,[1]内部转账!$C:$C,"<="&$D22,[1]内部转账!$F:$F,$G22)),"") -> 28413.08 | M22: 温州盛为装饰工程有限公司
D23: 45329 | F23: 支出 | G23: 九江银行 | H23: 办公室-工资 | I23: 聂辉 | K23: 10000 | L23: =IFERROR(IF(G23="","",VLOOKUP($G23,[1]基础信息!$B:$C,2,FALSE)+SUMIF(G$8:G23,G23,J$8:J23)-SUMIF(G$8:G23,G23,K$8:K23)+SUMIFS([1]内部转账!$G:$G,[1]内部转账!$C:$C,"<="&$D23,[1]内部转账!$E:$E,$G23)-SUMIFS([1]内部转账!$G:$G,[1]内部转账!$C:$C,"<="&$D23,[1]内部转账!$F:$F,$G23)),"") -> 18413.08 | M23: 温州盛为装饰工程有限公司 | N23: 聂辉
D24: 45372 | F24: 支出 | G24: 九江银行 | H24: 办公室-办公费 | I24: 入息 | K24: -5.15 | L24: =IFERROR(IF(G24="","",VLOOKUP($G24,[1]基础信息!$B:$C,2,FALSE)+SUMIF(G$8:G24,G24,J$8:J24)-SUMIF(G$8:G24,G24,K$8:K24)+SUMIFS([1]内部转账!$G:$G,[1]内部转账!$C:$C,"<="&$D24,[1]内部转账!$E:$E,$G24)-SUMIFS([1]内部转账!$G:$G,[1]内部转账!$C:$C,"<="&$D24,[1]内部转账!$F:$F,$G24)),"") -> 18418.23 | M24: 办公室
D25: 45404 | F25: 支出 | G25: 九江银行 | H25: 办公室-办公费 | I25: 解伟康的赔款 | K25: -4000 | L25: =IFERROR(IF(G25="","",VLOOKUP($G25,[1]基础信息!$B:$C,2,FALSE)+SUMIF(G$8:G25,G25,J$8:J25)-SUMIF(G$8:G25,G25,K$8:K25)+SUMIFS([1]内部转账!$G:$G,[1]内部转账!$C:$C,"<="&$D25,[1]内部转账!$E:$E,$G25)-SUMIFS([1]内部转账!$G:$G,[1]内部转账!$C:$C,"<="&$D25,[1]内部转账!$F:$F,$G25)),"") -> 22418.23 | M25: 温州盛为装饰工程有限公司 | P25: 中国平安财产保险股份有限公司广东分公司
D26: 45426 | F26: 支出 | G26: 九江银行 | H26: 项目-劳务费 | I26: 张传喜奖金 | K26: 9200 | L26: =IFERROR(IF(G26="","",VLOOKUP($G26,[1]基础信息!$B:$C,2,FALSE)+SUMIF(G$8:G26,G26,J$8:J26)-SUMIF(G$8:G26,G26,K$8:K26)+SUMIFS([1]内部转账!$G:$G,[1]内部转账!$C:$C,"<="&$D26,[1]内部转账!$E:$E,$G26)-SUMIFS([1]内部转账!$G:$G,[1]内部转账!$C:$C,"<="&$D26,[1]内部转账!$F:$F,$G26)),"") -> 13218.23 | M26: 温州盛为装饰工程有限公司
D27: 45426 | F27: 支出 | G27: 九江银行 | H27: 项目-劳务费 | I27: 张小朋奖金 | K27: 9500 | L27: =IFERROR(IF(G27="","",VLOOKUP($G27,[1]基础信息!$B:$C,2,FALSE)+SUMIF(G$8:G27,G27,J$8:J27)-SUMIF(G$8:G27,G27,K$8:K27)+SUMIFS([1]内部转账!$G:$G,[1]内部转账!$C:$C,"<="&$D27,[1]内部转账!$E:$E,$G27)-SUMIFS([1]内部转账!$G:$G,[1]内部转账!$C:$C,"<="&$D27,[1]内部转账!$F:$F,$G27)),"") -> 3718.23 | M27: 温州盛为装饰工程有限公司 | P27: 张小朋
D28: 45429 | F28: 支出 | G28: 九江银行 | H28: 项目-期间费 | I28: 支付保险费 | K28: 2310 | L28: =IFERROR(IF(G28="","",VLOOKUP($G28,[1]基础信息!$B:$C,2,FALSE)+SUMIF(G$8:G28,G28,J$8:J28)-SUMIF(G$8:G28,G28,K$8:K28)+SUMIFS([1]内部转账!$G:$G,[1]内部转账!$C:$C,"<="&$D28,[1]内部转账!$E:$E,$G28)-SUMIFS([1]内部转账!$G:$G,[1]内部转账!$C:$C,"<="&$D28,[1]内部转账!$F:$F,$G28)),"") -> 1408.23 | M28: 隆世光伏/共青办公楼/德祥工地 | P28: 中国平安财产保险股份有限公司广东分公司
D29: 45449 | F29: 收入 | G29: 九江银行 | H29: 工程款 | I29: 隆世光伏/共青办公楼/德祥工地工程款 | J29: 300000 | L29: =IFERROR(IF(G29="","",VLOOKUP($G29,[1]基础信息!$B:$C,2,FALSE)+SUMIF(G$8:G29,G29,J$8:J29)-SUMIF(G$8:G29,G29,K$8:K29)+SUMIFS([1]内部转账!$G:$G,[1]内部转账!$C:$C,"<="&$D29,[1]内部转账!$E:$E,$G29)-SUMIFS([1]内部转账!$G:$G,[1]内部转账!$C:$C,"<="&$D29,[1]内部转账!$F:$F,$G29)),"") -> 301408.23 | M29: 隆世光伏/共青办公楼/德祥工地 | O29: 共青农商行
D30: 45449 | F30: 支出 | G30: 九江银行 | H30: 项目-材料费 | I30: 付熊总材料费 | K30: 5146 | L30: =IFERROR(IF(G30="","",VLOOKUP($G30,[1]基础信息!$B:$C,2,FALSE)+SUMIF(G$8:G30,G30,J$8:J30)-SUMIF(G$8:G30,G30,K$8:K30)+SUMIFS([1]内部转账!$G:$G,[1]内部转账!$C:$C,"<="&$D30,[1]内部转账!$E:$E,$G30)-SUMIFS([1]内部转账!$G:$G,[1]内部转账!$C:$C,"<="&$D30,[1]内部转账!$F:$F,$G30)),"") -> 296262.23 | M30: 隆世光伏/共青办公楼/德祥工地 | P30: 德安小熊平价钢材店
D31: 45449 | F31: 支出 | G31: 九江银行 | H31: 项目-材料费 | I31: 付熊总材料费 | K31: -5146 | L31: =IFERROR(IF(G31="","",VLOOKUP($G31,[1]基础信息!$B:$C,2,FALSE)+SUMIF(G$8:G31,G31,J$8:J31)-SUMIF(G$8:G31,G31,K$8:K31)+SUMIFS([1]内部转账!$G:$G,[1]内部转账!$C:$C,"<="&$D31,[1]内部转账!$E:$E,$G31)-SUMIFS([1]内部转账!$G:$G,[1]内部转账!$C:$C,"<="&$D31,[1]内部转账!$F:$F,$G31)),"") -> 301408.23 | M31: 隆世光伏/共青办公楼/德祥工地 | P31: 德安小熊平价钢材店
D32: 45449 | F32: 支出 | G32: 九江银行 | H32: 项目-材料费 | I32: 付熊总材料费 | K32: 5146 | L32: =IFERROR(IF(G32="","",VLOOKUP($G32,[1]基础信息!$B:$C,2,FALSE)+SUMIF(G$8:G32,G32,J$8:J32)-SUMIF(G$8:G32,G32,K$8:K32)+SUMIFS([1]内部转账!$G:$G,[1]内部转账!$C:$C,"<="&$D32,[1]内部转账!$E:$E,$G32)-SUMIFS([1]内部转账!$G:$G,[1]内部转账!$C:$C,"<="&$D32,[1]内部转账!$F:$F,$G32)),"") -> 296262.23 | M32: 隆世光伏/共青办公楼/德祥工地 | P32: 德安小熊平价钢材店
D33: 45449 | F33: 支出 | G33: 九江银行 | H33: 项目-材料费 | I33: 付熊总材料费 | K33: 130000 | L33: =IFERROR(IF(G33="","",VLOOKUP($G33,[1]基础信息!$B:$C,2,FALSE)+SUMIF(G$8:G33,G33,J$8:J33)-SUMIF(G$8:G33,G33,K$8:K33)+SUMIFS([1]内部转账!$G:$G,[1]内部转账!$C:$C,"<="&$D33,[1]内部转账!$E:$E,$G33)-SUMIFS([1]内部转账!$G:$G,[1]内部转账!$C:$C,"<="&$D33,[1]内部转账!$F:$F,$G33)),"") -> 166262.23 | M33: 隆世光伏/共青办公楼/德祥工地 | P33: 德安小熊平价钢材店
D34: 45449 | F34: 支出 | G34: 九江银行 | H34: 项目-材料费 | I34: 付熊总材料费 | K34: 20000 | L34: =IFERROR(IF(G34="","",VLOOKUP($G34,[1]基础信息!$B:$C,2,FALSE)+SUMIF(G$8:G34,G34,J$8:J34)-SUMIF(G$8:G34,G34,K$8:K34)+SUMIFS([1]内部转账!$G:$G,[1]内部转账!$C:$C,"<="&$D34,[1]内部转账!$E:$E,$G34)-SUMIFS([1]内部转账!$G:$G,[1]内部转账!$C:$C,"<="&$D34,[1]内部转账!$F:$F,$G34)),"") -> 146262.23 | M34: 隆世光伏/共青办公楼/德祥工地 | P34: 德安小熊平价钢材店
D35: 45451 | F35: 支出 | G35: 九江银行 | H35: 项目-劳务费 | I35: 叶焰平 | K35: 5000 | L35: =IFERROR(IF(G35="","",VLOOKUP($G35,[1]基础信息!$B:$C,2,FALSE)+SUMIF(G$8:G35,G35,J$8:J35)-SUMIF(G$8:G35,G35,K$8:K35)+SUMIFS([1]内部转账!$G:$G,[1]内部转账!$C:$C,"<="&$D35,[1]内部转账!$E:$E,$G35)-SUMIFS([1]内部转账!$G:$G,[1]内部转账!$C:$C,"<="&$D35,[1]内部转账!$F:$F,$G35)),"") -> 141262.23 | M35: 隆世光伏/共青办公楼/德祥工地
D36: 45451 | F36: 支出 | G36: 九江银行 | H36: 项目-劳务费 | I36: 何正拥 | K36: 5000 | L36: =IFERROR(IF(G36="","",VLOOKUP($G36,[1]基础信息!$B:$C,2,FALSE)+SUMIF(G$8:G36,G36,J$8:J36)-SUMIF(G$8:G36,G36,K$8:K36)+SUMIFS([1]内部转账!$G:$G,[1]内部转账!$C:$C,"<="&$D36,[1]内部转账!$E:$E,$G36)-SUMIFS([1]内部转账!$G:$G,[1]内部转账!$C:$C,"<="&$D36,[1]内部转账!$F:$F,$G36)),"") -> 136262.23 | M36: 隆世光伏/共青办公楼/德祥工地
D37: 45451 | F37: 支出 | G37: 九江银行 | H37: 项目-劳务费 | I37: 李金平 | K37: 5000 | L37: =IFERROR(IF(G37="","",VLOOKUP($G37,[1]基础信息!$B:$C,2,FALSE)+SUMIF(G$8:G37,G37,J$8:J37)-SUMIF(G$8:G37,G37,K$8:K37)+SUMIFS([1]内部转账!$G:$G,[1]内部转账!$C:$C,"<="&$D37,[1]内部转账!$E:$E,$G37)-SUMIFS([1]内部转账!$G:$G,[1]内部转账!$C:$C,"<="&$D37,[1]内部转账!$F:$F,$G37)),"") -> 131262.23 | M37: 隆世光伏/共青办公楼/德祥工地
D38: 45451 | F38: 支出 | G38: 九江银行 | H38: 项目-劳务费 | I38: 李金平 | K38: -5000 | L38: =IFERROR(IF(G38="","",VLOOKUP($G38,[1]基础信息!$B:$C,2,FALSE)+SUMIF(G$8:G38,G38,J$8:J38)-SUMIF(G$8:G38,G38,K$8:K38)+SUMIFS([1]内部转账!$G:$G,[1]内部转账!$C:$C,"<="&$D38,[1]内部转账!$E:$E,$G38)-SUMIFS([1]内部转账!$G:$G,[1]内部转账!$C:$C,"<="&$D38,[1]内部转账!$F:$F,$G38)),"") -> 136262.23 | M38: 隆世光伏/共青办公楼/德祥工地
D39: 45451 | F39: 支出 | G39: 九江银行 | H39: 项目-劳务费 | I39: 吴志刚 | K39: 5000 | L39: =IFERROR(IF(G39="","",VLOOKUP($G39,[1]基础信息!$B:$C,2,FALSE)+SUMIF(G$8:G39,G39,J$8:J39)-SUMIF(G$8:G39,G39,K$8:K39)+SUMIFS([1]内部转账!$G:$G,[1]内部转账!$C:$C,"<="&$D39,[1]内部转账!$E:$E,$G39)-SUMIFS([1]内部转账!$G:$G,[1]内部转账!$C:$C,"<="&$D39,[1]内部转账!$F:$F,$G39)),"") -> 131262.23 | M39: 隆世光伏/共青办公楼/德祥工地
D40: 45451 | F40: 支出 | G40: 九江银行 | H40: 项目-劳务费 | I40: 成峰 | K40: 5000 | L40: =IFERROR(IF(G40="","",VLOOKUP($G40,[1]基础信息!$B:$C,2,FALSE)+SUMIF(G$8:G40,G40,J$8:J40)-SUMIF(G$8:G40,G40,K$8:K40)+SUMIFS([1]内部转账!$G:$G,[1]内部转账!$C:$C,"<="&$D40,[1]内部转账!$E:$E,$G40)-SUMIFS([1]内部转账!$G:$G,[1]内部转账!$C:$C,"<="&$D40,[1]内部转账!$F:$F,$G40)),"") -> 126262.23 | M40: 隆世光伏/共青办公楼/德祥工地
D41: 45451 | F41: 支出 | G41: 九江银行 | H41: 项目-劳务费 | I41: 何正辉 | K41: 5000 | L41: =IFERROR(IF(G41="","",VLOOKUP($G41,[1]基础信息!$B:$C,2,FALSE)+SUMIF(G$8:G41,G41,J$8:J41)-SUMIF(G$8:G41,G41,K$8:K41)+SUMIFS([1]内部转账!$G:$G,[1]内部转账!$C:$C,"<="&$D41,[1]内部转账!$E:$E,$G41)-SUMIFS([1]内部转账!$G:$G,[1]内部转账!$C:$C,"<="&$D41,[1]内部转账!$F:$F,$G41)),"") -> 121262.23 | M41: 隆世光伏/共青办公楼/德祥工地
D42: 45451 | F42: 支出 | G42: 九江银行 | H42: 项目-劳务费 | I42: 梅时金 | K42: 5000 | L42: =IFERROR(IF(G42="","",VLOOKUP($G42,[1]基础信息!$B:$C,2,FALSE)+SUMIF(G$8:G42,G42,J$8:J42)-SUMIF(G$8:G42,G42,K$8:K42)+SUMIFS([1]内部转账!$G:$G,[1]内部转账!$C:$C,"<="&$D42,[1]内部转账!$E:$E,$G42)-SUMIFS([1]内部转账!$G:$G,[1]内部转账!$C:$C,"<="&$D42,[1]内部转账!$F:$F,$G42)),"") -> 116262.23 | M42: 隆世光伏/共青办公楼/德祥工地
D43: 45451 | F43: 支出 | G43: 九江银行 | H43: 项目-劳务费 | I43: 余水明 | K43: 1500 | L43: =IFERROR(IF(G43="","",VLOOKUP($G43,[1]基础信息!$B:$C,2,FALSE)+SUMIF(G$8:G43,G43,J$8:J43)-SUMIF(G$8:G43,G43,K$8:K43)+SUMIFS([1]内部转账!$G:$G,[1]内部转账!$C:$C,"<="&$D43,[1]内部转账!$E:$E,$G43)-SUMIFS([1]内部转账!$G:$G,[1]内部转账!$C:$C,"<="&$D43,[1]内部转账!$F:$F,$G43)),"") -> 114762.23 | M43: 隆世光伏/共青办公楼/德祥工地
D44: 45451 | F44: 支出 | G44: 九江银行 | H44: 项目-劳务费 | I44: 李银华 | K44: 5000 | L44: =IFERROR(IF(G44="","",VLOOKUP($G44,[1]基础信息!$B:$C,2,FALSE)+SUMIF(G$8:G44,G44,J$8:J44)-SUMIF(G$8:G44,G44,K$8:K44)+SUMIFS([1]内部转账!$G:$G,[1]内部转账!$C:$C,"<="&$D44,[1]内部转账!$E:$E,$G44)-SUMIFS([1]内部转账!$G:$G,[1]内部转账!$C:$C,"<="&$D44,[1]内部转账!$F:$F,$G44)),"") -> 109762.23 | M44: 隆世光伏/共青办公楼/德祥工地
...
