Workbook

Sheet 基本信息表
A1: 机械工种 | B1: 单价
A2: 轮挖斗 | B2: 150
A3: 炮头 | B3: 250

Sheet Sheet1
A1: 机械工作费用明细表 | T1: 应付金额 | U1: 已付金额 | V1: 剩余金额
A2: 日期 | B2: 项目名称 | C2: 供应商名称 | D2: 机械种类 | E2: 单价 | F2: 上午时间 | G2: 下午时间 | H2: 工作时长 （时间） | I2: 工作时长 （小时） | J2: 应付金额 （元） | K2: 已付金额 （元） | L2: 付款日期 | M2: 付款账户 | N2: 已开票金额 | O2: 税率 | P2: 税额 | Q2: 备注2 | T2: =SUBTOTAL(9,J:J) -> 105775 | U2: =SUBTOTAL(9,K:K) -> 35000 | V2: =T2-U2 -> 70775
A3: 45942 | B3: 科创中心 | C3: 杨工轮挖 | D3: 轮挖斗 | E3: {=IFERROR(VLOOKUP(D3,基本信息表!A:B,{2},FALSE),"")} -> 150 | G3: 13:00-17:30 | H3: {=NPV(-2,--_xlfn.TEXTSPLIT(_xlfn.TEXTJOIN("-",,F3:G3),"-"))} -> 0.1875 | I3: =H3*24 -> 4.5 | J3: =E3*I3 -> 675 | K3: 5000 | L3: 45971 | M3: 九江银行 | N3: 5000 | O3: 0.01 | P3: =N3/(1+O3)*O3 -> 49.50495 | R3: 0.13
A4: 45943 | B4: 科创中心 | C4: 杨工轮挖 | D4: 轮挖斗 | E4: {=IFERROR(VLOOKUP(D4,基本信息表!A:B,{2},FALSE),"")} -> 150 | F4: 7:00-11:30 | G4: 13:00-17:30 | H4: {=NPV(-2,--_xlfn.TEXTSPLIT(_xlfn.TEXTJOIN("-",,F4:G4),"-"))} -> 0.375 | I4: =H4*24 -> 9 | J4: =E4*I4 -> 1350 | K4: 30000 | M4: 王伟垫付 | P4: =N4/(1+O4)*O4 -> 0 | R4: 0.09 | T4: 杨工 | U4: =T2-U5 -> 98875
A5: 45944 | B5: 科创中心 | C5: 杨工轮挖 | D5: 轮挖斗 | E5: {=IFERROR(VLOOKUP(D5,基本信息表!A:B,{2},FALSE),"")} -> 150 | F5: 7:00-11:30 | H5: {=NPV(-2,--_xlfn.TEXTSPLIT(_xlfn.TEXTJOIN("-",,F5:G5),"-"))} -> 0.1875 | I5: =H5*24 -> 4.5 | J5: =E5*I5 -> 675 | P5: =N5/(1+O5)*O5 -> 0 | R5: 0.06 | T5: 徐工 | U5: 6900
A6: 45946 | B6: 科创中心 | C6: 杨工轮挖 | D6: 轮挖斗 | E6: {=IFERROR(VLOOKUP(D6,基本信息表!A:B,{2},FALSE),"")} -> 150 | G6: 13:00-17:30 | H6: {=NPV(-2,--_xlfn.TEXTSPLIT(_xlfn.TEXTJOIN("-",,F6:G6),"-"))} -> 0.1875 | I6: =H6*24 -> 4.5 | J6: =E6*I6 -> 675 | P6: =N6/(1+O6)*O6 -> 0 | R6: 0.03
A7: 45947 | B7: 科创中心 | C7: 杨工轮挖 | D7: 轮挖斗 | E7: {=IFERROR(VLOOKUP(D7,基本信息表!A:B,{2},FALSE),"")} -> 150 | F7: 7:00-11:30 | G7: 13:00-17:30 | H7: {=NPV(-2,--_xlfn.TEXTSPLIT(_xlfn.TEXTJOIN("-",,F7:G7),"-"))} -> 0.375 | I7: =H7*24 -> 9 | J7: =E7*I7 -> 1350 | P7: =N7/(1+O7)*O7 -> 0 | R7: 0.01
A8: 45948 | B8: 科创中心 | C8: 杨工轮挖 | D8: 轮挖斗 | E8: {=IFERROR(VLOOKUP(D8,基本信息表!A:B,{2},FALSE),"")} -> 150 | F8: 7:00-11:30 | G8: 13:00-17:30 | H8: {=NPV(-2,--_xlfn.TEXTSPLIT(_xlfn.TEXTJOIN("-",,F8:G8),"-"))} -> 0.375 | I8: =H8*24 -> 9 | J8: =E8*I8 -> 1350 | P8: =N8/(1+O8)*O8 -> 0
A9: 45949 | B9: 科创中心 | C9: 杨工轮挖 | D9: 轮挖斗 | E9: {=IFERROR(VLOOKUP(D9,基本信息表!A:B,{2},FALSE),"")} -> 150 | F9: 7:00-11:30 | H9: {=NPV(-2,--_xlfn.TEXTSPLIT(_xlfn.TEXTJOIN("-",,F9:G9),"-"))} -> 0.1875 | I9: =H9*24 -> 4.5 | J9: =E9*I9 -> 675 | P9: =N9/(1+O9)*O9 -> 0
A10: 45950 | B10: 科创中心 | C10: 杨工轮挖 | D10: 轮挖斗 | E10: {=IFERROR(VLOOKUP(D10,基本信息表!A:B,{2},FALSE),"")} -> 150 | F10: 7:00-11:30 | G10: 13:00-17:30 | H10: {=NPV(-2,--_xlfn.TEXTSPLIT(_xlfn.TEXTJOIN("-",,F10:G10),"-"))} -> 0.375 | I10: =H10*24 -> 9 | J10: =E10*I10 -> 1350 | P10: =N10/(1+O10)*O10 -> 0
A11: 45951 | B11: 科创中心 | C11: 杨工轮挖 | D11: 轮挖斗 | E11: {=IFERROR(VLOOKUP(D11,基本信息表!A:B,{2},FALSE),"")} -> 150 | F11: 7:00-11:30 | G11: 13:00-17:30 | H11: {=NPV(-2,--_xlfn.TEXTSPLIT(_xlfn.TEXTJOIN("-",,F11:G11),"-"))} -> 0.375 | I11: =H11*24 -> 9 | J11: =E11*I11 -> 1350 | P11: =N11/(1+O11)*O11 -> 0
A12: 45952 | B12: 科创中心 | C12: 杨工轮挖 | D12: 轮挖斗 | E12: {=IFERROR(VLOOKUP(D12,基本信息表!A:B,{2},FALSE),"")} -> 150 | F12: 7:00-11:30 | G12: 13:00-17:30 | H12: {=NPV(-2,--_xlfn.TEXTSPLIT(_xlfn.TEXTJOIN("-",,F12:G12),"-"))} -> 0.375 | I12: =H12*24 -> 9 | J12: =E12*I12 -> 1350 | P12: =N12/(1+O12)*O12 -> 0
A13: 45953 | B13: 科创中心 | C13: 杨工轮挖 | D13: 轮挖斗 | E13: {=IFERROR(VLOOKUP(D13,基本信息表!A:B,{2},FALSE),"")} -> 150 | F13: 7:00-11:30 | G13: 13:00-17:30 | H13: {=NPV(-2,--_xlfn.TEXTSPLIT(_xlfn.TEXTJOIN("-",,F13:G13),"-"))} -> 0.375 | I13: =H13*24 -> 9 | J13: =E13*I13 -> 1350 | P13: =N13/(1+O13)*O13 -> 0
A14: 45954 | B14: 科创中心 | C14: 杨工轮挖 | D14: 轮挖斗 | E14: {=IFERROR(VLOOKUP(D14,基本信息表!A:B,{2},FALSE),"")} -> 150 | F14: 7:00-11:30 | G14: 13:00-17:30 | H14: {=NPV(-2,--_xlfn.TEXTSPLIT(_xlfn.TEXTJOIN("-",,F14:G14),"-"))} -> 0.375 | I14: =H14*24 -> 9 | J14: =E14*I14 -> 1350 | P14: =N14/(1+O14)*O14 -> 0
A15: 45955 | B15: 科创中心 | C15: 杨工轮挖 | D15: 轮挖斗 | E15: {=IFERROR(VLOOKUP(D15,基本信息表!A:B,{2},FALSE),"")} -> 150 | F15: 7:00-11:30 | G15: 13:00-17:30 | H15: {=NPV(-2,--_xlfn.TEXTSPLIT(_xlfn.TEXTJOIN("-",,F15:G15),"-"))} -> 0.375 | I15: =H15*24 -> 9 | J15: =E15*I15 -> 1350 | P15: =N15/(1+O15)*O15 -> 0
A16: 45956 | B16: 科创中心 | C16: 杨工轮挖 | D16: 轮挖斗 | E16: {=IFERROR(VLOOKUP(D16,基本信息表!A:B,{2},FALSE),"")} -> 150 | F16: 7:00-11:30 | G16: 13:00-17:30 | H16: {=NPV(-2,--_xlfn.TEXTSPLIT(_xlfn.TEXTJOIN("-",,F16:G16),"-"))} -> 0.375 | I16: =H16*24 -> 9 | J16: =E16*I16 -> 1350 | P16: =N16/(1+O16)*O16 -> 0
A17: 45957 | B17: 科创中心 | C17: 杨工轮挖 | D17: 轮挖斗 | E17: {=IFERROR(VLOOKUP(D17,基本信息表!A:B,{2},FALSE),"")} -> 150 | F17: 7:00-11:30 | G17: 13:00-17:30 | H17: {=NPV(-2,--_xlfn.TEXTSPLIT(_xlfn.TEXTJOIN("-",,F17:G17),"-"))} -> 0.375 | I17: =H17*24 -> 9 | J17: =E17*I17 -> 1350 | P17: =N17/(1+O17)*O17 -> 0
A18: 45958 | B18: 科创中心 | C18: 杨工轮挖 | D18: 轮挖斗 | E18: {=IFERROR(VLOOKUP(D18,基本信息表!A:B,{2},FALSE),"")} -> 150 | F18: 7:00-11:30 | G18: 13:00-17:30 | H18: {=NPV(-2,--_xlfn.TEXTSPLIT(_xlfn.TEXTJOIN("-",,F18:G18),"-"))} -> 0.375 | I18: =H18*24 -> 9 | J18: =E18*I18 -> 1350 | P18: =N18/(1+O18)*O18 -> 0
A19: 45959 | B19: 科创中心 | C19: 杨工轮挖 | D19: 轮挖斗 | E19: {=IFERROR(VLOOKUP(D19,基本信息表!A:B,{2},FALSE),"")} -> 150 | F19: 7:00-11:30 | G19: 13:00-17:30 | H19: {=NPV(-2,--_xlfn.TEXTSPLIT(_xlfn.TEXTJOIN("-",,F19:G19),"-"))} -> 0.375 | I19: =H19*24 -> 9 | J19: =E19*I19 -> 1350 | P19: =N19/(1+O19)*O19 -> 0
A20: 45961 | B20: 科创中心 | C20: 杨工轮挖 | D20: 轮挖斗 | E20: {=IFERROR(VLOOKUP(D20,基本信息表!A:B,{2},FALSE),"")} -> 150 | F20: 7:00-11:30 | G20: 13:00-17:30 | H20: {=NPV(-2,--_xlfn.TEXTSPLIT(_xlfn.TEXTJOIN("-",,F20:G20),"-"))} -> 0.375 | I20: =H20*24 -> 9 | J20: =E20*I20 -> 1350 | P20: =N20/(1+O20)*O20 -> 0
A21: 45962 | B21: 科创中心 | C21: 杨工轮挖 | D21: 轮挖斗 | E21: {=IFERROR(VLOOKUP(D21,基本信息表!A:B,{2},FALSE),"")} -> 150 | F21: 7:00-11:30 | G21: 13:00-17:30 | H21: {=NPV(-2,--_xlfn.TEXTSPLIT(_xlfn.TEXTJOIN("-",,F21:G21),"-"))} -> 0.375 | I21: =H21*24 -> 9 | J21: =E21*I21 -> 1350 | P21: =N21/(1+O21)*O21 -> 0
... A24: 45965 | B24: 科创中心 | C24: 杨工轮挖 | D24: 轮挖斗 | E24: {=IFERROR(VLOOKUP(D24,基本信息表!A:B,{2},FALSE),"")} -> 150 | F24: 7:00-11:30 | G24: 13:00-17:30 | H24: {=NPV(-2,--_xlfn.TEXTSPLIT(_xlfn.TEXTJOIN("-",,F24:G24),"-"))} -> 0.375 | I24: =H24*24 -> 9 | J24: =E24*I24 -> 1350 | P24: =N24/(1+O24)*O24 -> 0
A25: 45966 | B25: 科创中心 | C25: 杨工轮挖 | D25: 轮挖斗 | E25: {=IFERROR(VLOOKUP(D25,基本信息表!A:B,{2},FALSE),"")} -> 150 | F25: 7:00-10:00 | H25: {=NPV(-2,--_xlfn.TEXTSPLIT(_xlfn.TEXTJOIN("-",,F25:G25),"-"))} -> 0.125 | I25: =H25*24 -> 3 | J25: =E25*I25 -> 450 | P25: =N25/(1+O25)*O25 -> 0
A26: 45973 | B26: 科创中心 | C26: 杨工轮挖 | D26: 轮挖斗 | E26: {=IFERROR(VLOOKUP(D26,基本信息表!A:B,{2},FALSE),"")} -> 150 | F26: 9:30-11:30 | G26: 13:00-17:30 | H26: {=NPV(-2,--_xlfn.TEXTSPLIT(_xlfn.TEXTJOIN("-",,F26:G26),"-"))} -> 0.27083333 | I26: =H26*24 -> 6.5 | J26: =E26*I26 -> 975 | P26: =N26/(1+O26)*O26 -> 0
A27: 45974 | B27: 科创中心 | C27: 杨工轮挖 | D27: 轮挖斗 | E27: {=IFERROR(VLOOKUP(D27,基本信息表!A:B,{2},FALSE),"")} -> 150 | F27: 7:00-11:30 | G27: 13:00-17:30 | H27: {=NPV(-2,--_xlfn.TEXTSPLIT(_xlfn.TEXTJOIN("-",,F27:G27),"-"))} -> 0.375 | I27: =H27*24 -> 9 | J27: =E27*I27 -> 1350 | P27: =N27/(1+O27)*O27 -> 0
A28: 45975 | B28: 科创中心 | C28: 杨工轮挖 | D28: 轮挖斗 | E28: {=IFERROR(VLOOKUP(D28,基本信息表!A:B,{2},FALSE),"")} -> 150 | F28: 7:00-11:30 | G28: 13:00-17:30 | H28: {=NPV(-2,--_xlfn.TEXTSPLIT(_xlfn.TEXTJOIN("-",,F28:G28),"-"))} -> 0.375 | I28: =H28*24 -> 9 | J28: =E28*I28 -> 1350 | P28: =N28/(1+O28)*O28 -> 0
A29: 45976 | B29: 科创中心 | C29: 杨工轮挖 | D29: 轮挖斗 | E29: {=IFERROR(VLOOKUP(D29,基本信息表!A:B,{2},FALSE),"")} -> 150 | F29: 7:00-11:30 | G29: 13:00-17:30 | H29: {=NPV(-2,--_xlfn.TEXTSPLIT(_xlfn.TEXTJOIN("-",,F29:G29),"-"))} -> 0.375 | I29: =H29*24 -> 9 | J29: =E29*I29 -> 1350 | P29: =N29/(1+O29)*O29 -> 0
A30: 45977 | B30: 科创中心 | C30: 杨工轮挖 | D30: 轮挖斗 | E30: {=IFERROR(VLOOKUP(D30,基本信息表!A:B,{2},FALSE),"")} -> 150 | F30: 7:00-11:30 | G30: 13:00-17:30 | H30: {=NPV(-2,--_xlfn.TEXTSPLIT(_xlfn.TEXTJOIN("-",,F30:G30),"-"))} -> 0.375 | I30: =H30*24 -> 9 | J30: =E30*I30 -> 1350 | P30: =N30/(1+O30)*O30 -> 0
A31: 45978 | B31: 科创中心 | C31: 杨工轮挖 | D31: 轮挖斗 | E31: {=IFERROR(VLOOKUP(D31,基本信息表!A:B,{2},FALSE),"")} -> 150 | F31: 7:00-11:30 | G31: 13:00-17:30 | H31: {=NPV(-2,--_xlfn.TEXTSPLIT(_xlfn.TEXTJOIN("-",,F31:G31),"-"))} -> 0.375 | I31: =H31*24 -> 9 | J31: =E31*I31 -> 1350 | P31: =N31/(1+O31)*O31 -> 0
A32: 45979 | B32: 科创中心 | C32: 杨工轮挖 | D32: 轮挖斗 | E32: {=IFERROR(VLOOKUP(D32,基本信息表!A:B,{2},FALSE),"")} -> 150 | F32: 7:00-11:30 | G32: 13:00-17:30 | H32: {=NPV(-2,--_xlfn.TEXTSPLIT(_xlfn.TEXTJOIN("-",,F32:G32),"-"))} -> 0.375 | I32: =H32*24 -> 9 | J32: =E32*I32 -> 1350 | P32: =N32/(1+O32)*O32 -> 0
A33: 45980 | B33: 科创中心 | C33: 杨工轮挖 | D33: 轮挖斗 | E33: {=IFERROR(VLOOKUP(D33,基本信息表!A:B,{2},FALSE),"")} -> 150 | F33: 7:00-11:30 | G33: 13:00-17:00 | H33: {=NPV(-2,--_xlfn.TEXTSPLIT(_xlfn.TEXTJOIN("-",,F33:G33),"-"))} -> 0.35416667 | I33: =H33*24 -> 8.5 | J33: =E33*I33 -> 1275 | P33: =N33/(1+O33)*O33 -> 0
A34: 45982 | B34: 科创中心 | C34: 杨工轮挖 | D34: 轮挖斗 | E34: {=IFERROR(VLOOKUP(D34,基本信息表!A:B,{2},FALSE),"")} -> 150 | F34: 7:00-11:30 | G34: 13:00-17:30 | H34: {=NPV(-2,--_xlfn.TEXTSPLIT(_xlfn.TEXTJOIN("-",,F34:G34),"-"))} -> 0.375 | I34: =H34*24 -> 9 | J34: =E34*I34 -> 1350 | P34: =N34/(1+O34)*O34 -> 0
A35: 45984 | B35: 科创中心 | C35: 杨工轮挖 | D35: 轮挖斗 | E35: {=IFERROR(VLOOKUP(D35,基本信息表!A:B,{2},FALSE),"")} -> 150 | F35: 7:00-11:30 | H35: {=NPV(-2,--_xlfn.TEXTSPLIT(_xlfn.TEXTJOIN("-",,F35:G35),"-"))} -> 0.1875 | I35: =H35*24 -> 4.5 | J35: =E35*I35 -> 675 | P35: =N35/(1+O35)*O35 -> 0
A36: 45985 | B36: 科创中心 | C36: 杨工轮挖 | D36: 轮挖斗 | E36: {=IFERROR(VLOOKUP(D36,基本信息表!A:B,{2},FALSE),"")} -> 150 | G36: 13:00-17:30 | H36: {=NPV(-2,--_xlfn.TEXTSPLIT(_xlfn.TEXTJOIN("-",,F36:G36),"-"))} -> 0.1875 | I36: =H36*24 -> 4.5 | J36: =E36*I36 -> 675 | P36: =N36/(1+O36)*O36 -> 0
A37: 45986 | B37: 科创中心 | C37: 杨工轮挖 | D37: 轮挖斗 | E37: {=IFERROR(VLOOKUP(D37,基本信息表!A:B,{2},FALSE),"")} -> 150 | F37: 7:00-11:30 | G37: 13:00-17:30 | H37: {=NPV(-2,--_xlfn.TEXTSPLIT(_xlfn.TEXTJOIN("-",,F37:G37),"-"))} -> 0.375 | I37: =H37*24 -> 9 | J37: =E37*I37 -> 1350 | P37: =N37/(1+O37)*O37 -> 0
A38: 45987 | B38: 科创中心 | C38: 杨工轮挖 | D38: 轮挖斗 | E38: {=IFERROR(VLOOKUP(D38,基本信息表!A:B,{2},FALSE),"")} -> 150 | F38: 7:00-11:30 | G38: 13:00-17:30 | H38: {=NPV(-2,--_xlfn.TEXTSPLIT(_xlfn.TEXTJOIN("-",,F38:G38),"-"))} -> 0.375 | I38: =H38*24 -> 9 | J38: =E38*I38 -> 1350 | P38: =N38/(1+O38)*O38 -> 0
A39: 45988 | B39: 科创中心 | C39: 杨工轮挖 | D39: 轮挖斗 | E39: {=IFERROR(VLOOKUP(D39,基本信息表!A:B,{2},FALSE),"")} -> 150 | F39: 7:00-11:30 | G39: 13:00-17:30 | H39: {=NPV(-2,--_xlfn.TEXTSPLIT(_xlfn.TEXTJOIN("-",,F39:G39),"-"))} -> 0.375 | I39: =H39*24 -> 9 | J39: =E39*I39 -> 1350 | P39: =N39/(1+O39)*O39 -> 0
A40: 45989 | B40: 科创中心 | C40: 杨工轮挖 | D40: 轮挖斗 | E40: {=IFERROR(VLOOKUP(D40,基本信息表!A:B,{2},FALSE),"")} -> 150 | F40: 7:00-10:00 | H40: {=NPV(-2,--_xlfn.TEXTSPLIT(_xlfn.TEXTJOIN("-",,F40:G40),"-"))} -> 0.125 | I40: =H40*24 -> 3 | J40: =E40*I40 -> 450 | P40: =N40/(1+O40)*O40 -> 0
A41: 45991 | B41: 科创中心 | C41: 杨工轮挖 | D41: 轮挖斗 | E41: {=IFERROR(VLOOKUP(D41,基本信息表!A:B,{2},FALSE),"")} -> 150 | F41: 7:00-11:30 | G41: 13:30-17:30 | H41: {=NPV(-2,--_xlfn.TEXTSPLIT(_xlfn.TEXTJOIN("-",,F41:G41),"-"))} -> 0.35416667 | I41: =H41*24 -> 8.5 | J41: =E41*I41 -> 1275 | P41: =N41/(1+O41)*O41 -> 0
A42: 45992 | B42: 科创中心 | C42: 杨工轮挖 | D42: 轮挖斗 | E42: {=IFERROR(VLOOKUP(D42,基本信息表!A:B,{2},FALSE),"")} -> 150 | F42: 7:00-11:30 | G42: 13:00-16:00 | H42: {=NPV(-2,--_xlfn.TEXTSPLIT(_xlfn.TEXTJOIN("-",,F42:G42),"-"))} -> 0.3125 | I42: =H42*24 -> 7.5 | J42: =E42*I42 -> 1125 | P42: =N42/(1+O42)*O42 -> 0
...

Sheet Sheet3
A1: 机械费汇总表 | B1: 机械+运输费用汇总表 | O1: {=_xlfn.PIVOTBY(_xlfn._TRO_TRAILING(C2:C999),,_xlfn._TRO_TRAILING(D2:E999),_xleta.SUM,3)} -> 项目名称 | P1: 应付金额 | Q1: 已付金额 | R1: 未付金额
A2: 日期 | B2: 挖机班组/（运输）名称 | C2: 项目名称 | D2: 应付金额 | E2: 已付金额 | F2: 付款日期 | G2: 付款账户 | H2: 收款账户 | I2: 已开票金额 | J2: 开票日期 | K2: 税率 | L2: 税额 | M2: 备注2 | O2: 德安农商行总部 | P2: 800 | Q2: 800 | R2: =P2-Q2 -> 0
A3: 25/11-26/1 | B3: 杨工 | C3: 科创中心 | D3: 98875 | E3: 30000 | G3: 王伟垫付 | O3: 科创中心 | P3: 105775 | Q3: 35000 | R3: =P3-Q3 -> 70775
A4: 25/11-26/1 | B4: 徐工 | C4: 科创中心 | D4: 6900 | E4: 5000 | F4: 45971 | G4: 九江银行 | H4: 九江翌年行建筑工程劳务有限公司 | I4: 5000 | K4: 0.01 | O4: 邹桥派出所 | P4: 1280 | Q4: 1280 | R4: =P4-Q4 -> 0
A5: 46174 | B5: 德安县恒建工程部 | C5: 德安农商行总部 | D5: 800 | E5: 800 | F5: 46205 | G5: 九江银行 | H5: 舒文龙 | I5: 800 | K5: 0.01 | O5: 总计 | P5: 107855 | Q5: 37080
A6: 46173 | B6: 航帆增辉 | C6: 邹桥派出所 | D6: 1000 | E6: 1000 | F6: 46173 | G6: 王伟垫付 | H6: 航帆增辉
A7: 46172 | B7: 章德吉货运 | C7: 邹桥派出所 | D7: 280 | E7: 280 | F7: 46172 | G7: 王伟垫付 | H7: 章德吉货运
