Workbook

Sheet 首页
A1: =基础资料!$C$5&" · 建筑安装财务模板（消防改造 · 水电安装 · 强弱电）" -> 竣辉 · 建筑安装财务模板（消防改造 · 水电安装 · 强弱电） | Z1: =IF(AND(项目利润表!$B$7<>"",OR(N(项目利润表!$Q$7)<>0,N(项目利润表!$R$7)+N(项目利润表!$S$7)+N(项目利润表!$T$7)+N(项目利润表!$U$7)+N(项目利润表!$V$7)<>0)),N(项目利润表!$Z$7)+(61-1)/10000000,"") -> 504646.35
A2: 💡 平时只录蓝色那几张（资金流水、应付登记、考勤工资、发票、收入确认、代发抵账），其余全是自动的。下面黄格子选报表年度和截止月份（选那个月任意一天，报表都算到月底；空着＝最后一笔流水那个月），所有报表跟着变。 | Z2: =IF(AND(项目利润表!$B$8<>"",OR(N(项目利润表!$Q$8)<>0,N(项目利润表!$R$8)+N(项目利润表!$S$8)+N(项目利润表!$T$8)+N(项目利润表!$U$8)+N(项目利润表!$V$8)<>0)),N(项目利润表!$Z$8)+(61-2)/10000000,"") -> 522827.04
Z3: =IF(AND(项目利润表!$B$9<>"",OR(N(项目利润表!$Q$9)<>0,N(项目利润表!$R$9)+N(项目利润表!$S$9)+N(项目利润表!$T$9)+N(项目利润表!$U$9)+N(项目利润表!$V$9)<>0)),N(项目利润表!$Z$9)+(61-3)/10000000,"") -> 1099488.6
B4: 报表年度 | C4: 2026 | E4: 截止月份 | H4: =IF(N(C4)<_辅助!$J$6,"⚠ 早于建账年（"&_辅助!$J$6&"），没有数","报表到："&TEXT(_辅助!$J$9,"yyyy年m月d日")&"（截止日所在月的月底；最后一笔流水 "&TEXT(_辅助!$J$10,"m月d日")&"）") -> 报表到：2026年8月31日（截止日所在月的月底；最后一笔流水 8月28日） | Z4: =IF(AND(项目利润表!$B$10<>"",OR(N(项目利润表!$Q$10)<>0,N(项目利润表!$R$10)+N(项目利润表!$S$10)+N(项目利润表!$T$10)+N(项目利润表!$U$10)+N(项目利润表!$V$10)<>0)),N(项目利润表!$Z$10)+(61-4)/10000000,"") -> 211042.55
B5: ⚠ 现在表里是你原表的数（演示用）：原表只有「累计」数，建账日定在 2026-03-01，以前的都当期初；2026 年只有德安农商行总部录了产值确认，其他项目 3 月以后的产值确认、5～8 月的考勤都还没录，所以本年利润表只有成本、收入很少，工人显示「多发了」。补录【收入确认】【考勤工资】后就准了。正式用之前，看说明里「开始用自己的账」清空这几张表。 | Z5: =IF(AND(项目利润表!$B$11<>"",OR(N(项目利润表!$Q$11)<>0,N(项目利润表!$R$11)+N(项目利润表!$S$11)+N(项目利润表!$T$11)+N(项目利润表!$U$11)+N(项目利润表!$V$11)<>0)),N(项目利润表!$Z$11)+(61-5)/10000000,"") -> 1084.41
B6: 关键数（到截止月底） | Z6: =IF(AND(项目利润表!$B$12<>"",OR(N(项目利润表!$Q$12)<>0,N(项目利润表!$R$12)+N(项目利润表!$S$12)+N(项目利润表!$T$12)+N(项目利润表!$U$12)+N(项目利润表!$V$12)<>0)),N(项目利润表!$Z$12)+(61-6)/10000000,"") -> 111782.44
B7: =HYPERLINK("#'利润表'!A1","本年确认产值") -> 本年确认产值 | E7: =HYPERLINK("#'利润表'!A1","本年净利润") -> 本年净利润 | H7: =HYPERLINK("#'资金报表'!A1","银行＋现金余额") -> 银行＋现金余额 | K7: =HYPERLINK("#'应收账款总表'!A1","甲方还欠（应收净额）") -> 甲方还欠（应收净额） | Z7: =IF(AND(项目利润表!$B$13<>"",OR(N(项目利润表!$Q$13)<>0,N(项目利润表!$R$13)+N(项目利润表!$S$13)+N(项目利润表!$T$13)+N(项目利润表!$U$13)+N(项目利润表!$V$13)<>0)),N(项目利润表!$Z$13)+(61-7)/10000000,"") -> 241332.28
B8: =_月汇总!$O$3 -> 8992 | E8: =_月汇总!$O$3+_月汇总!$O$22-(_月汇总!$O$4+_月汇总!$O$5+_月汇总!$O$6+_月汇总!$O$7+_月汇总!$O$8+_月汇总!$O$9+_月汇总!$O$10+_月汇总!$O$11+_月汇总!$O$12+_月汇总!$O$13+_月汇总!$O$14+_月汇总!$O$15+_月汇总!$O$16+_月汇总!$O$17+_月汇总!$O$18+_月汇总!$O$19+_月汇总!$O$20+_月汇总!$O$21+_月汇总!$O$23+_月汇总!$O$24+_月汇总!$O$25) -> -506604.59 | H8: =资产负债表!$B$6 -> 690444.46 | K8: =SUM(_项目汇总!$AV$3:$AV$62) -> 3327665.1 | Z8: =IF(AND(项目利润表!$B$14<>"",OR(N(项目利润表!$Q$14)<>0,N(项目利润表!$R$14)+N(项目利润表!$S$14)+N(项目利润表!$T$14)+N(项目利润表!$U$14)+N(项目利润表!$V$14)<>0)),N(项目利润表!$Z$14)+(61-8)/10000000,"") -> 62175.08
B9: =HYPERLINK("#'应付账款总表'!A1","欠材料分包机械（应付净额）") -> 欠材料分包机械（应付净额） | E9: =HYPERLINK("#'工资汇总'!A1","欠工资（净额，含管理人员）") -> 欠工资（净额，含管理人员） | H9: =HYPERLINK("#'个人往来'!A1","公司欠老板/负责人（个人户）") -> 公司欠老板/负责人（个人户） | K9: =HYPERLINK("#'盈亏平衡表'!A1","全年保本产值") -> 全年保本产值 | Z9: =IF(AND(项目利润表!$B$15<>"",OR(N(项目利润表!$Q$15)<>0,N(项目利润表!$R$15)+N(项目利润表!$S$15)+N(项目利润表!$T$15)+N(项目利润表!$U$15)+N(项目利润表!$V$15)<>0)),N(项目利润表!$Z$15)+(61-9)/10000000,"") -> 510758.96
B10: =SUM(_余额!$C$3:$C$302) -> 403773.38 | E10: =SUM(_余额!$E$3:$E$302) -> 5312.59 | H10: =-SUMIFS(_余额!$S$3:$S$22,_余额!$Q$3:$Q$22,"个人户") -> 283527.6 | K10: =盈亏平衡表!$C$16 -> 526119.2 | Z10: =IF(AND(项目利润表!$B$16<>"",OR(N(项目利润表!$Q$16)<>0,N(项目利润表!$R$16)+N(项目利润表!$S$16)+N(项目利润表!$T$16)+N(项目利润表!$U$16)+N(项目利润表!$V$16)<>0)),N(项目利润表!$Z$16)+(61-10)/10000000,"") -> 5965.21
B11: ="安全边际："&IF(ISNUMBER(盈亏平衡表!$C$22),TEXT(盈亏平衡表!$C$22,"0%"),"-")&" "&盈亏平衡表!$C$24 -> 安全边际：-2825% 照现在的速度，今年产值约 2 万，还差 51 万产值才保本 | Z11: =IF(AND(项目利润表!$B$17<>"",OR(N(项目利润表!$Q$17)<>0,N(项目利润表!$R$17)+N(项目利润表!$S$17)+N(项目利润表!$T$17)+N(项目利润表!$U$17)+N(项目利润表!$V$17)<>0)),N(项目利润表!$Z$17)+(61-11)/10000000,"") -> -9493.87
Z12: =IF(AND(项目利润表!$B$18<>"",OR(N(项目利润表!$Q$18)<>0,N(项目利润表!$R$18)+N(项目利润表!$S$18)+N(项目利润表!$T$18)+N(项目利润表!$U$18)+N(项目利润表!$V$18)<>0)),N(项目利润表!$Z$18)+(61-12)/10000000,"")
B13: 赚得最多的 5 个项目（开工至今） | H13: 亏得最多 / 赚得最少的 5 个项目 | Z13: =IF(AND(项目利润表!$B$19<>"",OR(N(项目利润表!$Q$19)<>0,N(项目利润表!$R$19)+N(项目利润表!$S$19)+N(项目利润表!$T$19)+N(项目利润表!$U$19)+N(项目利润表!$V$19)<>0)),N(项目利润表!$Z$19)+(61-13)/10000000,"")
B14: 项目 | C14: 净利 | E14: 确认产值 | F14: 净利率 | H14: 项目 | I14: 净利 | K14: 确认产值 | L14: 净利率 | Z14: =IF(AND(项目利润表!$B$20<>"",OR(N(项目利润表!$Q$20)<>0,N(项目利润表!$R$20)+N(项目利润表!$S$20)+N(项目利润表!$T$20)+N(项目利润表!$U$20)+N(项目利润表!$V$20)<>0)),N(项目利润表!$Z$20)+(61-14)/10000000,"") -> -2500
B15: =IF(IFERROR(MATCH(LARGE($Z$1:$Z$60,1),$Z$1:$Z$60,0),0)=0,"",INDEX(项目利润表!$B$7:$B$66,IFERROR(MATCH(LARGE($Z$1:$Z$60,1),$Z$1:$Z$60,0),0))) -> 九安架空层 | C15: =IF(IFERROR(MATCH(LARGE($Z$1:$Z$60,1),$Z$1:$Z$60,0),0)=0,"",INDEX(项目利润表!$Z$7:$Z$66,IFERROR(MATCH(LARGE($Z$1:$Z$60,1),$Z$1:$Z$60,0),0))) -> 1099488.6 | E15: =IF(IFERROR(MATCH(LARGE($Z$1:$Z$60,1),$Z$1:$Z$60,0),0)=0,"",INDEX(项目利润表!$Q$7:$Q$66,IFERROR(MATCH(LARGE($Z$1:$Z$60,1),$Z$1:$Z$60,0),0))) -> 1500000 | F15: =IF(IFERROR(MATCH(LARGE($Z$1:$Z$60,1),$Z$1:$Z$60,0),0)=0,"",INDEX(项目利润表!$AA$7:$AA$66,IFERROR(MATCH(LARGE($Z$1:$Z$60,1),$Z$1:$Z$60,0),0))) -> 0.73299237 | H15: =IF(IF(1>COUNT($Z$1:$Z$60)-5,0,IFERROR(MATCH(SMALL($Z$1:$Z$60,1),$Z$1:$Z$60,0),0))=0,"",INDEX(项目利润表!$B$7:$B$66,IF(1>COUNT($Z$1:$Z$60)-5,0,IFERROR(MATCH(SMALL($Z$1:$Z$60,1),$Z$1:$Z$60,0),0)))) -> 吴山政府项目 | I15: =IF(IF(1>COUNT($Z$1:$Z$60)-5,0,IFERROR(MATCH(SMALL($Z$1:$Z$60,1),$Z$1:$Z$60,0),0))=0,"",INDEX(项目利润表!$Z$7:$Z$66,IF(1>COUNT($Z$1:$Z$60)-5,0,IFERROR(MATCH(SMALL($Z$1:$Z$60,1),$Z$1:$Z$60,0),0)))) -> -56647.98 | K15: =IF(IF(1>COUNT($Z$1:$Z$60)-5,0,IFERROR(MATCH(SMALL($Z$1:$Z$60,1),$Z$1:$Z$60,0),0))=0,"",INDEX(项目利润表!$Q$7:$Q$66,IF(1>COUNT($Z$1:$Z$60)-5,0,IFERROR(MATCH(SMALL($Z$1:$Z$60,1),$Z$1:$Z$60,0),0)))) -> 0 | L15: =IF(IF(1>COUNT($Z$1:$Z$60)-5,0,IFERROR(MATCH(SMALL($Z$1:$Z$60,1),$Z$1:$Z$60,0),0))=0,"",INDEX(项目利润表!$AA$7:$AA$66,IF(1>COUNT($Z$1:$Z$60)-5,0,IFERROR(MATCH(SMALL($Z$1:$Z$60,1),$Z$1:$Z$60,0),0)))) | Z15: =IF(AND(项目利润表!$B$21<>"",OR(N(项目利润表!$Q$21)<>0,N(项目利润表!$R$21)+N(项目利润表!$S$21)+N(项目利润表!$T$21)+N(项目利润表!$U$21)+N(项目利润表!$V$21)<>0)),N(项目利润表!$Z$21)+(61-15)/10000000,"")
B16: =IF(IFERROR(MATCH(LARGE($Z$1:$Z$60,2),$Z$1:$Z$60,0),0)=0,"",INDEX(项目利润表!$B$7:$B$66,IFERROR(MATCH(LARGE($Z$1:$Z$60,2),$Z$1:$Z$60,0),0))) -> 科创中心 | C16: =IF(IFERROR(MATCH(LARGE($Z$1:$Z$60,2),$Z$1:$Z$60,0),0)=0,"",INDEX(项目利润表!$Z$7:$Z$66,IFERROR(MATCH(LARGE($Z$1:$Z$60,2),$Z$1:$Z$60,0),0))) -> 522827.04 | E16: =IF(IFERROR(MATCH(LARGE($Z$1:$Z$60,2),$Z$1:$Z$60,0),0)=0,"",INDEX(项目利润表!$Q$7:$Q$66,IFERROR(MATCH(LARGE($Z$1:$Z$60,2),$Z$1:$Z$60,0),0))) -> 1641809 | F16: =IF(IFERROR(MATCH(LARGE($Z$1:$Z$60,2),$Z$1:$Z$60,0),0)=0,"",INDEX(项目利润表!$AA$7:$AA$66,IFERROR(MATCH(LARGE($Z$1:$Z$60,2),$Z$1:$Z$60,0),0))) -> 0.31844571 | H16: =IF(IF(2>COUNT($Z$1:$Z$60)-5,0,IFERROR(MATCH(SMALL($Z$1:$Z$60,2),$Z$1:$Z$60,0),0))=0,"",INDEX(项目利润表!$B$7:$B$66,IF(2>COUNT($Z$1:$Z$60)-5,0,IFERROR(MATCH(SMALL($Z$1:$Z$60,2),$Z$1:$Z$60,0),0)))) -> 示范园 | I16: =IF(IF(2>COUNT($Z$1:$Z$60)-5,0,IFERROR(MATCH(SMALL($Z$1:$Z$60,2),$Z$1:$Z$60,0),0))=0,"",INDEX(项目利润表!$Z$7:$Z$66,IF(2>COUNT($Z$1:$Z$60)-5,0,IFERROR(MATCH(SMALL($Z$1:$Z$60,2),$Z$1:$Z$60,0),0)))) -> -9493.87 | K16: =IF(IF(2>COUNT($Z$1:$Z$60)-5,0,IFERROR(MATCH(SMALL($Z$1:$Z$60,2),$Z$1:$Z$60,0),0))=0,"",INDEX(项目利润表!$Q$7:$Q$66,IF(2>COUNT($Z$1:$Z$60)-5,0,IFERROR(MATCH(SMALL($Z$1:$Z$60,2),$Z$1:$Z$60,0),0)))) -> 0 | L16: =IF(IF(2>COUNT($Z$1:$Z$60)-5,0,IFERROR(MATCH(SMALL($Z$1:$Z$60,2),$Z$1:$Z$60,0),0))=0,"",INDEX(项目利润表!$AA$7:$AA$66,IF(2>COUNT($Z$1:$Z$60)-5,0,IFERROR(MATCH(SMALL($Z$1:$Z$60,2),$Z$1:$Z$60,0),0)))) | Z16: =IF(AND(项目利润表!$B$22<>"",OR(N(项目利润表!$Q$22)<>0,N(项目利润表!$R$22)+N(项目利润表!$S$22)+N(项目利润表!$T$22)+N(项目利润表!$U$22)+N(项目利润表!$V$22)<>0)),N(项目利润表!$Z$22)+(61-16)/10000000,"") -> -56647.98
B17: =IF(IFERROR(MATCH(LARGE($Z$1:$Z$60,3),$Z$1:$Z$60,0),0)=0,"",INDEX(项目利润表!$B$7:$B$66,IFERROR(MATCH(LARGE($Z$1:$Z$60,3),$Z$1:$Z$60,0),0))) -> 博河科创中心 | C17: =IF(IFERROR(MATCH(LARGE($Z$1:$Z$60,3),$Z$1:$Z$60,0),0)=0,"",INDEX(项目利润表!$Z$7:$Z$66,IFERROR(MATCH(LARGE($Z$1:$Z$60,3),$Z$1:$Z$60,0),0))) -> 510758.96 | E17: =IF(IFERROR(MATCH(LARGE($Z$1:$Z$60,3),$Z$1:$Z$60,0),0)=0,"",INDEX(项目利润表!$Q$7:$Q$66,IFERROR(MATCH(LARGE($Z$1:$Z$60,3),$Z$1:$Z$60,0),0))) -> 510758.96 | F17: =IF(IFERROR(MATCH(LARGE($Z$1:$Z$60,3),$Z$1:$Z$60,0),0)=0,"",INDEX(项目利润表!$AA$7:$AA$66,IFERROR(MATCH(LARGE($Z$1:$Z$60,3),$Z$1:$Z$60,0),0))) -> 1 | H17: =IF(IF(3>COUNT($Z$1:$Z$60)-5,0,IFERROR(MATCH(SMALL($Z$1:$Z$60,3),$Z$1:$Z$60,0),0))=0,"",INDEX(项目利润表!$B$7:$B$66,IF(3>COUNT($Z$1:$Z$60)-5,0,IFERROR(MATCH(SMALL($Z$1:$Z$60,3),$Z$1:$Z$60,0),0)))) -> 隆世光伏 | I17: =IF(IF(3>COUNT($Z$1:$Z$60)-5,0,IFERROR(MATCH(SMALL($Z$1:$Z$60,3),$Z$1:$Z$60,0),0))=0,"",INDEX(项目利润表!$Z$7:$Z$66,IF(3>COUNT($Z$1:$Z$60)-5,0,IFERROR(MATCH(SMALL($Z$1:$Z$60,3),$Z$1:$Z$60,0),0)))) -> -2500 | K17: =IF(IF(3>COUNT($Z$1:$Z$60)-5,0,IFERROR(MATCH(SMALL($Z$1:$Z$60,3),$Z$1:$Z$60,0),0))=0,"",INDEX(项目利润表!$Q$7:$Q$66,IF(3>COUNT($Z$1:$Z$60)-5,0,IFERROR(MATCH(SMALL($Z$1:$Z$60,3),$Z$1:$Z$60,0),0)))) -> 0 | L17: =IF(IF(3>COUNT($Z$1:$Z$60)-5,0,IFERROR(MATCH(SMALL($Z$1:$Z$60,3),$Z$1:$Z$60,0),0))=0,"",INDEX(项目利润表!$AA$7:$AA$66,IF(3>COUNT($Z$1:$Z$60)-5,0,IFERROR(MATCH(SMALL($Z$1:$Z$60,3),$Z$1:$Z$60,0),0)))) | Z17: =IF(AND(项目利润表!$B$23<>"",OR(N(项目利润表!$Q$23)<>0,N(项目利润表!$R$23)+N(项目利润表!$S$23)+N(项目利润表!$T$23)+N(项目利润表!$U$23)+N(项目利润表!$V$23)<>0)),N(项目利润表!$Z$23)+(61-17)/10000000,"")
B18: =IF(IFERROR(MATCH(LARGE($Z$1:$Z$60,4),$Z$1:$Z$60,0),0)=0,"",INDEX(项目利润表!$B$7:$B$66,IFERROR(MATCH(LARGE($Z$1:$Z$60,4),$Z$1:$Z$60,0),0))) -> 德安养老中心 | C18: =IF(IFERROR(MATCH(LARGE($Z$1:$Z$60,4),$Z$1:$Z$60,0),0)=0,"",INDEX(项目利润表!$Z$7:$Z$66,IFERROR(MATCH(LARGE($Z$1:$Z$60,4),$Z$1:$Z$60,0),0))) -> 504646.35 | E18: =IF(IFERROR(MATCH(LARGE($Z$1:$Z$60,4),$Z$1:$Z$60,0),0)=0,"",INDEX(项目利润表!$Q$7:$Q$66,IFERROR(MATCH(LARGE($Z$1:$Z$60,4),$Z$1:$Z$60,0),0))) -> 4362576.5 | F18: =IF(IFERROR(MATCH(LARGE($Z$1:$Z$60,4),$Z$1:$Z$60,0),0)=0,"",INDEX(项目利润表!$AA$7:$AA$66,IFERROR(MATCH(LARGE($Z$1:$Z$60,4),$Z$1:$Z$60,0),0))) -> 0.11567622 | H18: =IF(IF(4>COUNT($Z$1:$Z$60)-5,0,IFERROR(MATCH(SMALL($Z$1:$Z$60,4),$Z$1:$Z$60,0),0))=0,"",INDEX(项目利润表!$B$7:$B$66,IF(4>COUNT($Z$1:$Z$60)-5,0,IFERROR(MATCH(SMALL($Z$1:$Z$60,4),$Z$1:$Z$60,0),0)))) -> 邹桥派出所 | I18: =IF(IF(4>COUNT($Z$1:$Z$60)-5,0,IFERROR(MATCH(SMALL($Z$1:$Z$60,4),$Z$1:$Z$60,0),0))=0,"",INDEX(项目利润表!$Z$7:$Z$66,IF(4>COUNT($Z$1:$Z$60)-5,0,IFERROR(MATCH(SMALL($Z$1:$Z$60,4),$Z$1:$Z$60,0),0)))) -> 1084.41 | K18: =IF(IF(4>COUNT($Z$1:$Z$60)-5,0,IFERROR(MATCH(SMALL($Z$1:$Z$60,4),$Z$1:$Z$60,0),0))=0,"",INDEX(项目利润表!$Q$7:$Q$66,IF(4>COUNT($Z$1:$Z$60)-5,0,IFERROR(MATCH(SMALL($Z$1:$Z$60,4),$Z$1:$Z$60,0),0)))) -> 95560.56 | L18: =IF(IF(4>COUNT($Z$1:$Z$60)-5,0,IFERROR(MATCH(SMALL($Z$1:$Z$60,4),$Z$1:$Z$60,0),0))=0,"",INDEX(项目利润表!$AA$7:$AA$66,IF(4>COUNT($Z$1:$Z$60)-5,0,IFERROR(MATCH(SMALL($Z$1:$Z$60,4),$Z$1:$Z$60,0),0)))) -> 0.011347882 | Z18: =IF(AND(项目利润表!$B$24<>"",OR(N(项目利润表!$Q$24)<>0,N(项目利润表!$R$24)+N(项目利润表!$S$24)+N(项目利润表!$T$24)+N(项目利润表!$U$24)+N(项目利润表!$V$24)<>0)),N(项目利润表!$Z$24)+(61-18)/10000000,"")
B19: =IF(IFERROR(MATCH(LARGE($Z$1:$Z$60,5),$Z$1:$Z$60,0),0)=0,"",INDEX(项目利润表!$B$7:$B$66,IFERROR(MATCH(LARGE($Z$1:$Z$60,5),$Z$1:$Z$60,0),0))) -> 抚州8号楼 | C19: =IF(IFERROR(MATCH(LARGE($Z$1:$Z$60,5),$Z$1:$Z$60,0),0)=0,"",INDEX(项目利润表!$Z$7:$Z$66,IFERROR(MATCH(LARGE($Z$1:$Z$60,5),$Z$1:$Z$60,0),0))) -> 241332.28 | E19: =IF(IFERROR(MATCH(LARGE($Z$1:$Z$60,5),$Z$1:$Z$60,0),0)=0,"",INDEX(项目利润表!$Q$7:$Q$66,IFERROR(MATCH(LARGE($Z$1:$Z$60,5),$Z$1:$Z$60,0),0))) -> 960000 | F19: =IF(IFERROR(MATCH(LARGE($Z$1:$Z$60,5),$Z$1:$Z$60,0),0)=0,"",INDEX(项目利润表!$AA$7:$AA$66,IFERROR(MATCH(LARGE($Z$1:$Z$60,5),$Z$1:$Z$60,0),0))) -> 0.25138779 | H19: =IF(IF(5>COUNT($Z$1:$Z$60)-5,0,IFERROR(MATCH(SMALL($Z$1:$Z$60,5),$Z$1:$Z$60,0),0))=0,"",INDEX(项目利润表!$B$7:$B$66,IF(5>COUNT($Z$1:$Z$60)-5,0,IFERROR(MATCH(SMALL($Z$1:$Z$60,5),$Z$1:$Z$60,0),0)))) -> 德安农商行总部 | I19: =IF(IF(5>COUNT($Z$1:$Z$60)-5,0,IFERROR(MATCH(SMALL($Z$1:$Z$60,5),$Z$1:$Z$60,0),0))=0,"",INDEX(项目利润表!$Z$7:$Z$66,IF(5>COUNT($Z$1:$Z$60)-5,0,IFERROR(MATCH(SMALL($Z$1:$Z$60,5),$Z$1:$Z$60,0),0)))) -> 5965.21 | K19: =IF(IF(5>COUNT($Z$1:$Z$60)-5,0,IFERROR(MATCH(SMALL($Z$1:$Z$60,5),$Z$1:$Z$60,0),0))=0,"",INDEX(项目利润表!$Q$7:$Q$66,IF(5>COUNT($Z$1:$Z$60)-5,0,IFERROR(MATCH(SMALL($Z$1:$Z$60,5),$Z$1:$Z$60,0),0)))) -> 8992 | L19: =IF(IF(5>COUNT($Z$1:$Z$60)-5,0,IFERROR(MATCH(SMALL($Z$1:$Z$60,5),$Z$1:$Z$60,0),0))=0,"",INDEX(项目利润表!$AA$7:$AA$66,IF(5>COUNT($Z$1:$Z$60)-5,0,IFERROR(MATCH(SMALL($Z$1:$Z$60,5),$Z$1:$Z$60,0),0)))) -> 0.66339079 | Z19: =IF(AND(项目利润表!$B$25<>"",OR(N(项目利润表!$Q$25)<>0,N(项目利润表!$R$25)+N(项目利润表!$S$25)+N(项目利润表!$T$25)+N(项目利润表!$U$25)+N(项目利润表!$V$25)<>0)),N(项目利润表!$Z$25)+(61-19)/10000000,"")
Z20: =IF(AND(项目利润表!$B$26<>"",OR(N(项目利润表!$Q$26)<>0,N(项目利润表!$R$26)+N(项目利润表!$S$26)+N(项目利润表!$T$26)+N(项目利润表!$U$26)+N(项目利润表!$V$26)<>0)),N(项目利润表!$Z$26)+(61-20)/10000000,"")
B21: 提醒 | Z21: =IF(AND(项目利润表!$B$27<>"",OR(N(项目利润表!$Q$27)<>0,N(项目利润表!$R$27)+N(项目利润表!$S$27)+N(项目利润表!$T$27)+N(项目利润表!$U$27)+N(项目利润表!$V$27)<>0)),N(项目利润表!$Z$27)+(61-21)/10000000,"")
B22: ="数据校验：要改 "&COUNTIF(数据校验!$D$5:$D$45,"✗")&" 项、要看 "&COUNTIF(数据校验!$D$5:$D$45,"⚠")&" 项"&IF(COUNTIF(数据校验!$D$5:$D$45,"✗")+COUNTIF(数据校验!$D$5:$D$45,"⚠")=0,"，都没问题 √"," → 点这里去看") -> 数据校验：要改 1 项、要看 4 项 → 点这里去看 | Z22: =IF(AND(项目利润表!$B$28<>"",OR(N(项目利润表!$Q$28)<>0,N(项目利润表!$R$28)+N(项目利润表!$S$28)+N(项目利润表!$T$28)+N(项目利润表!$U$28)+N(项目利润表!$V$28)<>0)),N(项目利润表!$Z$28)+(61-22)/10000000,"")
B23: =IF(N(数据校验!$C$5)>0,"资金流水有 "&数据校验!$C$5&" 行要改（没认出类别、项目或单位）","资金流水都认出来了 √") -> 资金流水有 7 行要改（没认出类别、项目或单位） | Z23: =IF(AND(项目利润表!$B$29<>"",OR(N(项目利润表!$Q$29)<>0,N(项目利润表!$R$29)+N(项目利润表!$S$29)+N(项目利润表!$T$29)+N(项目利润表!$U$29)+N(项目利润表!$V$29)<>0)),N(项目利润表!$Z$29)+(61-23)/10000000,"")
B24: =IF(N(数据校验!$C$26)>0,数据校验!$C$26&" 个项目要注意：成本花得多产值确认得少（该找甲方报量）、完工没结算或亏损 → 看【项目利润表】提示","") -> 7 个项目要注意：成本花得多产值确认得少（该找甲方报量）、完工没结算或亏损 → 看【项目利润表】提示 | Z24: =IF(AND(项目利润表!$B$30<>"",OR(N(项目利润表!$Q$30)<>0,N(项目利润表!$R$30)+N(项目利润表!$S$30)+N(项目利润表!$T$30)+N(项目利润表!$U$30)+N(项目利润表!$V$30)<>0)),N(项目利润表!$Z$30)+(61-24)/10000000,"")
B25: =IF(COUNTIF(应收账款总表!$Y$6:$Y$65,"质保金*")>0,COUNTIF(应收账款总表!$Y$6:$Y$65,"质保金*")&" 个项目质保金到期可以催了","")&IF(N(应收账款总表!$L$4)>0," 开了票没回款的 "&TEXT(应收账款总表!$L$4,"#,##0")&" 元","") -> 开了票没回款的 135,732 元 | Z25: =IF(AND(项目利润表!$B$31<>"",OR(N(项目利润表!$Q$31)<>0,N(项目利润表!$R$31)+N(项目利润表!$S$31)+N(项目利润表!$T$31)+N(项目利润表!$U$31)+N(项目利润表!$V$31)<>0)),N(项目利润表!$Z$31)+(61-25)/10000000,"")
B26: =IF(N(数据校验!$C$15)>0,数据校验!$C$15&" 个管理人员有月份没录考勤（管理费会少算）","") -> 5 个管理人员有月份没录考勤（管理费会少算） | Z26: =IF(AND(项目利润表!$B$32<>"",OR(N(项目利润表!$Q$32)<>0,N(项目利润表!$R$32)+N(项目利润表!$S$32)+N(项目利润表!$T$32)+N(项目利润表!$U$32)+N(项目利润表!$V$32)<>0)),N(项目利润表!$Z$32)+(61-26)/10000000,"")
B27: =IF(ABS(N(数据校验!$C$17))>0.01,"账户余额跟银行 App 对不上，差 "&TEXT(数据校验!$C$17,"#,##0.00"),"") | Z27: =IF(AND(项目利润表!$B$33<>"",OR(N(项目利润表!$Q$33)<>0,N(项目利润表!$R$33)+N(项目利润表!$S$33)+N(项目利润表!$T$33)+N(项目利润表!$U$33)+N(项目利润表!$V$33)<>0)),N(项目利润表!$Z$33)+(61-27)/10000000,"")
Z28: =IF(AND(项目利润表!$B$34<>"",OR(N(项目利润表!$Q$34)<>0,N(项目利润表!$R$34)+N(项目利润表!$S$34)+N(项目利润表!$T$34)+N(项目利润表!$U$34)+N(项目利润表!$V$34)<>0)),N(项目利润表!$Z$34)+(61-28)/10000000,"")
B29: 各张表（点名字跳过去；每张表右上角有「← 回首页」） | Z29: =IF(AND(项目利润表!$B$35<>"",OR(N(项目利润表!$Q$35)<>0,N(项目利润表!$R$35)+N(项目利润表!$S$35)+N(项目利润表!$T$35)+N(项目利润表!$U$35)+N(项目利润表!$V$35)<>0)),N(项目利润表!$Z$35)+(61-29)/10000000,"")
B30: 每天 / 每笔录 | Z30: =IF(AND(项目利润表!$B$36<>"",OR(N(项目利润表!$Q$36)<>0,N(项目利润表!$R$36)+N(项目利润表!$S$36)+N(项目利润表!$T$36)+N(项目利润表!$U$36)+N(项目利润表!$V$36)<>0)),N(项目利润表!$Z$36)+(61-30)/10000000,"")
B31: 资金流水 | C31: 银行、现金、老板个人户的每一笔收支（摘要里的项目、单位、类别自动认） | H31: 应付登记 | I31: 跟材料商、分包、机械对了账就登记应付（付款在流水里记） | Z31: =IF(AND(项目利润表!$B$37<>"",OR(N(项目利润表!$Q$37)<>0,N(项目利润表!$R$37)+N(项目利润表!$S$37)+N(项目利润表!$T$37)+N(项目利润表!$U$37)+N(项目利润表!$V$37)<>0)),N(项目利润表!$Z$37)+(61-31)/10000000,"")
B32: 考勤工资 | C32: 每人每月一行：在哪个工地干了几天，工资自动算 | H32: 发票登记 | I32: 电子税务局导出的发票整块粘进来 | Z32: =IF(AND(项目利润表!$B$38<>"",OR(N(项目利润表!$Q$38)<>0,N(项目利润表!$R$38)+N(项目利润表!$S$38)+N(项目利润表!$T$38)+N(项目利润表!$U$38)+N(项目利润表!$V$38)<>0)),N(项目利润表!$Z$38)+(61-32)/10000000,"")
B33: 收入确认 | C33: 甲方/总包确认的产值、结算（收入按这里算） | H33: 代发抵账 | I33: 总包代发工资、代付款、甲供材、甲方扣款 | Z33: =IF(AND(项目利润表!$B$39<>"",OR(N(项目利润表!$Q$39)<>0,N(项目利润表!$R$39)+N(项目利润表!$S$39)+N(项目利润表!$T$39)+N(项目利润表!$U$39)+N(项目利润表!$V$39)<>0)),N(项目利润表!$Z$39)+(61-33)/10000000,"")
B34: 档案（偶尔改） | Z34: =IF(AND(项目利润表!$B$40<>"",OR(N(项目利润表!$Q$40)<>0,N(项目利润表!$R$40)+N(项目利润表!$S$40)+N(项目利润表!$T$40)+N(项目利润表!$U$40)+N(项目利润表!$V$40)<>0)),N(项目利润表!$Z$40)+(61-34)/10000000,"")
B35: 项目档案 | C35: 一个工地一行：合同额、甲方、开工完工、摘要关键词 | H35: 往来单位 | I35: 甲方、材料商、分包、机械、工人、老板都在这一张 | Z35: =IF(AND(项目利润表!$B$41<>"",OR(N(项目利润表!$Q$41)<>0,N(项目利润表!$R$41)+N(项目利润表!$S$41)+N(项目利润表!$T$41)+N(项目利润表!$U$41)+N(项目利润表!$V$41)<>0)),N(项目利润表!$Z$41)+(61-35)/10000000,"")
B36: 工资标准 | C36: 日工资、月薪；涨工资加一行 | H36: 期初余额 | I36: 建账日以前的数，只填一次 | Z36: =IF(AND(项目利润表!$B$42<>"",OR(N(项目利润表!$Q$42)<>0,N(项目利润表!$R$42)+N(项目利润表!$S$42)+N(项目利润表!$T$42)+N(项目利润表!$U$42)+N(项目利润表!$V$42)<>0)),N(项目利润表!$Z$42)+(61-36)/10000000,"")
B37: 基础资料 | C37: 公司、资金账户、收支类别、关键词、税率、固定资产 | Z37: =IF(AND(项目利润表!$B$43<>"",OR(N(项目利润表!$Q$43)<>0,N(项目利润表!$R$43)+N(项目利润表!$S$43)+N(项目利润表!$T$43)+N(项目利润表!$U$43)+N(项目利润表!$V$43)<>0)),N(项目利润表!$Z$43)+(61-37)/10000000,"")
B38: 查看（自动） | Z38: =IF(AND(项目利润表!$B$44<>"",OR(N(项目利润表!$Q$44)<>0,N(项目利润表!$R$44)+N(项目利润表!$S$44)+N(项目利润表!$T$44)+N(项目利润表!$U$44)+N(项目利润表!$V$44)<>0)),N(项目利润表!$Z$44)+(61-38)/10000000,"")
B39: 账户明细 | C39: 选一个账户看每一笔和余额 | H39: 资金报表 | I39: 资金周报 / 月报 | Z39: =IF(AND(项目利润表!$B$45<>"",OR(N(项目利润表!$Q$45)<>0,N(项目利润表!$R$45)+N(项目利润表!$S$45)+N(项目利润表!$T$45)+N(项目利润表!$U$45)+N(项目利润表!$V$45)<>0)),N(项目利润表!$Z$45)+(61-39)/10000000,"")
B40: 应收账款总表 | C40: 每个项目甲方还欠多少、欠了多久 | H40: 应付账款总表 | I40: 欠材料商、分包、机械多少，对账单 | Z40: =IF(AND(项目利润表!$B$46<>"",OR(N(项目利润表!$Q$46)<>0,N(项目利润表!$R$46)+N(项目利润表!$S$46)+N(项目利润表!$T$46)+N(项目利润表!$U$46)+N(项目利润表!$V$46)<>0)),N(项目利润表!$Z$46)+(61-40)/10000000,"")
...

Sheet 资金流水
A1: 资 金 流 水（所有账户一张表 · 每天录 · 自动认项目、类别、单位） | Q1: ← 回首页
A2: 💡 左边照原来录：日期、账户、摘要、收入、支出（收款记「收入」，付款记「支出」；银行退回来的钱在支出栏记负数也行，自动当冲回）。中间灰色是按摘要自动认出的 项目 / 收支类别 / 单位或人，看一眼对不对；不对或认不出，在右边黄格「改项目、改类别、改单位」选（改的优先）。几条规矩：①「代X付」（代老叶付佩力材料款）：单位是 X（冲 X 的账），真正收钱的写备注；② 一笔钱是几个项目的（隆世光伏/共青办公楼/德祥工地工程款），拆成几行分别记；③ 自己账户之间转钱（银行↔银行、银行↔老板个人户：借款、还款、报销、备用金）类别是「账户互转」，只记一边，对方账户自动认或在 O 列选；④ 老板、负责人替公司花的钱，记在他的个人户里（账户选他的个人户）。G 列是这个账户记到这一笔为止的余额。⑤ 记错的行清空内容就行，不要删整行、也不要插行（别的表按行取数）。
A3: 笔数 | B3: =COUNT(资金流水!$B$6:$B$2005) -> 217 | C3: 收入合计 | D3: =SUMIFS(资金流水!$R$6:$R$2005,资金流水!$AH$6:$AH$2005,"收",资金流水!$I$6:$I$2005,"<>账户互转") -> 1673903.2 | E3: 支出合计 | F3: =-SUMIFS(资金流水!$R$6:$R$2005,资金流水!$AH$6:$AH$2005,"支",资金流水!$I$6:$I$2005,"<>账户互转") -> 839466.34 | G3: 待处理 | H3: =COUNTIF(资金流水!$K$6:$K$2005,"✗*")&" 笔" -> 7 笔 | I3: 提醒 | J3: =COUNTIF(资金流水!$K$6:$K$2005,"⚠*")&" 笔" -> 0 笔 | K3: ="收支不含账户互转；容量 "&TEXT(B3/2000,"0%") -> 收支不含账户互转；容量 11%
A4: ① 照原来录 | G4: ② 自动认的（看对不对） | L4: ③ 不对才改（改的优先）
A5: 序号 | B5: 日期 | C5: 账户 | D5: 摘要 | E5: 收入 | F5: 支出 | G5: 结存 （本账户） | H5: 项目 | I5: 收支类别 | J5: 单位 / 人 | K5: 校验 | L5: 改项目 | M5: 改类别 | N5: 改单位/人 | O5: 对方账户 （互转） | P5: 备注 | R5: 净额 | S5: 年月 | T5: 认项目 | U5: 认类别 | V5: 认单位 | W5: 分摊归类 | X5: 报表项目 | Y5: 有应付 | Z5: 单位类型 | AA5: 走考勤的人 | AB5: 代X付 | AC5: 认对方账户 | AD5: 对方账户 | AE5: 账户类型 | AF5: 对方类型 | AG5: 关键词类别 | AH5: 收支 | AI5: 项目命中词 | AJ5: 别的项目 | AK5: 项目码 | AL5: 单位码 | AM5: 代付单位码 | AN5: 日期数 | AO5: 收款排号 | AP5: 付款排号 | AQ5: 押金排号
A6: =IF(AND(B6="",D6="",E6="",F6=""),"",ROW()-5) -> 1 | B6: 46143 | C6: 九江银行 | D6: 代吴群付向勇工资 | F6: 15000 | G6: =IF(C6="","",ROUND(IFERROR(INDEX(基础资料!$K$5:$K$24,MATCH(C6,基础资料!$G$5:$G$24,0)),0)+SUMIFS($R$6:R6,$C$6:C6,C6)-SUMIFS($R$6:R6,$AD$6:AD6,C6,$X$6:X6,"账户互转"),2)) -> -15000 | H6: =IF(L6<>"",L6,T6) | I6: =IF(M6<>"",M6,U6) -> 付应付款 | J6: =IF(N6<>"",N6,V6) -> 吴群 | K6: =IF(AND(B6="",D6="",E6="",F6=""),"",IF(C6="","✗ 没选账户",IF(AE6="","✗ 账户不在【基础资料】② 里",IF(NOT(ISNUMBER(B6)),"✗ 日期要填成日期（2026/5/1）",IF(AND(ISNUMBER(B6),B6<基础资料!$C$9),"✗ 日期早于建账日期（建账前的放【期初余额】）",IF(AND(N(E6)<>0,N(F6)<>0),"✗ 收入、支出只填一边",IF(R6=0,"✗ 没有金额",IF(I6="","✗ 认不出收支类别：在「改类别」选",IF(W6="？","✗ 收支类别不在【基础资料】③ 里",IF(OR(I6="管理人员工资",I6="折旧费"),"✗ 这一类是自动算的，流水里不能选（发工资选「工资」，买设备选「固定资产购置」）",IF(AND(OR(X6="材料费",X6="人工费",X6="分包费",X6="机械运输费",X6="其他直接费",X6="票据贴息",X6="应收账款"),H6=""),"✗ 这一笔要选项目（摘要里的项目没在【项目档案】的话先去加上）",IF(AND(H6<>"",COUNTIF(项目档案!$B$4:$B$63,H6)=0),"✗ 项目不在【项目档案】里",IF(AND(OR(IFERROR(INDEX(基础资料!$W$5:$W$64,MATCH(I6,基础资料!$S$5:$S$64,0))&"","")="人",IFERROR(INDEX(基础资料!$W$5:$W$64,MATCH(I6,基础资料!$S$5:$S$64,0))&"","")="单位"),J6=""),"✗ 这一笔要选是谁（改单位/人）",IF(AND(I6="付应付款",NOT(OR(Z6="材料供应商",Z6="分包",Z6="机械运输",Z6="其他"))),"✗ 付应付款要选材料商、分包或机械单位",IF(AND(I6="付应付款",Y6=0),"✗ 这家没有应付：先在【应付登记】登记（现买现付的选材料费等）",IF(AND(OR(I6="工资",I6="工资退回"),AA6=0),"✗ 工资要选管理人员或工人（临时工选「临时工工资」）",IF(AND(I6="账户互转",AD6=""),"✗ 账户互转要在「对方账户」选（借款、报销选那个人的个人户）",IF(AND(I6="账户互转",AF6=""),"✗ 对方账户不在【基础资料】② 里",IF(AND(I6="账户互转",AD6=C6),"✗ 对方账户不能是自己",IF(IF(I6="账户互转",COUNTIFS(资金流水!$C$6:$C$2005,AD6,资金流水!$AD$6:$AD$2005,C6,资金流水!$I$6:$I$2005,"账户互转",资金流水!$R$6:$R$2005,-R6)>0,FALSE),"✗ 对方账户那边也记了这笔互转（只记一边：清空其中一行的内容）",IF(AJ6>0,"⚠ 摘要里有两个项目：拆成几行，或在「改项目」选",IF(AND(I6<>"账户互转",O6<>""),"⚠ 填了对方账户但类别不是账户互转（对方账户不起作用）",IF(AND(J6<>"",Z6=""),"⚠ 单位/人没在【往来单位】登记",IF(AND(N(F6)<0,AH6="收"),"⚠ 这是收款，以后请记在收入栏",IF(N(E6)<0,"⚠ 收入填了负数，已按支出算",IF(N(F6)<0,"↩ 冲回（退款）",IF(AND(R6<0,I6<>"固定资产购置",I6<>"付应付款",ISNUMBER(B6),IFERROR(SUMPRODUCT(ISNUMBER(SEARCH(基础资料!$AJ$5:$AJ$34,D6))*(基础资料!$AJ$5:$AJ$34<>"")*((AN6-基础资料!$AK$5:$AK$34)<=30)*((AN6-基础资料!$AK$5:$AK$34)>=-30)),0)>0),"⚠ 像是在买【基础资料】⑥ 登记的车/设备：类别改成「固定资产购置」，不然成本算两遍",IF(AND(OR(I6="材料费",I6="分包费",I6="机械运输费",I6="其他直接费"),J6="",H6<>"",COUNTIFS(应付登记!$E$5:$E$1004,H6,应付登记!$G$5:$G$1004,-R6)>0),"⚠ 这个项目有同样金额的应付登记：是付那家的，改类别选「付应付款」、改单位选那家（不然成本算两遍）","√")))))))))))))))))))))))))))) -> √ | R6: =ROUND(N(E6)-N(F6),2) -> -15000 | S6: =IF(ISNUMBER(B6),YEAR(B6)*100+MONTH(B6),"") -> 202605 | T6: =IF(N(AK6)=0,"",INDEX(_辅助!$S$1:$S$240,AK6)) | U6: =IF(OR(D6="",R6=0),"",IF(AND(Z6="临时工",R6<0),"临时工工资",IF(AG6="",IF(AA6=1,"工资",IF(Z6="临时工","临时工工资",IF(Z6="甲方/总包","工程款",IF(AND(OR(Z6="材料供应商",Z6="分包",Z6="机械运输"),Y6=1),"付应付款","")))),IF(AND(Y6=1,OR(Z6="材料供应商",Z6="分包",Z6="机械运输",Z6="其他"),OR(AG6="材料费",AG6="分包费",AG6="机械运输费",AG6="其他直接费",AG6="工资",AG6="临时工工资")),"付应付款",AG6)))) -> 付应付款 | V6: =IF(D6="","",IF(N(AM6)>0,IF(N(AM6)=0,"",INDEX(_辅助!$W$1:$W$900,AM6)),IF(N(AL6)=0,"",INDEX(_辅助!$W$1:$W$900,AL6)))) -> 吴群 | W6: =IF(I6="","",IFERROR(INDEX(基础资料!$V$5:$V$64,MATCH(I6,基础资料!$S$5:$S$64,0))&"","？")) -> 不进利润 | X6: =IF(R6=0,"",IF(OR(I6="",IFERROR(INDEX(基础资料!$U$5:$U$64,MATCH(I6,基础资料!$S$5:$S$64,0))&"","")=""),"待分类",IF(OR(I6="付应付款",IFERROR(INDEX(基础资料!$U$5:$U$64,MATCH(I6,基础资料!$S$5:$S$64,0))&"","")="应付款"),IF(Z6="材料供应商","应付材料款",IF(Z6="分包","应付分包款",IF(Z6="机械运输","应付机械运输费","应付其他款"))),IFERROR(INDEX(基础资料!$U$5:$U$64,MATCH(I6,基础资料!$S$5:$S$64,0))&"","")))) -> 应付分包款 | Y6: =IF(J6="",0,IF(COUNTIF(应付登记!$D$5:$D$1004,J6)+COUNTIF(期初余额!$P$5:$P$204,J6)>0,1,0)) -> 1 | Z6: =IF(J6="","",IFERROR(INDEX(往来单位!$C$4:$C$303,MATCH(J6,往来单位!$B$4:$B$303,0))&"","")) -> 分包 | AA6: =IF(OR(Z6="管理人员",Z6="工人"),1,0) -> 0 | AB6: =IF(ISERROR(FIND("代",D6)),"",IFERROR(MID(D6,FIND("代",D6)+1,FIND("付",D6,FIND("代",D6))-FIND("代",D6)-1),"")) -> 吴群 | AC6: =IF(I6<>"账户互转","",IF(J6<>"",IFERROR(INDEX(_辅助!$G$1:$G$40,MATCH(J6,_辅助!$F$1:$F$40,0)),IF(IFERROR(MATCH(1,INDEX(ISNUMBER(SEARCH(_辅助!$Z$1:$Z$40,D6))*(_辅助!$Z$1:$Z$40<>""),0),0),0)=0,"",INDEX(_辅助!$AA$1:$AA$40,IFERROR(MATCH(1,INDEX(ISNUMBER(SEARCH(_辅助!$Z$1:$Z$40,D6))*(_辅助!$Z$1:$Z$40<>""),0),0),0)))),IF(IFERROR(MATCH(1,INDEX(ISNUMBER(SEARCH(_辅助!$Z$1:$Z$40,D6))*(_辅助!$Z$1:$Z$40<>""),0),0),0)=0,"",INDEX(_辅助!$AA$1:$AA$40,IFERROR(MATCH(1,INDEX(ISNUMBER(SEARCH(_辅助!$Z$1:$Z$40,D6))*(_辅助!$Z$1:$Z$40<>""),0),0),0))))) | AD6: =IF(O6<>"",O6,AC6) | AE6: =IF(C6="","",IFERROR(INDEX(基础资料!$H$5:$H$24,MATCH(C6,基础资料!$G$5:$G$24,0))&"","")) -> 银行 | AF6: =IF(AD6="","",IFERROR(INDEX(基础资料!$H$5:$H$24,MATCH(AD6,基础资料!$G$5:$G$24,0))&"","")) | AG6: =IF(OR(D6="",R6=0),"",IFERROR(INDEX(基础资料!$AC$5:$AC$164,IF(IF(F6<>"","支","收")="收",MATCH(1,INDEX(ISNUMBER(SEARCH(_辅助!$AB$1:$AB$160,D6))*(_辅助!$AB$1:$AB$160<>""),0),0),MATCH(1,INDEX(ISNUMBER(SEARCH(_辅助!$AC$1:$AC$160,D6))*(_辅助!$AC$1:$AC$160<>""),0),0)))&"","")) -> 工资 | AH6: =IF(R6=0,"",IF(OR(IFERROR(INDEX(基础资料!$T$5:$T$64,MATCH(I6,基础资料!$S$5:$S$64,0))&"","")="收",IFERROR(INDEX(基础资料!$T$5:$T$64,MATCH(I6,基础资料!$S$5:$S$64,0))&"","")="支"),IFERROR(INDEX(基础资料!$T$5:$T$64,MATCH(I6,基础资料!$S$5:$S$64,0))&"",""),IF(R6>0,"收","支"))) -> 支 | AI6: =IF(N(AK6)=0,"",INDEX(_辅助!$R$1:$R$240,AK6)) | AJ6: =IF(OR(AI6="",L6<>""),0,SUMPRODUCT(ISNUMBER(SEARCH(_辅助!$R$1:$R$240,D6))*(_辅助!$R$1:$R$240<>"")*(1-ISNUMBER(SEARCH(_辅助!$R$1:$R$240,AI6)))*(_辅助!$S$1:$S$240<>T6))) -> 0 | AK6: =IF(D6="",0,IFERROR(MATCH(1,INDEX(ISNUMBER(SEARCH(_辅助!$R$1:$R$240,D6))*(_辅助!$R$1:$R$240<>""),0),0),0)) -> 0 | AL6: =IF(D6="",0,IFERROR(MATCH(1,INDEX(ISNUMBER(SEARCH(_辅助!$V$1:$V$900,D6))*(_辅助!$V$1:$V$900<>""),0),0),0)) -> 99 | AM6: =IF(AB6="",0,IFERROR(MATCH(1,INDEX(ISNUMBER(SEARCH(_辅助!$V$1:$V$900,AB6))*(_辅助!$V$1:$V$900<>""),0),0),0)) -> 99 | AN6: =IF(ISNUMBER(B6),INT(B6),0) -> 46143 | AO6: =IF(AND(X6="应收账款",R6>0,AN6>0,H6<>""),H6&"|"&COUNTIFS(资金流水!$H$6:$H$2005,H6,资金流水!$X$6:$X$2005,"应收账款",资金流水!$R$6:$R$2005,">0",资金流水!$AN$6:$AN$2005,">0",资金流水!$AN$6:$AN$2005,"<="&AN6),"") | AP6: =IF(AND(J6<>"",R6<0,AN6>0),J6&"|"&COUNTIFS(资金流水!$J$6:$J$2005,J6,资金流水!$R$6:$R$2005,"<0",资金流水!$AN$6:$AN$2005,">0",资金流水!$AN$6:$AN$2005,"<="&AN6),"") -> 吴群|1 | AQ6: =IF(AND(X6="其他应收款",AN6>0,J6<>""),J6&"|"&(COUNTIFS(资金流水!$J$6:$J$2005,J6,资金流水!$X$6:$X$2005,"其他应收款",资金流水!$AN$6:$AN$2005,">0",资金流水!$AN$6:$AN$2005,"<"&AN6)+COUNTIFS($J$6:J6,J6,$X$6:X6,"其他应收款",$AN$6:AN6,AN6)),"")
A7: =IF(AND(B7="",D7="",E7="",F7=""),"",ROW()-5) -> 2 | B7: 46144 | C7: 九江银行 | D7: 付邓泽贵工资 | F7: 3000 | G7: =IF(C7="","",ROUND(IFERROR(INDEX(基础资料!$K$5:$K$24,MATCH(C7,基础资料!$G$5:$G$24,0)),0)+SUMIFS($R$6:R7,$C$6:C7,C7)-SUMIFS($R$6:R7,$AD$6:AD7,C7,$X$6:X7,"账户互转"),2)) -> -18000 | H7: =IF(L7<>"",L7,T7) | I7: =IF(M7<>"",M7,U7) -> 工资 | J7: =IF(N7<>"",N7,V7) -> 邓泽贵 | K7: =IF(AND(B7="",D7="",E7="",F7=""),"",IF(C7="","✗ 没选账户",IF(AE7="","✗ 账户不在【基础资料】② 里",IF(NOT(ISNUMBER(B7)),"✗ 日期要填成日期（2026/5/1）",IF(AND(ISNUMBER(B7),B7<基础资料!$C$9),"✗ 日期早于建账日期（建账前的放【期初余额】）",IF(AND(N(E7)<>0,N(F7)<>0),"✗ 收入、支出只填一边",IF(R7=0,"✗ 没有金额",IF(I7="","✗ 认不出收支类别：在「改类别」选",IF(W7="？","✗ 收支类别不在【基础资料】③ 里",IF(OR(I7="管理人员工资",I7="折旧费"),"✗ 这一类是自动算的，流水里不能选（发工资选「工资」，买设备选「固定资产购置」）",IF(AND(OR(X7="材料费",X7="人工费",X7="分包费",X7="机械运输费",X7="其他直接费",X7="票据贴息",X7="应收账款"),H7=""),"✗ 这一笔要选项目（摘要里的项目没在【项目档案】的话先去加上）",IF(AND(H7<>"",COUNTIF(项目档案!$B$4:$B$63,H7)=0),"✗ 项目不在【项目档案】里",IF(AND(OR(IFERROR(INDEX(基础资料!$W$5:$W$64,MATCH(I7,基础资料!$S$5:$S$64,0))&"","")="人",IFERROR(INDEX(基础资料!$W$5:$W$64,MATCH(I7,基础资料!$S$5:$S$64,0))&"","")="单位"),J7=""),"✗ 这一笔要选是谁（改单位/人）",IF(AND(I7="付应付款",NOT(OR(Z7="材料供应商",Z7="分包",Z7="机械运输",Z7="其他"))),"✗ 付应付款要选材料商、分包或机械单位",IF(AND(I7="付应付款",Y7=0),"✗ 这家没有应付：先在【应付登记】登记（现买现付的选材料费等）",IF(AND(OR(I7="工资",I7="工资退回"),AA7=0),"✗ 工资要选管理人员或工人（临时工选「临时工工资」）",IF(AND(I7="账户互转",AD7=""),"✗ 账户互转要在「对方账户」选（借款、报销选那个人的个人户）",IF(AND(I7="账户互转",AF7=""),"✗ 对方账户不在【基础资料】② 里",IF(AND(I7="账户互转",AD7=C7),"✗ 对方账户不能是自己",IF(IF(I7="账户互转",COUNTIFS(资金流水!$C$6:$C$2005,AD7,资金流水!$AD$6:$AD$2005,C7,资金流水!$I$6:$I$2005,"账户互转",资金流水!$R$6:$R$2005,-R7)>0,FALSE),"✗ 对方账户那边也记了这笔互转（只记一边：清空其中一行的内容）",IF(AJ7>0,"⚠ 摘要里有两个项目：拆成几行，或在「改项目」选",IF(AND(I7<>"账户互转",O7<>""),"⚠ 填了对方账户但类别不是账户互转（对方账户不起作用）",IF(AND(J7<>"",Z7=""),"⚠ 单位/人没在【往来单位】登记",IF(AND(N(F7)<0,AH7="收"),"⚠ 这是收款，以后请记在收入栏",IF(N(E7)<0,"⚠ 收入填了负数，已按支出算",IF(N(F7)<0,"↩ 冲回（退款）",IF(AND(R7<0,I7<>"固定资产购置",I7<>"付应付款",ISNUMBER(B7),IFERROR(SUMPRODUCT(ISNUMBER(SEARCH(基础资料!$AJ$5:$AJ$34,D7))*(基础资料!$AJ$5:$AJ$34<>"")*((AN7-基础资料!$AK$5:$AK$34)<=30)*((AN7-基础资料!$AK$5:$AK$34)>=-30)),0)>0),"⚠ 像是在买【基础资料】⑥ 登记的车/设备：类别改成「固定资产购置」，不然成本算两遍",IF(AND(OR(I7="材料费",I7="分包费",I7="机械运输费",I7="其他直接费"),J7="",H7<>"",COUNTIFS(应付登记!$E$5:$E$1004,H7,应付登记!$G$5:$G$1004,-R7)>0),"⚠ 这个项目有同样金额的应付登记：是付那家的，改类别选「付应付款」、改单位选那家（不然成本算两遍）","√")))))))))))))))))))))))))))) -> √ | R7: =ROUND(N(E7)-N(F7),2) -> -3000 | S7: =IF(ISNUMBER(B7),YEAR(B7)*100+MONTH(B7),"") -> 202605 | T7: =IF(N(AK7)=0,"",INDEX(_辅助!$S$1:$S$240,AK7)) | U7: =IF(OR(D7="",R7=0),"",IF(AND(Z7="临时工",R7<0),"临时工工资",IF(AG7="",IF(AA7=1,"工资",IF(Z7="临时工","临时工工资",IF(Z7="甲方/总包","工程款",IF(AND(OR(Z7="材料供应商",Z7="分包",Z7="机械运输"),Y7=1),"付应付款","")))),IF(AND(Y7=1,OR(Z7="材料供应商",Z7="分包",Z7="机械运输",Z7="其他"),OR(AG7="材料费",AG7="分包费",AG7="机械运输费",AG7="其他直接费",AG7="工资",AG7="临时工工资")),"付应付款",AG7)))) -> 工资 | V7: =IF(D7="","",IF(N(AM7)>0,IF(N(AM7)=0,"",INDEX(_辅助!$W$1:$W$900,AM7)),IF(N(AL7)=0,"",INDEX(_辅助!$W$1:$W$900,AL7)))) -> 邓泽贵 | W7: =IF(I7="","",IFERROR(INDEX(基础资料!$V$5:$V$64,MATCH(I7,基础资料!$S$5:$S$64,0))&"","？")) -> 不进利润 | X7: =IF(R7=0,"",IF(OR(I7="",IFERROR(INDEX(基础资料!$U$5:$U$64,MATCH(I7,基础资料!$S$5:$S$64,0))&"","")=""),"待分类",IF(OR(I7="付应付款",IFERROR(INDEX(基础资料!$U$5:$U$64,MATCH(I7,基础资料!$S$5:$S$64,0))&"","")="应付款"),IF(Z7="材料供应商","应付材料款",IF(Z7="分包","应付分包款",IF(Z7="机械运输","应付机械运输费","应付其他款"))),IFERROR(INDEX(基础资料!$U$5:$U$64,MATCH(I7,基础资料!$S$5:$S$64,0))&"","")))) -> 应付职工薪酬 | Y7: =IF(J7="",0,IF(COUNTIF(应付登记!$D$5:$D$1004,J7)+COUNTIF(期初余额!$P$5:$P$204,J7)>0,1,0)) -> 0 | Z7: =IF(J7="","",IFERROR(INDEX(往来单位!$C$4:$C$303,MATCH(J7,往来单位!$B$4:$B$303,0))&"","")) -> 工人 | AA7: =IF(OR(Z7="管理人员",Z7="工人"),1,0) -> 1 | AB7: =IF(ISERROR(FIND("代",D7)),"",IFERROR(MID(D7,FIND("代",D7)+1,FIND("付",D7,FIND("代",D7))-FIND("代",D7)-1),"")) | AC7: =IF(I7<>"账户互转","",IF(J7<>"",IFERROR(INDEX(_辅助!$G$1:$G$40,MATCH(J7,_辅助!$F$1:$F$40,0)),IF(IFERROR(MATCH(1,INDEX(ISNUMBER(SEARCH(_辅助!$Z$1:$Z$40,D7))*(_辅助!$Z$1:$Z$40<>""),0),0),0)=0,"",INDEX(_辅助!$AA$1:$AA$40,IFERROR(MATCH(1,INDEX(ISNUMBER(SEARCH(_辅助!$Z$1:$Z$40,D7))*(_辅助!$Z$1:$Z$40<>""),0),0),0)))),IF(IFERROR(MATCH(1,INDEX(ISNUMBER(SEARCH(_辅助!$Z$1:$Z$40,D7))*(_辅助!$Z$1:$Z$40<>""),0),0),0)=0,"",INDEX(_辅助!$AA$1:$AA$40,IFERROR(MATCH(1,INDEX(ISNUMBER(SEARCH(_辅助!$Z$1:$Z$40,D7))*(_辅助!$Z$1:$Z$40<>""),0),0),0))))) | AD7: =IF(O7<>"",O7,AC7) | AE7: =IF(C7="","",IFERROR(INDEX(基础资料!$H$5:$H$24,MATCH(C7,基础资料!$G$5:$G$24,0))&"","")) -> 银行 | AF7: =IF(AD7="","",IFERROR(INDEX(基础资料!$H$5:$H$24,MATCH(AD7,基础资料!$G$5:$G$24,0))&"","")) | AG7: =IF(OR(D7="",R7=0),"",IFERROR(INDEX(基础资料!$AC$5:$AC$164,IF(IF(F7<>"","支","收")="收",MATCH(1,INDEX(ISNUMBER(SEARCH(_辅助!$AB$1:$AB$160,D7))*(_辅助!$AB$1:$AB$160<>""),0),0),MATCH(1,INDEX(ISNUMBER(SEARCH(_辅助!$AC$1:$AC$160,D7))*(_辅助!$AC$1:$AC$160<>""),0),0)))&"","")) -> 工资 | AH7: =IF(R7=0,"",IF(OR(IFERROR(INDEX(基础资料!$T$5:$T$64,MATCH(I7,基础资料!$S$5:$S$64,0))&"","")="收",IFERROR(INDEX(基础资料!$T$5:$T$64,MATCH(I7,基础资料!$S$5:$S$64,0))&"","")="支"),IFERROR(INDEX(基础资料!$T$5:$T$64,MATCH(I7,基础资料!$S$5:$S$64,0))&"",""),IF(R7>0,"收","支"))) -> 支 | AI7: =IF(N(AK7)=0,"",INDEX(_辅助!$R$1:$R$240,AK7)) | AJ7: =IF(OR(AI7="",L7<>""),0,SUMPRODUCT(ISNUMBER(SEARCH(_辅助!$R$1:$R$240,D7))*(_辅助!$R$1:$R$240<>"")*(1-ISNUMBER(SEARCH(_辅助!$R$1:$R$240,AI7)))*(_辅助!$S$1:$S$240<>T7))) -> 0 | AK7: =IF(D7="",0,IFERROR(MATCH(1,INDEX(ISNUMBER(SEARCH(_辅助!$R$1:$R$240,D7))*(_辅助!$R$1:$R$240<>""),0),0),0)) -> 0 | AL7: =IF(D7="",0,IFERROR(MATCH(1,INDEX(ISNUMBER(SEARCH(_辅助!$V$1:$V$900,D7))*(_辅助!$V$1:$V$900<>""),0),0),0)) -> 52 | AM7: =IF(AB7="",0,IFERROR(MATCH(1,INDEX(ISNUMBER(SEARCH(_辅助!$V$1:$V$900,AB7))*(_辅助!$V$1:$V$900<>""),0),0),0)) -> 0 | AN7: =IF(ISNUMBER(B7),INT(B7),0) -> 46144 | AO7: =IF(AND(X7="应收账款",R7>0,AN7>0,H7<>""),H7&"|"&COUNTIFS(资金流水!$H$6:$H$2005,H7,资金流水!$X$6:$X$2005,"应收账款",资金流水!$R$6:$R$2005,">0",资金流水!$AN$6:$AN$2005,">0",资金流水!$AN$6:$AN$2005,"<="&AN7),"") | AP7: =IF(AND(J7<>"",R7<0,AN7>0),J7&"|"&COUNTIFS(资金流水!$J$6:$J$2005,J7,资金流水!$R$6:$R$2005,"<0",资金流水!$AN$6:$AN$2005,">0",资金流水!$AN$6:$AN$2005,"<="&AN7),"") -> 邓泽贵|1 | AQ7: =IF(AND(X7="其他应收款",AN7>0,J7<>""),J7&"|"&(COUNTIFS(资金流水!$J$6:$J$2005,J7,资金流水!$X$6:$X$2005,"其他应收款",资金流水!$AN$6:$AN$2005,">0",资金流水!$AN$6:$AN$2005,"<"&AN7)+COUNTIFS($J$6:J7,J7,$X$6:X7,"其他应收款",$AN$6:AN7,AN7)),"")
A8: =IF(AND(B8="",D8="",E8="",F8=""),"",ROW()-5) -> 3 | B8: 46144 | C8: 九江银行 | D8: 付吴志刚工资 | F8: 3000 | G8: =IF(C8="","",ROUND(IFERROR(INDEX(基础资料!$K$5:$K$24,MATCH(C8,基础资料!$G$5:$G$24,0)),0)+SUMIFS($R$6:R8,$C$6:C8,C8)-SUMIFS($R$6:R8,$AD$6:AD8,C8,$X$6:X8,"账户互转"),2)) -> -21000 | H8: =IF(L8<>"",L8,T8) | I8: =IF(M8<>"",M8,U8) -> 工资 | J8: =IF(N8<>"",N8,V8) -> 吴志刚 | K8: =IF(AND(B8="",D8="",E8="",F8=""),"",IF(C8="","✗ 没选账户",IF(AE8="","✗ 账户不在【基础资料】② 里",IF(NOT(ISNUMBER(B8)),"✗ 日期要填成日期（2026/5/1）",IF(AND(ISNUMBER(B8),B8<基础资料!$C$9),"✗ 日期早于建账日期（建账前的放【期初余额】）",IF(AND(N(E8)<>0,N(F8)<>0),"✗ 收入、支出只填一边",IF(R8=0,"✗ 没有金额",IF(I8="","✗ 认不出收支类别：在「改类别」选",IF(W8="？","✗ 收支类别不在【基础资料】③ 里",IF(OR(I8="管理人员工资",I8="折旧费"),"✗ 这一类是自动算的，流水里不能选（发工资选「工资」，买设备选「固定资产购置」）",IF(AND(OR(X8="材料费",X8="人工费",X8="分包费",X8="机械运输费",X8="其他直接费",X8="票据贴息",X8="应收账款"),H8=""),"✗ 这一笔要选项目（摘要里的项目没在【项目档案】的话先去加上）",IF(AND(H8<>"",COUNTIF(项目档案!$B$4:$B$63,H8)=0),"✗ 项目不在【项目档案】里",IF(AND(OR(IFERROR(INDEX(基础资料!$W$5:$W$64,MATCH(I8,基础资料!$S$5:$S$64,0))&"","")="人",IFERROR(INDEX(基础资料!$W$5:$W$64,MATCH(I8,基础资料!$S$5:$S$64,0))&"","")="单位"),J8=""),"✗ 这一笔要选是谁（改单位/人）",IF(AND(I8="付应付款",NOT(OR(Z8="材料供应商",Z8="分包",Z8="机械运输",Z8="其他"))),"✗ 付应付款要选材料商、分包或机械单位",IF(AND(I8="付应付款",Y8=0),"✗ 这家没有应付：先在【应付登记】登记（现买现付的选材料费等）",IF(AND(OR(I8="工资",I8="工资退回"),AA8=0),"✗ 工资要选管理人员或工人（临时工选「临时工工资」）",IF(AND(I8="账户互转",AD8=""),"✗ 账户互转要在「对方账户」选（借款、报销选那个人的个人户）",IF(AND(I8="账户互转",AF8=""),"✗ 对方账户不在【基础资料】② 里",IF(AND(I8="账户互转",AD8=C8),"✗ 对方账户不能是自己",IF(IF(I8="账户互转",COUNTIFS(资金流水!$C$6:$C$2005,AD8,资金流水!$AD$6:$AD$2005,C8,资金流水!$I$6:$I$2005,"账户互转",资金流水!$R$6:$R$2005,-R8)>0,FALSE),"✗ 对方账户那边也记了这笔互转（只记一边：清空其中一行的内容）",IF(AJ8>0,"⚠ 摘要里有两个项目：拆成几行，或在「改项目」选",IF(AND(I8<>"账户互转",O8<>""),"⚠ 填了对方账户但类别不是账户互转（对方账户不起作用）",IF(AND(J8<>"",Z8=""),"⚠ 单位/人没在【往来单位】登记",IF(AND(N(F8)<0,AH8="收"),"⚠ 这是收款，以后请记在收入栏",IF(N(E8)<0,"⚠ 收入填了负数，已按支出算",IF(N(F8)<0,"↩ 冲回（退款）",IF(AND(R8<0,I8<>"固定资产购置",I8<>"付应付款",ISNUMBER(B8),IFERROR(SUMPRODUCT(ISNUMBER(SEARCH(基础资料!$AJ$5:$AJ$34,D8))*(基础资料!$AJ$5:$AJ$34<>"")*((AN8-基础资料!$AK$5:$AK$34)<=30)*((AN8-基础资料!$AK$5:$AK$34)>=-30)),0)>0),"⚠ 像是在买【基础资料】⑥ 登记的车/设备：类别改成「固定资产购置」，不然成本算两遍",IF(AND(OR(I8="材料费",I8="分包费",I8="机械运输费",I8="其他直接费"),J8="",H8<>"",COUNTIFS(应付登记!$E$5:$E$1004,H8,应付登记!$G$5:$G$1004,-R8)>0),"⚠ 这个项目有同样金额的应付登记：是付那家的，改类别选「付应付款」、改单位选那家（不然成本算两遍）","√")))))))))))))))))))))))))))) -> √ | R8: =ROUND(N(E8)-N(F8),2) -> -3000 | S8: =IF(ISNUMBER(B8),YEAR(B8)*100+MONTH(B8),"") -> 202605 | T8: =IF(N(AK8)=0,"",INDEX(_辅助!$S$1:$S$240,AK8)) | U8: =IF(OR(D8="",R8=0),"",IF(AND(Z8="临时工",R8<0),"临时工工资",IF(AG8="",IF(AA8=1,"工资",IF(Z8="临时工","临时工工资",IF(Z8="甲方/总包","工程款",IF(AND(OR(Z8="材料供应商",Z8="分包",Z8="机械运输"),Y8=1),"付应付款","")))),IF(AND(Y8=1,OR(Z8="材料供应商",Z8="分包",Z8="机械运输",Z8="其他"),OR(AG8="材料费",AG8="分包费",AG8="机械运输费",AG8="其他直接费",AG8="工资",AG8="临时工工资")),"付应付款",AG8)))) -> 工资 | V8: =IF(D8="","",IF(N(AM8)>0,IF(N(AM8)=0,"",INDEX(_辅助!$W$1:$W$900,AM8)),IF(N(AL8)=0,"",INDEX(_辅助!$W$1:$W$900,AL8)))) -> 吴志刚 | W8: =IF(I8="","",IFERROR(INDEX(基础资料!$V$5:$V$64,MATCH(I8,基础资料!$S$5:$S$64,0))&"","？")) -> 不进利润 | X8: =IF(R8=0,"",IF(OR(I8="",IFERROR(INDEX(基础资料!$U$5:$U$64,MATCH(I8,基础资料!$S$5:$S$64,0))&"","")=""),"待分类",IF(OR(I8="付应付款",IFERROR(INDEX(基础资料!$U$5:$U$64,MATCH(I8,基础资料!$S$5:$S$64,0))&"","")="应付款"),IF(Z8="材料供应商","应付材料款",IF(Z8="分包","应付分包款",IF(Z8="机械运输","应付机械运输费","应付其他款"))),IFERROR(INDEX(基础资料!$U$5:$U$64,MATCH(I8,基础资料!$S$5:$S$64,0))&"","")))) -> 应付职工薪酬 | Y8: =IF(J8="",0,IF(COUNTIF(应付登记!$D$5:$D$1004,J8)+COUNTIF(期初余额!$P$5:$P$204,J8)>0,1,0)) -> 0 | Z8: =IF(J8="","",IFERROR(INDEX(往来单位!$C$4:$C$303,MATCH(J8,往来单位!$B$4:$B$303,0))&"","")) -> 工人 | AA8: =IF(OR(Z8="管理人员",Z8="工人"),1,0) -> 1 | AB8: =IF(ISERROR(FIND("代",D8)),"",IFERROR(MID(D8,FIND("代",D8)+1,FIND("付",D8,FIND("代",D8))-FIND("代",D8)-1),"")) | AC8: =IF(I8<>"账户互转","",IF(J8<>"",IFERROR(INDEX(_辅助!$G$1:$G$40,MATCH(J8,_辅助!$F$1:$F$40,0)),IF(IFERROR(MATCH(1,INDEX(ISNUMBER(SEARCH(_辅助!$Z$1:$Z$40,D8))*(_辅助!$Z$1:$Z$40<>""),0),0),0)=0,"",INDEX(_辅助!$AA$1:$AA$40,IFERROR(MATCH(1,INDEX(ISNUMBER(SEARCH(_辅助!$Z$1:$Z$40,D8))*(_辅助!$Z$1:$Z$40<>""),0),0),0)))),IF(IFERROR(MATCH(1,INDEX(ISNUMBER(SEARCH(_辅助!$Z$1:$Z$40,D8))*(_辅助!$Z$1:$Z$40<>""),0),0),0)=0,"",INDEX(_辅助!$AA$1:$AA$40,IFERROR(MATCH(1,INDEX(ISNUMBER(SEARCH(_辅助!$Z$1:$Z$40,D8))*(_辅助!$Z$1:$Z$40<>""),0),0),0))))) | AD8: =IF(O8<>"",O8,AC8) | AE8: =IF(C8="","",IFERROR(INDEX(基础资料!$H$5:$H$24,MATCH(C8,基础资料!$G$5:$G$24,0))&"","")) -> 银行 | AF8: =IF(AD8="","",IFERROR(INDEX(基础资料!$H$5:$H$24,MATCH(AD8,基础资料!$G$5:$G$24,0))&"","")) | AG8: =IF(OR(D8="",R8=0),"",IFERROR(INDEX(基础资料!$AC$5:$AC$164,IF(IF(F8<>"","支","收")="收",MATCH(1,INDEX(ISNUMBER(SEARCH(_辅助!$AB$1:$AB$160,D8))*(_辅助!$AB$1:$AB$160<>""),0),0),MATCH(1,INDEX(ISNUMBER(SEARCH(_辅助!$AC$1:$AC$160,D8))*(_辅助!$AC$1:$AC$160<>""),0),0)))&"","")) -> 工资 | AH8: =IF(R8=0,"",IF(OR(IFERROR(INDEX(基础资料!$T$5:$T$64,MATCH(I8,基础资料!$S$5:$S$64,0))&"","")="收",IFERROR(INDEX(基础资料!$T$5:$T$64,MATCH(I8,基础资料!$S$5:$S$64,0))&"","")="支"),IFERROR(INDEX(基础资料!$T$5:$T$64,MATCH(I8,基础资料!$S$5:$S$64,0))&"",""),IF(R8>0,"收","支"))) -> 支 | AI8: =IF(N(AK8)=0,"",INDEX(_辅助!$R$1:$R$240,AK8)) | AJ8: =IF(OR(AI8="",L8<>""),0,SUMPRODUCT(ISNUMBER(SEARCH(_辅助!$R$1:$R$240,D8))*(_辅助!$R$1:$R$240<>"")*(1-ISNUMBER(SEARCH(_辅助!$R$1:$R$240,AI8)))*(_辅助!$S$1:$S$240<>T8))) -> 0 | AK8: =IF(D8="",0,IFERROR(MATCH(1,INDEX(ISNUMBER(SEARCH(_辅助!$R$1:$R$240,D8))*(_辅助!$R$1:$R$240<>""),0),0),0)) -> 0 | AL8: =IF(D8="",0,IFERROR(MATCH(1,INDEX(ISNUMBER(SEARCH(_辅助!$V$1:$V$900,D8))*(_辅助!$V$1:$V$900<>""),0),0),0)) -> 65 | AM8: =IF(AB8="",0,IFERROR(MATCH(1,INDEX(ISNUMBER(SEARCH(_辅助!$V$1:$V$900,AB8))*(_辅助!$V$1:$V$900<>""),0),0),0)) -> 0 | AN8: =IF(ISNUMBER(B8),INT(B8),0) -> 46144 | AO8: =IF(AND(X8="应收账款",R8>0,AN8>0,H8<>""),H8&"|"&COUNTIFS(资金流水!$H$6:$H$2005,H8,资金流水!$X$6:$X$2005,"应收账款",资金流水!$R$6:$R$2005,">0",资金流水!$AN$6:$AN$2005,">0",资金流水!$AN$6:$AN$2005,"<="&AN8),"") | AP8: =IF(AND(J8<>"",R8<0,AN8>0),J8&"|"&COUNTIFS(资金流水!$J$6:$J$2005,J8,资金流水!$R$6:$R$2005,"<0",资金流水!$AN$6:$AN$2005,">0",资金流水!$AN$6:$AN$2005,"<="&AN8),"") -> 吴志刚|1 | AQ8: =IF(AND(X8="其他应收款",AN8>0,J8<>""),J8&"|"&(COUNTIFS(资金流水!$J$6:$J$2005,J8,资金流水!$X$6:$X$2005,"其他应收款",资金流水!$AN$6:$AN$2005,">0",资金流水!$AN$6:$AN$2005,"<"&AN8)+COUNTIFS($J$6:J8,J8,$X$6:X8,"其他应收款",$AN$6:AN8,AN8)),"")
A9: =IF(AND(B9="",D9="",E9="",F9=""),"",ROW()-5) -> 4 | B9: 46144 | C9: 九江银行 | D9: 付金南水工资 | F9: 3000 | G9: =IF(C9="","",ROUND(IFERROR(INDEX(基础资料!$K$5:$K$24,MATCH(C9,基础资料!$G$5:$G$24,0)),0)+SUMIFS($R$6:R9,$C$6:C9,C9)-SUMIFS($R$6:R9,$AD$6:AD9,C9,$X$6:X9,"账户互转"),2)) -> -24000 | H9: =IF(L9<>"",L9,T9) | I9: =IF(M9<>"",M9,U9) -> 工资 | J9: =IF(N9<>"",N9,V9) -> 金南水 | K9: =IF(AND(B9="",D9="",E9="",F9=""),"",IF(C9="","✗ 没选账户",IF(AE9="","✗ 账户不在【基础资料】② 里",IF(NOT(ISNUMBER(B9)),"✗ 日期要填成日期（2026/5/1）",IF(AND(ISNUMBER(B9),B9<基础资料!$C$9),"✗ 日期早于建账日期（建账前的放【期初余额】）",IF(AND(N(E9)<>0,N(F9)<>0),"✗ 收入、支出只填一边",IF(R9=0,"✗ 没有金额",IF(I9="","✗ 认不出收支类别：在「改类别」选",IF(W9="？","✗ 收支类别不在【基础资料】③ 里",IF(OR(I9="管理人员工资",I9="折旧费"),"✗ 这一类是自动算的，流水里不能选（发工资选「工资」，买设备选「固定资产购置」）",IF(AND(OR(X9="材料费",X9="人工费",X9="分包费",X9="机械运输费",X9="其他直接费",X9="票据贴息",X9="应收账款"),H9=""),"✗ 这一笔要选项目（摘要里的项目没在【项目档案】的话先去加上）",IF(AND(H9<>"",COUNTIF(项目档案!$B$4:$B$63,H9)=0),"✗ 项目不在【项目档案】里",IF(AND(OR(IFERROR(INDEX(基础资料!$W$5:$W$64,MATCH(I9,基础资料!$S$5:$S$64,0))&"","")="人",IFERROR(INDEX(基础资料!$W$5:$W$64,MATCH(I9,基础资料!$S$5:$S$64,0))&"","")="单位"),J9=""),"✗ 这一笔要选是谁（改单位/人）",IF(AND(I9="付应付款",NOT(OR(Z9="材料供应商",Z9="分包",Z9="机械运输",Z9="其他"))),"✗ 付应付款要选材料商、分包或机械单位",IF(AND(I9="付应付款",Y9=0),"✗ 这家没有应付：先在【应付登记】登记（现买现付的选材料费等）",IF(AND(OR(I9="工资",I9="工资退回"),AA9=0),"✗ 工资要选管理人员或工人（临时工选「临时工工资」）",IF(AND(I9="账户互转",AD9=""),"✗ 账户互转要在「对方账户」选（借款、报销选那个人的个人户）",IF(AND(I9="账户互转",AF9=""),"✗ 对方账户不在【基础资料】② 里",IF(AND(I9="账户互转",AD9=C9),"✗ 对方账户不能是自己",IF(IF(I9="账户互转",COUNTIFS(资金流水!$C$6:$C$2005,AD9,资金流水!$AD$6:$AD$2005,C9,资金流水!$I$6:$I$2005,"账户互转",资金流水!$R$6:$R$2005,-R9)>0,FALSE),"✗ 对方账户那边也记了这笔互转（只记一边：清空其中一行的内容）",IF(AJ9>0,"⚠ 摘要里有两个项目：拆成几行，或在「改项目」选",IF(AND(I9<>"账户互转",O9<>""),"⚠ 填了对方账户但类别不是账户互转（对方账户不起作用）",IF(AND(J9<>"",Z9=""),"⚠ 单位/人没在【往来单位】登记",IF(AND(N(F9)<0,AH9="收"),"⚠ 这是收款，以后请记在收入栏",IF(N(E9)<0,"⚠ 收入填了负数，已按支出算",IF(N(F9)<0,"↩ 冲回（退款）",IF(AND(R9<0,I9<>"固定资产购置",I9<>"付应付款",ISNUMBER(B9),IFERROR(SUMPRODUCT(ISNUMBER(SEARCH(基础资料!$AJ$5:$AJ$34,D9))*(基础资料!$AJ$5:$AJ$34<>"")*((AN9-基础资料!$AK$5:$AK$34)<=30)*((AN9-基础资料!$AK$5:$AK$34)>=-30)),0)>0),"⚠ 像是在买【基础资料】⑥ 登记的车/设备：类别改成「固定资产购置」，不然成本算两遍",IF(AND(OR(I9="材料费",I9="分包费",I9="机械运输费",I9="其他直接费"),J9="",H9<>"",COUNTIFS(应付登记!$E$5:$E$1004,H9,应付登记!$G$5:$G$1004,-R9)>0),"⚠ 这个项目有同样金额的应付登记：是付那家的，改类别选「付应付款」、改单位选那家（不然成本算两遍）","√")))))))))))))))))))))))))))) -> √ | R9: =ROUND(N(E9)-N(F9),2) -> -3000 | S9: =IF(ISNUMBER(B9),YEAR(B9)*100+MONTH(B9),"") -> 202605 | T9: =IF(N(AK9)=0,"",INDEX(_辅助!$S$1:$S$240,AK9)) | U9: =IF(OR(D9="",R9=0),"",IF(AND(Z9="临时工",R9<0),"临时工工资",IF(AG9="",IF(AA9=1,"工资",IF(Z9="临时工","临时工工资",IF(Z9="甲方/总包","工程款",IF(AND(OR(Z9="材料供应商",Z9="分包",Z9="机械运输"),Y9=1),"付应付款","")))),IF(AND(Y9=1,OR(Z9="材料供应商",Z9="分包",Z9="机械运输",Z9="其他"),OR(AG9="材料费",AG9="分包费",AG9="机械运输费",AG9="其他直接费",AG9="工资",AG9="临时工工资")),"付应付款",AG9)))) -> 工资 | V9: =IF(D9="","",IF(N(AM9)>0,IF(N(AM9)=0,"",INDEX(_辅助!$W$1:$W$900,AM9)),IF(N(AL9)=0,"",INDEX(_辅助!$W$1:$W$900,AL9)))) -> 金南水 | W9: =IF(I9="","",IFERROR(INDEX(基础资料!$V$5:$V$64,MATCH(I9,基础资料!$S$5:$S$64,0))&"","？")) -> 不进利润 | X9: =IF(R9=0,"",IF(OR(I9="",IFERROR(INDEX(基础资料!$U$5:$U$64,MATCH(I9,基础资料!$S$5:$S$64,0))&"","")=""),"待分类",IF(OR(I9="付应付款",IFERROR(INDEX(基础资料!$U$5:$U$64,MATCH(I9,基础资料!$S$5:$S$64,0))&"","")="应付款"),IF(Z9="材料供应商","应付材料款",IF(Z9="分包","应付分包款",IF(Z9="机械运输","应付机械运输费","应付其他款"))),IFERROR(INDEX(基础资料!$U$5:$U$64,MATCH(I9,基础资料!$S$5:$S$64,0))&"","")))) -> 应付职工薪酬 | Y9: =IF(J9="",0,IF(COUNTIF(应付登记!$D$5:$D$1004,J9)+COUNTIF(期初余额!$P$5:$P$204,J9)>0,1,0)) -> 0 | Z9: =IF(J9="","",IFERROR(INDEX(往来单位!$C$4:$C$303,MATCH(J9,往来单位!$B$4:$B$303,0))&"","")) -> 工人 | AA9: =IF(OR(Z9="管理人员",Z9="工人"),1,0) -> 1 | AB9: =IF(ISERROR(FIND("代",D9)),"",IFERROR(MID(D9,FIND("代",D9)+1,FIND("付",D9,FIND("代",D9))-FIND("代",D9)-1),"")) | AC9: =IF(I9<>"账户互转","",IF(J9<>"",IFERROR(INDEX(_辅助!$G$1:$G$40,MATCH(J9,_辅助!$F$1:$F$40,0)),IF(IFERROR(MATCH(1,INDEX(ISNUMBER(SEARCH(_辅助!$Z$1:$Z$40,D9))*(_辅助!$Z$1:$Z$40<>""),0),0),0)=0,"",INDEX(_辅助!$AA$1:$AA$40,IFERROR(MATCH(1,INDEX(ISNUMBER(SEARCH(_辅助!$Z$1:$Z$40,D9))*(_辅助!$Z$1:$Z$40<>""),0),0),0)))),IF(IFERROR(MATCH(1,INDEX(ISNUMBER(SEARCH(_辅助!$Z$1:$Z$40,D9))*(_辅助!$Z$1:$Z$40<>""),0),0),0)=0,"",INDEX(_辅助!$AA$1:$AA$40,IFERROR(MATCH(1,INDEX(ISNUMBER(SEARCH(_辅助!$Z$1:$Z$40,D9))*(_辅助!$Z$1:$Z$40<>""),0),0),0))))) | AD9: =IF(O9<>"",O9,AC9) | AE9: =IF(C9="","",IFERROR(INDEX(基础资料!$H$5:$H$24,MATCH(C9,基础资料!$G$5:$G$24,0))&"","")) -> 银行 | AF9: =IF(AD9="","",IFERROR(INDEX(基础资料!$H$5:$H$24,MATCH(AD9,基础资料!$G$5:$G$24,0))&"","")) | AG9: =IF(OR(D9="",R9=0),"",IFERROR(INDEX(基础资料!$AC$5:$AC$164,IF(IF(F9<>"","支","收")="收",MATCH(1,INDEX(ISNUMBER(SEARCH(_辅助!$AB$1:$AB$160,D9))*(_辅助!$AB$1:$AB$160<>""),0),0),MATCH(1,INDEX(ISNUMBER(SEARCH(_辅助!$AC$1:$AC$160,D9))*(_辅助!$AC$1:$AC$160<>""),0),0)))&"","")) -> 工资 | AH9: =IF(R9=0,"",IF(OR(IFERROR(INDEX(基础资料!$T$5:$T$64,MATCH(I9,基础资料!$S$5:$S$64,0))&"","")="收",IFERROR(INDEX(基础资料!$T$5:$T$64,MATCH(I9,基础资料!$S$5:$S$64,0))&"","")="支"),IFERROR(INDEX(基础资料!$T$5:$T$64,MATCH(I9,基础资料!$S$5:$S$64,0))&"",""),IF(R9>0,"收","支"))) -> 支 | AI9: =IF(N(AK9)=0,"",INDEX(_辅助!$R$1:$R$240,AK9)) | AJ9: =IF(OR(AI9="",L9<>""),0,SUMPRODUCT(ISNUMBER(SEARCH(_辅助!$R$1:$R$240,D9))*(_辅助!$R$1:$R$240<>"")*(1-ISNUMBER(SEARCH(_辅助!$R$1:$R$240,AI9)))*(_辅助!$S$1:$S$240<>T9))) -> 0 | AK9: =IF(D9="",0,IFERROR(MATCH(1,INDEX(ISNUMBER(SEARCH(_辅助!$R$1:$R$240,D9))*(_辅助!$R$1:$R$240<>""),0),0),0)) -> 0 | AL9: =IF(D9="",0,IFERROR(MATCH(1,INDEX(ISNUMBER(SEARCH(_辅助!$V$1:$V$900,D9))*(_辅助!$V$1:$V$900<>""),0),0),0)) -> 57 | AM9: =IF(AB9="",0,IFERROR(MATCH(1,INDEX(ISNUMBER(SEARCH(_辅助!$V$1:$V$900,AB9))*(_辅助!$V$1:$V$900<>""),0),0),0)) -> 0 | AN9: =IF(ISNUMBER(B9),INT(B9),0) -> 46144 | AO9: =IF(AND(X9="应收账款",R9>0,AN9>0,H9<>""),H9&"|"&COUNTIFS(资金流水!$H$6:$H$2005,H9,资金流水!$X$6:$X$2005,"应收账款",资金流水!$R$6:$R$2005,">0",资金流水!$AN$6:$AN$2005,">0",资金流水!$AN$6:$AN$2005,"<="&AN9),"") | AP9: =IF(AND(J9<>"",R9<0,AN9>0),J9&"|"&COUNTIFS(资金流水!$J$6:$J$2005,J9,资金流水!$R$6:$R$2005,"<0",资金流水!$AN$6:$AN$2005,">0",资金流水!$AN$6:$AN$2005,"<="&AN9),"") -> 金南水|1 | AQ9: =IF(AND(X9="其他应收款",AN9>0,J9<>""),J9&"|"&(COUNTIFS(资金流水!$J$6:$J$2005,J9,资金流水!$X$6:$X$2005,"其他应收款",资金流水!$AN$6:$AN$2005,">0",资金流水!$AN$6:$AN$2005,"<"&AN9)+COUNTIFS($J$6:J9,J9,$X$6:X9,"其他应收款",$AN$6:AN9,AN9)),"")
A10: =IF(AND(B10="",D10="",E10="",F10=""),"",ROW()-5) -> 5 | B10: 46145 | C10: 九江银行 | D10: 付张亮亮工资 | F10: 4000 | G10: =IF(C10="","",ROUND(IFERROR(INDEX(基础资料!$K$5:$K$24,MATCH(C10,基础资料!$G$5:$G$24,0)),0)+SUMIFS($R$6:R10,$C$6:C10,C10)-SUMIFS($R$6:R10,$AD$6:AD10,C10,$X$6:X10,"账户互转"),2)) -> -28000 | H10: =IF(L10<>"",L10,T10) | I10: =IF(M10<>"",M10,U10) -> 工资 | J10: =IF(N10<>"",N10,V10) -> 张亮亮 | K10: =IF(AND(B10="",D10="",E10="",F10=""),"",IF(C10="","✗ 没选账户",IF(AE10="","✗ 账户不在【基础资料】② 里",IF(NOT(ISNUMBER(B10)),"✗ 日期要填成日期（2026/5/1）",IF(AND(ISNUMBER(B10),B10<基础资料!$C$9),"✗ 日期早于建账日期（建账前的放【期初余额】）",IF(AND(N(E10)<>0,N(F10)<>0),"✗ 收入、支出只填一边",IF(R10=0,"✗ 没有金额",IF(I10="","✗ 认不出收支类别：在「改类别」选",IF(W10="？","✗ 收支类别不在【基础资料】③ 里",IF(OR(I10="管理人员工资",I10="折旧费"),"✗ 这一类是自动算的，流水里不能选（发工资选「工资」，买设备选「固定资产购置」）",IF(AND(OR(X10="材料费",X10="人工费",X10="分包费",X10="机械运输费",X10="其他直接费",X10="票据贴息",X10="应收账款"),H10=""),"✗ 这一笔要选项目（摘要里的项目没在【项目档案】的话先去加上）",IF(AND(H10<>"",COUNTIF(项目档案!$B$4:$B$63,H10)=0),"✗ 项目不在【项目档案】里",IF(AND(OR(IFERROR(INDEX(基础资料!$W$5:$W$64,MATCH(I10,基础资料!$S$5:$S$64,0))&"","")="人",IFERROR(INDEX(基础资料!$W$5:$W$64,MATCH(I10,基础资料!$S$5:$S$64,0))&"","")="单位"),J10=""),"✗ 这一笔要选是谁（改单位/人）",IF(AND(I10="付应付款",NOT(OR(Z10="材料供应商",Z10="分包",Z10="机械运输",Z10="其他"))),"✗ 付应付款要选材料商、分包或机械单位",IF(AND(I10="付应付款",Y10=0),"✗ 这家没有应付：先在【应付登记】登记（现买现付的选材料费等）",IF(AND(OR(I10="工资",I10="工资退回"),AA10=0),"✗ 工资要选管理人员或工人（临时工选「临时工工资」）",IF(AND(I10="账户互转",AD10=""),"✗ 账户互转要在「对方账户」选（借款、报销选那个人的个人户）",IF(AND(I10="账户互转",AF10=""),"✗ 对方账户不在【基础资料】② 里",IF(AND(I10="账户互转",AD10=C10),"✗ 对方账户不能是自己",IF(IF(I10="账户互转",COUNTIFS(资金流水!$C$6:$C$2005,AD10,资金流水!$AD$6:$AD$2005,C10,资金流水!$I$6:$I$2005,"账户互转",资金流水!$R$6:$R$2005,-R10)>0,FALSE),"✗ 对方账户那边也记了这笔互转（只记一边：清空其中一行的内容）",IF(AJ10>0,"⚠ 摘要里有两个项目：拆成几行，或在「改项目」选",IF(AND(I10<>"账户互转",O10<>""),"⚠ 填了对方账户但类别不是账户互转（对方账户不起作用）",IF(AND(J10<>"",Z10=""),"⚠ 单位/人没在【往来单位】登记",IF(AND(N(F10)<0,AH10="收"),"⚠ 这是收款，以后请记在收入栏",IF(N(E10)<0,"⚠ 收入填了负数，已按支出算",IF(N(F10)<0,"↩ 冲回（退款）",IF(AND(R10<0,I10<>"固定资产购置",I10<>"付应付款",ISNUMBER(B10),IFERROR(SUMPRODUCT(ISNUMBER(SEARCH(基础资料!$AJ$5:$AJ$34,D10))*(基础资料!$AJ$5:$AJ$34<>"")*((AN10-基础资料!$AK$5:$AK$34)<=30)*((AN10-基础资料!$AK$5:$AK$34)>=-30)),0)>0),"⚠ 像是在买【基础资料】⑥ 登记的车/设备：类别改成「固定资产购置」，不然成本算两遍",IF(AND(OR(I10="材料费",I10="分包费",I10="机械运输费",I10="其他直接费"),J10="",H10<>"",COUNTIFS(应付登记!$E$5:$E$1004,H10,应付登记!$G$5:$G$1004,-R10)>0),"⚠ 这个项目有同样金额的应付登记：是付那家的，改类别选「付应付款」、改单位选那家（不然成本算两遍）","√")))))))))))))))))))))))))))) -> √ | R10: =ROUND(N(E10)-N(F10),2) -> -4000 | S10: =IF(ISNUMBER(B10),YEAR(B10)*100+MONTH(B10),"") -> 202605 | T10: =IF(N(AK10)=0,"",INDEX(_辅助!$S$1:$S$240,AK10)) | U10: =IF(OR(D10="",R10=0),"",IF(AND(Z10="临时工",R10<0),"临时工工资",IF(AG10="",IF(AA10=1,"工资",IF(Z10="临时工","临时工工资",IF(Z10="甲方/总包","工程款",IF(AND(OR(Z10="材料供应商",Z10="分包",Z10="机械运输"),Y10=1),"付应付款","")))),IF(AND(Y10=1,OR(Z10="材料供应商",Z10="分包",Z10="机械运输",Z10="其他"),OR(AG10="材料费",AG10="分包费",AG10="机械运输费",AG10="其他直接费",AG10="工资",AG10="临时工工资")),"付应付款",AG10)))) -> 工资 | V10: =IF(D10="","",IF(N(AM10)>0,IF(N(AM10)=0,"",INDEX(_辅助!$W$1:$W$900,AM10)),IF(N(AL10)=0,"",INDEX(_辅助!$W$1:$W$900,AL10)))) -> 张亮亮 | W10: =IF(I10="","",IFERROR(INDEX(基础资料!$V$5:$V$64,MATCH(I10,基础资料!$S$5:$S$64,0))&"","？")) -> 不进利润 | X10: =IF(R10=0,"",IF(OR(I10="",IFERROR(INDEX(基础资料!$U$5:$U$64,MATCH(I10,基础资料!$S$5:$S$64,0))&"","")=""),"待分类",IF(OR(I10="付应付款",IFERROR(INDEX(基础资料!$U$5:$U$64,MATCH(I10,基础资料!$S$5:$S$64,0))&"","")="应付款"),IF(Z10="材料供应商","应付材料款",IF(Z10="分包","应付分包款",IF(Z10="机械运输","应付机械运输费","应付其他款"))),IFERROR(INDEX(基础资料!$U$5:$U$64,MATCH(I10,基础资料!$S$5:$S$64,0))&"","")))) -> 应付职工薪酬 | Y10: =IF(J10="",0,IF(COUNTIF(应付登记!$D$5:$D$1004,J10)+COUNTIF(期初余额!$P$5:$P$204,J10)>0,1,0)) -> 0 | Z10: =IF(J10="","",IFERROR(INDEX(往来单位!$C$4:$C$303,MATCH(J10,往来单位!$B$4:$B$303,0))&"","")) -> 工人 | AA10: =IF(OR(Z10="管理人员",Z10="工人"),1,0) -> 1 | AB10: =IF(ISERROR(FIND("代",D10)),"",IFERROR(MID(D10,FIND("代",D10)+1,FIND("付",D10,FIND("代",D10))-FIND("代",D10)-1),"")) | AC10: =IF(I10<>"账户互转","",IF(J10<>"",IFERROR(INDEX(_辅助!$G$1:$G$40,MATCH(J10,_辅助!$F$1:$F$40,0)),IF(IFERROR(MATCH(1,INDEX(ISNUMBER(SEARCH(_辅助!$Z$1:$Z$40,D10))*(_辅助!$Z$1:$Z$40<>""),0),0),0)=0,"",INDEX(_辅助!$AA$1:$AA$40,IFERROR(MATCH(1,INDEX(ISNUMBER(SEARCH(_辅助!$Z$1:$Z$40,D10))*(_辅助!$Z$1:$Z$40<>""),0),0),0)))),IF(IFERROR(MATCH(1,INDEX(ISNUMBER(SEARCH(_辅助!$Z$1:$Z$40,D10))*(_辅助!$Z$1:$Z$40<>""),0),0),0)=0,"",INDEX(_辅助!$AA$1:$AA$40,IFERROR(MATCH(1,INDEX(ISNUMBER(SEARCH(_辅助!$Z$1:$Z$40,D10))*(_辅助!$Z$1:$Z$40<>""),0),0),0))))) | AD10: =IF(O10<>"",O10,AC10) | AE10: =IF(C10="","",IFERROR(INDEX(基础资料!$H$5:$H$24,MATCH(C10,基础资料!$G$5:$G$24,0))&"","")) -> 银行 | AF10: =IF(AD10="","",IFERROR(INDEX(基础资料!$H$5:$H$24,MATCH(AD10,基础资料!$G$5:$G$24,0))&"","")) | AG10: =IF(OR(D10="",R10=0),"",IFERROR(INDEX(基础资料!$AC$5:$AC$164,IF(IF(F10<>"","支","收")="收",MATCH(1,INDEX(ISNUMBER(SEARCH(_辅助!$AB$1:$AB$160,D10))*(_辅助!$AB$1:$AB$160<>""),0),0),MATCH(1,INDEX(ISNUMBER(SEARCH(_辅助!$AC$1:$AC$160,D10))*(_辅助!$AC$1:$AC$160<>""),0),0)))&"","")) -> 工资 | AH10: =IF(R10=0,"",IF(OR(IFERROR(INDEX(基础资料!$T$5:$T$64,MATCH(I10,基础资料!$S$5:$S$64,0))&"","")="收",IFERROR(INDEX(基础资料!$T$5:$T$64,MATCH(I10,基础资料!$S$5:$S$64,0))&"","")="支"),IFERROR(INDEX(基础资料!$T$5:$T$64,MATCH(I10,基础资料!$S$5:$S$64,0))&"",""),IF(R10>0,"收","支"))) -> 支 | AI10: =IF(N(AK10)=0,"",INDEX(_辅助!$R$1:$R$240,AK10)) | AJ10: =IF(OR(AI10="",L10<>""),0,SUMPRODUCT(ISNUMBER(SEARCH(_辅助!$R$1:$R$240,D10))*(_辅助!$R$1:$R$240<>"")*(1-ISNUMBER(SEARCH(_辅助!$R$1:$R$240,AI10)))*(_辅助!$S$1:$S$240<>T10))) -> 0 | AK10: =IF(D10="",0,IFERROR(MATCH(1,INDEX(ISNUMBER(SEARCH(_辅助!$R$1:$R$240,D10))*(_辅助!$R$1:$R$240<>""),0),0),0)) -> 0 | AL10: =IF(D10="",0,IFERROR(MATCH(1,INDEX(ISNUMBER(SEARCH(_辅助!$V$1:$V$900,D10))*(_辅助!$V$1:$V$900<>""),0),0),0)) -> 63 | AM10: =IF(AB10="",0,IFERROR(MATCH(1,INDEX(ISNUMBER(SEARCH(_辅助!$V$1:$V$900,AB10))*(_辅助!$V$1:$V$900<>""),0),0),0)) -> 0 | AN10: =IF(ISNUMBER(B10),INT(B10),0) -> 46145 | AO10: =IF(AND(X10="应收账款",R10>0,AN10>0,H10<>""),H10&"|"&COUNTIFS(资金流水!$H$6:$H$2005,H10,资金流水!$X$6:$X$2005,"应收账款",资金流水!$R$6:$R$2005,">0",资金流水!$AN$6:$AN$2005,">0",资金流水!$AN$6:$AN$2005,"<="&AN10),"") | AP10: =IF(AND(J10<>"",R10<0,AN10>0),J10&"|"&COUNTIFS(资金流水!$J$6:$J$2005,J10,资金流水!$R$6:$R$2005,"<0",资金流水!$AN$6:$AN$2005,">0",资金流水!$AN$6:$AN$2005,"<="&AN10),"") -> 张亮亮|1 | AQ10: =IF(AND(X10="其他应收款",AN10>0,J10<>""),J10&"|"&(COUNTIFS(资金流水!$J$6:$J$2005,J10,资金流水!$X$6:$X$2005,"其他应收款",资金流水!$AN$6:$AN$2005,">0",资金流水!$AN$6:$AN$2005,"<"&AN10)+COUNTIFS($J$6:J10,J10,$X$6:X10,"其他应收款",$AN$6:AN10,AN10)),"")
A11: =IF(AND(B11="",D11="",E11="",F11=""),"",ROW()-5) -> 6 | B11: 46148 | C11: 九江银行 | D11: 付共安门业材料款 | F11: 4940 | G11: =IF(C11="","",ROUND(IFERROR(INDEX(基础资料!$K$5:$K$24,MATCH(C11,基础资料!$G$5:$G$24,0)),0)+SUMIFS($R$6:R11,$C$6:C11,C11)-SUMIFS($R$6:R11,$AD$6:AD11,C11,$X$6:X11,"账户互转"),2)) -> -32940 | H11: =IF(L11<>"",L11,T11) | I11: =IF(M11<>"",M11,U11) -> 付应付款 | J11: =IF(N11<>"",N11,V11) -> 共安门业 | K11: =IF(AND(B11="",D11="",E11="",F11=""),"",IF(C11="","✗ 没选账户",IF(AE11="","✗ 账户不在【基础资料】② 里",IF(NOT(ISNUMBER(B11)),"✗ 日期要填成日期（2026/5/1）",IF(AND(ISNUMBER(B11),B11<基础资料!$C$9),"✗ 日期早于建账日期（建账前的放【期初余额】）",IF(AND(N(E11)<>0,N(F11)<>0),"✗ 收入、支出只填一边",IF(R11=0,"✗ 没有金额",IF(I11="","✗ 认不出收支类别：在「改类别」选",IF(W11="？","✗ 收支类别不在【基础资料】③ 里",IF(OR(I11="管理人员工资",I11="折旧费"),"✗ 这一类是自动算的，流水里不能选（发工资选「工资」，买设备选「固定资产购置」）",IF(AND(OR(X11="材料费",X11="人工费",X11="分包费",X11="机械运输费",X11="其他直接费",X11="票据贴息",X11="应收账款"),H11=""),"✗ 这一笔要选项目（摘要里的项目没在【项目档案】的话先去加上）",IF(AND(H11<>"",COUNTIF(项目档案!$B$4:$B$63,H11)=0),"✗ 项目不在【项目档案】里",IF(AND(OR(IFERROR(INDEX(基础资料!$W$5:$W$64,MATCH(I11,基础资料!$S$5:$S$64,0))&"","")="人",IFERROR(INDEX(基础资料!$W$5:$W$64,MATCH(I11,基础资料!$S$5:$S$64,0))&"","")="单位"),J11=""),"✗ 这一笔要选是谁（改单位/人）",IF(AND(I11="付应付款",NOT(OR(Z11="材料供应商",Z11="分包",Z11="机械运输",Z11="其他"))),"✗ 付应付款要选材料商、分包或机械单位",IF(AND(I11="付应付款",Y11=0),"✗ 这家没有应付：先在【应付登记】登记（现买现付的选材料费等）",IF(AND(OR(I11="工资",I11="工资退回"),AA11=0),"✗ 工资要选管理人员或工人（临时工选「临时工工资」）",IF(AND(I11="账户互转",AD11=""),"✗ 账户互转要在「对方账户」选（借款、报销选那个人的个人户）",IF(AND(I11="账户互转",AF11=""),"✗ 对方账户不在【基础资料】② 里",IF(AND(I11="账户互转",AD11=C11),"✗ 对方账户不能是自己",IF(IF(I11="账户互转",COUNTIFS(资金流水!$C$6:$C$2005,AD11,资金流水!$AD$6:$AD$2005,C11,资金流水!$I$6:$I$2005,"账户互转",资金流水!$R$6:$R$2005,-R11)>0,FALSE),"✗ 对方账户那边也记了这笔互转（只记一边：清空其中一行的内容）",IF(AJ11>0,"⚠ 摘要里有两个项目：拆成几行，或在「改项目」选",IF(AND(I11<>"账户互转",O11<>""),"⚠ 填了对方账户但类别不是账户互转（对方账户不起作用）",IF(AND(J11<>"",Z11=""),"⚠ 单位/人没在【往来单位】登记",IF(AND(N(F11)<0,AH11="收"),"⚠ 这是收款，以后请记在收入栏",IF(N(E11)<0,"⚠ 收入填了负数，已按支出算",IF(N(F11)<0,"↩ 冲回（退款）",IF(AND(R11<0,I11<>"固定资产购置",I11<>"付应付款",ISNUMBER(B11),IFERROR(SUMPRODUCT(ISNUMBER(SEARCH(基础资料!$AJ$5:$AJ$34,D11))*(基础资料!$AJ$5:$AJ$34<>"")*((AN11-基础资料!$AK$5:$AK$34)<=30)*((AN11-基础资料!$AK$5:$AK$34)>=-30)),0)>0),"⚠ 像是在买【基础资料】⑥ 登记的车/设备：类别改成「固定资产购置」，不然成本算两遍",IF(AND(OR(I11="材料费",I11="分包费",I11="机械运输费",I11="其他直接费"),J11="",H11<>"",COUNTIFS(应付登记!$E$5:$E$1004,H11,应付登记!$G$5:$G$1004,-R11)>0),"⚠ 这个项目有同样金额的应付登记：是付那家的，改类别选「付应付款」、改单位选那家（不然成本算两遍）","√")))))))))))))))))))))))))))) -> √ | R11: =ROUND(N(E11)-N(F11),2) -> -4940 | S11: =IF(ISNUMBER(B11),YEAR(B11)*100+MONTH(B11),"") -> 202605 | T11: =IF(N(AK11)=0,"",INDEX(_辅助!$S$1:$S$240,AK11)) | U11: =IF(OR(D11="",R11=0),"",IF(AND(Z11="临时工",R11<0),"临时工工资",IF(AG11="",IF(AA11=1,"工资",IF(Z11="临时工","临时工工资",IF(Z11="甲方/总包","工程款",IF(AND(OR(Z11="材料供应商",Z11="分包",Z11="机械运输"),Y11=1),"付应付款","")))),IF(AND(Y11=1,OR(Z11="材料供应商",Z11="分包",Z11="机械运输",Z11="其他"),OR(AG11="材料费",AG11="分包费",AG11="机械运输费",AG11="其他直接费",AG11="工资",AG11="临时工工资")),"付应付款",AG11)))) -> 付应付款 | V11: =IF(D11="","",IF(N(AM11)>0,IF(N(AM11)=0,"",INDEX(_辅助!$W$1:$W$900,AM11)),IF(N(AL11)=0,"",INDEX(_辅助!$W$1:$W$900,AL11)))) -> 共安门业 | W11: =IF(I11="","",IFERROR(INDEX(基础资料!$V$5:$V$64,MATCH(I11,基础资料!$S$5:$S$64,0))&"","？")) -> 不进利润 | X11: =IF(R11=0,"",IF(OR(I11="",IFERROR(INDEX(基础资料!$U$5:$U$64,MATCH(I11,基础资料!$S$5:$S$64,0))&"","")=""),"待分类",IF(OR(I11="付应付款",IFERROR(INDEX(基础资料!$U$5:$U$64,MATCH(I11,基础资料!$S$5:$S$64,0))&"","")="应付款"),IF(Z11="材料供应商","应付材料款",IF(Z11="分包","应付分包款",IF(Z11="机械运输","应付机械运输费","应付其他款"))),IFERROR(INDEX(基础资料!$U$5:$U$64,MATCH(I11,基础资料!$S$5:$S$64,0))&"","")))) -> 应付分包款 | Y11: =IF(J11="",0,IF(COUNTIF(应付登记!$D$5:$D$1004,J11)+COUNTIF(期初余额!$P$5:$P$204,J11)>0,1,0)) -> 1 | Z11: =IF(J11="","",IFERROR(INDEX(往来单位!$C$4:$C$303,MATCH(J11,往来单位!$B$4:$B$303,0))&"","")) -> 分包 | AA11: =IF(OR(Z11="管理人员",Z11="工人"),1,0) -> 0 | AB11: =IF(ISERROR(FIND("代",D11)),"",IFERROR(MID(D11,FIND("代",D11)+1,FIND("付",D11,FIND("代",D11))-FIND("代",D11)-1),"")) | AC11: =IF(I11<>"账户互转","",IF(J11<>"",IFERROR(INDEX(_辅助!$G$1:$G$40,MATCH(J11,_辅助!$F$1:$F$40,0)),IF(IFERROR(MATCH(1,INDEX(ISNUMBER(SEARCH(_辅助!$Z$1:$Z$40,D11))*(_辅助!$Z$1:$Z$40<>""),0),0),0)=0,"",INDEX(_辅助!$AA$1:$AA$40,IFERROR(MATCH(1,INDEX(ISNUMBER(SEARCH(_辅助!$Z$1:$Z$40,D11))*(_辅助!$Z$1:$Z$40<>""),0),0),0)))),IF(IFERROR(MATCH(1,INDEX(ISNUMBER(SEARCH(_辅助!$Z$1:$Z$40,D11))*(_辅助!$Z$1:$Z$40<>""),0),0),0)=0,"",INDEX(_辅助!$AA$1:$AA$40,IFERROR(MATCH(1,INDEX(ISNUMBER(SEARCH(_辅助!$Z$1:$Z$40,D11))*(_辅助!$Z$1:$Z$40<>""),0),0),0))))) | AD11: =IF(O11<>"",O11,AC11) | AE11: =IF(C11="","",IFERROR(INDEX(基础资料!$H$5:$H$24,MATCH(C11,基础资料!$G$5:$G$24,0))&"","")) -> 银行 | AF11: =IF(AD11="","",IFERROR(INDEX(基础资料!$H$5:$H$24,MATCH(AD11,基础资料!$G$5:$G$24,0))&"","")) | AG11: =IF(OR(D11="",R11=0),"",IFERROR(INDEX(基础资料!$AC$5:$AC$164,IF(IF(F11<>"","支","收")="收",MATCH(1,INDEX(ISNUMBER(SEARCH(_辅助!$AB$1:$AB$160,D11))*(_辅助!$AB$1:$AB$160<>""),0),0),MATCH(1,INDEX(ISNUMBER(SEARCH(_辅助!$AC$1:$AC$160,D11))*(_辅助!$AC$1:$AC$160<>""),0),0)))&"","")) -> 材料费 | AH11: =IF(R11=0,"",IF(OR(IFERROR(INDEX(基础资料!$T$5:$T$64,MATCH(I11,基础资料!$S$5:$S$64,0))&"","")="收",IFERROR(INDEX(基础资料!$T$5:$T$64,MATCH(I11,基础资料!$S$5:$S$64,0))&"","")="支"),IFERROR(INDEX(基础资料!$T$5:$T$64,MATCH(I11,基础资料!$S$5:$S$64,0))&"",""),IF(R11>0,"收","支"))) -> 支 | AI11: =IF(N(AK11)=0,"",INDEX(_辅助!$R$1:$R$240,AK11)) | AJ11: =IF(OR(AI11="",L11<>""),0,SUMPRODUCT(ISNUMBER(SEARCH(_辅助!$R$1:$R$240,D11))*(_辅助!$R$1:$R$240<>"")*(1-ISNUMBER(SEARCH(_辅助!$R$1:$R$240,AI11)))*(_辅助!$S$1:$S$240<>T11))) -> 0 | AK11: =IF(D11="",0,IFERROR(MATCH(1,INDEX(ISNUMBER(SEARCH(_辅助!$R$1:$R$240,D11))*(_辅助!$R$1:$R$240<>""),0),0),0)) -> 0 | AL11: =IF(D11="",0,IFERROR(MATCH(1,INDEX(ISNUMBER(SEARCH(_辅助!$V$1:$V$900,D11))*(_辅助!$V$1:$V$900<>""),0),0),0)) -> 38 | AM11: =IF(AB11="",0,IFERROR(MATCH(1,INDEX(ISNUMBER(SEARCH(_辅助!$V$1:$V$900,AB11))*(_辅助!$V$1:$V$900<>""),0),0),0)) -> 0 | AN11: =IF(ISNUMBER(B11),INT(B11),0) -> 46148 | AO11: =IF(AND(X11="应收账款",R11>0,AN11>0,H11<>""),H11&"|"&COUNTIFS(资金流水!$H$6:$H$2005,H11,资金流水!$X$6:$X$2005,"应收账款",资金流水!$R$6:$R$2005,">0",资金流水!$AN$6:$AN$2005,">0",资金流水!$AN$6:$AN$2005,"<="&AN11),"") | AP11: =IF(AND(J11<>"",R11<0,AN11>0),J11&"|"&COUNTIFS(资金流水!$J$6:$J$2005,J11,资金流水!$R$6:$R$2005,"<0",资金流水!$AN$6:$AN$2005,">0",资金流水!$AN$6:$AN$2005,"<="&AN11),"") -> 共安门业|2 | AQ11: =IF(AND(X11="其他应收款",AN11>0,J11<>""),J11&"|"&(COUNTIFS(资金流水!$J$6:$J$2005,J11,资金流水!$X$6:$X$2005,"其他应收款",资金流水!$AN$6:$AN$2005,">0",资金流水!$AN$6:$AN$2005,"<"&AN11)+COUNTIFS($J$6:J11,J11,$X$6:X11,"其他应收款",$AN$6:AN11,AN11)),"")
