Workbook
Name 年度: 基础资料!$B$5
Name 年初日: 基础资料!$B$7
Name 年末日: 基础资料!$B$8
Name 客户列表: OFFSET(总览汇总!$B$5,0,0,MAX(1,COUNTA(总览汇总!$B$5:$B$304)),1)
Name 商品列表: OFFSET(基础资料!$E$5,0,0,MAX(1,COUNTA(基础资料!$E$5:$E$104)),1)
Name 供应商列表: OFFSET(基础资料!$Q$5,0,0,MAX(1,COUNTA(基础资料!$Q$5:$Q$54)),1)
Name 账户列表: OFFSET(基础资料!$W$5,0,0,MAX(1,COUNTA(基础资料!$W$5:$W$24)),1)
Name 收支项目列表: OFFSET(基础资料!$AC$5,0,0,MAX(1,COUNTA(基础资料!$AC$5:$AC$34)),1)
Name 费用项目列表: OFFSET(基础资料!$AI$5,0,0,MAX(1,COUNTA(基础资料!$AI$5:$AI$54)),1)

Sheet 首页
A1: =IF(基础资料!B6="","饮料经销财务模板",基础资料!B6)&" · "&年度&"年度账" -> 饮料经销财务模板 · 2026年度账
A2: 💡 日常只录四张表：资金台帐（收钱付钱）、出库明细（送货）、存条明细（客户存条）、采购进货（进货）；报损照原来每月一张。其余全部自动：总览、库存、收付款明细、对账单、利润表、资产负债表。淡黄/白格子手填，灰格子别动。
A4: 关键数（截至今天录入的数据）
A5: 本年销售额 | B5: 本年毛利 | C5: 本年净利润 | D5: 当前资金余额 | E5: 客户欠我们 | F5: 客户存条/预存 | G5: 欠厂家货款 | H5: 数据校验待改项
A6: =利润表!Q7 -> 1707307.7 | B6: =利润表!Q12 -> 571498.93 | C6: =利润表!Q24 -> 553843.71 | D6: =基础资料!Y25 -> 3869309.7 | E6: =SUMIF(总览汇总!$G$5:$G$304,">0") -> 61456.5 | F6: =-SUMIF(总览汇总!$G$5:$G$304,"<0") -> 2223458.5 | G6: =SUMIF(_辅助!$K$5:$K$54,">0") -> 0 | H6: =数据校验!$C$32 -> 1
A7: 「欠厂家货款」按资产负债表选定月份月底算；其余是全年/当前数。
A9: 表格导航（点表名直接跳过去）
A10: 表名 | B10: 干什么的 | D10: 你要做什么
A11: 资金台帐 | B11: 收支混合录入，逐笔出账户余额和总余额 | D11: ★ 每收/付一笔钱记一行；收客户的选客户，付厂家的选供应商，花钱的选费用项目
A12: 出库明细 | B12: （原表）客户领货/送货 | D12: ★ 每次送货记一行
A13: 存条明细 | B13: （原表）客户存条（预付的货） | D13: ★ 客户存条时记，一个商品一行
A14: 采购进货 | B14: （新）从厂家进货 | D14: ★ 每张进货单记，厂家搭赠填赠品数量
A15: 2026年9月报损 | B15: （原表）每月过期报损 | D15: ★ 每月一张，照原来的填；新月份复制上月的表，并在基础资料登记表名
A16: 基础资料 | B16: 商品、供应商、资金账户、收支项目、费用项目 | D16: 新商品/新账户先在这里加；商品的参考进价要填
A17: 总览汇总 | B17: （原表）客户存条&货款总览——客户名单也在这 | D17: 新客户在 B 列加；已付款自动从资金台帐取
A18: 商品库存 | B18: （原表）每个客户每个商品的存条库存 | D18: 全自动
A19: 收付款明细 | B19: （原表）收付款明细 | D19: 全自动，从资金台帐提取
A20: 客户查询 | B20: （原表）客户快速查询 | D20: 选客户看
A21: 收付款汇总 | B21: 按月收付、按客户/供应商汇总 | D21: 全自动
... A29: 数据校验 | B29: 所有数据问题一表列出 | D29: 有 ✗ 就按提示改
A31: 钱和货是怎么流的
A32: 1. 客户付存条款/货款 → 资金台帐（选客户）→ 总览汇总「已付款」、收付款明细、客户对账单
A33: 2. 客户领货 → 出库明细 → 总览汇总「已领用」、商品库存、利润表「主营业务收入」、公司库存「出库」
A34: 3. 从厂家进货 → 采购进货 → 公司库存、成本计算（加权平均进价）、供应商对账单「进货」
A35: 4. 付厂家货款 → 资金台帐（选供应商）→ 供应商对账单「付款」、资产负债表「应付账款」
A36: 5. 各项开支 → 资金台帐（选费用项目）→ 费用汇总 → 利润表
A37: 6. 过期报损 → 各月报损表 → 报损汇总一览、利润表「商品报损损失」、公司库存「报损」
A39: 颜色
B40: 淡黄：手填的格子 | D40: 淡灰：公式自动算，别改 | F40: 亮黄：查询/报表的选择格 | H40: 淡红：校验发现的问题

Sheet 基础资料
A1: 基础资料（参数 · 商品 · 供应商 · 资金账户 · 收支项目 · 费用项目 · 报损月表）
A2: 💡 淡黄格子手填，灰格子自动。这里的清单就是各录入表的下拉内容——清单里没有的先在这里加一行，再去录。客户名单还在【总览汇总】B 列（跟原来一样，新客户在那里加）。不要插入或删除行，直接往下面的空行里填。
A3: 参数 | D3: 商品档案（出库 / 存条 / 采购 的「商品品类」都从这里选） | P3: 供应商档案 | V3: 资金账户（资金台帐「账户」下拉） | AB3: 收支项目（资金台帐「收支项目」下拉；前 6 个名称别改，公式按名字认） | AH3: 费用项目（资金台帐「费用项目」下拉） | AM3: 报损月表清单（几月的报损记在哪张表）
A4: 项目 | B4: 值 | D4: 序号 | E4: 商品名称 | F4: 供应商 (所属公司) | G4: 报损表品名 | H4: 规格 | I4: 每件 瓶数 | J4: 参考进价 (元/件) | K4: 参考售价 (元/件) | L4: 期初库存 (件) | M4: 期初单价 (元/件) | N4: 期初金额 (元) | P4: 序号 | Q4: 供应商名称 | R4: 年初应付(元) 正=我欠他 负=预付 | S4: 联系人/电话 | T4: 备注 | V4: 序号 | W4: 账户名称 | X4: 年初余额(元) | Y4: 当前余额(元) 自动 | Z4: 备注 | AB4: 序号 | AC4: 收支项目 | AD4: 方向 | AE4: 去向 | AF4: 说明 | AH4: 序号 | AI4: 费用项目 | AJ4: 利润表归类 | AK4: 说明 | AM4: 月份 | AN4: 报损表名 | AO4: 说明
A5: 会计年度 | B5: 2026 | D5: =IF(E5="","",ROW()-4) -> 1 | E5: 大东鹏 | F5: 东鹏公司 | G5: 东鹏500ML特饮 | H5: 1*24 | I5: 24 | J5: 77.52 | K5: 90 | N5: =IF(N(L5)=0,"",L5*N(M5)) | P5: =IF(Q5="","",ROW()-4) -> 1 | Q5: 东鹏公司 | T5: 东鹏特饮、补水啦、果之茶、大咖等 | V5: =IF(W5="","",ROW()-4) -> 1 | W5: 收款码 | Y5: =IF(W5="","",N(X5)+SUMIF(资金台帐!$C$7:$C$3006,W5,资金台帐!$F$7:$F$3006)-SUMIF(资金台帐!$C$7:$C$3006,W5,资金台帐!$G$7:$G$3006)) -> 3857959.7 | Z5: 原收付款明细的「收款码」 | AB5: =IF(AC5="","",ROW()-4) -> 1 | AC5: 客户回款 | AD5: 收 | AE5: 应收 | AF5: 客户付货款、存条款。要选【客户】，自动冲减他在总览汇总的未付货款 | AH5: =IF(AI5="","",ROW()-4) -> 1 | AI5: 工资 | AJ5: 销售费用 | AK5: 司机、业务员、装卸工工资 | AM5: 1 | AO5: =IF(AN5="","（这个月没有报损表）",IF(ISREF(INDIRECT("'"&AN5&"'!A1")),"√ 找到这张表","✗ 没有叫这个名字的表")) -> （这个月没有报损表）
A6: 公司名称 | D6: =IF(E6="","",ROW()-4) -> 2 | E6: 小东鹏 | F6: 东鹏公司 | G6: 东鹏250ML特饮 | H6: 1*24 | I6: 24 | J6: 37.92 | K6: 50 | N6: =IF(N(L6)=0,"",L6*N(M6)) | P6: =IF(Q6="","",ROW()-4) -> 2 | Q6: 农夫山泉公司 | T6: 农夫饮料、水 | V6: =IF(W6="","",ROW()-4) -> 2 | W6: 农业工账 | Y6: =IF(W6="","",N(X6)+SUMIF(资金台帐!$C$7:$C$3006,W6,资金台帐!$F$7:$F$3006)-SUMIF(资金台帐!$C$7:$C$3006,W6,资金台帐!$G$7:$G$3006)) -> 11350 | Z6: 原收付款明细第 39 行（阳光超市 11,350）用的账户 | AB6: =IF(AC6="","",ROW()-4) -> 2 | AC6: 客户退款 | AD6: 支 | AE6: 应收 | AF6: 退钱给客户。要选【客户】 | AH6: =IF(AI6="","",ROW()-4) -> 2 | AI6: 提成奖金 | AJ6: 销售费用 | AM6: 2 | AO6: =IF(AN6="","（这个月没有报损表）",IF(ISREF(INDIRECT("'"&AN6&"'!A1")),"√ 找到这张表","✗ 没有叫这个名字的表")) -> （这个月没有报损表）
A7: 年初日 | B7: =DATE(B5,1,1) -> 46023 | D7: =IF(E7="","",ROW()-4) -> 3 | E7: 555补水 | F7: 东鹏公司 | G7: 东鹏555补水 | H7: 1*24 | I7: 24 | J7: 54.816 | K7: 65 | N7: =IF(N(L7)=0,"",L7*N(M7)) | P7: =IF(Q7="","",ROW()-4) -> 3 | Q7: 青岛公司 | T7: 青岛啤酒 | V7: =IF(W7="","",ROW()-4) -> 3 | W7: 现金 | Y7: =IF(W7="","",N(X7)+SUMIF(资金台帐!$C$7:$C$3006,W7,资金台帐!$F$7:$F$3006)-SUMIF(资金台帐!$C$7:$C$3006,W7,资金台帐!$G$7:$G$3006)) -> 0 | AB7: =IF(AC7="","",ROW()-4) -> 3 | AC7: 供应商付款 | AD7: 支 | AE7: 应付 | AF7: 付厂家/供应商货款。要选【供应商】，自动冲减应付 | AH7: =IF(AI7="","",ROW()-4) -> 3 | AI7: 运费油费 | AJ7: 销售费用 | AK7: 送货油费、过路费、外请运输 | AM7: 3 | AO7: =IF(AN7="","（这个月没有报损表）",IF(ISREF(INDIRECT("'"&AN7&"'!A1")),"√ 找到这张表","✗ 没有叫这个名字的表")) -> （这个月没有报损表）
A8: 年末日 | B8: =DATE(B5,12,31) -> 46387 | D8: =IF(E8="","",ROW()-4) -> 4 | E8: 1L补水 | F8: 东鹏公司 | G8: 东鹏1L补水 | H8: 1*12 | I8: 12 | J8: 43.2696 | K8: 55 | N8: =IF(N(L8)=0,"",L8*N(M8)) | P8: =IF(Q8="","",ROW()-4) -> 4 | Q8: 其他公司 | T8: 艾精隆瓜子花生等 | V8: =IF(W8="","",ROW()-4) -> 4 | W8: 微信 | Y8: =IF(W8="","",N(X8)+SUMIF(资金台帐!$C$7:$C$3006,W8,资金台帐!$F$7:$F$3006)-SUMIF(资金台帐!$C$7:$C$3006,W8,资金台帐!$G$7:$G$3006)) -> 0 | AB8: =IF(AC8="","",ROW()-4) -> 4 | AC8: 供应商退款 | AD8: 收 | AE8: 应付 | AF8: 厂家退回来的货款。要选【供应商】 | AH8: =IF(AI8="","",ROW()-4) -> 4 | AI8: 车辆费用 | AJ8: 销售费用 | AK8: 车辆保养维修、保险、年检 | AM8: 4 | AO8: =IF(AN8="","（这个月没有报损表）",IF(ISREF(INDIRECT("'"&AN8&"'!A1")),"√ 找到这张表","✗ 没有叫这个名字的表")) -> （这个月没有报损表）
A9: 年初借款余额 | B9: 0 | D9: =IF(E9="","",ROW()-4) -> 5 | E9: 小果之茶 | F9: 东鹏公司 | G9: 东鹏小果茶 | H9: 1*24 | I9: 24 | K9: 47 | N9: =IF(N(L9)=0,"",L9*N(M9)) | P9: =IF(Q9="","",ROW()-4) | V9: =IF(W9="","",ROW()-4) -> 5 | W9: 支付宝 | Y9: =IF(W9="","",N(X9)+SUMIF(资金台帐!$C$7:$C$3006,W9,资金台帐!$F$7:$F$3006)-SUMIF(资金台帐!$C$7:$C$3006,W9,资金台帐!$G$7:$G$3006)) -> 0 | AB9: =IF(AC9="","",ROW()-4) -> 5 | AC9: 厂家返利 | AD9: 收 | AE9: 返利收入 | AF9: 返利、陈列补贴、报损补偿等厂家给的钱，建议选上【供应商】 | AH9: =IF(AI9="","",ROW()-4) -> 5 | AI9: 装卸费 | AJ9: 销售费用 | AM9: 5 | AO9: =IF(AN9="","（这个月没有报损表）",IF(ISREF(INDIRECT("'"&AN9&"'!A1")),"√ 找到这张表","✗ 没有叫这个名字的表")) -> （这个月没有报损表）
A10: 年初其他应收(+)/应付(-) | B10: 0 | D10: =IF(E10="","",ROW()-4) -> 6 | E10: 1L果之茶 | F10: 东鹏公司 | G10: 东鹏1L果之茶 | H10: 1*12 | I10: 12 | K10: 43 | N10: =IF(N(L10)=0,"",L10*N(M10)) | P10: =IF(Q10="","",ROW()-4) | V10: =IF(W10="","",ROW()-4) -> 6 | W10: 银行卡 | Y10: =IF(W10="","",N(X10)+SUMIF(资金台帐!$C$7:$C$3006,W10,资金台帐!$F$7:$F$3006)-SUMIF(资金台帐!$C$7:$C$3006,W10,资金台帐!$G$7:$G$3006)) -> 0 | AB10: =IF(AC10="","",ROW()-4) -> 6 | AC10: 费用支出 | AD10: 支 | AE10: 费用 | AF10: 工资、运费、房租……要选【费用项目】 | AH10: =IF(AI10="","",ROW()-4) -> 6 | AI10: 促销陈列费 | AJ10: 销售费用 | AK10: 给店里的陈列费、促销品（厂家报销的记厂家返利） | AM10: 6 | AN10: 报损明细台账 | AO10: =IF(AN10="","（这个月没有报损表）",IF(ISREF(INDIRECT("'"&AN10&"'!A1")),"√ 找到这张表","✗ 没有叫这个名字的表")) -> √ 找到这张表
D11: =IF(E11="","",ROW()-4) -> 7 | E11: 港式奶茶 | F11: 东鹏公司 | G11: 东鹏港式奶茶 | H11: 1*24 | I11: 24 | K11: 69 | N11: =IF(N(L11)=0,"",L11*N(M11)) | P11: =IF(Q11="","",ROW()-4) | V11: =IF(W11="","",ROW()-4) | Y11: =IF(W11="","",N(X11)+SUMIF(资金台帐!$C$7:$C$3006,W11,资金台帐!$F$7:$F$3006)-SUMIF(资金台帐!$C$7:$C$3006,W11,资金台帐!$G$7:$G$3006)) | AB11: =IF(AC11="","",ROW()-4) -> 7 | AC11: 其他收入 | AD11: 收 | AE11: 其他收入 | AF11: 卖废品/空箱、利息等零星收入 | AH11: =IF(AI11="","",ROW()-4) -> 7 | AI11: 业务招待费 | AJ11: 管理费用 | AM11: 7 | AN11: 2026年7月报损 | AO11: =IF(AN11="","（这个月没有报损表）",IF(ISREF(INDIRECT("'"&AN11&"'!A1")),"√ 找到这张表","✗ 没有叫这个名字的表")) -> √ 找到这张表
A12: 「去向」说明（收支项目落到报表哪一行） | D12: =IF(E12="","",ROW()-4) -> 8 | E12: 大咖 | F12: 东鹏公司 | G12: 东鹏500大咖 | H12: 1*15 | I12: 15 | J12: 73.08 | K12: 83 | N12: =IF(N(L12)=0,"",L12*N(M12)) | P12: =IF(Q12="","",ROW()-4) | V12: =IF(W12="","",ROW()-4) | Y12: =IF(W12="","",N(X12)+SUMIF(资金台帐!$C$7:$C$3006,W12,资金台帐!$F$7:$F$3006)-SUMIF(资金台帐!$C$7:$C$3006,W12,资金台帐!$G$7:$G$3006)) | AB12: =IF(AC12="","",ROW()-4) -> 8 | AC12: 股东投入 | AD12: 收 | AE12: 投入 | AF12: 老板往账上投钱 | AH12: =IF(AI12="","",ROW()-4) -> 8 | AI12: 管理人员工资 | AJ12: 管理费用 | AM12: 8 | AN12: 2026年8月报损 | AO12: =IF(AN12="","（这个月没有报损表）",IF(ISREF(INDIRECT("'"&AN12&"'!A1")),"√ 找到这张表","✗ 没有叫这个名字的表")) -> √ 找到这张表
A13: 应收 | B13: 冲减客户未付货款（总览汇总·已付款） | D13: =IF(E13="","",ROW()-4) -> 9 | E13: 330大咖 | F13: 东鹏公司 | K13: 90 | N13: =IF(N(L13)=0,"",L13*N(M13)) | P13: =IF(Q13="","",ROW()-4) | V13: =IF(W13="","",ROW()-4) | Y13: =IF(W13="","",N(X13)+SUMIF(资金台帐!$C$7:$C$3006,W13,资金台帐!$F$7:$F$3006)-SUMIF(资金台帐!$C$7:$C$3006,W13,资金台帐!$G$7:$G$3006)) | AB13: =IF(AC13="","",ROW()-4) -> 9 | AC13: 股东提取 | AD13: 支 | AE13: 提取 | AF13: 老板从账上拿钱自用 | AH13: =IF(AI13="","",ROW()-4) -> 9 | AI13: 仓库租金 | AJ13: 管理费用 | AM13: 9 | AN13: 2026年9月报损 | AO13: =IF(AN13="","（这个月没有报损表）",IF(ISREF(INDIRECT("'"&AN13&"'!A1")),"√ 找到这张表","✗ 没有叫这个名字的表")) -> √ 找到这张表
A14: 应付 | B14: 冲减欠供应商的货款 | D14: =IF(E14="","",ROW()-4) -> 10 | E14: 小咖 | F14: 东鹏公司 | K14: 90 | N14: =IF(N(L14)=0,"",L14*N(M14)) | P14: =IF(Q14="","",ROW()-4) | V14: =IF(W14="","",ROW()-4) | Y14: =IF(W14="","",N(X14)+SUMIF(资金台帐!$C$7:$C$3006,W14,资金台帐!$F$7:$F$3006)-SUMIF(资金台帐!$C$7:$C$3006,W14,资金台帐!$G$7:$G$3006)) | AB14: =IF(AC14="","",ROW()-4) -> 10 | AC14: 借入款项 | AD14: 收 | AE14: 借款 | AF14: 借进来的钱 | AH14: =IF(AI14="","",ROW()-4) -> 10 | AI14: 水电费 | AJ14: 管理费用 | AM14: 10 | AO14: =IF(AN14="","（这个月没有报损表）",IF(ISREF(INDIRECT("'"&AN14&"'!A1")),"√ 找到这张表","✗ 没有叫这个名字的表")) -> （这个月没有报损表）
A15: 费用 | B15: 按费用项目进利润表 | D15: =IF(E15="","",ROW()-4) -> 11 | E15: 小海岛椰 | F15: 东鹏公司 | G15: 东鹏小海岛椰 | H15: 1*12 | I15: 12 | J15: 29.52 | K15: 32 | N15: =IF(N(L15)=0,"",L15*N(M15)) | P15: =IF(Q15="","",ROW()-4) | V15: =IF(W15="","",ROW()-4) | Y15: =IF(W15="","",N(X15)+SUMIF(资金台帐!$C$7:$C$3006,W15,资金台帐!$F$7:$F$3006)-SUMIF(资金台帐!$C$7:$C$3006,W15,资金台帐!$G$7:$G$3006)) | AB15: =IF(AC15="","",ROW()-4) -> 11 | AC15: 归还借款 | AD15: 支 | AE15: 借款 | AF15: 还借款本金（利息记「费用支出·利息支出」） | AH15: =IF(AI15="","",ROW()-4) -> 11 | AI15: 通讯费 | AJ15: 管理费用 | AM15: 11 | AO15: =IF(AN15="","（这个月没有报损表）",IF(ISREF(INDIRECT("'"&AN15&"'!A1")),"√ 找到这张表","✗ 没有叫这个名字的表")) -> （这个月没有报损表）
A16: 返利收入 | B16: 利润表·其他业务收入 | D16: =IF(E16="","",ROW()-4) -> 12 | E16: 330海岛椰 | F16: 东鹏公司 | K16: 36 | N16: =IF(N(L16)=0,"",L16*N(M16)) | P16: =IF(Q16="","",ROW()-4) | V16: =IF(W16="","",ROW()-4) | Y16: =IF(W16="","",N(X16)+SUMIF(资金台帐!$C$7:$C$3006,W16,资金台帐!$F$7:$F$3006)-SUMIF(资金台帐!$C$7:$C$3006,W16,资金台帐!$G$7:$G$3006)) | AB16: =IF(AC16="","",ROW()-4) -> 12 | AC16: 内部转账 | AD16: 收支 | AE16: 转账 | AF16: 账户之间互转：转出账户记一行支出、转入账户记一行收入，两行都选这个 | AH16: =IF(AI16="","",ROW()-4) -> 12 | AI16: 办公费 | AJ16: 管理费用 | AM16: 12 | AO16: =IF(AN16="","（这个月没有报损表）",IF(ISREF(INDIRECT("'"&AN16&"'!A1")),"√ 找到这张表","✗ 没有叫这个名字的表")) -> （这个月没有报损表）
A17: 其他收入 | B17: 利润表·营业外收入 | D17: =IF(E17="","",ROW()-4) -> 13 | E17: 1.25海岛椰 | F17: 东鹏公司 | G17: 东鹏1.25L海岛椰 | H17: 1*6 | I17: 6 | K17: 51 | N17: =IF(N(L17)=0,"",L17*N(M17)) | P17: =IF(Q17="","",ROW()-4) | V17: =IF(W17="","",ROW()-4) | Y17: =IF(W17="","",N(X17)+SUMIF(资金台帐!$C$7:$C$3006,W17,资金台帐!$F$7:$F$3006)-SUMIF(资金台帐!$C$7:$C$3006,W17,资金台帐!$G$7:$G$3006)) | AB17: =IF(AC17="","",ROW()-4) -> 13 | AC17: 其他往来 | AD17: 收支 | AE17: 其他往来 | AF17: 押金、代收代付等以后要收回/付出的钱 | AH17: =IF(AI17="","",ROW()-4) -> 13 | AI17: 其他费用 | AJ17: 管理费用
A18: 投入 | B18: 资产负债表·股东投入 | D18: =IF(E18="","",ROW()-4) -> 14 | E18: 东鹏椰子水 | F18: 东鹏公司 | K18: 90 | N18: =IF(N(L18)=0,"",L18*N(M18)) | P18: =IF(Q18="","",ROW()-4) | V18: =IF(W18="","",ROW()-4) | Y18: =IF(W18="","",N(X18)+SUMIF(资金台帐!$C$7:$C$3006,W18,资金台帐!$F$7:$F$3006)-SUMIF(资金台帐!$C$7:$C$3006,W18,资金台帐!$G$7:$G$3006)) | AB18: =IF(AC18="","",ROW()-4) | AH18: =IF(AI18="","",ROW()-4) -> 14 | AI18: 手续费 | AJ18: 财务费用 | AK18: 收款码/银行手续费 | AM18: 新的一个月：右键上个月的报损表→移动或复制→建立副本，改成「2026年10月报损」这样的表名，清掉数量，再回这里填上表名。
A19: 提取 | B19: 资产负债表·股东提取 | D19: =IF(E19="","",ROW()-4) -> 15 | E19: 555椰子水 | F19: 东鹏公司 | K19: 93 | N19: =IF(N(L19)=0,"",L19*N(M19)) | P19: =IF(Q19="","",ROW()-4) | V19: =IF(W19="","",ROW()-4) | Y19: =IF(W19="","",N(X19)+SUMIF(资金台帐!$C$7:$C$3006,W19,资金台帐!$F$7:$F$3006)-SUMIF(资金台帐!$C$7:$C$3006,W19,资金台帐!$G$7:$G$3006)) | AB19: =IF(AC19="","",ROW()-4) | AH19: =IF(AI19="","",ROW()-4) -> 15 | AI19: 利息支出 | AJ19: 财务费用
A20: 借款 | B20: 资产负债表·短期借款 | D20: =IF(E20="","",ROW()-4) -> 16 | E20: 菊花茶 | F20: 东鹏公司 | G20: 东鹏菊花茶 | H20: 1*24 | I20: 24 | J20: 59.616 | N20: =IF(N(L20)=0,"",L20*N(M20)) | P20: =IF(Q20="","",ROW()-4) | V20: =IF(W20="","",ROW()-4) | Y20: =IF(W20="","",N(X20)+SUMIF(资金台帐!$C$7:$C$3006,W20,资金台帐!$F$7:$F$3006)-SUMIF(资金台帐!$C$7:$C$3006,W20,资金台帐!$G$7:$G$3006)) | AB20: =IF(AC20="","",ROW()-4) | AH20: =IF(AI20="","",ROW()-4) -> 16 | AI20: 税费 | AJ20: 税金及附加 | AK20: 按实际交的钱计
A21: 转账 | B21: 账户互转，不进报表（收支要成对） | D21: =IF(E21="","",ROW()-4) -> 17 | E21: 九制陈皮 | K21: 47 | N21: =IF(N(L21)=0,"",L21*N(M21)) | P21: =IF(Q21="","",ROW()-4) | V21: =IF(W21="","",ROW()-4) | Y21: =IF(W21="","",N(X21)+SUMIF(资金台帐!$C$7:$C$3006,W21,资金台帐!$F$7:$F$3006)-SUMIF(资金台帐!$C$7:$C$3006,W21,资金台帐!$G$7:$G$3006)) | AB21: =IF(AC21="","",ROW()-4) | AH21: =IF(AI21="","",ROW()-4) -> 17 | AI21: 罚款赔偿 | AJ21: 营业外支出
A22: 其他往来 | B22: 其他应收 / 其他应付（押金等） | D22: =IF(E22="","",ROW()-4) -> 18 | E22: 小焙好茶 | K22: 48 | N22: =IF(N(L22)=0,"",L22*N(M22)) | P22: =IF(Q22="","",ROW()-4) | V22: =IF(W22="","",ROW()-4) | Y22: =IF(W22="","",N(X22)+SUMIF(资金台帐!$C$7:$C$3006,W22,资金台帐!$F$7:$F$3006)-SUMIF(资金台帐!$C$7:$C$3006,W22,资金台帐!$G$7:$G$3006)) | AB22: =IF(AC22="","",ROW()-4) | AH22: =IF(AI22="","",ROW()-4) -> 18 | AI22: 所得税 | AJ22: 所得税费用
D23: =IF(E23="","",ROW()-4) -> 19 | E23: 1L焙好茶 | K23: 46 | N23: =IF(N(L23)=0,"",L23*N(M23)) | P23: =IF(Q23="","",ROW()-4) | V23: =IF(W23="","",ROW()-4) | Y23: =IF(W23="","",N(X23)+SUMIF(资金台帐!$C$7:$C$3006,W23,资金台帐!$F$7:$F$3006)-SUMIF(资金台帐!$C$7:$C$3006,W23,资金台帐!$G$7:$G$3006)) | AB23: =IF(AC23="","",ROW()-4) | AH23: =IF(AI23="","",ROW()-4)
D24: =IF(E24="","",ROW()-4) -> 20 | E24: 大鹏 | K24: 86 | N24: =IF(N(L24)=0,"",L24*N(M24)) | P24: =IF(Q24="","",ROW()-4) | V24: =IF(W24="","",ROW()-4) | Y24: =IF(W24="","",N(X24)+SUMIF(资金台帐!$C$7:$C$3006,W24,资金台帐!$F$7:$F$3006)-SUMIF(资金台帐!$C$7:$C$3006,W24,资金台帐!$G$7:$G$3006)) | AB24: =IF(AC24="","",ROW()-4) | AH24: =IF(AI24="","",ROW()-4)
D25: =IF(E25="","",ROW()-4) -> 21 | E25: 500农夫饮料 | F25: 农夫山泉公司 | G25: 农夫500ML饮料 | H25: 1*15 | I25: 15 | J25: 46.005 | K25: 52 | N25: =IF(N(L25)=0,"",L25*N(M25)) | P25: =IF(Q25="","",ROW()-4) | W25: 合计 | X25: =SUM(X5:X24) -> 0 | Y25: =SUM(Y5:Y24) -> 3869309.7 | AB25: =IF(AC25="","",ROW()-4) | AH25: =IF(AI25="","",ROW()-4)
D26: =IF(E26="","",ROW()-4) -> 22 | E26: 900农夫饮料 | F26: 农夫山泉公司 | G26: 农夫900ML饮料 | H26: 1*12 | I26: 12 | J26: 50.04 | K26: 62 | N26: =IF(N(L26)=0,"",L26*N(M26)) | P26: =IF(Q26="","",ROW()-4) | AB26: =IF(AC26="","",ROW()-4) | AH26: =IF(AI26="","",ROW()-4)
D27: =IF(E27="","",ROW()-4) -> 23 | E27: 550农夫水 | F27: 农夫山泉公司 | G27: 农夫550ML水 | H27: 1*24 | I27: 24 | J27: 20.016 | K27: 20 | N27: =IF(N(L27)=0,"",L27*N(M27)) | P27: =IF(Q27="","",ROW()-4) | AB27: =IF(AC27="","",ROW()-4) | AH27: =IF(AI27="","",ROW()-4)
D28: =IF(E28="","",ROW()-4) -> 24 | E28: 550农夫纯净水 | F28: 农夫山泉公司 | G28: 农夫550ML纯净水 | H28: 1*24 | I28: 24 | J28: 15 | K28: 14 | N28: =IF(N(L28)=0,"",L28*N(M28)) | P28: =IF(Q28="","",ROW()-4) | AB28: =IF(AC28="","",ROW()-4) | AH28: =IF(AI28="","",ROW()-4)
D29: =IF(E29="","",ROW()-4) -> 25 | E29: 550纯净水12入 | F29: 农夫山泉公司 | H29: 1*12 | I29: 12 | J29: 7.5 | K29: 7.6 | N29: =IF(N(L29)=0,"",L29*N(M29)) | P29: =IF(Q29="","",ROW()-4) | AB29: =IF(AC29="","",ROW()-4) | AH29: =IF(AI29="","",ROW()-4)
D30: =IF(E30="","",ROW()-4) -> 26 | E30: 1.5L水 | F30: 农夫山泉公司 | G30: 农夫1.5L水 | H30: 1*12 | I30: 12 | J30: 20.004 | K30: 25 | N30: =IF(N(L30)=0,"",L30*N(M30)) | P30: =IF(Q30="","",ROW()-4) | AB30: =IF(AC30="","",ROW()-4) | AH30: =IF(AI30="","",ROW()-4)
D31: =IF(E31="","",ROW()-4) -> 27 | E31: 农夫苏打水 | F31: 农夫山泉公司 | G31: 农夫苏打水 | H31: 1*15 | I31: 15 | J31: 34.05 | N31: =IF(N(L31)=0,"",L31*N(M31)) | P31: =IF(Q31="","",ROW()-4) | AB31: =IF(AC31="","",ROW()-4) | AH31: =IF(AI31="","",ROW()-4)
D32: =IF(E32="","",ROW()-4) -> 28 | E32: 农夫2L水 | F32: 农夫山泉公司 | G32: 农夫2L水 | H32: 1*8 | I32: 8 | J32: 18 | N32: =IF(N(L32)=0,"",L32*N(M32)) | P32: =IF(Q32="","",ROW()-4) | AB32: =IF(AC32="","",ROW()-4) | AH32: =IF(AI32="","",ROW()-4)
D33: =IF(E33="","",ROW()-4) -> 29 | E33: 农夫5L水 | F33: 农夫山泉公司 | G33: 农夫5L水 | H33: 1*4 | I33: 4 | N33: =IF(N(L33)=0,"",L33*N(M33)) | P33: =IF(Q33="","",ROW()-4) | AB33: =IF(AC33="","",ROW()-4) | AH33: =IF(AI33="","",ROW()-4)
D34: =IF(E34="","",ROW()-4) -> 30 | E34: 农夫12.9L水 | F34: 农夫山泉公司 | G34: 农夫12.9L水 | N34: =IF(N(L34)=0,"",L34*N(M34)) | P34: =IF(Q34="","",ROW()-4) | AB34: =IF(AC34="","",ROW()-4) | AH34: =IF(AI34="","",ROW()-4)
D35: =IF(E35="","",ROW()-4) -> 31 | E35: 农夫1.25L果园 | F35: 农夫山泉公司 | G35: 农夫1.25L果园 | H35: 1*6 | I35: 6 | J35: 38.5 | N35: =IF(N(L35)=0,"",L35*N(M35)) | P35: =IF(Q35="","",ROW()-4) | AH35: =IF(AI35="","",ROW()-4)
D36: =IF(E36="","",ROW()-4) -> 32 | E36: 农夫1.5L东方树叶 | F36: 农夫山泉公司 | G36: 农夫1.5L东方树叶 | H36: 1*6 | I36: 6 | J36: 42 | N36: =IF(N(L36)=0,"",L36*N(M36)) | P36: =IF(Q36="","",ROW()-4) | AH36: =IF(AI36="","",ROW()-4)
D37: =IF(E37="","",ROW()-4) -> 33 | E37: 清爽 | F37: 青岛公司 | G37: 青岛清爽8 | H37: 1*12 | I37: 12 | J37: 35.28 | K37: 42 | N37: =IF(N(L37)=0,"",L37*N(M37)) | P37: =IF(Q37="","",ROW()-4) | AH37: =IF(AI37="","",ROW()-4)
D38: =IF(E38="","",ROW()-4) -> 34 | E38: 青岛清爽8奖盖过期 | F38: 青岛公司 | G38: 青岛清爽8奖盖过期 | H38: 1*12 | I38: 12 | J38: 35.28 | N38: =IF(N(L38)=0,"",L38*N(M38)) | P38: =IF(Q38="","",ROW()-4) | AH38: =IF(AI38="","",ROW()-4)
D39: =IF(E39="","",ROW()-4) -> 35 | E39: 青岛经典 | F39: 青岛公司 | G39: 青岛经典 | H39: 1*12 | I39: 12 | J39: 50.04 | N39: =IF(N(L39)=0,"",L39*N(M39)) | P39: =IF(Q39="","",ROW()-4) | AH39: =IF(AI39="","",ROW()-4)
D40: =IF(E40="","",ROW()-4) -> 36 | E40: 青岛崂山 | F40: 青岛公司 | G40: 青岛崂山 | H40: 1*12 | I40: 12 | J40: 24 | N40: =IF(N(L40)=0,"",L40*N(M40)) | P40: =IF(Q40="","",ROW()-4) | AH40: =IF(AI40="","",ROW()-4)
...

Sheet 资金台帐
A1: 资金台帐（收支混合录入 · 即时余额）
A2: 💡 一笔一行，按发生顺序往下记：收钱填【收入金额】，付钱填【支出金额】，右边【账户余额】【总余额】自动滚出来。收客户的钱选【客户】、付厂家货款选【供应商】、花钱选【费用项目】——总览汇总、收付款明细、对账单、利润表都从这里自动取数。选了客户/供应商/费用项目的，【收支项目】可以不选，会自动认。
A3: 月份： | B3: 9 | C3: 本月收入： | D3: =SUMIFS($F$7:$F$3006,$B$7:$B$3006,">="&DATE(年度,$B$3,1),$B$7:$B$3006,"<"&DATE(年度,$B$3+1,1),$P$7:$P$3006,"<>转账") -> 2700 | E3: 本月支出： | F3: =SUMIFS($G$7:$G$3006,$B$7:$B$3006,">="&DATE(年度,$B$3,1),$B$7:$B$3006,"<"&DATE(年度,$B$3+1,1),$P$7:$P$3006,"<>转账") -> 0 | G3: 上月结余： | H3: =SUM(基础资料!$X$5:$X$24)+SUMIFS($F$7:$F$3006,$B$7:$B$3006,">="&年初日,$B$7:$B$3006,"<"&DATE(年度,$B$3,1))-SUMIFS($G$7:$G$3006,$B$7:$B$3006,">="&年初日,$B$7:$B$3006,"<"&DATE(年度,$B$3,1)) -> 3866609.7 | I3: 本月结余： | J3: =SUM(基础资料!$X$5:$X$24)+SUMIFS($F$7:$F$3006,$B$7:$B$3006,">="&年初日,$B$7:$B$3006,"<"&DATE(年度,$B$3+1,1))-SUMIFS($G$7:$G$3006,$B$7:$B$3006,">="&年初日,$B$7:$B$3006,"<"&DATE(年度,$B$3+1,1)) -> 3869309.7 | K3: 当前总余额： | L3: =SUM(基础资料!$X$5:$X$24)+SUM($F$7:$F$3006)-SUM($G$7:$G$3006) -> 3869309.7 | M3: 按日期统计，本月收入/支出不含内部转账
A5: 登 记 信 息 | F5: ＋ 收 入 | G5: ＋ 支 出 | H5: 即时余额（自动） | J5: 往来 / 费用（筛选列） | M5: 备注 / 校验
A6: 序号 | B6: 日期 | C6: 账户 | D6: 收支项目 | E6: 摘要 | F6: 收入金额 | G6: 支出金额 | H6: 账户余额 | I6: 总余额 | J6: 客户 | K6: 供应商 | L6: 费用项目 | M6: 备注 | N6: 校验 | O6: 实际项目 | P6: 去向 | Q6: 客户收款序 | R6: 供应商付款序 | S6: 净额
A7: =IF(AND(F7="",G7=""),"",ROW()-6) -> 1 | B7: 46156 | C7: 收款码 | D7: 客户回款 | E7: 收货款 | F7: 100000 | H7: =IF(OR(C7="",AND(F7="",G7="")),"",SUMIF(基础资料!$W$5:$W$24,C7,基础资料!$X$5:$X$24)+SUMIF(C$7:C7,C7,F$7:F7)-SUMIF(C$7:C7,C7,G$7:G7)) -> 100000 | I7: =IF(AND(F7="",G7=""),"",SUM(基础资料!$X$5:$X$24)+SUM(F$7:F7)-SUM(G$7:G7)) -> 100000 | J7: 鼎龙陈财超市 | N7: =IF(AND(AND(F7="",G7=""),B7="",C7="",D7="",J7="",K7="",L7=""),"",IF(AND(F7="",G7=""),"✗ 没填金额",IF(AND(N(F7)<>0,N(G7)<>0),"✗ 收入、支出只能填一边",IF(NOT(ISNUMBER(B7)),"✗ 日期不是真日期（要像 2026/9/25 这样填）",IF(OR(B7<年初日,B7>年末日),"✗ 日期不在本会计年度",IF(C7="","✗ 没选账户",IF(COUNTIF(基础资料!$W$5:$W$24,C7)=0,"✗ 账户不在基础资料里",IF(O7="","✗ 没选收支项目",IF(P7="未知","✗ 收支项目不在基础资料里",IF(AND(P7="应收",J7=""),"✗ 这笔要选客户",IF(AND(P7="应收",COUNTIF(总览汇总!$B$5:$B$304,J7)=0),"✗ 客户不在总览汇总名单里",IF(AND(P7="应付",K7=""),"✗ 这笔要选供应商",IF(AND(P7="应付",COUNTIF(基础资料!$Q$5:$Q$54,K7)=0),"✗ 供应商不在基础资料里",IF(AND(P7="费用",L7=""),"✗ 费用支出要选费用项目",IF(AND(L7<>"",COUNTIF(基础资料!$AI$5:$AI$54,L7)=0),"✗ 费用项目不在基础资料里",IF(AND(IFERROR(INDEX(基础资料!$AD$5:$AD$34,MATCH(O7,基础资料!$AC$5:$AC$34,0)),"")="收",N(G7)<>0),"✗ 这类是收款，金额填到收入列",IF(AND(IFERROR(INDEX(基础资料!$AD$5:$AD$34,MATCH(O7,基础资料!$AC$5:$AC$34,0)),"")="支",N(F7)<>0),"✗ 这类是付款，金额填到支出列",IF(N(H7)<0,"⚠ 账户余额成负数了，核对一下","√")))))))))))))))))) -> √ | O7: =IF(D7<>"",D7,IF(AND(F7="",G7=""),"",IF(J7<>"",IF(N(F7)>0,"客户回款","客户退款"),IF(K7<>"",IF(N(G7)>0,"供应商付款","供应商退款"),IF(L7<>"","费用支出",""))))) -> 客户回款 | P7: =IF(O7="","",IFERROR(INDEX(基础资料!$AE$5:$AE$34,MATCH(O7,基础资料!$AC$5:$AC$34,0)),"未知")) -> 应收 | Q7: =IF(P7="应收",COUNTIF(P$7:P7,"应收"),"") -> 1 | R7: =IF(P7="应付",COUNTIF(P$7:P7,"应付"),"") | S7: =N(F7)-N(G7) -> 100000
A8: =IF(AND(F8="",G8=""),"",ROW()-6) -> 2 | B8: 46198 | C8: 收款码 | D8: 客户回款 | E8: 收货款 | F8: 39547 | H8: =IF(OR(C8="",AND(F8="",G8="")),"",SUMIF(基础资料!$W$5:$W$24,C8,基础资料!$X$5:$X$24)+SUMIF(C$7:C8,C8,F$7:F8)-SUMIF(C$7:C8,C8,G$7:G8)) -> 139547 | I8: =IF(AND(F8="",G8=""),"",SUM(基础资料!$X$5:$X$24)+SUM(F$7:F8)-SUM(G$7:G8)) -> 139547 | J8: 星海超市 | N8: =IF(AND(AND(F8="",G8=""),B8="",C8="",D8="",J8="",K8="",L8=""),"",IF(AND(F8="",G8=""),"✗ 没填金额",IF(AND(N(F8)<>0,N(G8)<>0),"✗ 收入、支出只能填一边",IF(NOT(ISNUMBER(B8)),"✗ 日期不是真日期（要像 2026/9/25 这样填）",IF(OR(B8<年初日,B8>年末日),"✗ 日期不在本会计年度",IF(C8="","✗ 没选账户",IF(COUNTIF(基础资料!$W$5:$W$24,C8)=0,"✗ 账户不在基础资料里",IF(O8="","✗ 没选收支项目",IF(P8="未知","✗ 收支项目不在基础资料里",IF(AND(P8="应收",J8=""),"✗ 这笔要选客户",IF(AND(P8="应收",COUNTIF(总览汇总!$B$5:$B$304,J8)=0),"✗ 客户不在总览汇总名单里",IF(AND(P8="应付",K8=""),"✗ 这笔要选供应商",IF(AND(P8="应付",COUNTIF(基础资料!$Q$5:$Q$54,K8)=0),"✗ 供应商不在基础资料里",IF(AND(P8="费用",L8=""),"✗ 费用支出要选费用项目",IF(AND(L8<>"",COUNTIF(基础资料!$AI$5:$AI$54,L8)=0),"✗ 费用项目不在基础资料里",IF(AND(IFERROR(INDEX(基础资料!$AD$5:$AD$34,MATCH(O8,基础资料!$AC$5:$AC$34,0)),"")="收",N(G8)<>0),"✗ 这类是收款，金额填到收入列",IF(AND(IFERROR(INDEX(基础资料!$AD$5:$AD$34,MATCH(O8,基础资料!$AC$5:$AC$34,0)),"")="支",N(F8)<>0),"✗ 这类是付款，金额填到支出列",IF(N(H8)<0,"⚠ 账户余额成负数了，核对一下","√")))))))))))))))))) -> √ | O8: =IF(D8<>"",D8,IF(AND(F8="",G8=""),"",IF(J8<>"",IF(N(F8)>0,"客户回款","客户退款"),IF(K8<>"",IF(N(G8)>0,"供应商付款","供应商退款"),IF(L8<>"","费用支出",""))))) -> 客户回款 | P8: =IF(O8="","",IFERROR(INDEX(基础资料!$AE$5:$AE$34,MATCH(O8,基础资料!$AC$5:$AC$34,0)),"未知")) -> 应收 | Q8: =IF(P8="应收",COUNTIF(P$7:P8,"应收"),"") -> 2 | R8: =IF(P8="应付",COUNTIF(P$7:P8,"应付"),"") | S8: =N(F8)-N(G8) -> 39547
A9: =IF(AND(F9="",G9=""),"",ROW()-6) -> 3 | B9: 46198 | C9: 收款码 | D9: 客户回款 | E9: 收货款 | F9: 99000 | H9: =IF(OR(C9="",AND(F9="",G9="")),"",SUMIF(基础资料!$W$5:$W$24,C9,基础资料!$X$5:$X$24)+SUMIF(C$7:C9,C9,F$7:F9)-SUMIF(C$7:C9,C9,G$7:G9)) -> 238547 | I9: =IF(AND(F9="",G9=""),"",SUM(基础资料!$X$5:$X$24)+SUM(F$7:F9)-SUM(G$7:G9)) -> 238547 | J9: 王玉琴 | N9: =IF(AND(AND(F9="",G9=""),B9="",C9="",D9="",J9="",K9="",L9=""),"",IF(AND(F9="",G9=""),"✗ 没填金额",IF(AND(N(F9)<>0,N(G9)<>0),"✗ 收入、支出只能填一边",IF(NOT(ISNUMBER(B9)),"✗ 日期不是真日期（要像 2026/9/25 这样填）",IF(OR(B9<年初日,B9>年末日),"✗ 日期不在本会计年度",IF(C9="","✗ 没选账户",IF(COUNTIF(基础资料!$W$5:$W$24,C9)=0,"✗ 账户不在基础资料里",IF(O9="","✗ 没选收支项目",IF(P9="未知","✗ 收支项目不在基础资料里",IF(AND(P9="应收",J9=""),"✗ 这笔要选客户",IF(AND(P9="应收",COUNTIF(总览汇总!$B$5:$B$304,J9)=0),"✗ 客户不在总览汇总名单里",IF(AND(P9="应付",K9=""),"✗ 这笔要选供应商",IF(AND(P9="应付",COUNTIF(基础资料!$Q$5:$Q$54,K9)=0),"✗ 供应商不在基础资料里",IF(AND(P9="费用",L9=""),"✗ 费用支出要选费用项目",IF(AND(L9<>"",COUNTIF(基础资料!$AI$5:$AI$54,L9)=0),"✗ 费用项目不在基础资料里",IF(AND(IFERROR(INDEX(基础资料!$AD$5:$AD$34,MATCH(O9,基础资料!$AC$5:$AC$34,0)),"")="收",N(G9)<>0),"✗ 这类是收款，金额填到收入列",IF(AND(IFERROR(INDEX(基础资料!$AD$5:$AD$34,MATCH(O9,基础资料!$AC$5:$AC$34,0)),"")="支",N(F9)<>0),"✗ 这类是付款，金额填到支出列",IF(N(H9)<0,"⚠ 账户余额成负数了，核对一下","√")))))))))))))))))) -> √ | O9: =IF(D9<>"",D9,IF(AND(F9="",G9=""),"",IF(J9<>"",IF(N(F9)>0,"客户回款","客户退款"),IF(K9<>"",IF(N(G9)>0,"供应商付款","供应商退款"),IF(L9<>"","费用支出",""))))) -> 客户回款 | P9: =IF(O9="","",IFERROR(INDEX(基础资料!$AE$5:$AE$34,MATCH(O9,基础资料!$AC$5:$AC$34,0)),"未知")) -> 应收 | Q9: =IF(P9="应收",COUNTIF(P$7:P9,"应收"),"") -> 3 | R9: =IF(P9="应付",COUNTIF(P$7:P9,"应付"),"") | S9: =N(F9)-N(G9) -> 99000
A10: =IF(AND(F10="",G10=""),"",ROW()-6) -> 4 | B10: 46198 | C10: 收款码 | D10: 客户回款 | E10: 还差我46313元 | F10: 700231.47 | H10: =IF(OR(C10="",AND(F10="",G10="")),"",SUMIF(基础资料!$W$5:$W$24,C10,基础资料!$X$5:$X$24)+SUMIF(C$7:C10,C10,F$7:F10)-SUMIF(C$7:C10,C10,G$7:G10)) -> 938778.47 | I10: =IF(AND(F10="",G10=""),"",SUM(基础资料!$X$5:$X$24)+SUM(F$7:F10)-SUM(G$7:G10)) -> 938778.47 | J10: 桐心源 | N10: =IF(AND(AND(F10="",G10=""),B10="",C10="",D10="",J10="",K10="",L10=""),"",IF(AND(F10="",G10=""),"✗ 没填金额",IF(AND(N(F10)<>0,N(G10)<>0),"✗ 收入、支出只能填一边",IF(NOT(ISNUMBER(B10)),"✗ 日期不是真日期（要像 2026/9/25 这样填）",IF(OR(B10<年初日,B10>年末日),"✗ 日期不在本会计年度",IF(C10="","✗ 没选账户",IF(COUNTIF(基础资料!$W$5:$W$24,C10)=0,"✗ 账户不在基础资料里",IF(O10="","✗ 没选收支项目",IF(P10="未知","✗ 收支项目不在基础资料里",IF(AND(P10="应收",J10=""),"✗ 这笔要选客户",IF(AND(P10="应收",COUNTIF(总览汇总!$B$5:$B$304,J10)=0),"✗ 客户不在总览汇总名单里",IF(AND(P10="应付",K10=""),"✗ 这笔要选供应商",IF(AND(P10="应付",COUNTIF(基础资料!$Q$5:$Q$54,K10)=0),"✗ 供应商不在基础资料里",IF(AND(P10="费用",L10=""),"✗ 费用支出要选费用项目",IF(AND(L10<>"",COUNTIF(基础资料!$AI$5:$AI$54,L10)=0),"✗ 费用项目不在基础资料里",IF(AND(IFERROR(INDEX(基础资料!$AD$5:$AD$34,MATCH(O10,基础资料!$AC$5:$AC$34,0)),"")="收",N(G10)<>0),"✗ 这类是收款，金额填到收入列",IF(AND(IFERROR(INDEX(基础资料!$AD$5:$AD$34,MATCH(O10,基础资料!$AC$5:$AC$34,0)),"")="支",N(F10)<>0),"✗ 这类是付款，金额填到支出列",IF(N(H10)<0,"⚠ 账户余额成负数了，核对一下","√")))))))))))))))))) -> √ | O10: =IF(D10<>"",D10,IF(AND(F10="",G10=""),"",IF(J10<>"",IF(N(F10)>0,"客户回款","客户退款"),IF(K10<>"",IF(N(G10)>0,"供应商付款","供应商退款"),IF(L10<>"","费用支出",""))))) -> 客户回款 | P10: =IF(O10="","",IFERROR(INDEX(基础资料!$AE$5:$AE$34,MATCH(O10,基础资料!$AC$5:$AC$34,0)),"未知")) -> 应收 | Q10: =IF(P10="应收",COUNTIF(P$7:P10,"应收"),"") -> 4 | R10: =IF(P10="应付",COUNTIF(P$7:P10,"应付"),"") | S10: =N(F10)-N(G10) -> 700231.47
A11: =IF(AND(F11="",G11=""),"",ROW()-6) -> 5 | B11: 46198 | C11: 收款码 | D11: 客户回款 | E11: 农夫饮料 | F11: 46360 | H11: =IF(OR(C11="",AND(F11="",G11="")),"",SUMIF(基础资料!$W$5:$W$24,C11,基础资料!$X$5:$X$24)+SUMIF(C$7:C11,C11,F$7:F11)-SUMIF(C$7:C11,C11,G$7:G11)) -> 985138.47 | I11: =IF(AND(F11="",G11=""),"",SUM(基础资料!$X$5:$X$24)+SUM(F$7:F11)-SUM(G$7:G11)) -> 985138.47 | J11: 桐心源 | N11: =IF(AND(AND(F11="",G11=""),B11="",C11="",D11="",J11="",K11="",L11=""),"",IF(AND(F11="",G11=""),"✗ 没填金额",IF(AND(N(F11)<>0,N(G11)<>0),"✗ 收入、支出只能填一边",IF(NOT(ISNUMBER(B11)),"✗ 日期不是真日期（要像 2026/9/25 这样填）",IF(OR(B11<年初日,B11>年末日),"✗ 日期不在本会计年度",IF(C11="","✗ 没选账户",IF(COUNTIF(基础资料!$W$5:$W$24,C11)=0,"✗ 账户不在基础资料里",IF(O11="","✗ 没选收支项目",IF(P11="未知","✗ 收支项目不在基础资料里",IF(AND(P11="应收",J11=""),"✗ 这笔要选客户",IF(AND(P11="应收",COUNTIF(总览汇总!$B$5:$B$304,J11)=0),"✗ 客户不在总览汇总名单里",IF(AND(P11="应付",K11=""),"✗ 这笔要选供应商",IF(AND(P11="应付",COUNTIF(基础资料!$Q$5:$Q$54,K11)=0),"✗ 供应商不在基础资料里",IF(AND(P11="费用",L11=""),"✗ 费用支出要选费用项目",IF(AND(L11<>"",COUNTIF(基础资料!$AI$5:$AI$54,L11)=0),"✗ 费用项目不在基础资料里",IF(AND(IFERROR(INDEX(基础资料!$AD$5:$AD$34,MATCH(O11,基础资料!$AC$5:$AC$34,0)),"")="收",N(G11)<>0),"✗ 这类是收款，金额填到收入列",IF(AND(IFERROR(INDEX(基础资料!$AD$5:$AD$34,MATCH(O11,基础资料!$AC$5:$AC$34,0)),"")="支",N(F11)<>0),"✗ 这类是付款，金额填到支出列",IF(N(H11)<0,"⚠ 账户余额成负数了，核对一下","√")))))))))))))))))) -> √ | O11: =IF(D11<>"",D11,IF(AND(F11="",G11=""),"",IF(J11<>"",IF(N(F11)>0,"客户回款","客户退款"),IF(K11<>"",IF(N(G11)>0,"供应商付款","供应商退款"),IF(L11<>"","费用支出",""))))) -> 客户回款 | P11: =IF(O11="","",IFERROR(INDEX(基础资料!$AE$5:$AE$34,MATCH(O11,基础资料!$AC$5:$AC$34,0)),"未知")) -> 应收 | Q11: =IF(P11="应收",COUNTIF(P$7:P11,"应收"),"") -> 5 | R11: =IF(P11="应付",COUNTIF(P$7:P11,"应付"),"") | S11: =N(F11)-N(G11) -> 46360
A12: =IF(AND(F12="",G12=""),"",ROW()-6) -> 6 | B12: 46198 | C12: 收款码 | D12: 客户回款 | E12: 还差我37433元 | F12: 570147.22 | H12: =IF(OR(C12="",AND(F12="",G12="")),"",SUMIF(基础资料!$W$5:$W$24,C12,基础资料!$X$5:$X$24)+SUMIF(C$7:C12,C12,F$7:F12)-SUMIF(C$7:C12,C12,G$7:G12)) -> 1555285.7 | I12: =IF(AND(F12="",G12=""),"",SUM(基础资料!$X$5:$X$24)+SUM(F$7:F12)-SUM(G$7:G12)) -> 1555285.7 | J12: 阿东副食 | N12: =IF(AND(AND(F12="",G12=""),B12="",C12="",D12="",J12="",K12="",L12=""),"",IF(AND(F12="",G12=""),"✗ 没填金额",IF(AND(N(F12)<>0,N(G12)<>0),"✗ 收入、支出只能填一边",IF(NOT(ISNUMBER(B12)),"✗ 日期不是真日期（要像 2026/9/25 这样填）",IF(OR(B12<年初日,B12>年末日),"✗ 日期不在本会计年度",IF(C12="","✗ 没选账户",IF(COUNTIF(基础资料!$W$5:$W$24,C12)=0,"✗ 账户不在基础资料里",IF(O12="","✗ 没选收支项目",IF(P12="未知","✗ 收支项目不在基础资料里",IF(AND(P12="应收",J12=""),"✗ 这笔要选客户",IF(AND(P12="应收",COUNTIF(总览汇总!$B$5:$B$304,J12)=0),"✗ 客户不在总览汇总名单里",IF(AND(P12="应付",K12=""),"✗ 这笔要选供应商",IF(AND(P12="应付",COUNTIF(基础资料!$Q$5:$Q$54,K12)=0),"✗ 供应商不在基础资料里",IF(AND(P12="费用",L12=""),"✗ 费用支出要选费用项目",IF(AND(L12<>"",COUNTIF(基础资料!$AI$5:$AI$54,L12)=0),"✗ 费用项目不在基础资料里",IF(AND(IFERROR(INDEX(基础资料!$AD$5:$AD$34,MATCH(O12,基础资料!$AC$5:$AC$34,0)),"")="收",N(G12)<>0),"✗ 这类是收款，金额填到收入列",IF(AND(IFERROR(INDEX(基础资料!$AD$5:$AD$34,MATCH(O12,基础资料!$AC$5:$AC$34,0)),"")="支",N(F12)<>0),"✗ 这类是付款，金额填到支出列",IF(N(H12)<0,"⚠ 账户余额成负数了，核对一下","√")))))))))))))))))) -> √ | O12: =IF(D12<>"",D12,IF(AND(F12="",G12=""),"",IF(J12<>"",IF(N(F12)>0,"客户回款","客户退款"),IF(K12<>"",IF(N(G12)>0,"供应商付款","供应商退款"),IF(L12<>"","费用支出",""))))) -> 客户回款 | P12: =IF(O12="","",IFERROR(INDEX(基础资料!$AE$5:$AE$34,MATCH(O12,基础资料!$AC$5:$AC$34,0)),"未知")) -> 应收 | Q12: =IF(P12="应收",COUNTIF(P$7:P12,"应收"),"") -> 6 | R12: =IF(P12="应付",COUNTIF(P$7:P12,"应付"),"") | S12: =N(F12)-N(G12) -> 570147.22
A13: =IF(AND(F13="",G13=""),"",ROW()-6) -> 7 | B13: 46199 | C13: 收款码 | D13: 客户回款 | E13: 收货款 | F13: 8950 | H13: =IF(OR(C13="",AND(F13="",G13="")),"",SUMIF(基础资料!$W$5:$W$24,C13,基础资料!$X$5:$X$24)+SUMIF(C$7:C13,C13,F$7:F13)-SUMIF(C$7:C13,C13,G$7:G13)) -> 1564235.7 | I13: =IF(AND(F13="",G13=""),"",SUM(基础资料!$X$5:$X$24)+SUM(F$7:F13)-SUM(G$7:G13)) -> 1564235.7 | J13: 金凤副食 | N13: =IF(AND(AND(F13="",G13=""),B13="",C13="",D13="",J13="",K13="",L13=""),"",IF(AND(F13="",G13=""),"✗ 没填金额",IF(AND(N(F13)<>0,N(G13)<>0),"✗ 收入、支出只能填一边",IF(NOT(ISNUMBER(B13)),"✗ 日期不是真日期（要像 2026/9/25 这样填）",IF(OR(B13<年初日,B13>年末日),"✗ 日期不在本会计年度",IF(C13="","✗ 没选账户",IF(COUNTIF(基础资料!$W$5:$W$24,C13)=0,"✗ 账户不在基础资料里",IF(O13="","✗ 没选收支项目",IF(P13="未知","✗ 收支项目不在基础资料里",IF(AND(P13="应收",J13=""),"✗ 这笔要选客户",IF(AND(P13="应收",COUNTIF(总览汇总!$B$5:$B$304,J13)=0),"✗ 客户不在总览汇总名单里",IF(AND(P13="应付",K13=""),"✗ 这笔要选供应商",IF(AND(P13="应付",COUNTIF(基础资料!$Q$5:$Q$54,K13)=0),"✗ 供应商不在基础资料里",IF(AND(P13="费用",L13=""),"✗ 费用支出要选费用项目",IF(AND(L13<>"",COUNTIF(基础资料!$AI$5:$AI$54,L13)=0),"✗ 费用项目不在基础资料里",IF(AND(IFERROR(INDEX(基础资料!$AD$5:$AD$34,MATCH(O13,基础资料!$AC$5:$AC$34,0)),"")="收",N(G13)<>0),"✗ 这类是收款，金额填到收入列",IF(AND(IFERROR(INDEX(基础资料!$AD$5:$AD$34,MATCH(O13,基础资料!$AC$5:$AC$34,0)),"")="支",N(F13)<>0),"✗ 这类是付款，金额填到支出列",IF(N(H13)<0,"⚠ 账户余额成负数了，核对一下","√")))))))))))))))))) -> √ | O13: =IF(D13<>"",D13,IF(AND(F13="",G13=""),"",IF(J13<>"",IF(N(F13)>0,"客户回款","客户退款"),IF(K13<>"",IF(N(G13)>0,"供应商付款","供应商退款"),IF(L13<>"","费用支出",""))))) -> 客户回款 | P13: =IF(O13="","",IFERROR(INDEX(基础资料!$AE$5:$AE$34,MATCH(O13,基础资料!$AC$5:$AC$34,0)),"未知")) -> 应收 | Q13: =IF(P13="应收",COUNTIF(P$7:P13,"应收"),"") -> 7 | R13: =IF(P13="应付",COUNTIF(P$7:P13,"应付"),"") | S13: =N(F13)-N(G13) -> 8950
A14: =IF(AND(F14="",G14=""),"",ROW()-6) -> 8 | B14: 46199 | C14: 收款码 | D14: 客户回款 | E14: 收货款 | F14: 437965 | H14: =IF(OR(C14="",AND(F14="",G14="")),"",SUMIF(基础资料!$W$5:$W$24,C14,基础资料!$X$5:$X$24)+SUMIF(C$7:C14,C14,F$7:F14)-SUMIF(C$7:C14,C14,G$7:G14)) -> 2002200.7 | I14: =IF(AND(F14="",G14=""),"",SUM(基础资料!$X$5:$X$24)+SUM(F$7:F14)-SUM(G$7:G14)) -> 2002200.7 | J14: 致发商行 | N14: =IF(AND(AND(F14="",G14=""),B14="",C14="",D14="",J14="",K14="",L14=""),"",IF(AND(F14="",G14=""),"✗ 没填金额",IF(AND(N(F14)<>0,N(G14)<>0),"✗ 收入、支出只能填一边",IF(NOT(ISNUMBER(B14)),"✗ 日期不是真日期（要像 2026/9/25 这样填）",IF(OR(B14<年初日,B14>年末日),"✗ 日期不在本会计年度",IF(C14="","✗ 没选账户",IF(COUNTIF(基础资料!$W$5:$W$24,C14)=0,"✗ 账户不在基础资料里",IF(O14="","✗ 没选收支项目",IF(P14="未知","✗ 收支项目不在基础资料里",IF(AND(P14="应收",J14=""),"✗ 这笔要选客户",IF(AND(P14="应收",COUNTIF(总览汇总!$B$5:$B$304,J14)=0),"✗ 客户不在总览汇总名单里",IF(AND(P14="应付",K14=""),"✗ 这笔要选供应商",IF(AND(P14="应付",COUNTIF(基础资料!$Q$5:$Q$54,K14)=0),"✗ 供应商不在基础资料里",IF(AND(P14="费用",L14=""),"✗ 费用支出要选费用项目",IF(AND(L14<>"",COUNTIF(基础资料!$AI$5:$AI$54,L14)=0),"✗ 费用项目不在基础资料里",IF(AND(IFERROR(INDEX(基础资料!$AD$5:$AD$34,MATCH(O14,基础资料!$AC$5:$AC$34,0)),"")="收",N(G14)<>0),"✗ 这类是收款，金额填到收入列",IF(AND(IFERROR(INDEX(基础资料!$AD$5:$AD$34,MATCH(O14,基础资料!$AC$5:$AC$34,0)),"")="支",N(F14)<>0),"✗ 这类是付款，金额填到支出列",IF(N(H14)<0,"⚠ 账户余额成负数了，核对一下","√")))))))))))))))))) -> √ | O14: =IF(D14<>"",D14,IF(AND(F14="",G14=""),"",IF(J14<>"",IF(N(F14)>0,"客户回款","客户退款"),IF(K14<>"",IF(N(G14)>0,"供应商付款","供应商退款"),IF(L14<>"","费用支出",""))))) -> 客户回款 | P14: =IF(O14="","",IFERROR(INDEX(基础资料!$AE$5:$AE$34,MATCH(O14,基础资料!$AC$5:$AC$34,0)),"未知")) -> 应收 | Q14: =IF(P14="应收",COUNTIF(P$7:P14,"应收"),"") -> 8 | R14: =IF(P14="应付",COUNTIF(P$7:P14,"应付"),"") | S14: =N(F14)-N(G14) -> 437965
A15: =IF(AND(F15="",G15=""),"",ROW()-6) -> 9 | B15: 46199 | C15: 收款码 | D15: 客户回款 | E15: 收货款 | F15: 18000 | H15: =IF(OR(C15="",AND(F15="",G15="")),"",SUMIF(基础资料!$W$5:$W$24,C15,基础资料!$X$5:$X$24)+SUMIF(C$7:C15,C15,F$7:F15)-SUMIF(C$7:C15,C15,G$7:G15)) -> 2020200.7 | I15: =IF(AND(F15="",G15=""),"",SUM(基础资料!$X$5:$X$24)+SUM(F$7:F15)-SUM(G$7:G15)) -> 2020200.7 | J15: 通达商行 | N15: =IF(AND(AND(F15="",G15=""),B15="",C15="",D15="",J15="",K15="",L15=""),"",IF(AND(F15="",G15=""),"✗ 没填金额",IF(AND(N(F15)<>0,N(G15)<>0),"✗ 收入、支出只能填一边",IF(NOT(ISNUMBER(B15)),"✗ 日期不是真日期（要像 2026/9/25 这样填）",IF(OR(B15<年初日,B15>年末日),"✗ 日期不在本会计年度",IF(C15="","✗ 没选账户",IF(COUNTIF(基础资料!$W$5:$W$24,C15)=0,"✗ 账户不在基础资料里",IF(O15="","✗ 没选收支项目",IF(P15="未知","✗ 收支项目不在基础资料里",IF(AND(P15="应收",J15=""),"✗ 这笔要选客户",IF(AND(P15="应收",COUNTIF(总览汇总!$B$5:$B$304,J15)=0),"✗ 客户不在总览汇总名单里",IF(AND(P15="应付",K15=""),"✗ 这笔要选供应商",IF(AND(P15="应付",COUNTIF(基础资料!$Q$5:$Q$54,K15)=0),"✗ 供应商不在基础资料里",IF(AND(P15="费用",L15=""),"✗ 费用支出要选费用项目",IF(AND(L15<>"",COUNTIF(基础资料!$AI$5:$AI$54,L15)=0),"✗ 费用项目不在基础资料里",IF(AND(IFERROR(INDEX(基础资料!$AD$5:$AD$34,MATCH(O15,基础资料!$AC$5:$AC$34,0)),"")="收",N(G15)<>0),"✗ 这类是收款，金额填到收入列",IF(AND(IFERROR(INDEX(基础资料!$AD$5:$AD$34,MATCH(O15,基础资料!$AC$5:$AC$34,0)),"")="支",N(F15)<>0),"✗ 这类是付款，金额填到支出列",IF(N(H15)<0,"⚠ 账户余额成负数了，核对一下","√")))))))))))))))))) -> √ | O15: =IF(D15<>"",D15,IF(AND(F15="",G15=""),"",IF(J15<>"",IF(N(F15)>0,"客户回款","客户退款"),IF(K15<>"",IF(N(G15)>0,"供应商付款","供应商退款"),IF(L15<>"","费用支出",""))))) -> 客户回款 | P15: =IF(O15="","",IFERROR(INDEX(基础资料!$AE$5:$AE$34,MATCH(O15,基础资料!$AC$5:$AC$34,0)),"未知")) -> 应收 | Q15: =IF(P15="应收",COUNTIF(P$7:P15,"应收"),"") -> 9 | R15: =IF(P15="应付",COUNTIF(P$7:P15,"应付"),"") | S15: =N(F15)-N(G15) -> 18000
A16: =IF(AND(F16="",G16=""),"",ROW()-6) -> 10 | B16: 46199 | C16: 收款码 | D16: 客户回款 | E16: 收货款 | F16: 54000 | H16: =IF(OR(C16="",AND(F16="",G16="")),"",SUMIF(基础资料!$W$5:$W$24,C16,基础资料!$X$5:$X$24)+SUMIF(C$7:C16,C16,F$7:F16)-SUMIF(C$7:C16,C16,G$7:G16)) -> 2074200.7 | I16: =IF(AND(F16="",G16=""),"",SUM(基础资料!$X$5:$X$24)+SUM(F$7:F16)-SUM(G$7:G16)) -> 2074200.7 | J16: 宜兴粮油 | N16: =IF(AND(AND(F16="",G16=""),B16="",C16="",D16="",J16="",K16="",L16=""),"",IF(AND(F16="",G16=""),"✗ 没填金额",IF(AND(N(F16)<>0,N(G16)<>0),"✗ 收入、支出只能填一边",IF(NOT(ISNUMBER(B16)),"✗ 日期不是真日期（要像 2026/9/25 这样填）",IF(OR(B16<年初日,B16>年末日),"✗ 日期不在本会计年度",IF(C16="","✗ 没选账户",IF(COUNTIF(基础资料!$W$5:$W$24,C16)=0,"✗ 账户不在基础资料里",IF(O16="","✗ 没选收支项目",IF(P16="未知","✗ 收支项目不在基础资料里",IF(AND(P16="应收",J16=""),"✗ 这笔要选客户",IF(AND(P16="应收",COUNTIF(总览汇总!$B$5:$B$304,J16)=0),"✗ 客户不在总览汇总名单里",IF(AND(P16="应付",K16=""),"✗ 这笔要选供应商",IF(AND(P16="应付",COUNTIF(基础资料!$Q$5:$Q$54,K16)=0),"✗ 供应商不在基础资料里",IF(AND(P16="费用",L16=""),"✗ 费用支出要选费用项目",IF(AND(L16<>"",COUNTIF(基础资料!$AI$5:$AI$54,L16)=0),"✗ 费用项目不在基础资料里",IF(AND(IFERROR(INDEX(基础资料!$AD$5:$AD$34,MATCH(O16,基础资料!$AC$5:$AC$34,0)),"")="收",N(G16)<>0),"✗ 这类是收款，金额填到收入列",IF(AND(IFERROR(INDEX(基础资料!$AD$5:$AD$34,MATCH(O16,基础资料!$AC$5:$AC$34,0)),"")="支",N(F16)<>0),"✗ 这类是付款，金额填到支出列",IF(N(H16)<0,"⚠ 账户余额成负数了，核对一下","√")))))))))))))))))) -> √ | O16: =IF(D16<>"",D16,IF(AND(F16="",G16=""),"",IF(J16<>"",IF(N(F16)>0,"客户回款","客户退款"),IF(K16<>"",IF(N(G16)>0,"供应商付款","供应商退款"),IF(L16<>"","费用支出",""))))) -> 客户回款 | P16: =IF(O16="","",IFERROR(INDEX(基础资料!$AE$5:$AE$34,MATCH(O16,基础资料!$AC$5:$AC$34,0)),"未知")) -> 应收 | Q16: =IF(P16="应收",COUNTIF(P$7:P16,"应收"),"") -> 10 | R16: =IF(P16="应付",COUNTIF(P$7:P16,"应付"),"") | S16: =N(F16)-N(G16) -> 54000
A17: =IF(AND(F17="",G17=""),"",ROW()-6) -> 11 | B17: 46200 | C17: 收款码 | D17: 客户回款 | E17: 东鹏新品订货款 | F17: 840 | H17: =IF(OR(C17="",AND(F17="",G17="")),"",SUMIF(基础资料!$W$5:$W$24,C17,基础资料!$X$5:$X$24)+SUMIF(C$7:C17,C17,F$7:F17)-SUMIF(C$7:C17,C17,G$7:G17)) -> 2075040.7 | I17: =IF(AND(F17="",G17=""),"",SUM(基础资料!$X$5:$X$24)+SUM(F$7:F17)-SUM(G$7:G17)) -> 2075040.7 | J17: 马路下小卖部 | N17: =IF(AND(AND(F17="",G17=""),B17="",C17="",D17="",J17="",K17="",L17=""),"",IF(AND(F17="",G17=""),"✗ 没填金额",IF(AND(N(F17)<>0,N(G17)<>0),"✗ 收入、支出只能填一边",IF(NOT(ISNUMBER(B17)),"✗ 日期不是真日期（要像 2026/9/25 这样填）",IF(OR(B17<年初日,B17>年末日),"✗ 日期不在本会计年度",IF(C17="","✗ 没选账户",IF(COUNTIF(基础资料!$W$5:$W$24,C17)=0,"✗ 账户不在基础资料里",IF(O17="","✗ 没选收支项目",IF(P17="未知","✗ 收支项目不在基础资料里",IF(AND(P17="应收",J17=""),"✗ 这笔要选客户",IF(AND(P17="应收",COUNTIF(总览汇总!$B$5:$B$304,J17)=0),"✗ 客户不在总览汇总名单里",IF(AND(P17="应付",K17=""),"✗ 这笔要选供应商",IF(AND(P17="应付",COUNTIF(基础资料!$Q$5:$Q$54,K17)=0),"✗ 供应商不在基础资料里",IF(AND(P17="费用",L17=""),"✗ 费用支出要选费用项目",IF(AND(L17<>"",COUNTIF(基础资料!$AI$5:$AI$54,L17)=0),"✗ 费用项目不在基础资料里",IF(AND(IFERROR(INDEX(基础资料!$AD$5:$AD$34,MATCH(O17,基础资料!$AC$5:$AC$34,0)),"")="收",N(G17)<>0),"✗ 这类是收款，金额填到收入列",IF(AND(IFERROR(INDEX(基础资料!$AD$5:$AD$34,MATCH(O17,基础资料!$AC$5:$AC$34,0)),"")="支",N(F17)<>0),"✗ 这类是付款，金额填到支出列",IF(N(H17)<0,"⚠ 账户余额成负数了，核对一下","√")))))))))))))))))) -> √ | O17: =IF(D17<>"",D17,IF(AND(F17="",G17=""),"",IF(J17<>"",IF(N(F17)>0,"客户回款","客户退款"),IF(K17<>"",IF(N(G17)>0,"供应商付款","供应商退款"),IF(L17<>"","费用支出",""))))) -> 客户回款 | P17: =IF(O17="","",IFERROR(INDEX(基础资料!$AE$5:$AE$34,MATCH(O17,基础资料!$AC$5:$AC$34,0)),"未知")) -> 应收 | Q17: =IF(P17="应收",COUNTIF(P$7:P17,"应收"),"") -> 11 | R17: =IF(P17="应付",COUNTIF(P$7:P17,"应付"),"") | S17: =N(F17)-N(G17) -> 840
A18: =IF(AND(F18="",G18=""),"",ROW()-6) -> 12 | B18: 46200 | C18: 收款码 | D18: 客户回款 | E18: 收货款 | F18: 30043 | H18: =IF(OR(C18="",AND(F18="",G18="")),"",SUMIF(基础资料!$W$5:$W$24,C18,基础资料!$X$5:$X$24)+SUMIF(C$7:C18,C18,F$7:F18)-SUMIF(C$7:C18,C18,G$7:G18)) -> 2105083.7 | I18: =IF(AND(F18="",G18=""),"",SUM(基础资料!$X$5:$X$24)+SUM(F$7:F18)-SUM(G$7:G18)) -> 2105083.7 | J18: 兴莲隆兴商行 | N18: =IF(AND(AND(F18="",G18=""),B18="",C18="",D18="",J18="",K18="",L18=""),"",IF(AND(F18="",G18=""),"✗ 没填金额",IF(AND(N(F18)<>0,N(G18)<>0),"✗ 收入、支出只能填一边",IF(NOT(ISNUMBER(B18)),"✗ 日期不是真日期（要像 2026/9/25 这样填）",IF(OR(B18<年初日,B18>年末日),"✗ 日期不在本会计年度",IF(C18="","✗ 没选账户",IF(COUNTIF(基础资料!$W$5:$W$24,C18)=0,"✗ 账户不在基础资料里",IF(O18="","✗ 没选收支项目",IF(P18="未知","✗ 收支项目不在基础资料里",IF(AND(P18="应收",J18=""),"✗ 这笔要选客户",IF(AND(P18="应收",COUNTIF(总览汇总!$B$5:$B$304,J18)=0),"✗ 客户不在总览汇总名单里",IF(AND(P18="应付",K18=""),"✗ 这笔要选供应商",IF(AND(P18="应付",COUNTIF(基础资料!$Q$5:$Q$54,K18)=0),"✗ 供应商不在基础资料里",IF(AND(P18="费用",L18=""),"✗ 费用支出要选费用项目",IF(AND(L18<>"",COUNTIF(基础资料!$AI$5:$AI$54,L18)=0),"✗ 费用项目不在基础资料里",IF(AND(IFERROR(INDEX(基础资料!$AD$5:$AD$34,MATCH(O18,基础资料!$AC$5:$AC$34,0)),"")="收",N(G18)<>0),"✗ 这类是收款，金额填到收入列",IF(AND(IFERROR(INDEX(基础资料!$AD$5:$AD$34,MATCH(O18,基础资料!$AC$5:$AC$34,0)),"")="支",N(F18)<>0),"✗ 这类是付款，金额填到支出列",IF(N(H18)<0,"⚠ 账户余额成负数了，核对一下","√")))))))))))))))))) -> √ | O18: =IF(D18<>"",D18,IF(AND(F18="",G18=""),"",IF(J18<>"",IF(N(F18)>0,"客户回款","客户退款"),IF(K18<>"",IF(N(G18)>0,"供应商付款","供应商退款"),IF(L18<>"","费用支出",""))))) -> 客户回款 | P18: =IF(O18="","",IFERROR(INDEX(基础资料!$AE$5:$AE$34,MATCH(O18,基础资料!$AC$5:$AC$34,0)),"未知")) -> 应收 | Q18: =IF(P18="应收",COUNTIF(P$7:P18,"应收"),"") -> 12 | R18: =IF(P18="应付",COUNTIF(P$7:P18,"应付"),"") | S18: =N(F18)-N(G18) -> 30043
... A123: =IF(AND(F123="",G123=""),"",ROW()-6) -> 117 | B123: 46270 | C123: 收款码 | D123: 客户回款 | E123: 收货款 | F123: 2700 | H123: =IF(OR(C123="",AND(F123="",G123="")),"",SUMIF(基础资料!$W$5:$W$24,C123,基础资料!$X$5:$X$24)+SUMIF(C$7:C123,C123,F$7:F123)-SUMIF(C$7:C123,C123,G$7:G123)) -> 3857959.7 | I123: =IF(AND(F123="",G123=""),"",SUM(基础资料!$X$5:$X$24)+SUM(F$7:F123)-SUM(G$7:G123)) -> 3869309.7 | J123: 城岗老石商行 | N123: =IF(AND(AND(F123="",G123=""),B123="",C123="",D123="",J123="",K123="",L123=""),"",IF(AND(F123="",G123=""),"✗ 没填金额",IF(AND(N(F123)<>0,N(G123)<>0),"✗ 收入、支出只能填一边",IF(NOT(ISNUMBER(B123)),"✗ 日期不是真日期（要像 2026/9/25 这样填）",IF(OR(B123<年初日,B123>年末日),"✗ 日期不在本会计年度",IF(C123="","✗ 没选账户",IF(COUNTIF(基础资料!$W$5:$W$24,C123)=0,"✗ 账户不在基础资料里",IF(O123="","✗ 没选收支项目",IF(P123="未知","✗ 收支项目不在基础资料里",IF(AND(P123="应收",J123=""),"✗ 这笔要选客户",IF(AND(P123="应收",COUNTIF(总览汇总!$B$5:$B$304,J123)=0),"✗ 客户不在总览汇总名单里",IF(AND(P123="应付",K123=""),"✗ 这笔要选供应商",IF(AND(P123="应付",COUNTIF(基础资料!$Q$5:$Q$54,K123)=0),"✗ 供应商不在基础资料里",IF(AND(P123="费用",L123=""),"✗ 费用支出要选费用项目",IF(AND(L123<>"",COUNTIF(基础资料!$AI$5:$AI$54,L123)=0),"✗ 费用项目不在基础资料里",IF(AND(IFERROR(INDEX(基础资料!$AD$5:$AD$34,MATCH(O123,基础资料!$AC$5:$AC$34,0)),"")="收",N(G123)<>0),"✗ 这类是收款，金额填到收入列",IF(AND(IFERROR(INDEX(基础资料!$AD$5:$AD$34,MATCH(O123,基础资料!$AC$5:$AC$34,0)),"")="支",N(F123)<>0),"✗ 这类是付款，金额填到支出列",IF(N(H123)<0,"⚠ 账户余额成负数了，核对一下","√")))))))))))))))))) -> √ | O123: =IF(D123<>"",D123,IF(AND(F123="",G123=""),"",IF(J123<>"",IF(N(F123)>0,"客户回款","客户退款"),IF(K123<>"",IF(N(G123)>0,"供应商付款","供应商退款"),IF(L123<>"","费用支出",""))))) -> 客户回款 | P123: =IF(O123="","",IFERROR(INDEX(基础资料!$AE$5:$AE$34,MATCH(O123,基础资料!$AC$5:$AC$34,0)),"未知")) -> 应收 | Q123: =IF(P123="应收",COUNTIF(P$7:P123,"应收"),"") -> 117 | R123: =IF(P123="应付",COUNTIF(P$7:P123,"应付"),"") | S123: =N(F123)-N(G123) -> 2700
A124: =IF(AND(F124="",G124=""),"",ROW()-6) | H124: =IF(OR(C124="",AND(F124="",G124="")),"",SUMIF(基础资料!$W$5:$W$24,C124,基础资料!$X$5:$X$24)+SUMIF(C$7:C124,C124,F$7:F124)-SUMIF(C$7:C124,C124,G$7:G124)) | I124: =IF(AND(F124="",G124=""),"",SUM(基础资料!$X$5:$X$24)+SUM(F$7:F124)-SUM(G$7:G124)) | N124: =IF(AND(AND(F124="",G124=""),B124="",C124="",D124="",J124="",K124="",L124=""),"",IF(AND(F124="",G124=""),"✗ 没填金额",IF(AND(N(F124)<>0,N(G124)<>0),"✗ 收入、支出只能填一边",IF(NOT(ISNUMBER(B124)),"✗ 日期不是真日期（要像 2026/9/25 这样填）",IF(OR(B124<年初日,B124>年末日),"✗ 日期不在本会计年度",IF(C124="","✗ 没选账户",IF(COUNTIF(基础资料!$W$5:$W$24,C124)=0,"✗ 账户不在基础资料里",IF(O124="","✗ 没选收支项目",IF(P124="未知","✗ 收支项目不在基础资料里",IF(AND(P124="应收",J124=""),"✗ 这笔要选客户",IF(AND(P124="应收",COUNTIF(总览汇总!$B$5:$B$304,J124)=0),"✗ 客户不在总览汇总名单里",IF(AND(P124="应付",K124=""),"✗ 这笔要选供应商",IF(AND(P124="应付",COUNTIF(基础资料!$Q$5:$Q$54,K124)=0),"✗ 供应商不在基础资料里",IF(AND(P124="费用",L124=""),"✗ 费用支出要选费用项目",IF(AND(L124<>"",COUNTIF(基础资料!$AI$5:$AI$54,L124)=0),"✗ 费用项目不在基础资料里",IF(AND(IFERROR(INDEX(基础资料!$AD$5:$AD$34,MATCH(O124,基础资料!$AC$5:$AC$34,0)),"")="收",N(G124)<>0),"✗ 这类是收款，金额填到收入列",IF(AND(IFERROR(INDEX(基础资料!$AD$5:$AD$34,MATCH(O124,基础资料!$AC$5:$AC$34,0)),"")="支",N(F124)<>0),"✗ 这类是付款，金额填到支出列",IF(N(H124)<0,"⚠ 账户余额成负数了，核对一下","√")))))))))))))))))) | O124: =IF(D124<>"",D124,IF(AND(F124="",G124=""),"",IF(J124<>"",IF(N(F124)>0,"客户回款","客户退款"),IF(K124<>"",IF(N(G124)>0,"供应商付款","供应商退款"),IF(L124<>"","费用支出",""))))) | P124: =IF(O124="","",IFERROR(INDEX(基础资料!$AE$5:$AE$34,MATCH(O124,基础资料!$AC$5:$AC$34,0)),"未知")) | Q124: =IF(P124="应收",COUNTIF(P$7:P124,"应收"),"") | R124: =IF(P124="应付",COUNTIF(P$7:P124,"应付"),"") | S124: =N(F124)-N(G124) -> 0
A125: =IF(AND(F125="",G125=""),"",ROW()-6) | H125: =IF(OR(C125="",AND(F125="",G125="")),"",SUMIF(基础资料!$W$5:$W$24,C125,基础资料!$X$5:$X$24)+SUMIF(C$7:C125,C125,F$7:F125)-SUMIF(C$7:C125,C125,G$7:G125)) | I125: =IF(AND(F125="",G125=""),"",SUM(基础资料!$X$5:$X$24)+SUM(F$7:F125)-SUM(G$7:G125)) | N125: =IF(AND(AND(F125="",G125=""),B125="",C125="",D125="",J125="",K125="",L125=""),"",IF(AND(F125="",G125=""),"✗ 没填金额",IF(AND(N(F125)<>0,N(G125)<>0),"✗ 收入、支出只能填一边",IF(NOT(ISNUMBER(B125)),"✗ 日期不是真日期（要像 2026/9/25 这样填）",IF(OR(B125<年初日,B125>年末日),"✗ 日期不在本会计年度",IF(C125="","✗ 没选账户",IF(COUNTIF(基础资料!$W$5:$W$24,C125)=0,"✗ 账户不在基础资料里",IF(O125="","✗ 没选收支项目",IF(P125="未知","✗ 收支项目不在基础资料里",IF(AND(P125="应收",J125=""),"✗ 这笔要选客户",IF(AND(P125="应收",COUNTIF(总览汇总!$B$5:$B$304,J125)=0),"✗ 客户不在总览汇总名单里",IF(AND(P125="应付",K125=""),"✗ 这笔要选供应商",IF(AND(P125="应付",COUNTIF(基础资料!$Q$5:$Q$54,K125)=0),"✗ 供应商不在基础资料里",IF(AND(P125="费用",L125=""),"✗ 费用支出要选费用项目",IF(AND(L125<>"",COUNTIF(基础资料!$AI$5:$AI$54,L125)=0),"✗ 费用项目不在基础资料里",IF(AND(IFERROR(INDEX(基础资料!$AD$5:$AD$34,MATCH(O125,基础资料!$AC$5:$AC$34,0)),"")="收",N(G125)<>0),"✗ 这类是收款，金额填到收入列",IF(AND(IFERROR(INDEX(基础资料!$AD$5:$AD$34,MATCH(O125,基础资料!$AC$5:$AC$34,0)),"")="支",N(F125)<>0),"✗ 这类是付款，金额填到支出列",IF(N(H125)<0,"⚠ 账户余额成负数了，核对一下","√")))))))))))))))))) | O125: =IF(D125<>"",D125,IF(AND(F125="",G125=""),"",IF(J125<>"",IF(N(F125)>0,"客户回款","客户退款"),IF(K125<>"",IF(N(G125)>0,"供应商付款","供应商退款"),IF(L125<>"","费用支出",""))))) | P125: =IF(O125="","",IFERROR(INDEX(基础资料!$AE$5:$AE$34,MATCH(O125,基础资料!$AC$5:$AC$34,0)),"未知")) | Q125: =IF(P125="应收",COUNTIF(P$7:P125,"应收"),"") | R125: =IF(P125="应付",COUNTIF(P$7:P125,"应付"),"") | S125: =N(F125)-N(G125) -> 0
A126: =IF(AND(F126="",G126=""),"",ROW()-6) | H126: =IF(OR(C126="",AND(F126="",G126="")),"",SUMIF(基础资料!$W$5:$W$24,C126,基础资料!$X$5:$X$24)+SUMIF(C$7:C126,C126,F$7:F126)-SUMIF(C$7:C126,C126,G$7:G126)) | I126: =IF(AND(F126="",G126=""),"",SUM(基础资料!$X$5:$X$24)+SUM(F$7:F126)-SUM(G$7:G126)) | N126: =IF(AND(AND(F126="",G126=""),B126="",C126="",D126="",J126="",K126="",L126=""),"",IF(AND(F126="",G126=""),"✗ 没填金额",IF(AND(N(F126)<>0,N(G126)<>0),"✗ 收入、支出只能填一边",IF(NOT(ISNUMBER(B126)),"✗ 日期不是真日期（要像 2026/9/25 这样填）",IF(OR(B126<年初日,B126>年末日),"✗ 日期不在本会计年度",IF(C126="","✗ 没选账户",IF(COUNTIF(基础资料!$W$5:$W$24,C126)=0,"✗ 账户不在基础资料里",IF(O126="","✗ 没选收支项目",IF(P126="未知","✗ 收支项目不在基础资料里",IF(AND(P126="应收",J126=""),"✗ 这笔要选客户",IF(AND(P126="应收",COUNTIF(总览汇总!$B$5:$B$304,J126)=0),"✗ 客户不在总览汇总名单里",IF(AND(P126="应付",K126=""),"✗ 这笔要选供应商",IF(AND(P126="应付",COUNTIF(基础资料!$Q$5:$Q$54,K126)=0),"✗ 供应商不在基础资料里",IF(AND(P126="费用",L126=""),"✗ 费用支出要选费用项目",IF(AND(L126<>"",COUNTIF(基础资料!$AI$5:$AI$54,L126)=0),"✗ 费用项目不在基础资料里",IF(AND(IFERROR(INDEX(基础资料!$AD$5:$AD$34,MATCH(O126,基础资料!$AC$5:$AC$34,0)),"")="收",N(G126)<>0),"✗ 这类是收款，金额填到收入列",IF(AND(IFERROR(INDEX(基础资料!$AD$5:$AD$34,MATCH(O126,基础资料!$AC$5:$AC$34,0)),"")="支",N(F126)<>0),"✗ 这类是付款，金额填到支出列",IF(N(H126)<0,"⚠ 账户余额成负数了，核对一下","√")))))))))))))))))) | O126: =IF(D126<>"",D126,IF(AND(F126="",G126=""),"",IF(J126<>"",IF(N(F126)>0,"客户回款","客户退款"),IF(K126<>"",IF(N(G126)>0,"供应商付款","供应商退款"),IF(L126<>"","费用支出",""))))) | P126: =IF(O126="","",IFERROR(INDEX(基础资料!$AE$5:$AE$34,MATCH(O126,基础资料!$AC$5:$AC$34,0)),"未知")) | Q126: =IF(P126="应收",COUNTIF(P$7:P126,"应收"),"") | R126: =IF(P126="应付",COUNTIF(P$7:P126,"应付"),"") | S126: =N(F126)-N(G126) -> 0
A127: =IF(AND(F127="",G127=""),"",ROW()-6) | H127: =IF(OR(C127="",AND(F127="",G127="")),"",SUMIF(基础资料!$W$5:$W$24,C127,基础资料!$X$5:$X$24)+SUMIF(C$7:C127,C127,F$7:F127)-SUMIF(C$7:C127,C127,G$7:G127)) | I127: =IF(AND(F127="",G127=""),"",SUM(基础资料!$X$5:$X$24)+SUM(F$7:F127)-SUM(G$7:G127)) | N127: =IF(AND(AND(F127="",G127=""),B127="",C127="",D127="",J127="",K127="",L127=""),"",IF(AND(F127="",G127=""),"✗ 没填金额",IF(AND(N(F127)<>0,N(G127)<>0),"✗ 收入、支出只能填一边",IF(NOT(ISNUMBER(B127)),"✗ 日期不是真日期（要像 2026/9/25 这样填）",IF(OR(B127<年初日,B127>年末日),"✗ 日期不在本会计年度",IF(C127="","✗ 没选账户",IF(COUNTIF(基础资料!$W$5:$W$24,C127)=0,"✗ 账户不在基础资料里",IF(O127="","✗ 没选收支项目",IF(P127="未知","✗ 收支项目不在基础资料里",IF(AND(P127="应收",J127=""),"✗ 这笔要选客户",IF(AND(P127="应收",COUNTIF(总览汇总!$B$5:$B$304,J127)=0),"✗ 客户不在总览汇总名单里",IF(AND(P127="应付",K127=""),"✗ 这笔要选供应商",IF(AND(P127="应付",COUNTIF(基础资料!$Q$5:$Q$54,K127)=0),"✗ 供应商不在基础资料里",IF(AND(P127="费用",L127=""),"✗ 费用支出要选费用项目",IF(AND(L127<>"",COUNTIF(基础资料!$AI$5:$AI$54,L127)=0),"✗ 费用项目不在基础资料里",IF(AND(IFERROR(INDEX(基础资料!$AD$5:$AD$34,MATCH(O127,基础资料!$AC$5:$AC$34,0)),"")="收",N(G127)<>0),"✗ 这类是收款，金额填到收入列",IF(AND(IFERROR(INDEX(基础资料!$AD$5:$AD$34,MATCH(O127,基础资料!$AC$5:$AC$34,0)),"")="支",N(F127)<>0),"✗ 这类是付款，金额填到支出列",IF(N(H127)<0,"⚠ 账户余额成负数了，核对一下","√")))))))))))))))))) | O127: =IF(D127<>"",D127,IF(AND(F127="",G127=""),"",IF(J127<>"",IF(N(F127)>0,"客户回款","客户退款"),IF(K127<>"",IF(N(G127)>0,"供应商付款","供应商退款"),IF(L127<>"","费用支出",""))))) | P127: =IF(O127="","",IFERROR(INDEX(基础资料!$AE$5:$AE$34,MATCH(O127,基础资料!$AC$5:$AC$34,0)),"未知")) | Q127: =IF(P127="应收",COUNTIF(P$7:P127,"应收"),"") | R127: =IF(P127="应付",COUNTIF(P$7:P127,"应付"),"") | S127: =N(F127)-N(G127) -> 0
A128: =IF(AND(F128="",G128=""),"",ROW()-6) | H128: =IF(OR(C128="",AND(F128="",G128="")),"",SUMIF(基础资料!$W$5:$W$24,C128,基础资料!$X$5:$X$24)+SUMIF(C$7:C128,C128,F$7:F128)-SUMIF(C$7:C128,C128,G$7:G128)) | I128: =IF(AND(F128="",G128=""),"",SUM(基础资料!$X$5:$X$24)+SUM(F$7:F128)-SUM(G$7:G128)) | N128: =IF(AND(AND(F128="",G128=""),B128="",C128="",D128="",J128="",K128="",L128=""),"",IF(AND(F128="",G128=""),"✗ 没填金额",IF(AND(N(F128)<>0,N(G128)<>0),"✗ 收入、支出只能填一边",IF(NOT(ISNUMBER(B128)),"✗ 日期不是真日期（要像 2026/9/25 这样填）",IF(OR(B128<年初日,B128>年末日),"✗ 日期不在本会计年度",IF(C128="","✗ 没选账户",IF(COUNTIF(基础资料!$W$5:$W$24,C128)=0,"✗ 账户不在基础资料里",IF(O128="","✗ 没选收支项目",IF(P128="未知","✗ 收支项目不在基础资料里",IF(AND(P128="应收",J128=""),"✗ 这笔要选客户",IF(AND(P128="应收",COUNTIF(总览汇总!$B$5:$B$304,J128)=0),"✗ 客户不在总览汇总名单里",IF(AND(P128="应付",K128=""),"✗ 这笔要选供应商",IF(AND(P128="应付",COUNTIF(基础资料!$Q$5:$Q$54,K128)=0),"✗ 供应商不在基础资料里",IF(AND(P128="费用",L128=""),"✗ 费用支出要选费用项目",IF(AND(L128<>"",COUNTIF(基础资料!$AI$5:$AI$54,L128)=0),"✗ 费用项目不在基础资料里",IF(AND(IFERROR(INDEX(基础资料!$AD$5:$AD$34,MATCH(O128,基础资料!$AC$5:$AC$34,0)),"")="收",N(G128)<>0),"✗ 这类是收款，金额填到收入列",IF(AND(IFERROR(INDEX(基础资料!$AD$5:$AD$34,MATCH(O128,基础资料!$AC$5:$AC$34,0)),"")="支",N(F128)<>0),"✗ 这类是付款，金额填到支出列",IF(N(H128)<0,"⚠ 账户余额成负数了，核对一下","√")))))))))))))))))) | O128: =IF(D128<>"",D128,IF(AND(F128="",G128=""),"",IF(J128<>"",IF(N(F128)>0,"客户回款","客户退款"),IF(K128<>"",IF(N(G128)>0,"供应商付款","供应商退款"),IF(L128<>"","费用支出",""))))) | P128: =IF(O128="","",IFERROR(INDEX(基础资料!$AE$5:$AE$34,MATCH(O128,基础资料!$AC$5:$AC$34,0)),"未知")) | Q128: =IF(P128="应收",COUNTIF(P$7:P128,"应收"),"") | R128: =IF(P128="应付",COUNTIF(P$7:P128,"应付"),"") | S128: =N(F128)-N(G128) -> 0
A129: =IF(AND(F129="",G129=""),"",ROW()-6) | H129: =IF(OR(C129="",AND(F129="",G129="")),"",SUMIF(基础资料!$W$5:$W$24,C129,基础资料!$X$5:$X$24)+SUMIF(C$7:C129,C129,F$7:F129)-SUMIF(C$7:C129,C129,G$7:G129)) | I129: =IF(AND(F129="",G129=""),"",SUM(基础资料!$X$5:$X$24)+SUM(F$7:F129)-SUM(G$7:G129)) | N129: =IF(AND(AND(F129="",G129=""),B129="",C129="",D129="",J129="",K129="",L129=""),"",IF(AND(F129="",G129=""),"✗ 没填金额",IF(AND(N(F129)<>0,N(G129)<>0),"✗ 收入、支出只能填一边",IF(NOT(ISNUMBER(B129)),"✗ 日期不是真日期（要像 2026/9/25 这样填）",IF(OR(B129<年初日,B129>年末日),"✗ 日期不在本会计年度",IF(C129="","✗ 没选账户",IF(COUNTIF(基础资料!$W$5:$W$24,C129)=0,"✗ 账户不在基础资料里",IF(O129="","✗ 没选收支项目",IF(P129="未知","✗ 收支项目不在基础资料里",IF(AND(P129="应收",J129=""),"✗ 这笔要选客户",IF(AND(P129="应收",COUNTIF(总览汇总!$B$5:$B$304,J129)=0),"✗ 客户不在总览汇总名单里",IF(AND(P129="应付",K129=""),"✗ 这笔要选供应商",IF(AND(P129="应付",COUNTIF(基础资料!$Q$5:$Q$54,K129)=0),"✗ 供应商不在基础资料里",IF(AND(P129="费用",L129=""),"✗ 费用支出要选费用项目",IF(AND(L129<>"",COUNTIF(基础资料!$AI$5:$AI$54,L129)=0),"✗ 费用项目不在基础资料里",IF(AND(IFERROR(INDEX(基础资料!$AD$5:$AD$34,MATCH(O129,基础资料!$AC$5:$AC$34,0)),"")="收",N(G129)<>0),"✗ 这类是收款，金额填到收入列",IF(AND(IFERROR(INDEX(基础资料!$AD$5:$AD$34,MATCH(O129,基础资料!$AC$5:$AC$34,0)),"")="支",N(F129)<>0),"✗ 这类是付款，金额填到支出列",IF(N(H129)<0,"⚠ 账户余额成负数了，核对一下","√")))))))))))))))))) | O129: =IF(D129<>"",D129,IF(AND(F129="",G129=""),"",IF(J129<>"",IF(N(F129)>0,"客户回款","客户退款"),IF(K129<>"",IF(N(G129)>0,"供应商付款","供应商退款"),IF(L129<>"","费用支出",""))))) | P129: =IF(O129="","",IFERROR(INDEX(基础资料!$AE$5:$AE$34,MATCH(O129,基础资料!$AC$5:$AC$34,0)),"未知")) | Q129: =IF(P129="应收",COUNTIF(P$7:P129,"应收"),"") | R129: =IF(P129="应付",COUNTIF(P$7:P129,"应付"),"") | S129: =N(F129)-N(G129) -> 0
A130: =IF(AND(F130="",G130=""),"",ROW()-6) | H130: =IF(OR(C130="",AND(F130="",G130="")),"",SUMIF(基础资料!$W$5:$W$24,C130,基础资料!$X$5:$X$24)+SUMIF(C$7:C130,C130,F$7:F130)-SUMIF(C$7:C130,C130,G$7:G130)) | I130: =IF(AND(F130="",G130=""),"",SUM(基础资料!$X$5:$X$24)+SUM(F$7:F130)-SUM(G$7:G130)) | N130: =IF(AND(AND(F130="",G130=""),B130="",C130="",D130="",J130="",K130="",L130=""),"",IF(AND(F130="",G130=""),"✗ 没填金额",IF(AND(N(F130)<>0,N(G130)<>0),"✗ 收入、支出只能填一边",IF(NOT(ISNUMBER(B130)),"✗ 日期不是真日期（要像 2026/9/25 这样填）",IF(OR(B130<年初日,B130>年末日),"✗ 日期不在本会计年度",IF(C130="","✗ 没选账户",IF(COUNTIF(基础资料!$W$5:$W$24,C130)=0,"✗ 账户不在基础资料里",IF(O130="","✗ 没选收支项目",IF(P130="未知","✗ 收支项目不在基础资料里",IF(AND(P130="应收",J130=""),"✗ 这笔要选客户",IF(AND(P130="应收",COUNTIF(总览汇总!$B$5:$B$304,J130)=0),"✗ 客户不在总览汇总名单里",IF(AND(P130="应付",K130=""),"✗ 这笔要选供应商",IF(AND(P130="应付",COUNTIF(基础资料!$Q$5:$Q$54,K130)=0),"✗ 供应商不在基础资料里",IF(AND(P130="费用",L130=""),"✗ 费用支出要选费用项目",IF(AND(L130<>"",COUNTIF(基础资料!$AI$5:$AI$54,L130)=0),"✗ 费用项目不在基础资料里",IF(AND(IFERROR(INDEX(基础资料!$AD$5:$AD$34,MATCH(O130,基础资料!$AC$5:$AC$34,0)),"")="收",N(G130)<>0),"✗ 这类是收款，金额填到收入列",IF(AND(IFERROR(INDEX(基础资料!$AD$5:$AD$34,MATCH(O130,基础资料!$AC$5:$AC$34,0)),"")="支",N(F130)<>0),"✗ 这类是付款，金额填到支出列",IF(N(H130)<0,"⚠ 账户余额成负数了，核对一下","√")))))))))))))))))) | O130: =IF(D130<>"",D130,IF(AND(F130="",G130=""),"",IF(J130<>"",IF(N(F130)>0,"客户回款","客户退款"),IF(K130<>"",IF(N(G130)>0,"供应商付款","供应商退款"),IF(L130<>"","费用支出",""))))) | P130: =IF(O130="","",IFERROR(INDEX(基础资料!$AE$5:$AE$34,MATCH(O130,基础资料!$AC$5:$AC$34,0)),"未知")) | Q130: =IF(P130="应收",COUNTIF(P$7:P130,"应收"),"") | R130: =IF(P130="应付",COUNTIF(P$7:P130,"应付"),"") | S130: =N(F130)-N(G130) -> 0
A131: =IF(AND(F131="",G131=""),"",ROW()-6) | H131: =IF(OR(C131="",AND(F131="",G131="")),"",SUMIF(基础资料!$W$5:$W$24,C131,基础资料!$X$5:$X$24)+SUMIF(C$7:C131,C131,F$7:F131)-SUMIF(C$7:C131,C131,G$7:G131)) | I131: =IF(AND(F131="",G131=""),"",SUM(基础资料!$X$5:$X$24)+SUM(F$7:F131)-SUM(G$7:G131)) | N131: =IF(AND(AND(F131="",G131=""),B131="",C131="",D131="",J131="",K131="",L131=""),"",IF(AND(F131="",G131=""),"✗ 没填金额",IF(AND(N(F131)<>0,N(G131)<>0),"✗ 收入、支出只能填一边",IF(NOT(ISNUMBER(B131)),"✗ 日期不是真日期（要像 2026/9/25 这样填）",IF(OR(B131<年初日,B131>年末日),"✗ 日期不在本会计年度",IF(C131="","✗ 没选账户",IF(COUNTIF(基础资料!$W$5:$W$24,C131)=0,"✗ 账户不在基础资料里",IF(O131="","✗ 没选收支项目",IF(P131="未知","✗ 收支项目不在基础资料里",IF(AND(P131="应收",J131=""),"✗ 这笔要选客户",IF(AND(P131="应收",COUNTIF(总览汇总!$B$5:$B$304,J131)=0),"✗ 客户不在总览汇总名单里",IF(AND(P131="应付",K131=""),"✗ 这笔要选供应商",IF(AND(P131="应付",COUNTIF(基础资料!$Q$5:$Q$54,K131)=0),"✗ 供应商不在基础资料里",IF(AND(P131="费用",L131=""),"✗ 费用支出要选费用项目",IF(AND(L131<>"",COUNTIF(基础资料!$AI$5:$AI$54,L131)=0),"✗ 费用项目不在基础资料里",IF(AND(IFERROR(INDEX(基础资料!$AD$5:$AD$34,MATCH(O131,基础资料!$AC$5:$AC$34,0)),"")="收",N(G131)<>0),"✗ 这类是收款，金额填到收入列",IF(AND(IFERROR(INDEX(基础资料!$AD$5:$AD$34,MATCH(O131,基础资料!$AC$5:$AC$34,0)),"")="支",N(F131)<>0),"✗ 这类是付款，金额填到支出列",IF(N(H131)<0,"⚠ 账户余额成负数了，核对一下","√")))))))))))))))))) | O131: =IF(D131<>"",D131,IF(AND(F131="",G131=""),"",IF(J131<>"",IF(N(F131)>0,"客户回款","客户退款"),IF(K131<>"",IF(N(G131)>0,"供应商付款","供应商退款"),IF(L131<>"","费用支出",""))))) | P131: =IF(O131="","",IFERROR(INDEX(基础资料!$AE$5:$AE$34,MATCH(O131,基础资料!$AC$5:$AC$34,0)),"未知")) | Q131: =IF(P131="应收",COUNTIF(P$7:P131,"应收"),"") | R131: =IF(P131="应付",COUNTIF(P$7:P131,"应付"),"") | S131: =N(F131)-N(G131) -> 0
A132: =IF(AND(F132="",G132=""),"",ROW()-6) | H132: =IF(OR(C132="",AND(F132="",G132="")),"",SUMIF(基础资料!$W$5:$W$24,C132,基础资料!$X$5:$X$24)+SUMIF(C$7:C132,C132,F$7:F132)-SUMIF(C$7:C132,C132,G$7:G132)) | I132: =IF(AND(F132="",G132=""),"",SUM(基础资料!$X$5:$X$24)+SUM(F$7:F132)-SUM(G$7:G132)) | N132: =IF(AND(AND(F132="",G132=""),B132="",C132="",D132="",J132="",K132="",L132=""),"",IF(AND(F132="",G132=""),"✗ 没填金额",IF(AND(N(F132)<>0,N(G132)<>0),"✗ 收入、支出只能填一边",IF(NOT(ISNUMBER(B132)),"✗ 日期不是真日期（要像 2026/9/25 这样填）",IF(OR(B132<年初日,B132>年末日),"✗ 日期不在本会计年度",IF(C132="","✗ 没选账户",IF(COUNTIF(基础资料!$W$5:$W$24,C132)=0,"✗ 账户不在基础资料里",IF(O132="","✗ 没选收支项目",IF(P132="未知","✗ 收支项目不在基础资料里",IF(AND(P132="应收",J132=""),"✗ 这笔要选客户",IF(AND(P132="应收",COUNTIF(总览汇总!$B$5:$B$304,J132)=0),"✗ 客户不在总览汇总名单里",IF(AND(P132="应付",K132=""),"✗ 这笔要选供应商",IF(AND(P132="应付",COUNTIF(基础资料!$Q$5:$Q$54,K132)=0),"✗ 供应商不在基础资料里",IF(AND(P132="费用",L132=""),"✗ 费用支出要选费用项目",IF(AND(L132<>"",COUNTIF(基础资料!$AI$5:$AI$54,L132)=0),"✗ 费用项目不在基础资料里",IF(AND(IFERROR(INDEX(基础资料!$AD$5:$AD$34,MATCH(O132,基础资料!$AC$5:$AC$34,0)),"")="收",N(G132)<>0),"✗ 这类是收款，金额填到收入列",IF(AND(IFERROR(INDEX(基础资料!$AD$5:$AD$34,MATCH(O132,基础资料!$AC$5:$AC$34,0)),"")="支",N(F132)<>0),"✗ 这类是付款，金额填到支出列",IF(N(H132)<0,"⚠ 账户余额成负数了，核对一下","√")))))))))))))))))) | O132: =IF(D132<>"",D132,IF(AND(F132="",G132=""),"",IF(J132<>"",IF(N(F132)>0,"客户回款","客户退款"),IF(K132<>"",IF(N(G132)>0,"供应商付款","供应商退款"),IF(L132<>"","费用支出",""))))) | P132: =IF(O132="","",IFERROR(INDEX(基础资料!$AE$5:$AE$34,MATCH(O132,基础资料!$AC$5:$AC$34,0)),"未知")) | Q132: =IF(P132="应收",COUNTIF(P$7:P132,"应收"),"") | R132: =IF(P132="应付",COUNTIF(P$7:P132,"应付"),"") | S132: =N(F132)-N(G132) -> 0
A133: =IF(AND(F133="",G133=""),"",ROW()-6) | H133: =IF(OR(C133="",AND(F133="",G133="")),"",SUMIF(基础资料!$W$5:$W$24,C133,基础资料!$X$5:$X$24)+SUMIF(C$7:C133,C133,F$7:F133)-SUMIF(C$7:C133,C133,G$7:G133)) | I133: =IF(AND(F133="",G133=""),"",SUM(基础资料!$X$5:$X$24)+SUM(F$7:F133)-SUM(G$7:G133)) | N133: =IF(AND(AND(F133="",G133=""),B133="",C133="",D133="",J133="",K133="",L133=""),"",IF(AND(F133="",G133=""),"✗ 没填金额",IF(AND(N(F133)<>0,N(G133)<>0),"✗ 收入、支出只能填一边",IF(NOT(ISNUMBER(B133)),"✗ 日期不是真日期（要像 2026/9/25 这样填）",IF(OR(B133<年初日,B133>年末日),"✗ 日期不在本会计年度",IF(C133="","✗ 没选账户",IF(COUNTIF(基础资料!$W$5:$W$24,C133)=0,"✗ 账户不在基础资料里",IF(O133="","✗ 没选收支项目",IF(P133="未知","✗ 收支项目不在基础资料里",IF(AND(P133="应收",J133=""),"✗ 这笔要选客户",IF(AND(P133="应收",COUNTIF(总览汇总!$B$5:$B$304,J133)=0),"✗ 客户不在总览汇总名单里",IF(AND(P133="应付",K133=""),"✗ 这笔要选供应商",IF(AND(P133="应付",COUNTIF(基础资料!$Q$5:$Q$54,K133)=0),"✗ 供应商不在基础资料里",IF(AND(P133="费用",L133=""),"✗ 费用支出要选费用项目",IF(AND(L133<>"",COUNTIF(基础资料!$AI$5:$AI$54,L133)=0),"✗ 费用项目不在基础资料里",IF(AND(IFERROR(INDEX(基础资料!$AD$5:$AD$34,MATCH(O133,基础资料!$AC$5:$AC$34,0)),"")="收",N(G133)<>0),"✗ 这类是收款，金额填到收入列",IF(AND(IFERROR(INDEX(基础资料!$AD$5:$AD$34,MATCH(O133,基础资料!$AC$5:$AC$34,0)),"")="支",N(F133)<>0),"✗ 这类是付款，金额填到支出列",IF(N(H133)<0,"⚠ 账户余额成负数了，核对一下","√")))))))))))))))))) | O133: =IF(D133<>"",D133,IF(AND(F133="",G133=""),"",IF(J133<>"",IF(N(F133)>0,"客户回款","客户退款"),IF(K133<>"",IF(N(G133)>0,"供应商付款","供应商退款"),IF(L133<>"","费用支出",""))))) | P133: =IF(O133="","",IFERROR(INDEX(基础资料!$AE$5:$AE$34,MATCH(O133,基础资料!$AC$5:$AC$34,0)),"未知")) | Q133: =IF(P133="应收",COUNTIF(P$7:P133,"应收"),"") | R133: =IF(P133="应付",COUNTIF(P$7:P133,"应付"),"") | S133: =N(F133)-N(G133) -> 0
A134: =IF(AND(F134="",G134=""),"",ROW()-6) | H134: =IF(OR(C134="",AND(F134="",G134="")),"",SUMIF(基础资料!$W$5:$W$24,C134,基础资料!$X$5:$X$24)+SUMIF(C$7:C134,C134,F$7:F134)-SUMIF(C$7:C134,C134,G$7:G134)) | I134: =IF(AND(F134="",G134=""),"",SUM(基础资料!$X$5:$X$24)+SUM(F$7:F134)-SUM(G$7:G134)) | N134: =IF(AND(AND(F134="",G134=""),B134="",C134="",D134="",J134="",K134="",L134=""),"",IF(AND(F134="",G134=""),"✗ 没填金额",IF(AND(N(F134)<>0,N(G134)<>0),"✗ 收入、支出只能填一边",IF(NOT(ISNUMBER(B134)),"✗ 日期不是真日期（要像 2026/9/25 这样填）",IF(OR(B134<年初日,B134>年末日),"✗ 日期不在本会计年度",IF(C134="","✗ 没选账户",IF(COUNTIF(基础资料!$W$5:$W$24,C134)=0,"✗ 账户不在基础资料里",IF(O134="","✗ 没选收支项目",IF(P134="未知","✗ 收支项目不在基础资料里",IF(AND(P134="应收",J134=""),"✗ 这笔要选客户",IF(AND(P134="应收",COUNTIF(总览汇总!$B$5:$B$304,J134)=0),"✗ 客户不在总览汇总名单里",IF(AND(P134="应付",K134=""),"✗ 这笔要选供应商",IF(AND(P134="应付",COUNTIF(基础资料!$Q$5:$Q$54,K134)=0),"✗ 供应商不在基础资料里",IF(AND(P134="费用",L134=""),"✗ 费用支出要选费用项目",IF(AND(L134<>"",COUNTIF(基础资料!$AI$5:$AI$54,L134)=0),"✗ 费用项目不在基础资料里",IF(AND(IFERROR(INDEX(基础资料!$AD$5:$AD$34,MATCH(O134,基础资料!$AC$5:$AC$34,0)),"")="收",N(G134)<>0),"✗ 这类是收款，金额填到收入列",IF(AND(IFERROR(INDEX(基础资料!$AD$5:$AD$34,MATCH(O134,基础资料!$AC$5:$AC$34,0)),"")="支",N(F134)<>0),"✗ 这类是付款，金额填到支出列",IF(N(H134)<0,"⚠ 账户余额成负数了，核对一下","√")))))))))))))))))) | O134: =IF(D134<>"",D134,IF(AND(F134="",G134=""),"",IF(J134<>"",IF(N(F134)>0,"客户回款","客户退款"),IF(K134<>"",IF(N(G134)>0,"供应商付款","供应商退款"),IF(L134<>"","费用支出",""))))) | P134: =IF(O134="","",IFERROR(INDEX(基础资料!$AE$5:$AE$34,MATCH(O134,基础资料!$AC$5:$AC$34,0)),"未知")) | Q134: =IF(P134="应收",COUNTIF(P$7:P134,"应收"),"") | R134: =IF(P134="应付",COUNTIF(P$7:P134,"应付"),"") | S134: =N(F134)-N(G134) -> 0
