Workbook

Sheet 应收账款
A1: 项目名称 | B1: 客户名称 | C1: 应收金额(元） | D1: 已收金额（元） | E1: 回款比例 | F1: 未收金额（元） | G1: 已开票金额 | H1: 税率 | I1: 未开票金额 | J1: 备注
C2: 0 | D2: 0 | F2: 0 | G2: 0 | I2: 0
A3: 博河科创 | B3: 德安县博河产业控股集团有限公司 | C3: 510758.96 | D3: 0 | E3: 0 | F3: 510758.96 | G3: 102151.79 | I3: 408607.17
A4: 德安养老中心 | B4: 九江浔辉建筑工程有限公司 | C4: 4362576.5 | D4: 2658453.4 | E4: 0.60937691 | F4: 1704123.1 | G4: 2658453.4 | I4: 1704123.1
B5: 江西揽之建设工程有限公司 | C5: 695372.72 | D5: 562296 | E5: 0.80862534 | F5: 133076.72 | G5: 562296 | I5: 133076.72
B6: 江西揽之建设工程有限公司 | C6: 960000 | D6: 670593.83 | E6: 0.69853524 | F6: 289406.17 | G6: 670593.83 | I6: 289406.17
B7: 江西揽之建设工程有限公司 | C7: 64000 | D7: 51200 | E7: 0.8 | F7: 12800 | G7: 51200 | I7: 12800
B8: 德安县市政工程公司 | C8: 1641809 | D8: 1148361.8 | E8: 0.69944908 | F8: 493447.2 | G8: 1148361.8 | I8: 493447.2
B9: 德安县水利水电建筑工程公司 | C9: 95560.56 | D9: 63746.59 | E9: 0.66708054 | F9: 31813.97 | G9: 88334.56 | I9: 2672

Sheet 应付账款
A1: 应付账款总表 | F1: 开始日期 | G1: 45292 | H1: 结束日期 | I1: 28
A3: 序号 | B3: 供应商名称 | C3: 链接 | D3: 应付总额 | E3: 已付总额 | F3: 剩余未付总额 | G3: 德安养老中心 | H3: 科创中心 | I3: 九安架空层 | J3: 数字产业园 | K3: 德安农商行总部 | L3: 抚州1号楼 | M3: 抚州8号楼
A4: 1 | B4: 筑强 | C4: 点击跳转 | D4: 1532992 | E4: 1308939.2 | F4: 224052.85 | G4: 604482.11 | H4: 446419.88 | I4: 44610.37 | J4: 33897.01 | K4: 546.94 | L4: 196807.17 | M4: 165801.94
A5: 2 | B5: 九江安洋钢材熊总 | C5: 点击跳转 | D5: 331446.38 | E5: 331446.38 | F5: 0 | G5: 331446.38 | H5: 0 | I5: 0 | J5: 0 | K5: 0 | L5: 0 | M5: 0
A6: 3 | B6: 鑫城五金庄总 | C6: 点击跳转 | D6: 256240 | E6: 256240 | F6: 0 | G6: 64938.4 | H6: 0 | I6: 172061.6 | J6: 0 | K6: 0 | L6: 0 | M6: 0
A7: 4 | B7: 浔阳楼电缆 | C7: 点击跳转 | D7: 222007 | E7: 187470 | F7: 34537 | G7: 128958 | H7: 11971 | I7: 0 | J7: 0 | K7: 0 | L7: 5808 | M7: 59858
A8: 5 | B8: 启航五金 | C8: 点击跳转 | D8: 30949 | E8: 22490 | F8: 8459 | G8: 19835 | H8: 8112 | I8: 327 | J8: 978 | K8: 0 | L8: 0 | M8: 0
A9: 6 | B9: 杭州行消物资贸易 | C9: 点击跳转 | D9: 36511 | E9: 36511 | F9: 0 | G9: 10338 | H9: 10121 | I9: 0 | J9: 0 | K9: 0 | L9: 10068 | M9: 5984
A10: 7 | B10: 南昌盈厚建材 | C10: 点击跳转 | D10: 34674 | E10: 34674 | F10: 0 | G10: 24954 | H10: 0 | I10: 0 | J10: 0 | K10: 0 | L10: 9720 | M10: 0
A11: 8 | B11: 浙缆元通电缆 | C11: 点击跳转 | D11: 74807.4 | E11: 74807.4 | F11: 0 | G11: 38175.4 | H11: 0 | I11: 0 | J11: 0 | K11: 0 | L11: 36632 | M11: 0
A12: 9 | B12: 江西允诺消防 | C12: 点击跳转 | D12: 45881 | E12: 45881 | F12: 0 | G12: 45881 | H12: 0 | I12: 0 | J12: 0 | K12: 0 | L12: 0 | M12: 0
A13: 10 | B13: 江西沐丰水箱 | C13: 点击跳转 | D13: 55000 | E13: 53500 | F13: 1500 | G13: 0 | H13: 31500 | I13: 0 | J13: 0 | K13: 0 | L13: 0 | M13: 0
A14: 11 | B14: 上海诚果泵阀 | C14: 点击跳转 | D14: 90744 | E14: 90744 | F14: 0 | G14: 63800 | H14: 15144 | I14: 0 | J14: 0 | K14: 0 | L14: 0 | M14: 0

Sheet 分包商
A1: 应付分包商账款 | E1: 开始日期 | F1: 25 | G1: 结束日期 | H1: 25
A3: 分包商 | B3: 链接 | C3: 应付总额 | D3: 已付总额 | E3: 剩余未付总额 | F3: 德安养老中心 | G3: 科创中心 | H3: 九安架空层 | I3: 数字产业园 | K3: 抚州1号楼 | L3: 抚州8号楼
A4: 恩旗老叶 | B4: 点击跳转 | C4: 558437.5 | D4: 558437.5 | E4: 0 | F4: 520437.5 | G4: 0 | H4: 0 | I4: 0 | J4: 0 | K4: 38000 | L4: 0
A5: 吴群 | B5: 点击跳转 | C5: 78100 | D5: 78100 | E5: 0 | F5: 78100 | G5: 0 | H5: 0 | I5: 0 | J5: 0 | K5: 0 | L5: 0
A6: 吴聪 | B6: 点击跳转 | C6: 28000 | D6: 28000 | E6: 0 | F6: 28000 | G6: 0 | H6: 0 | I6: 0 | J6: 0 | K6: 0 | L6: 0
A7: 九江朱总 | B7: 点击跳转 | C7: 55000 | D7: 55400 | E7: -400 | F7: 55000 | G7: 0 | H7: 0 | I7: 0 | J7: 0 | K7: 0 | L7: 0
A8: 共安门业 | B8: 点击跳转 | C8: 128922.53 | D8: 128922 | E8: 0.53 | F8: 101842.53 | G8: 0 | H8: 0 | I8: 0 | J8: 0 | K8: 14680 | L8: 12400
A9: 图揽成善 | B9: 点击跳转 | C9: 155462 | D9: 101245 | E9: 54217 | F9: 120527 | G9: 0 | H9: 0 | I9: 0 | J9: 0 | K9: 22812 | L9: 10855
A10: 祝冬冬 | B10: 点击跳转 | C10: 140000 | D10: 132000 | E10: 8000 | F10: 0 | G10: 0 | H10: 0 | I10: 0 | J10: 0 | K10: 0 | L10: 140000
A11: 张小朋 | B11: 点击跳转 | C11: 52410 | D11: 50260 | E11: 2150 | F11: 0 | G11: 0 | H11: 0 | I11: 52410 | J11: 0 | K11: 0 | L11: 0
A12: 徐怀生 | B12: 点击跳转 | C12: 35960 | D12: 35960 | E12: 0 | F12: 0 | G12: 0 | H12: 35960 | I12: 0 | J12: 0 | K12: 0 | L12: 0

Sheet 机械费
A1: 机械费汇总表 | B1: 机械+运输费用汇总表 | O1: {=_xlfn.PIVOTBY(_xlfn._TRO_TRAILING(C2:C999),,_xlfn._TRO_TRAILING(D2:E999),_xleta.SUM,3)} -> 项目名称 | P1: 应付金额 | Q1: 已付金额 | R1: 未付金额
A2: 日期 | B2: 挖机班组/（运输）名称 | C2: 项目名称 | D2: 应付金额 | E2: 已付金额 | F2: 付款日期 | G2: 付款账户 | H2: 收款账户 | I2: 已开票金额 | J2: 开票日期 | K2: 税率 | L2: 税额 | M2: 备注2 | O2: 德安农商行总部 | P2: 800 | Q2: 800 | R2: =P2-Q2 -> 0
A3: 25/11-26/1 | B3: 杨工 | C3: 科创中心 | D3: 98875 | E3: 30000 | G3: 王伟垫付 | O3: 科创中心 | P3: 105775 | Q3: 35000 | R3: =P3-Q3 -> 70775
A4: 25/11-26/1 | B4: 徐工 | C4: 科创中心 | D4: 6900 | E4: 5000 | F4: 45971 | G4: 九江银行 | H4: 九江翌年行建筑工程劳务有限公司 | I4: 5000 | K4: 0.01 | O4: 邹桥派出所 | P4: 1280 | Q4: 1280 | R4: =P4-Q4 -> 0
A5: 46174 | B5: 德安县恒建工程部 | C5: 德安农商行总部 | D5: 800 | E5: 800 | F5: 46205 | G5: 九江银行 | H5: 舒文龙 | I5: 800 | K5: 0.01 | O5: 总计 | P5: 107855 | Q5: 37080
A6: 46173 | B6: 航帆增辉 | C6: 邹桥派出所 | D6: 1000 | E6: 1000 | F6: 46173 | G6: 王伟垫付 | H6: 航帆增辉
A7: 46172 | B7: 章德吉货运 | C7: 邹桥派出所 | D7: 280 | E7: 280 | F7: 46172 | G7: 王伟垫付 | H7: 章德吉货运

Sheet 流水登记
A1: 流水账登记总表
I3: 九江银行
A4: 期初余额: | B4: 0 | E4: 收入合计： | F4: =SUBTOTAL(9,D10:D2006) -> 1865048.4 | I4: 农业银行
I5: 工商银行
A6: 账户余额： | B6: 0 | E6: 支出合计： | F6: =SUBTOTAL(9,E10:E2006) -> 1467663.6 | I6: 聂辉微信
I7: 王伟微信
I8: 张滨微信
A9: 日期 | B9: 账户 | C9: 摘要 | D9: 收入 | E9: 支出 | F9: 结存 | G9: 备注
A10: 46143 | B10: 九江银行 | C10: 代吴群付向勇工资 | E10: 15000 | F10: {=_xlfn.SCAN(B4,D10:D2006-E10:E2006,_xleta.SUM)} -> -15000
A11: 46144 | B11: 九江银行 | C11: 付邓泽贵工资 | E11: 3000 | F11: -18000
A12: 46144 | B12: 九江银行 | C12: 付吴志刚工资 | E12: 3000 | F12: -21000
A13: 46144 | B13: 九江银行 | C13: 付金南水工资 | E13: 3000 | F13: -24000
A14: 46145 | B14: 九江银行 | C14: 付张亮亮工资 | E14: 4000 | F14: -28000
A15: 46148 | B15: 九江银行 | C15: 付共安门业材料款 | E15: 4940 | F15: -32940
A16: 46150 | B16: 九江银行 | C16: 收到股东借款-聂辉 | E16: -10000 | F16: -22940
A17: 46150 | B17: 九江银行 | C17: 收到股东借款-聂辉 | E17: -2000 | F17: -20940
A18: 46150 | B18: 九江银行 | C18: 支付酒款 | E18: 20000 | F18: -40940
A19: 46155 | B19: 九江银行 | C19: 收到股东借款-聂辉 | E19: -10000 | F19: -30940
A20: 46155 | B20: 九江银行 | C20: 支付异地预缴税 | E20: 6467.49 | F20: -37407.49
A21: 46155 | B21: 九江银行 | C21: 支付异地预缴税 | E21: 410.63 | F21: -37818.12
A22: 46155 | B22: 九江银行 | C22: 代扣个税 | E22: 1245.06 | F22: -39063.18
... A28: 46161 | B28: 九江银行 | C28: 支付食品厂投标保证金 | E28: 90000 | F28: -38460.18
A29: 46163 | B29: 九江银行 | C29: 收江西赣粤高速公路工程款 | D29: 14502.87 | F29: -23957.31
A30: 46164 | B30: 九江银行 | C30: 食品厂投标保证金退回 | E30: -90000 | F30: 66042.69
A31: 46165 | B31: 九江银行 | C31: 归还股东个人借款-聂辉 | E31: 10000 | F31: 56042.69
A32: 46165 | B32: 九江银行 | C32: 归还股东个人借款-聂辉 | E32: 80000 | F32: -23957.31
A33: 46167 | B33: 九江银行 | C33: 支付社保费 | E33: 30.54 | F33: -23987.85
A34: 46167 | B34: 九江银行 | C34: 支付社保费 | E34: 2008.42 | F34: -25996.27
A35: 46170 | B35: 九江银行 | C35: 付代账公司费用 | E35: 1000 | F35: -26996.27
A36: 46145 | B36: 王伟微信 | C36: 支付顺丰快递费 | E36: 23 | F36: -27019.27
A37: 46145 | B37: 王伟微信 | C37: 付老叶分包劳务费 | E37: 3000 | F37: -30019.27
A38: 46146 | B38: 王伟微信 | C38: 支付快餐费 | E38: 68 | F38: -30087.27
A39: 46154 | B39: 王伟微信 | C39: 皮卡车加油 | E39: 200 | F39: -30287.27
A40: 46156 | B40: 王伟微信 | C40: 付养老中心期间费 | E40: 4000 | F40: -34287.27
A41: 46157 | B41: 王伟微信 | C41: 公司日用品 | E41: 55 | F41: -34342.27
... A66: 46163 | B66: 农业银行 | C66: 支付贷款利息 | E66: 1052.92 | F66: -41108.79
A67: 46022 | B67: 工商银行 | C67: 云链平台转入 | D67: 0.01 | F67: -41108.78
A68: 46034 | B68: 工商银行 | C68: 对公贷款 | D68: 281148 | F68: 240039.22
A69: 46036 | B69: 工商银行 | C69: 付筑强货款 | E69: 281000 | F69: -40960.78
A70: 46036 | B70: 工商银行 | C70: 跨行汇款手续费 | E70: 0.01 | F70: -40960.79
...

Sheet 工资表月分表
B1: 26年4月工资表 | W1: 26年4月工资明细
A2: 序号 | B2: 姓名 | C2: 身份证号 | D2: 手机号 | E2: 账号 | F2: 开户行 | G2: 德养 | H2: 科创中心 | I2: 示范园 | J2: 邹桥 | K2: 架空层 | L2: 未知 | M2: 未知 | N2: 未知 | O2: 未知 | P2: 未知 | Q2: 未知 | R2: 未知 | S2: 未知 | T2: 未知 | U2: 合计天数 | V2: 日工资 (月工资） | W2: 德养小计 | X2: 科创中心小计 | Y2: 示范园小计 | Z2: 邹桥小计 | AA2: 架空层小计 | AK2: 应发工资 | AL2: 本月发工资 | AM2: 补贴 | AN2: 代扣个税 | AO2: 代扣社保 | AP2: 已退回 | AQ2: 剩余工资
A3: =ROW()-2 -> 1 | B3: 聂峰 | F3: =IFERROR(VLOOKUP($B3,[1]基础信息表!$A:$F,5,FALSE),"") -> 共青农商行 | H3: 6 | J3: 18 | U3: =SUM(G3:T3) -> 24 | V3: =IFERROR(VLOOKUP($B3,[1]基础信息表!$A:$F,6,FALSE),"") -> 500 | W3: =IFERROR(G3*$V3,"") -> 0 | X3: =IFERROR(H3*$V3,"") -> 3000 | Y3: =IFERROR(I3*$V3,"") -> 0 | Z3: =IFERROR(J3*$V3,"") -> 9000 | AA3: =IFERROR(K3*$V3,"") -> 0 | AB3: =IFERROR(L3*$V3,"") -> 0 | AC3: =IFERROR(M3*$V3,"") -> 0 | AD3: =IFERROR(N3*$V3,"") -> 0 | ... AJ3: =IFERROR(T3*$V3,"") -> 0 | AK3: =IFERROR(V3*U3,"") -> 12000 | AL3: 10000 | AN3: 50 | AP3: 2000 | AQ3: =AK3-AL3-AN3+AP3 -> 3950
A4: =ROW()-2 -> 2 | B4: 袁斌财 | F4: =IFERROR(VLOOKUP($B4,[1]基础信息表!$A:$F,5,FALSE),"") -> 建行 | G4: 7.67 | K4: 17 | U4: =SUM(G4:T4) -> 24.67 | V4: =IFERROR(VLOOKUP($B4,[1]基础信息表!$A:$F,6,FALSE),"") -> 330 | W4: =IFERROR(G4*$V4,"") -> 2531.1 | X4: =IFERROR(H4*$V4,"") -> 0 | Y4: =IFERROR(I4*$V4,"") -> 0 | Z4: =IFERROR(J4*$V4,"") -> 0 | AA4: =IFERROR(K4*$V4,"") -> 5610 | AB4: =IFERROR(L4*$V4,"") -> 0 | AC4: =IFERROR(M4*$V4,"") -> 0 | AD4: =IFERROR(N4*$V4,"") -> 0 | ... AJ4: =IFERROR(T4*$V4,"") -> 0 | AK4: =IFERROR(V4*U4,"") -> 8141.1 | AL4: 10001 | AQ4: =AK4-AL7-AN4+AP4 -> 141.1
A5: =ROW()-2 -> 3 | B5: 胡家新 | F5: =IFERROR(VLOOKUP($B5,[1]基础信息表!$A:$F,5,FALSE),"") -> 建行 | G5: 3 | U5: =SUM(G5:T5) -> 3 | V5: =IFERROR(VLOOKUP($B5,[1]基础信息表!$A:$F,6,FALSE),"") -> 270 | W5: =IFERROR(G5*$V5,"") -> 810 | X5: =IFERROR(H5*$V5,"") -> 0 | Y5: =IFERROR(I5*$V5,"") -> 0 | Z5: =IFERROR(J5*$V5,"") -> 0 | AA5: =IFERROR(K5*$V5,"") -> 0 | AB5: =IFERROR(L5*$V5,"") -> 0 | AC5: =IFERROR(M5*$V5,"") -> 0 | AD5: =IFERROR(N5*$V5,"") -> 0 | ... AJ5: =IFERROR(T5*$V5,"") -> 0 | AK5: =IFERROR(V5*U5,"") -> 810 | AL5: 10002 | AQ5: =AK5-AL5-AN5+AP5 -> -9192
A6: =ROW()-2 -> 4 | B6: 刘海 | F6: =IFERROR(VLOOKUP($B6,[1]基础信息表!$A:$F,5,FALSE),"") -> 建行 | G6: 3 | U6: =SUM(G6:T6) -> 3 | V6: =IFERROR(VLOOKUP($B6,[1]基础信息表!$A:$F,6,FALSE),"") -> 250 | W6: =IFERROR(G6*$V6,"") -> 750 | X6: =IFERROR(H6*$V6,"") -> 0 | Y6: =IFERROR(I6*$V6,"") -> 0 | Z6: =IFERROR(J6*$V6,"") -> 0 | AA6: =IFERROR(K6*$V6,"") -> 0 | AB6: =IFERROR(L6*$V6,"") -> 0 | AC6: =IFERROR(M6*$V6,"") -> 0 | AD6: =IFERROR(N6*$V6,"") -> 0 | ... AJ6: =IFERROR(T6*$V6,"") -> 0 | AK6: =IFERROR(V6*U6,"") -> 750 | AP6: 1000 | AQ6: =AK6-AL6-AN6+AP6 -> 1750
A7: =ROW()-2 -> 5 | B7: 程章赐 | F7: =IFERROR(VLOOKUP($B7,[1]基础信息表!$A:$F,5,FALSE),"") -> 工行宁波奉化大桥支行 | G7: 10 | H7: 0.5 | J7: 4.5 | U7: =SUM(G7:T7) -> 15 | V7: =IFERROR(VLOOKUP($B7,[1]基础信息表!$A:$F,6,FALSE),"") -> 350 | W7: =IFERROR(G7*$V7,"") -> 3500 | X7: =IFERROR(H7*$V7,"") -> 175 | Y7: =IFERROR(I7*$V7,"") -> 0 | Z7: =IFERROR(J7*$V7,"") -> 1575 | AA7: =IFERROR(K7*$V7,"") -> 0 | AB7: =IFERROR(L7*$V7,"") -> 0 | AC7: =IFERROR(M7*$V7,"") -> 0 | AD7: =IFERROR(N7*$V7,"") -> 0 | ... AJ7: =IFERROR(T7*$V7,"") -> 0 | AK7: =IFERROR(V7*U7,"") -> 5250 | AL7: 8000 | AQ7: =AK7-#REF!-AN7+AP7 -> #REF!
A8: =ROW()-2 -> 6 | B8: 程章材 | F8: =IFERROR(VLOOKUP($B8,[1]基础信息表!$A:$F,5,FALSE),"") -> 工行德安支行营业室 | G8: 7 | H8: 0.5 | J8: 4.5 | U8: =SUM(G8:T8) -> 12 | V8: =IFERROR(VLOOKUP($B8,[1]基础信息表!$A:$F,6,FALSE),"") -> 200 | W8: =IFERROR(G8*$V8,"") -> 1400 | X8: =IFERROR(H8*$V8,"") -> 100 | Y8: =IFERROR(I8*$V8,"") -> 0 | Z8: =IFERROR(J8*$V8,"") -> 900 | AA8: =IFERROR(K8*$V8,"") -> 0 | AB8: =IFERROR(L8*$V8,"") -> 0 | AC8: =IFERROR(M8*$V8,"") -> 0 | AD8: =IFERROR(N8*$V8,"") -> 0 | ... AJ8: =IFERROR(T8*$V8,"") -> 0 | AK8: =IFERROR(V8*U8,"") -> 2400 | AL8: 8001 | AP8: 1000 | AQ8: =AK8-AL8-AN8+AP8 -> -4601
A9: =ROW()-2 -> 7 | B9: 叶炳南 | F9: =IFERROR(VLOOKUP($B9,[1]基础信息表!$A:$F,5,FALSE),"") -> 建行 | G9: 25.78 | U9: =SUM(G9:T9) -> 25.78 | V9: =IFERROR(VLOOKUP($B9,[1]基础信息表!$A:$F,6,FALSE),"") -> 330 | W9: =IFERROR(G9*$V9,"") -> 8507.4 | X9: =IFERROR(H9*$V9,"") -> 0 | Y9: =IFERROR(I9*$V9,"") -> 0 | Z9: =IFERROR(J9*$V9,"") -> 0 | AA9: =IFERROR(K9*$V9,"") -> 0 | AB9: =IFERROR(L9*$V9,"") -> 0 | AC9: =IFERROR(M9*$V9,"") -> 0 | AD9: =IFERROR(N9*$V9,"") -> 0 | ... AJ9: =IFERROR(T9*$V9,"") -> 0 | AK9: =IFERROR(V9*U9,"") -> 8507.4 | AL9: 8002 | AP9: 1001 | AQ9: =AK9-AL9-AN9+AP9 -> 1506.4
A10: =ROW()-2 -> 8 | B10: 万焕和 | F10: =IFERROR(VLOOKUP($B10,[1]基础信息表!$A:$F,5,FALSE),"") -> 建行 | G10: 3 | U10: =SUM(G10:T10) -> 3 | V10: =IFERROR(VLOOKUP($B10,[1]基础信息表!$A:$F,6,FALSE),"") -> 320 | W10: =IFERROR(G10*$V10,"") -> 960 | X10: =IFERROR(H10*$V10,"") -> 0 | Y10: =IFERROR(I10*$V10,"") -> 0 | Z10: =IFERROR(J10*$V10,"") -> 0 | AA10: =IFERROR(K10*$V10,"") -> 0 | AB10: =IFERROR(L10*$V10,"") -> 0 | AC10: =IFERROR(M10*$V10,"") -> 0 | AD10: =IFERROR(N10*$V10,"") -> 0 | ... AJ10: =IFERROR(T10*$V10,"") -> 0 | AK10: =IFERROR(V10*U10,"") -> 960 | AL10: 8003 | AP10: 1002 | AQ10: =AK10-AL10-AN10+AP10 -> -6041
A11: =ROW()-2 -> 9 | B11: 邓泽贵 | F11: =IFERROR(VLOOKUP($B11,[1]基础信息表!$A:$F,5,FALSE),"") -> 建行 | G11: 26.78 | U11: =SUM(G11:T11) -> 26.78 | V11: =IFERROR(VLOOKUP($B11,[1]基础信息表!$A:$F,6,FALSE),"") -> 350 | W11: =IFERROR(G11*$V11,"") -> 9373 | X11: =IFERROR(H11*$V11,"") -> 0 | Y11: =IFERROR(I11*$V11,"") -> 0 | Z11: =IFERROR(J11*$V11,"") -> 0 | AA11: =IFERROR(K11*$V11,"") -> 0 | AB11: =IFERROR(L11*$V11,"") -> 0 | AC11: =IFERROR(M11*$V11,"") -> 0 | AD11: =IFERROR(N11*$V11,"") -> 0 | ... AJ11: =IFERROR(T11*$V11,"") -> 0 | AK11: =IFERROR(V11*U11,"") -> 9373 | AL11: 8004 | AP11: 1003 | AQ11: =AK11-AL11-AN11+AP11 -> 2372
A12: =ROW()-2 -> 10 | B12: 吴长友 | F12: =IFERROR(VLOOKUP($B12,[1]基础信息表!$A:$F,5,FALSE),"") -> 农行 | G12: 14.28 | U12: =SUM(G12:T12) -> 14.28 | V12: =IFERROR(VLOOKUP($B12,[1]基础信息表!$A:$F,6,FALSE),"") -> 330 | W12: =IFERROR(G12*$V12,"") -> 4712.4 | X12: =IFERROR(H12*$V12,"") -> 0 | Y12: =IFERROR(I12*$V12,"") -> 0 | Z12: =IFERROR(J12*$V12,"") -> 0 | AA12: =IFERROR(K12*$V12,"") -> 0 | AB12: =IFERROR(L12*$V12,"") -> 0 | AC12: =IFERROR(M12*$V12,"") -> 0 | AD12: =IFERROR(N12*$V12,"") -> 0 | ... AJ12: =IFERROR(T12*$V12,"") -> 0 | AK12: =IFERROR(V12*U12,"") -> 4712.4 | AL12: 8005 | AP12: 1004 | AQ12: =AK12-AL12-AN12+AP12 -> -2288.6
A13: =ROW()-2 -> 11 | B13: 闵清林 | F13: =IFERROR(VLOOKUP($B13,[1]基础信息表!$A:$F,5,FALSE),"") -> 建行 | G13: 13.5 | U13: =SUM(G13:T13) -> 13.5 | V13: =IFERROR(VLOOKUP($B13,[1]基础信息表!$A:$F,6,FALSE),"") -> 300 | W13: =IFERROR(G13*$V13,"") -> 4050 | X13: =IFERROR(H13*$V13,"") -> 0 | Y13: =IFERROR(I13*$V13,"") -> 0 | Z13: =IFERROR(J13*$V13,"") -> 0 | AA13: =IFERROR(K13*$V13,"") -> 0 | AB13: =IFERROR(L13*$V13,"") -> 0 | AC13: =IFERROR(M13*$V13,"") -> 0 | AD13: =IFERROR(N13*$V13,"") -> 0 | ... AJ13: =IFERROR(T13*$V13,"") -> 0 | AK13: =IFERROR(V13*U13,"") -> 4050 | AL13: 8006 | AP13: 1005 | AQ13: =AK13-AL13-AN13+AP13 -> -2951
A14: =ROW()-2 -> 12 | B14: 徐从国 | F14: =IFERROR(VLOOKUP($B14,[1]基础信息表!$A:$F,5,FALSE),"") -> 建行 | G14: 24.5 | U14: =SUM(G14:T14) -> 24.5 | V14: =IFERROR(VLOOKUP($B14,[1]基础信息表!$A:$F,6,FALSE),"") -> 280 | W14: =IFERROR(G14*$V14,"") -> 6860 | X14: =IFERROR(H14*$V14,"") -> 0 | Y14: =IFERROR(I14*$V14,"") -> 0 | Z14: =IFERROR(J14*$V14,"") -> 0 | AA14: =IFERROR(K14*$V14,"") -> 0 | AB14: =IFERROR(L14*$V14,"") -> 0 | AC14: =IFERROR(M14*$V14,"") -> 0 | AD14: =IFERROR(N14*$V14,"") -> 0 | ... AJ14: =IFERROR(T14*$V14,"") -> 0 | AK14: =IFERROR(V14*U14,"") -> 6860 | AP14: 1006 | AQ14: =AK14-AL14-AN14+AP14 -> 7866
A15: =ROW()-2 -> 13 | B15: 梅秀刚 | F15: =IFERROR(VLOOKUP($B15,[1]基础信息表!$A:$F,5,FALSE),"") -> 建行 | G15: 11.5 | U15: =SUM(G15:T15) -> 11.5 | V15: =IFERROR(VLOOKUP($B15,[1]基础信息表!$A:$F,6,FALSE),"") -> 340 | W15: =IFERROR(G15*$V15,"") -> 3910 | X15: =IFERROR(H15*$V15,"") -> 0 | Y15: =IFERROR(I15*$V15,"") -> 0 | Z15: =IFERROR(J15*$V15,"") -> 0 | AA15: =IFERROR(K15*$V15,"") -> 0 | AB15: =IFERROR(L15*$V15,"") -> 0 | AC15: =IFERROR(M15*$V15,"") -> 0 | AD15: =IFERROR(N15*$V15,"") -> 0 | ... AJ15: =IFERROR(T15*$V15,"") -> 0 | AK15: =IFERROR(V15*U15,"") -> 3910 | AQ15: =AK15-AL15-AN15+AP15 -> 3910
A16: =ROW()-2 -> 14 | B16: 金南水 | F16: =IFERROR(VLOOKUP($B16,[1]基础信息表!$A:$F,5,FALSE),"") -> 建行 | G16: 24.5 | U16: =SUM(G16:T16) -> 24.5 | V16: =IFERROR(VLOOKUP($B16,[1]基础信息表!$A:$F,6,FALSE),"") -> 290 | W16: =IFERROR(G16*$V16,"") -> 7105 | X16: =IFERROR(H16*$V16,"") -> 0 | Y16: =IFERROR(I16*$V16,"") -> 0 | Z16: =IFERROR(J16*$V16,"") -> 0 | AA16: =IFERROR(K16*$V16,"") -> 0 | AB16: =IFERROR(L16*$V16,"") -> 0 | AC16: =IFERROR(M16*$V16,"") -> 0 | AD16: =IFERROR(N16*$V16,"") -> 0 | ... AJ16: =IFERROR(T16*$V16,"") -> 0 | AK16: =IFERROR(V16*U16,"") -> 7105 | AQ16: =AK16-AL16-AN16+AP16 -> 7105
A17: =ROW()-2 -> 15 | B17: 金李平 | F17: =IFERROR(VLOOKUP($B17,[1]基础信息表!$A:$F,5,FALSE),"") -> 温州银行 | G17: 14.28 | U17: =SUM(G17:T17) -> 14.28 | V17: =IFERROR(VLOOKUP($B17,[1]基础信息表!$A:$F,6,FALSE),"") -> 270 | W17: =IFERROR(G17*$V17,"") -> 3855.6 | X17: =IFERROR(H17*$V17,"") -> 0 | Y17: =IFERROR(I17*$V17,"") -> 0 | Z17: =IFERROR(J17*$V17,"") -> 0 | AA17: =IFERROR(K17*$V17,"") -> 0 | AB17: =IFERROR(L17*$V17,"") -> 0 | AC17: =IFERROR(M17*$V17,"") -> 0 | AD17: =IFERROR(N17*$V17,"") -> 0 | ... AJ17: =IFERROR(T17*$V17,"") -> 0 | AK17: =IFERROR(V17*U17,"") -> 3855.6 | AQ17: =AK17-AL17-AN17+AP17 -> 3855.6
A18: =ROW()-2 -> 16 | B18: 杨明定 | F18: =IFERROR(VLOOKUP($B18,[1]基础信息表!$A:$F,5,FALSE),"") -> 建行 | G18: 13.28 | U18: =SUM(G18:T18) -> 13.28 | V18: =IFERROR(VLOOKUP($B18,[1]基础信息表!$A:$F,6,FALSE),"") -> 310 | W18: =IFERROR(G18*$V18,"") -> 4116.8 | X18: =IFERROR(H18*$V18,"") -> 0 | Y18: =IFERROR(I18*$V18,"") -> 0 | Z18: =IFERROR(J18*$V18,"") -> 0 | AA18: =IFERROR(K18*$V18,"") -> 0 | AB18: =IFERROR(L18*$V18,"") -> 0 | AC18: =IFERROR(M18*$V18,"") -> 0 | AD18: =IFERROR(N18*$V18,"") -> 0 | ... AJ18: =IFERROR(T18*$V18,"") -> 0 | AK18: =IFERROR(V18*U18,"") -> 4116.8 | AQ18: =AK18-AL18-AN18+AP18 -> 4116.8
A19: =ROW()-2 -> 17 | B19: 王兴蛟 | F19: =IFERROR(VLOOKUP($B19,[1]基础信息表!$A:$F,5,FALSE),"") -> 农行 | G19: 22.78 | U19: =SUM(G19:T19) -> 22.78 | V19: =IFERROR(VLOOKUP($B19,[1]基础信息表!$A:$F,6,FALSE),"") -> 320 | W19: =IFERROR(G19*$V19,"") -> 7289.6 | X19: =IFERROR(H19*$V19,"") -> 0 | Y19: =IFERROR(I19*$V19,"") -> 0 | Z19: =IFERROR(J19*$V19,"") -> 0 | AA19: =IFERROR(K19*$V19,"") -> 0 | AB19: =IFERROR(L19*$V19,"") -> 0 | AC19: =IFERROR(M19*$V19,"") -> 0 | AD19: =IFERROR(N19*$V19,"") -> 0 | ... AJ19: =IFERROR(T19*$V19,"") -> 0 | AK19: =IFERROR(V19*U19,"") -> 7289.6 | AQ19: =AK19-AL19-AN19+AP19 -> 7289.6
A20: =ROW()-2 -> 18 | B20: 高征坤 | F20: =IFERROR(VLOOKUP($B20,[1]基础信息表!$A:$F,5,FALSE),"") -> 建行 | G20: 13 | U20: =SUM(G20:T20) -> 13 | V20: =IFERROR(VLOOKUP($B20,[1]基础信息表!$A:$F,6,FALSE),"") -> 290 | W20: =IFERROR(G20*$V20,"") -> 3770 | X20: =IFERROR(H20*$V20,"") -> 0 | Y20: =IFERROR(I20*$V20,"") -> 0 | Z20: =IFERROR(J20*$V20,"") -> 0 | AA20: =IFERROR(K20*$V20,"") -> 0 | AB20: =IFERROR(L20*$V20,"") -> 0 | AC20: =IFERROR(M20*$V20,"") -> 0 | AD20: =IFERROR(N20*$V20,"") -> 0 | ... AJ20: =IFERROR(T20*$V20,"") -> 0 | AK20: =IFERROR(V20*U20,"") -> 3770 | AQ20: =AK20-AL20-AN20+AP20 -> 3770
A21: =ROW()-2 -> 19 | B21: 张亮亮 | F21: =IFERROR(VLOOKUP($B21,[1]基础信息表!$A:$F,5,FALSE),"") -> 温州银行 | G21: 3 | J21: 11 | U21: =SUM(G21:T21) -> 14 | V21: =IFERROR(VLOOKUP($B21,[1]基础信息表!$A:$F,6,FALSE),"") -> 390 | W21: =IFERROR(G21*$V21,"") -> 1170 | X21: =IFERROR(H21*$V21,"") -> 0 | Y21: =IFERROR(I21*$V21,"") -> 0 | Z21: =IFERROR(J21*$V21,"") -> 4290 | AA21: =IFERROR(K21*$V21,"") -> 0 | AB21: =IFERROR(L21*$V21,"") -> 0 | AC21: =IFERROR(M21*$V21,"") -> 0 | AD21: =IFERROR(N21*$V21,"") -> 0 | ... AJ21: =IFERROR(T21*$V21,"") -> 0 | AK21: =IFERROR(V21*U21,"") -> 5460 | AQ21: =AK21-AL21-AN21+AP21 -> 5460
A22: =ROW()-2 -> 20 | B22: 成峰 | F22: =IFERROR(VLOOKUP($B22,[1]基础信息表!$A:$F,5,FALSE),"") -> 建行 | G22: 3 | U22: =SUM(G22:T22) -> 3 | V22: =IFERROR(VLOOKUP($B22,[1]基础信息表!$A:$F,6,FALSE),"") -> 370 | W22: =IFERROR(G22*$V22,"") -> 1110 | X22: =IFERROR(H22*$V22,"") -> 0 | Y22: =IFERROR(I22*$V22,"") -> 0 | Z22: =IFERROR(J22*$V22,"") -> 0 | AA22: =IFERROR(K22*$V22,"") -> 0 | AB22: =IFERROR(L22*$V22,"") -> 0 | AC22: =IFERROR(M22*$V22,"") -> 0 | AD22: =IFERROR(N22*$V22,"") -> 0 | ... AJ22: =IFERROR(T22*$V22,"") -> 0 | AK22: =IFERROR(V22*U22,"") -> 1110 | AQ22: =AK22-AL22-AN22+AP22 -> 1110
A23: =ROW()-2 -> 21 | B23: 何正新 | F23: =IFERROR(VLOOKUP($B23,[1]基础信息表!$A:$F,5,FALSE),"") -> 中国银行 | G23: 3 | U23: =SUM(G23:T23) -> 3 | V23: =IFERROR(VLOOKUP($B23,[1]基础信息表!$A:$F,6,FALSE),"") -> 320 | W23: =IFERROR(G23*$V23,"") -> 960 | X23: =IFERROR(H23*$V23,"") -> 0 | Y23: =IFERROR(I23*$V23,"") -> 0 | Z23: =IFERROR(J23*$V23,"") -> 0 | AA23: =IFERROR(K23*$V23,"") -> 0 | AB23: =IFERROR(L23*$V23,"") -> 0 | AC23: =IFERROR(M23*$V23,"") -> 0 | AD23: =IFERROR(N23*$V23,"") -> 0 | ... AJ23: =IFERROR(T23*$V23,"") -> 0 | AK23: =IFERROR(V23*U23,"") -> 960 | AQ23: =AK23-AL23-AN23+AP23 -> 960
A24: =ROW()-2 -> 22 | B24: 吴志刚 | F24: =IFERROR(VLOOKUP($B24,[1]基础信息表!$A:$F,5,FALSE),"") -> 建行 | G24: 26.28 | U24: =SUM(G24:T24) -> 26.28 | V24: =IFERROR(VLOOKUP($B24,[1]基础信息表!$A:$F,6,FALSE),"") -> 350 | W24: =IFERROR(G24*$V24,"") -> 9198 | X24: =IFERROR(H24*$V24,"") -> 0 | Y24: =IFERROR(I24*$V24,"") -> 0 | Z24: =IFERROR(J24*$V24,"") -> 0 | AA24: =IFERROR(K24*$V24,"") -> 0 | AB24: =IFERROR(L24*$V24,"") -> 0 | AC24: =IFERROR(M24*$V24,"") -> 0 | AD24: =IFERROR(N24*$V24,"") -> 0 | ... AJ24: =IFERROR(T24*$V24,"") -> 0 | AK24: =IFERROR(V24*U24,"") -> 9198 | AQ24: =AK24-AL24-AN24+AP24 -> 9198
A25: =ROW()-2 -> 23 | B25: 张小友 | F25: =IFERROR(VLOOKUP($B25,[1]基础信息表!$A:$F,5,FALSE),"") -> 江西农村信用社 | G25: 3 | J25: 11 | U25: =SUM(G25:T25) -> 14 | V25: =IFERROR(VLOOKUP($B25,[1]基础信息表!$A:$F,6,FALSE),"") -> 370 | W25: =IFERROR(G25*$V25,"") -> 1110 | X25: =IFERROR(H25*$V25,"") -> 0 | Y25: =IFERROR(I25*$V25,"") -> 0 | Z25: =IFERROR(J25*$V25,"") -> 4070 | AA25: =IFERROR(K25*$V25,"") -> 0 | AB25: =IFERROR(L25*$V25,"") -> 0 | AC25: =IFERROR(M25*$V25,"") -> 0 | AD25: =IFERROR(N25*$V25,"") -> 0 | ... AJ25: =IFERROR(T25*$V25,"") -> 0 | AK25: =IFERROR(V25*U25,"") -> 5180 | AQ25: =AK25-AL25-AN25+AP25 -> 5180
A26: =ROW()-2 -> 24 | B26: 曹买生 | F26: =IFERROR(VLOOKUP($B26,[1]基础信息表!$A:$F,5,FALSE),"") -> 中国工商银行 | G26: 3 | U26: =SUM(G26:T26) -> 3 | V26: =IFERROR(VLOOKUP($B26,[1]基础信息表!$A:$F,6,FALSE),"") -> 360 | W26: =IFERROR(G26*$V26,"") -> 1080 | X26: =IFERROR(H26*$V26,"") -> 0 | Y26: =IFERROR(I26*$V26,"") -> 0 | Z26: =IFERROR(J26*$V26,"") -> 0 | AA26: =IFERROR(K26*$V26,"") -> 0 | AB26: =IFERROR(L26*$V26,"") -> 0 | AC26: =IFERROR(M26*$V26,"") -> 0 | AD26: =IFERROR(N26*$V26,"") -> 0 | ... AJ26: =IFERROR(T26*$V26,"") -> 0 | AK26: =IFERROR(V26*U26,"") -> 1080 | AQ26: =AK26-AL26-AN26+AP26 -> 1080
A27: =ROW()-2 -> 25 | B27: 刘桂水 | F27: =IFERROR(VLOOKUP($B27,[1]基础信息表!$A:$F,5,FALSE),"") -> 建行 | G27: 3 | U27: =SUM(G27:T27) -> 3 | V27: =IFERROR(VLOOKUP($B27,[1]基础信息表!$A:$F,6,FALSE),"") -> 270 | W27: =IFERROR(G27*$V27,"") -> 810 | X27: =IFERROR(H27*$V27,"") -> 0 | Y27: =IFERROR(I27*$V27,"") -> 0 | Z27: =IFERROR(J27*$V27,"") -> 0 | AA27: =IFERROR(K27*$V27,"") -> 0 | AB27: =IFERROR(L27*$V27,"") -> 0 | AC27: =IFERROR(M27*$V27,"") -> 0 | AD27: =IFERROR(N27*$V27,"") -> 0 | ... AJ27: =IFERROR(T27*$V27,"") -> 0 | AK27: =IFERROR(V27*U27,"") -> 810 | AQ27: =AK27-AL27-AN27+AP27 -> 810
A28: =ROW()-2 -> 26 | B28: 张小朋 | F28: =IFERROR(VLOOKUP($B28,[1]基础信息表!$A:$F,5,FALSE),"") -> 温州银行 | J28: 11 | U28: =SUM(G28:T28) -> 11 | V28: =IFERROR(VLOOKUP($B28,[1]基础信息表!$A:$F,6,FALSE),"") -> 400 | W28: =IFERROR(G28*$V28,"") -> 0 | X28: =IFERROR(H28*$V28,"") -> 0 | Y28: =IFERROR(I28*$V28,"") -> 0 | Z28: =IFERROR(J28*$V28,"") -> 4400 | AA28: =IFERROR(K28*$V28,"") -> 0 | AB28: =IFERROR(L28*$V28,"") -> 0 | AC28: =IFERROR(M28*$V28,"") -> 0 | AD28: =IFERROR(N28*$V28,"") -> 0 | ... AJ28: =IFERROR(T28*$V28,"") -> 0 | AK28: =IFERROR(V28*U28,"") -> 4400 | AQ28: =AK28-AL28-AN28+AP28 -> 4400
A29: =ROW()-2 -> 27 | B29: 叶焰平 | F29: =IFERROR(VLOOKUP($B29,[1]基础信息表!$A:$F,5,FALSE),"") -> 建行 | G29: 29 | U29: =SUM(G29:T29) -> 29 | V29: =IFERROR(VLOOKUP($B29,[1]基础信息表!$A:$F,6,FALSE),"") -> 500 | W29: =IFERROR(G29*$V29,"") -> 14500 | X29: =IFERROR(H29*$V29,"") -> 0 | Y29: =IFERROR(I29*$V29,"") -> 0 | Z29: =IFERROR(J29*$V29,"") -> 0 | AA29: =IFERROR(K29*$V29,"") -> 0 | AB29: =IFERROR(L29*$V29,"") -> 0 | AC29: =IFERROR(M29*$V29,"") -> 0 | AD29: =IFERROR(N29*$V29,"") -> 0 | ... AJ29: =IFERROR(T29*$V29,"") -> 0 | AK29: =IFERROR(V29*U29,"") -> 14500 | AQ29: =AK29-AL29-AN29+AP29 -> 14500
A30: =ROW()-2 -> 28 | B30: 张滨 | F30: =IFERROR(VLOOKUP($B30,[1]基础信息表!$A:$F,5,FALSE),"") -> 建行 | U30: 1 | V30: =IFERROR(VLOOKUP($B30,[1]基础信息表!$A:$F,6,FALSE),"") -> 8000 | W30: =IFERROR(G30*$V30,"") -> 0 | X30: =IFERROR(H30*$V30,"") -> 0 | Y30: =IFERROR(I30*$V30,"") -> 0 | Z30: =IFERROR(J30*$V30,"") -> 0 | AA30: =IFERROR(K30*$V30,"") -> 0 | AB30: =IFERROR(L30*$V30,"") -> 0 | AC30: =IFERROR(M30*$V30,"") -> 0 | AD30: =IFERROR(N30*$V30,"") -> 0 | ... AJ30: =IFERROR(T30*$V30,"") -> 0 | AK30: =IFERROR(V30*U30,"") -> 8000 | AQ30: =AK30-AL30-AN30+AP30 -> 8000
A31: =ROW()-2 -> 29 | B31: 张淑平 | F31: =IFERROR(VLOOKUP($B31,[1]基础信息表!$A:$F,5,FALSE),"") -> 农行 | U31: 1 | V31: =IFERROR(VLOOKUP($B31,[1]基础信息表!$A:$F,6,FALSE),"") -> 5000 | W31: =IFERROR(G31*$V31,"") -> 0 | X31: =IFERROR(H31*$V31,"") -> 0 | Y31: =IFERROR(I31*$V31,"") -> 0 | Z31: =IFERROR(J31*$V31,"") -> 0 | AA31: =IFERROR(K31*$V31,"") -> 0 | AB31: =IFERROR(L31*$V31,"") -> 0 | AC31: =IFERROR(M31*$V31,"") -> 0 | AD31: =IFERROR(N31*$V31,"") -> 0 | ... AJ31: =IFERROR(T31*$V31,"") -> 0 | AK31: =IFERROR(V31*U31,"") -> 5000 | AQ31: =AK31-AL31-AN31+AP31 -> 5000
A32: =ROW()-2 -> 30 | B32: 聂辉 | F32: =IFERROR(VLOOKUP($B32,[1]基础信息表!$A:$F,5,FALSE),"") -> 德安 | U32: 1 | V32: =IFERROR(VLOOKUP($B32,[1]基础信息表!$A:$F,6,FALSE),"") -> 10000 | W32: =IFERROR(G32*$V32,"") -> 0 | X32: =IFERROR(H32*$V32,"") -> 0 | Y32: =IFERROR(I32*$V32,"") -> 0 | Z32: =IFERROR(J32*$V32,"") -> 0 | AA32: =IFERROR(K32*$V32,"") -> 0 | AB32: =IFERROR(L32*$V32,"") -> 0 | AC32: =IFERROR(M32*$V32,"") -> 0 | AD32: =IFERROR(N32*$V32,"") -> 0 | ... AJ32: =IFERROR(T32*$V32,"") -> 0 | AK32: =IFERROR(V32*U32,"") -> 10000 | AQ32: =AK32-AL32-AN32+AP32 -> 10000
A33: =ROW()-2 -> 31 | B33: 王伟 | F33: =IFERROR(VLOOKUP($B33,[1]基础信息表!$A:$F,5,FALSE),"") -> 共青农商行 | U33: 1 | V33: =IFERROR(VLOOKUP($B33,[1]基础信息表!$A:$F,6,FALSE),"") -> 10000 | W33: =IFERROR(G33*$V33,"") -> 0 | X33: =IFERROR(H33*$V33,"") -> 0 | Y33: =IFERROR(I33*$V33,"") -> 0 | Z33: =IFERROR(J33*$V33,"") -> 0 | AA33: =IFERROR(K33*$V33,"") -> 0 | AB33: =IFERROR(L33*$V33,"") -> 0 | AC33: =IFERROR(M33*$V33,"") -> 0 | AD33: =IFERROR(N33*$V33,"") -> 0 | ... AJ33: =IFERROR(T33*$V33,"") -> 0 | AK33: =IFERROR(V33*U33,"") -> 10000 | AQ33: =AK33-AL33-AN33+AP33 -> 10000
A34: =ROW()-2 -> 32 | B34: 姚俊强 | F34: =IFERROR(VLOOKUP($B34,[1]基础信息表!$A:$F,5,FALSE),"") -> 九江银行 | U34: 1 | V34: =IFERROR(VLOOKUP($B34,[1]基础信息表!$A:$F,6,FALSE),"") -> 4500 | W34: =IFERROR(G34*$V34,"") -> 0 | X34: =IFERROR(H34*$V34,"") -> 0 | Y34: =IFERROR(I34*$V34,"") -> 0 | Z34: =IFERROR(J34*$V34,"") -> 0 | AA34: =IFERROR(K34*$V34,"") -> 0 | AB34: =IFERROR(L34*$V34,"") -> 0 | AC34: =IFERROR(M34*$V34,"") -> 0 | AD34: =IFERROR(N34*$V34,"") -> 0 | ... AJ34: =IFERROR(T34*$V34,"") -> 0 | AK34: =IFERROR(V34*U34,"") -> 4500 | AQ34: =AK34-AL34-AN34+AP34 -> 4500
A35: =ROW()-2 -> 33 | U35: =SUM(G35:T35) -> 0 | V35: =IFERROR(VLOOKUP($B35,[1]基础信息表!$A:$F,6,FALSE),"") | W35: =IFERROR(G35*$V35,"") | X35: =IFERROR(H35*$V35,"") | Y35: =IFERROR(I35*$V35,"") | Z35: =IFERROR(J35*$V35,"") | AA35: =IFERROR(K35*$V35,"") | AB35: =IFERROR(L35*$V35,"") | AC35: =IFERROR(M35*$V35,"") | AD35: =IFERROR(N35*$V35,"") | ... AJ35: =IFERROR(T35*$V35,"") | AK35: =IFERROR(V35*U35,"") | AQ35: =AK35-AL35-AN35+AP35 -> #VALUE!
A36: =ROW()-2 -> 34 | U36: =SUM(G36:T36) -> 0 | AK36: =IFERROR(V36*U36,"") -> 0 | AQ36: =AK36-AL36-AN36+AP36 -> 0
A37: =ROW()-2 -> 35 | U37: =SUM(G37:T37) -> 0 | AK37: =IFERROR(V37*U37,"") -> 0 | AQ37: =AK37-AL37-AN37+AP37 -> 0
A38: =ROW()-2 -> 36 | U38: =SUM(G38:T38) -> 0 | AK38: =IFERROR(V38*U38,"") -> 0 | AQ38: =AK38-AL38-AN38+AP38 -> 0
U39: =SUM(G39:T39) -> 0 | AK39: =IFERROR(V39*U39,"") -> 0 | AQ39: =AK39-AL39-AN39+AP39 -> 0
V40: 合计： | W40: =SUM(W3:W39) -> 103438.9 | X40: =SUM(X3:X39) -> 3275 | Y40: =SUM(Y3:Y39) -> 0 | Z40: =SUM(Z3:Z39) -> 24235 | AA40: =SUM(AA3:AA39) -> 5610 | AJ40: =SUM(AJ3:AJ39) -> 0 | AK40: =SUM(AK3:AK39) -> 174058.9 | AQ40: =AK40-AL40-AN40+AP40 -> 174058.9
...

Sheet 用工成本表
B1: 2026年各项目用工成本合计(不含分包）
A2: 序号 | B2: 项目名称 月份 | C2: 德安养老中心 | D2: 科创中心 | E2: 邹桥派出所 | F2: 架空层 | G2: 农商行（德安总部） | H2: 恒科华府 | I2: 博河科创中心 | O2: 总计
A3: 1 | B3: 25年-26年二月合计 | C3: 1073656.4 | D3: 402775 | F3: 96985 | O3: =SUM(C3:N3) -> 1573416.4
A4: 2 | O4: =SUM(C4:N4) -> 0
A5: 3 | B5: 3月 | C5: 214880 | D5: 24950 | E5: 14295 | O5: =SUM(C5:N5) -> 254125
A6: 4 | B6: 4月 | C6: 103438.9 | D6: 3275 | E6: 24235 | F6: 5610 | G6: 360 | O6: =SUM(C6:N6) -> 136918.9
A7: 5 | B7: 5月 | C7: 32665 | E7: 7240 | F7: 9070 | G7: 1820 | O7: =SUM(C7:N7) -> 50795
A8: 6 | B8: 6月 | C8: 23600 | D8: 3915 | E8: 4310 | F8: 7670 | O8: =SUM(C8:N8) -> 39495
A9: 7 | B9: 7月 | C9: 43790 | E9: 1300 | F9: 470 | O9: =SUM(C9:N9) -> 45560
A10: 8 | B10: 8月 | C10: 33940 | H10: 3405 | I10: 1300 | O10: =SUM(C10:N10) -> 38645
A11: 9 | B11: 9月 | D11: 14050 | O11: =SUM(C11:N11) -> 14050
A12: 10 | B12: 10月 | O12: =SUM(C12:N12) -> 0
A13: 11 | B13: 11月 | O13: =SUM(C13:N13) -> 0
A14: 12 | B14: 12月 | O14: =SUM(C14:N14) -> 0
B15: 26年小计： | C15: =SUM(C5:C14) -> 452313.9 | D15: =SUM(D5:D14) -> 46190 | E15: =SUM(E5:E14) -> 51380 | F15: =SUM(F5:F14) -> 22820 | G15: =SUM(G5:G14) -> 2180 | H15: =SUM(H5:H14) -> 3405 | I15: =SUM(I5:I14) -> 1300 | J15: =SUM(J5:J14) -> 0 | ... N15: =SUM(N5:N14) -> 0 | O15: =SUM(C15:N15) -> 579588.9
A16: 25年-26年合计： | C16: =SUM(C3:C14) -> 1525970.3 | D16: =SUM(D3:D14) -> 448965 | E16: =SUM(E3:E14) -> 51380 | F16: =SUM(F3:F14) -> 119805 | G16: =SUM(G3:G14) -> 2180 | H16: =SUM(H3:H14) -> 3405 | I16: =SUM(I3:I14) -> 1300 | J16: =SUM(J3:J14) -> 0 | ... N16: =SUM(N3:N14) -> 0 | O16: =SUM(C16:N16) -> 2153005.3
G18: 农商行360是临时工
D19: 14050是临时工王金山

Sheet 工资汇总表
E1: 工资年度汇总
A2: 姓名 | B2: 日工资/ 月工资 | C2: 合计天数 | D2: 应发工资 | E2: 实际发放 | F2: 代扣社保 | G2: 代扣个税 | H2: 已退回 | I2: 补贴 | J2: 剩余工资
A3: 曹买生 | B3: 360 | C3: 26 | D3: 9360 | E3: 0 | F3: 0 | G3: 0 | H3: 0 | I3: 0 | J3: 9360
A4: 陈德银 | B4: 260 | C4: 4 | D4: 1040 | E4: 1040 | F4: 0 | G4: 0 | H4: 0 | I4: 0 | J4: 0
A5: 成峰 | B5: 370 | C5: 27 | D5: 9990 | E5: 4000 | F5: 0 | G5: 0 | H5: 0 | I5: 0 | J5: 5990
A6: 程章材 | B6: 200 | C6: 32.5 | D6: 6500 | E6: 4000 | F6: 0 | G6: 0 | H6: 0 | I6: 0 | J6: 2500
A7: 程章赐 | B7: 350 | C7: 37 | D7: 12950 | E7: 4000 | F7: 0 | G7: 0 | H7: 0 | I7: 0 | J7: 8950
A8: 邓付贞 | B8: 400 | C8: 0 | D8: 0 | E8: 5000 | F8: 0 | G8: 0 | H8: 0 | I8: 0 | J8: -5000
A9: 邓泽贵 | B9: 350 | C9: 87.78 | D9: 30723 | E9: 25184.31 | F9: 0 | G9: 463.69 | H9: 0 | I9: 0 | J9: 5075
A10: 高征坤 | B10: 290 | C10: 35.5 | D10: 10295 | E10: 4000 | F10: 0 | G10: 0 | H10: 0 | I10: 0 | J10: 6295
A11: 桂木生 | B11: 300 | C11: 2.5 | D11: 750 | E11: 0 | F11: 0 | G11: 0 | H11: 0 | I11: 0 | J11: 750
A12: 何正新 | B12: 320 | C12: 26 | D12: 8320 | E12: 0 | F12: 0 | G12: 0 | H12: 0 | I12: 0 | J12: 8320
A13: 胡家新 | B13: 270 | C13: 38 | D13: 10260 | E13: 7000 | F13: 0 | G13: 0 | H13: 0 | I13: 0 | J13: 3260
A14: 金李平 | B14: 270 | C14: 45.78 | D14: 12360.6 | E14: 4000 | F14: 0 | G14: 0 | H14: 0 | I14: 0 | J14: 8360.6
A15: 金南水 | B15: 290 | C15: 142.5 | D15: 41325 | E15: 36800 | F15: 0 | G15: 0 | H15: 15800 | I15: 0 | J15: 20325

Sheet 老板个人往来
A1: 王总个人收支明细
A2: 交易时间 | B2: 收入 | C2: 其他收入 | D2: 个人借款支出 | E2: 其他支出 | F2: 摘要 | G2: 支付账户 | H2: 收款账户 | I2: 支付方式 | J2: 备注
A3: 45531 | B3: 30000 | F3: 工资款 | G3: 九江银行 | H3: 王伟 | I3: 转账
A4: 45803 | B4: 10000 | F4: 工资款 | G4: 九江银行 | H4: 王伟 | I4: 转账
A5: 45929 | B5: 10000 | F5: 王伟报销款 | G5: 九江银行 | H5: 王伟 | I5: 转账
A6: 45957 | D6: 20000 | F6: 王伟个人借款 | G6: 王伟 | H6: 九江银行 | I6: 转账
A7: 45972 | D7: 30000 | F7: 王伟个人借款 | G7: 王伟 | H7: 九江银行 | I7: 转账
A8: 45974 | D8: 30000 | F8: 王伟个人借款 | G8: 王伟 | H8: 九江银行 | I8: 转账
A9: 45975 | D9: 40000 | F9: 王伟个人借款 | G9: 王伟 | H9: 九江银行 | I9: 转账
A10: 45980 | D10: 30000 | F10: 王伟个人借款 | G10: 王伟 | H10: 九江银行 | I10: 转账
A11: 45984 | D11: 40000 | F11: 王伟个人借款 | G11: 王伟 | H11: 九江银行 | I11: 转账

Sheet 老板2个人明细
A1: 聂总个人收支明细
A2: 交易时间 | B2: 工资收入 | C2: 其他收入 | D2: 个人借款支出 | E2: 其他支出 | F2: 摘要 | G2: 支付账户 | H2: 收款账户 | I2: 支付方式 | J2: 备注
A3: 45271 | D3: 1668 | F3: 个人借款 | G3: 聂辉 | H3: 九江银行 | I3: 转账
A4: 45308 | D4: 500000 | F4: 聂辉支付项目保证金 | G4: 聂辉 | H4: 九江银行 | I4: 转账
A5: 45310 | D5: 500000 | F5: 聂辉支付项目保证金 | G5: 聂辉 | H5: 九江银行 | I5: 转账
A6: 45329 | B6: 10000 | F6: 工资款 | G6: 九江银行 | H6: 聂辉 | I6: 转账
A7: 45509 | D7: 5000 | F7: 个人借款 | G7: 聂辉 | H7: 九江银行 | I7: 转账
A8: 45523 | D8: -200000 | F8: 公司退聂辉个人借款 | G8: 九江银行 | H8: 聂辉 | I8: 转账
A9: 45524 | D9: -490000 | F9: 公司退聂辉个人借款 | G9: 九江银行 | H9: 聂辉 | I9: 转账
A10: 45530 | D10: -95000 | F10: 公司退聂辉个人借款 | G10: 九江银行 | H10: 聂辉 | I10: 转账
A11: 45532 | B11: 20000 | F11: 工资款 | G11: 九江银行 | H11: 聂辉 | I11: 转账
A12: 45567 | D12: 10000 | F12: 个人借款 | G12: 聂辉 | H12: 九江银行 | I12: 转账
A13: 45575 | D13: 1000 | F13: 个人借款 | G13: 聂辉 | H13: 九江银行 | I13: 转账
A14: 45593 | D14: 5000 | F14: 个人借款 | G14: 聂辉 | H14: 九江银行 | I14: 转账

Sheet 项目部负责人个人明细
A1: 张总个人收支明细表
A2: 交易时间 | B2: 收入 | C2: 退款 | D2: 垫付款 | E2: 代付款 | F2: 摘要 | G2: 支付账户 | H2: 收款账户 | I2: 支付方式 | J2: 备注
A3: 45567 | B3: 10000 | F3: 工资款 | G3: 九江银行 | H3: 张滨 | I3: 转账
A4: 45656 | B4: 10000 | F4: 工资款 | G4: 九江银行 | H4: 张滨 | I4: 转账
A5: 45659 | B5: 10000 | F5: 工资款 | G5: 九江银行 | H5: 张滨 | I5: 转账
A6: 45747 | B6: 10000 | F6: 工资款 | G6: 九江银行 | H6: 张滨 | I6: 转账
A7: 45749 | B7: 10000 | F7: 工资款 | G7: 九江银行 | H7: 张滨 | I7: 转账
A8: 45768 | B8: 700 | F8: 工程款 | G8: 星辰宾馆老板 | H8: 张滨微信 | I8: 微信转账 | J8: 星辰宾馆工程款
A9: 45803 | B9: 10000 | F9: 工资款 | G9: 九江银行 | H9: 张滨 | I9: 转账
A10: 45838 | B10: 10000 | F10: 工资款 | G10: 九江银行 | H10: 张滨 | I10: 转账
A11: 45838 | B11: 10000 | F11: 工资款 | G11: 九江银行 | H11: 张滨 | I11: 转账
A12: 45839 | B12: 60000 | F12: 备用金 | G12: 九江银行 | H12: 张滨 | I12: 转账
A13: 45888 | B13: 5000 | F13: 工资款 | G13: 九江银行 | H13: 张滨 | I13: 转账
