Workbook

Sheet 总览汇总
A1: 客户存条&货款总览汇总表
A2: 💡 一篮子查看所有客户情况：新增客户请在此表填写初始信息，领用和付款在对应明细表登记，数据自动更新
A3: 序号 | B3: 客户名称 | C3: 初始存条金额(元) | D3: 已领用金额(元) | E3: 剩余存条金额(元) | F3: 已付款金额(元) | G3: 未付货款(元) | H3: 状态 | I3: 库存总结余数量(件) | J3: 库存总结余金额(元)
B4: 合计 | C4: =C155 -> 3333127.2 | D4: =D155 -> 1718940.7 | E4: =E155 -> 1629523 | F4: =F155 -> 4092006.2 | G4: =G155 -> -2377565.5 | H4: =H155 -> 0 | I4: =I155 -> 30091 | J4: =J155 -> 2606252.3
A5: 1 | B5: 星海超市 | C5: 39547 | D5: =IF(B5<>"",SUMIF(出库明细!C:C,B5,出库明细!G:G),"") -> 77322 | E5: =IF(AND(C5<>"",D5<>""),C5-D5,"") -> -37775 | F5: =IF(B5<>"",SUMIF(收付款明细!C:C,B5,收付款明细!D:D),"") -> 148067 | G5: =IF(AND(D5<>"",F5<>""),D5-F5,"") -> -70745 | H5: =IF(B5="","",IF(G5=0,"已结清",IF(G5>0,"有欠款","预存款"))) -> 预存款 | I5: =IFERROR(SUMIF(商品库存!B:B,B5,商品库存!I:I),0) -> 1137 | J5: =IFERROR(SUMIF(商品库存!B:B,B5,商品库存!J:J),0) -> 79591
A6: 2 | B6: 王玉琴 | C6: 99000 | D6: =IF(B6<>"",SUMIF(出库明细!C:C,B6,出库明细!G:G),"") -> 54172.5 | E6: =IF(AND(C6<>"",D6<>""),C6-D6,"") -> 44827.5 | F6: =IF(B6<>"",SUMIF(收付款明细!C:C,B6,收付款明细!D:D),"") -> 106697 | G6: =IF(AND(D6<>"",F6<>""),D6-F6,"") -> -52524.5 | H6: =IF(B6="","",IF(G6=0,"已结清",IF(G6>0,"有欠款","预存款"))) -> 预存款 | I6: =IFERROR(SUMIF(商品库存!B:B,B6,商品库存!I:I),0) -> 550 | J6: =IFERROR(SUMIF(商品库存!B:B,B6,商品库存!J:J),0) -> 49500
A7: 3 | B7: 桐心源 | C7: 700231.47 | D7: =IF(B7<>"",SUMIF(出库明细!C:C,B7,出库明细!G:G),"") -> 416695 | E7: =IF(AND(C7<>"",D7<>""),C7-D7,"") -> 283536.47 | F7: =IF(B7<>"",SUMIF(收付款明细!C:C,B7,收付款明细!D:D),"") -> 868551.47 | G7: =IF(AND(D7<>"",F7<>""),D7-F7,"") -> -451856.47 | H7: =IF(B7="","",IF(G7=0,"已结清",IF(G7>0,"有欠款","预存款"))) -> 预存款 | I7: =IFERROR(SUMIF(商品库存!B:B,B7,商品库存!I:I),0) -> 5560 | J7: =IFERROR(SUMIF(商品库存!B:B,B7,商品库存!J:J),0) -> 469317
A8: 5 | B8: 阿东副食 | C8: 570147.22 | D8: =IF(B8<>"",SUMIF(出库明细!C:C,B8,出库明细!G:G),"") -> 184072 | E8: =IF(AND(C8<>"",D8<>""),C8-D8,"") -> 386075.22 | F8: =IF(B8<>"",SUMIF(收付款明细!C:C,B8,收付款明细!D:D),"") -> 649147.22 | G8: =IF(AND(D8<>"",F8<>""),D8-F8,"") -> -465075.22 | H8: =IF(B8="","",IF(G8=0,"已结清",IF(G8>0,"有欠款","预存款"))) -> 预存款 | I8: =IFERROR(SUMIF(商品库存!B:B,B8,商品库存!I:I),0) -> 6635 | J8: =IFERROR(SUMIF(商品库存!B:B,B8,商品库存!J:J),0) -> 515900
A9: 6 | B9: 金凤副食 | C9: 8950 | D9: =IF(B9<>"",SUMIF(出库明细!C:C,B9,出库明细!G:G),"") -> 47079.2 | E9: =IF(AND(C9<>"",D9<>""),C9-D9,"") -> -38129.2 | F9: =IF(B9<>"",SUMIF(收付款明细!C:C,B9,收付款明细!D:D),"") -> 56950 | G9: =IF(AND(D9<>"",F9<>""),D9-F9,"") -> -9870.8 | H9: =IF(B9="","",IF(G9=0,"已结清",IF(G9>0,"有欠款","预存款"))) -> 预存款 | I9: =IFERROR(SUMIF(商品库存!B:B,B9,商品库存!I:I),0) -> 11 | J9: =IFERROR(SUMIF(商品库存!B:B,B9,商品库存!J:J),0) -> 715.8
B10: 致发商行 | C10: 437965 | D10: =IF(B10<>"",SUMIF(出库明细!C:C,B10,出库明细!G:G),"") -> 164100 | E10: =IF(AND(C10<>"",D10<>""),C10-D10,"") -> 273865 | F10: =IF(B10<>"",SUMIF(收付款明细!C:C,B10,收付款明细!D:D),"") -> 437965 | G10: =IF(AND(D10<>"",F10<>""),D10-F10,"") -> -273865 | H10: =IF(B10="","",IF(G10=0,"已结清",IF(G10>0,"有欠款","预存款"))) -> 预存款 | I10: =IFERROR(SUMIF(商品库存!B:B,B10,商品库存!I:I),0) -> 3275 | J10: =IFERROR(SUMIF(商品库存!B:B,B10,商品库存!J:J),0) -> 273865
A11: 7 | B11: 家家兴超市 | D11: =IF(B11<>"",SUMIF(出库明细!C:C,B11,出库明细!G:G),"") -> 14616.5 | E11: =IF(AND(C11<>"",D11<>""),C11-D11,"") | F11: =IF(B11<>"",SUMIF(收付款明细!C:C,B11,收付款明细!D:D),"") -> 12579 | G11: =IF(AND(D11<>"",F11<>""),D11-F11,"") -> 2037.5 | H11: =IF(B11="","",IF(G11=0,"已结清",IF(G11>0,"有欠款","预存款"))) -> 有欠款 | I11: =IFERROR(SUMIF(商品库存!B:B,B11,商品库存!I:I),0) -> 0 | J11: =IFERROR(SUMIF(商品库存!B:B,B11,商品库存!J:J),0) -> 0
A12: 8 | B12: 通达商行 | C12: 18000 | D12: =IF(B12<>"",SUMIF(出库明细!C:C,B12,出库明细!G:G),"") -> 18000 | E12: =IF(AND(C12<>"",D12<>""),C12-D12,"") -> 0 | F12: =IF(B12<>"",SUMIF(收付款明细!C:C,B12,收付款明细!D:D),"") -> 18000 | G12: =IF(AND(D12<>"",F12<>""),D12-F12,"") -> 0 | H12: =IF(B12="","",IF(G12=0,"已结清",IF(G12>0,"有欠款","预存款"))) -> 已结清 | I12: =IFERROR(SUMIF(商品库存!B:B,B12,商品库存!I:I),0) -> 0 | J12: =IFERROR(SUMIF(商品库存!B:B,B12,商品库存!J:J),0) -> 0
A13: 9 | B13: 宜兴粮油 | C13: 54000 | D13: =IF(B13<>"",SUMIF(出库明细!C:C,B13,出库明细!G:G),"") -> 64943.5 | E13: =IF(AND(C13<>"",D13<>""),C13-D13,"") -> -10943.5 | F13: =IF(B13<>"",SUMIF(收付款明细!C:C,B13,收付款明细!D:D),"") -> 66416.5 | G13: =IF(AND(D13<>"",F13<>""),D13-F13,"") -> -1473 | H13: =IF(B13="","",IF(G13=0,"已结清",IF(G13>0,"有欠款","预存款"))) -> 预存款 | I13: =IFERROR(SUMIF(商品库存!B:B,B13,商品库存!I:I),0) -> 50 | J13: =IFERROR(SUMIF(商品库存!B:B,B13,商品库存!J:J),0) -> 1473
A14: 10 | B14: 马路下小卖部 | C14: 840 | D14: =IF(B14<>"",SUMIF(出库明细!C:C,B14,出库明细!G:G),"") -> 4986 | E14: =IF(AND(C14<>"",D14<>""),C14-D14,"") -> -4146 | F14: =IF(B14<>"",SUMIF(收付款明细!C:C,B14,收付款明细!D:D),"") -> 19440 | G14: =IF(AND(D14<>"",F14<>""),D14-F14,"") -> -14454 | H14: =IF(B14="","",IF(G14=0,"已结清",IF(G14>0,"有欠款","预存款"))) -> 预存款 | I14: =IFERROR(SUMIF(商品库存!B:B,B14,商品库存!I:I),0) -> 150 | J14: =IFERROR(SUMIF(商品库存!B:B,B14,商品库存!J:J),0) -> 13950
A15: 11 | B15: 兴莲隆兴商行 | C15: 30043 | D15: =IF(B15<>"",SUMIF(出库明细!C:C,B15,出库明细!G:G),"") -> 0 | E15: =IF(AND(C15<>"",D15<>""),C15-D15,"") -> 30043 | F15: =IF(B15<>"",SUMIF(收付款明细!C:C,B15,收付款明细!D:D),"") -> 39043 | G15: =IF(AND(D15<>"",F15<>""),D15-F15,"") -> -39043 | H15: =IF(B15="","",IF(G15=0,"已结清",IF(G15>0,"有欠款","预存款"))) -> 预存款 | I15: =IFERROR(SUMIF(商品库存!B:B,B15,商品库存!I:I),0) -> 0 | J15: =IFERROR(SUMIF(商品库存!B:B,B15,商品库存!J:J),0) -> 0
A16: 12 | B16: 诚信粮油 | C16: 29565 | D16: =IF(B16<>"",SUMIF(出库明细!C:C,B16,出库明细!G:G),"") -> 29900 | E16: =IF(AND(C16<>"",D16<>""),C16-D16,"") -> -335 | F16: =IF(B16<>"",SUMIF(收付款明细!C:C,B16,收付款明细!D:D),"") -> 79565 | G16: =IF(AND(D16<>"",F16<>""),D16-F16,"") -> -49665 | H16: =IF(B16="","",IF(G16=0,"已结清",IF(G16>0,"有欠款","预存款"))) -> 预存款 | I16: =IFERROR(SUMIF(商品库存!B:B,B16,商品库存!I:I),0) -> 0 | J16: =IFERROR(SUMIF(商品库存!B:B,B16,商品库存!J:J),0) -> 0
A17: 13 | B17: 李记副食 | C17: 6930 | D17: =IF(B17<>"",SUMIF(出库明细!C:C,B17,出库明细!G:G),"") -> 6562.5 | E17: =IF(AND(C17<>"",D17<>""),C17-D17,"") -> 367.5 | F17: =IF(B17<>"",SUMIF(收付款明细!C:C,B17,收付款明细!D:D),"") -> 6930 | G17: =IF(AND(D17<>"",F17<>""),D17-F17,"") -> -367.5 | H17: =IF(B17="","",IF(G17=0,"已结清",IF(G17>0,"有欠款","预存款"))) -> 预存款 | I17: =IFERROR(SUMIF(商品库存!B:B,B17,商品库存!I:I),0) -> 0 | J17: =IFERROR(SUMIF(商品库存!B:B,B17,商品库存!J:J),0) -> 0
A18: 14 | B18: 吕维春 | C18: 32440 | D18: =IF(B18<>"",SUMIF(出库明细!C:C,B18,出库明细!G:G),"") -> 16400 | E18: =IF(AND(C18<>"",D18<>""),C18-D18,"") -> 16040 | F18: =IF(B18<>"",SUMIF(收付款明细!C:C,B18,收付款明细!D:D),"") -> 62440 | G18: =IF(AND(D18<>"",F18<>""),D18-F18,"") -> -46040 | H18: =IF(B18="","",IF(G18=0,"已结清",IF(G18>0,"有欠款","预存款"))) -> 预存款 | I18: =IFERROR(SUMIF(商品库存!B:B,B18,商品库存!I:I),0) -> 300 | J18: =IFERROR(SUMIF(商品库存!B:B,B18,商品库存!J:J),0) -> 20740
A19: 15 | B19: 兴发商行 | C19: 15300 | D19: =IF(B19<>"",SUMIF(出库明细!C:C,B19,出库明细!G:G),"") -> 9270 | E19: =IF(AND(C19<>"",D19<>""),C19-D19,"") -> 6030 | F19: =IF(B19<>"",SUMIF(收付款明细!C:C,B19,收付款明细!D:D),"") -> 16437.5 | G19: =IF(AND(D19<>"",F19<>""),D19-F19,"") -> -7167.5 | H19: =IF(B19="","",IF(G19=0,"已结清",IF(G19>0,"有欠款","预存款"))) -> 预存款 | I19: =IFERROR(SUMIF(商品库存!B:B,B19,商品库存!I:I),0) -> 80 | J19: =IFERROR(SUMIF(商品库存!B:B,B19,商品库存!J:J),0) -> 7167.5
A20: 16 | B20: 城岗日日升超市 | C20: 36895 | D20: =IF(B20<>"",SUMIF(出库明细!C:C,B20,出库明细!G:G),"") -> 38496.5 | E20: =IF(AND(C20<>"",D20<>""),C20-D20,"") -> -1601.5 | F20: =IF(B20<>"",SUMIF(收付款明细!C:C,B20,收付款明细!D:D),"") -> 63895 | G20: =IF(AND(D20<>"",F20<>""),D20-F20,"") -> -25398.5 | H20: =IF(B20="","",IF(G20=0,"已结清",IF(G20>0,"有欠款","预存款"))) -> 预存款 | I20: =IFERROR(SUMIF(商品库存!B:B,B20,商品库存!I:I),0) -> 545 | J20: =IFERROR(SUMIF(商品库存!B:B,B20,商品库存!J:J),0) -> 25398.5
A21: 17 | B21: 江背久明商行 | C21: 21620 | D21: =IF(B21<>"",SUMIF(出库明细!C:C,B21,出库明细!G:G),"") -> 56620 | E21: =IF(AND(C21<>"",D21<>""),C21-D21,"") -> -35000 | F21: =IF(B21<>"",SUMIF(收付款明细!C:C,B21,收付款明细!D:D),"") -> 21620 | G21: =IF(AND(D21<>"",F21<>""),D21-F21,"") -> 35000 | H21: =IF(B21="","",IF(G21=0,"已结清",IF(G21>0,"有欠款","预存款"))) -> 有欠款 | I21: =IFERROR(SUMIF(商品库存!B:B,B21,商品库存!I:I),0) -> 0 | J21: =IFERROR(SUMIF(商品库存!B:B,B21,商品库存!J:J),0) -> 0
A22: 18 | B22: 社富丽华超市 | C22: 8100 | D22: =IF(B22<>"",SUMIF(出库明细!C:C,B22,出库明细!G:G),"") -> 0 | E22: =IF(AND(C22<>"",D22<>""),C22-D22,"") -> 8100 | F22: =IF(B22<>"",SUMIF(收付款明细!C:C,B22,收付款明细!D:D),"") -> 8100 | G22: =IF(AND(D22<>"",F22<>""),D22-F22,"") -> -8100 | H22: =IF(B22="","",IF(G22=0,"已结清",IF(G22>0,"有欠款","预存款"))) -> 预存款 | I22: =IFERROR(SUMIF(商品库存!B:B,B22,商品库存!I:I),0) -> 90 | J22: =IFERROR(SUMIF(商品库存!B:B,B22,商品库存!J:J),0) -> 8100
A23: 19 | B23: 九鑫粮油 | C23: 3150 | D23: =IF(B23<>"",SUMIF(出库明细!C:C,B23,出库明细!G:G),"") -> 6030 | E23: =IF(AND(C23<>"",D23<>""),C23-D23,"") -> -2880 | F23: =IF(B23<>"",SUMIF(收付款明细!C:C,B23,收付款明细!D:D),"") -> 13150 | G23: =IF(AND(D23<>"",F23<>""),D23-F23,"") -> -7120 | H23: =IF(B23="","",IF(G23=0,"已结清",IF(G23>0,"有欠款","预存款"))) -> 预存款 | I23: =IFERROR(SUMIF(商品库存!B:B,B23,商品库存!I:I),0) -> -32 | J23: =IFERROR(SUMIF(商品库存!B:B,B23,商品库存!J:J),0) -> -2880
... A42: 38 | B42: 崇贤三角超市 | C42: 2955 | D42: =IF(B42<>"",SUMIF(出库明细!C:C,B42,出库明细!G:G),"") -> 2955 | E42: =IF(AND(C42<>"",D42<>""),C42-D42,"") -> 0 | F42: =IF(B42<>"",SUMIF(收付款明细!C:C,B42,收付款明细!D:D),"") -> 2955 | G42: =IF(AND(D42<>"",F42<>""),D42-F42,"") -> 0 | H42: =IF(B42="","",IF(G42=0,"已结清",IF(G42>0,"有欠款","预存款"))) -> 已结清 | I42: =IFERROR(SUMIF(商品库存!B:B,B42,商品库存!I:I),0) -> 0 | J42: =IFERROR(SUMIF(商品库存!B:B,B42,商品库存!J:J),0) -> 0
A43: 39 | B43: 财源批发 | C43: 4500 | D43: =IF(B43<>"",SUMIF(出库明细!C:C,B43,出库明细!G:G),"") -> 4500 | E43: =IF(AND(C43<>"",D43<>""),C43-D43,"") -> 0 | F43: =IF(B43<>"",SUMIF(收付款明细!C:C,B43,收付款明细!D:D),"") -> 4500 | G43: -4500 | H43: =IF(B43="","",IF(G43=0,"已结清",IF(G43>0,"有欠款","预存款"))) -> 预存款 | I43: =IFERROR(SUMIF(商品库存!B:B,B43,商品库存!I:I),0) -> 0 | J43: =IFERROR(SUMIF(商品库存!B:B,B43,商品库存!J:J),0) -> 0
A44: 40 | B44: 标哥副食 | C44: 2526.5 | D44: =IF(B44<>"",SUMIF(出库明细!C:C,B44,出库明细!G:G),"") -> 2526.5 | E44: =IF(AND(C44<>"",D44<>""),C44-D44,"") -> 0 | F44: =IF(B44<>"",SUMIF(收付款明细!C:C,B44,收付款明细!D:D),"") -> 2526.5 | G44: =IF(AND(D44<>"",F44<>""),D44-F44,"") -> 0 | H44: =IF(B44="","",IF(G44=0,"已结清",IF(G44>0,"有欠款","预存款"))) -> 已结清 | I44: =IFERROR(SUMIF(商品库存!B:B,B44,商品库存!I:I),0) -> 0 | J44: =IFERROR(SUMIF(商品库存!B:B,B44,商品库存!J:J),0) -> 0
A45: 41 | B45: 鼎龙陈财超市 | C45: 100000 | D45: =IF(B45<>"",SUMIF(出库明细!C:C,B45,出库明细!G:G),"") -> 10660 | E45: =IF(AND(C45<>"",D45<>""),C45-D45,"") -> 89340 | F45: =IF(B45<>"",SUMIF(收付款明细!C:C,B45,收付款明细!D:D),"") -> 180682.5 | G45: =IF(AND(D45<>"",F45<>""),D45-F45,"") -> -170022.5 | H45: =IF(B45="","",IF(G45=0,"已结清",IF(G45>0,"有欠款","预存款"))) -> 预存款 | I45: =IFERROR(SUMIF(商品库存!B:B,B45,商品库存!I:I),0) -> 2083.5 | J45: =IFERROR(SUMIF(商品库存!B:B,B45,商品库存!J:J),0) -> 310532.5
A46: 42 | B46: 春萌副食 | C46: 2325 | D46: =IF(B46<>"",SUMIF(出库明细!C:C,B46,出库明细!G:G),"") -> 2325 | E46: =IF(AND(C46<>"",D46<>""),C46-D46,"") -> 0 | F46: =IF(B46<>"",SUMIF(收付款明细!C:C,B46,收付款明细!D:D),"") -> 2325 | G46: =IF(AND(D46<>"",F46<>""),D46-F46,"") -> 0 | H46: =IF(B46="","",IF(G46=0,"已结清",IF(G46>0,"有欠款","预存款"))) -> 已结清 | I46: =IFERROR(SUMIF(商品库存!B:B,B46,商品库存!I:I),0) -> 0 | J46: =IFERROR(SUMIF(商品库存!B:B,B46,商品库存!J:J),0) -> 0
A47: 43 | B47: 城西街福临门超市 | C47: 2046 | D47: =IF(B47<>"",SUMIF(出库明细!C:C,B47,出库明细!G:G),"") -> 465 | E47: =IF(AND(C47<>"",D47<>""),C47-D47,"") -> 1581 | F47: =IF(B47<>"",SUMIF(收付款明细!C:C,B47,收付款明细!D:D),"") -> 2046 | G47: =IF(AND(D47<>"",F47<>""),D47-F47,"") -> -1581 | H47: =IF(B47="","",IF(G47=0,"已结清",IF(G47>0,"有欠款","预存款"))) -> 预存款 | I47: =IFERROR(SUMIF(商品库存!B:B,B47,商品库存!I:I),0) -> 17 | J47: =IFERROR(SUMIF(商品库存!B:B,B47,商品库存!J:J),0) -> 1581
A48: 44 | B48: 滨江路莲花便利店 | C48: 1582 | D48: =IF(B48<>"",SUMIF(出库明细!C:C,B48,出库明细!G:G),"") -> 2427 | E48: =IF(AND(C48<>"",D48<>""),C48-D48,"") -> -845 | F48: =IF(B48<>"",SUMIF(收付款明细!C:C,B48,收付款明细!D:D),"") -> 1582 | G48: =IF(AND(D48<>"",F48<>""),D48-F48,"") -> 845 | H48: =IF(B48="","",IF(G48=0,"已结清",IF(G48>0,"有欠款","预存款"))) -> 有欠款 | I48: =IFERROR(SUMIF(商品库存!B:B,B48,商品库存!I:I),0) -> 11 | J48: =IFERROR(SUMIF(商品库存!B:B,B48,商品库存!J:J),0) -> 550
A49: 45 | B49: 马路下小卖部 | C49: 186000 | D49: =IF(B49<>"",SUMIF(出库明细!C:C,B49,出库明细!G:G),"") -> 4986 | E49: =IF(AND(C49<>"",D49<>""),C49-D49,"") -> 181014 | F49: =IF(B49<>"",SUMIF(收付款明细!C:C,B49,收付款明细!D:D),"") -> 19440 | G49: =IF(AND(D49<>"",F49<>""),D49-F49,"") -> -14454 | H49: =IF(B49="","",IF(G49=0,"已结清",IF(G49>0,"有欠款","预存款"))) -> 预存款 | I49: =IFERROR(SUMIF(商品库存!B:B,B49,商品库存!I:I),0) -> 150 | J49: =IFERROR(SUMIF(商品库存!B:B,B49,商品库存!J:J),0) -> 13950
A50: 46 | B50: 好帮手 | C50: 12000 | D50: =IF(B50<>"",SUMIF(出库明细!C:C,B50,出库明细!G:G),"") -> 12327.5 | E50: =IF(AND(C50<>"",D50<>""),C50-D50,"") -> -327.5 | F50: =IF(B50<>"",SUMIF(收付款明细!C:C,B50,收付款明细!D:D),"") -> 12327.5 | G50: =IF(AND(D50<>"",F50<>""),D50-F50,"") -> 0 | H50: =IF(B50="","",IF(G50=0,"已结清",IF(G50>0,"有欠款","预存款"))) -> 已结清 | I50: =IFERROR(SUMIF(商品库存!B:B,B50,商品库存!I:I),0) -> 0 | J50: =IFERROR(SUMIF(商品库存!B:B,B50,商品库存!J:J),0) -> 0
A51: 47 | B51: 优生副食 | D51: =IF(B51<>"",SUMIF(出库明细!C:C,B51,出库明细!G:G),"") -> 720 | E51: =IF(AND(C51<>"",D51<>""),C51-D51,"") | F51: =IF(B51<>"",SUMIF(收付款明细!C:C,B51,收付款明细!D:D),"") -> 0 | G51: =IF(AND(D51<>"",F51<>""),D51-F51,"") -> 720 | H51: =IF(B51="","",IF(G51=0,"已结清",IF(G51>0,"有欠款","预存款"))) -> 有欠款 | I51: =IFERROR(SUMIF(商品库存!B:B,B51,商品库存!I:I),0) -> 0 | J51: =IFERROR(SUMIF(商品库存!B:B,B51,商品库存!J:J),0) -> 0
A52: 48 | B52: 龙岗好又全超市 | C52: 137732 | D52: =IF(B52<>"",SUMIF(出库明细!C:C,B52,出库明细!G:G),"") -> 24252 | E52: =IF(AND(C52<>"",D52<>""),C52-D52,"") -> 113480 | F52: =IF(B52<>"",SUMIF(收付款明细!C:C,B52,收付款明细!D:D),"") -> 152732 | G52: =IF(AND(D52<>"",F52<>""),D52-F52,"") -> -128480 | H52: =IF(B52="","",IF(G52=0,"已结清",IF(G52>0,"有欠款","预存款"))) -> 预存款 | I52: =IFERROR(SUMIF(商品库存!B:B,B52,商品库存!I:I),0) -> 1578 | J52: =IFERROR(SUMIF(商品库存!B:B,B52,商品库存!J:J),0) -> 113930
A53: 49 | B53: 福旺家优购 | C53: 27220 | D53: =IF(B53<>"",SUMIF(出库明细!C:C,B53,出库明细!G:G),"") -> 14037 | E53: =IF(AND(C53<>"",D53<>""),C53-D53,"") -> 13183 | F53: =IF(B53<>"",SUMIF(收付款明细!C:C,B53,收付款明细!D:D),"") -> 27220 | G53: =IF(AND(D53<>"",F53<>""),D53-F53,"") -> -13183 | H53: =IF(B53="","",IF(G53=0,"已结清",IF(G53>0,"有欠款","预存款"))) -> 预存款 | I53: =IFERROR(SUMIF(商品库存!B:B,B53,商品库存!I:I),0) -> 159 | J53: =IFERROR(SUMIF(商品库存!B:B,B53,商品库存!J:J),0) -> 12949
A54: 50 | B54: 友兰商行 | C54: 602 | D54: =IF(B54<>"",SUMIF(出库明细!C:C,B54,出库明细!G:G),"") -> 5252 | E54: =IF(AND(C54<>"",D54<>""),C54-D54,"") -> -4650 | F54: =IF(B54<>"",SUMIF(收付款明细!C:C,B54,收付款明细!D:D),"") -> 5252 | G54: =IF(AND(D54<>"",F54<>""),D54-F54,"") -> 0 | H54: =IF(B54="","",IF(G54=0,"已结清",IF(G54>0,"有欠款","预存款"))) -> 已结清 | I54: =IFERROR(SUMIF(商品库存!B:B,B54,商品库存!I:I),0) -> 0 | J54: =IFERROR(SUMIF(商品库存!B:B,B54,商品库存!J:J),0) -> 0
A55: 51 | B55: 隆坪美林副食 | C55: 5386 | D55: =IF(B55<>"",SUMIF(出库明细!C:C,B55,出库明细!G:G),"") -> 2833 | E55: =IF(AND(C55<>"",D55<>""),C55-D55,"") -> 2553 | F55: =IF(B55<>"",SUMIF(收付款明细!C:C,B55,收付款明细!D:D),"") -> 5386 | G55: =IF(AND(D55<>"",F55<>""),D55-F55,"") -> -2553 | H55: =IF(B55="","",IF(G55=0,"已结清",IF(G55>0,"有欠款","预存款"))) -> 预存款 | I55: =IFERROR(SUMIF(商品库存!B:B,B55,商品库存!I:I),0) -> 0 | J55: =IFERROR(SUMIF(商品库存!B:B,B55,商品库存!J:J),0) -> 0
A56: 52 | B56: 高兴四季春副食 | C56: 2697 | D56: =IF(B56<>"",SUMIF(出库明细!C:C,B56,出库明细!G:G),"") -> 24180 | E56: =IF(AND(C56<>"",D56<>""),C56-D56,"") -> -21483 | F56: =IF(B56<>"",SUMIF(收付款明细!C:C,B56,收付款明细!D:D),"") -> 2697 | G56: =IF(AND(D56<>"",F56<>""),D56-F56,"") -> 21483 | H56: =IF(B56="","",IF(G56=0,"已结清",IF(G56>0,"有欠款","预存款"))) -> 有欠款 | I56: =IFERROR(SUMIF(商品库存!B:B,B56,商品库存!I:I),0) -> 10 | J56: =IFERROR(SUMIF(商品库存!B:B,B56,商品库存!J:J),0) -> -21483
A57: 53 | B57: 崇贤高平副食 | C57: 2325 | D57: =IF(B57<>"",SUMIF(出库明细!C:C,B57,出库明细!G:G),"") -> 1395 | E57: =IF(AND(C57<>"",D57<>""),C57-D57,"") -> 930 | F57: =IF(B57<>"",SUMIF(收付款明细!C:C,B57,收付款明细!D:D),"") -> 2325 | G57: =IF(AND(D57<>"",F57<>""),D57-F57,"") -> -930 | H57: =IF(B57="","",IF(G57=0,"已结清",IF(G57>0,"有欠款","预存款"))) -> 预存款 | I57: =IFERROR(SUMIF(商品库存!B:B,B57,商品库存!I:I),0) -> 10 | J57: =IFERROR(SUMIF(商品库存!B:B,B57,商品库存!J:J),0) -> 930
A58: 54 | B58: 高兴张声英 | C58: 2325 | D58: =IF(B58<>"",SUMIF(出库明细!C:C,B58,出库明细!G:G),"") -> 0 | E58: =IF(AND(C58<>"",D58<>""),C58-D58,"") -> 2325 | F58: =IF(B58<>"",SUMIF(收付款明细!C:C,B58,收付款明细!D:D),"") -> 2325 | G58: =IF(AND(D58<>"",F58<>""),D58-F58,"") -> -2325 | H58: =IF(B58="","",IF(G58=0,"已结清",IF(G58>0,"有欠款","预存款"))) -> 预存款 | I58: =IFERROR(SUMIF(商品库存!B:B,B58,商品库存!I:I),0) -> 25 | J58: =IFERROR(SUMIF(商品库存!B:B,B58,商品库存!J:J),0) -> 2325
...

Sheet 出库明细
A1: 商品领用明细台账
A2: 💡 每次送货/拣货在此登记，总览表和库存表自动更新
A3: 序号 | B3: 日期 | D3: 商品品类 | E3: 领用数量(件) | F3: 单价(元/件) | G3: 本次领用金额(元) | H3: 备注
A4: 1 | B4: 46202 | C4: 阿东副食 | D4: 555补水 | E4: 11 | F4: 65 | G4: =IF(AND(E4<>"",F4<>""),E4*F4,"") -> 715
A5: 2 | B5: 46202 | C5: 阿东副食 | D5: 小焙好茶 | E5: 20 | F5: 48 | G5: =IF(AND(E5<>"",F5<>""),E5*F5,"") -> 960
A6: 3 | B6: 46203 | C6: 阿东副食 | D6: 小果之茶 | E6: 166 | F6: 47 | G6: =IF(AND(E6<>"",F6<>""),E6*F6,"") -> 7802
A7: 4 | B7: 46210 | C7: 阿东副食 | D7: 555补水 | E7: 80 | F7: 65 | G7: =IF(AND(E7<>"",F7<>""),E7*F7,"") -> 5200
A8: 5 | B8: 46210 | C8: 阿东副食 | D8: 1L补水 | E8: 50 | F8: 55 | G8: =IF(AND(E8<>"",F8<>""),E8*F8,"") -> 2750
A9: 6 | B9: 46220 | C9: 阿东副食 | D9: 1L果之茶 | E9: 90 | F9: 43 | G9: =IF(AND(E9<>"",F9<>""),E9*F9,"") -> 3870
A10: 7 | B10: 46220 | C10: 阿东副食 | D10: 小焙好茶 | E10: 20 | F10: 48 | G10: =IF(AND(E10<>"",F10<>""),E10*F10,"") -> 960
A11: 8 | B11: 46220 | C11: 阿东副食 | D11: 555补水 | E11: 25 | F11: 65 | G11: =IF(AND(E11<>"",F11<>""),E11*F11,"") -> 1625
A12: 9 | B12: 46220 | C12: 阿东副食 | D12: 小果之茶 | E12: 50 | F12: 47 | G12: =IF(AND(E12<>"",F12<>""),E12*F12,"") -> 2350
A13: 10 | B13: 46227 | C13: 阿东副食 | D13: 大咖 | E13: 50 | F13: 83 | G13: =IF(AND(E13<>"",F13<>""),E13*F13,"") -> 4150
A14: 11 | B14: 46225 | C14: 阿东副食 | D14: 330大咖 | E14: 20 | F14: 90 | G14: =IF(AND(E14<>"",F14<>""),E14*F14,"") -> 1800
A15: 12 | B15: 46225 | C15: 阿东副食 | D15: 555补水 | E15: 30 | F15: 65 | G15: =IF(AND(E15<>"",F15<>""),E15*F15,"") -> 1950
... A25: 22 | B25: 46230 | C25: 诚信粮油 | D25: 大东鹏 | E25: 100 | F25: 90 | G25: =IF(AND(E25<>"",F25<>""),E25*F25,"") -> 9000
A26: 23 | B26: 46214 | C26: 城北街隆兴商行 | D26: 大东鹏 | E26: 1 | G26: =IF(AND(E26<>"",F26<>""),E26*F26,"")
A27: 24 | B27: 46214 | C27: 城北街隆兴商行 | D27: 555补水 | E27: 3 | F27: 68 | G27: =IF(AND(E27<>"",F27<>""),E27*F27,"") -> 204
A28: 25 | B28: 46214 | C28: 城北街隆兴商行 | D28: 555补水 | E28: 1 | G28: =IF(AND(E28<>"",F28<>""),E28*F28,"")
A29: 26 | B29: 46221 | C29: 崇贤三角超市 | D29: 1L补水 | E29: 5 | F29: 58 | G29: =IF(AND(E29<>"",F29<>""),E29*F29,"") -> 290
A30: 27 | B30: 46197 | C30: 枫边德华超市 | D30: 555补水 | E30: 30 | F30: 65 | G30: =IF(AND(E30<>"",F30<>""),E30*F30,"") -> 1950
A31: 28 | B31: 46221 | C31: 枫边德华超市 | D31: 大东鹏 | E31: 100 | F31: 90 | G31: =IF(AND(E31<>"",F31<>""),E31*F31,"") -> 9000
A32: 29 | B32: 46213 | C32: 福旺家优购 | D32: 大东鹏 | E32: 20 | F32: 93 | G32: =IF(AND(E32<>"",F32<>""),E32*F32,"") -> 1860
A33: 30 | B33: 46213 | C33: 福旺家优购 | D33: 小果之茶 | E33: 5 | F33: 50 | G33: =IF(AND(E33<>"",F33<>""),E33*F33,"") -> 250
A34: 31 | B34: 46213 | C34: 福旺家优购 | D34: 555补水 | E34: 3 | F34: 68 | G34: =IF(AND(E34<>"",F34<>""),E34*F34,"") -> 204
A35: 32 | B35: 46213 | C35: 福旺家优购 | D35: 1L补水 | E35: 3 | F35: 58 | G35: =IF(AND(E35<>"",F35<>""),E35*F35,"") -> 174
A36: 33 | B36: 46222 | C36: 福旺家优购 | D36: 1L补水 | E36: 12 | F36: 58 | G36: =IF(AND(E36<>"",F36<>""),E36*F36,"") -> 696
A37: 34 | B37: 46222 | C37: 福旺家优购 | D37: 1L果之茶 | E37: 10 | F37: 46 | G37: =IF(AND(E37<>"",F37<>""),E37*F37,"") -> 460
A38: 35 | B38: 46219 | C38: 福旺家优购 | D38: 大东鹏 | E38: 25 | F38: 93 | G38: =IF(AND(E38<>"",F38<>""),E38*F38,"") -> 2325
A39: 36 | B39: 46219 | C39: 福旺家优购 | D39: 555补水 | E39: 11 | F39: 68 | G39: =IF(AND(E39<>"",F39<>""),E39*F39,"") -> 748
A40: 37 | B40: 46219 | C40: 福旺家优购 | D40: 港式奶茶 | E40: 2 | F40: 72 | G40: =IF(AND(E40<>"",F40<>""),E40*F40,"") -> 144
... A61: 58 | B61: 46230 | C61: 洪门兴诚超市 | D61: 大东鹏 | E61: 100 | F61: 90 | G61: =IF(AND(E61<>"",F61<>""),E61*F61,"") -> 9000
A62: 59 | B62: 46195 | C62: 家家兴超市 | D62: 500农夫饮料 | E62: 4 | F62: 54 | G62: =IF(AND(E62<>"",F62<>""),E62*F62,"") -> 216 | H62: 高兴店
A63: 60 | B63: 46195 | C63: 家家兴超市 | D63: 500农夫饮料 | E63: 5 | F63: 54 | G63: =IF(AND(E63<>"",F63<>""),E63*F63,"") -> 270 | H63: 城岗店
A64: 61 | B64: 46200 | C64: 家家兴超市 | D64: 500农夫饮料 | E64: 6 | F64: 54 | G64: =IF(AND(E64<>"",F64<>""),E64*F64,"") -> 324 | H64: 龙岗店
A65: 62 | B65: 46203 | C65: 家家兴超市 | D65: 500农夫饮料 | E65: 10 | F65: 54 | G65: =IF(AND(E65<>"",F65<>""),E65*F65,"") -> 540 | H65: 模范城
A66: 63 | B66: 46203 | C66: 家家兴超市 | D66: 1.5L水 | E66: 2 | F66: 25 | G66: =IF(AND(E66<>"",F66<>""),E66*F66,"") -> 50
A67: 64 | B67: 46204 | C67: 家家兴超市 | D67: 500农夫饮料 | E67: 2 | F67: 54 | G67: =IF(AND(E67<>"",F67<>""),E67*F67,"") -> 108 | H67: 梅窖
A68: 65 | B68: 46204 | C68: 家家兴超市 | D68: 550农夫纯净水 | E68: 50 | F68: 14 | G68: =IF(AND(E68<>"",F68<>""),E68*F68,"") -> 700 | H68: 梅窖
A69: 66 | B69: 46204 | C69: 家家兴超市 | D69: 550农夫纯净水 | E69: -6.5 | F69: 14 | G69: =IF(AND(E69<>"",F69<>""),E69*F69,"") -> -91
...

Sheet 收付款明细
A1: 收付款明细台账
A2: 💡 客户每次付款在此登记，总览表自动更新未付货款
A3: 序号 | B3: 日期 | C3: 客户名称 | D3: 收款金额(元) | E3: 付款方式 | F3: 备注
A4: 1 | B4: 2026.6.25 | C4: 星海超市 | D4: 39547 | E4: 收款码
A5: 2 | B5: 2026.6.25 | C5: 王玉琴 | D5: 99000 | E5: 收款码
A6: 3 | B6: 2026.6.25 | C6: 桐心源 | D6: 700231.47 | E6: 收款码 | F6: 还差我46313元
A7: 4 | B7: 2026.6.25 | C7: 桐心源 | D7: 46360 | E7: 收款码 | F7: 农夫饮料
A8: 5 | B8: 2026.6.25 | C8: 阿东副食 | D8: 570147.22 | E8: 收款码 | F8: 还差我37433元
A9: 6 | B9: 2026.6.26 | C9: 金凤副食 | D9: 8950 | E9: 收款码
B10: 2026.6.26 | C10: 致发商行 | D10: 437965 | E10: 收款码
A11: 7 | B11: 2026.6.26 | C11: 通达商行 | D11: 18000 | E11: 收款码
A12: 8 | B12: 2026.6.26 | C12: 宜兴粮油 | D12: 54000 | E12: 收款码
A13: 9 | B13: 2026.6.27 | C13: 马路下小卖部 | D13: 840 | E13: 收款码 | F13: 东鹏新品订货款
A14: 10 | B14: 2026.6.27 | C14: 兴莲隆兴商行 | D14: 30043 | E14: 收款码
A15: 11 | B15: 2026.6.27 | C15: 诚信粮油 | D15: 27000 | E15: 收款码
A16: 12 | B16: 2026.6.27 | C16: 诚信粮油 | D16: 2565 | E16: 收款码 | F16: 东鹏新品订货款
A17: 13 | B17: 2026.6.27 | C17: 李记副食 | D17: 6930 | E17: 收款码 | F17: 东鹏新品订货款
A18: 14 | B18: 2026.6.27 | C18: 吕维春 | D18: 32440 | E18: 收款码
A19: 15 | B19: 2026.6.27 | C19: 兴发商行 | D19: 15300 | E19: 收款码
A20: 16 | B20: 2026.6.27 | C20: 城岗日日升超市 | D20: 36895 | E20: 收款码
A21: 17 | B21: 2026.6.27 | C21: 江背久明商行 | D21: 21620 | E21: 收款码
A22: 18 | B22: 2026.6.27 | C22: 龙岗好又全超市 | D22: 137732 | E22: 收款码
A23: 19 | B23: 2026.6.27 | C23: 社富丽华超市 | D23: 8100 | E23: 收款码
A24: 20 | B24: 2026.6.27 | C24: 九鑫粮油 | D24: 3150 | E24: 收款码
A25: 21 | B25: 2026.6.27 | C25: 鼎龙陈财超市 | D25: 77682.5 | E25: 收款码 | F25: 还欠2400元
A26: 22 | B26: 2026.6.27 | C26: 洪门美群商行 | D26: 4500 | E26: 收款码
A27: 23 | B27: 2026.6.27 | C27: 兴江家源超市 | D27: 1800 | E27: 收款码
A28: 24 | B28: 2026.6.27 | C28: 永丰橙丰购物 | D28: 1067 | E28: 收款码 | F28: 东鹏新品订货款
A29: 25 | B29: 2026.6.27 | C29: 枫边德华超市 | D29: 38440 | E29: 收款码
A30: 26 | B30: 2026.6.27 | C30: 梅窖建军批发 | D30: 11740 | E30: 收款码
A31: 27 | B31: 2026.6.27 | C31: 高兴美宜佳 | D31: 704 | E31: 收款码 | F31: 东鹏新品订货款
A32: 28 | B32: 2026.6.27 | C32: 永丰焦溪兰兰副食 | D32: 3244 | E32: 收款码 | F32: 东鹏新品订货款
A33: 29 | B33: 2026.6.27 | C33: 高兴枫树平价超市 | D33: 1126 | E33: 收款码 | F33: 东鹏新品订货款
A34: 30 | B34: 2026.6.27 | C34: 鼎龙众家乐超市 | D34: 2182 | E34: 收款码 | F34: 东鹏新品订货款
A35: 31 | B35: 2026.6.27 | C35: 洪门兴诚超市 | D35: 45000 | E35: 收款码
A36: 32 | B36: 2026.6.29 | C36: 兴江吴辉明 | D36: 21135 | E36: 收款码
A37: 33 | B37: 2026.6.29 | C37: 和睦公园百顺 | D37: 27000 | E37: 收款码
A38: 34 | B38: 2026.6.28 | C38: 王玉琴 | D38: 7697 | E38: 收款码
A39: 35 | B39: 2026.7.1 | C39: 阳光超市 | D39: 11350 | E39: 农业工账
A40: 36 | B40: 2026.7.2 | C40: 家家兴超市 | D40: 10000 | E40: 收款码
...

Sheet 存条明细
A1: 商品入库明细台账
A2: 💡 每次进货/入库在此登记，库存表自动汇总更新，支持同一客户+商品多笔入库自动累加
A3: 序号 | B3: 入库日期 | C3: 客户名称 | D3: 商品品类 | E3: 入库数量(件) | F3: 入库单价(元/件) | G3: 本次入库总金额(元) | H3: 备注
A4: 1 | B4: 46198 | C4: 星海超市 | D4: 小东鹏 | E4: 282 | F4: 50 | G4: =IF(AND(E4<>"",F4<>""),E4*F4,"") -> 14100
A5: 2 | B5: 46198 | C5: 星海超市 | D5: 555补水 | E5: 83 | F5: 65 | G5: =IF(AND(E5<>"",F5<>""),E5*F5,"") -> 5395
A6: 3 | B6: 46198 | C6: 星海超市 | D6: 1L补水 | E6: 142 | F6: 55 | G6: =IF(AND(E6<>"",F6<>""),E6*F6,"") -> 7810
A7: 4 | B7: 46198 | C7: 星海超市 | D7: 1L果之茶 | E7: 118 | F7: 43 | G7: =IF(AND(E7<>"",F7<>""),E7*F7,"") -> 5074
A8: 5 | B8: 46198 | C8: 星海超市 | D8: 港式奶茶 | E8: 96 | F8: 69 | G8: =IF(AND(E8<>"",F8<>""),E8*F8,"") -> 6624
A9: 6 | B9: 46198 | C9: 王玉琴 | D9: 大东鹏 | E9: 1100 | F9: 90 | G9: =IF(AND(E9<>"",F9<>""),E9*F9,"") -> 99000
A10: 7 | B10: 46198 | C10: 桐心源 | D10: 大东鹏 | E10: 6531 | F10: 90 | G10: =IF(AND(E10<>"",F10<>""),E10*F10,"") -> 587790
A11: 8 | B11: 46198 | C11: 桐心源 | D11: 1L补水 | E11: 625 | F11: 55 | G11: =IF(AND(E11<>"",F11<>""),E11*F11,"") -> 34375
A12: 9 | B12: 46198 | C12: 桐心源 | D12: 555补水 | E12: 604 | F12: 65 | G12: =IF(AND(E12<>"",F12<>""),E12*F12,"") -> 39260
A13: 10 | B13: 46198 | C13: 桐心源 | D13: 小果之茶 | E13: 906 | F13: 47 | G13: =IF(AND(E13<>"",F13<>""),E13*F13,"") -> 42582
A14: 11 | B14: 46198 | C14: 桐心源 | D14: 大咖 | E14: 236 | F14: 83 | G14: =IF(AND(E14<>"",F14<>""),E14*F14,"") -> 19588
A15: 12 | B15: 46198 | C15: 桐心源 | D15: 港式奶茶 | E15: 152 | F15: 69 | G15: =IF(AND(E15<>"",F15<>""),E15*F15,"") -> 10488
... A43: 40 | B43: 46199 | C43: 致发商行 | D43: 大东鹏 | E43: 2300 | F43: 90 | G43: =IF(AND(E43<>"",F43<>""),E43*F43,"") -> 207000
A44: 41 | B44: 46199 | C44: 致发商行 | D44: 小果之茶 | E44: 1040 | F44: 47 | G44: 47000
A45: 42 | B45: 46199 | C45: 致发商行 | D45: 大咖 | E45: 208 | F45: 86 | G45: 16600
A46: 43 | B46: 46199 | C46: 致发商行 | D46: 1L果之茶 | E46: 208 | F46: 43 | G46: 8600
A47: 44 | B47: 46199 | C47: 通达商行 | D47: 大东鹏 | E47: 200 | F47: 90 | G47: =IF(AND(E47<>"",F47<>""),E47*F47,"") -> 18000
A48: 45 | B48: 46199 | C48: 宜兴粮油 | D48: 大东鹏 | E48: 615 | F48: 87.8 | G48: 54000
A49: 46 | B49: 46199 | C49: 宜兴粮油 | D49: 555补水 | E49: 5 | F49: 0 | G49: =IF(AND(E49<>"",F49<>""),E49*F49,"") -> 0
A50: 47 | B50: 46200 | C50: 兴隆隆兴商行 | D50: 大东鹏 | E50: 162 | F50: 90 | G50: =IF(AND(E50<>"",F50<>""),E50*F50,"") -> 14580
A51: 48 | B51: 46200 | C51: 兴隆隆兴商行 | D51: 1L补水 | E51: 23 | F51: 55 | G51: =IF(AND(E51<>"",F51<>""),E51*F51,"") -> 1265
A52: 49 | B52: 46200 | C52: 兴隆隆兴商行 | D52: 555补水 | E52: 23 | F52: 65 | G52: =IF(AND(E52<>"",F52<>""),E52*F52,"") -> 1495
A53: 50 | B53: 46200 | C53: 兴隆隆兴商行 | D53: 大咖 | E53: 68 | F53: 83 | G53: =IF(AND(E53<>"",F53<>""),E53*F53,"") -> 5644
A54: 51 | B54: 46200 | C54: 兴隆隆兴商行 | D54: 港式奶茶 | E54: 11 | F54: 69 | G54: =IF(AND(E54<>"",F54<>""),E54*F54,"") -> 759
A55: 52 | B55: 46200 | C55: 诚信粮油 | D55: 大东鹏 | E55: 300 | F55: 90 | G55: =IF(AND(E55<>"",F55<>""),E55*F55,"") -> 27000
A56: 53 | B56: 46200 | C56: 吕维春 | D56: 大东鹏 | E56: 250 | F56: 90 | G56: =IF(AND(E56<>"",F56<>""),E56*F56,"") -> 22500
A57: 54 | B57: 46200 | C57: 吕维春 | D57: 1L补水 | E57: 150 | F57: 55 | G57: =IF(AND(E57<>"",F57<>""),E57*F57,"") -> 8250
A58: 55 | B58: 46200 | C58: 吕维春 | D58: 1L果之茶 | E58: 20 | F58: 43 | G58: =IF(AND(E58<>"",F58<>""),E58*F58,"") -> 860
A59: 56 | B59: 46200 | C59: 吕维春 | D59: 大咖 | E59: 10 | F59: 83 | G59: =IF(AND(E59<>"",F59<>""),E59*F59,"") -> 830
A60: 57 | B60: 46200 | C60: 兴发商行 | D60: 大东鹏 | E60: 170 | F60: 90 | G60: =IF(AND(E60<>"",F60<>""),E60*F60,"") -> 15300
... A89: 86 | B89: 46200 | C89: 洪门美群商行 | D89: 大东鹏 | E89: 50 | F89: 90 | G89: =IF(AND(E89<>"",F89<>""),E89*F89,"") -> 4500
A90: 87 | B90: 46200 | C90: 兴江家源超市 | D90: 大东鹏 | E90: 20 | F90: 90 | G90: =IF(AND(E90<>"",F90<>""),E90*F90,"") -> 1800 | H90: 2024年7月5日存条
A91: 88 | B91: 46200 | C91: 枫边德华超市 | D91: 大东鹏 | E91: 100 | F91: 90 | G91: =IF(AND(E91<>"",F91<>""),E91*F91,"") -> 9000
A92: 89 | B92: 46200 | C92: 枫边德华超市 | D92: 555补水 | E92: 80 | F92: 65 | G92: =IF(AND(E92<>"",F92<>""),E92*F92,"") -> 5200
A93: 90 | B93: 46200 | C93: 枫边德华超市 | D93: 1L补水 | E93: 80 | F93: 55 | G93: =IF(AND(E93<>"",F93<>""),E93*F93,"") -> 4400
A94: 91 | B94: 46200 | C94: 枫边德华超市 | D94: 港式奶茶 | E94: 80 | F94: 69 | G94: =IF(AND(E94<>"",F94<>""),E94*F94,"") -> 5520
A95: 92 | B95: 46200 | C95: 枫边德华超市 | D95: 1L果之茶 | E95: 80 | F95: 46 | G95: =IF(AND(E95<>"",F95<>""),E95*F95,"") -> 3680
...

Sheet 商品库存
A1: 商品库存明细（按客户+商品）
A2: 💡 查看每个客户每个商品的库存情况：新增客户+商品在此填写初始数量，领用后自动扣减
A3: 序号 | B3: 客户名称 | C3: 商品品类 | D3: 累计入库数量(件) | E3: 入库单价(元) | F3: 累计入库总金额(元) | G3: 已领用数量(件) | H3: 已领用金额(元) | I3: 剩余数量(件) | J3: 剩余金额(元) | K3: 最后更新日期
A4: 1 | B4: 星海超市 | C4: 小东鹏 | D4: =IFERROR(SUMIFS(存条明细!E:E,存条明细!C:C,B4,存条明细!D:D,C4),0) -> 282 | E4: 50 | F4: =IFERROR(SUMIFS(存条明细!G:G,存条明细!C:C,B4,存条明细!D:D,C4),0) -> 14100 | G4: =IFERROR(SUMIFS(出库明细!E:E,出库明细!C:C,B4,出库明细!D:D,C4),0) -> 182 | H4: =IFERROR(SUMIFS(出库明细!G:G,出库明细!C:C,B4,出库明细!D:D,C4),0) -> 9282 | I4: =IFERROR(D4-G4,0) -> 100 | J4: =IFERROR(F4-H4,0) -> 4818 | K4: =TODAY() -> 46289
A5: 2 | B5: 星海超市 | C5: 555补水 | D5: =IFERROR(SUMIFS(存条明细!E:E,存条明细!C:C,B5,存条明细!D:D,C5),0) -> 303 | E5: 65 | F5: =IFERROR(SUMIFS(存条明细!G:G,存条明细!C:C,B5,存条明细!D:D,C5),0) -> 18395 | G5: =IFERROR(SUMIFS(出库明细!E:E,出库明细!C:C,B5,出库明细!D:D,C5),0) -> 100 | H5: =IFERROR(SUMIFS(出库明细!G:G,出库明细!C:C,B5,出库明细!D:D,C5),0) -> 6500 | I5: =IFERROR(D5-G5,0) -> 203 | J5: =IFERROR(F5-H5,0) -> 11895 | K5: =TODAY() -> 46289
A6: 3 | B6: 星海超市 | C6: 1L补水 | D6: =IFERROR(SUMIFS(存条明细!E:E,存条明细!C:C,B6,存条明细!D:D,C6),0) -> 142 | E6: 55 | F6: =IFERROR(SUMIFS(存条明细!G:G,存条明细!C:C,B6,存条明细!D:D,C6),0) -> 7810 | G6: =IFERROR(SUMIFS(出库明细!E:E,出库明细!C:C,B6,出库明细!D:D,C6),0) -> 90 | H6: =IFERROR(SUMIFS(出库明细!G:G,出库明细!C:C,B6,出库明细!D:D,C6),0) -> 4950 | I6: =IFERROR(D6-G6,0) -> 52 | J6: =IFERROR(F6-H6,0) -> 2860 | K6: =TODAY() -> 46289
A7: 4 | B7: 星海超市 | C7: 1L果之茶 | D7: =IFERROR(SUMIFS(存条明细!E:E,存条明细!C:C,B7,存条明细!D:D,C7),0) -> 118 | E7: 43 | F7: =IFERROR(SUMIFS(存条明细!G:G,存条明细!C:C,B7,存条明细!D:D,C7),0) -> 5074 | G7: =IFERROR(SUMIFS(出库明细!E:E,出库明细!C:C,B7,出库明细!D:D,C7),0) -> 80 | H7: =IFERROR(SUMIFS(出库明细!G:G,出库明细!C:C,B7,出库明细!D:D,C7),0) -> 3440 | I7: =IFERROR(D7-G7,0) -> 38 | J7: =IFERROR(F7-H7,0) -> 1634 | K7: =TODAY() -> 46289
A8: 5 | B8: 星海超市 | C8: 港式奶茶 | D8: =IFERROR(SUMIFS(存条明细!E:E,存条明细!C:C,B8,存条明细!D:D,C8),0) -> 96 | E8: 69 | F8: =IFERROR(SUMIFS(存条明细!G:G,存条明细!C:C,B8,存条明细!D:D,C8),0) -> 6624 | G8: =IFERROR(SUMIFS(出库明细!E:E,出库明细!C:C,B8,出库明细!D:D,C8),0) -> 0 | H8: =IFERROR(SUMIFS(出库明细!G:G,出库明细!C:C,B8,出库明细!D:D,C8),0) -> 0 | I8: =IFERROR(D8-G8,0) -> 96 | J8: =IFERROR(F8-H8,0) -> 6624 | K8: =TODAY() -> 46289
A9: 6 | B9: 星海超市 | C9: 小焙好茶 | D9: 0 | E9: 48 | F9: =IFERROR(SUMIFS(存条明细!G:G,存条明细!C:C,B9,存条明细!D:D,C9),0) -> 0 | G9: =IFERROR(SUMIFS(出库明细!E:E,出库明细!C:C,B9,出库明细!D:D,C9),0) -> 20 | H9: =IFERROR(SUMIFS(出库明细!G:G,出库明细!C:C,B9,出库明细!D:D,C9),0) -> 960 | I9: =IFERROR(D9-G9,0) -> -20 | J9: =IFERROR(F9-H9,0) -> -960 | K9: =TODAY() -> 46289
A10: 7 | B10: 星海超市 | C10: 大咖 | D10: 0 | E10: 83 | F10: =IFERROR(SUMIFS(存条明细!G:G,存条明细!C:C,B10,存条明细!D:D,C10),0) -> 8300 | G10: =IFERROR(SUMIFS(出库明细!E:E,出库明细!C:C,B10,出库明细!D:D,C10),0) -> 30 | H10: =IFERROR(SUMIFS(出库明细!G:G,出库明细!C:C,B10,出库明细!D:D,C10),0) -> 2490 | I10: =IFERROR(D10-G10,0) -> -30 | J10: =IFERROR(F10-H10,0) -> 5810 | K10: =TODAY() -> 46289
A11: 8 | B11: 王玉琴 | C11: 大东鹏 | D11: =IFERROR(SUMIFS(存条明细!E:E,存条明细!C:C,B11,存条明细!D:D,C11),0) -> 1100 | E11: 90 | F11: =IFERROR(SUMIFS(存条明细!G:G,存条明细!C:C,B11,存条明细!D:D,C11),0) -> 99000 | G11: =IFERROR(SUMIFS(出库明细!E:E,出库明细!C:C,B11,出库明细!D:D,C11),0) -> 550 | H11: =IFERROR(SUMIFS(出库明细!G:G,出库明细!C:C,B11,出库明细!D:D,C11),0) -> 49500 | I11: =IFERROR(D11-G11,0) -> 550 | J11: =IFERROR(F11-H11,0) -> 49500 | K11: =TODAY() -> 46289
A12: 9 | B12: 桐心源 | C12: 大东鹏 | D12: =IFERROR(SUMIFS(存条明细!E:E,存条明细!C:C,B12,存条明细!D:D,C12),0) -> 6531 | E12: 90 | F12: =IFERROR(SUMIFS(存条明细!G:G,存条明细!C:C,B12,存条明细!D:D,C12),0) -> 587790 | G12: =IFERROR(SUMIFS(出库明细!E:E,出库明细!C:C,B12,出库明细!D:D,C12),0) -> 2000 | H12: =IFERROR(SUMIFS(出库明细!G:G,出库明细!C:C,B12,出库明细!D:D,C12),0) -> 180000 | I12: =IFERROR(D12-G12,0) -> 4531 | J12: =IFERROR(F12-H12,0) -> 407790 | K12: =TODAY() -> 46289
A13: 10 | B13: 桐心源 | C13: 1L补水 | D13: =IFERROR(SUMIFS(存条明细!E:E,存条明细!C:C,B13,存条明细!D:D,C13),0) -> 625 | E13: 55 | F13: =IFERROR(SUMIFS(存条明细!G:G,存条明细!C:C,B13,存条明细!D:D,C13),0) -> 34375 | G13: =IFERROR(SUMIFS(出库明细!E:E,出库明细!C:C,B13,出库明细!D:D,C13),0) -> 490 | H13: =IFERROR(SUMIFS(出库明细!G:G,出库明细!C:C,B13,出库明细!D:D,C13),0) -> 26950 | I13: =IFERROR(D13-G13,0) -> 135 | J13: =IFERROR(F13-H13,0) -> 7425 | K13: =TODAY() -> 46289
A14: 11 | B14: 桐心源 | C14: 555补水 | D14: =IFERROR(SUMIFS(存条明细!E:E,存条明细!C:C,B14,存条明细!D:D,C14),0) -> 1154 | E14: 65 | F14: =IFERROR(SUMIFS(存条明细!G:G,存条明细!C:C,B14,存条明细!D:D,C14),0) -> 71760 | G14: =IFERROR(SUMIFS(出库明细!E:E,出库明细!C:C,B14,出库明细!D:D,C14),0) -> 710 | H14: =IFERROR(SUMIFS(出库明细!G:G,出库明细!C:C,B14,出库明细!D:D,C14),0) -> 46150 | I14: =IFERROR(D14-G14,0) -> 444 | J14: =IFERROR(F14-H14,0) -> 25610 | K14: =TODAY() -> 46289
A15: 12 | B15: 桐心源 | C15: 小果之茶 | D15: =IFERROR(SUMIFS(存条明细!E:E,存条明细!C:C,B15,存条明细!D:D,C15),0) -> 1530 | E15: 47 | F15: =IFERROR(SUMIFS(存条明细!G:G,存条明细!C:C,B15,存条明细!D:D,C15),0) -> 70782 | G15: =IFERROR(SUMIFS(出库明细!E:E,出库明细!C:C,B15,出库明细!D:D,C15),0) -> 1632 | H15: =IFERROR(SUMIFS(出库明细!G:G,出库明细!C:C,B15,出库明细!D:D,C15),0) -> 76704 | I15: =IFERROR(D15-G15,0) -> -102 | J15: =IFERROR(F15-H15,0) -> -5922 | K15: =TODAY() -> 46289
A16: 13 | B16: 桐心源 | C16: 大咖 | D16: =IFERROR(SUMIFS(存条明细!E:E,存条明细!C:C,B16,存条明细!D:D,C16),0) -> 236 | E16: 83 | F16: =IFERROR(SUMIFS(存条明细!G:G,存条明细!C:C,B16,存条明细!D:D,C16),0) -> 19588 | G16: =IFERROR(SUMIFS(出库明细!E:E,出库明细!C:C,B16,出库明细!D:D,C16),0) -> 50 | H16: =IFERROR(SUMIFS(出库明细!G:G,出库明细!C:C,B16,出库明细!D:D,C16),0) -> 4150 | I16: =IFERROR(D16-G16,0) -> 186 | J16: =IFERROR(F16-H16,0) -> 15438 | K16: =TODAY() -> 46289
A17: 14 | B17: 桐心源 | C17: 港式奶茶 | D17: =IFERROR(SUMIFS(存条明细!E:E,存条明细!C:C,B17,存条明细!D:D,C17),0) -> 152 | E17: 69 | F17: =IFERROR(SUMIFS(存条明细!G:G,存条明细!C:C,B17,存条明细!D:D,C17),0) -> 10488 | G17: =IFERROR(SUMIFS(出库明细!E:E,出库明细!C:C,B17,出库明细!D:D,C17),0) -> 20 | H17: =IFERROR(SUMIFS(出库明细!G:G,出库明细!C:C,B17,出库明细!D:D,C17),0) -> 1380 | I17: =IFERROR(D17-G17,0) -> 132 | J17: =IFERROR(F17-H17,0) -> 9108 | K17: =TODAY() -> 46289
A18: 15 | B18: 桐心源 | C18: 1L果之茶 | D18: =IFERROR(SUMIFS(存条明细!E:E,存条明细!C:C,B18,存条明细!D:D,C18),0) -> 494 | E18: 43 | F18: =IFERROR(SUMIFS(存条明细!G:G,存条明细!C:C,B18,存条明细!D:D,C18),0) -> 20554 | G18: =IFERROR(SUMIFS(出库明细!E:E,出库明细!C:C,B18,出库明细!D:D,C18),0) -> 195 | H18: =IFERROR(SUMIFS(出库明细!G:G,出库明细!C:C,B18,出库明细!D:D,C18),0) -> 8385 | I18: =IFERROR(D18-G18,0) -> 299 | J18: =IFERROR(F18-H18,0) -> 12169 | K18: =TODAY() -> 46289
A19: 16 | B19: 桐心源 | C19: 330大咖 | D19: =IFERROR(SUMIFS(存条明细!E:E,存条明细!C:C,B19,存条明细!D:D,C19),0) -> 134 | E19: 90 | F19: =IFERROR(SUMIFS(存条明细!G:G,存条明细!C:C,B19,存条明细!D:D,C19),0) -> 12060 | G19: =IFERROR(SUMIFS(出库明细!E:E,出库明细!C:C,B19,出库明细!D:D,C19),0) -> 30 | H19: =IFERROR(SUMIFS(出库明细!G:G,出库明细!C:C,B19,出库明细!D:D,C19),0) -> 2700 | I19: =IFERROR(D19-G19,0) -> 104 | J19: =IFERROR(F19-H19,0) -> 9360 | K19: =TODAY() -> 46289
A20: 17 | B20: 桐心源 | C20: 小海岛椰 | D20: =IFERROR(SUMIFS(存条明细!E:E,存条明细!C:C,B20,存条明细!D:D,C20),0) -> 30 | E20: 32 | F20: =IFERROR(SUMIFS(存条明细!G:G,存条明细!C:C,B20,存条明细!D:D,C20),0) -> 960 | G20: =IFERROR(SUMIFS(出库明细!E:E,出库明细!C:C,B20,出库明细!D:D,C20),0) -> 10 | H20: =IFERROR(SUMIFS(出库明细!G:G,出库明细!C:C,B20,出库明细!D:D,C20),0) -> 320 | I20: =IFERROR(D20-G20,0) -> 20 | J20: =IFERROR(F20-H20,0) -> 640 | K20: =TODAY() -> 46289
A21: 18 | B21: 桐心源 | C21: 1.25海岛椰 | D21: =IFERROR(SUMIFS(存条明细!E:E,存条明细!C:C,B21,存条明细!D:D,C21),0) -> 45 | E21: 51 | F21: =IFERROR(SUMIFS(存条明细!G:G,存条明细!C:C,B21,存条明细!D:D,C21),0) -> 2295 | G21: =IFERROR(SUMIFS(出库明细!E:E,出库明细!C:C,B21,出库明细!D:D,C21),0) -> 0 | H21: =IFERROR(SUMIFS(出库明细!G:G,出库明细!C:C,B21,出库明细!D:D,C21),0) -> 0 | I21: =IFERROR(D21-G21,0) -> 45 | J21: =IFERROR(F21-H21,0) -> 2295 | K21: =TODAY() -> 46289
A22: 19 | B22: 桐心源 | C22: 500农夫饮料 | D22: =IFERROR(SUMIFS(存条明细!E:E,存条明细!C:C,B22,存条明细!D:D,C22),0) -> 720 | E22: 52 | F22: =IFERROR(SUMIFS(存条明细!G:G,存条明细!C:C,B22,存条明细!D:D,C22),0) -> 37440 | G22: =IFERROR(SUMIFS(出库明细!E:E,出库明细!C:C,B22,出库明细!D:D,C22),0) -> 1062 | H22: =IFERROR(SUMIFS(出库明细!G:G,出库明细!C:C,B22,出库明细!D:D,C22),0) -> 55800 | I22: =IFERROR(D22-G22,0) -> -342 | J22: =IFERROR(F22-H22,0) -> -18360 | K22: =TODAY() -> 46289
... A43: 38 | B43: 致发商行 | C43: 小焙好茶 | D43: =IFERROR(SUMIFS(存条明细!E:E,存条明细!C:C,B43,存条明细!D:D,C43),0) -> 10 | E43: 48 | F43: =IFERROR(SUMIFS(存条明细!G:G,存条明细!C:C,B43,存条明细!D:D,C43),0) -> 480 | G43: =IFERROR(SUMIFS(出库明细!E:E,出库明细!C:C,B43,出库明细!D:D,C43),0) -> 10 | H43: =IFERROR(SUMIFS(出库明细!G:G,出库明细!C:C,B43,出库明细!D:D,C43),0) -> 480 | I43: =IFERROR(D43-G43,0) -> 0 | J43: =IFERROR(F43-H43,0) -> 0 | K43: =TODAY() -> 46289
A44: 39 | B44: 致发商行 | C44: 1L果之茶 | D44: =IFERROR(SUMIFS(存条明细!E:E,存条明细!C:C,B44,存条明细!D:D,C44),0) -> 158 | E44: 43 | F44: =IFERROR(SUMIFS(存条明细!G:G,存条明细!C:C,B44,存条明细!D:D,C44),0) -> 6450 | G44: =IFERROR(SUMIFS(出库明细!E:E,出库明细!C:C,B44,出库明细!D:D,C44),0) -> 268 | H44: =IFERROR(SUMIFS(出库明细!G:G,出库明细!C:C,B44,出库明细!D:D,C44),0) -> 11524 | J44: =IFERROR(F44-H44,0) -> -5074 | K44: =TODAY() -> 46289
A45: 42 | B45: 致发商行 | C45: 大咖 | D45: =IFERROR(SUMIFS(存条明细!E:E,存条明细!C:C,B45,存条明细!D:D,C45),0) -> 208 | E45: 83 | F45: =IFERROR(SUMIFS(存条明细!G:G,存条明细!C:C,B45,存条明细!D:D,C45),0) -> 16600 | G45: =IFERROR(SUMIFS(出库明细!E:E,出库明细!C:C,B45,出库明细!D:D,C45),0) -> 80 | H45: =IFERROR(SUMIFS(出库明细!G:G,出库明细!C:C,B45,出库明细!D:D,C45),0) -> 6640 | I45: =IFERROR(D45-G45,0) -> 128 | J45: =IFERROR(F45-H45,0) -> 9960 | K45: =TODAY() -> 46289
A46: 44 | B46: 通达商行 | C46: 大东鹏 | D46: =IFERROR(SUMIFS(存条明细!E:E,存条明细!C:C,B46,存条明细!D:D,C46),0) -> 200 | E46: 90 | F46: =IFERROR(SUMIFS(存条明细!G:G,存条明细!C:C,B46,存条明细!D:D,C46),0) -> 18000 | G46: =IFERROR(SUMIFS(出库明细!E:E,出库明细!C:C,B46,出库明细!D:D,C46),0) -> 200 | H46: =IFERROR(SUMIFS(出库明细!G:G,出库明细!C:C,B46,出库明细!D:D,C46),0) -> 18000 | I46: =IFERROR(D46-G46,0) -> 0 | J46: =IFERROR(F46-H46,0) -> 0 | K46: =TODAY() -> 46289
A47: 45 | B47: 宜兴粮油 | C47: 大东鹏 | D47: 615 | E47: 87.8 | F47: 54000 | G47: =IFERROR(SUMIFS(出库明细!E:E,出库明细!C:C,B47,出库明细!D:D,C47),0) -> 615 | H47: =IFERROR(SUMIFS(出库明细!G:G,出库明细!C:C,B47,出库明细!D:D,C47),0) -> 54877 | I47: =IFERROR(D47-G47,0) -> 0 | J47: =IFERROR(F47-H47,0) -> -877 | K47: =TODAY() -> 46289
A48: 46 | B48: 宜兴粮油 | C48: 555补水 | D48: 76 | F48: =IFERROR(SUMIFS(存条明细!G:G,存条明细!C:C,B48,存条明细!D:D,C48),0) -> 3900 | G48: =IFERROR(SUMIFS(出库明细!E:E,出库明细!C:C,B48,出库明细!D:D,C48),0) -> 76 | H48: =IFERROR(SUMIFS(出库明细!G:G,出库明细!C:C,B48,出库明细!D:D,C48),0) -> 3900 | I48: =IFERROR(D48-G48,0) -> 0 | J48: =IFERROR(F48-H48,0) -> 0 | K48: =TODAY() -> 46289
A49: 47 | B49: 兴隆隆兴商行 | C49: 大东鹏 | D49: =IFERROR(SUMIFS(存条明细!E:E,存条明细!C:C,B49,存条明细!D:D,C49),0) -> 162 | E49: 90 | F49: =IFERROR(SUMIFS(存条明细!G:G,存条明细!C:C,B49,存条明细!D:D,C49),0) -> 14580 | G49: =IFERROR(SUMIFS(出库明细!E:E,出库明细!C:C,B49,出库明细!D:D,C49),0) -> 162 | H49: =IFERROR(SUMIFS(出库明细!G:G,出库明细!C:C,B49,出库明细!D:D,C49),0) -> 14580 | I49: =IFERROR(D49-G49,0) -> 0 | J49: =IFERROR(F49-H49,0) -> 0 | K49: =TODAY() -> 46289
A50: 48 | B50: 兴隆隆兴商行 | C50: 1L补水 | D50: =IFERROR(SUMIFS(存条明细!E:E,存条明细!C:C,B50,存条明细!D:D,C50),0) -> 23 | E50: 55 | F50: =IFERROR(SUMIFS(存条明细!G:G,存条明细!C:C,B50,存条明细!D:D,C50),0) -> 1265 | G50: =IFERROR(SUMIFS(出库明细!E:E,出库明细!C:C,B50,出库明细!D:D,C50),0) -> 23 | H50: =IFERROR(SUMIFS(出库明细!G:G,出库明细!C:C,B50,出库明细!D:D,C50),0) -> 1265 | I50: =IFERROR(D50-G50,0) -> 0 | J50: =IFERROR(F50-H50,0) -> 0 | K50: =TODAY() -> 46289
A51: 49 | B51: 兴隆隆兴商行 | C51: 555补水 | D51: =IFERROR(SUMIFS(存条明细!E:E,存条明细!C:C,B51,存条明细!D:D,C51),0) -> 23 | E51: 65 | F51: =IFERROR(SUMIFS(存条明细!G:G,存条明细!C:C,B51,存条明细!D:D,C51),0) -> 1495 | G51: =IFERROR(SUMIFS(出库明细!E:E,出库明细!C:C,B51,出库明细!D:D,C51),0) -> 59 | H51: =IFERROR(SUMIFS(出库明细!G:G,出库明细!C:C,B51,出库明细!D:D,C51),0) -> 3770 | I51: =IFERROR(D51-G51,0) -> -36 | J51: =IFERROR(F51-H51,0) -> -2275 | K51: =TODAY() -> 46289
A52: 50 | B52: 兴隆隆兴商行 | C52: 大咖 | D52: =IFERROR(SUMIFS(存条明细!E:E,存条明细!C:C,B52,存条明细!D:D,C52),0) -> 68 | E52: 83 | F52: =IFERROR(SUMIFS(存条明细!G:G,存条明细!C:C,B52,存条明细!D:D,C52),0) -> 5644 | G52: =IFERROR(SUMIFS(出库明细!E:E,出库明细!C:C,B52,出库明细!D:D,C52),0) -> 10 | H52: =IFERROR(SUMIFS(出库明细!G:G,出库明细!C:C,B52,出库明细!D:D,C52),0) -> 830 | I52: =IFERROR(D52-G52,0) -> 58 | J52: =IFERROR(F52-H52,0) -> 4814 | K52: =TODAY() -> 46289
A53: 51 | B53: 兴隆隆兴商行 | C53: 港式奶茶 | D53: =IFERROR(SUMIFS(存条明细!E:E,存条明细!C:C,B53,存条明细!D:D,C53),0) -> 11 | E53: 69 | F53: =IFERROR(SUMIFS(存条明细!G:G,存条明细!C:C,B53,存条明细!D:D,C53),0) -> 759 | G53: =IFERROR(SUMIFS(出库明细!E:E,出库明细!C:C,B53,出库明细!D:D,C53),0) -> 0 | H53: =IFERROR(SUMIFS(出库明细!G:G,出库明细!C:C,B53,出库明细!D:D,C53),0) -> 0 | I53: =IFERROR(D53-G53,0) -> 11 | J53: =IFERROR(F53-H53,0) -> 759 | K53: =TODAY() -> 46289
A54: 52 | B54: 诚信粮油 | C54: 大东鹏 | D54: 300 | E54: 90 | F54: =IFERROR(SUMIFS(存条明细!G:G,存条明细!C:C,B54,存条明细!D:D,C54),0) -> 27000 | G54: =IFERROR(SUMIFS(出库明细!E:E,出库明细!C:C,B54,出库明细!D:D,C54),0) -> 300 | H54: =IFERROR(SUMIFS(出库明细!G:G,出库明细!C:C,B54,出库明细!D:D,C54),0) -> 27000 | I54: =IFERROR(D54-G54,0) -> 0 | J54: =IFERROR(F54-H54,0) -> 0 | K54: =TODAY() -> 46289
A55: 53 | B55: 吕维春 | C55: 大东鹏 | D55: 250 | E55: 90 | F55: =IFERROR(SUMIFS(存条明细!G:G,存条明细!C:C,B55,存条明细!D:D,C55),0) -> 22500 | G55: =IFERROR(SUMIFS(出库明细!E:E,出库明细!C:C,B55,出库明细!D:D,C55),0) -> 130 | H55: =IFERROR(SUMIFS(出库明细!G:G,出库明细!C:C,B55,出库明细!D:D,C55),0) -> 11700 | I55: =IFERROR(D55-G55,0) -> 120 | J55: =IFERROR(F55-H55,0) -> 10800 | K55: =TODAY() -> 46289
A56: 54 | B56: 吕维春 | C56: 1L补水 | D56: 150 | E56: 55 | F56: =IFERROR(SUMIFS(存条明细!G:G,存条明细!C:C,B56,存条明细!D:D,C56),0) -> 8250 | G56: =IFERROR(SUMIFS(出库明细!E:E,出库明细!C:C,B56,出库明细!D:D,C56),0) -> 0 | H56: =IFERROR(SUMIFS(出库明细!G:G,出库明细!C:C,B56,出库明细!D:D,C56),0) -> 0 | I56: =IFERROR(D56-G56,0) -> 150 | J56: =IFERROR(F56-H56,0) -> 8250 | K56: =TODAY() -> 46289
A57: 55 | B57: 吕维春 | C57: 1L果之茶 | D57: 20 | E57: 43 | F57: =IFERROR(SUMIFS(存条明细!G:G,存条明细!C:C,B57,存条明细!D:D,C57),0) -> 860 | G57: =IFERROR(SUMIFS(出库明细!E:E,出库明细!C:C,B57,出库明细!D:D,C57),0) -> 0 | H57: =IFERROR(SUMIFS(出库明细!G:G,出库明细!C:C,B57,出库明细!D:D,C57),0) -> 0 | I57: =IFERROR(D57-G57,0) -> 20 | J57: =IFERROR(F57-H57,0) -> 860 | K57: =TODAY() -> 46289
A58: 56 | B58: 吕维春 | C58: 大咖 | D58: 10 | E58: 83 | F58: =IFERROR(SUMIFS(存条明细!G:G,存条明细!C:C,B58,存条明细!D:D,C58),0) -> 830 | G58: =IFERROR(SUMIFS(出库明细!E:E,出库明细!C:C,B58,出库明细!D:D,C58),0) -> 0 | H58: =IFERROR(SUMIFS(出库明细!G:G,出库明细!C:C,B58,出库明细!D:D,C58),0) -> 0 | I58: =IFERROR(D58-G58,0) -> 10 | J58: =IFERROR(F58-H58,0) -> 830 | K58: =TODAY() -> 46289
A59: 57 | B59: 兴发商行 | C59: 大东鹏 | D59: 170 | E59: 90 | F59: =IFERROR(SUMIFS(存条明细!G:G,存条明细!C:C,B59,存条明细!D:D,C59),0) -> 15300 | G59: =IFERROR(SUMIFS(出库明细!E:E,出库明细!C:C,B59,出库明细!D:D,C59),0) -> 90 | H59: =IFERROR(SUMIFS(出库明细!G:G,出库明细!C:C,B59,出库明细!D:D,C59),0) -> 8100 | I59: =IFERROR(D59-G59,0) -> 80 | J59: =IFERROR(F59-H59,0) -> 7200 | K59: =TODAY() -> 46289
A60: 58 | B60: 城岗日日升超市 | C60: 大东鹏 | D60: =IFERROR(SUMIFS(存条明细!E:E,存条明细!C:C,B60,存条明细!D:D,C60),0) -> 464 | E60: 90 | F60: =IFERROR(SUMIFS(存条明细!G:G,存条明细!C:C,B60,存条明细!D:D,C60),0) -> 41760 | G60: =IFERROR(SUMIFS(出库明细!E:E,出库明细!C:C,B60,出库明细!D:D,C60),0) -> 364 | H60: =IFERROR(SUMIFS(出库明细!G:G,出库明细!C:C,B60,出库明细!D:D,C60),0) -> 32760 | I60: =IFERROR(D60-G60,0) -> 100 | J60: =IFERROR(F60-H60,0) -> 9000 | K60: =TODAY() -> 46289
...

Sheet 客户查询
A1: 客户快速查询
A2: 💡 在黄色格子输入客户名称，自动显示该客户的所有库存和货款情况
A4: 🔍 请输入客户名称： | B4: 星海超市
A6: 💰 货款汇总
A7: 初始存条金额 | B7: 已领用金额 | C7: 剩余存条金额 | D7: 已付款金额 | E7: 未付货款 | F7: 状态
A8: =IFERROR(VLOOKUP($B$4,总览汇总!$B$5:$H$154,2,FALSE),"") -> 39547 | B8: =IFERROR(VLOOKUP($B$4,总览汇总!$B$5:$H$154,3,FALSE),"") -> 77322 | C8: =IFERROR(VLOOKUP($B$4,总览汇总!$B$5:$H$154,4,FALSE),"") -> -37775 | D8: =IFERROR(VLOOKUP($B$4,总览汇总!$B$5:$H$154,5,FALSE),"") -> 148067 | E8: =IFERROR(VLOOKUP($B$4,总览汇总!$B$5:$H$154,6,FALSE),"") -> -70745 | F8: =IFERROR(VLOOKUP($B$4,总览汇总!$B$5:$H$154,7,FALSE),"") -> 预存款
A10: 📦 商品库存明细
A11: 商品品类 | B11: 初始数量 | C11: 初始金额 | D11: 已领用数量 | E11: 已领用金额 | F11: 剩余数量 | G11: 剩余金额
A12: =IFERROR(INDEX(商品库存!$C$4:$C$297,SMALL(IF(商品库存!$B$4:$B$297=$B$4,ROW(商品库存!$B$4:$B$297)-3,999),1)),"") | B12: =IF(A12<>"",VLOOKUP(A12,IF(商品库存!$B$4:$B$297=$B$4,商品库存!$C$4:$D$297),2,FALSE),"") | C12: =IF(A12<>"",VLOOKUP(A12,IF(商品库存!$B$4:$B$297=$B$4,商品库存!$C$4:$F$297),4,FALSE),"") | D12: =IF(A12<>"",VLOOKUP(A12,IF(商品库存!$B$4:$B$297=$B$4,商品库存!$C$4:$G$297),5,FALSE),"") | E12: =IF(A12<>"",VLOOKUP(A12,IF(商品库存!$B$4:$B$297=$B$4,商品库存!$C$4:$H$297),6,FALSE),"") | F12: =IF(A12<>"",VLOOKUP(A12,IF(商品库存!$B$4:$B$297=$B$4,商品库存!$C$4:$I$297),7,FALSE),"") | G12: =IF(A12<>"",VLOOKUP(A12,IF(商品库存!$B$4:$B$297=$B$4,商品库存!$C$4:$J$297),8,FALSE),"")
A13: =IFERROR(INDEX(商品库存!$C$4:$C$297,SMALL(IF(商品库存!$B$4:$B$297=$B$4,ROW(商品库存!$B$4:$B$297)-3,999),2)),"") | B13: =IF(A13<>"",VLOOKUP(A13,IF(商品库存!$B$4:$B$297=$B$4,商品库存!$C$4:$D$297),2,FALSE),"") | C13: =IF(A13<>"",VLOOKUP(A13,IF(商品库存!$B$4:$B$297=$B$4,商品库存!$C$4:$F$297),4,FALSE),"") | D13: =IF(A13<>"",VLOOKUP(A13,IF(商品库存!$B$4:$B$297=$B$4,商品库存!$C$4:$G$297),5,FALSE),"") | E13: =IF(A13<>"",VLOOKUP(A13,IF(商品库存!$B$4:$B$297=$B$4,商品库存!$C$4:$H$297),6,FALSE),"") | F13: =IF(A13<>"",VLOOKUP(A13,IF(商品库存!$B$4:$B$297=$B$4,商品库存!$C$4:$I$297),7,FALSE),"") | G13: =IF(A13<>"",VLOOKUP(A13,IF(商品库存!$B$4:$B$297=$B$4,商品库存!$C$4:$J$297),8,FALSE),"")
A14: =IFERROR(INDEX(商品库存!$C$4:$C$297,SMALL(IF(商品库存!$B$4:$B$297=$B$4,ROW(商品库存!$B$4:$B$297)-3,999),3)),"") | B14: =IF(A14<>"",VLOOKUP(A14,IF(商品库存!$B$4:$B$297=$B$4,商品库存!$C$4:$D$297),2,FALSE),"") | C14: =IF(A14<>"",VLOOKUP(A14,IF(商品库存!$B$4:$B$297=$B$4,商品库存!$C$4:$F$297),4,FALSE),"") | D14: =IF(A14<>"",VLOOKUP(A14,IF(商品库存!$B$4:$B$297=$B$4,商品库存!$C$4:$G$297),5,FALSE),"") | E14: =IF(A14<>"",VLOOKUP(A14,IF(商品库存!$B$4:$B$297=$B$4,商品库存!$C$4:$H$297),6,FALSE),"") | F14: =IF(A14<>"",VLOOKUP(A14,IF(商品库存!$B$4:$B$297=$B$4,商品库存!$C$4:$I$297),7,FALSE),"") | G14: =IF(A14<>"",VLOOKUP(A14,IF(商品库存!$B$4:$B$297=$B$4,商品库存!$C$4:$J$297),8,FALSE),"")
A15: =IFERROR(INDEX(商品库存!$C$4:$C$297,SMALL(IF(商品库存!$B$4:$B$297=$B$4,ROW(商品库存!$B$4:$B$297)-3,999),4)),"") | B15: =IF(A15<>"",VLOOKUP(A15,IF(商品库存!$B$4:$B$297=$B$4,商品库存!$C$4:$D$297),2,FALSE),"") | C15: =IF(A15<>"",VLOOKUP(A15,IF(商品库存!$B$4:$B$297=$B$4,商品库存!$C$4:$F$297),4,FALSE),"") | D15: =IF(A15<>"",VLOOKUP(A15,IF(商品库存!$B$4:$B$297=$B$4,商品库存!$C$4:$G$297),5,FALSE),"") | E15: =IF(A15<>"",VLOOKUP(A15,IF(商品库存!$B$4:$B$297=$B$4,商品库存!$C$4:$H$297),6,FALSE),"") | F15: =IF(A15<>"",VLOOKUP(A15,IF(商品库存!$B$4:$B$297=$B$4,商品库存!$C$4:$I$297),7,FALSE),"") | G15: =IF(A15<>"",VLOOKUP(A15,IF(商品库存!$B$4:$B$297=$B$4,商品库存!$C$4:$J$297),8,FALSE),"")
A16: =IFERROR(INDEX(商品库存!$C$4:$C$297,SMALL(IF(商品库存!$B$4:$B$297=$B$4,ROW(商品库存!$B$4:$B$297)-3,999),5)),"") | B16: =IF(A16<>"",VLOOKUP(A16,IF(商品库存!$B$4:$B$297=$B$4,商品库存!$C$4:$D$297),2,FALSE),"") | C16: =IF(A16<>"",VLOOKUP(A16,IF(商品库存!$B$4:$B$297=$B$4,商品库存!$C$4:$F$297),4,FALSE),"") | D16: =IF(A16<>"",VLOOKUP(A16,IF(商品库存!$B$4:$B$297=$B$4,商品库存!$C$4:$G$297),5,FALSE),"") | E16: =IF(A16<>"",VLOOKUP(A16,IF(商品库存!$B$4:$B$297=$B$4,商品库存!$C$4:$H$297),6,FALSE),"") | F16: =IF(A16<>"",VLOOKUP(A16,IF(商品库存!$B$4:$B$297=$B$4,商品库存!$C$4:$I$297),7,FALSE),"") | G16: =IF(A16<>"",VLOOKUP(A16,IF(商品库存!$B$4:$B$297=$B$4,商品库存!$C$4:$J$297),8,FALSE),"")
A17: =IFERROR(INDEX(商品库存!$C$4:$C$297,SMALL(IF(商品库存!$B$4:$B$297=$B$4,ROW(商品库存!$B$4:$B$297)-3,999),6)),"") | B17: =IF(A17<>"",VLOOKUP(A17,IF(商品库存!$B$4:$B$297=$B$4,商品库存!$C$4:$D$297),2,FALSE),"") | C17: =IF(A17<>"",VLOOKUP(A17,IF(商品库存!$B$4:$B$297=$B$4,商品库存!$C$4:$F$297),4,FALSE),"") | D17: =IF(A17<>"",VLOOKUP(A17,IF(商品库存!$B$4:$B$297=$B$4,商品库存!$C$4:$G$297),5,FALSE),"") | E17: =IF(A17<>"",VLOOKUP(A17,IF(商品库存!$B$4:$B$297=$B$4,商品库存!$C$4:$H$297),6,FALSE),"") | F17: =IF(A17<>"",VLOOKUP(A17,IF(商品库存!$B$4:$B$297=$B$4,商品库存!$C$4:$I$297),7,FALSE),"") | G17: =IF(A17<>"",VLOOKUP(A17,IF(商品库存!$B$4:$B$297=$B$4,商品库存!$C$4:$J$297),8,FALSE),"")
A18: =IFERROR(INDEX(商品库存!$C$4:$C$297,SMALL(IF(商品库存!$B$4:$B$297=$B$4,ROW(商品库存!$B$4:$B$297)-3,999),7)),"") | B18: =IF(A18<>"",VLOOKUP(A18,IF(商品库存!$B$4:$B$297=$B$4,商品库存!$C$4:$D$297),2,FALSE),"") | C18: =IF(A18<>"",VLOOKUP(A18,IF(商品库存!$B$4:$B$297=$B$4,商品库存!$C$4:$F$297),4,FALSE),"") | D18: =IF(A18<>"",VLOOKUP(A18,IF(商品库存!$B$4:$B$297=$B$4,商品库存!$C$4:$G$297),5,FALSE),"") | E18: =IF(A18<>"",VLOOKUP(A18,IF(商品库存!$B$4:$B$297=$B$4,商品库存!$C$4:$H$297),6,FALSE),"") | F18: =IF(A18<>"",VLOOKUP(A18,IF(商品库存!$B$4:$B$297=$B$4,商品库存!$C$4:$I$297),7,FALSE),"") | G18: =IF(A18<>"",VLOOKUP(A18,IF(商品库存!$B$4:$B$297=$B$4,商品库存!$C$4:$J$297),8,FALSE),"")
A19: =IFERROR(INDEX(商品库存!$C$4:$C$297,SMALL(IF(商品库存!$B$4:$B$297=$B$4,ROW(商品库存!$B$4:$B$297)-3,999),8)),"") | B19: =IF(A19<>"",VLOOKUP(A19,IF(商品库存!$B$4:$B$297=$B$4,商品库存!$C$4:$D$297),2,FALSE),"") | C19: =IF(A19<>"",VLOOKUP(A19,IF(商品库存!$B$4:$B$297=$B$4,商品库存!$C$4:$F$297),4,FALSE),"") | D19: =IF(A19<>"",VLOOKUP(A19,IF(商品库存!$B$4:$B$297=$B$4,商品库存!$C$4:$G$297),5,FALSE),"") | E19: =IF(A19<>"",VLOOKUP(A19,IF(商品库存!$B$4:$B$297=$B$4,商品库存!$C$4:$H$297),6,FALSE),"") | F19: =IF(A19<>"",VLOOKUP(A19,IF(商品库存!$B$4:$B$297=$B$4,商品库存!$C$4:$I$297),7,FALSE),"") | G19: =IF(A19<>"",VLOOKUP(A19,IF(商品库存!$B$4:$B$297=$B$4,商品库存!$C$4:$J$297),8,FALSE),"")
A20: =IFERROR(INDEX(商品库存!$C$4:$C$297,SMALL(IF(商品库存!$B$4:$B$297=$B$4,ROW(商品库存!$B$4:$B$297)-3,999),9)),"") | B20: =IF(A20<>"",VLOOKUP(A20,IF(商品库存!$B$4:$B$297=$B$4,商品库存!$C$4:$D$297),2,FALSE),"") | C20: =IF(A20<>"",VLOOKUP(A20,IF(商品库存!$B$4:$B$297=$B$4,商品库存!$C$4:$F$297),4,FALSE),"") | D20: =IF(A20<>"",VLOOKUP(A20,IF(商品库存!$B$4:$B$297=$B$4,商品库存!$C$4:$G$297),5,FALSE),"") | E20: =IF(A20<>"",VLOOKUP(A20,IF(商品库存!$B$4:$B$297=$B$4,商品库存!$C$4:$H$297),6,FALSE),"") | F20: =IF(A20<>"",VLOOKUP(A20,IF(商品库存!$B$4:$B$297=$B$4,商品库存!$C$4:$I$297),7,FALSE),"") | G20: =IF(A20<>"",VLOOKUP(A20,IF(商品库存!$B$4:$B$297=$B$4,商品库存!$C$4:$J$297),8,FALSE),"")
A21: =IFERROR(INDEX(商品库存!$C$4:$C$297,SMALL(IF(商品库存!$B$4:$B$297=$B$4,ROW(商品库存!$B$4:$B$297)-3,999),10)),"") | B21: =IF(A21<>"",VLOOKUP(A21,IF(商品库存!$B$4:$B$297=$B$4,商品库存!$C$4:$D$297),2,FALSE),"") | C21: =IF(A21<>"",VLOOKUP(A21,IF(商品库存!$B$4:$B$297=$B$4,商品库存!$C$4:$F$297),4,FALSE),"") | D21: =IF(A21<>"",VLOOKUP(A21,IF(商品库存!$B$4:$B$297=$B$4,商品库存!$C$4:$G$297),5,FALSE),"") | E21: =IF(A21<>"",VLOOKUP(A21,IF(商品库存!$B$4:$B$297=$B$4,商品库存!$C$4:$H$297),6,FALSE),"") | F21: =IF(A21<>"",VLOOKUP(A21,IF(商品库存!$B$4:$B$297=$B$4,商品库存!$C$4:$I$297),7,FALSE),"") | G21: =IF(A21<>"",VLOOKUP(A21,IF(商品库存!$B$4:$B$297=$B$4,商品库存!$C$4:$J$297),8,FALSE),"")
A22: =IFERROR(INDEX(商品库存!$C$4:$C$297,SMALL(IF(商品库存!$B$4:$B$297=$B$4,ROW(商品库存!$B$4:$B$297)-3,999),11)),"") | B22: =IF(A22<>"",VLOOKUP(A22,IF(商品库存!$B$4:$B$297=$B$4,商品库存!$C$4:$D$297),2,FALSE),"") | C22: =IF(A22<>"",VLOOKUP(A22,IF(商品库存!$B$4:$B$297=$B$4,商品库存!$C$4:$F$297),4,FALSE),"") | D22: =IF(A22<>"",VLOOKUP(A22,IF(商品库存!$B$4:$B$297=$B$4,商品库存!$C$4:$G$297),5,FALSE),"") | E22: =IF(A22<>"",VLOOKUP(A22,IF(商品库存!$B$4:$B$297=$B$4,商品库存!$C$4:$H$297),6,FALSE),"") | F22: =IF(A22<>"",VLOOKUP(A22,IF(商品库存!$B$4:$B$297=$B$4,商品库存!$C$4:$I$297),7,FALSE),"") | G22: =IF(A22<>"",VLOOKUP(A22,IF(商品库存!$B$4:$B$297=$B$4,商品库存!$C$4:$J$297),8,FALSE),"")
A23: =IFERROR(INDEX(商品库存!$C$4:$C$297,SMALL(IF(商品库存!$B$4:$B$297=$B$4,ROW(商品库存!$B$4:$B$297)-3,999),12)),"") | B23: =IF(A23<>"",VLOOKUP(A23,IF(商品库存!$B$4:$B$297=$B$4,商品库存!$C$4:$D$297),2,FALSE),"") | C23: =IF(A23<>"",VLOOKUP(A23,IF(商品库存!$B$4:$B$297=$B$4,商品库存!$C$4:$F$297),4,FALSE),"") | D23: =IF(A23<>"",VLOOKUP(A23,IF(商品库存!$B$4:$B$297=$B$4,商品库存!$C$4:$G$297),5,FALSE),"") | E23: =IF(A23<>"",VLOOKUP(A23,IF(商品库存!$B$4:$B$297=$B$4,商品库存!$C$4:$H$297),6,FALSE),"") | F23: =IF(A23<>"",VLOOKUP(A23,IF(商品库存!$B$4:$B$297=$B$4,商品库存!$C$4:$I$297),7,FALSE),"") | G23: =IF(A23<>"",VLOOKUP(A23,IF(商品库存!$B$4:$B$297=$B$4,商品库存!$C$4:$J$297),8,FALSE),"")
A24: =IFERROR(INDEX(商品库存!$C$4:$C$297,SMALL(IF(商品库存!$B$4:$B$297=$B$4,ROW(商品库存!$B$4:$B$297)-3,999),13)),"") | B24: =IF(A24<>"",VLOOKUP(A24,IF(商品库存!$B$4:$B$297=$B$4,商品库存!$C$4:$D$297),2,FALSE),"") | C24: =IF(A24<>"",VLOOKUP(A24,IF(商品库存!$B$4:$B$297=$B$4,商品库存!$C$4:$F$297),4,FALSE),"") | D24: =IF(A24<>"",VLOOKUP(A24,IF(商品库存!$B$4:$B$297=$B$4,商品库存!$C$4:$G$297),5,FALSE),"") | E24: =IF(A24<>"",VLOOKUP(A24,IF(商品库存!$B$4:$B$297=$B$4,商品库存!$C$4:$H$297),6,FALSE),"") | F24: =IF(A24<>"",VLOOKUP(A24,IF(商品库存!$B$4:$B$297=$B$4,商品库存!$C$4:$I$297),7,FALSE),"") | G24: =IF(A24<>"",VLOOKUP(A24,IF(商品库存!$B$4:$B$297=$B$4,商品库存!$C$4:$J$297),8,FALSE),"")
A25: =IFERROR(INDEX(商品库存!$C$4:$C$297,SMALL(IF(商品库存!$B$4:$B$297=$B$4,ROW(商品库存!$B$4:$B$297)-3,999),14)),"") | B25: =IF(A25<>"",VLOOKUP(A25,IF(商品库存!$B$4:$B$297=$B$4,商品库存!$C$4:$D$297),2,FALSE),"") | C25: =IF(A25<>"",VLOOKUP(A25,IF(商品库存!$B$4:$B$297=$B$4,商品库存!$C$4:$F$297),4,FALSE),"") | D25: =IF(A25<>"",VLOOKUP(A25,IF(商品库存!$B$4:$B$297=$B$4,商品库存!$C$4:$G$297),5,FALSE),"") | E25: =IF(A25<>"",VLOOKUP(A25,IF(商品库存!$B$4:$B$297=$B$4,商品库存!$C$4:$H$297),6,FALSE),"") | F25: =IF(A25<>"",VLOOKUP(A25,IF(商品库存!$B$4:$B$297=$B$4,商品库存!$C$4:$I$297),7,FALSE),"") | G25: =IF(A25<>"",VLOOKUP(A25,IF(商品库存!$B$4:$B$297=$B$4,商品库存!$C$4:$J$297),8,FALSE),"")
A26: =IFERROR(INDEX(商品库存!$C$4:$C$297,SMALL(IF(商品库存!$B$4:$B$297=$B$4,ROW(商品库存!$B$4:$B$297)-3,999),15)),"") | B26: =IF(A26<>"",VLOOKUP(A26,IF(商品库存!$B$4:$B$297=$B$4,商品库存!$C$4:$D$297),2,FALSE),"") | C26: =IF(A26<>"",VLOOKUP(A26,IF(商品库存!$B$4:$B$297=$B$4,商品库存!$C$4:$F$297),4,FALSE),"") | D26: =IF(A26<>"",VLOOKUP(A26,IF(商品库存!$B$4:$B$297=$B$4,商品库存!$C$4:$G$297),5,FALSE),"") | E26: =IF(A26<>"",VLOOKUP(A26,IF(商品库存!$B$4:$B$297=$B$4,商品库存!$C$4:$H$297),6,FALSE),"") | F26: =IF(A26<>"",VLOOKUP(A26,IF(商品库存!$B$4:$B$297=$B$4,商品库存!$C$4:$I$297),7,FALSE),"") | G26: =IF(A26<>"",VLOOKUP(A26,IF(商品库存!$B$4:$B$297=$B$4,商品库存!$C$4:$J$297),8,FALSE),"")

Sheet Sheet1
A1: =4200+1000+620+760+325+21+55 -> 6981
