Workbook

Sheet 首页
A1: A076 拼多多电脑电商财务帐套 · 首页（报表本）
A2: 录入本连接： | B2: =IF(ISERROR(COUNTIF('[1]基础资料'!$A$4:$A$5,"?*")),"请先打开 A076-1_录入本.xlsx，再在这本按 F9／更新","录入本已连上（数取自 A076-1_录入本.xlsx）") -> 录入本已连上（数取自 A076-1_录入本.xlsx）
A3: 用法：先开录入本（记账、粘管家婆和拼多多导出都在那本），再开这本看报表。两本放同一个文件夹，文件名别改。下面年份、月份可以改（淡黄格）。
A4: 年份 | B4: 2026 | D4: 月份（本月） | E4: 9
A6: 资金账户 | B6: 当前余额 | D6: 本月（见上面月份） | E6: 金额
A7: =IF('[1]基础资料'!$A$5="","",'[1]基础资料'!$A$5) -> 招商银行 | B7: =IF(A7="","",'[1]基础资料'!$D$5) -> 100000 | D7: 资金台帐收入（不含内部转账） | E7: =SUMIFS('[1]资金台帐'!$G$4:$G$3003,'[1]资金台帐'!$N$4:$N$3003,'首页'!$B$4*100+'首页'!$E$4,'[1]资金台帐'!$M$4:$M$3003,"<>内部转账") -> 0
A8: =IF('[1]基础资料'!$A$6="","",'[1]基础资料'!$A$6) -> 微信 | B8: =IF(A8="","",'[1]基础资料'!$D$6) -> 0 | D8: 资金台帐支出（不含内部转账） | E8: =SUMIFS('[1]资金台帐'!$H$4:$H$3003,'[1]资金台帐'!$N$4:$N$3003,'首页'!$B$4*100+'首页'!$E$4,'[1]资金台帐'!$M$4:$M$3003,"<>内部转账") -> 0
A9: =IF('[1]基础资料'!$A$7="","",'[1]基础资料'!$A$7) -> 支付宝 | B9: =IF(A9="","",'[1]基础资料'!$D$7) -> 0 | D9: 销售收入（管家婆） | E9: =INDEX('利润表'!$C$7:$N$7,'首页'!$E$4) -> 2807123
A10: =IF('[1]基础资料'!$A$8="","",'[1]基础资料'!$A$8) -> 拼多多店铺余额 | B10: =IF(A10="","",'[1]基础资料'!$D$8) -> 61390.86 | C10: 含平台账务明细 | D10: 销售成本 | E10: =INDEX('利润表'!$C$8:$N$8,'首页'!$E$4) -> 2698448.2
A11: =IF('[1]基础资料'!$A$9="","",'[1]基础资料'!$A$9) | B11: =IF(A11="","",'[1]基础资料'!$D$9) | D11: 毛利 | E11: =INDEX('利润表'!$C$9:$N$9,'首页'!$E$4) -> 108674.77
A12: =IF('[1]基础资料'!$A$10="","",'[1]基础资料'!$A$10) | B12: =IF(A12="","",'[1]基础资料'!$D$10) | D12: 净利润（简易） | E12: =INDEX('利润表'!$C$17:$N$17,'首页'!$E$4) -> 114126.63
A13: 合计 | B13: =SUM(B7:B12) -> 161390.86
A15: 拼多多对账提示 | B15: 笔数／单数 | C15: 金额 | D15: 看哪里／怎么处理
A16: 本月店铺净额 跟账务明细「#总计」差 | C16: =INDEX('拼多多对账'!$C$24:$N$24,'首页'!$E$4) -> 0 | D16: 拼多多对账「一」；应为 0
A17: 本月月末店铺余额（期初＋净额） | C17: =INDEX('拼多多对账'!$C$26:$N$26,'首页'!$E$4) -> 61390.86 | D17: 期初在录入本基础资料第 8 行
A18: 本月提现没记进资金台帐的差额 | C18: =INDEX('拼多多对账'!$C$28:$N$28,'首页'!$E$4) -> 0 | D18: 应为 0；提现在资金台帐记内部转账
A19: 到账批次：对账单里没有明细的 | B19: =COUNTIF('拼多多对账'!$J$32:$J$91,"对账单里没有*") -> 6 | C19: =SUMIFS('拼多多对账'!$E$32:$E$91,'拼多多对账'!$J$32:$J$91,"对账单里没有*") -> 3991.59 | D19: 按批次号去后台下载这几批的对账单明细，粘进录入本
A20: 对账单批次：账务明细还没到账的 | B20: =COUNTIF('拼多多对账'!$I$95:$I$134,"账务明细里还没到账*") -> 3 | C20: =SUMIFS('拼多多对账'!$F$95:$F$134,'拼多多对账'!$I$95:$I$134,"账务明细里还没到账*") -> 1320 | D20: 看结算时间，粘那个月的账务明细再看
A21: 营销活动逐单不一致 | B21: ='拼多多对账'!$I$138 -> 0 | D21: 拼多多对账「三」
A22: 百亿补贴技术服务费 扣了还没返 | B22: ='技术服务费核对'!$H$10 -> 40 | C22: ='技术服务费核对'!$H$11 -> 2183.3 | D22: 技术服务费核对「三」；超过 30 天没返问客服
A23: 返还账单里在账务明细找不到这单 | B23: ='技术服务费核对'!$C$10 -> 64 | C23: ='技术服务费核对'!$C$11 -> 4637.2 | D23: 扣费在更早月份，把那个月账务明细也粘上
A24: 返了又扣回（-t01） | B24: ='技术服务费核对'!$C$7 -> 1 | C24: ='技术服务费核对'!$C$8 -> -50.39 | D24: 技术服务费核对「二」，问客服扣回原因
A27: 跳转
A28: → 拼多多对账 | D28: → 打开录入本 A076-1_录入本.xlsx（同一文件夹）
A29: → 技术服务费核对
A30: → 库存
A31: → 往来
A32: → 费用统计
A33: → 利润表
A34: → 使用说明

Sheet 拼多多对账
A1: A076 拼多多对账（店铺余额·批次·营销活动）
A2: 怎么核才准：① 先看「一」每月净额跟账务明细最后一行「#总计」对上没有；② 补贴汇入、技术服务费返还在账务明细里只有一笔总数，备注里有批次号——拿批次号去对账单里找同批次的明细，合计要等于到账金额（「二」）；③ 营销活动逐单：应结＝报名价－活动价＋补贴券（「三」）；④ 技术服务费逐单在「技术服务费核对」表。对账单是按结算时间出的，账务明细是按到账月份出的，月份不一样就会「对不上」，要按批次号对。
A4: 一、按月店铺余额（年份见首页；单位：元，收入正、支出负）
A5: 账务类型 | B5: 利润表归类 | C5: 1 | D5: 2 | E5: 3 | F5: 4 | G5: 5 | H5: 6 | I5: 7 | J5: 8 | K5: 9 | L5: 10 | M5: 11 | N5: 12 | O5: 全年合计
A6: =IF('[1]基础资料'!$B$47="","",'[1]基础资料'!$B$47) -> 订单收入 | B6: =IF(A6="","",'[1]基础资料'!$C$47) -> 店铺回款 | C6: =IF($A6="",0,SUMIFS('[1]粘贴_账务明细'!$K$4:$K$3003,'[1]粘贴_账务明细'!$L$4:$L$3003,$A6,'[1]粘贴_账务明细'!$I$4:$I$3003,'首页'!$B$4*100+C$5)) -> 0 | D6: =IF($A6="",0,SUMIFS('[1]粘贴_账务明细'!$K$4:$K$3003,'[1]粘贴_账务明细'!$L$4:$L$3003,$A6,'[1]粘贴_账务明细'!$I$4:$I$3003,'首页'!$B$4*100+D$5)) -> 0 | E6: =IF($A6="",0,SUMIFS('[1]粘贴_账务明细'!$K$4:$K$3003,'[1]粘贴_账务明细'!$L$4:$L$3003,$A6,'[1]粘贴_账务明细'!$I$4:$I$3003,'首页'!$B$4*100+E$5)) -> 0 | F6: =IF($A6="",0,SUMIFS('[1]粘贴_账务明细'!$K$4:$K$3003,'[1]粘贴_账务明细'!$L$4:$L$3003,$A6,'[1]粘贴_账务明细'!$I$4:$I$3003,'首页'!$B$4*100+F$5)) -> 0 | G6: =IF($A6="",0,SUMIFS('[1]粘贴_账务明细'!$K$4:$K$3003,'[1]粘贴_账务明细'!$L$4:$L$3003,$A6,'[1]粘贴_账务明细'!$I$4:$I$3003,'首页'!$B$4*100+G$5)) -> 0 | H6: =IF($A6="",0,SUMIFS('[1]粘贴_账务明细'!$K$4:$K$3003,'[1]粘贴_账务明细'!$L$4:$L$3003,$A6,'[1]粘贴_账务明细'!$I$4:$I$3003,'首页'!$B$4*100+H$5)) -> 0 | I6: =IF($A6="",0,SUMIFS('[1]粘贴_账务明细'!$K$4:$K$3003,'[1]粘贴_账务明细'!$L$4:$L$3003,$A6,'[1]粘贴_账务明细'!$I$4:$I$3003,'首页'!$B$4*100+I$5)) -> 0 | J6: =IF($A6="",0,SUMIFS('[1]粘贴_账务明细'!$K$4:$K$3003,'[1]粘贴_账务明细'!$L$4:$L$3003,$A6,'[1]粘贴_账务明细'!$I$4:$I$3003,'首页'!$B$4*100+J$5)) -> 0 | ... N6: =IF($A6="",0,SUMIFS('[1]粘贴_账务明细'!$K$4:$K$3003,'[1]粘贴_账务明细'!$L$4:$L$3003,$A6,'[1]粘贴_账务明细'!$I$4:$I$3003,'首页'!$B$4*100+N$5)) -> 0 | O6: =SUM(C6:N6) -> 303943
A7: =IF('[1]基础资料'!$B$48="","",'[1]基础资料'!$B$48) -> 优惠券结算 | B7: =IF(A7="","",'[1]基础资料'!$C$48) -> 店铺回款 | C7: =IF($A7="",0,SUMIFS('[1]粘贴_账务明细'!$K$4:$K$3003,'[1]粘贴_账务明细'!$L$4:$L$3003,$A7,'[1]粘贴_账务明细'!$I$4:$I$3003,'首页'!$B$4*100+C$5)) -> 0 | D7: =IF($A7="",0,SUMIFS('[1]粘贴_账务明细'!$K$4:$K$3003,'[1]粘贴_账务明细'!$L$4:$L$3003,$A7,'[1]粘贴_账务明细'!$I$4:$I$3003,'首页'!$B$4*100+D$5)) -> 0 | E7: =IF($A7="",0,SUMIFS('[1]粘贴_账务明细'!$K$4:$K$3003,'[1]粘贴_账务明细'!$L$4:$L$3003,$A7,'[1]粘贴_账务明细'!$I$4:$I$3003,'首页'!$B$4*100+E$5)) -> 0 | F7: =IF($A7="",0,SUMIFS('[1]粘贴_账务明细'!$K$4:$K$3003,'[1]粘贴_账务明细'!$L$4:$L$3003,$A7,'[1]粘贴_账务明细'!$I$4:$I$3003,'首页'!$B$4*100+F$5)) -> 0 | G7: =IF($A7="",0,SUMIFS('[1]粘贴_账务明细'!$K$4:$K$3003,'[1]粘贴_账务明细'!$L$4:$L$3003,$A7,'[1]粘贴_账务明细'!$I$4:$I$3003,'首页'!$B$4*100+G$5)) -> 0 | H7: =IF($A7="",0,SUMIFS('[1]粘贴_账务明细'!$K$4:$K$3003,'[1]粘贴_账务明细'!$L$4:$L$3003,$A7,'[1]粘贴_账务明细'!$I$4:$I$3003,'首页'!$B$4*100+H$5)) -> 0 | I7: =IF($A7="",0,SUMIFS('[1]粘贴_账务明细'!$K$4:$K$3003,'[1]粘贴_账务明细'!$L$4:$L$3003,$A7,'[1]粘贴_账务明细'!$I$4:$I$3003,'首页'!$B$4*100+I$5)) -> 0 | J7: =IF($A7="",0,SUMIFS('[1]粘贴_账务明细'!$K$4:$K$3003,'[1]粘贴_账务明细'!$L$4:$L$3003,$A7,'[1]粘贴_账务明细'!$I$4:$I$3003,'首页'!$B$4*100+J$5)) -> 0 | ... N7: =IF($A7="",0,SUMIFS('[1]粘贴_账务明细'!$K$4:$K$3003,'[1]粘贴_账务明细'!$L$4:$L$3003,$A7,'[1]粘贴_账务明细'!$I$4:$I$3003,'首页'!$B$4*100+N$5)) -> 0 | O7: =SUM(C7:N7) -> 7172
A8: =IF('[1]基础资料'!$B$49="","",'[1]基础资料'!$B$49) -> 交易退款 | B8: =IF(A8="","",'[1]基础资料'!$C$49) -> 店铺回款 | C8: =IF($A8="",0,SUMIFS('[1]粘贴_账务明细'!$K$4:$K$3003,'[1]粘贴_账务明细'!$L$4:$L$3003,$A8,'[1]粘贴_账务明细'!$I$4:$I$3003,'首页'!$B$4*100+C$5)) -> 0 | D8: =IF($A8="",0,SUMIFS('[1]粘贴_账务明细'!$K$4:$K$3003,'[1]粘贴_账务明细'!$L$4:$L$3003,$A8,'[1]粘贴_账务明细'!$I$4:$I$3003,'首页'!$B$4*100+D$5)) -> 0 | E8: =IF($A8="",0,SUMIFS('[1]粘贴_账务明细'!$K$4:$K$3003,'[1]粘贴_账务明细'!$L$4:$L$3003,$A8,'[1]粘贴_账务明细'!$I$4:$I$3003,'首页'!$B$4*100+E$5)) -> 0 | F8: =IF($A8="",0,SUMIFS('[1]粘贴_账务明细'!$K$4:$K$3003,'[1]粘贴_账务明细'!$L$4:$L$3003,$A8,'[1]粘贴_账务明细'!$I$4:$I$3003,'首页'!$B$4*100+F$5)) -> 0 | G8: =IF($A8="",0,SUMIFS('[1]粘贴_账务明细'!$K$4:$K$3003,'[1]粘贴_账务明细'!$L$4:$L$3003,$A8,'[1]粘贴_账务明细'!$I$4:$I$3003,'首页'!$B$4*100+G$5)) -> 0 | H8: =IF($A8="",0,SUMIFS('[1]粘贴_账务明细'!$K$4:$K$3003,'[1]粘贴_账务明细'!$L$4:$L$3003,$A8,'[1]粘贴_账务明细'!$I$4:$I$3003,'首页'!$B$4*100+H$5)) -> 0 | I8: =IF($A8="",0,SUMIFS('[1]粘贴_账务明细'!$K$4:$K$3003,'[1]粘贴_账务明细'!$L$4:$L$3003,$A8,'[1]粘贴_账务明细'!$I$4:$I$3003,'首页'!$B$4*100+I$5)) -> 0 | J8: =IF($A8="",0,SUMIFS('[1]粘贴_账务明细'!$K$4:$K$3003,'[1]粘贴_账务明细'!$L$4:$L$3003,$A8,'[1]粘贴_账务明细'!$I$4:$I$3003,'首页'!$B$4*100+J$5)) -> 0 | ... N8: =IF($A8="",0,SUMIFS('[1]粘贴_账务明细'!$K$4:$K$3003,'[1]粘贴_账务明细'!$L$4:$L$3003,$A8,'[1]粘贴_账务明细'!$I$4:$I$3003,'首页'!$B$4*100+N$5)) -> 0 | O8: =SUM(C8:N8) -> -151906
A9: =IF('[1]基础资料'!$B$50="","",'[1]基础资料'!$B$50) -> 退款扣优惠券 | B9: =IF(A9="","",'[1]基础资料'!$C$50) -> 店铺回款 | C9: =IF($A9="",0,SUMIFS('[1]粘贴_账务明细'!$K$4:$K$3003,'[1]粘贴_账务明细'!$L$4:$L$3003,$A9,'[1]粘贴_账务明细'!$I$4:$I$3003,'首页'!$B$4*100+C$5)) -> 0 | D9: =IF($A9="",0,SUMIFS('[1]粘贴_账务明细'!$K$4:$K$3003,'[1]粘贴_账务明细'!$L$4:$L$3003,$A9,'[1]粘贴_账务明细'!$I$4:$I$3003,'首页'!$B$4*100+D$5)) -> 0 | E9: =IF($A9="",0,SUMIFS('[1]粘贴_账务明细'!$K$4:$K$3003,'[1]粘贴_账务明细'!$L$4:$L$3003,$A9,'[1]粘贴_账务明细'!$I$4:$I$3003,'首页'!$B$4*100+E$5)) -> 0 | F9: =IF($A9="",0,SUMIFS('[1]粘贴_账务明细'!$K$4:$K$3003,'[1]粘贴_账务明细'!$L$4:$L$3003,$A9,'[1]粘贴_账务明细'!$I$4:$I$3003,'首页'!$B$4*100+F$5)) -> 0 | G9: =IF($A9="",0,SUMIFS('[1]粘贴_账务明细'!$K$4:$K$3003,'[1]粘贴_账务明细'!$L$4:$L$3003,$A9,'[1]粘贴_账务明细'!$I$4:$I$3003,'首页'!$B$4*100+G$5)) -> 0 | H9: =IF($A9="",0,SUMIFS('[1]粘贴_账务明细'!$K$4:$K$3003,'[1]粘贴_账务明细'!$L$4:$L$3003,$A9,'[1]粘贴_账务明细'!$I$4:$I$3003,'首页'!$B$4*100+H$5)) -> 0 | I9: =IF($A9="",0,SUMIFS('[1]粘贴_账务明细'!$K$4:$K$3003,'[1]粘贴_账务明细'!$L$4:$L$3003,$A9,'[1]粘贴_账务明细'!$I$4:$I$3003,'首页'!$B$4*100+I$5)) -> 0 | J9: =IF($A9="",0,SUMIFS('[1]粘贴_账务明细'!$K$4:$K$3003,'[1]粘贴_账务明细'!$L$4:$L$3003,$A9,'[1]粘贴_账务明细'!$I$4:$I$3003,'首页'!$B$4*100+J$5)) -> 0 | ... N9: =IF($A9="",0,SUMIFS('[1]粘贴_账务明细'!$K$4:$K$3003,'[1]粘贴_账务明细'!$L$4:$L$3003,$A9,'[1]粘贴_账务明细'!$I$4:$I$3003,'首页'!$B$4*100+N$5)) -> 0 | O9: =SUM(C9:N9) -> -3270
A10: =IF('[1]基础资料'!$B$51="","",'[1]基础资料'!$B$51) -> 基础技术服务费 | B10: =IF(A10="","",'[1]基础资料'!$C$51) -> 技术服务费 | C10: =IF($A10="",0,SUMIFS('[1]粘贴_账务明细'!$K$4:$K$3003,'[1]粘贴_账务明细'!$L$4:$L$3003,$A10,'[1]粘贴_账务明细'!$I$4:$I$3003,'首页'!$B$4*100+C$5)) -> 0 | D10: =IF($A10="",0,SUMIFS('[1]粘贴_账务明细'!$K$4:$K$3003,'[1]粘贴_账务明细'!$L$4:$L$3003,$A10,'[1]粘贴_账务明细'!$I$4:$I$3003,'首页'!$B$4*100+D$5)) -> 0 | E10: =IF($A10="",0,SUMIFS('[1]粘贴_账务明细'!$K$4:$K$3003,'[1]粘贴_账务明细'!$L$4:$L$3003,$A10,'[1]粘贴_账务明细'!$I$4:$I$3003,'首页'!$B$4*100+E$5)) -> 0 | F10: =IF($A10="",0,SUMIFS('[1]粘贴_账务明细'!$K$4:$K$3003,'[1]粘贴_账务明细'!$L$4:$L$3003,$A10,'[1]粘贴_账务明细'!$I$4:$I$3003,'首页'!$B$4*100+F$5)) -> 0 | G10: =IF($A10="",0,SUMIFS('[1]粘贴_账务明细'!$K$4:$K$3003,'[1]粘贴_账务明细'!$L$4:$L$3003,$A10,'[1]粘贴_账务明细'!$I$4:$I$3003,'首页'!$B$4*100+G$5)) -> 0 | H10: =IF($A10="",0,SUMIFS('[1]粘贴_账务明细'!$K$4:$K$3003,'[1]粘贴_账务明细'!$L$4:$L$3003,$A10,'[1]粘贴_账务明细'!$I$4:$I$3003,'首页'!$B$4*100+H$5)) -> 0 | I10: =IF($A10="",0,SUMIFS('[1]粘贴_账务明细'!$K$4:$K$3003,'[1]粘贴_账务明细'!$L$4:$L$3003,$A10,'[1]粘贴_账务明细'!$I$4:$I$3003,'首页'!$B$4*100+I$5)) -> 0 | J10: =IF($A10="",0,SUMIFS('[1]粘贴_账务明细'!$K$4:$K$3003,'[1]粘贴_账务明细'!$L$4:$L$3003,$A10,'[1]粘贴_账务明细'!$I$4:$I$3003,'首页'!$B$4*100+J$5)) -> 0 | ... N10: =IF($A10="",0,SUMIFS('[1]粘贴_账务明细'!$K$4:$K$3003,'[1]粘贴_账务明细'!$L$4:$L$3003,$A10,'[1]粘贴_账务明细'!$I$4:$I$3003,'首页'!$B$4*100+N$5)) -> 0 | O10: =SUM(C10:N10) -> -956.47
A11: =IF('[1]基础资料'!$B$52="","",'[1]基础资料'!$B$52) -> 百亿补贴技术服务费 | B11: =IF(A11="","",'[1]基础资料'!$C$52) -> 技术服务费 | C11: =IF($A11="",0,SUMIFS('[1]粘贴_账务明细'!$K$4:$K$3003,'[1]粘贴_账务明细'!$L$4:$L$3003,$A11,'[1]粘贴_账务明细'!$I$4:$I$3003,'首页'!$B$4*100+C$5)) -> 0 | D11: =IF($A11="",0,SUMIFS('[1]粘贴_账务明细'!$K$4:$K$3003,'[1]粘贴_账务明细'!$L$4:$L$3003,$A11,'[1]粘贴_账务明细'!$I$4:$I$3003,'首页'!$B$4*100+D$5)) -> 0 | E11: =IF($A11="",0,SUMIFS('[1]粘贴_账务明细'!$K$4:$K$3003,'[1]粘贴_账务明细'!$L$4:$L$3003,$A11,'[1]粘贴_账务明细'!$I$4:$I$3003,'首页'!$B$4*100+E$5)) -> 0 | F11: =IF($A11="",0,SUMIFS('[1]粘贴_账务明细'!$K$4:$K$3003,'[1]粘贴_账务明细'!$L$4:$L$3003,$A11,'[1]粘贴_账务明细'!$I$4:$I$3003,'首页'!$B$4*100+F$5)) -> 0 | G11: =IF($A11="",0,SUMIFS('[1]粘贴_账务明细'!$K$4:$K$3003,'[1]粘贴_账务明细'!$L$4:$L$3003,$A11,'[1]粘贴_账务明细'!$I$4:$I$3003,'首页'!$B$4*100+G$5)) -> 0 | H11: =IF($A11="",0,SUMIFS('[1]粘贴_账务明细'!$K$4:$K$3003,'[1]粘贴_账务明细'!$L$4:$L$3003,$A11,'[1]粘贴_账务明细'!$I$4:$I$3003,'首页'!$B$4*100+H$5)) -> 0 | I11: =IF($A11="",0,SUMIFS('[1]粘贴_账务明细'!$K$4:$K$3003,'[1]粘贴_账务明细'!$L$4:$L$3003,$A11,'[1]粘贴_账务明细'!$I$4:$I$3003,'首页'!$B$4*100+I$5)) -> 0 | J11: =IF($A11="",0,SUMIFS('[1]粘贴_账务明细'!$K$4:$K$3003,'[1]粘贴_账务明细'!$L$4:$L$3003,$A11,'[1]粘贴_账务明细'!$I$4:$I$3003,'首页'!$B$4*100+J$5)) -> 0 | ... N11: =IF($A11="",0,SUMIFS('[1]粘贴_账务明细'!$K$4:$K$3003,'[1]粘贴_账务明细'!$L$4:$L$3003,$A11,'[1]粘贴_账务明细'!$I$4:$I$3003,'首页'!$B$4*100+N$5)) -> 0 | O11: =SUM(C11:N11) -> -2183.3
A12: =IF('[1]基础资料'!$B$53="","",'[1]基础资料'!$B$53) -> 技术服务费返还 | B12: =IF(A12="","",'[1]基础资料'!$C$53) -> 技术服务费 | C12: =IF($A12="",0,SUMIFS('[1]粘贴_账务明细'!$K$4:$K$3003,'[1]粘贴_账务明细'!$L$4:$L$3003,$A12,'[1]粘贴_账务明细'!$I$4:$I$3003,'首页'!$B$4*100+C$5)) -> 0 | D12: =IF($A12="",0,SUMIFS('[1]粘贴_账务明细'!$K$4:$K$3003,'[1]粘贴_账务明细'!$L$4:$L$3003,$A12,'[1]粘贴_账务明细'!$I$4:$I$3003,'首页'!$B$4*100+D$5)) -> 0 | E12: =IF($A12="",0,SUMIFS('[1]粘贴_账务明细'!$K$4:$K$3003,'[1]粘贴_账务明细'!$L$4:$L$3003,$A12,'[1]粘贴_账务明细'!$I$4:$I$3003,'首页'!$B$4*100+E$5)) -> 0 | F12: =IF($A12="",0,SUMIFS('[1]粘贴_账务明细'!$K$4:$K$3003,'[1]粘贴_账务明细'!$L$4:$L$3003,$A12,'[1]粘贴_账务明细'!$I$4:$I$3003,'首页'!$B$4*100+F$5)) -> 0 | G12: =IF($A12="",0,SUMIFS('[1]粘贴_账务明细'!$K$4:$K$3003,'[1]粘贴_账务明细'!$L$4:$L$3003,$A12,'[1]粘贴_账务明细'!$I$4:$I$3003,'首页'!$B$4*100+G$5)) -> 0 | H12: =IF($A12="",0,SUMIFS('[1]粘贴_账务明细'!$K$4:$K$3003,'[1]粘贴_账务明细'!$L$4:$L$3003,$A12,'[1]粘贴_账务明细'!$I$4:$I$3003,'首页'!$B$4*100+H$5)) -> 0 | I12: =IF($A12="",0,SUMIFS('[1]粘贴_账务明细'!$K$4:$K$3003,'[1]粘贴_账务明细'!$L$4:$L$3003,$A12,'[1]粘贴_账务明细'!$I$4:$I$3003,'首页'!$B$4*100+I$5)) -> 0 | J12: =IF($A12="",0,SUMIFS('[1]粘贴_账务明细'!$K$4:$K$3003,'[1]粘贴_账务明细'!$L$4:$L$3003,$A12,'[1]粘贴_账务明细'!$I$4:$I$3003,'首页'!$B$4*100+J$5)) -> 0 | ... N12: =IF($A12="",0,SUMIFS('[1]粘贴_账务明细'!$K$4:$K$3003,'[1]粘贴_账务明细'!$L$4:$L$3003,$A12,'[1]粘贴_账务明细'!$I$4:$I$3003,'首页'!$B$4*100+N$5)) -> 0 | O12: =SUM(C12:N12) -> 4608.4
A13: =IF('[1]基础资料'!$B$54="","",'[1]基础资料'!$B$54) -> 补贴汇入 | B13: =IF(A13="","",'[1]基础资料'!$C$54) -> 平台补贴 | C13: =IF($A13="",0,SUMIFS('[1]粘贴_账务明细'!$K$4:$K$3003,'[1]粘贴_账务明细'!$L$4:$L$3003,$A13,'[1]粘贴_账务明细'!$I$4:$I$3003,'首页'!$B$4*100+C$5)) -> 0 | D13: =IF($A13="",0,SUMIFS('[1]粘贴_账务明细'!$K$4:$K$3003,'[1]粘贴_账务明细'!$L$4:$L$3003,$A13,'[1]粘贴_账务明细'!$I$4:$I$3003,'首页'!$B$4*100+D$5)) -> 0 | E13: =IF($A13="",0,SUMIFS('[1]粘贴_账务明细'!$K$4:$K$3003,'[1]粘贴_账务明细'!$L$4:$L$3003,$A13,'[1]粘贴_账务明细'!$I$4:$I$3003,'首页'!$B$4*100+E$5)) -> 0 | F13: =IF($A13="",0,SUMIFS('[1]粘贴_账务明细'!$K$4:$K$3003,'[1]粘贴_账务明细'!$L$4:$L$3003,$A13,'[1]粘贴_账务明细'!$I$4:$I$3003,'首页'!$B$4*100+F$5)) -> 0 | G13: =IF($A13="",0,SUMIFS('[1]粘贴_账务明细'!$K$4:$K$3003,'[1]粘贴_账务明细'!$L$4:$L$3003,$A13,'[1]粘贴_账务明细'!$I$4:$I$3003,'首页'!$B$4*100+G$5)) -> 0 | H13: =IF($A13="",0,SUMIFS('[1]粘贴_账务明细'!$K$4:$K$3003,'[1]粘贴_账务明细'!$L$4:$L$3003,$A13,'[1]粘贴_账务明细'!$I$4:$I$3003,'首页'!$B$4*100+H$5)) -> 0 | I13: =IF($A13="",0,SUMIFS('[1]粘贴_账务明细'!$K$4:$K$3003,'[1]粘贴_账务明细'!$L$4:$L$3003,$A13,'[1]粘贴_账务明细'!$I$4:$I$3003,'首页'!$B$4*100+I$5)) -> 0 | J13: =IF($A13="",0,SUMIFS('[1]粘贴_账务明细'!$K$4:$K$3003,'[1]粘贴_账务明细'!$L$4:$L$3003,$A13,'[1]粘贴_账务明细'!$I$4:$I$3003,'首页'!$B$4*100+J$5)) -> 0 | ... N13: =IF($A13="",0,SUMIFS('[1]粘贴_账务明细'!$K$4:$K$3003,'[1]粘贴_账务明细'!$L$4:$L$3003,$A13,'[1]粘贴_账务明细'!$I$4:$I$3003,'首页'!$B$4*100+N$5)) -> 0 | O13: =SUM(C13:N13) -> 3970
A14: =IF('[1]基础资料'!$B$55="","",'[1]基础资料'!$B$55) -> 消费者体验提升计划 | B14: =IF(A14="","",'[1]基础资料'!$C$55) -> 体验计划 | C14: =IF($A14="",0,SUMIFS('[1]粘贴_账务明细'!$K$4:$K$3003,'[1]粘贴_账务明细'!$L$4:$L$3003,$A14,'[1]粘贴_账务明细'!$I$4:$I$3003,'首页'!$B$4*100+C$5)) -> 0 | D14: =IF($A14="",0,SUMIFS('[1]粘贴_账务明细'!$K$4:$K$3003,'[1]粘贴_账务明细'!$L$4:$L$3003,$A14,'[1]粘贴_账务明细'!$I$4:$I$3003,'首页'!$B$4*100+D$5)) -> 0 | E14: =IF($A14="",0,SUMIFS('[1]粘贴_账务明细'!$K$4:$K$3003,'[1]粘贴_账务明细'!$L$4:$L$3003,$A14,'[1]粘贴_账务明细'!$I$4:$I$3003,'首页'!$B$4*100+E$5)) -> 0 | F14: =IF($A14="",0,SUMIFS('[1]粘贴_账务明细'!$K$4:$K$3003,'[1]粘贴_账务明细'!$L$4:$L$3003,$A14,'[1]粘贴_账务明细'!$I$4:$I$3003,'首页'!$B$4*100+F$5)) -> 0 | G14: =IF($A14="",0,SUMIFS('[1]粘贴_账务明细'!$K$4:$K$3003,'[1]粘贴_账务明细'!$L$4:$L$3003,$A14,'[1]粘贴_账务明细'!$I$4:$I$3003,'首页'!$B$4*100+G$5)) -> 0 | H14: =IF($A14="",0,SUMIFS('[1]粘贴_账务明细'!$K$4:$K$3003,'[1]粘贴_账务明细'!$L$4:$L$3003,$A14,'[1]粘贴_账务明细'!$I$4:$I$3003,'首页'!$B$4*100+H$5)) -> 0 | I14: =IF($A14="",0,SUMIFS('[1]粘贴_账务明细'!$K$4:$K$3003,'[1]粘贴_账务明细'!$L$4:$L$3003,$A14,'[1]粘贴_账务明细'!$I$4:$I$3003,'首页'!$B$4*100+I$5)) -> 0 | J14: =IF($A14="",0,SUMIFS('[1]粘贴_账务明细'!$K$4:$K$3003,'[1]粘贴_账务明细'!$L$4:$L$3003,$A14,'[1]粘贴_账务明细'!$I$4:$I$3003,'首页'!$B$4*100+J$5)) -> 0 | ... N14: =IF($A14="",0,SUMIFS('[1]粘贴_账务明细'!$K$4:$K$3003,'[1]粘贴_账务明细'!$L$4:$L$3003,$A14,'[1]粘贴_账务明细'!$I$4:$I$3003,'首页'!$B$4*100+N$5)) -> 0 | O14: =SUM(C14:N14) -> -9.77
A15: =IF('[1]基础资料'!$B$56="","",'[1]基础资料'!$B$56) -> 售后补偿 | B15: =IF(A15="","",'[1]基础资料'!$C$56) -> 售后补偿 | C15: =IF($A15="",0,SUMIFS('[1]粘贴_账务明细'!$K$4:$K$3003,'[1]粘贴_账务明细'!$L$4:$L$3003,$A15,'[1]粘贴_账务明细'!$I$4:$I$3003,'首页'!$B$4*100+C$5)) -> 0 | D15: =IF($A15="",0,SUMIFS('[1]粘贴_账务明细'!$K$4:$K$3003,'[1]粘贴_账务明细'!$L$4:$L$3003,$A15,'[1]粘贴_账务明细'!$I$4:$I$3003,'首页'!$B$4*100+D$5)) -> 0 | E15: =IF($A15="",0,SUMIFS('[1]粘贴_账务明细'!$K$4:$K$3003,'[1]粘贴_账务明细'!$L$4:$L$3003,$A15,'[1]粘贴_账务明细'!$I$4:$I$3003,'首页'!$B$4*100+E$5)) -> 0 | F15: =IF($A15="",0,SUMIFS('[1]粘贴_账务明细'!$K$4:$K$3003,'[1]粘贴_账务明细'!$L$4:$L$3003,$A15,'[1]粘贴_账务明细'!$I$4:$I$3003,'首页'!$B$4*100+F$5)) -> 0 | G15: =IF($A15="",0,SUMIFS('[1]粘贴_账务明细'!$K$4:$K$3003,'[1]粘贴_账务明细'!$L$4:$L$3003,$A15,'[1]粘贴_账务明细'!$I$4:$I$3003,'首页'!$B$4*100+G$5)) -> 0 | H15: =IF($A15="",0,SUMIFS('[1]粘贴_账务明细'!$K$4:$K$3003,'[1]粘贴_账务明细'!$L$4:$L$3003,$A15,'[1]粘贴_账务明细'!$I$4:$I$3003,'首页'!$B$4*100+H$5)) -> 0 | I15: =IF($A15="",0,SUMIFS('[1]粘贴_账务明细'!$K$4:$K$3003,'[1]粘贴_账务明细'!$L$4:$L$3003,$A15,'[1]粘贴_账务明细'!$I$4:$I$3003,'首页'!$B$4*100+I$5)) -> 0 | J15: =IF($A15="",0,SUMIFS('[1]粘贴_账务明细'!$K$4:$K$3003,'[1]粘贴_账务明细'!$L$4:$L$3003,$A15,'[1]粘贴_账务明细'!$I$4:$I$3003,'首页'!$B$4*100+J$5)) -> 0 | ... N15: =IF($A15="",0,SUMIFS('[1]粘贴_账务明细'!$K$4:$K$3003,'[1]粘贴_账务明细'!$L$4:$L$3003,$A15,'[1]粘贴_账务明细'!$I$4:$I$3003,'首页'!$B$4*100+N$5)) -> 0 | O15: =SUM(C15:N15) -> -103
A16: =IF('[1]基础资料'!$B$57="","",'[1]基础资料'!$B$57) -> 申诉补回 | B16: =IF(A16="","",'[1]基础资料'!$C$57) -> 售后补偿 | C16: =IF($A16="",0,SUMIFS('[1]粘贴_账务明细'!$K$4:$K$3003,'[1]粘贴_账务明细'!$L$4:$L$3003,$A16,'[1]粘贴_账务明细'!$I$4:$I$3003,'首页'!$B$4*100+C$5)) -> 0 | D16: =IF($A16="",0,SUMIFS('[1]粘贴_账务明细'!$K$4:$K$3003,'[1]粘贴_账务明细'!$L$4:$L$3003,$A16,'[1]粘贴_账务明细'!$I$4:$I$3003,'首页'!$B$4*100+D$5)) -> 0 | E16: =IF($A16="",0,SUMIFS('[1]粘贴_账务明细'!$K$4:$K$3003,'[1]粘贴_账务明细'!$L$4:$L$3003,$A16,'[1]粘贴_账务明细'!$I$4:$I$3003,'首页'!$B$4*100+E$5)) -> 0 | F16: =IF($A16="",0,SUMIFS('[1]粘贴_账务明细'!$K$4:$K$3003,'[1]粘贴_账务明细'!$L$4:$L$3003,$A16,'[1]粘贴_账务明细'!$I$4:$I$3003,'首页'!$B$4*100+F$5)) -> 0 | G16: =IF($A16="",0,SUMIFS('[1]粘贴_账务明细'!$K$4:$K$3003,'[1]粘贴_账务明细'!$L$4:$L$3003,$A16,'[1]粘贴_账务明细'!$I$4:$I$3003,'首页'!$B$4*100+G$5)) -> 0 | H16: =IF($A16="",0,SUMIFS('[1]粘贴_账务明细'!$K$4:$K$3003,'[1]粘贴_账务明细'!$L$4:$L$3003,$A16,'[1]粘贴_账务明细'!$I$4:$I$3003,'首页'!$B$4*100+H$5)) -> 0 | I16: =IF($A16="",0,SUMIFS('[1]粘贴_账务明细'!$K$4:$K$3003,'[1]粘贴_账务明细'!$L$4:$L$3003,$A16,'[1]粘贴_账务明细'!$I$4:$I$3003,'首页'!$B$4*100+I$5)) -> 0 | J16: =IF($A16="",0,SUMIFS('[1]粘贴_账务明细'!$K$4:$K$3003,'[1]粘贴_账务明细'!$L$4:$L$3003,$A16,'[1]粘贴_账务明细'!$I$4:$I$3003,'首页'!$B$4*100+J$5)) -> 0 | ... N16: =IF($A16="",0,SUMIFS('[1]粘贴_账务明细'!$K$4:$K$3003,'[1]粘贴_账务明细'!$L$4:$L$3003,$A16,'[1]粘贴_账务明细'!$I$4:$I$3003,'首页'!$B$4*100+N$5)) -> 0 | O16: =SUM(C16:N16) -> 126
A17: =IF('[1]基础资料'!$B$58="","",'[1]基础资料'!$B$58) -> 提现 | B17: =IF(A17="","",'[1]基础资料'!$C$58) -> 提现 | C17: =IF($A17="",0,SUMIFS('[1]粘贴_账务明细'!$K$4:$K$3003,'[1]粘贴_账务明细'!$L$4:$L$3003,$A17,'[1]粘贴_账务明细'!$I$4:$I$3003,'首页'!$B$4*100+C$5)) -> 0 | D17: =IF($A17="",0,SUMIFS('[1]粘贴_账务明细'!$K$4:$K$3003,'[1]粘贴_账务明细'!$L$4:$L$3003,$A17,'[1]粘贴_账务明细'!$I$4:$I$3003,'首页'!$B$4*100+D$5)) -> 0 | E17: =IF($A17="",0,SUMIFS('[1]粘贴_账务明细'!$K$4:$K$3003,'[1]粘贴_账务明细'!$L$4:$L$3003,$A17,'[1]粘贴_账务明细'!$I$4:$I$3003,'首页'!$B$4*100+E$5)) -> 0 | F17: =IF($A17="",0,SUMIFS('[1]粘贴_账务明细'!$K$4:$K$3003,'[1]粘贴_账务明细'!$L$4:$L$3003,$A17,'[1]粘贴_账务明细'!$I$4:$I$3003,'首页'!$B$4*100+F$5)) -> 0 | G17: =IF($A17="",0,SUMIFS('[1]粘贴_账务明细'!$K$4:$K$3003,'[1]粘贴_账务明细'!$L$4:$L$3003,$A17,'[1]粘贴_账务明细'!$I$4:$I$3003,'首页'!$B$4*100+G$5)) -> 0 | H17: =IF($A17="",0,SUMIFS('[1]粘贴_账务明细'!$K$4:$K$3003,'[1]粘贴_账务明细'!$L$4:$L$3003,$A17,'[1]粘贴_账务明细'!$I$4:$I$3003,'首页'!$B$4*100+H$5)) -> 0 | I17: =IF($A17="",0,SUMIFS('[1]粘贴_账务明细'!$K$4:$K$3003,'[1]粘贴_账务明细'!$L$4:$L$3003,$A17,'[1]粘贴_账务明细'!$I$4:$I$3003,'首页'!$B$4*100+I$5)) -> 0 | J17: =IF($A17="",0,SUMIFS('[1]粘贴_账务明细'!$K$4:$K$3003,'[1]粘贴_账务明细'!$L$4:$L$3003,$A17,'[1]粘贴_账务明细'!$I$4:$I$3003,'首页'!$B$4*100+J$5)) -> 0 | ... N17: =IF($A17="",0,SUMIFS('[1]粘贴_账务明细'!$K$4:$K$3003,'[1]粘贴_账务明细'!$L$4:$L$3003,$A17,'[1]粘贴_账务明细'!$I$4:$I$3003,'首页'!$B$4*100+N$5)) -> 0 | O17: =SUM(C17:N17) -> -100000
A18: =IF('[1]基础资料'!$B$59="","",'[1]基础资料'!$B$59) | B18: =IF(A18="","",'[1]基础资料'!$C$59) | C18: =IF($A18="",0,SUMIFS('[1]粘贴_账务明细'!$K$4:$K$3003,'[1]粘贴_账务明细'!$L$4:$L$3003,$A18,'[1]粘贴_账务明细'!$I$4:$I$3003,'首页'!$B$4*100+C$5)) -> 0 | D18: =IF($A18="",0,SUMIFS('[1]粘贴_账务明细'!$K$4:$K$3003,'[1]粘贴_账务明细'!$L$4:$L$3003,$A18,'[1]粘贴_账务明细'!$I$4:$I$3003,'首页'!$B$4*100+D$5)) -> 0 | E18: =IF($A18="",0,SUMIFS('[1]粘贴_账务明细'!$K$4:$K$3003,'[1]粘贴_账务明细'!$L$4:$L$3003,$A18,'[1]粘贴_账务明细'!$I$4:$I$3003,'首页'!$B$4*100+E$5)) -> 0 | F18: =IF($A18="",0,SUMIFS('[1]粘贴_账务明细'!$K$4:$K$3003,'[1]粘贴_账务明细'!$L$4:$L$3003,$A18,'[1]粘贴_账务明细'!$I$4:$I$3003,'首页'!$B$4*100+F$5)) -> 0 | G18: =IF($A18="",0,SUMIFS('[1]粘贴_账务明细'!$K$4:$K$3003,'[1]粘贴_账务明细'!$L$4:$L$3003,$A18,'[1]粘贴_账务明细'!$I$4:$I$3003,'首页'!$B$4*100+G$5)) -> 0 | H18: =IF($A18="",0,SUMIFS('[1]粘贴_账务明细'!$K$4:$K$3003,'[1]粘贴_账务明细'!$L$4:$L$3003,$A18,'[1]粘贴_账务明细'!$I$4:$I$3003,'首页'!$B$4*100+H$5)) -> 0 | I18: =IF($A18="",0,SUMIFS('[1]粘贴_账务明细'!$K$4:$K$3003,'[1]粘贴_账务明细'!$L$4:$L$3003,$A18,'[1]粘贴_账务明细'!$I$4:$I$3003,'首页'!$B$4*100+I$5)) -> 0 | J18: =IF($A18="",0,SUMIFS('[1]粘贴_账务明细'!$K$4:$K$3003,'[1]粘贴_账务明细'!$L$4:$L$3003,$A18,'[1]粘贴_账务明细'!$I$4:$I$3003,'首页'!$B$4*100+J$5)) -> 0 | ... N18: =IF($A18="",0,SUMIFS('[1]粘贴_账务明细'!$K$4:$K$3003,'[1]粘贴_账务明细'!$L$4:$L$3003,$A18,'[1]粘贴_账务明细'!$I$4:$I$3003,'首页'!$B$4*100+N$5)) -> 0 | O18: =SUM(C18:N18) -> 0
A19: =IF('[1]基础资料'!$B$60="","",'[1]基础资料'!$B$60) | B19: =IF(A19="","",'[1]基础资料'!$C$60) | C19: =IF($A19="",0,SUMIFS('[1]粘贴_账务明细'!$K$4:$K$3003,'[1]粘贴_账务明细'!$L$4:$L$3003,$A19,'[1]粘贴_账务明细'!$I$4:$I$3003,'首页'!$B$4*100+C$5)) -> 0 | D19: =IF($A19="",0,SUMIFS('[1]粘贴_账务明细'!$K$4:$K$3003,'[1]粘贴_账务明细'!$L$4:$L$3003,$A19,'[1]粘贴_账务明细'!$I$4:$I$3003,'首页'!$B$4*100+D$5)) -> 0 | E19: =IF($A19="",0,SUMIFS('[1]粘贴_账务明细'!$K$4:$K$3003,'[1]粘贴_账务明细'!$L$4:$L$3003,$A19,'[1]粘贴_账务明细'!$I$4:$I$3003,'首页'!$B$4*100+E$5)) -> 0 | F19: =IF($A19="",0,SUMIFS('[1]粘贴_账务明细'!$K$4:$K$3003,'[1]粘贴_账务明细'!$L$4:$L$3003,$A19,'[1]粘贴_账务明细'!$I$4:$I$3003,'首页'!$B$4*100+F$5)) -> 0 | G19: =IF($A19="",0,SUMIFS('[1]粘贴_账务明细'!$K$4:$K$3003,'[1]粘贴_账务明细'!$L$4:$L$3003,$A19,'[1]粘贴_账务明细'!$I$4:$I$3003,'首页'!$B$4*100+G$5)) -> 0 | H19: =IF($A19="",0,SUMIFS('[1]粘贴_账务明细'!$K$4:$K$3003,'[1]粘贴_账务明细'!$L$4:$L$3003,$A19,'[1]粘贴_账务明细'!$I$4:$I$3003,'首页'!$B$4*100+H$5)) -> 0 | I19: =IF($A19="",0,SUMIFS('[1]粘贴_账务明细'!$K$4:$K$3003,'[1]粘贴_账务明细'!$L$4:$L$3003,$A19,'[1]粘贴_账务明细'!$I$4:$I$3003,'首页'!$B$4*100+I$5)) -> 0 | J19: =IF($A19="",0,SUMIFS('[1]粘贴_账务明细'!$K$4:$K$3003,'[1]粘贴_账务明细'!$L$4:$L$3003,$A19,'[1]粘贴_账务明细'!$I$4:$I$3003,'首页'!$B$4*100+J$5)) -> 0 | ... N19: =IF($A19="",0,SUMIFS('[1]粘贴_账务明细'!$K$4:$K$3003,'[1]粘贴_账务明细'!$L$4:$L$3003,$A19,'[1]粘贴_账务明细'!$I$4:$I$3003,'首页'!$B$4*100+N$5)) -> 0 | O19: =SUM(C19:N19) -> 0
A20: =IF('[1]基础资料'!$B$61="","",'[1]基础资料'!$B$61) | B20: =IF(A20="","",'[1]基础资料'!$C$61) | C20: =IF($A20="",0,SUMIFS('[1]粘贴_账务明细'!$K$4:$K$3003,'[1]粘贴_账务明细'!$L$4:$L$3003,$A20,'[1]粘贴_账务明细'!$I$4:$I$3003,'首页'!$B$4*100+C$5)) -> 0 | D20: =IF($A20="",0,SUMIFS('[1]粘贴_账务明细'!$K$4:$K$3003,'[1]粘贴_账务明细'!$L$4:$L$3003,$A20,'[1]粘贴_账务明细'!$I$4:$I$3003,'首页'!$B$4*100+D$5)) -> 0 | E20: =IF($A20="",0,SUMIFS('[1]粘贴_账务明细'!$K$4:$K$3003,'[1]粘贴_账务明细'!$L$4:$L$3003,$A20,'[1]粘贴_账务明细'!$I$4:$I$3003,'首页'!$B$4*100+E$5)) -> 0 | F20: =IF($A20="",0,SUMIFS('[1]粘贴_账务明细'!$K$4:$K$3003,'[1]粘贴_账务明细'!$L$4:$L$3003,$A20,'[1]粘贴_账务明细'!$I$4:$I$3003,'首页'!$B$4*100+F$5)) -> 0 | G20: =IF($A20="",0,SUMIFS('[1]粘贴_账务明细'!$K$4:$K$3003,'[1]粘贴_账务明细'!$L$4:$L$3003,$A20,'[1]粘贴_账务明细'!$I$4:$I$3003,'首页'!$B$4*100+G$5)) -> 0 | H20: =IF($A20="",0,SUMIFS('[1]粘贴_账务明细'!$K$4:$K$3003,'[1]粘贴_账务明细'!$L$4:$L$3003,$A20,'[1]粘贴_账务明细'!$I$4:$I$3003,'首页'!$B$4*100+H$5)) -> 0 | I20: =IF($A20="",0,SUMIFS('[1]粘贴_账务明细'!$K$4:$K$3003,'[1]粘贴_账务明细'!$L$4:$L$3003,$A20,'[1]粘贴_账务明细'!$I$4:$I$3003,'首页'!$B$4*100+I$5)) -> 0 | J20: =IF($A20="",0,SUMIFS('[1]粘贴_账务明细'!$K$4:$K$3003,'[1]粘贴_账务明细'!$L$4:$L$3003,$A20,'[1]粘贴_账务明细'!$I$4:$I$3003,'首页'!$B$4*100+J$5)) -> 0 | ... N20: =IF($A20="",0,SUMIFS('[1]粘贴_账务明细'!$K$4:$K$3003,'[1]粘贴_账务明细'!$L$4:$L$3003,$A20,'[1]粘贴_账务明细'!$I$4:$I$3003,'首页'!$B$4*100+N$5)) -> 0 | O20: =SUM(C20:N20) -> 0
A21: 其他未归类 | B21: 其他费用 | C21: =IF($A21="",0,SUMIFS('[1]粘贴_账务明细'!$K$4:$K$3003,'[1]粘贴_账务明细'!$L$4:$L$3003,$A21,'[1]粘贴_账务明细'!$I$4:$I$3003,'首页'!$B$4*100+C$5)) -> 0 | D21: =IF($A21="",0,SUMIFS('[1]粘贴_账务明细'!$K$4:$K$3003,'[1]粘贴_账务明细'!$L$4:$L$3003,$A21,'[1]粘贴_账务明细'!$I$4:$I$3003,'首页'!$B$4*100+D$5)) -> 0 | E21: =IF($A21="",0,SUMIFS('[1]粘贴_账务明细'!$K$4:$K$3003,'[1]粘贴_账务明细'!$L$4:$L$3003,$A21,'[1]粘贴_账务明细'!$I$4:$I$3003,'首页'!$B$4*100+E$5)) -> 0 | F21: =IF($A21="",0,SUMIFS('[1]粘贴_账务明细'!$K$4:$K$3003,'[1]粘贴_账务明细'!$L$4:$L$3003,$A21,'[1]粘贴_账务明细'!$I$4:$I$3003,'首页'!$B$4*100+F$5)) -> 0 | G21: =IF($A21="",0,SUMIFS('[1]粘贴_账务明细'!$K$4:$K$3003,'[1]粘贴_账务明细'!$L$4:$L$3003,$A21,'[1]粘贴_账务明细'!$I$4:$I$3003,'首页'!$B$4*100+G$5)) -> 0 | H21: =IF($A21="",0,SUMIFS('[1]粘贴_账务明细'!$K$4:$K$3003,'[1]粘贴_账务明细'!$L$4:$L$3003,$A21,'[1]粘贴_账务明细'!$I$4:$I$3003,'首页'!$B$4*100+H$5)) -> 0 | I21: =IF($A21="",0,SUMIFS('[1]粘贴_账务明细'!$K$4:$K$3003,'[1]粘贴_账务明细'!$L$4:$L$3003,$A21,'[1]粘贴_账务明细'!$I$4:$I$3003,'首页'!$B$4*100+I$5)) -> 0 | J21: =IF($A21="",0,SUMIFS('[1]粘贴_账务明细'!$K$4:$K$3003,'[1]粘贴_账务明细'!$L$4:$L$3003,$A21,'[1]粘贴_账务明细'!$I$4:$I$3003,'首页'!$B$4*100+J$5)) -> 0 | ... N21: =IF($A21="",0,SUMIFS('[1]粘贴_账务明细'!$K$4:$K$3003,'[1]粘贴_账务明细'!$L$4:$L$3003,$A21,'[1]粘贴_账务明细'!$I$4:$I$3003,'首页'!$B$4*100+N$5)) -> 0 | O21: =SUM(C21:N21) -> 0
A22: 本月净额（上面合计） | C22: =SUM(C6:C21) -> 0 | D22: =SUM(D6:D21) -> 0 | E22: =SUM(E6:E21) -> 0 | F22: =SUM(F6:F21) -> 0 | G22: =SUM(G6:G21) -> 0 | H22: =SUM(H6:H21) -> 0 | I22: =SUM(I6:I21) -> 0 | J22: =SUM(J6:J21) -> 0 | ... N22: =SUM(N6:N21) -> 0 | O22: =SUM(C22:N22) -> 61390.86
A23: 账务明细「#总计」 | C23: =IF(COUNTIFS('[1]粘贴_账务明细'!$J$4:$J$3003,">-9E+99",'[1]粘贴_账务明细'!$I$4:$I$3003,'首页'!$B$4*100+C$5)=0,"",SUMIFS('[1]粘贴_账务明细'!$J$4:$J$3003,'[1]粘贴_账务明细'!$I$4:$I$3003,'首页'!$B$4*100+C$5)) | D23: =IF(COUNTIFS('[1]粘贴_账务明细'!$J$4:$J$3003,">-9E+99",'[1]粘贴_账务明细'!$I$4:$I$3003,'首页'!$B$4*100+D$5)=0,"",SUMIFS('[1]粘贴_账务明细'!$J$4:$J$3003,'[1]粘贴_账务明细'!$I$4:$I$3003,'首页'!$B$4*100+D$5)) | E23: =IF(COUNTIFS('[1]粘贴_账务明细'!$J$4:$J$3003,">-9E+99",'[1]粘贴_账务明细'!$I$4:$I$3003,'首页'!$B$4*100+E$5)=0,"",SUMIFS('[1]粘贴_账务明细'!$J$4:$J$3003,'[1]粘贴_账务明细'!$I$4:$I$3003,'首页'!$B$4*100+E$5)) | F23: =IF(COUNTIFS('[1]粘贴_账务明细'!$J$4:$J$3003,">-9E+99",'[1]粘贴_账务明细'!$I$4:$I$3003,'首页'!$B$4*100+F$5)=0,"",SUMIFS('[1]粘贴_账务明细'!$J$4:$J$3003,'[1]粘贴_账务明细'!$I$4:$I$3003,'首页'!$B$4*100+F$5)) | G23: =IF(COUNTIFS('[1]粘贴_账务明细'!$J$4:$J$3003,">-9E+99",'[1]粘贴_账务明细'!$I$4:$I$3003,'首页'!$B$4*100+G$5)=0,"",SUMIFS('[1]粘贴_账务明细'!$J$4:$J$3003,'[1]粘贴_账务明细'!$I$4:$I$3003,'首页'!$B$4*100+G$5)) | H23: =IF(COUNTIFS('[1]粘贴_账务明细'!$J$4:$J$3003,">-9E+99",'[1]粘贴_账务明细'!$I$4:$I$3003,'首页'!$B$4*100+H$5)=0,"",SUMIFS('[1]粘贴_账务明细'!$J$4:$J$3003,'[1]粘贴_账务明细'!$I$4:$I$3003,'首页'!$B$4*100+H$5)) | I23: =IF(COUNTIFS('[1]粘贴_账务明细'!$J$4:$J$3003,">-9E+99",'[1]粘贴_账务明细'!$I$4:$I$3003,'首页'!$B$4*100+I$5)=0,"",SUMIFS('[1]粘贴_账务明细'!$J$4:$J$3003,'[1]粘贴_账务明细'!$I$4:$I$3003,'首页'!$B$4*100+I$5)) | J23: =IF(COUNTIFS('[1]粘贴_账务明细'!$J$4:$J$3003,">-9E+99",'[1]粘贴_账务明细'!$I$4:$I$3003,'首页'!$B$4*100+J$5)=0,"",SUMIFS('[1]粘贴_账务明细'!$J$4:$J$3003,'[1]粘贴_账务明细'!$I$4:$I$3003,'首页'!$B$4*100+J$5)) | ... N23: =IF(COUNTIFS('[1]粘贴_账务明细'!$J$4:$J$3003,">-9E+99",'[1]粘贴_账务明细'!$I$4:$I$3003,'首页'!$B$4*100+N$5)=0,"",SUMIFS('[1]粘贴_账务明细'!$J$4:$J$3003,'[1]粘贴_账务明细'!$I$4:$I$3003,'首页'!$B$4*100+N$5))
A24: 差异（应为 0） | C24: =IF(C23="","没粘#总计",ROUND(C22-C23,2)) -> 没粘#总计 | D24: =IF(D23="","没粘#总计",ROUND(D22-D23,2)) -> 没粘#总计 | E24: =IF(E23="","没粘#总计",ROUND(E22-E23,2)) -> 没粘#总计 | F24: =IF(F23="","没粘#总计",ROUND(F22-F23,2)) -> 没粘#总计 | G24: =IF(G23="","没粘#总计",ROUND(G22-G23,2)) -> 没粘#总计 | H24: =IF(H23="","没粘#总计",ROUND(H22-H23,2)) -> 没粘#总计 | I24: =IF(I23="","没粘#总计",ROUND(I22-I23,2)) -> 没粘#总计 | J24: =IF(J23="","没粘#总计",ROUND(J22-J23,2)) -> 没粘#总计 | ... N24: =IF(N23="","没粘#总计",ROUND(N22-N23,2)) -> 没粘#总计
A25: 月初店铺余额 | C25: =N('[1]基础资料'!$C$8) -> 0 | D25: =C26 -> 0 | E25: =D26 -> 0 | F25: =E26 -> 0 | G25: =F26 -> 0 | H25: =G26 -> 0 | I25: =H26 -> 0 | J25: =I26 -> 0 | K25: =J26 -> 0 | ... N25: =M26 -> 61390.86
A26: 月末店铺余额 | C26: =C25+C22 -> 0 | D26: =D25+D22 -> 0 | E26: =E25+E22 -> 0 | F26: =F25+F22 -> 0 | G26: =G25+G22 -> 0 | H26: =H25+H22 -> 0 | I26: =I25+I22 -> 0 | J26: =J25+J22 -> 0 | ... N26: =N25+N22 -> 61390.86
A27: 资金台帐记的提现 | C27: =SUMIFS('[1]资金台帐'!$H$4:$H$3003,'[1]资金台帐'!$B$4:$B$3003,'[1]基础资料'!$A$8,'[1]资金台帐'!$M$4:$M$3003,"内部转账",'[1]资金台帐'!$N$4:$N$3003,'首页'!$B$4*100+C$5)-SUMIFS('[1]资金台帐'!$G$4:$G$3003,'[1]资金台帐'!$B$4:$B$3003,'[1]基础资料'!$A$8,'[1]资金台帐'!$M$4:$M$3003,"内部转账",'[1]资金台帐'!$N$4:$N$3003,'首页'!$B$4*100+C$5)+SUMIFS('[1]资金台帐'!$G$4:$G$3003,'[1]资金台帐'!$I$4:$I$3003,'[1]基础资料'!$A$8,'[1]资金台帐'!$M$4:$M$3003,"内部转账",'[1]资金台帐'!$N$4:$N$3003,'首页'!$B$4*100+C$5)-SUMIFS('[1]资金台帐'!$H$4:$H$3003,'[1]资金台帐'!$I$4:$I$3003,'[1]基础资料'!$A$8,'[1]资金台帐'!$M$4:$M$3003,"内部转账",'[1]资金台帐'!$N$4:$N$3003,'首页'!$B$4*100+C$5) -> 0 | D27: =SUMIFS('[1]资金台帐'!$H$4:$H$3003,'[1]资金台帐'!$B$4:$B$3003,'[1]基础资料'!$A$8,'[1]资金台帐'!$M$4:$M$3003,"内部转账",'[1]资金台帐'!$N$4:$N$3003,'首页'!$B$4*100+D$5)-SUMIFS('[1]资金台帐'!$G$4:$G$3003,'[1]资金台帐'!$B$4:$B$3003,'[1]基础资料'!$A$8,'[1]资金台帐'!$M$4:$M$3003,"内部转账",'[1]资金台帐'!$N$4:$N$3003,'首页'!$B$4*100+D$5)+SUMIFS('[1]资金台帐'!$G$4:$G$3003,'[1]资金台帐'!$I$4:$I$3003,'[1]基础资料'!$A$8,'[1]资金台帐'!$M$4:$M$3003,"内部转账",'[1]资金台帐'!$N$4:$N$3003,'首页'!$B$4*100+D$5)-SUMIFS('[1]资金台帐'!$H$4:$H$3003,'[1]资金台帐'!$I$4:$I$3003,'[1]基础资料'!$A$8,'[1]资金台帐'!$M$4:$M$3003,"内部转账",'[1]资金台帐'!$N$4:$N$3003,'首页'!$B$4*100+D$5) -> 0 | E27: =SUMIFS('[1]资金台帐'!$H$4:$H$3003,'[1]资金台帐'!$B$4:$B$3003,'[1]基础资料'!$A$8,'[1]资金台帐'!$M$4:$M$3003,"内部转账",'[1]资金台帐'!$N$4:$N$3003,'首页'!$B$4*100+E$5)-SUMIFS('[1]资金台帐'!$G$4:$G$3003,'[1]资金台帐'!$B$4:$B$3003,'[1]基础资料'!$A$8,'[1]资金台帐'!$M$4:$M$3003,"内部转账",'[1]资金台帐'!$N$4:$N$3003,'首页'!$B$4*100+E$5)+SUMIFS('[1]资金台帐'!$G$4:$G$3003,'[1]资金台帐'!$I$4:$I$3003,'[1]基础资料'!$A$8,'[1]资金台帐'!$M$4:$M$3003,"内部转账",'[1]资金台帐'!$N$4:$N$3003,'首页'!$B$4*100+E$5)-SUMIFS('[1]资金台帐'!$H$4:$H$3003,'[1]资金台帐'!$I$4:$I$3003,'[1]基础资料'!$A$8,'[1]资金台帐'!$M$4:$M$3003,"内部转账",'[1]资金台帐'!$N$4:$N$3003,'首页'!$B$4*100+E$5) -> 0 | F27: =SUMIFS('[1]资金台帐'!$H$4:$H$3003,'[1]资金台帐'!$B$4:$B$3003,'[1]基础资料'!$A$8,'[1]资金台帐'!$M$4:$M$3003,"内部转账",'[1]资金台帐'!$N$4:$N$3003,'首页'!$B$4*100+F$5)-SUMIFS('[1]资金台帐'!$G$4:$G$3003,'[1]资金台帐'!$B$4:$B$3003,'[1]基础资料'!$A$8,'[1]资金台帐'!$M$4:$M$3003,"内部转账",'[1]资金台帐'!$N$4:$N$3003,'首页'!$B$4*100+F$5)+SUMIFS('[1]资金台帐'!$G$4:$G$3003,'[1]资金台帐'!$I$4:$I$3003,'[1]基础资料'!$A$8,'[1]资金台帐'!$M$4:$M$3003,"内部转账",'[1]资金台帐'!$N$4:$N$3003,'首页'!$B$4*100+F$5)-SUMIFS('[1]资金台帐'!$H$4:$H$3003,'[1]资金台帐'!$I$4:$I$3003,'[1]基础资料'!$A$8,'[1]资金台帐'!$M$4:$M$3003,"内部转账",'[1]资金台帐'!$N$4:$N$3003,'首页'!$B$4*100+F$5) -> 0 | G27: =SUMIFS('[1]资金台帐'!$H$4:$H$3003,'[1]资金台帐'!$B$4:$B$3003,'[1]基础资料'!$A$8,'[1]资金台帐'!$M$4:$M$3003,"内部转账",'[1]资金台帐'!$N$4:$N$3003,'首页'!$B$4*100+G$5)-SUMIFS('[1]资金台帐'!$G$4:$G$3003,'[1]资金台帐'!$B$4:$B$3003,'[1]基础资料'!$A$8,'[1]资金台帐'!$M$4:$M$3003,"内部转账",'[1]资金台帐'!$N$4:$N$3003,'首页'!$B$4*100+G$5)+SUMIFS('[1]资金台帐'!$G$4:$G$3003,'[1]资金台帐'!$I$4:$I$3003,'[1]基础资料'!$A$8,'[1]资金台帐'!$M$4:$M$3003,"内部转账",'[1]资金台帐'!$N$4:$N$3003,'首页'!$B$4*100+G$5)-SUMIFS('[1]资金台帐'!$H$4:$H$3003,'[1]资金台帐'!$I$4:$I$3003,'[1]基础资料'!$A$8,'[1]资金台帐'!$M$4:$M$3003,"内部转账",'[1]资金台帐'!$N$4:$N$3003,'首页'!$B$4*100+G$5) -> 0 | H27: =SUMIFS('[1]资金台帐'!$H$4:$H$3003,'[1]资金台帐'!$B$4:$B$3003,'[1]基础资料'!$A$8,'[1]资金台帐'!$M$4:$M$3003,"内部转账",'[1]资金台帐'!$N$4:$N$3003,'首页'!$B$4*100+H$5)-SUMIFS('[1]资金台帐'!$G$4:$G$3003,'[1]资金台帐'!$B$4:$B$3003,'[1]基础资料'!$A$8,'[1]资金台帐'!$M$4:$M$3003,"内部转账",'[1]资金台帐'!$N$4:$N$3003,'首页'!$B$4*100+H$5)+SUMIFS('[1]资金台帐'!$G$4:$G$3003,'[1]资金台帐'!$I$4:$I$3003,'[1]基础资料'!$A$8,'[1]资金台帐'!$M$4:$M$3003,"内部转账",'[1]资金台帐'!$N$4:$N$3003,'首页'!$B$4*100+H$5)-SUMIFS('[1]资金台帐'!$H$4:$H$3003,'[1]资金台帐'!$I$4:$I$3003,'[1]基础资料'!$A$8,'[1]资金台帐'!$M$4:$M$3003,"内部转账",'[1]资金台帐'!$N$4:$N$3003,'首页'!$B$4*100+H$5) -> 0 | I27: =SUMIFS('[1]资金台帐'!$H$4:$H$3003,'[1]资金台帐'!$B$4:$B$3003,'[1]基础资料'!$A$8,'[1]资金台帐'!$M$4:$M$3003,"内部转账",'[1]资金台帐'!$N$4:$N$3003,'首页'!$B$4*100+I$5)-SUMIFS('[1]资金台帐'!$G$4:$G$3003,'[1]资金台帐'!$B$4:$B$3003,'[1]基础资料'!$A$8,'[1]资金台帐'!$M$4:$M$3003,"内部转账",'[1]资金台帐'!$N$4:$N$3003,'首页'!$B$4*100+I$5)+SUMIFS('[1]资金台帐'!$G$4:$G$3003,'[1]资金台帐'!$I$4:$I$3003,'[1]基础资料'!$A$8,'[1]资金台帐'!$M$4:$M$3003,"内部转账",'[1]资金台帐'!$N$4:$N$3003,'首页'!$B$4*100+I$5)-SUMIFS('[1]资金台帐'!$H$4:$H$3003,'[1]资金台帐'!$I$4:$I$3003,'[1]基础资料'!$A$8,'[1]资金台帐'!$M$4:$M$3003,"内部转账",'[1]资金台帐'!$N$4:$N$3003,'首页'!$B$4*100+I$5) -> 0 | J27: =SUMIFS('[1]资金台帐'!$H$4:$H$3003,'[1]资金台帐'!$B$4:$B$3003,'[1]基础资料'!$A$8,'[1]资金台帐'!$M$4:$M$3003,"内部转账",'[1]资金台帐'!$N$4:$N$3003,'首页'!$B$4*100+J$5)-SUMIFS('[1]资金台帐'!$G$4:$G$3003,'[1]资金台帐'!$B$4:$B$3003,'[1]基础资料'!$A$8,'[1]资金台帐'!$M$4:$M$3003,"内部转账",'[1]资金台帐'!$N$4:$N$3003,'首页'!$B$4*100+J$5)+SUMIFS('[1]资金台帐'!$G$4:$G$3003,'[1]资金台帐'!$I$4:$I$3003,'[1]基础资料'!$A$8,'[1]资金台帐'!$M$4:$M$3003,"内部转账",'[1]资金台帐'!$N$4:$N$3003,'首页'!$B$4*100+J$5)-SUMIFS('[1]资金台帐'!$H$4:$H$3003,'[1]资金台帐'!$I$4:$I$3003,'[1]基础资料'!$A$8,'[1]资金台帐'!$M$4:$M$3003,"内部转账",'[1]资金台帐'!$N$4:$N$3003,'首页'!$B$4*100+J$5) -> 0 | ... N27: =SUMIFS('[1]资金台帐'!$H$4:$H$3003,'[1]资金台帐'!$B$4:$B$3003,'[1]基础资料'!$A$8,'[1]资金台帐'!$M$4:$M$3003,"内部转账",'[1]资金台帐'!$N$4:$N$3003,'首页'!$B$4*100+N$5)-SUMIFS('[1]资金台帐'!$G$4:$G$3003,'[1]资金台帐'!$B$4:$B$3003,'[1]基础资料'!$A$8,'[1]资金台帐'!$M$4:$M$3003,"内部转账",'[1]资金台帐'!$N$4:$N$3003,'首页'!$B$4*100+N$5)+SUMIFS('[1]资金台帐'!$G$4:$G$3003,'[1]资金台帐'!$I$4:$I$3003,'[1]基础资料'!$A$8,'[1]资金台帐'!$M$4:$M$3003,"内部转账",'[1]资金台帐'!$N$4:$N$3003,'首页'!$B$4*100+N$5)-SUMIFS('[1]资金台帐'!$H$4:$H$3003,'[1]资金台帐'!$I$4:$I$3003,'[1]基础资料'!$A$8,'[1]资金台帐'!$M$4:$M$3003,"内部转账",'[1]资金台帐'!$N$4:$N$3003,'首页'!$B$4*100+N$5) -> 0 | O27: =SUM(C27:N27) -> 100000
A28: 提现差异（台帐－账务明细） | C28: =ROUND(C27+SUMIFS('[1]粘贴_账务明细'!$K$4:$K$3003,'[1]粘贴_账务明细'!$L$4:$L$3003,"提现",'[1]粘贴_账务明细'!$I$4:$I$3003,'首页'!$B$4*100+C$5),2) -> 0 | D28: =ROUND(D27+SUMIFS('[1]粘贴_账务明细'!$K$4:$K$3003,'[1]粘贴_账务明细'!$L$4:$L$3003,"提现",'[1]粘贴_账务明细'!$I$4:$I$3003,'首页'!$B$4*100+D$5),2) -> 0 | E28: =ROUND(E27+SUMIFS('[1]粘贴_账务明细'!$K$4:$K$3003,'[1]粘贴_账务明细'!$L$4:$L$3003,"提现",'[1]粘贴_账务明细'!$I$4:$I$3003,'首页'!$B$4*100+E$5),2) -> 0 | F28: =ROUND(F27+SUMIFS('[1]粘贴_账务明细'!$K$4:$K$3003,'[1]粘贴_账务明细'!$L$4:$L$3003,"提现",'[1]粘贴_账务明细'!$I$4:$I$3003,'首页'!$B$4*100+F$5),2) -> 0 | G28: =ROUND(G27+SUMIFS('[1]粘贴_账务明细'!$K$4:$K$3003,'[1]粘贴_账务明细'!$L$4:$L$3003,"提现",'[1]粘贴_账务明细'!$I$4:$I$3003,'首页'!$B$4*100+G$5),2) -> 0 | H28: =ROUND(H27+SUMIFS('[1]粘贴_账务明细'!$K$4:$K$3003,'[1]粘贴_账务明细'!$L$4:$L$3003,"提现",'[1]粘贴_账务明细'!$I$4:$I$3003,'首页'!$B$4*100+H$5),2) -> 0 | I28: =ROUND(I27+SUMIFS('[1]粘贴_账务明细'!$K$4:$K$3003,'[1]粘贴_账务明细'!$L$4:$L$3003,"提现",'[1]粘贴_账务明细'!$I$4:$I$3003,'首页'!$B$4*100+I$5),2) -> 0 | J28: =ROUND(J27+SUMIFS('[1]粘贴_账务明细'!$K$4:$K$3003,'[1]粘贴_账务明细'!$L$4:$L$3003,"提现",'[1]粘贴_账务明细'!$I$4:$I$3003,'首页'!$B$4*100+J$5),2) -> 0 | ... N28: =ROUND(N27+SUMIFS('[1]粘贴_账务明细'!$K$4:$K$3003,'[1]粘贴_账务明细'!$L$4:$L$3003,"提现",'[1]粘贴_账务明细'!$I$4:$I$3003,'首页'!$B$4*100+N$5),2) -> 0 | O28: =SUM(C28:N28) -> 0
A30: 二、批次核对 A. 账务明细里到账的批次（补贴汇入／技术服务费返还）→ 对账单里同一批次号的合计 | P30: ='[1]粘贴_账务明细'!$N$3003 -> 7 | Q30: ← 批数
A31: 序 | B31: 到账时间 | C31: 类型 | D31: 批次号 | E31: 到账金额 | F31: 营销活动对账单 | G31: 服务费返还账单 | H31: 对账单笔数 | I31: 差额 | J31: 结论 | P31: (位置)
A32: 1 | B32: =IF($P32="","",INDEX('[1]粘贴_账务明细'!$H$4:$H$3003,$P32)) -> 46289.375 | C32: =IF($P32="","",INDEX('[1]粘贴_账务明细'!$L$4:$L$3003,$P32)) -> 技术服务费返还 | D32: =IF($P32="","",INDEX('[1]粘贴_账务明细'!$M$4:$M$3003,$P32)) -> BO260915078057502 | E32: =IF($P32="","",INDEX('[1]粘贴_账务明细'!$K$4:$K$3003,$P32)) -> 4586.81 | F32: =IF($P32="","",SUMIFS('[1]粘贴_营销活动'!$M$4:$M$3003,'[1]粘贴_营销活动'!$I$4:$I$3003,$D32)) -> 0 | G32: =IF($P32="","",SUMIFS('[1]粘贴_服务费返还'!$M$4:$M$3003,'[1]粘贴_服务费返还'!$I$4:$I$3003,$D32)) -> 4586.81 | H32: =IF($P32="","",COUNTIFS('[1]粘贴_营销活动'!$I$4:$I$3003,$D32)+COUNTIFS('[1]粘贴_服务费返还'!$I$4:$I$3003,$D32)) -> 65 | I32: =IF($P32="","",ROUND(E32-F32-G32,2)) -> 0 | J32: =IF($P32="","",IF(H32=0,"对账单里没有这批明细",IF(ABS(I32)<0.01,"对上","差 "&TEXT(I32,"0.00")))) -> 对上 | P32: =IF(A32>$P$30,"",MATCH(A32,'[1]粘贴_账务明细'!$N$4:$N$3003,0)) -> 93
A33: 2 | B33: =IF($P33="","",INDEX('[1]粘贴_账务明细'!$H$4:$H$3003,$P33)) -> 46280.006 | C33: =IF($P33="","",INDEX('[1]粘贴_账务明细'!$L$4:$L$3003,$P33)) -> 补贴汇入 | D33: =IF($P33="","",INDEX('[1]粘贴_账务明细'!$M$4:$M$3003,$P33)) -> BO260825067002610 | E33: =IF($P33="","",INDEX('[1]粘贴_账务明细'!$K$4:$K$3003,$P33)) -> 690 | F33: =IF($P33="","",SUMIFS('[1]粘贴_营销活动'!$M$4:$M$3003,'[1]粘贴_营销活动'!$I$4:$I$3003,$D33)) -> 0 | G33: =IF($P33="","",SUMIFS('[1]粘贴_服务费返还'!$M$4:$M$3003,'[1]粘贴_服务费返还'!$I$4:$I$3003,$D33)) -> 0 | H33: =IF($P33="","",COUNTIFS('[1]粘贴_营销活动'!$I$4:$I$3003,$D33)+COUNTIFS('[1]粘贴_服务费返还'!$I$4:$I$3003,$D33)) -> 0 | I33: =IF($P33="","",ROUND(E33-F33-G33,2)) -> 690 | J33: =IF($P33="","",IF(H33=0,"对账单里没有这批明细",IF(ABS(I33)<0.01,"对上","差 "&TEXT(I33,"0.00")))) -> 对账单里没有这批明细 | P33: =IF(A33>$P$30,"",MATCH(A33,'[1]粘贴_账务明细'!$N$4:$N$3003,0)) -> 239
A34: 3 | B34: =IF($P34="","",INDEX('[1]粘贴_账务明细'!$H$4:$H$3003,$P34)) -> 46280.006 | C34: =IF($P34="","",INDEX('[1]粘贴_账务明细'!$L$4:$L$3003,$P34)) -> 补贴汇入 | D34: =IF($P34="","",INDEX('[1]粘贴_账务明细'!$M$4:$M$3003,$P34)) -> BO260904188542622 | E34: =IF($P34="","",INDEX('[1]粘贴_账务明细'!$K$4:$K$3003,$P34)) -> 310 | F34: =IF($P34="","",SUMIFS('[1]粘贴_营销活动'!$M$4:$M$3003,'[1]粘贴_营销活动'!$I$4:$I$3003,$D34)) -> 0 | G34: =IF($P34="","",SUMIFS('[1]粘贴_服务费返还'!$M$4:$M$3003,'[1]粘贴_服务费返还'!$I$4:$I$3003,$D34)) -> 0 | H34: =IF($P34="","",COUNTIFS('[1]粘贴_营销活动'!$I$4:$I$3003,$D34)+COUNTIFS('[1]粘贴_服务费返还'!$I$4:$I$3003,$D34)) -> 0 | I34: =IF($P34="","",ROUND(E34-F34-G34,2)) -> 310 | J34: =IF($P34="","",IF(H34=0,"对账单里没有这批明细",IF(ABS(I34)<0.01,"对上","差 "&TEXT(I34,"0.00")))) -> 对账单里没有这批明细 | P34: =IF(A34>$P$30,"",MATCH(A34,'[1]粘贴_账务明细'!$N$4:$N$3003,0)) -> 240
A35: 4 | B35: =IF($P35="","",INDEX('[1]粘贴_账务明细'!$H$4:$H$3003,$P35)) -> 46280.005 | C35: =IF($P35="","",INDEX('[1]粘贴_账务明细'!$L$4:$L$3003,$P35)) -> 补贴汇入 | D35: =IF($P35="","",INDEX('[1]粘贴_账务明细'!$M$4:$M$3003,$P35)) -> BO260828184556094 | E35: =IF($P35="","",INDEX('[1]粘贴_账务明细'!$K$4:$K$3003,$P35)) -> 600 | F35: =IF($P35="","",SUMIFS('[1]粘贴_营销活动'!$M$4:$M$3003,'[1]粘贴_营销活动'!$I$4:$I$3003,$D35)) -> 0 | G35: =IF($P35="","",SUMIFS('[1]粘贴_服务费返还'!$M$4:$M$3003,'[1]粘贴_服务费返还'!$I$4:$I$3003,$D35)) -> 0 | H35: =IF($P35="","",COUNTIFS('[1]粘贴_营销活动'!$I$4:$I$3003,$D35)+COUNTIFS('[1]粘贴_服务费返还'!$I$4:$I$3003,$D35)) -> 0 | I35: =IF($P35="","",ROUND(E35-F35-G35,2)) -> 600 | J35: =IF($P35="","",IF(H35=0,"对账单里没有这批明细",IF(ABS(I35)<0.01,"对上","差 "&TEXT(I35,"0.00")))) -> 对账单里没有这批明细 | P35: =IF(A35>$P$30,"",MATCH(A35,'[1]粘贴_账务明细'!$N$4:$N$3003,0)) -> 241
A36: 5 | B36: =IF($P36="","",INDEX('[1]粘贴_账务明细'!$H$4:$H$3003,$P36)) -> 46280.005 | C36: =IF($P36="","",INDEX('[1]粘贴_账务明细'!$L$4:$L$3003,$P36)) -> 补贴汇入 | D36: =IF($P36="","",INDEX('[1]粘贴_账务明细'!$M$4:$M$3003,$P36)) -> BO260904071810200 | E36: =IF($P36="","",INDEX('[1]粘贴_账务明细'!$K$4:$K$3003,$P36)) -> 660 | F36: =IF($P36="","",SUMIFS('[1]粘贴_营销活动'!$M$4:$M$3003,'[1]粘贴_营销活动'!$I$4:$I$3003,$D36)) -> 0 | G36: =IF($P36="","",SUMIFS('[1]粘贴_服务费返还'!$M$4:$M$3003,'[1]粘贴_服务费返还'!$I$4:$I$3003,$D36)) -> 0 | H36: =IF($P36="","",COUNTIFS('[1]粘贴_营销活动'!$I$4:$I$3003,$D36)+COUNTIFS('[1]粘贴_服务费返还'!$I$4:$I$3003,$D36)) -> 0 | I36: =IF($P36="","",ROUND(E36-F36-G36,2)) -> 660 | J36: =IF($P36="","",IF(H36=0,"对账单里没有这批明细",IF(ABS(I36)<0.01,"对上","差 "&TEXT(I36,"0.00")))) -> 对账单里没有这批明细 | P36: =IF(A36>$P$30,"",MATCH(A36,'[1]粘贴_账务明细'!$N$4:$N$3003,0)) -> 242
A37: 6 | B37: =IF($P37="","",INDEX('[1]粘贴_账务明细'!$H$4:$H$3003,$P37)) -> 46280.005 | C37: =IF($P37="","",INDEX('[1]粘贴_账务明细'!$L$4:$L$3003,$P37)) -> 补贴汇入 | D37: =IF($P37="","",INDEX('[1]粘贴_账务明细'!$M$4:$M$3003,$P37)) -> BO260828184181181 | E37: =IF($P37="","",INDEX('[1]粘贴_账务明细'!$K$4:$K$3003,$P37)) -> 1710 | F37: =IF($P37="","",SUMIFS('[1]粘贴_营销活动'!$M$4:$M$3003,'[1]粘贴_营销活动'!$I$4:$I$3003,$D37)) -> 0 | G37: =IF($P37="","",SUMIFS('[1]粘贴_服务费返还'!$M$4:$M$3003,'[1]粘贴_服务费返还'!$I$4:$I$3003,$D37)) -> 0 | H37: =IF($P37="","",COUNTIFS('[1]粘贴_营销活动'!$I$4:$I$3003,$D37)+COUNTIFS('[1]粘贴_服务费返还'!$I$4:$I$3003,$D37)) -> 0 | I37: =IF($P37="","",ROUND(E37-F37-G37,2)) -> 1710 | J37: =IF($P37="","",IF(H37=0,"对账单里没有这批明细",IF(ABS(I37)<0.01,"对上","差 "&TEXT(I37,"0.00")))) -> 对账单里没有这批明细 | P37: =IF(A37>$P$30,"",MATCH(A37,'[1]粘贴_账务明细'!$N$4:$N$3003,0)) -> 243
A38: 7 | B38: =IF($P38="","",INDEX('[1]粘贴_账务明细'!$H$4:$H$3003,$P38)) -> 46273.4 | C38: =IF($P38="","",INDEX('[1]粘贴_账务明细'!$L$4:$L$3003,$P38)) -> 技术服务费返还 | D38: =IF($P38="","",INDEX('[1]粘贴_账务明细'!$M$4:$M$3003,$P38)) -> BO260904188278880 | E38: =IF($P38="","",INDEX('[1]粘贴_账务明细'!$K$4:$K$3003,$P38)) -> 21.59 | F38: =IF($P38="","",SUMIFS('[1]粘贴_营销活动'!$M$4:$M$3003,'[1]粘贴_营销活动'!$I$4:$I$3003,$D38)) -> 0 | G38: =IF($P38="","",SUMIFS('[1]粘贴_服务费返还'!$M$4:$M$3003,'[1]粘贴_服务费返还'!$I$4:$I$3003,$D38)) -> 0 | H38: =IF($P38="","",COUNTIFS('[1]粘贴_营销活动'!$I$4:$I$3003,$D38)+COUNTIFS('[1]粘贴_服务费返还'!$I$4:$I$3003,$D38)) -> 0 | I38: =IF($P38="","",ROUND(E38-F38-G38,2)) -> 21.59 | J38: =IF($P38="","",IF(H38=0,"对账单里没有这批明细",IF(ABS(I38)<0.01,"对上","差 "&TEXT(I38,"0.00")))) -> 对账单里没有这批明细 | P38: =IF(A38>$P$30,"",MATCH(A38,'[1]粘贴_账务明细'!$N$4:$N$3003,0)) -> 292
A39: 8 | B39: =IF($P39="","",INDEX('[1]粘贴_账务明细'!$H$4:$H$3003,$P39)) | C39: =IF($P39="","",INDEX('[1]粘贴_账务明细'!$L$4:$L$3003,$P39)) | D39: =IF($P39="","",INDEX('[1]粘贴_账务明细'!$M$4:$M$3003,$P39)) | E39: =IF($P39="","",INDEX('[1]粘贴_账务明细'!$K$4:$K$3003,$P39)) | F39: =IF($P39="","",SUMIFS('[1]粘贴_营销活动'!$M$4:$M$3003,'[1]粘贴_营销活动'!$I$4:$I$3003,$D39)) | G39: =IF($P39="","",SUMIFS('[1]粘贴_服务费返还'!$M$4:$M$3003,'[1]粘贴_服务费返还'!$I$4:$I$3003,$D39)) | H39: =IF($P39="","",COUNTIFS('[1]粘贴_营销活动'!$I$4:$I$3003,$D39)+COUNTIFS('[1]粘贴_服务费返还'!$I$4:$I$3003,$D39)) | I39: =IF($P39="","",ROUND(E39-F39-G39,2)) | J39: =IF($P39="","",IF(H39=0,"对账单里没有这批明细",IF(ABS(I39)<0.01,"对上","差 "&TEXT(I39,"0.00")))) | P39: =IF(A39>$P$30,"",MATCH(A39,'[1]粘贴_账务明细'!$N$4:$N$3003,0))
A40: 9 | B40: =IF($P40="","",INDEX('[1]粘贴_账务明细'!$H$4:$H$3003,$P40)) | C40: =IF($P40="","",INDEX('[1]粘贴_账务明细'!$L$4:$L$3003,$P40)) | D40: =IF($P40="","",INDEX('[1]粘贴_账务明细'!$M$4:$M$3003,$P40)) | E40: =IF($P40="","",INDEX('[1]粘贴_账务明细'!$K$4:$K$3003,$P40)) | F40: =IF($P40="","",SUMIFS('[1]粘贴_营销活动'!$M$4:$M$3003,'[1]粘贴_营销活动'!$I$4:$I$3003,$D40)) | G40: =IF($P40="","",SUMIFS('[1]粘贴_服务费返还'!$M$4:$M$3003,'[1]粘贴_服务费返还'!$I$4:$I$3003,$D40)) | H40: =IF($P40="","",COUNTIFS('[1]粘贴_营销活动'!$I$4:$I$3003,$D40)+COUNTIFS('[1]粘贴_服务费返还'!$I$4:$I$3003,$D40)) | I40: =IF($P40="","",ROUND(E40-F40-G40,2)) | J40: =IF($P40="","",IF(H40=0,"对账单里没有这批明细",IF(ABS(I40)<0.01,"对上","差 "&TEXT(I40,"0.00")))) | P40: =IF(A40>$P$30,"",MATCH(A40,'[1]粘贴_账务明细'!$N$4:$N$3003,0))
A41: 10 | B41: =IF($P41="","",INDEX('[1]粘贴_账务明细'!$H$4:$H$3003,$P41)) | C41: =IF($P41="","",INDEX('[1]粘贴_账务明细'!$L$4:$L$3003,$P41)) | D41: =IF($P41="","",INDEX('[1]粘贴_账务明细'!$M$4:$M$3003,$P41)) | E41: =IF($P41="","",INDEX('[1]粘贴_账务明细'!$K$4:$K$3003,$P41)) | F41: =IF($P41="","",SUMIFS('[1]粘贴_营销活动'!$M$4:$M$3003,'[1]粘贴_营销活动'!$I$4:$I$3003,$D41)) | G41: =IF($P41="","",SUMIFS('[1]粘贴_服务费返还'!$M$4:$M$3003,'[1]粘贴_服务费返还'!$I$4:$I$3003,$D41)) | H41: =IF($P41="","",COUNTIFS('[1]粘贴_营销活动'!$I$4:$I$3003,$D41)+COUNTIFS('[1]粘贴_服务费返还'!$I$4:$I$3003,$D41)) | I41: =IF($P41="","",ROUND(E41-F41-G41,2)) | J41: =IF($P41="","",IF(H41=0,"对账单里没有这批明细",IF(ABS(I41)<0.01,"对上","差 "&TEXT(I41,"0.00")))) | P41: =IF(A41>$P$30,"",MATCH(A41,'[1]粘贴_账务明细'!$N$4:$N$3003,0))
A42: 11 | B42: =IF($P42="","",INDEX('[1]粘贴_账务明细'!$H$4:$H$3003,$P42)) | C42: =IF($P42="","",INDEX('[1]粘贴_账务明细'!$L$4:$L$3003,$P42)) | D42: =IF($P42="","",INDEX('[1]粘贴_账务明细'!$M$4:$M$3003,$P42)) | E42: =IF($P42="","",INDEX('[1]粘贴_账务明细'!$K$4:$K$3003,$P42)) | F42: =IF($P42="","",SUMIFS('[1]粘贴_营销活动'!$M$4:$M$3003,'[1]粘贴_营销活动'!$I$4:$I$3003,$D42)) | G42: =IF($P42="","",SUMIFS('[1]粘贴_服务费返还'!$M$4:$M$3003,'[1]粘贴_服务费返还'!$I$4:$I$3003,$D42)) | H42: =IF($P42="","",COUNTIFS('[1]粘贴_营销活动'!$I$4:$I$3003,$D42)+COUNTIFS('[1]粘贴_服务费返还'!$I$4:$I$3003,$D42)) | I42: =IF($P42="","",ROUND(E42-F42-G42,2)) | J42: =IF($P42="","",IF(H42=0,"对账单里没有这批明细",IF(ABS(I42)<0.01,"对上","差 "&TEXT(I42,"0.00")))) | P42: =IF(A42>$P$30,"",MATCH(A42,'[1]粘贴_账务明细'!$N$4:$N$3003,0))
...

Sheet 技术服务费核对
A1: A076 技术服务费核对（百亿补贴技术服务费 1.4% 返还，逐单）
A2: 百亿补贴的单，确认收货时账务明细扣「基础技术服务费 0.6%」＋「百亿补贴技术服务费 1.4%」；1.4% 这部分平台过后按批次返还（返还账单一单一行，账务明细里只有一笔批次总额）。下面「三」逐单看：扣了多少、返了多少、有没有返了又扣回（订单号带 -t01）。返还一般晚一个月左右，所以要把扣费那个月和返还那个月的账务明细都粘进录入本。
A4: 一、汇总
B5: 返还账单：返还笔数 | C5: =COUNTIFS('[1]粘贴_服务费返还'!$O$4:$O$3003,"返还") -> 64 | E5: 账务明细：扣了百亿费的订单数 | H5: ='[1]粘贴_账务明细'!$O$3003 -> 84 | J5: 账务明细最后一天
B6: 返还合计 | C6: =SUMIFS('[1]粘贴_服务费返还'!$M$4:$M$3003,'[1]粘贴_服务费返还'!$O$4:$O$3003,"返还") -> 4637.2 | E6: 实扣百亿费合计 | H6: =SUM(F29:F428) -> 2183.3 | J6: =MAX('[1]粘贴_账务明细'!$H$4:$H$3003) -> 46295.446
B7: 扣回笔数（-t01） | C7: =COUNTIFS('[1]粘贴_服务费返还'!$O$4:$O$3003,"扣回") -> 1 | E7: 订单已退款、不用返（单） | H7: =COUNTIF(J29:J428,"订单已退款*") -> 44
B8: 扣回合计 | C8: =SUMIFS('[1]粘贴_服务费返还'!$M$4:$M$3003,'[1]粘贴_服务费返还'!$O$4:$O$3003,"扣回") -> -50.39 | E8: 已返还（单） | H8: =COUNTIF(J29:J428,"已返还") -> 0
B9: 净返还 | C9: =C6+C8 -> 4586.81 | E9: 已返还金额 | H9: =SUMIFS(G29:G428,J29:J428,"已返还") -> 0
B10: 账务明细里找不到这单（笔） | C10: =COUNTIFS('[1]粘贴_服务费返还'!$P$4:$P$3003,"没有",'[1]粘贴_服务费返还'!$O$4:$O$3003,"返还") -> 64 | E10: 扣了还没返（单） | H10: =COUNTIF(J29:J428,"扣了还没返") -> 40
B11: 金额（扣费在更早月份） | C11: =SUMIFS('[1]粘贴_服务费返还'!$M$4:$M$3003,'[1]粘贴_服务费返还'!$P$4:$P$3003,"没有",'[1]粘贴_服务费返还'!$O$4:$O$3003,"返还") -> 4637.2 | E11: 扣了还没返金额 | H11: =SUMIFS(I29:I428,J29:J428,"扣了还没返") -> 2183.3
E12: 少返／返了又扣回（单） | H12: =COUNTIF(J29:J428,"少返*")+COUNTIF(J29:J428,"返了又扣回*") -> 0
A15: 二、返了又扣回（返还账单里订单号带 -t01 的负数行）
A16: 序 | B16: 账单订单号 | C16: 原订单号 | D16: 金额 | E16: 批次号 | F16: 结算时间 | L16: (位置)
A17: 1 | B17: =IF($L17="","",INDEX('[1]粘贴_服务费返还'!$A$4:$A$3003,$L17)) -> 260819-158733494712735-t01 | C17: =IF($L17="","",INDEX('[1]粘贴_服务费返还'!$N$4:$N$3003,$L17)) -> 260819-158733494712735 | D17: =IF($L17="","",INDEX('[1]粘贴_服务费返还'!$M$4:$M$3003,$L17)) -> -50.39 | E17: =IF($L17="","",INDEX('[1]粘贴_服务费返还'!$I$4:$I$3003,$L17)) -> BO260915078057502 | F17: =IF($L17="","",INDEX('[1]粘贴_服务费返还'!$K$4:$K$3003,$L17)) -> 2026-09-24 08:59:43 | L17: =IFERROR(MATCH(A17,'[1]粘贴_服务费返还'!$S$4:$S$3003,0),"") -> 35
A18: 2 | B18: =IF($L18="","",INDEX('[1]粘贴_服务费返还'!$A$4:$A$3003,$L18)) | C18: =IF($L18="","",INDEX('[1]粘贴_服务费返还'!$N$4:$N$3003,$L18)) | D18: =IF($L18="","",INDEX('[1]粘贴_服务费返还'!$M$4:$M$3003,$L18)) | E18: =IF($L18="","",INDEX('[1]粘贴_服务费返还'!$I$4:$I$3003,$L18)) | F18: =IF($L18="","",INDEX('[1]粘贴_服务费返还'!$K$4:$K$3003,$L18)) | L18: =IFERROR(MATCH(A18,'[1]粘贴_服务费返还'!$S$4:$S$3003,0),"")
A19: 3 | B19: =IF($L19="","",INDEX('[1]粘贴_服务费返还'!$A$4:$A$3003,$L19)) | C19: =IF($L19="","",INDEX('[1]粘贴_服务费返还'!$N$4:$N$3003,$L19)) | D19: =IF($L19="","",INDEX('[1]粘贴_服务费返还'!$M$4:$M$3003,$L19)) | E19: =IF($L19="","",INDEX('[1]粘贴_服务费返还'!$I$4:$I$3003,$L19)) | F19: =IF($L19="","",INDEX('[1]粘贴_服务费返还'!$K$4:$K$3003,$L19)) | L19: =IFERROR(MATCH(A19,'[1]粘贴_服务费返还'!$S$4:$S$3003,0),"")
A20: 4 | B20: =IF($L20="","",INDEX('[1]粘贴_服务费返还'!$A$4:$A$3003,$L20)) | C20: =IF($L20="","",INDEX('[1]粘贴_服务费返还'!$N$4:$N$3003,$L20)) | D20: =IF($L20="","",INDEX('[1]粘贴_服务费返还'!$M$4:$M$3003,$L20)) | E20: =IF($L20="","",INDEX('[1]粘贴_服务费返还'!$I$4:$I$3003,$L20)) | F20: =IF($L20="","",INDEX('[1]粘贴_服务费返还'!$K$4:$K$3003,$L20)) | L20: =IFERROR(MATCH(A20,'[1]粘贴_服务费返还'!$S$4:$S$3003,0),"")
A21: 5 | B21: =IF($L21="","",INDEX('[1]粘贴_服务费返还'!$A$4:$A$3003,$L21)) | C21: =IF($L21="","",INDEX('[1]粘贴_服务费返还'!$N$4:$N$3003,$L21)) | D21: =IF($L21="","",INDEX('[1]粘贴_服务费返还'!$M$4:$M$3003,$L21)) | E21: =IF($L21="","",INDEX('[1]粘贴_服务费返还'!$I$4:$I$3003,$L21)) | F21: =IF($L21="","",INDEX('[1]粘贴_服务费返还'!$K$4:$K$3003,$L21)) | L21: =IFERROR(MATCH(A21,'[1]粘贴_服务费返还'!$S$4:$S$3003,0),"")
A22: 6 | B22: =IF($L22="","",INDEX('[1]粘贴_服务费返还'!$A$4:$A$3003,$L22)) | C22: =IF($L22="","",INDEX('[1]粘贴_服务费返还'!$N$4:$N$3003,$L22)) | D22: =IF($L22="","",INDEX('[1]粘贴_服务费返还'!$M$4:$M$3003,$L22)) | E22: =IF($L22="","",INDEX('[1]粘贴_服务费返还'!$I$4:$I$3003,$L22)) | F22: =IF($L22="","",INDEX('[1]粘贴_服务费返还'!$K$4:$K$3003,$L22)) | L22: =IFERROR(MATCH(A22,'[1]粘贴_服务费返还'!$S$4:$S$3003,0),"")
A23: 7 | B23: =IF($L23="","",INDEX('[1]粘贴_服务费返还'!$A$4:$A$3003,$L23)) | C23: =IF($L23="","",INDEX('[1]粘贴_服务费返还'!$N$4:$N$3003,$L23)) | D23: =IF($L23="","",INDEX('[1]粘贴_服务费返还'!$M$4:$M$3003,$L23)) | E23: =IF($L23="","",INDEX('[1]粘贴_服务费返还'!$I$4:$I$3003,$L23)) | F23: =IF($L23="","",INDEX('[1]粘贴_服务费返还'!$K$4:$K$3003,$L23)) | L23: =IFERROR(MATCH(A23,'[1]粘贴_服务费返还'!$S$4:$S$3003,0),"")
A24: 8 | B24: =IF($L24="","",INDEX('[1]粘贴_服务费返还'!$A$4:$A$3003,$L24)) | C24: =IF($L24="","",INDEX('[1]粘贴_服务费返还'!$N$4:$N$3003,$L24)) | D24: =IF($L24="","",INDEX('[1]粘贴_服务费返还'!$M$4:$M$3003,$L24)) | E24: =IF($L24="","",INDEX('[1]粘贴_服务费返还'!$I$4:$I$3003,$L24)) | F24: =IF($L24="","",INDEX('[1]粘贴_服务费返还'!$K$4:$K$3003,$L24)) | L24: =IFERROR(MATCH(A24,'[1]粘贴_服务费返还'!$S$4:$S$3003,0),"")
A27: 三、逐单：账务明细里扣了「百亿补贴技术服务费」的订单（最多 400 单）
A28: 序 | B28: 订单号 | C28: 扣费时间 | D28: 订单价 | E28: 应返(1.4%) | F28: 实扣百亿费 | G28: 已返还 | H28: 扣回 | I28: 待返 | J28: 状态 | K28: 距账务明细 最后一天(天) | L28: (位置)
A29: 1 | B29: =IF($L29="","",INDEX('[1]粘贴_账务明细'!$A$4:$A$3003,$L29)) -> 260925-191061040790069 | C29: =IF($L29="","",INDEX('[1]粘贴_账务明细'!$H$4:$H$3003,$L29)) -> 46294.771 | D29: =IF($L29="","",SUMIFS('[1]粘贴_账务明细'!$K$4:$K$3003,'[1]粘贴_账务明细'!$A$4:$A$3003,$B29,'[1]粘贴_账务明细'!$L$4:$L$3003,"订单收入")+SUMIFS('[1]粘贴_账务明细'!$K$4:$K$3003,'[1]粘贴_账务明细'!$A$4:$A$3003,$B29,'[1]粘贴_账务明细'!$L$4:$L$3003,"优惠券结算")) -> 3499 | E29: =IF($L29="","",ROUND(D29*0.014,2)) -> 48.99 | F29: =IF($L29="","",-SUMIFS('[1]粘贴_账务明细'!$K$4:$K$3003,'[1]粘贴_账务明细'!$A$4:$A$3003,$B29,'[1]粘贴_账务明细'!$L$4:$L$3003,"百亿补贴技术服务费")) -> 48.99 | G29: =IF($L29="","",SUMIFS('[1]粘贴_服务费返还'!$M$4:$M$3003,'[1]粘贴_服务费返还'!$N$4:$N$3003,$B29,'[1]粘贴_服务费返还'!$O$4:$O$3003,"返还")) -> 0 | H29: =IF($L29="","",SUMIFS('[1]粘贴_服务费返还'!$M$4:$M$3003,'[1]粘贴_服务费返还'!$N$4:$N$3003,$B29,'[1]粘贴_服务费返还'!$O$4:$O$3003,"扣回")) -> 0 | I29: =IF($L29="","",ROUND(F29-G29-H29,2)) -> 48.99 | J29: =IF($L29="","",IF(F29<0.005,"订单已退款，百亿费已原路退回，不用返",IF(G29+H29>=F29-0.01,"已返还",IF(H29<0,"返了又扣回(-t01)，问客服",IF(G29>0,"少返 "&TEXT(I29,"0.00"),"扣了还没返"))))) -> 扣了还没返 | K29: =IF($L29="","",INT($J$6)-INT(C29)) -> 1 | L29: =IF(A29>$H$5,"",MATCH(A29,'[1]粘贴_账务明细'!$O$4:$O$3003,0)) -> 5
A30: 2 | B30: =IF($L30="","",INDEX('[1]粘贴_账务明细'!$A$4:$A$3003,$L30)) -> 260926-409783560592068 | C30: =IF($L30="","",INDEX('[1]粘贴_账务明细'!$H$4:$H$3003,$L30)) -> 46294.706 | D30: =IF($L30="","",SUMIFS('[1]粘贴_账务明细'!$K$4:$K$3003,'[1]粘贴_账务明细'!$A$4:$A$3003,$B30,'[1]粘贴_账务明细'!$L$4:$L$3003,"订单收入")+SUMIFS('[1]粘贴_账务明细'!$K$4:$K$3003,'[1]粘贴_账务明细'!$A$4:$A$3003,$B30,'[1]粘贴_账务明细'!$L$4:$L$3003,"优惠券结算")) -> 3169 | E30: =IF($L30="","",ROUND(D30*0.014,2)) -> 44.37 | F30: =IF($L30="","",-SUMIFS('[1]粘贴_账务明细'!$K$4:$K$3003,'[1]粘贴_账务明细'!$A$4:$A$3003,$B30,'[1]粘贴_账务明细'!$L$4:$L$3003,"百亿补贴技术服务费")) -> 44.37 | G30: =IF($L30="","",SUMIFS('[1]粘贴_服务费返还'!$M$4:$M$3003,'[1]粘贴_服务费返还'!$N$4:$N$3003,$B30,'[1]粘贴_服务费返还'!$O$4:$O$3003,"返还")) -> 0 | H30: =IF($L30="","",SUMIFS('[1]粘贴_服务费返还'!$M$4:$M$3003,'[1]粘贴_服务费返还'!$N$4:$N$3003,$B30,'[1]粘贴_服务费返还'!$O$4:$O$3003,"扣回")) -> 0 | I30: =IF($L30="","",ROUND(F30-G30-H30,2)) -> 44.37 | J30: =IF($L30="","",IF(F30<0.005,"订单已退款，百亿费已原路退回，不用返",IF(G30+H30>=F30-0.01,"已返还",IF(H30<0,"返了又扣回(-t01)，问客服",IF(G30>0,"少返 "&TEXT(I30,"0.00"),"扣了还没返"))))) -> 扣了还没返 | K30: =IF($L30="","",INT($J$6)-INT(C30)) -> 1 | L30: =IF(A30>$H$5,"",MATCH(A30,'[1]粘贴_账务明细'!$O$4:$O$3003,0)) -> 6
A31: 3 | B31: =IF($L31="","",INDEX('[1]粘贴_账务明细'!$A$4:$A$3003,$L31)) -> 260922-289307420991455 | C31: =IF($L31="","",INDEX('[1]粘贴_账务明细'!$H$4:$H$3003,$L31)) -> 46294.671 | D31: =IF($L31="","",SUMIFS('[1]粘贴_账务明细'!$K$4:$K$3003,'[1]粘贴_账务明细'!$A$4:$A$3003,$B31,'[1]粘贴_账务明细'!$L$4:$L$3003,"订单收入")+SUMIFS('[1]粘贴_账务明细'!$K$4:$K$3003,'[1]粘贴_账务明细'!$A$4:$A$3003,$B31,'[1]粘贴_账务明细'!$L$4:$L$3003,"优惠券结算")) -> 3589 | E31: =IF($L31="","",ROUND(D31*0.014,2)) -> 50.25 | F31: =IF($L31="","",-SUMIFS('[1]粘贴_账务明细'!$K$4:$K$3003,'[1]粘贴_账务明细'!$A$4:$A$3003,$B31,'[1]粘贴_账务明细'!$L$4:$L$3003,"百亿补贴技术服务费")) -> 50.25 | G31: =IF($L31="","",SUMIFS('[1]粘贴_服务费返还'!$M$4:$M$3003,'[1]粘贴_服务费返还'!$N$4:$N$3003,$B31,'[1]粘贴_服务费返还'!$O$4:$O$3003,"返还")) -> 0 | H31: =IF($L31="","",SUMIFS('[1]粘贴_服务费返还'!$M$4:$M$3003,'[1]粘贴_服务费返还'!$N$4:$N$3003,$B31,'[1]粘贴_服务费返还'!$O$4:$O$3003,"扣回")) -> 0 | I31: =IF($L31="","",ROUND(F31-G31-H31,2)) -> 50.25 | J31: =IF($L31="","",IF(F31<0.005,"订单已退款，百亿费已原路退回，不用返",IF(G31+H31>=F31-0.01,"已返还",IF(H31<0,"返了又扣回(-t01)，问客服",IF(G31>0,"少返 "&TEXT(I31,"0.00"),"扣了还没返"))))) -> 扣了还没返 | K31: =IF($L31="","",INT($J$6)-INT(C31)) -> 1 | L31: =IF(A31>$H$5,"",MATCH(A31,'[1]粘贴_账务明细'!$O$4:$O$3003,0)) -> 9
A32: 4 | B32: =IF($L32="","",INDEX('[1]粘贴_账务明细'!$A$4:$A$3003,$L32)) -> 260926-467518103081461 | C32: =IF($L32="","",INDEX('[1]粘贴_账务明细'!$H$4:$H$3003,$L32)) -> 46294.435 | D32: =IF($L32="","",SUMIFS('[1]粘贴_账务明细'!$K$4:$K$3003,'[1]粘贴_账务明细'!$A$4:$A$3003,$B32,'[1]粘贴_账务明细'!$L$4:$L$3003,"订单收入")+SUMIFS('[1]粘贴_账务明细'!$K$4:$K$3003,'[1]粘贴_账务明细'!$A$4:$A$3003,$B32,'[1]粘贴_账务明细'!$L$4:$L$3003,"优惠券结算")) -> 3589 | E32: =IF($L32="","",ROUND(D32*0.014,2)) -> 50.25 | F32: =IF($L32="","",-SUMIFS('[1]粘贴_账务明细'!$K$4:$K$3003,'[1]粘贴_账务明细'!$A$4:$A$3003,$B32,'[1]粘贴_账务明细'!$L$4:$L$3003,"百亿补贴技术服务费")) -> 50.25 | G32: =IF($L32="","",SUMIFS('[1]粘贴_服务费返还'!$M$4:$M$3003,'[1]粘贴_服务费返还'!$N$4:$N$3003,$B32,'[1]粘贴_服务费返还'!$O$4:$O$3003,"返还")) -> 0 | H32: =IF($L32="","",SUMIFS('[1]粘贴_服务费返还'!$M$4:$M$3003,'[1]粘贴_服务费返还'!$N$4:$N$3003,$B32,'[1]粘贴_服务费返还'!$O$4:$O$3003,"扣回")) -> 0 | I32: =IF($L32="","",ROUND(F32-G32-H32,2)) -> 50.25 | J32: =IF($L32="","",IF(F32<0.005,"订单已退款，百亿费已原路退回，不用返",IF(G32+H32>=F32-0.01,"已返还",IF(H32<0,"返了又扣回(-t01)，问客服",IF(G32>0,"少返 "&TEXT(I32,"0.00"),"扣了还没返"))))) -> 扣了还没返 | K32: =IF($L32="","",INT($J$6)-INT(C32)) -> 1 | L32: =IF(A32>$H$5,"",MATCH(A32,'[1]粘贴_账务明细'!$O$4:$O$3003,0)) -> 15
A33: 5 | B33: =IF($L33="","",INDEX('[1]粘贴_账务明细'!$A$4:$A$3003,$L33)) -> 260924-421034770800999 | C33: =IF($L33="","",INDEX('[1]粘贴_账务明细'!$H$4:$H$3003,$L33)) -> 46294.021 | D33: =IF($L33="","",SUMIFS('[1]粘贴_账务明细'!$K$4:$K$3003,'[1]粘贴_账务明细'!$A$4:$A$3003,$B33,'[1]粘贴_账务明细'!$L$4:$L$3003,"订单收入")+SUMIFS('[1]粘贴_账务明细'!$K$4:$K$3003,'[1]粘贴_账务明细'!$A$4:$A$3003,$B33,'[1]粘贴_账务明细'!$L$4:$L$3003,"优惠券结算")) -> 3589 | E33: =IF($L33="","",ROUND(D33*0.014,2)) -> 50.25 | F33: =IF($L33="","",-SUMIFS('[1]粘贴_账务明细'!$K$4:$K$3003,'[1]粘贴_账务明细'!$A$4:$A$3003,$B33,'[1]粘贴_账务明细'!$L$4:$L$3003,"百亿补贴技术服务费")) -> 50.25 | G33: =IF($L33="","",SUMIFS('[1]粘贴_服务费返还'!$M$4:$M$3003,'[1]粘贴_服务费返还'!$N$4:$N$3003,$B33,'[1]粘贴_服务费返还'!$O$4:$O$3003,"返还")) -> 0 | H33: =IF($L33="","",SUMIFS('[1]粘贴_服务费返还'!$M$4:$M$3003,'[1]粘贴_服务费返还'!$N$4:$N$3003,$B33,'[1]粘贴_服务费返还'!$O$4:$O$3003,"扣回")) -> 0 | I33: =IF($L33="","",ROUND(F33-G33-H33,2)) -> 50.25 | J33: =IF($L33="","",IF(F33<0.005,"订单已退款，百亿费已原路退回，不用返",IF(G33+H33>=F33-0.01,"已返还",IF(H33<0,"返了又扣回(-t01)，问客服",IF(G33>0,"少返 "&TEXT(I33,"0.00"),"扣了还没返"))))) -> 扣了还没返 | K33: =IF($L33="","",INT($J$6)-INT(C33)) -> 1 | L33: =IF(A33>$H$5,"",MATCH(A33,'[1]粘贴_账务明细'!$O$4:$O$3003,0)) -> 18
A34: 6 | B34: =IF($L34="","",INDEX('[1]粘贴_账务明细'!$A$4:$A$3003,$L34)) -> 260928-546318641462943 | C34: =IF($L34="","",INDEX('[1]粘贴_账务明细'!$H$4:$H$3003,$L34)) -> 46293.692 | D34: =IF($L34="","",SUMIFS('[1]粘贴_账务明细'!$K$4:$K$3003,'[1]粘贴_账务明细'!$A$4:$A$3003,$B34,'[1]粘贴_账务明细'!$L$4:$L$3003,"订单收入")+SUMIFS('[1]粘贴_账务明细'!$K$4:$K$3003,'[1]粘贴_账务明细'!$A$4:$A$3003,$B34,'[1]粘贴_账务明细'!$L$4:$L$3003,"优惠券结算")) -> 3019 | E34: =IF($L34="","",ROUND(D34*0.014,2)) -> 42.27 | F34: =IF($L34="","",-SUMIFS('[1]粘贴_账务明细'!$K$4:$K$3003,'[1]粘贴_账务明细'!$A$4:$A$3003,$B34,'[1]粘贴_账务明细'!$L$4:$L$3003,"百亿补贴技术服务费")) -> 0 | G34: =IF($L34="","",SUMIFS('[1]粘贴_服务费返还'!$M$4:$M$3003,'[1]粘贴_服务费返还'!$N$4:$N$3003,$B34,'[1]粘贴_服务费返还'!$O$4:$O$3003,"返还")) -> 0 | H34: =IF($L34="","",SUMIFS('[1]粘贴_服务费返还'!$M$4:$M$3003,'[1]粘贴_服务费返还'!$N$4:$N$3003,$B34,'[1]粘贴_服务费返还'!$O$4:$O$3003,"扣回")) -> 0 | I34: =IF($L34="","",ROUND(F34-G34-H34,2)) -> 0 | J34: =IF($L34="","",IF(F34<0.005,"订单已退款，百亿费已原路退回，不用返",IF(G34+H34>=F34-0.01,"已返还",IF(H34<0,"返了又扣回(-t01)，问客服",IF(G34>0,"少返 "&TEXT(I34,"0.00"),"扣了还没返"))))) -> 订单已退款，百亿费已原路退回，不用返 | K34: =IF($L34="","",INT($J$6)-INT(C34)) -> 2 | L34: =IF(A34>$H$5,"",MATCH(A34,'[1]粘贴_账务明细'!$O$4:$O$3003,0)) -> 23
A35: 7 | B35: =IF($L35="","",INDEX('[1]粘贴_账务明细'!$A$4:$A$3003,$L35)) -> 260925-504543394092041 | C35: =IF($L35="","",INDEX('[1]粘贴_账务明细'!$H$4:$H$3003,$L35)) -> 46292.546 | D35: =IF($L35="","",SUMIFS('[1]粘贴_账务明细'!$K$4:$K$3003,'[1]粘贴_账务明细'!$A$4:$A$3003,$B35,'[1]粘贴_账务明细'!$L$4:$L$3003,"订单收入")+SUMIFS('[1]粘贴_账务明细'!$K$4:$K$3003,'[1]粘贴_账务明细'!$A$4:$A$3003,$B35,'[1]粘贴_账务明细'!$L$4:$L$3003,"优惠券结算")) -> 3499 | E35: =IF($L35="","",ROUND(D35*0.014,2)) -> 48.99 | F35: =IF($L35="","",-SUMIFS('[1]粘贴_账务明细'!$K$4:$K$3003,'[1]粘贴_账务明细'!$A$4:$A$3003,$B35,'[1]粘贴_账务明细'!$L$4:$L$3003,"百亿补贴技术服务费")) -> 48.99 | G35: =IF($L35="","",SUMIFS('[1]粘贴_服务费返还'!$M$4:$M$3003,'[1]粘贴_服务费返还'!$N$4:$N$3003,$B35,'[1]粘贴_服务费返还'!$O$4:$O$3003,"返还")) -> 0 | H35: =IF($L35="","",SUMIFS('[1]粘贴_服务费返还'!$M$4:$M$3003,'[1]粘贴_服务费返还'!$N$4:$N$3003,$B35,'[1]粘贴_服务费返还'!$O$4:$O$3003,"扣回")) -> 0 | I35: =IF($L35="","",ROUND(F35-G35-H35,2)) -> 48.99 | J35: =IF($L35="","",IF(F35<0.005,"订单已退款，百亿费已原路退回，不用返",IF(G35+H35>=F35-0.01,"已返还",IF(H35<0,"返了又扣回(-t01)，问客服",IF(G35>0,"少返 "&TEXT(I35,"0.00"),"扣了还没返"))))) -> 扣了还没返 | K35: =IF($L35="","",INT($J$6)-INT(C35)) -> 3 | L35: =IF(A35>$H$5,"",MATCH(A35,'[1]粘贴_账务明细'!$O$4:$O$3003,0)) -> 29
A36: 8 | B36: =IF($L36="","",INDEX('[1]粘贴_账务明细'!$A$4:$A$3003,$L36)) -> 260926-645083962921461 | C36: =IF($L36="","",INDEX('[1]粘贴_账务明细'!$H$4:$H$3003,$L36)) -> 46291.823 | D36: =IF($L36="","",SUMIFS('[1]粘贴_账务明细'!$K$4:$K$3003,'[1]粘贴_账务明细'!$A$4:$A$3003,$B36,'[1]粘贴_账务明细'!$L$4:$L$3003,"订单收入")+SUMIFS('[1]粘贴_账务明细'!$K$4:$K$3003,'[1]粘贴_账务明细'!$A$4:$A$3003,$B36,'[1]粘贴_账务明细'!$L$4:$L$3003,"优惠券结算")) -> 3589 | E36: =IF($L36="","",ROUND(D36*0.014,2)) -> 50.25 | F36: =IF($L36="","",-SUMIFS('[1]粘贴_账务明细'!$K$4:$K$3003,'[1]粘贴_账务明细'!$A$4:$A$3003,$B36,'[1]粘贴_账务明细'!$L$4:$L$3003,"百亿补贴技术服务费")) -> 0 | G36: =IF($L36="","",SUMIFS('[1]粘贴_服务费返还'!$M$4:$M$3003,'[1]粘贴_服务费返还'!$N$4:$N$3003,$B36,'[1]粘贴_服务费返还'!$O$4:$O$3003,"返还")) -> 0 | H36: =IF($L36="","",SUMIFS('[1]粘贴_服务费返还'!$M$4:$M$3003,'[1]粘贴_服务费返还'!$N$4:$N$3003,$B36,'[1]粘贴_服务费返还'!$O$4:$O$3003,"扣回")) -> 0 | I36: =IF($L36="","",ROUND(F36-G36-H36,2)) -> 0 | J36: =IF($L36="","",IF(F36<0.005,"订单已退款，百亿费已原路退回，不用返",IF(G36+H36>=F36-0.01,"已返还",IF(H36<0,"返了又扣回(-t01)，问客服",IF(G36>0,"少返 "&TEXT(I36,"0.00"),"扣了还没返"))))) -> 订单已退款，百亿费已原路退回，不用返 | K36: =IF($L36="","",INT($J$6)-INT(C36)) -> 4 | L36: =IF(A36>$H$5,"",MATCH(A36,'[1]粘贴_账务明细'!$O$4:$O$3003,0)) -> 34
A37: 9 | B37: =IF($L37="","",INDEX('[1]粘贴_账务明细'!$A$4:$A$3003,$L37)) -> 260924-102770983250639 | C37: =IF($L37="","",INDEX('[1]粘贴_账务明细'!$H$4:$H$3003,$L37)) -> 46291.803 | D37: =IF($L37="","",SUMIFS('[1]粘贴_账务明细'!$K$4:$K$3003,'[1]粘贴_账务明细'!$A$4:$A$3003,$B37,'[1]粘贴_账务明细'!$L$4:$L$3003,"订单收入")+SUMIFS('[1]粘贴_账务明细'!$K$4:$K$3003,'[1]粘贴_账务明细'!$A$4:$A$3003,$B37,'[1]粘贴_账务明细'!$L$4:$L$3003,"优惠券结算")) -> 3499 | E37: =IF($L37="","",ROUND(D37*0.014,2)) -> 48.99 | F37: =IF($L37="","",-SUMIFS('[1]粘贴_账务明细'!$K$4:$K$3003,'[1]粘贴_账务明细'!$A$4:$A$3003,$B37,'[1]粘贴_账务明细'!$L$4:$L$3003,"百亿补贴技术服务费")) -> 48.99 | G37: =IF($L37="","",SUMIFS('[1]粘贴_服务费返还'!$M$4:$M$3003,'[1]粘贴_服务费返还'!$N$4:$N$3003,$B37,'[1]粘贴_服务费返还'!$O$4:$O$3003,"返还")) -> 0 | H37: =IF($L37="","",SUMIFS('[1]粘贴_服务费返还'!$M$4:$M$3003,'[1]粘贴_服务费返还'!$N$4:$N$3003,$B37,'[1]粘贴_服务费返还'!$O$4:$O$3003,"扣回")) -> 0 | I37: =IF($L37="","",ROUND(F37-G37-H37,2)) -> 48.99 | J37: =IF($L37="","",IF(F37<0.005,"订单已退款，百亿费已原路退回，不用返",IF(G37+H37>=F37-0.01,"已返还",IF(H37<0,"返了又扣回(-t01)，问客服",IF(G37>0,"少返 "&TEXT(I37,"0.00"),"扣了还没返"))))) -> 扣了还没返 | K37: =IF($L37="","",INT($J$6)-INT(C37)) -> 4 | L37: =IF(A37>$H$5,"",MATCH(A37,'[1]粘贴_账务明细'!$O$4:$O$3003,0)) -> 39
A38: 10 | B38: =IF($L38="","",INDEX('[1]粘贴_账务明细'!$A$4:$A$3003,$L38)) -> 260924-347508652384062 | C38: =IF($L38="","",INDEX('[1]粘贴_账务明细'!$H$4:$H$3003,$L38)) -> 46291.695 | D38: =IF($L38="","",SUMIFS('[1]粘贴_账务明细'!$K$4:$K$3003,'[1]粘贴_账务明细'!$A$4:$A$3003,$B38,'[1]粘贴_账务明细'!$L$4:$L$3003,"订单收入")+SUMIFS('[1]粘贴_账务明细'!$K$4:$K$3003,'[1]粘贴_账务明细'!$A$4:$A$3003,$B38,'[1]粘贴_账务明细'!$L$4:$L$3003,"优惠券结算")) -> 3499 | E38: =IF($L38="","",ROUND(D38*0.014,2)) -> 48.99 | F38: =IF($L38="","",-SUMIFS('[1]粘贴_账务明细'!$K$4:$K$3003,'[1]粘贴_账务明细'!$A$4:$A$3003,$B38,'[1]粘贴_账务明细'!$L$4:$L$3003,"百亿补贴技术服务费")) -> 48.99 | G38: =IF($L38="","",SUMIFS('[1]粘贴_服务费返还'!$M$4:$M$3003,'[1]粘贴_服务费返还'!$N$4:$N$3003,$B38,'[1]粘贴_服务费返还'!$O$4:$O$3003,"返还")) -> 0 | H38: =IF($L38="","",SUMIFS('[1]粘贴_服务费返还'!$M$4:$M$3003,'[1]粘贴_服务费返还'!$N$4:$N$3003,$B38,'[1]粘贴_服务费返还'!$O$4:$O$3003,"扣回")) -> 0 | I38: =IF($L38="","",ROUND(F38-G38-H38,2)) -> 48.99 | J38: =IF($L38="","",IF(F38<0.005,"订单已退款，百亿费已原路退回，不用返",IF(G38+H38>=F38-0.01,"已返还",IF(H38<0,"返了又扣回(-t01)，问客服",IF(G38>0,"少返 "&TEXT(I38,"0.00"),"扣了还没返"))))) -> 扣了还没返 | K38: =IF($L38="","",INT($J$6)-INT(C38)) -> 4 | L38: =IF(A38>$H$5,"",MATCH(A38,'[1]粘贴_账务明细'!$O$4:$O$3003,0)) -> 43
